<?xml version='1.0' encoding='UTF-8'?>
<mujoco model="model">
  <option timestep="0.002" gravity="0.0 0.0 -9.81"/>
  <compiler angle="radian"/>
  <asset>
    <mesh file="visuals/knob_front_left.obj" name="knob_front_left_vis"/>
    <mesh file="visuals/knob_front_right.obj" name="knob_front_right_vis"/>
    <mesh file="visuals/knob_rear_left.obj" name="knob_rear_left_vis"/>
    <mesh file="visuals/knob_rear_right.obj" name="knob_rear_right_vis"/>
    <mesh file="visuals/rack0.obj" name="rack0_vis"/>
    <mesh file="visuals/Body001.obj" name="Body001_vis"/>
    <mesh file="visuals/Door001.obj" name="Door001_vis"/>
    <mesh file="visuals/Door001_Clear.obj" name="Door001_Clear_vis"/>
    <mesh file="visuals/Knob001.obj" name="Knob001_vis"/>
    <mesh file="visuals/Knob002.obj" name="Knob002_vis"/>
    <texture file="visuals/T_BC001.png" name="Body001_material" type="2d"/>
    <material name="Body001_material" rgba="1 1 1 1.0" texture="Body001_material" shininess="0.4472135901451111" specular="2"/>
    <texture file="visuals/T_BC001.png" name="knob_front_left_material" type="2d"/>
    <material name="knob_front_left_material" rgba="1 1 1 1.0" texture="knob_front_left_material" shininess="0.4472135901451111" specular="0.3103448502657381"/>
    <texture file="visuals/T_BC001.png" name="knob_front_right_material" type="2d"/>
    <material name="knob_front_right_material" rgba="1 1 1 1.0" texture="knob_front_right_material" shininess="0.4472135901451111" specular="0.3103448502657381"/>
    <texture file="visuals/T_BC001.png" name="knob_rear_left_material" type="2d"/>
    <material name="knob_rear_left_material" rgba="1 1 1 1.0" texture="knob_rear_left_material" shininess="0.4472135901451111" specular="0.3103448502657381"/>
    <texture file="visuals/T_BC001.png" name="knob_rear_right_material" type="2d"/>
    <material name="knob_rear_right_material" rgba="1 1 1 1.0" texture="knob_rear_right_material" shininess="0.4472135901451111" specular="0.3103448502657381"/>
    <texture file="visuals/T_BC001.png" name="rack0_material" type="2d"/>
    <material name="rack0_material" rgba="1 1 1 1.0" texture="rack0_material" shininess="0.2472135901451111" specular="3"/>
    <texture file="visuals/T_BC001.png" name="Door001_material" type="2d"/>
    <material name="Door001_material" rgba="1 1 1 1.0" texture="Door001_material" shininess="0.4472135901451111" specular="1"/>
    <texture file="visuals/T_BC001.png" name="Door001_Clear_material" type="2d"/>
    <material name="Door001_Clear_material" rgba="1 1 1 0.5" texture="Door001_Clear_material" shininess="0.4472135901451111" specular="0.3103448502657381"/>
    <texture file="visuals/T_BC001.png" name="Knob001_material" type="2d"/>
    <material name="Knob001_material" rgba="1 1 1 1.0" texture="Knob001_material" shininess="0.4472135901451111" specular="0.3103448502657381"/>
    <texture file="visuals/T_BC001.png" name="Knob002_material" type="2d"/>
    <material name="Knob002_material" rgba="1 1 1 1.0" texture="Knob002_material" shininess="0.4472135901451111" specular="0.3103448502657381"/>
  </asset>
  <default>
    <default class="visual">
      <geom conaffinity="0" contype="0" group="1" type="mesh"/>
    </default>
    <default class="collision">
      <geom group="0" rgba="0.5 0 0 0.5"/>
    </default>
    <default class="spawn">
      <geom group="0" rgba="1 1 1 0.5" contype="0" conaffinity="0"/>
      <site group="0" rgba="1 1 1 0.5"/>
    </default>
    <default class="region">
      <geom group="1" conaffinity="0" contype="0" rgba="0 1 0 0"/>
    </default>
  </default>
  <worldbody>
    <body>
      <body name="object">
        <geom mesh="Body001_vis" type="mesh" solimp="0.998 0.998 0.001" solref="0.001 1" friction="0.95 0.3 0.1" class="visual" material="Body001_material"/>
        <geom class="collision" type="box" pos="-0.00000004 0.33141214 0.00043112" size="0.3806862235069275 0.020578525960445404 0.5647372007369995" quat="1.0 0.0 0.0 0.0"/>
        <geom class="collision" type="box" pos="-0.00000006 0.01016810 0.27145514" size="0.3806861639022827 0.3160743713378906 0.017430339008569717" quat="1.0 0.0 0.0 0.0"/>
        <geom class="collision" type="box" pos="-0.34369320 0.01970948 -0.15603361" size="0.036992400884628296 0.29352086782455444 0.40876296162605286" quat="1.0 0.0 0.0 0.0"/>
        <geom class="collision" type="box" pos="0.34371990 0.01970945 -0.15603361" size="0.03696554899215698 0.29352104663848877 0.4087632894515991" quat="1.0 0.0 0.0 0.0"/>
        <geom class="collision" type="box" pos="0.00000008 0.04733154 -0.39487693" size="0.38068604469299316 0.3046591281890869 0.1715342402458191" quat="1.0 0.0 0.0 0.0"/>
        <geom class="collision" type="box" pos="-0.00000009 0.29649845 0.47859463" size="0.38068610429763794 0.022199612110853195 0.08681080490350723" quat="1.0 0.0 0.0 0.0"/>
        <geom class="collision" type="box" pos="-0.00000008 -0.27832919 -0.43511754" size="0.38068604469299316 0.027558965608477592 0.1312955766916275" quat="1.0 0.0 0.0 0.0"/>
        <geom class="collision" type="box" pos="-0.00000008 0.02697441 0.21697469" size="0.3806861639022827 0.29926806688308716 0.03758362680673599" quat="1.0 0.0 0.0 0.0"/>
        <geom class="collision" type="box" pos="-0.00000005 0.27038795 -0.14452395" size="0.3806861639022827 0.052861034870147705 0.4197821319103241" quat="1.0 0.0 0.0 0.0"/>
        <geom class="collision" type="box" pos="0.00000003 0.32591942 0.34033477" size="0.3806862235069275 0.021302122622728348 0.05144909396767616" quat="1.0 0.0 0.0 0.0"/>
        <geom class="collision" type="box" pos="-0.30340379 -0.02562435 -0.03495346" size="0.008126471191644669 0.2303268164396286 0.0058300914242863655" quat="1.0 0.0 0.0 0.0"/>
        <geom class="collision" type="box" pos="0.30343747 -0.02562435 -0.03495346" size="0.008126477710902691 0.2303270399570465 0.005830096546560526" quat="1.0 0.0 0.0 0.0"/>
        <body name="knob_front_left">
          <joint axis="0.0 -1.0 0.0" pos="-0.29997504 0.26397789 0.48121476" limited="true" name="knob_front_left_joint" range="0.0 3.490658503988659" type="hinge" damping="0.05" frictionloss="0.1" armature="0.001"/>
          <geom mesh="knob_front_left_vis" type="mesh" solimp="0.998 0.998 0.001" solref="0.001 1" friction="0.95 0.3 0.1" class="visual" material="knob_front_left_material"/>
          <geom class="collision" type="cylinder" pos="-0.30022097 0.25812337 0.48115158" size="0.02481306903064251 0.010621534660458565" quat="0.7071067094802856 0.70710688829422 0.0 0.0" density="0.001"/>
          <geom class="collision" type="box" pos="-0.30009180 0.24537212 0.47713476" size="0.005765822716057301 0.003975169267505407 0.018001941964030266" quat="1.0 0.0 0.0 0.0" name="knob_front_left_main" density="0.001"/>
        </body>
        <body name="knob_front_right">
          <joint axis="0.0 -1.0 0.0" pos="0.30002493 0.26397789 0.48121476" limited="true" name="knob_front_right_joint" range="0.0 3.490658503988659" type="hinge" damping="0.05" frictionloss="0.1" armature="0.001"/>
          <geom mesh="knob_front_right_vis" type="mesh" solimp="0.998 0.998 0.001" solref="0.001 1" friction="0.95 0.3 0.1" class="visual" material="knob_front_right_material"/>
          <geom class="collision" type="cylinder" pos="0.29960778 0.25812337 0.48132321" size="0.02481306903064251 0.010621534660458565" quat="0.7071067094802856 0.70710688829422 0.0 0.0" density="0.001"/>
          <geom class="collision" type="box" pos="0.29987156 0.24537212 0.47735271" size="0.005765830632299185 0.003975172061473131 0.018001960590481758" quat="1.0 0.0 0.0 0.0" name="knob_front_right_main" density="0.001"/>
        </body>
        <body name="knob_rear_left">
          <joint axis="0.0 -1.0 0.0" pos="-0.17997505 0.26397789 0.48123443" limited="true" name="knob_rear_left_joint" range="0.0 3.490658503988659" type="hinge" damping="0.05" armature="0.001"/>
          <geom mesh="knob_rear_left_vis" type="mesh" solimp="0.998 0.998 0.001" solref="0.001 1" friction="0.95 0.3 0.1" class="visual" material="knob_rear_left_material"/>
          <geom class="collision" type="cylinder" pos="-0.17979206 0.25812337 0.48115158" size="0.02481306903064251 0.010621534660458565" quat="0.7071067094802856 0.70710688829422 0.0 0.0"/>
          <geom class="collision" type="box" pos="-0.18023492 0.24537212 0.47713476" size="0.005765832494944334 0.00397517392411828 0.0180019810795784" quat="1.0 0.0 0.0 0.0" name="knob_rear_left_main"/>
        </body>
        <body name="knob_rear_right">
          <joint axis="0.0 -1.0 0.0" pos="0.18002495 0.26397789 0.48123443" limited="true" name="knob_rear_right_joint" range="0.0 3.490658503988659" type="hinge" damping="0.05" frictionloss="0.1" armature="0.001"/>
          <geom mesh="knob_rear_right_vis" type="mesh" solimp="0.998 0.998 0.001" solref="0.001 1" friction="0.95 0.3 0.1" class="visual" material="knob_rear_right_material"/>
          <geom class="collision" type="cylinder" pos="0.17970701 0.25812337 0.48109198" size="0.02481306903064251 0.010621534660458565" quat="0.7071067094802856 0.70710688829422 0.0 0.0" density="0.001"/>
          <geom class="collision" type="box" pos="0.17995484 0.24537212 0.47735271" size="0.005765839945524931 0.0039751771837472916 0.018001999706029892" quat="1.0 0.0 0.0 0.0" name="knob_rear_right_main" density="0.001"/>
        </body>
        <body name="rack0">
          <geom class="region" name="reg_rack0" type="box" pos="0.0001460199999999967 -0.027455795000000005 0.07908313" size="0.29649165 0.218130715 0.09631961"/>
          <joint axis="0.0 -1.0 0.0" pos="-0.00030982 -0.02778162 -0.02440071" limited="true" name="rack0_joint" range="0.0 0.4" type="slide" damping="1" frictionloss="1" armature=".01" stiffness="0.05"/>
          <geom mesh="rack0_vis" type="mesh" solimp="0.998 0.998 0.001" solref="0.001 1" friction="0.95 0.3 0.1" class="visual" material="rack0_material"/>
          <geom class="collision" type="box" pos="0.00004929 -0.02774362 -0.02444427" size="0.30589088797569275 0.2233871966600418 0.0033582113683223724" quat="1.0 0.0 0.0 0.0"/>
        </body>
        <body name="Door001">
          <joint axis="1.0 0.0 0.0" pos="0.00002470 -0.30591324 -0.29060394" limited="true" name="Door001_joint" range="0.0 1.5707963267948966" type="hinge" damping="1" frictionloss="1" armature=".01" stiffness="0.05"/>
          <geom mesh="Door001_vis" type="mesh" solimp="0.998 0.998 0.001" solref="0.001 1" friction="0.95 0.3 0.1" class="visual" material="Door001_material"/>
          <geom class="collision" type="box" pos="-0.00016396 -0.29060730 -0.02252813" size="0.37981483340263367 0.0152989961206913 0.27016061544418335" quat="1.0 0.0 0.0 0.0"/>
          <geom class="collision" type="box" pos="-0.25672275 -0.31927585 0.22760564" size="0.057031355798244476 0.01119912974536419 0.016437169164419174" quat="1.9142196094890096e-07 0.9831273555755615 -0.18292252719402313 -3.5616331217624975e-08"/>
          <geom class="collision" type="box" pos="0.25520575 -0.31996482 0.22760564" size="0.0557350218296051 0.011199130676686764 0.016437169164419174" quat="0.9820809364318848 0.0 0.0 0.1884595900774002"/>
          <geom class="collision" type="box" pos="-0.00219345 -0.34284508 0.22760564" size="0.2057637721300125 0.009586269967257977 0.016437506303191185" quat="1.0 0.0 0.0 0.0"/>
          <geom class="collision" type="box" pos="-0.00011302 -0.29200640 -0.00566677" size="0.3775268495082855 0.010744334198534489 0.14932073652744293" quat="1.0 0.0 0.0 0.0"/>
          <body name="Door001_Clear">
            <geom mesh="Door001_Clear_vis" type="mesh" solimp="0.998 0.998 0.001" solref="0.001 1" friction="0.95 0.3 0.1" class="visual" material="Door001_Clear_material"/>
            <geom class="collision" type="box" pos="-0.00011302 -0.29200640 -0.00566677" size="0.3775268495082855 0.010744334198534489 0.14932073652744293" quat="1.0 0.0 0.0 0.0"/>
          </body>
        </body>
        <body name="Knob001">
          <joint axis="0.0 1.0 0.0" pos="-0.06086761 0.25894112 0.48261145" limited="true" name="Knob001_joint" range="0.0 5.235987755982989" type="hinge" damping="0.05" armature="0.001"/>
          <geom mesh="Knob001_vis" type="mesh" solimp="0.998 0.998 0.001" solref="0.001 1" friction="0.95 0.3 0.1" class="visual" material="Knob001_material"/>
          <geom class="collision" type="cylinder" pos="-0.06157003 0.25812337 0.48248187" size="0.02481306903064251 0.010621534660458565" quat="0.7071067094802856 0.70710688829422 0.0 0.0"/>
          <geom class="collision" type="box" pos="-0.05733858 0.24537212 0.48249927" size="0.018002020195126534 0.003975180443376303 0.005765845067799091" quat="1.0 0.0 0.0 0.0"/>
        </body>
        <body name="Knob002">
          <joint axis="0.0 1.0 0.0" pos="0.06002495 0.26397789 0.48121476" limited="true" name="Knob002_joint" range="0.0 5.585053606381854" type="hinge" damping="0.05" frictionloss="0.1" armature="0.001"/>
          <geom mesh="Knob002_vis" type="mesh" solimp="0.998 0.998 0.001" solref="0.001 1" friction="0.95 0.3 0.1" class="visual" material="Knob002_material"/>
          <geom class="collision" type="cylinder" pos="0.06021304 0.25812337 0.48115158" size="0.02481306903064251 0.010621534660458565" quat="0.7071067094802856 0.70710688829422 0.0 0.0" density="0.001"/>
          <geom class="collision" type="box" pos="0.05986389 0.24485770 0.48577774" size="0.005765849258750677 0.003975181840360165 0.018002036958932877" quat="1.0 0.0 0.0 0.0" density="0.001"/>
        </body>
        <geom class="region" name="reg_int" type="box" pos="-2.506499999999079e-05 -0.02881033000000001 -0.021701229999999988" size="0.301569235 0.24124599000000002 0.19622017"/>
        <site type="cylinder" rgba="0.5 0 0 0.5" size="0.08162451535463333 0.0001" pos="0.18573228 0.14049077 0.28735113" name="burner_on_rear_right"/>
        <site type="cylinder" rgba="0.5 0 0 0.5" size="0.10100214928388596 0.0001" pos="-0.15216334 0.12825166 0.28735113" name="burner_on_rear_left"/>
        <site type="cylinder" rgba="0.5 0 0 0.5" size="0.12768973410129547 0.0001" pos="0.16889362 -0.14327609 0.28735113" name="burner_on_front_right"/>
        <site type="cylinder" rgba="0.5 0 0 0.5" size="0.10568003356456757 0.0001" pos="-0.17063928 -0.14766781 0.28735113" name="burner_on_front_left"/>
        <site name="burner_rear_right_place_site" type="cylinder" rgba="0.5 0 0 0" size="0.08162451535463333 4.999999873689376e-05" pos="0.18573228 0.14049077 0.28735113"/>
        <site name="burner_rear_left_place_site" type="cylinder" rgba="0.5 0 0 0" size="0.10100214928388596 4.999999873689376e-05" pos="-0.15216334 0.12825166 0.28735113"/>
        <site name="burner_front_right_place_site" type="cylinder" rgba="0.5 0 0 0" size="0.12768973410129547 4.999999873689376e-05" pos="0.16889362 -0.14327609 0.28735113"/>
        <site name="burner_front_left_place_site" type="cylinder" rgba="0.5 0 0 0" size="0.10568003356456757 4.999999873689376e-05" pos="-0.17063928 -0.14766781 0.28735113"/>
        <geom class="region" name="reg_main" type="box" pos="4.999999997368221e-09 0.023042265000000006 -0.13876447000000003" size="0.38168598499999995 0.329948375 0.42865012"/>
      </body>
    </body>
  </worldbody>
  <actuator>
    <motor name="knob_front_left_joint_actuator" joint="knob_front_left_joint" gear="10"/>
    <motor name="knob_front_right_joint_actuator" joint="knob_front_right_joint" gear="10"/>
    <motor name="knob_rear_left_joint_actuator" joint="knob_rear_left_joint" gear="10"/>
    <motor name="knob_rear_right_joint_actuator" joint="knob_rear_right_joint" gear="10"/>
    <motor name="rack0_joint_actuator" joint="rack0_joint" gear="10"/>
    <motor name="Door001_joint_actuator" joint="Door001_joint" gear="150"/>
    <motor name="Knob001_joint_actuator" joint="Knob001_joint" gear="10"/>
    <motor name="Knob002_joint_actuator" joint="Knob002_joint" gear="10"/>
  </actuator>
</mujoco>
