<?xml version='1.0' encoding='UTF-8'?>
<mujoco model="model">
  <option timestep="0.002" gravity="0.0 0.0 -9.81"/>
  <compiler angle="radian"/>
  <asset>
    <mesh file="visuals/knob_front_left.obj" name="knob_front_left_vis"/>
    <mesh file="visuals/knob_front_right.obj" name="knob_front_right_vis"/>
    <mesh file="visuals/knob_rear_left.obj" name="knob_rear_left_vis"/>
    <mesh file="visuals/knob_rear_right.obj" name="knob_rear_right_vis"/>
    <mesh file="visuals/Body001.obj" name="Body001_vis"/>
    <mesh file="visuals/Door001.obj" name="Door001_vis"/>
    <mesh file="visuals/Door001_Clear.obj" name="Door001_Clear_vis"/>
    <mesh file="visuals/Knob001.obj" name="Knob001_vis"/>
    <mesh file="visuals/Knob002.obj" name="Knob002_vis"/>
    <mesh file="visuals/Shelf001.obj" name="Shelf001_vis"/>
    <texture file="visuals/T_BC001.png" name="Body001_material" type="2d"/>
    <material name="Body001_material" rgba="1 1 1 1.0" texture="Body001_material" shininess="0.4472135901451111" specular="1"/>
    <texture file="visuals/T_BC001.png" name="knob_front_left_material" type="2d"/>
    <material name="knob_front_left_material" rgba="1 1 1 1.0" texture="knob_front_left_material" shininess="0.4472135901451111" specular="0.3103448502657381"/>
    <texture file="visuals/T_BC001.png" name="knob_front_right_material" type="2d"/>
    <material name="knob_front_right_material" rgba="1 1 1 1.0" texture="knob_front_right_material" shininess="0.4472135901451111" specular="0.3103448502657381"/>
    <texture file="visuals/T_BC001.png" name="knob_rear_left_material" type="2d"/>
    <material name="knob_rear_left_material" rgba="1 1 1 1.0" texture="knob_rear_left_material" shininess="0.4472135901451111" specular="0.3103448502657381"/>
    <texture file="visuals/T_BC001.png" name="knob_rear_right_material" type="2d"/>
    <material name="knob_rear_right_material" rgba="1 1 1 1.0" texture="knob_rear_right_material" shininess="0.4472135901451111" specular="0.3103448502657381"/>
    <texture file="visuals/T_BC001.png" name="Door001_material" type="2d"/>
    <material name="Door001_material" rgba="1 1 1 1.0" texture="Door001_material" shininess="0.4472135901451111" specular="1"/>
    <texture file="visuals/T_BC001.png" name="Door001_Clear_material" type="2d"/>
    <material name="Door001_Clear_material" rgba="1 1 1 0.5" texture="Door001_Clear_material" shininess="0.4472135901451111" specular="0.3103448502657381"/>
    <texture file="visuals/T_BC001.png" name="Knob001_material" type="2d"/>
    <material name="Knob001_material" rgba="1 1 1 1.0" texture="Knob001_material" shininess="0.4472135901451111" specular="0.3103448502657381"/>
    <texture file="visuals/T_BC001.png" name="Knob002_material" type="2d"/>
    <material name="Knob002_material" rgba="1 1 1 1.0" texture="Knob002_material" shininess="0.4472135901451111" specular="0.3103448502657381"/>
    <texture file="visuals/T_BC001.png" name="Shelf001_material" type="2d"/>
    <material name="Shelf001_material" rgba="1 1 1 1.0" texture="Shelf001_material" shininess="0.4472135901451111" specular="5"/>
  </asset>
  <default>
    <default class="visual">
      <geom conaffinity="0" contype="0" group="1" type="mesh"/>
    </default>
    <default class="collision">
      <geom group="0" rgba="0.5 0 0 0.5"/>
    </default>
    <default class="spawn">
      <geom group="0" rgba="1 1 1 0.5" contype="0" conaffinity="0"/>
      <site group="0" rgba="1 1 1 0.5"/>
    </default>
    <default class="region">
      <geom group="1" conaffinity="0" contype="0" rgba="0 1 0 0"/>
    </default>
  </default>
  <worldbody>
    <body>
      <body name="object">
        <geom mesh="Body001_vis" type="mesh" solimp="0.998 0.998 0.001" solref="0.001 1" friction="0.95 0.3 0.1" class="visual" material="Body001_material"/>
        <geom class="collision" type="box" pos="-0.00000004 0.33141214 0.00043112" size="0.3806862235069275 0.020578525960445404 0.5647372007369995" quat="1.0 0.0 0.0 0.0"/>
        <geom class="collision" type="box" pos="-0.00000006 0.01016810 0.27145514" size="0.3806861639022827 0.3160743713378906 0.017430316656827927" quat="1.0 0.0 0.0 0.0"/>
        <geom class="collision" type="box" pos="-0.34369320 0.01970948 -0.15603361" size="0.03699234873056412 0.29352039098739624 0.40876227617263794" quat="1.0 0.0 0.0 0.0"/>
        <geom class="collision" type="box" pos="0.34371990 0.01970945 -0.15603361" size="0.0369655005633831 0.29352062940597534 0.4087626338005066" quat="1.0 0.0 0.0 0.0"/>
        <geom class="collision" type="box" pos="0.00000008 0.04733154 -0.39487693" size="0.38068604469299316 0.3046591281890869 0.17153392732143402" quat="1.0 0.0 0.0 0.0"/>
        <geom class="collision" type="box" pos="-0.00000009 0.29649845 0.47859463" size="0.38068610429763794 0.022199612110853195 0.08681080490350723" quat="1.0 0.0 0.0 0.0"/>
        <geom class="collision" type="box" pos="-0.00000008 -0.27832919 -0.43511754" size="0.38068604469299316 0.027558965608477592 0.13129544258117676" quat="1.0 0.0 0.0 0.0"/>
        <geom class="collision" type="box" pos="-0.00000008 0.02697441 0.21697469" size="0.3806861639022827 0.29926806688308716 0.03758356720209122" quat="1.0 0.0 0.0 0.0"/>
        <geom class="collision" type="box" pos="-0.00000005 0.27038795 -0.14452395" size="0.3806861639022827 0.052861034870147705 0.4197821319103241" quat="1.0 0.0 0.0 0.0"/>
        <geom class="collision" type="box" pos="0.00000003 0.32591942 0.34033477" size="0.3806862235069275 0.021302122622728348 0.05144909396767616" quat="1.0 0.0 0.0 0.0"/>
        <geom class="collision" type="box" pos="-0.30340379 -0.02562435 -0.03495346" size="0.008126465603709221 0.2303265929222107 0.005830086302012205" quat="1.0 0.0 0.0 0.0"/>
        <geom class="collision" type="box" pos="0.30343747 -0.02562435 -0.03495346" size="0.008126472122967243 0.230326846241951 0.005830091889947653" quat="1.0 0.0 0.0 0.0"/>
        <body name="knob_front_left">
          <joint axis="0.0 -1.0 0.0" pos="-0.29997504 0.26397789 0.48121476" limited="true" name="knob_front_left_joint" range="0.0 3.490658503988659" type="hinge" damping="0.05" frictionloss="0.1" armature="0.001"/>
          <geom mesh="knob_front_left_vis" type="mesh" solimp="0.998 0.998 0.001" solref="0.001 1" friction="0.95 0.3 0.1" class="visual" material="knob_front_left_material"/>
          <geom class="collision" type="cylinder" pos="-0.30022097 0.25812337 0.48115158" size="0.02481306903064251 0.010621534660458565" quat="0.7071067094802856 0.70710688829422 0.0 0.0" density="0.001"/>
          <geom class="collision" type="box" pos="-0.30009180 0.24537212 0.47713476" size="0.005765819922089577 0.003975167870521545 0.01800193078815937" quat="1.0 0.0 0.0 0.0" name="knob_front_left_main" density="0.001"/>
        </body>
        <body name="knob_front_right">
          <joint axis="0.0 -1.0 0.0" pos="0.30002493 0.26397789 0.48121476" limited="true" name="knob_front_right_joint" range="0.0 3.490658503988659" type="hinge" damping="0.05" frictionloss="0.1" armature="0.001"/>
          <geom mesh="knob_front_right_vis" type="mesh" solimp="0.998 0.998 0.001" solref="0.001 1" friction="0.95 0.3 0.1" class="visual" material="knob_front_right_material"/>
          <geom class="collision" type="cylinder" pos="0.29960778 0.25812337 0.48132321" size="0.02481306903064251 0.010621534660458565" quat="0.7071067094802856 0.70710688829422 0.0 0.0" density="0.001"/>
          <geom class="collision" type="box" pos="0.29987156 0.24537212 0.47735271" size="0.005765827838331461 0.0039751711301505566 0.018001951277256012" quat="1.0 0.0 0.0 0.0" name="knob_front_right_main" density="0.001"/>
        </body>
        <body name="knob_rear_left">
          <joint axis="0.0 -1.0 0.0" pos="-0.17997505 0.26397789 0.48123443" limited="true" name="knob_rear_left_joint" range="0.0 3.490658503988659" type="hinge" damping="0.05" armature="0.001"/>
          <geom mesh="knob_rear_left_vis" type="mesh" solimp="0.998 0.998 0.001" solref="0.001 1" friction="0.95 0.3 0.1" class="visual" material="knob_rear_left_material"/>
          <geom class="collision" type="cylinder" pos="-0.17979206 0.25812337 0.48115158" size="0.02481306903064251 0.010621534660458565" quat="0.7071067094802856 0.70710688829422 0.0 0.0"/>
          <geom class="collision" type="box" pos="-0.18023492 0.24537212 0.47713476" size="0.005765830632299185 0.003975172992795706 0.018001973628997803" quat="1.0 0.0 0.0 0.0" name="knob_rear_left_main"/>
        </body>
        <body name="knob_rear_right">
          <joint axis="0.0 -1.0 0.0" pos="0.18002495 0.26397789 0.48123443" limited="true" name="knob_rear_right_joint" range="0.0 3.490658503988659" type="hinge" damping="0.05" frictionloss="0.1" armature="0.001"/>
          <geom mesh="knob_rear_right_vis" type="mesh" solimp="0.998 0.998 0.001" solref="0.001 1" friction="0.95 0.3 0.1" class="visual" material="knob_rear_right_material"/>
          <geom class="collision" type="cylinder" pos="0.17970701 0.25812337 0.48109198" size="0.02481306903064251 0.010621534660458565" quat="0.7071067094802856 0.70710688829422 0.0 0.0" density="0.001"/>
          <geom class="collision" type="box" pos="0.17995484 0.24537212 0.47735271" size="0.005765838548541069 0.003975176252424717 0.018001994118094444" quat="1.0 0.0 0.0 0.0" name="knob_rear_right_main" density="0.001"/>
        </body>
        <body name="Door001">
          <joint axis="1.0 0.0 0.0" pos="0.00002470 -0.30591324 -0.29060394" limited="true" name="Door001_joint" range="0.0 1.5707963267948966" type="hinge" damping="1" frictionloss="1" armature=".01" stiffness="0.05"/>
          <geom mesh="Door001_vis" type="mesh" solimp="0.998 0.998 0.001" solref="0.001 1" friction="0.95 0.3 0.1" class="visual" material="Door001_material"/>
          <geom class="collision" type="box" pos="-0.00016396 -0.29060730 -0.02252813" size="0.37981483340263367 0.0152989961206913 0.27016061544418335" quat="1.0 0.0 0.0 0.0"/>
          <geom class="collision" type="box" pos="-0.25672275 -0.31927585 0.22760564" size="0.057031355798244476 0.01119912974536419 0.016437169164419174" quat="1.9142196094890096e-07 0.9831273555755615 -0.18292252719402313 -3.5616331217624975e-08"/>
          <geom class="collision" type="box" pos="0.25520575 -0.31996482 0.22760564" size="0.0557350218296051 0.011199130676686764 0.016437169164419174" quat="0.9820809364318848 0.0 0.0 0.1884595900774002"/>
          <geom class="collision" type="box" pos="-0.00219345 -0.34284508 0.22760564" size="0.20576396584510803 0.009586282074451447 0.01643751747906208" quat="1.0 0.0 0.0 0.0"/>
          <geom class="collision" type="box" pos="-0.00011302 -0.29200640 -0.00566677" size="0.3775268495082855 0.010744334198534489 0.14932073652744293" quat="1.0 0.0 0.0 0.0"/>
          <body name="Door001_Clear">
            <geom mesh="Door001_Clear_vis" type="mesh" solimp="0.998 0.998 0.001" solref="0.001 1" friction="0.95 0.3 0.1" class="visual" material="Door001_Clear_material"/>
            <geom class="collision" type="box" pos="-0.00011302 -0.29200640 -0.00566677" size="0.3775268495082855 0.010744334198534489 0.14932073652744293" quat="1.0 0.0 0.0 0.0"/>
          </body>
        </body>
        <body name="Knob001">
          <joint axis="0.0 1.0 0.0" pos="-0.06086761 0.25894112 0.48261145" limited="true" name="Knob001_joint" range="0.0 5.235987755982989" type="hinge" damping="0.05" armature="0.001"/>
          <geom mesh="Knob001_vis" type="mesh" solimp="0.998 0.998 0.001" solref="0.001 1" friction="0.95 0.3 0.1" class="visual" material="Knob001_material"/>
          <geom class="collision" type="cylinder" pos="-0.06157003 0.25812337 0.48248187" size="0.02481306903064251 0.010621534660458565" quat="0.7071067094802856 0.70710688829422 0.0 0.0"/>
          <geom class="collision" type="box" pos="-0.05733858 0.24537212 0.48249927" size="0.018002016469836235 0.003975179977715015 0.005765844136476517" quat="1.0 0.0 0.0 0.0"/>
        </body>
        <body name="Knob002">
          <joint axis="0.0 1.0 0.0" pos="0.06002495 0.26397789 0.48121476" limited="true" name="Knob002_joint" range="0.0 5.585053606381854" type="hinge" damping="0.05" frictionloss="0.1" armature="0.001"/>
          <geom mesh="Knob002_vis" type="mesh" solimp="0.998 0.998 0.001" solref="0.001 1" friction="0.95 0.3 0.1" class="visual" material="Knob002_material"/>
          <geom class="collision" type="cylinder" pos="0.06021304 0.25812337 0.48115158" size="0.02481306903064251 0.010621534660458565" quat="0.7071067094802856 0.70710688829422 0.0 0.0" density="0.001"/>
          <geom class="collision" type="box" pos="0.05986389 0.24485770 0.48577774" size="0.00576584879308939 0.003975181374698877 0.018002035096287727" quat="1.0 0.0 0.0 0.0" density="0.001"/>
        </body>
        <body name="Shelf001">
          <joint axis="0.0 -1.0 0.0" pos="-0.00030982 -0.02778162 -0.02440071" limited="true" name="Shelf001_joint" range="0.0 0.3" type="slide" damping="1" frictionloss="1" armature=".01" stiffness="0.05"/>
          <geom mesh="Shelf001_vis" type="mesh" solimp="0.998 0.998 0.001" solref="0.001 1" friction="0.95 0.3 0.1" class="visual" material="Shelf001_material"/>
          <geom class="collision" type="box" pos="0.00004929 -0.02774362 -0.02444427" size="0.3058905601501465 0.22338691353797913 0.0033582074102014303" quat="1.0 0.0 0.0 0.0"/>
        </body>
        <geom class="region" name="reg_int" type="box" pos="-2.506499999999079e-05 -0.02881033000000001 -0.021701229999999988" size="0.301569235 0.24124599000000002 0.19622017"/>
        <site type="cylinder" rgba="0.5 0 0 0.5" size="0.07591041177511215 0.0001" pos="0.18573228 0.14015998 0.28730112" name="burner_on_rear_right"/>
        <site type="cylinder" rgba="0.5 0 0 0.5" size="0.09568279981613159 0.0001" pos="-0.15299031 0.12825166 0.28730112" name="burner_on_rear_left"/>
        <site type="cylinder" rgba="0.5 0 0 0.5" size="0.12052343785762787 0.0001" pos="0.16929057 -0.14367304 0.28730112" name="burner_on_front_right"/>
        <site type="cylinder" rgba="0.5 0 0 0.5" size="0.09798440337181091 0.0001" pos="-0.17036362 -0.14766781 0.28730112" name="burner_on_front_left"/>
        <site name="burner_rear_right_place_site" type="cylinder" rgba="0.5 0 0 0" size="0.07591041177511215 4.999999873689376e-05" pos="0.18573228 0.14015998 0.28730112"/>
        <site name="burner_rear_left_place_site" type="cylinder" rgba="0.5 0 0 0" size="0.09568279981613159 4.999999873689376e-05" pos="-0.15299031 0.12825166 0.28730112"/>
        <site name="burner_front_right_place_site" type="cylinder" rgba="0.5 0 0 0" size="0.12052343785762787 4.999999873689376e-05" pos="0.16929057 -0.14367304 0.28730112"/>
        <site name="burner_front_left_place_site" type="cylinder" rgba="0.5 0 0 0" size="0.09798440337181091 4.999999873689376e-05" pos="-0.17036362 -0.14766781 0.28730112"/>
        <geom class="region" name="reg_main" type="box" pos="4.999999997368221e-09 0.023042265000000006 -0.13876447000000003" size="0.38168598499999995 0.329948375 0.42865012"/>
      </body>
    </body>
  </worldbody>
  <actuator>
    <motor name="knob_front_left_joint_actuator" joint="knob_front_left_joint" gear="10"/>
    <motor name="knob_front_right_joint_actuator" joint="knob_front_right_joint" gear="10"/>
    <motor name="knob_rear_left_joint_actuator" joint="knob_rear_left_joint" gear="10"/>
    <motor name="knob_rear_right_joint_actuator" joint="knob_rear_right_joint" gear="10"/>
    <motor name="Door001_joint_actuator" joint="Door001_joint" gear="50"/>
    <motor name="Knob001_joint_actuator" joint="Knob001_joint" gear="50"/>
    <motor name="Knob002_joint_actuator" joint="Knob002_joint" gear="50"/>
    <motor name="Shelf001_joint_actuator" joint="Shelf001_joint" gear="50"/>
  </actuator>
</mujoco>
