<?xml version='1.0' encoding='UTF-8'?>
<mujoco model="model">
  <option timestep="0.002" gravity="0.0 0.0 -9.81"/>
  <compiler angle="radian"/>
  <asset>
    <mesh file="visuals/handle.obj" name="handle_vis"/>
    <mesh file="visuals/Body001.obj" name="Body001_vis"/>
    <mesh file="visuals/spout.obj" name="spout_vis"/>
    <texture file="visuals/T_BC001.png" name="Body001_material" type="2d"/>
    <material name="Body001_material" rgba="1 1 1 1.0" texture="Body001_material" shininess="0.4472135901451111" specular="1"/>
    <texture file="visuals/T_BC001.png" name="handle_material" type="2d"/>
    <material name="handle_material" rgba="1 1 1 1.0" texture="handle_material" shininess="0.4472135901451111" specular="1"/>
    <texture file="visuals/T_BC001.png" name="spout_material" type="2d"/>
    <material name="spout_material" rgba="1 1 1 1.0" texture="spout_material" shininess="0.4472135901451111" specular="1"/>
  </asset>
  <default>
    <default class="visual">
      <geom conaffinity="0" contype="0" group="1" type="mesh"/>
    </default>
    <default class="collision">
      <geom group="0" rgba="0.5 0 0 0.5"/>
    </default>
    <default class="spawn">
      <geom group="0" rgba="1 1 1 0.5" contype="0" conaffinity="0"/>
      <site group="0" rgba="1 1 1 0.5"/>
    </default>
    <default class="region">
      <geom group="1" conaffinity="0" contype="0" rgba="0 1 0 0"/>
    </default>
  </default>
  <worldbody>
    <body>
      <body name="object">
        <geom mesh="Body001_vis" type="mesh" solimp="0.998 0.998 0.001" solref="0.001 1" friction="0.95 0.3 0.1" class="visual" material="Body001_material"/>
        <geom class="collision" type="box" pos="0.00061120 -0.22890670 -0.12269893" size="0.3741335868835449 0.024871043860912323 0.13373567163944244" quat="1.0 0.0 0.0 0.0"/>
        <geom class="collision" type="box" pos="0.00000427 0.20345906 -0.12269893" size="0.3747573494911194 0.049860287457704544 0.13373567163944244" quat="1.0 0.0 0.0 0.0"/>
        <geom class="collision" type="box" pos="-0.34692350 -0.02449246 -0.12269893" size="0.027821138501167297 0.1806069165468216 0.13373567163944244" quat="1.0 0.0 0.0 0.0"/>
        <geom class="collision" type="box" pos="0.34695294 -0.02449246 -0.12269893" size="0.027808651328086853 0.1806069165468216 0.13373567163944244" quat="1.0 0.0 0.0 0.0"/>
        <geom class="collision" type="box" pos="-0.02689746 -0.02449246 -0.23388979" size="0.3466249108314514 0.1806069165468216 0.02254481613636017" quat="1.0 0.0 0.0 0.0"/>
        <geom class="collision" type="cylinder" pos="0.00036726 0.20116485 0.04278069" size="0.02263602614402771 0.032472364604473114" quat="1.0 0.0 0.0 0.0"/>
        <geom class="collision" type="cylinder" pos="-0.00213505 0.20116485 0.06126888" size="0.02263602614402771 0.04693588986992836" quat="0.7071068286895752 -0.0 0.7071067690849304 0.0"/>
        <body name="handle">
          <joint axis="1.0 0.0 0.0" pos="0.06563651 0.20115647 0.06166259" limited="true" name="handle_temp_joint" type="hinge" range="-0.7853981633974483 0.7853981633974483" damping="1" frictionloss="1" armature=".01" stiffness="0.05"/>
          <joint axis="0.0 1.0 0.0" pos="0.06563651 0.20115647 0.06166259" limited="true" name="handle_joint" type="hinge" range="0 0.5" damping="1" frictionloss="1" armature=".01" stiffness="0.05"/>
          <geom mesh="handle_vis" type="mesh" solimp="0.998 0.998 0.001" solref="0.001 1" friction="0.95 0.3 0.1" class="visual" material="handle_material"/>
          <geom class="collision" type="cylinder" pos="0.07423763 0.20167435 0.11034441" size="0.0038201643619686365 0.027743283659219742" quat="1.0 0.0 0.0 0.0"/>
          <geom class="collision" type="cylinder" pos="0.06847246 0.20116485 0.06126888" size="0.02263602614402771 0.011875688098371029" quat="0.7071068286895752 -0.0 0.7071067690849304 0.0"/>
        </body>
        <body name="spout">
          <joint axis="0.0 0.0 1.0" pos="0.00041697 0.20115916 0.16729961" limited="true" name="spout_joint" range="-1.0471975511965976 1.0471975511965976" type="hinge" damping="1" frictionloss="1" armature=".01" stiffness="0.05"/>
          <site type="cylinder" rgba="0.5 0.75 1 0.5" size="0.006101064383983612 0.2378060519695282" pos="0.00040024 -0.00089565 -0.01125450" name="water"/>
          <geom mesh="spout_vis" type="mesh" solimp="0.998 0.998 0.001" solref="0.001 1" friction="0.95 0.3 0.1" class="visual" material="spout_material"/>
          <geom class="collision" type="cylinder" pos="0.00061748 0.20096052 0.14449674" size="0.012858516536653042 0.05865353345870972" quat="1.0 0.0 0.0 0.0"/>
          <geom class="collision" type="cylinder" pos="0.00042598 -0.00100528 0.23272023" size="0.009285930544137955 0.0064205266535282135" quat="1.0 0.0 0.0 0.0"/>
          <geom class="collision" type="cylinder" pos="0.00061748 0.19846044 0.21308295" size="0.012858516536653042 0.024497203528881073" quat="0.9920640587806702 0.12573324143886566 0.0 0.0"/>
          <geom class="collision" type="cylinder" pos="0.00061748 0.18844990 0.22989763" size="0.012858516536653042 0.024497203528881073" quat="0.9472011923789978 0.32063984870910645 0.0 0.0"/>
          <geom class="collision" type="cylinder" pos="0.00061748 0.16745245 0.24358638" size="0.012858516536653042 0.024497203528881073" quat="0.8263651132583618 0.5631347298622131 0.0 0.0"/>
          <geom class="collision" type="cylinder" pos="0.00061748 0.06914715 0.24813132" size="0.012858516536653042 0.09095170348882675" quat="0.7071067094802856 0.7071068286895752 0.0 0.0" name="spout_main"/>
        </body>
        <geom class="region" name="reg_basin" type="box" pos="0.0016593000000000024 -0.025191919999999993 -0.09573013" size="0.30364553000000005 0.16539562000000002 0.10582021999999999"/>
        <geom class="region" name="reg_main" type="box" pos="4.249999999983434e-06 -2.000000001722846e-08 -0.12390533" size="0.37575735 0.25477774 0.13661107"/>
      </body>
    </body>
  </worldbody>
  <actuator>
    <motor name="handle_joint_actuator" joint="handle_joint" gear="10"/>
    <motor name="handle_temp_joint_actuator" joint="handle_temp_joint" gear="10"/>
    <motor name="spout_joint_actuator" joint="spout_joint" gear="10"/>
  </actuator>
</mujoco>
