<?xml version='1.0' encoding='UTF-8'?>
<mujoco model="model">
  <option timestep="0.002" gravity="0.0 0.0 -9.81"/>
  <compiler angle="radian"/>
  <asset>
    <mesh file="visuals/button_lid.obj" name="button_lid_vis"/>
    <mesh file="visuals/Body001.obj" name="Body001_vis"/>
    <mesh file="visuals/kettle_main.obj" name="kettle_main_vis"/>
    <mesh file="visuals/lid.obj" name="lid_vis"/>
    <mesh file="visuals/switch.obj" name="switch_vis"/>
    <texture file="visuals/T_BC001.png" name="Body001_material" type="2d"/>
    <material name="Body001_material" rgba="1 1 1 1.0" texture="Body001_material" shininess="0.5" specular="0.3103448502657381"/>
    <texture file="visuals/T_BC001.png" name="kettle_main_material" type="2d"/>
    <material name="kettle_main_material" rgba="1 1 1 1.0" texture="kettle_main_material" shininess="0.5" specular="0.3103448502657381"/>
    <texture file="visuals/T_BC001.png" name="button_lid_material" type="2d"/>
    <material name="button_lid_material" rgba="1 1 1 1.0" texture="button_lid_material" shininess="0.5" specular="0.3103448502657381"/>
    <texture file="visuals/T_BC001.png" name="lid_material" type="2d"/>
    <material name="lid_material" rgba="1 1 1 1.0" texture="lid_material" shininess="0.5" specular="0.3103448502657381"/>
    <texture file="visuals/T_BC001.png" name="switch_material" type="2d"/>
    <material name="switch_material" rgba="1 1 1 1.0" texture="switch_material" shininess="0.5" specular="0.3103448502657381"/>
  </asset>
  <default>
    <default class="visual">
      <geom conaffinity="0" contype="0" group="1" type="mesh"/>
    </default>
    <default class="collision">
      <geom group="0" rgba="0.5 0 0 0.5"/>
    </default>
    <default class="spawn">
      <geom group="0" rgba="1 1 1 0.5" contype="0" conaffinity="0"/>
      <site group="0" rgba="1 1 1 0.5"/>
    </default>
    <default class="region">
      <geom group="1" conaffinity="0" contype="0" rgba="0 1 0 0" mass="0"/>
    </default>
  </default>
  <worldbody>
    <body>
      <body name="object">
        <geom mesh="Body001_vis" type="mesh" solimp="0.998 0.998 0.001" solref="0.001 1" friction="0.95 0.3 0.1" class="visual" material="Body001_material"/>
        <geom type="cylinder" pos="-0.01963663 -0.00000150 -0.10121969" size="0.0678660050034523 0.007532762363553047" quat="1.0 0.0 0.0 0.0" class="collision"/>
        <body name="kettle_main">
          <!-- <joint axis="0.0 0.0 1.0" pos="0.00000012 -0.00000022 0.00643535" limited="true" name="kettle_main_joint" range="0.0 0.07" type="slide" damping="1" frictionloss="1" armature=".01" stiffness="0.05"></joint> -->
          <geom mesh="kettle_main_vis" type="mesh" solimp="0.998 0.998 0.001" solref="0.001 1" friction="0.95 0.3 0.1" class="visual" material="kettle_main_material"/>
          <geom type="box" pos="-0.02087512 -0.06376910 0.00322897" size="0.007380795199424028 0.0054064602591097355 0.09264536201953888" quat="0.9999023079872131 -0.013977143913507462 -3.1035493982550703e-18 -1.4061116286136606e-24" class="collision"/>
          <geom type="box" pos="-0.00656249 -0.06215614 0.00322897" size="0.007380795665085316 0.005406459793448448 0.09264536201953888" quat="0.9936127662658691 -0.013889258727431297 -0.0015652369474992156 0.11197458952665329" class="collision"/>
          <geom type="box" pos="0.00790842 -0.05696791 0.00322897" size="0.007380795199424028 0.005406459793448448 0.09264536201953888" quat="0.9731060862541199 -0.013602576218545437 -0.003214121563360095 0.2299330085515976" class="collision"/>
          <geom type="box" pos="0.02078675 -0.04844906 0.00322897" size="0.007380795665085316 0.005406459793448448 0.09264536201953888" quat="0.9384636878967285 -0.013118329457938671 -0.0048239147290587425 0.3450949788093567" class="collision"/>
          <geom type="box" pos="0.03134342 -0.03699463 0.00322897" size="0.007380795199424028 0.005406459793448448 0.09264536201953888" quat="0.8897600769996643 -0.01243752334266901 -0.0063772015273571014 0.4562145173549652" class="collision"/>
          <geom type="box" pos="0.03876090 -0.02352557 0.00322897" size="0.007380795199424028 0.0054064602591097355 0.09264536201953888" quat="0.8288372159004211 -0.011585910804569721 -0.007818393409252167 0.5593152046203613" class="collision"/>
          <geom type="box" pos="0.04287180 -0.00794036 0.00322897" size="0.007380795665085316 0.0054064602591097355 0.09264536201953888" quat="0.7522096037864685 -0.010514771565794945 -0.00920870155096054 0.6587756276130676" class="collision"/>
          <geom type="box" pos="0.04299569 0.00802888 0.00322897" size="0.007380795665085316 0.005406459793448448 0.09264536201953888" quat="0.6645917892456055 -0.009290005080401897 -0.010443010367453098 0.7470759153366089" class="collision"/>
          <geom type="box" pos="0.03929050 0.02324776 0.00322897" size="0.007380794733762741 0.005406459793448448 0.09264536201953888" quat="0.568663477897644 -0.007949069142341614 -0.01149665005505085 0.8224515318870544" class="collision"/>
          <geom type="box" pos="0.03199303 0.03715262 0.00322897" size="0.007380795199424028 0.005406459793448448 0.09264536201953888" quat="0.4639919400215149 -0.0064859166741371155 -0.012381174601614475 0.8857291340827942" class="collision"/>
          <geom type="box" pos="0.02153089 0.04813135 0.00321319" size="0.007380795665085316 0.0059713320806622505 0.09264536201953888" quat="0.3559047281742096 -0.004975018557161093 -0.013061768375337124 0.934417724609375" class="collision"/>
          <geom type="box" pos="0.00928302 0.05679626 0.00321562" size="0.007380795199424028 0.0058844005689024925 0.09264536201953888" quat="0.24354730546474457 -0.003404434537515044 -0.013556244783103466 0.9697883129119873" class="collision"/>
          <geom type="box" pos="-0.00363009 0.06184334 0.00321150" size="0.007380795199424028 0.006031757686287165 0.09264536201953888" quat="0.13666599988937378 -0.0019103848608210683 -0.013845977373421192 0.9905185699462891" class="collision"/>
          <geom type="box" pos="-0.01769310 0.06411692 0.00321076" size="0.007380795199424028 0.006057980004698038 0.09264536947011948" quat="0.024998819455504417 -0.0003494487318675965 -0.013972951099276543 0.999589741230011" class="collision"/>
          <geom type="box" pos="-0.03177633 0.06309588 0.00320635" size="0.007380795199424028 0.006215929519385099 0.09264536947011948" quat="0.086149200797081 -0.0012042474700137973 0.013925346545875072 -0.9961841702461243" class="collision"/>
          <geom type="box" pos="-0.04521403 0.05893726 0.00319985" size="0.007380795199424028 0.006448398344218731 0.09264536201953888" quat="0.19614286720752716 -0.002741793403401971 0.013705610297620296 -0.9804757237434387" class="collision"/>
          <geom type="box" pos="-0.05743031 0.05216316 0.00319954" size="0.007380795199424028 0.00645945779979229 0.09264536201953888" quat="0.3031933009624481 -0.0042381915263831615 0.013319101184606552 -0.9528265595436096" class="collision"/>
          <geom type="box" pos="-0.06796989 0.04266269 0.00319755" size="0.007380795199424028 0.006530726794153452 0.09264536201953888" quat="0.4082055687904358 -0.005706107243895531 0.012759349308907986 -0.9127830266952515" class="collision"/>
          <geom type="box" pos="-0.07619869 0.03071164 0.00319285" size="0.007380795665085316 0.006699009332805872 0.09264536947011948" quat="0.5104392170906067 -0.007135199382901192 0.012018783949315548 -0.8598002791404724" class="collision"/>
          <geom type="box" pos="-0.08181117 0.01760569 0.00320024" size="0.007380795199424028 0.006434462033212185 0.09264536201953888" quat="0.6042205095291138 -0.008446104824543 0.011136606335639954 -0.7966945767402649" class="collision"/>
          <geom type="box" pos="-0.08409280 0.00313092 0.00319996" size="0.007380795199424028 0.006444517057389021 0.09264536201953888" quat="0.6924059987068176 -0.009678809903562069 0.010083721950650215 -0.7213727235794067" class="collision"/>
          <geom type="box" pos="-0.08285781 -0.01223680 0.00320038" size="0.007380795199424028 0.006429573055356741 0.09264536201953888" quat="0.7751274108886719 -0.0108351344242692 0.008829537779092789 -0.6316503286361694" class="collision"/>
          <geom type="box" pos="-0.07813482 -0.02686919 0.00320585" size="0.007380795199424028 0.0062337275594472885 0.09264536201953888" quat="0.8460131287574768 -0.01182600762695074 0.007450282573699951 -0.5329788327217102" class="collision"/>
          <geom type="box" pos="-0.06967236 -0.04037807 0.00321146" size="0.007380795199424028 0.006033082026988268 0.09264536201953888" quat="0.9061471819877625 -0.012666638940572739 0.005909170024096966 -0.42273157835006714" class="collision"/>
          <geom type="box" pos="-0.05859156 -0.05070016 0.00320984" size="0.007380795665085316 0.00609113834798336 0.09264536201953888" quat="0.9499987959861755 -0.013279573060572147 0.004360465332865715 -0.3119405210018158" class="collision"/>
          <geom type="box" pos="-0.04659072 -0.05794753 0.00321729" size="0.007380795199424028 0.005824490915983915 0.09264536201953888" quat="0.9785315990447998 -0.013678422197699547 0.0028742935974150896 -0.20562231540679932" class="collision"/>
          <geom type="box" pos="-0.03276167 -0.06244633 0.00322308" size="0.007380795199424028 0.0056175231002271175 0.09264536201953888" quat="0.9955569505691528 -0.013916447758674622 0.0013016596203669906 -0.09311829507350922" class="collision"/>
          <geom class="collision" type="box" pos="0.08776807 -0.00147141 0.02186287" size="0.009237316437065601 0.015317178331315517 0.06579349935054779" quat="1.0 0.0 0.0 0.0" name="handle_main"/>
          <geom class="collision" type="box" pos="0.06298625 -0.00147141 0.09452881" size="0.010538110509514809 0.015317178331315517 0.011243673972785473" quat="1.0 0.0 0.0 0.0" name="handle_5"/>
          <geom class="collision" type="box" pos="0.06792432 -0.00147141 -0.03491029" size="0.027031200006604195 0.015317169018089771 0.011243658140301704" quat="1.0 0.0 0.0 0.0" name="handle_1"/>
          <geom type="cylinder" pos="-0.02009697 -0.00047915 -0.08354763" size="0.06749360263347626 0.009196448139846325" quat="1.0 0.0 0.0 0.0" class="collision"/>
          <geom class="collision" type="box" pos="0.07944489 -0.01258445 0.09029644" size="0.014087814837694168 0.004204140044748783 0.01446246076375246" quat="1.0 0.0 0.0 0.0" name="handle_2"/>
          <geom class="collision" type="box" pos="0.09331013 -0.00227200 0.09114254" size="0.004896302707493305 0.014516595751047134 0.0037182148080319166" quat="0.9207598567008972 1.8260609445033696e-15 0.39012986421585083 5.241738776362581e-08" name="handle_3"/>
          <geom class="collision" type="box" pos="0.07944489 0.00935461 0.09029644" size="0.014087814837694168 0.004204140044748783 0.014462457969784737" quat="1.0 0.0 0.0 0.0" name="handle_4"/>
          <body name="button_lid">
            <joint axis="0.0 0.0 -1.0" pos="0.08168490 -0.00169983 0.09894308" limited="true" name="button_lid_joint" range="0.0 0.003" type="slide" damping="1" frictionloss="1" armature=".01" stiffness="1" springref="-0.5"/>
            <geom mesh="button_lid_vis" type="mesh" solimp="0.998 0.998 0.001" solref="0.001 1" friction="0.95 0.3 0.1" class="visual" material="button_lid_material"/>
            <geom class="collision" type="box" pos="0.08183561 -0.00147141 0.09907814" size="0.00587012292817235 0.006037034559994936 0.004397301468998194" quat="1.0 0.0 0.0 0.0" name="button_lid_main"/>
          </body>
          <body name="lid">
            <joint axis="0.0 1.0 0.0" pos="0.04942624 -0.00000037 0.10557619" limited="true" name="lid_joint" range="0.0 1.5707963267948966" type="hinge" damping="1" frictionloss="1" armature=".01" stiffness="0.05"/>
            <geom mesh="lid_vis" type="mesh" solimp="0.998 0.998 0.001" solref="0.001 1" friction="0.95 0.3 0.1" class="visual" material="lid_material"/>
            <geom class="collision" type="cylinder" pos="-0.02030399 -0.00000150 0.10326352" size="0.06299818307161331 0.005698506720364094" quat="1.0 0.0 0.0 0.0" name="lid_main"/>
          </body>
          <body name="switch">
            <joint axis="0.0 0.0 -1.0" pos="0.06325139 -0.00011485 -0.07238925" limited="true" name="switch_joint" range="0.0 0.001" type="slide" damping="1" frictionloss="1" armature=".01" stiffness="1" springref="-0.5"/>
            <geom mesh="switch_vis" type="mesh" solimp="0.998 0.998 0.001" solref="0.001 1" friction="0.95 0.3 0.1" class="visual" material="switch_material"/>
            <geom class="collision" type="box" pos="0.06869783 -0.00007649 -0.07203325" size="0.014857431873679161 0.008279125206172466 0.0039036166854202747" quat="1.0 0.0 0.0 0.0" name="switch_main"/>
          </body>
        </body>
        <geom class="region" name="reg_main" type="box" pos="1.2500000000359446e-07 -2.1999999999522402e-07 5.000000004307115e-09" size="0.098138345 0.06866772 0.11040140500000001"/>
      </body>
    </body>
  </worldbody>
  <actuator>
    <!-- <motor name="kettle_main_joint_actuator" joint="kettle_main_joint" gear="10"/> -->
    <motor name="button_lid_joint_actuator" joint="button_lid_joint" gear="50"/>
    <motor name="lid_joint_actuator" joint="lid_joint" gear="0.5"/>
    <motor name="switch_joint_actuator" joint="switch_joint" gear="50"/>
  </actuator>
</mujoco>