<?xml version='1.0' encoding='UTF-8'?>
<mujoco model="model">
  <option timestep="0.002" gravity="0.0 0.0 -9.81"/>
  <compiler angle="radian"/>
  <asset>
    <mesh file="visuals/handle.obj" name="handle_vis"/>
    <mesh file="visuals/Body001.obj" name="Body001_vis"/>
    <mesh file="visuals/Container001.obj" name="Container001_vis"/>
    <mesh file="visuals/spout.obj" name="spout_vis"/>
    <texture file="visuals/T_BC001.png" name="Body001_material" type="2d"/>
    <material name="Body001_material" rgba="1 1 1 1.0" texture="Body001_material" shininess="0.4472135901451111" specular="2"/>
    <texture file="visuals/T_BC001.png" name="handle_material" type="2d"/>
    <material name="handle_material" rgba="1 1 1 1.0" texture="handle_material" shininess="0.4472135901451111" specular="2"/>
    <texture file="visuals/T_BC001.png" name="Container001_material" type="2d"/>
    <material name="Container001_material" rgba="1 1 1 1.0" texture="Container001_material" shininess="0.4472135901451111" specular="2"/>
    <texture file="visuals/T_BC001.png" name="spout_material" type="2d"/>
    <material name="spout_material" rgba="1 1 1 1.0" texture="spout_material" shininess="0.4472135901451111" specular="2"/>
  </asset>
  <default>
    <default class="visual">
      <geom conaffinity="0" contype="0" group="1" type="mesh"/>
    </default>
    <default class="collision">
      <geom group="0" rgba="0.5 0 0 0.5" solimp="0.998 0.998 0.001" solref="0.001 2"/>
    </default>
    <default class="spawn">
      <geom group="0" rgba="1 1 1 0.5" contype="0" conaffinity="0"/>
      <site group="0" rgba="1 1 1 0.5"/>
    </default>
    <default class="region">
      <geom group="1" conaffinity="0" contype="0" rgba="0 1 0 0"/>
    </default>
  </default>
  <worldbody>
    <body>
      <body name="object">
        <geom mesh="Body001_vis" type="mesh" solimp="0.998 0.998 0.001" solref="0.001 1" friction="0.95 0.3 0.1" class="visual" material="Body001_material"/>
        <geom class="collision" type="box" pos="-0.09733528 0.24096072 -0.09907246" size="0.3727695345878601 0.017321495339274406 0.12300393730401993" quat="0.9990482330322266 -0.04361938312649727 -0.0 0.0"/>
        <geom class="collision" type="box" pos="-0.09957722 -0.23244750 -0.09654858" size="0.37052756547927856 0.007144593633711338 0.12283506244421005" quat="0.9987403750419617 0.05017663910984993 0.0 0.0"/>
        <geom class="collision" type="box" pos="0.00122067 0.00568839 -0.09344882" size="0.024436986073851585 0.23936474323272705 0.11840010434389114" quat="1.0 0.0 0.0 0.0"/>
        <geom class="collision" type="box" pos="-0.45927498 0.00568839 -0.09785312" size="0.23936714231967926 0.009068615734577179 0.12248902767896652" quat="0.7063643336296082 0.03239481896162033 -0.032394833862781525 -0.7063643336296082"/>
        <geom class="collision" type="box" pos="0.46855363 0.00568839 -0.09967011" size="0.23936714231967926 0.012515637092292309 0.1218361184000969" quat="0.7064337730407715 -0.030843568965792656 0.030843574553728104 -0.7064337730407715"/>
        <geom class="collision" type="box" pos="-0.24464411 0.00071127 -0.21517713" size="0.19713054597377777 0.22159570455551147 0.005509738810360432" quat="1.0 0.0 0.0 0.0"/>
        <geom class="collision" type="box" pos="0.24296237 0.00071127 -0.21532134" size="0.19713057577610016 0.22159630060195923 0.005365563090890646" quat="1.0 0.0 0.0 0.0"/>
        <geom class="collision" type="box" pos="0.35772776 -0.23268879 -0.09557176" size="0.08612968027591705 0.007468333933502436 0.12335024029016495" quat="0.998741865158081 0.05014668405056 0.0 0.0"/>
        <geom class="collision" type="box" pos="0.37909644 0.24140606 -0.09870375" size="0.1026066467165947 0.015348780900239944 0.12289652973413467" quat="0.9984838366508484 -0.05504579097032547 -0.0 0.0"/>
        <geom class="collision" type="cylinder" pos="0.00231999 0.24574796 0.06544980" size="0.02263527922332287 0.04246450588107109" quat="1.0 0.0 0.0 0.0"/>
        <geom class="collision" type="box" pos="-0.03465817 0.00568839 -0.09685095" size="0.008054555393755436 0.239366352558136 0.122091144323349" quat="0.9988089203834534 0.0 0.04879241809248924 0.0"/>
        <geom class="collision" type="box" pos="0.03096597 0.00568839 -0.09618440" size="0.006487147882580757 0.239366352558136 0.1191689521074295" quat="0.9994208216667175 0.0 -0.03402908891439438 0.0"/>
        <geom class="collision" type="box" pos="0.00135944 0.00071127 -0.21735723" size="0.07363183796405792 0.2215971201658249 0.0020765289664268494" quat="1.0 0.0 0.0 0.0"/>
        <geom class="collision" type="cylinder" pos="-0.24127152 0.09563573 -0.26658598" size="0.025850877165794373 0.016773579642176628" quat="1.0 0.0 0.0 0.0"/>
        <geom class="collision" type="cylinder" pos="0.24527887 0.09563573 -0.26658595" size="0.025850877165794373 0.016773564741015434" quat="1.0 0.0 0.0 0.0"/>
        <geom class="collision" type="box" pos="0.45742267 -0.23183293 -0.08318435" size="0.017486345022916794 0.012020817957818508 0.10824259370565414" quat="0.992235541343689 0.046697646379470825 0.00944522861391306 0.1148858293890953"/>
        <geom class="collision" type="box" pos="0.00100972 -0.25945828 0.02275396" size="0.49104830622673035 0.01011129654943943 0.0021978430449962616" quat="1.0 0.0 0.0 0.0"/>
        <geom class="collision" type="box" pos="-0.48246855 -0.00231883 0.02275398" size="0.010111317038536072 0.26331180334091187 0.0021978600416332483" quat="1.0 0.0 0.0 0.0"/>
        <geom class="collision" type="box" pos="0.48481404 -0.00231883 0.02275398" size="0.011485403403639793 0.26331183314323425 0.0021978600416332483" quat="1.0 0.0 0.0 0.0"/>
        <geom class="collision" type="box" pos="-0.19974374 0.08528299 -0.23693524" size="0.001313244691118598 0.0054823001846671104 0.020730527117848396" quat="0.8857115507125854 0.09684006124734879 0.40027427673339844 -0.21428391337394714"/>
        <geom class="collision" type="box" pos="-0.20404023 0.07510709 -0.23693524" size="0.001313244691118598 0.0054823001846671104 0.020730527117848396" quat="0.8625609874725342 0.13283111155033112 0.3898119330406189 -0.29392358660697937"/>
        <geom class="collision" type="box" pos="-0.21218096 0.06572265 -0.23693524" size="0.001313244691118598 0.0054823001846671104 0.020730527117848396" quat="0.8553867936134338 0.14199042320251465 0.3865698277950287 -0.3141908645629883"/>
        <geom class="collision" type="box" pos="-0.21851263 0.05916485 -0.23693524" size="0.001313244691118598 0.0054823001846671104 0.020730527117848396" quat="0.823074221611023 0.17674292623996735 0.3719668984413147 -0.3910899758338928"/>
        <geom class="collision" type="box" pos="-0.23762072 0.05396383 -0.23693524" size="0.001313244691118598 0.0054823001846671104 0.020730527117848396" quat="0.6984293460845947 0.26451992988586426 0.31563693284988403 -0.5853195190429688"/>
        <geom class="collision" type="box" pos="-0.22642723 0.05532062 -0.23693524" size="0.001313244691118598 0.0054823001846671104 0.020730527117848396" quat="0.7480040788650513 0.23521433770656586 0.33804091811180115 -0.520473301410675"/>
        <geom class="collision" type="box" pos="-0.23183302 0.13735502 -0.23693524" size="0.001313244691118598 0.0054823001846671104 0.020730527117848396" quat="0.7815460562705994 -0.21177266538143158 0.35319942235946655 0.4686024785041809"/>
        <geom class="collision" type="box" pos="-0.22172635 0.13289804 -0.23693524" size="0.001313244691118598 0.0054823001846671104 0.020730527117848396" quat="0.8209136128425598 -0.1787833571434021 0.370990514755249 0.39560505747795105"/>
        <geom class="collision" type="box" pos="-0.21247191 0.12460986 -0.23693524" size="0.001313244691118598 0.0054823001846671104 0.020730527117848396" quat="0.8300180435180664 -0.169981449842453 0.37510499358177185 0.37612849473953247"/>
        <geom class="collision" type="box" pos="-0.20601512 0.11817522 -0.23693524" size="0.001313244691118598 0.0054823001846671104 0.020730527117848396" quat="0.860933244228363 -0.1349705010652542 0.38907670974731445 0.2986573278903961"/>
        <geom class="collision" type="box" pos="-0.20111709 0.09898723 -0.23693524" size="0.001313244691118598 0.0054823001846671104 0.020730527117848396" quat="0.9083518981933594 -0.03289860486984253 0.4105059504508972 0.07279683649539948"/>
        <geom class="collision" type="box" pos="-0.20229659 0.11020078 -0.23693524" size="0.001313244691118598 0.005482300650328398 0.020730527117848396" quat="0.8981937766075134 -0.0695001408457756 0.405915230512619 0.15378731489181519"/>
        <geom class="collision" type="box" pos="-0.28353671 0.10672168 -0.23693524" size="0.001313244691118598 0.0054823001846671104 0.020730527117848396" quat="0.21711264550685883 -0.39996278285980225 0.09811841696500778 0.8850224018096924"/>
        <geom class="collision" type="box" pos="-0.27917526 0.11686996 -0.23693524" size="0.001313244691118598 0.0054823001846671104 0.020730527117848396" quat="0.2966778874397278 -0.38938552141189575 0.1340758055448532 0.8616175651550293"/>
        <geom class="collision" type="box" pos="-0.27097473 0.12620216 -0.23693524" size="0.001313244691118598 0.0054823001846671104 0.020730527117848396" quat="0.31692206859588623 -0.3861141502857208 0.14322467148303986 0.8543787002563477"/>
        <geom class="collision" type="box" pos="-0.26460130 0.13271937 -0.23693524" size="0.0013132448075339198 0.0054823001846671104 0.020730527117848396" quat="0.3937176465988159 -0.37140023708343506 0.17793041467666626 0.8218205571174622"/>
        <geom class="collision" type="box" pos="-0.24546037 0.13779820 -0.23693524" size="0.0013132448075339198 0.0054823001846671104 0.020730527117848396" quat="0.5875478386878967 -0.3147902488708496 0.2655269205570221 0.6965559124946594"/>
        <geom class="collision" type="box" pos="-0.25666228 0.13651296 -0.23693524" size="0.001313244691118598 0.0054823001846671104 0.020730527117848396" quat="0.5228604674339294 -0.33728769421577454 0.23629315197467804 0.7463374137878418"/>
        <geom class="collision" type="box" pos="-0.25409684 0.05458775 -0.23693524" size="0.001313244691118598 0.0054823001846671104 0.020730527117848396" quat="0.4672184884548187 0.35357359051704407 0.21114712953567505 -0.7823742628097534"/>
        <geom class="collision" type="box" pos="-0.26418767 0.05908049 -0.23693524" size="0.001313244691118598 0.0054823001846671104 0.020730527117848396" quat="0.3941517472267151 0.37130630016326904 0.17812657356262207 -0.8216124176979065"/>
        <geom class="collision" type="box" pos="-0.27341268 0.06740139 -0.23693524" size="0.001313244691118598 0.0054823001846671104 0.020730527117848396" quat="0.37465900182724 0.3754052221775055 0.1693173348903656 -0.8306823372840881"/>
        <geom class="collision" type="box" pos="-0.27984670 0.07385883 -0.23693524" size="0.001313244691118598 0.0054823001846671104 0.020730527117848396" quat="0.297132670879364 0.3893146216869354 0.13428127765655518 -0.8614608645439148"/>
        <geom class="collision" type="box" pos="-0.28467677 0.09306404 -0.23693524" size="0.001313244691118598 0.0054823001846671104 0.020730527117848396" quat="0.0711892694234848 0.41056355834007263 0.03217211365699768 -0.9084792733192444"/>
        <geom class="collision" type="box" pos="-0.28353695 0.08184639 -0.23693524" size="0.001313244691118598 0.0054823001846671104 0.020730527117848396" quat="0.15219734609127045 0.4060375392436981 0.06878159195184708 -0.898464560508728"/>
        <geom class="collision" type="box" pos="-0.24519611 0.05192865 -0.23693524" size="0.001313244691118598 0.0054823001846671104 0.020730527117848396" quat="0.5495147109031677 0.3285198509693146 0.24833880364894867 -0.7269361615180969"/>
        <geom class="collision" type="box" pos="-0.23680789 0.14040779 -0.23693524" size="0.0013132448075339198 0.005482300650328398 0.020730527117848396" quat="0.6244293451309204 -0.29993945360183716 0.2821945548057556 0.6636946201324463"/>
        <geom class="collision" type="box" pos="-0.28602413 0.10152066 -0.23693524" size="0.0013132448075339198 0.0054823001846671104 0.020730527117848396" quat="0.039065562188625336 -0.4114435017108917 0.01765468530356884 0.9104264974594116"/>
        <geom class="collision" type="box" pos="-0.19838696 0.09082320 -0.23693524" size="0.0013132448075339198 0.0054823001846671104 0.020730527117848396" quat="0.9110049605369568 -0.009822927415370941 0.41170498728752136 0.02173585072159767"/>
        <geom class="collision" type="box" pos="0.28803825 0.08528299 -0.23693524" size="0.001313244691118598 0.0054823001846671104 0.020730527117848396" quat="0.8857115507125854 0.09684006124734879 0.40027427673339844 -0.21428391337394714"/>
        <geom class="collision" type="box" pos="0.28374174 0.07510709 -0.23693524" size="0.001313244691118598 0.0054823001846671104 0.020730527117848396" quat="0.8625609874725342 0.13283111155033112 0.3898119330406189 -0.29392358660697937"/>
        <geom class="collision" type="box" pos="0.27560102 0.06572265 -0.23693524" size="0.001313244691118598 0.0054823001846671104 0.020730527117848396" quat="0.8553867936134338 0.14199042320251465 0.3865698277950287 -0.3141908645629883"/>
        <geom class="collision" type="box" pos="0.26926934 0.05916485 -0.23693524" size="0.001313244691118598 0.0054823001846671104 0.020730527117848396" quat="0.823074221611023 0.17674292623996735 0.3719668984413147 -0.3910899758338928"/>
        <geom class="collision" type="box" pos="0.25016126 0.05396383 -0.23693524" size="0.001313244691118598 0.0054823001846671104 0.020730527117848396" quat="0.6984293460845947 0.26451992988586426 0.31563693284988403 -0.5853195190429688"/>
        <geom class="collision" type="box" pos="0.26135474 0.05532062 -0.23693524" size="0.001313244691118598 0.0054823001846671104 0.020730527117848396" quat="0.7480040788650513 0.23521433770656586 0.33804091811180115 -0.520473301410675"/>
        <geom class="collision" type="box" pos="0.25594896 0.13735502 -0.23693524" size="0.001313244691118598 0.0054823001846671104 0.020730527117848396" quat="0.7815460562705994 -0.21177266538143158 0.35319942235946655 0.4686024785041809"/>
        <geom class="collision" type="box" pos="0.26605564 0.13289804 -0.23693524" size="0.001313244691118598 0.0054823001846671104 0.020730527117848396" quat="0.8209136128425598 -0.1787833571434021 0.370990514755249 0.39560505747795105"/>
        <geom class="collision" type="box" pos="0.27531006 0.12460986 -0.23693524" size="0.001313244691118598 0.0054823001846671104 0.020730527117848396" quat="0.8300180435180664 -0.169981449842453 0.37510499358177185 0.37612849473953247"/>
        <geom class="collision" type="box" pos="0.28176686 0.11817522 -0.23693524" size="0.001313244691118598 0.0054823001846671104 0.020730527117848396" quat="0.860933244228363 -0.1349705010652542 0.38907670974731445 0.2986573278903961"/>
        <geom class="collision" type="box" pos="0.28666490 0.09898723 -0.23693524" size="0.001313244691118598 0.0054823001846671104 0.020730527117848396" quat="0.9083518981933594 -0.03289860486984253 0.4105059504508972 0.07279683649539948"/>
        <geom class="collision" type="box" pos="0.28548538 0.11020078 -0.23693524" size="0.001313244691118598 0.005482300650328398 0.020730527117848396" quat="0.8981937766075134 -0.0695001408457756 0.405915230512619 0.15378731489181519"/>
        <geom class="collision" type="box" pos="0.20424526 0.10672168 -0.23693524" size="0.001313244691118598 0.0054823001846671104 0.020730527117848396" quat="0.21711264550685883 -0.39996278285980225 0.09811841696500778 0.8850224018096924"/>
        <geom class="collision" type="box" pos="0.20860671 0.11686996 -0.23693524" size="0.001313244691118598 0.0054823001846671104 0.020730527117848396" quat="0.2966778874397278 -0.38938552141189575 0.1340758055448532 0.8616175651550293"/>
        <geom class="collision" type="box" pos="0.21680724 0.12620216 -0.23693524" size="0.001313244691118598 0.0054823001846671104 0.020730527117848396" quat="0.31692206859588623 -0.3861141502857208 0.14322467148303986 0.8543787002563477"/>
        <geom class="collision" type="box" pos="0.22318068 0.13271937 -0.23693524" size="0.0013132448075339198 0.0054823001846671104 0.020730527117848396" quat="0.3937176465988159 -0.37140023708343506 0.17793041467666626 0.8218205571174622"/>
        <geom class="collision" type="box" pos="0.24232161 0.13779820 -0.23693524" size="0.0013132448075339198 0.0054823001846671104 0.020730527117848396" quat="0.5875478386878967 -0.3147902488708496 0.2655269205570221 0.6965559124946594"/>
        <geom class="collision" type="box" pos="0.23111969 0.13651296 -0.23693524" size="0.001313244691118598 0.0054823001846671104 0.020730527117848396" quat="0.5228604674339294 -0.33728769421577454 0.23629315197467804 0.7463374137878418"/>
        <geom class="collision" type="box" pos="0.23368513 0.05458775 -0.23693524" size="0.001313244691118598 0.0054823001846671104 0.020730527117848396" quat="0.4672184884548187 0.35357359051704407 0.21114712953567505 -0.7823742628097534"/>
        <geom class="collision" type="box" pos="0.22359430 0.05908049 -0.23693524" size="0.001313244691118598 0.0054823001846671104 0.020730527117848396" quat="0.3941517472267151 0.37130630016326904 0.17812657356262207 -0.8216124176979065"/>
        <geom class="collision" type="box" pos="0.21436929 0.06740139 -0.23693524" size="0.001313244691118598 0.0054823001846671104 0.020730527117848396" quat="0.37465900182724 0.3754052221775055 0.1693173348903656 -0.8306823372840881"/>
        <geom class="collision" type="box" pos="0.20793527 0.07385883 -0.23693524" size="0.001313244691118598 0.0054823001846671104 0.020730527117848396" quat="0.297132670879364 0.3893146216869354 0.13428127765655518 -0.8614608645439148"/>
        <geom class="collision" type="box" pos="0.20310521 0.09306404 -0.23693524" size="0.001313244691118598 0.0054823001846671104 0.020730527117848396" quat="0.0711892694234848 0.41056355834007263 0.03217211365699768 -0.9084792733192444"/>
        <geom class="collision" type="box" pos="0.20424503 0.08184639 -0.23693524" size="0.001313244691118598 0.0054823001846671104 0.020730527117848396" quat="0.15219734609127045 0.4060375392436981 0.06878159195184708 -0.898464560508728"/>
        <geom class="collision" type="box" pos="0.24258586 0.05192865 -0.23693524" size="0.001313244691118598 0.0054823001846671104 0.020730527117848396" quat="0.5495147109031677 0.3285198509693146 0.24833880364894867 -0.7269361615180969"/>
        <geom class="collision" type="box" pos="0.25097408 0.14040779 -0.23693524" size="0.0013132448075339198 0.005482300650328398 0.020730527117848396" quat="0.6244293451309204 -0.29993945360183716 0.2821945548057556 0.6636946201324463"/>
        <geom class="collision" type="box" pos="0.20175784 0.10152066 -0.23693524" size="0.0013132448075339198 0.0054823001846671104 0.020730527117848396" quat="0.039065562188625336 -0.4114435017108917 0.01765468530356884 0.9104264974594116"/>
        <geom class="collision" type="box" pos="0.28939503 0.09082320 -0.23693524" size="0.0013132448075339198 0.0054823001846671104 0.020730527117848396" quat="0.9110049605369568 -0.009822927415370941 0.41170498728752136 0.02173585072159767"/>
        <geom class="collision" type="box" pos="0.37837088 0.25789027 0.02243633" size="0.11339457333087921 0.011575007811188698 0.0024187914095818996" quat="1.0 0.0 0.0 0.0"/>
        <geom class="collision" type="cylinder" pos="0.03632380 0.24574791 0.07660449" size="0.020545145496726036 0.0217522531747818" quat="0.5316309928894043 0.4662279486656189 0.5316310524940491 0.4662278890609741"/>
        <body name="handle">
          <joint axis="1.0 0.0 0.0" pos="0.08550788 0.24645792 0.07713067" limited="true" name="handle_temp_joint" type="hinge" range="-0.7853981633974483 0.7853981633974483" damping="0.5" frictionloss="1" armature="2"/>
          <joint axis="0.0 1.0 0.0" pos="0.08550788 0.24645792 0.07713067" limited="true" name="handle_joint" type="hinge" range="0 0.5" damping="0.5" frictionloss="1" armature="2"/>
          <geom mesh="handle_vis" type="mesh" solimp="0.998 0.998 0.001" solref="0.001 1" friction="0.95 0.3 0.1" class="visual" material="handle_material"/>
          <geom class="collision" type="cylinder" pos="0.08637506 0.24646502 0.07724116" size="0.020715434104204178 0.01182409655302763" quat="0.7071068286895752 -0.0 0.7071067690849304 0.0"/>
          <geom name="handle_main" class="collision" type="cylinder" pos="0.08928870 0.24646502 0.12141787" size="0.0051301149651408195 0.0271417498588562" quat="0.9999178647994995 0.0 0.012815705500543118 0.0"/>
        </body>
        <body name="Container001">
          <joint axis="0.0 0.0 1.0" pos="0.36610650 -0.00004191 0.00191922" limited="true" name="Container001_joint" range="0.0 0.1" type="slide" damping="1" frictionloss="1" armature=".01" stiffness="0.05"/>
          <geom mesh="Container001_vis" type="mesh" solimp="0.998 0.998 0.001" solref="0.001 1" friction="0.95 0.3 0.1" class="visual" material="Container001_material"/>
          <geom class="collision" type="box" pos="0.36711859 0.00071127 -0.02197656" size="0.07616298645734787 0.22159786522388458 0.005960702430456877" quat="1.0 0.0 0.0 0.0"/>
          <geom class="collision" type="box" pos="0.28203684 0.00071127 0.00104703" size="0.0032559437677264214 0.2215978503227234 0.02203122153878212" quat="1.0 0.0 0.0 0.0"/>
          <geom class="collision" type="box" pos="0.45041778 0.00071127 0.00104703" size="0.0027486684266477823 0.22159895300865173 0.022031215950846672" quat="1.0 0.0 0.0 0.0"/>
          <geom class="collision" type="box" pos="0.36284112 -0.22194418 0.00104703" size="0.08651956170797348 0.0059606642462313175 0.022031307220458984" quat="1.0 0.0 0.0 0.0"/>
          <geom class="collision" type="box" pos="0.36284112 0.22351835 0.00104703" size="0.08651956170797348 0.0059606642462313175 0.02203129231929779" quat="1.0 0.0 0.0 0.0"/>
          <geom class="collision" type="box" pos="0.36284112 0.23729487 0.02605785" size="0.08651945739984512 0.019438279792666435 0.0010807234793901443" quat="1.0 0.0 0.0 0.0"/>
          <geom class="collision" type="box" pos="0.36284118 -0.23633433 0.02723291" size="0.08651956170797348 0.02102767676115036 0.0012742563849315047" quat="1.0 0.0 0.0 0.0"/>
        </body>
        <body name="spout">
          <joint axis="0.0 0.0 1.0" pos="0.00087071 0.24284998 0.25706225" limited="true" name="spout_joint" range="-0.9599310885968813 0.9599310885968813" type="hinge" damping="10"/>
          <site type="cylinder" rgba="0.5 0.75 1 0.5" size="0.009561539627611637 0.23631127178668976" pos="0.00081559 0.01067994 0.01993586" name="water"/>
          <geom mesh="spout_vis" type="mesh" solimp="0.998 0.998 0.001" solref="0.001 1" friction="0.95 0.3 0.1" class="visual" material="spout_material"/>
          <geom class="collision" type="cylinder" pos="-0.00043836 0.24562993 0.14825364" size="0.018415158614516258 0.03454742580652237" quat="1.0 0.0 0.0 0.0"/>
          <geom class="collision" type="cylinder" pos="-0.00043836 0.08187305 0.27184271" size="0.018038813024759293 0.09722638130187988" quat="0.7071068286895752 -0.7071067690849304 -0.0 0.0" name="spout_main"/>
          <geom class="collision" type="cylinder" pos="-0.00043836 0.23817227 0.21823973" size="0.018415158614516258 0.03454742580652237" quat="0.9848077297210693 0.17364826798439026 0.0 0.0"/>
          <geom class="collision" type="cylinder" pos="-0.00043836 0.20244489 0.26075979" size="0.018415158614516258 0.03454742580652237" quat="0.8191519975662231 0.5735765099525452 0.0 0.0"/>
          <geom class="collision" type="cylinder" pos="0.00089180 0.01061863 0.25100961" size="0.012974850833415985 0.007570096757262945" quat="1.0 0.0 0.0 0.0"/>
        </body>
        <geom class="region" name="reg_basin_left" type="box" pos="-0.24677453500000002 -1.2965000000003668e-05 -0.090257615" size="0.187743375 0.208902115 0.11499904500000001"/>
        <geom class="region" name="reg_basin_right" type="box" pos="0.16188746499999998 0.0011258900000000044 -0.09052758" size="0.11191285499999999 0.20806016 0.11500249000000001"/>
        <geom class="region" name="reg_main" type="box" pos="-1.150000000227358e-07 5.000000000143778e-08 -0.129203865" size="0.497299565 0.27117114 0.15515567500000002"/>
      </body>
    </body>
  </worldbody>
  <actuator>
    <motor name="handle_joint_actuator" joint="handle_joint" gear="10"/>
    <motor name="handle_temp_joint_actuator" joint="handle_temp_joint" gear="10"/>
    <motor name="Container001_joint_actuator" joint="Container001_joint" gear="10"/>
    <motor name="spout_joint_actuator" joint="spout_joint" gear="10"/>
  </actuator>
</mujoco>
