<?xml version='1.0' encoding='UTF-8'?>
<mujoco model="model">
  <compiler angle="radian"/>
  <asset>
    <mesh file="visuals/handle.obj" name="handle_vis"/>
    <mesh file="visuals/Body001.obj" name="Body001_vis"/>
    <mesh file="visuals/Container001.obj" name="Container001_vis"/>
    <mesh file="visuals/Funnel001.obj" name="Funnel001_vis"/>
    <mesh file="visuals/Funnel002.obj" name="Funnel002_vis"/>
    <mesh file="visuals/spout.obj" name="spout_vis"/>
    <texture file="visuals/T_BC001.png" name="Body001_material" type="2d"/>
    <material name="Body001_material" rgba="1 1 1 1.0" texture="Body001_material" shininess="0.4472135901451111" specular="0.3103448502657381"/>
    <texture file="visuals/T_BC001.png" name="handle_material" type="2d"/>
    <material name="handle_material" rgba="1 1 1 1.0" texture="handle_material" shininess="0.4472135901451111" specular="1"/>
    <texture file="visuals/T_BC001.png" name="Container001_material" type="2d"/>
    <material name="Container001_material" rgba="1 1 1 1.0" texture="Container001_material" shininess="0.4472135901451111" specular="1"/>
    <texture file="visuals/T_BC001.png" name="Funnel001_material" type="2d"/>
    <material name="Funnel001_material" rgba="1 1 1 1.0" texture="Funnel001_material" shininess="0.4472135901451111" specular="2"/>
    <texture file="visuals/T_BC001.png" name="Funnel002_material" type="2d"/>
    <material name="Funnel002_material" rgba="1 1 1 1.0" texture="Funnel002_material" shininess="0.4472135901451111" specular="2"/>
    <texture file="visuals/T_BC001.png" name="spout_material" type="2d"/>
    <material name="spout_material" rgba="1 1 1 1.0" texture="spout_material" shininess="0.4472135901451111" specular="1"/>
  </asset>
  <default>
    <default class="visual">
      <geom conaffinity="0" contype="0" group="1" type="mesh"/>
    </default>
    <default class="collision">
      <geom group="0" rgba="0.5 0 0 0.5"/>
    </default>
    <default class="spawn">
      <geom group="0" rgba="1 1 1 0.5" contype="0" conaffinity="0"/>
      <site group="0" rgba="1 1 1 0.5"/>
    </default>
    <default class="region">
      <geom group="1" conaffinity="0" contype="0" rgba="0 1 0 0"/>
    </default>
  </default>
  <worldbody>
    <body>
      <body name="object">
        <geom mesh="Body001_vis" type="mesh" solimp="0.998 0.998 0.001" solref="0.001 1" density="100" friction="0.95 0.3 0.1" class="visual" material="Body001_material"/>
        <geom class="collision" type="box" pos="-0.09733528 0.24096072 -0.11944095" size="0.3727695345878601 0.01719934493303299 0.12440010160207748" quat="0.9990482330322266 -0.04361938312649727 -0.0 0.0"/>
        <geom class="collision" type="box" pos="-0.09957722 -0.23252321 -0.11756697" size="0.37052756547927856 0.007144593633711338 0.12359046936035156" quat="0.9987403750419617 0.05017663165926933 0.0 0.0"/>
        <geom class="collision" type="box" pos="0.00122067 0.00568839 -0.11445136" size="0.024436986073851585 0.239365354180336 0.11916808784008026" quat="1.0 0.0 0.0 0.0"/>
        <geom class="collision" type="box" pos="-0.45941780 0.00568839 -0.11806926" size="0.23936714231967926 0.009068615734577179 0.12404944002628326" quat="0.7063643336296082 0.03239481896162033 -0.032394833862781525 -0.7063643336296082"/>
        <geom class="collision" type="box" pos="0.46855363 0.00568839 -0.12144011" size="0.23936714231967926 0.012515637092292309 0.1218361184000969" quat="0.7064337730407715 -0.030843568965792656 0.030843574553728104 -0.7064337730407715"/>
        <geom class="collision" type="box" pos="-0.12114539 0.00071127 -0.23545220" size="0.07363183796405792 0.2215971201658249 0.004479744005948305" quat="1.0 0.0 0.0 0.0"/>
        <geom class="collision" type="box" pos="-0.36401290 0.00071127 -0.23694713" size="0.07776174694299698 0.22159627079963684 0.0055097537115216255" quat="1.0 0.0 0.0 0.0"/>
        <geom class="collision" type="box" pos="-0.24591579 -0.08671883 -0.23694713" size="0.06047846004366875 0.13416701555252075 0.005509753245860338" quat="1.0 0.0 0.0 0.0"/>
        <geom class="collision" type="box" pos="-0.24591579 0.17909536 -0.23694713" size="0.060478467494249344 0.04014301672577858 0.005509752780199051" quat="1.0 0.0 0.0 0.0"/>
        <geom class="collision" type="box" pos="0.24169069 0.17876016 -0.23709134" size="0.060478467494249344 0.04047823324799538 0.005365547724068165" quat="1.0 0.0 0.0 0.0"/>
        <geom class="collision" type="box" pos="0.24169069 -0.08691750 -0.23709134" size="0.06047846004366875 0.13396848738193512 0.005365561693906784" quat="1.0 0.0 0.0 0.0"/>
        <geom class="collision" type="box" pos="0.12264396 0.00071127 -0.23709134" size="0.07681215554475784 0.22159676253795624 0.005365575663745403" quat="1.0 0.0 0.0 0.0"/>
        <geom class="collision" type="box" pos="0.36653229 0.00071127 -0.23709134" size="0.07356063276529312 0.2215968519449234 0.005365582183003426" quat="1.0 0.0 0.0 0.0"/>
        <geom class="collision" type="box" pos="0.35772776 -0.23268879 -0.11734176" size="0.08612968027591705 0.007468333933502436 0.12335024029016495" quat="0.998741865158081 0.05014668405056 0.0 0.0"/>
        <geom class="collision" type="box" pos="0.37909644 0.24394176 -0.11983144" size="0.1026066467165947 0.01779850758612156 0.1238136738538742" quat="0.9984838366508484 -0.05504579097032547 -0.0 0.0"/>
        <geom class="collision" type="cylinder" pos="0.00585980 0.24319141 0.06690051" size="0.03196365758776665 0.05996483936905861" quat="1.0 0.0 0.0 0.0"/>
        <geom class="collision" type="box" pos="-0.03465817 0.00568839 -0.11862095" size="0.008054555393755436 0.239366352558136 0.122091144323349" quat="0.9988089203834534 0.0 0.04879241809248924 0.0"/>
        <geom class="collision" type="box" pos="0.03096597 0.00568839 -0.11795440" size="0.006487147882580757 0.239366352558136 0.1191689521074295" quat="0.9994208216667175 0.0 -0.034029096364974976 0.0"/>
        <geom class="collision" type="box" pos="0.00135944 0.00071127 -0.23912723" size="0.07363183796405792 0.2215971201658249 0.0020765289664268494" quat="1.0 0.0 0.0 0.0"/>
        <geom class="collision" type="cylinder" pos="-0.24127152 0.09563573 -0.28846035" size="0.025850877165794373 0.01687796041369438" quat="1.0 0.0 0.0 0.0"/>
        <geom class="collision" type="cylinder" pos="0.24527887 0.09563573 -0.28846035" size="0.025850877165794373 0.01687796041369438" quat="1.0 0.0 0.0 0.0"/>
        <geom class="collision" type="box" pos="0.45743405 -0.23186786 -0.10457007" size="0.017486345022916794 0.012020817957818508 0.10862862318754196" quat="0.992235541343689 0.046697646379470825 0.00944522861391306 0.11488581448793411"/>
        <geom class="collision" type="box" pos="0.00100972 -0.25945828 0.00120491" size="0.49104857444763184 0.010111307725310326 0.002418790478259325" quat="1.0 0.0 0.0 0.0"/>
        <geom class="collision" type="box" pos="-0.48246855 -0.00231883 0.00120491" size="0.010111324489116669 0.26331180334091187 0.002418791875243187" quat="1.0 0.0 0.0 0.0"/>
        <geom class="collision" type="box" pos="0.48490366 -0.00231883 0.00120491" size="0.011575013399124146 0.26331183314323425 0.002418791875243187" quat="1.0 0.0 0.0 0.0"/>
        <geom class="collision" type="box" pos="-0.19974374 0.08528299 -0.25870524" size="0.001313244691118598 0.0054823001846671104 0.020730527117848396" quat="0.8857115507125854 0.09684006124734879 0.40027427673339844 -0.21428391337394714"/>
        <geom class="collision" type="box" pos="-0.20404023 0.07510709 -0.25870524" size="0.001313244691118598 0.0054823001846671104 0.020730527117848396" quat="0.8625609874725342 0.13283111155033112 0.3898119330406189 -0.29392358660697937"/>
        <geom class="collision" type="box" pos="-0.21218096 0.06572265 -0.25870524" size="0.001313244691118598 0.0054823001846671104 0.020730527117848396" quat="0.8553867936134338 0.14199042320251465 0.3865698277950287 -0.3141908645629883"/>
        <geom class="collision" type="box" pos="-0.21851263 0.05916485 -0.25870524" size="0.001313244691118598 0.0054823001846671104 0.020730527117848396" quat="0.823074221611023 0.17674292623996735 0.3719668984413147 -0.3910899758338928"/>
        <geom class="collision" type="box" pos="-0.23762072 0.05396383 -0.25870524" size="0.001313244691118598 0.0054823001846671104 0.020730527117848396" quat="0.6984293460845947 0.26451992988586426 0.31563693284988403 -0.5853195190429688"/>
        <geom class="collision" type="box" pos="-0.22642723 0.05532062 -0.25870524" size="0.001313244691118598 0.0054823001846671104 0.020730527117848396" quat="0.7480040788650513 0.23521433770656586 0.33804091811180115 -0.520473301410675"/>
        <geom class="collision" type="box" pos="-0.23183302 0.13735502 -0.25870524" size="0.001313244691118598 0.0054823001846671104 0.020730527117848396" quat="0.7815460562705994 -0.21177266538143158 0.35319942235946655 0.4686024785041809"/>
        <geom class="collision" type="box" pos="-0.22172635 0.13289804 -0.25870524" size="0.001313244691118598 0.0054823001846671104 0.020730527117848396" quat="0.8209136128425598 -0.1787833571434021 0.370990514755249 0.39560505747795105"/>
        <geom class="collision" type="box" pos="-0.21247191 0.12460986 -0.25870524" size="0.001313244691118598 0.0054823001846671104 0.020730527117848396" quat="0.8300180435180664 -0.169981449842453 0.37510499358177185 0.37612849473953247"/>
        <geom class="collision" type="box" pos="-0.20601512 0.11817522 -0.25870524" size="0.001313244691118598 0.0054823001846671104 0.020730527117848396" quat="0.860933244228363 -0.1349705010652542 0.38907670974731445 0.2986573278903961"/>
        <geom class="collision" type="box" pos="-0.20111709 0.09898723 -0.25870524" size="0.001313244691118598 0.0054823001846671104 0.020730527117848396" quat="0.9083518981933594 -0.03289860486984253 0.4105059504508972 0.07279683649539948"/>
        <geom class="collision" type="box" pos="-0.20229659 0.11020078 -0.25870524" size="0.001313244691118598 0.005482300650328398 0.020730527117848396" quat="0.8981937766075134 -0.0695001408457756 0.405915230512619 0.15378731489181519"/>
        <geom class="collision" type="box" pos="-0.28353671 0.10672168 -0.25870524" size="0.001313244691118598 0.0054823001846671104 0.020730527117848396" quat="0.21711264550685883 -0.39996278285980225 0.09811841696500778 0.8850224018096924"/>
        <geom class="collision" type="box" pos="-0.27917526 0.11686996 -0.25870524" size="0.001313244691118598 0.0054823001846671104 0.020730527117848396" quat="0.2966778874397278 -0.38938552141189575 0.1340758055448532 0.8616175651550293"/>
        <geom class="collision" type="box" pos="-0.27097473 0.12620216 -0.25870524" size="0.001313244691118598 0.0054823001846671104 0.020730527117848396" quat="0.31692206859588623 -0.3861141502857208 0.14322467148303986 0.8543787002563477"/>
        <geom class="collision" type="box" pos="-0.26460130 0.13271937 -0.25870524" size="0.0013132448075339198 0.0054823001846671104 0.020730527117848396" quat="0.3937176465988159 -0.37140023708343506 0.17793041467666626 0.8218205571174622"/>
        <geom class="collision" type="box" pos="-0.24546037 0.13779820 -0.25870524" size="0.0013132448075339198 0.0054823001846671104 0.020730527117848396" quat="0.5875478386878967 -0.3147902488708496 0.2655269205570221 0.6965559124946594"/>
        <geom class="collision" type="box" pos="-0.25666228 0.13651296 -0.25870524" size="0.001313244691118598 0.0054823001846671104 0.020730527117848396" quat="0.5228604674339294 -0.33728769421577454 0.23629315197467804 0.7463374137878418"/>
        <geom class="collision" type="box" pos="-0.25409684 0.05458775 -0.25870524" size="0.001313244691118598 0.0054823001846671104 0.020730527117848396" quat="0.4672184884548187 0.35357359051704407 0.21114712953567505 -0.7823742628097534"/>
        <geom class="collision" type="box" pos="-0.26418767 0.05908049 -0.25870524" size="0.001313244691118598 0.0054823001846671104 0.020730527117848396" quat="0.3941517472267151 0.37130630016326904 0.17812657356262207 -0.8216124176979065"/>
        <geom class="collision" type="box" pos="-0.27341268 0.06740139 -0.25870524" size="0.001313244691118598 0.0054823001846671104 0.020730527117848396" quat="0.37465900182724 0.3754052221775055 0.1693173348903656 -0.8306823372840881"/>
        <geom class="collision" type="box" pos="-0.27984670 0.07385883 -0.25870524" size="0.001313244691118598 0.0054823001846671104 0.020730527117848396" quat="0.297132670879364 0.3893146216869354 0.13428127765655518 -0.8614608645439148"/>
        <geom class="collision" type="box" pos="-0.28467677 0.09306404 -0.25870524" size="0.001313244691118598 0.0054823001846671104 0.020730527117848396" quat="0.0711892694234848 0.41056355834007263 0.03217211365699768 -0.9084792733192444"/>
        <geom class="collision" type="box" pos="-0.28353695 0.08184639 -0.25870524" size="0.001313244691118598 0.0054823001846671104 0.020730527117848396" quat="0.15219734609127045 0.4060375392436981 0.06878159195184708 -0.898464560508728"/>
        <geom class="collision" type="box" pos="-0.24519611 0.05192865 -0.25870524" size="0.001313244691118598 0.0054823001846671104 0.020730527117848396" quat="0.5495147109031677 0.3285198509693146 0.24833880364894867 -0.7269361615180969"/>
        <geom class="collision" type="box" pos="-0.23680789 0.14040779 -0.25870524" size="0.0013132448075339198 0.005482300650328398 0.020730527117848396" quat="0.6244293451309204 -0.29993945360183716 0.2821945548057556 0.6636946201324463"/>
        <geom class="collision" type="box" pos="-0.28602413 0.10152066 -0.25870524" size="0.0013132448075339198 0.0054823001846671104 0.020730527117848396" quat="0.039065562188625336 -0.4114435017108917 0.01765468530356884 0.9104264974594116"/>
        <geom class="collision" type="box" pos="-0.19838696 0.09082320 -0.25870524" size="0.0013132448075339198 0.0054823001846671104 0.020730527117848396" quat="0.9110049605369568 -0.009822927415370941 0.41170498728752136 0.02173585072159767"/>
        <geom class="collision" type="box" pos="0.28803825 0.08528299 -0.25870524" size="0.001313244691118598 0.0054823001846671104 0.020730527117848396" quat="0.8857115507125854 0.09684006124734879 0.40027427673339844 -0.21428391337394714"/>
        <geom class="collision" type="box" pos="0.28374174 0.07510709 -0.25870524" size="0.001313244691118598 0.0054823001846671104 0.020730527117848396" quat="0.8625609874725342 0.13283111155033112 0.3898119330406189 -0.29392358660697937"/>
        <geom class="collision" type="box" pos="0.27560102 0.06572265 -0.25870524" size="0.001313244691118598 0.0054823001846671104 0.020730527117848396" quat="0.8553867936134338 0.14199042320251465 0.3865698277950287 -0.3141908645629883"/>
        <geom class="collision" type="box" pos="0.26926934 0.05916485 -0.25870524" size="0.001313244691118598 0.0054823001846671104 0.020730527117848396" quat="0.823074221611023 0.17674292623996735 0.3719668984413147 -0.3910899758338928"/>
        <geom class="collision" type="box" pos="0.25016126 0.05396383 -0.25870524" size="0.001313244691118598 0.0054823001846671104 0.020730527117848396" quat="0.6984293460845947 0.26451992988586426 0.31563693284988403 -0.5853195190429688"/>
        <geom class="collision" type="box" pos="0.26135474 0.05532062 -0.25870524" size="0.001313244691118598 0.0054823001846671104 0.020730527117848396" quat="0.7480040788650513 0.23521433770656586 0.33804091811180115 -0.520473301410675"/>
        <geom class="collision" type="box" pos="0.25594896 0.13735502 -0.25870524" size="0.001313244691118598 0.0054823001846671104 0.020730527117848396" quat="0.7815460562705994 -0.21177266538143158 0.35319942235946655 0.4686024785041809"/>
        <geom class="collision" type="box" pos="0.26605564 0.13289804 -0.25870524" size="0.001313244691118598 0.0054823001846671104 0.020730527117848396" quat="0.8209136128425598 -0.1787833571434021 0.370990514755249 0.39560505747795105"/>
        <geom class="collision" type="box" pos="0.27531006 0.12460986 -0.25870524" size="0.001313244691118598 0.0054823001846671104 0.020730527117848396" quat="0.8300180435180664 -0.169981449842453 0.37510499358177185 0.37612849473953247"/>
        <geom class="collision" type="box" pos="0.28176686 0.11817522 -0.25870524" size="0.001313244691118598 0.0054823001846671104 0.020730527117848396" quat="0.860933244228363 -0.1349705010652542 0.38907670974731445 0.2986573278903961"/>
        <geom class="collision" type="box" pos="0.28666490 0.09898723 -0.25870524" size="0.001313244691118598 0.0054823001846671104 0.020730527117848396" quat="0.9083518981933594 -0.03289860486984253 0.4105059504508972 0.07279683649539948"/>
        <geom class="collision" type="box" pos="0.28548538 0.11020078 -0.25870524" size="0.001313244691118598 0.005482300650328398 0.020730527117848396" quat="0.8981937766075134 -0.0695001408457756 0.405915230512619 0.15378731489181519"/>
        <geom class="collision" type="box" pos="0.20424526 0.10672168 -0.25870524" size="0.001313244691118598 0.0054823001846671104 0.020730527117848396" quat="0.21711264550685883 -0.39996278285980225 0.09811841696500778 0.8850224018096924"/>
        <geom class="collision" type="box" pos="0.20860671 0.11686996 -0.25870524" size="0.001313244691118598 0.0054823001846671104 0.020730527117848396" quat="0.2966778874397278 -0.38938552141189575 0.1340758055448532 0.8616175651550293"/>
        <geom class="collision" type="box" pos="0.21680724 0.12620216 -0.25870524" size="0.001313244691118598 0.0054823001846671104 0.020730527117848396" quat="0.31692206859588623 -0.3861141502857208 0.14322467148303986 0.8543787002563477"/>
        <geom class="collision" type="box" pos="0.22318068 0.13271937 -0.25870524" size="0.0013132448075339198 0.0054823001846671104 0.020730527117848396" quat="0.3937176465988159 -0.37140023708343506 0.17793041467666626 0.8218205571174622"/>
        <geom class="collision" type="box" pos="0.24232161 0.13779820 -0.25870524" size="0.0013132448075339198 0.0054823001846671104 0.020730527117848396" quat="0.5875478386878967 -0.3147902488708496 0.2655269205570221 0.6965559124946594"/>
        <geom class="collision" type="box" pos="0.23111969 0.13651296 -0.25870524" size="0.001313244691118598 0.0054823001846671104 0.020730527117848396" quat="0.5228604674339294 -0.33728769421577454 0.23629315197467804 0.7463374137878418"/>
        <geom class="collision" type="box" pos="0.23368513 0.05458775 -0.25870524" size="0.001313244691118598 0.0054823001846671104 0.020730527117848396" quat="0.4672184884548187 0.35357359051704407 0.21114712953567505 -0.7823742628097534"/>
        <geom class="collision" type="box" pos="0.22359430 0.05908049 -0.25870524" size="0.001313244691118598 0.0054823001846671104 0.020730527117848396" quat="0.3941517472267151 0.37130630016326904 0.17812657356262207 -0.8216124176979065"/>
        <geom class="collision" type="box" pos="0.21436929 0.06740139 -0.25870524" size="0.001313244691118598 0.0054823001846671104 0.020730527117848396" quat="0.37465900182724 0.3754052221775055 0.1693173348903656 -0.8306823372840881"/>
        <geom class="collision" type="box" pos="0.20793527 0.07385883 -0.25870524" size="0.001313244691118598 0.0054823001846671104 0.020730527117848396" quat="0.297132670879364 0.3893146216869354 0.13428127765655518 -0.8614608645439148"/>
        <geom class="collision" type="box" pos="0.20310521 0.09306404 -0.25870524" size="0.001313244691118598 0.0054823001846671104 0.020730527117848396" quat="0.0711892694234848 0.41056355834007263 0.03217211365699768 -0.9084792733192444"/>
        <geom class="collision" type="box" pos="0.20424503 0.08184639 -0.25870524" size="0.001313244691118598 0.0054823001846671104 0.020730527117848396" quat="0.15219734609127045 0.4060375392436981 0.06878159195184708 -0.898464560508728"/>
        <geom class="collision" type="box" pos="0.24258586 0.05192865 -0.25870524" size="0.001313244691118598 0.0054823001846671104 0.020730527117848396" quat="0.5495147109031677 0.3285198509693146 0.24833880364894867 -0.7269361615180969"/>
        <geom class="collision" type="box" pos="0.25097408 0.14040779 -0.25870524" size="0.0013132448075339198 0.005482300650328398 0.020730527117848396" quat="0.6244293451309204 -0.29993945360183716 0.2821945548057556 0.6636946201324463"/>
        <geom class="collision" type="box" pos="0.20175784 0.10152066 -0.25870524" size="0.0013132448075339198 0.0054823001846671104 0.020730527117848396" quat="0.039065562188625336 -0.4114435017108917 0.01765468530356884 0.9104264974594116"/>
        <geom class="collision" type="box" pos="0.28939503 0.09082320 -0.25870524" size="0.0013132448075339198 0.0054823001846671104 0.020730527117848396" quat="0.9110049605369568 -0.009822927415370941 0.41170498728752136 0.02173585072159767"/>
        <geom class="collision" type="box" pos="0.37837088 0.25789027 0.00066633" size="0.113394595682621 0.011575007811188698 0.0024187916424125433" quat="1.0 0.0 0.0 0.0"/>
        <body name="handle">
          <joint axis="1.0 0.0 0.0" pos="0.06975854 0.24629996 0.08185302" limited="true" name="handle_temp_joint" type="hinge" range="-0.7853981633974483 0.7853981633974483" damping="1" frictionloss="1" armature=".01" stiffness="0.05"/>
          <joint axis="0.0 1.0 0.0" pos="0.06975854 0.24629996 0.08185302" limited="true" name="handle_joint" type="hinge" range="0 0.5" damping="1" frictionloss="1" armature=".01" stiffness="0.05"/>
          <geom mesh="handle_vis" type="mesh" solimp="0.998 0.998 0.001" solref="0.001 1" density="100" friction="0.95 0.3 0.1" class="visual" material="handle_material"/>
          <geom class="collision" type="cylinder" pos="0.07107804 0.24646502 0.08120888" size="0.029938509687781334 0.017088504508137703" quat="0.7071068286895752 -0.0 0.7071067690849304 0.0"/>
          <geom class="collision" type="cylinder" pos="0.07492610 0.24646502 0.14678024" size="0.006895358208566904 0.03648107498884201" quat="0.9999178647994995 0.0 0.012815705500543118 0.0"/>
        </body>
        <body name="Container001">
          <joint axis="0.0 0.0 1.0" pos="0.36610650 -0.00004191 -0.01985078" limited="true" name="Container001_joint" range="0.0 0.25" type="slide" damping="1" frictionloss="1" armature=".01" stiffness="0.05"/>
          <geom mesh="Container001_vis" type="mesh" solimp="0.998 0.998 0.001" solref="0.001 1" density="100" friction="0.95 0.3 0.1" class="visual" material="Container001_material"/>
          <geom class="collision" type="box" pos="0.36711859 0.00071127 -0.04374656" size="0.07616298645734787 0.22159786522388458 0.005960690323263407" quat="1.0 0.0 0.0 0.0"/>
          <geom class="collision" type="box" pos="0.28203684 0.00071127 -0.02072297" size="0.0032559500541538 0.2215978503227234 0.02203122153878212" quat="1.0 0.0 0.0 0.0"/>
          <geom class="collision" type="box" pos="0.45041778 0.00071127 -0.02072297" size="0.0027486684266477823 0.22159847617149353 0.022031215950846672" quat="1.0 0.0 0.0 0.0"/>
          <geom class="collision" type="box" pos="0.36284112 -0.22194418 -0.02072297" size="0.08651956170797348 0.0059606642462313175 0.022031269967556" quat="1.0 0.0 0.0 0.0"/>
          <geom class="collision" type="box" pos="0.36284112 0.22351835 -0.02072297" size="0.08651956170797348 0.0059606642462313175 0.022031256929039955" quat="1.0 0.0 0.0 0.0"/>
          <geom class="collision" type="box" pos="0.36284112 0.22449400 0.00428785" size="0.08651945739984512 0.00663741584867239 0.001080724992789328" quat="1.0 0.0 0.0 0.0"/>
          <geom class="collision" type="box" pos="0.36284118 -0.22325779 0.00546291" size="0.08651956170797348 0.00795113854110241 0.0012742563849315047" quat="1.0 0.0 0.0 0.0"/>
        </body>
        <body name="Funnel001">
          <joint axis="0.0 0.0 1.0" pos="-0.24119732 0.09509315 -0.24305578" limited="true" name="Funnel001_joint" range="0.0 0.3" type="slide" damping="1" frictionloss="1" armature=".01" stiffness="0.05"/>
          <geom mesh="Funnel001_vis" type="mesh" solimp="0.998 0.998 0.001" solref="0.001 1" density="100" friction="0.95 0.3 0.1" class="visual" material="Funnel001_material"/>
          <geom class="collision" type="cylinder" pos="-0.24173907 0.09516434 -0.23605155" size="0.03943944349884987 0.003031711792573333" quat="1.0 0.0 3.725290298461914e-09 0.0"/>
        </body>
        <body name="Funnel002">
          <joint axis="0.0 0.0 1.0" pos="0.24547432 0.09509305 -0.24305574" limited="true" name="Funnel002_joint" range="0.0 0.15" type="slide" damping="1" frictionloss="1" armature=".01" stiffness="0.05"/>
          <geom mesh="Funnel002_vis" type="mesh" solimp="0.998 0.998 0.001" solref="0.001 1" density="100" friction="0.95 0.3 0.1" class="visual" material="Funnel002_material"/>
          <geom class="collision" type="cylinder" pos="0.24693642 0.09516434 -0.23605152" size="0.03943944349884987 0.003031711792573333" quat="1.0 0.0 3.725290298461914e-09 0.0"/>
        </body>
        <body name="spout">
          <joint axis="0.0 0.0 1.0" pos="0.00647599 0.24284998 0.27883261" limited="true" name="spout_joint" range="-0.7853981633974483 0.7853981633974483" type="hinge" damping="1" frictionloss="1" armature=".01" stiffness="0.05"/>
          <site type="cylinder" rgba="0.5 0.75 1 0.5" size="0.010549696162343025 0.2677684426307678" pos="0.00552731 0.00990456 0.00819758" name="water"/>
          <geom mesh="spout_vis" type="mesh" solimp="0.998 0.998 0.001" solref="0.001 1" density="100" friction="0.95 0.3 0.1" class="visual" material="spout_material"/>
          <geom class="collision" type="cylinder" pos="0.00585980 0.24562993 0.16899627" size="0.018415158614516258 0.03454742580652237" quat="1.0 0.0 0.0 0.0"/>
          <geom class="collision" type="cylinder" pos="0.00585980 0.08187304 0.29258534" size="0.018038813024759293 0.09722638130187988" quat="0.7071068286895752 -0.7071067690849304 -0.0 0.0"/>
          <geom class="collision" type="cylinder" pos="0.00585980 0.23817227 0.23898236" size="0.018415158614516258 0.03454742580652237" quat="0.9848077297210693 0.17364826798439026 0.0 0.0"/>
          <geom class="collision" type="cylinder" pos="0.00585980 0.20244489 0.28150242" size="0.018415158614516258 0.03454742580652237" quat="0.8191519975662231 0.5735765099525452 0.0 0.0"/>
          <geom class="collision" type="cylinder" pos="0.00619874 0.01061863 0.27696680" size="0.01598123088479042 0.007570096757262945" quat="1.0 0.0 0.0 0.0"/>
        </body>
        <geom class="region" name="reg_main" type="box" pos="-1.0500000000024379e-07 5.000000000143778e-08 -0.150765335" size="0.49729956500000005 0.27117114 0.155364185"/>
        <geom class="region" name="reg_basin_left" type="box" pos="-0.24692372999999998 -0.002076759999999997 -0.116743905" size="0.21981913 0.24309138000000002 0.117908215"/>
        <geom class="region" name="reg_basin_right" type="box" pos="0.151884395 -0.00020193999999999768 -0.116743905" size="0.124047415 0.24121656000000002 0.117908215"/>
      </body>
    </body>
  </worldbody>
  <actuator>
    <motor name="handle_temp_joint_actuator" joint="handle_temp_joint" gear="10"/>
    <motor name="handle_joint_actuator" joint="handle_joint" gear="10"/>
    <motor name="Container001_joint_actuator" joint="Container001_joint" gear="30"/>
    <motor name="Funnel001_joint_actuator" joint="Funnel001_joint" gear="10"/>
    <motor name="Funnel002_joint_actuator" joint="Funnel002_joint" gear="10"/>
    <motor name="spout_joint_actuator" joint="spout_joint" gear="10"/>
  </actuator>
</mujoco>
