<?xml version='1.0' encoding='UTF-8'?>
<mujoco model="model">
  <option timestep="0.002" gravity="0.0 0.0 -9.81"/>
  <compiler angle="radian"/>
  <asset>
    <mesh file="visuals/door.obj" name="door_vis"/>
    <mesh file="visuals/knob_temp.obj" name="knob_temp_vis"/>
    <mesh file="visuals/knob_time.obj" name="knob_time_vis"/>
    <mesh file="visuals/rack0.obj" name="rack0_vis"/>
    <mesh file="visuals/rack1.obj" name="rack1_vis"/>
    <mesh file="visuals/Body001.obj" name="Body001_vis"/>
    <mesh file="visuals/window.obj" name="window_vis"/>
    <texture file="visuals/T_BC001.png" name="Body001_material" type="2d"/>
    <material name="Body001_material" rgba="1 1 1 1.0" texture="Body001_material" shininess="0.1" specular="2"/>
    <texture file="visuals/T_BC001.png" name="door_material" type="2d"/>
    <material name="door_material" rgba="1 1 1 1.0" texture="door_material" shininess="0.1" specular="2"/>
    <texture file="visuals/T_BC001.png" name="window_material" type="2d"/>
    <material name="window_material" rgba="1 1 1 0.7993370890617371" texture="window_material" shininess="0.5" specular="0.3103448502657381"/>
    <texture file="visuals/T_BC001.png" name="knob_temp_material" type="2d"/>
    <material name="knob_temp_material" rgba="1 1 1 1.0" texture="knob_temp_material" shininess="0.5" specular="0.3103448502657381"/>
    <texture file="visuals/T_BC001.png" name="knob_time_material" type="2d"/>
    <material name="knob_time_material" rgba="1 1 1 1.0" texture="knob_time_material" shininess="0.5" specular="0.3103448502657381"/>
    <texture file="visuals/T_BC001.png" name="rack0_material" type="2d"/>
    <material name="rack0_material" rgba="1 1 1 1.0" texture="rack0_material" shininess="0.1" specular="4"/>
    <texture file="visuals/T_BC001.png" name="rack1_material" type="2d"/>
    <material name="rack1_material" rgba="1 1 1 1.0" texture="rack1_material" shininess="0.1" specular="4"/>
  </asset>
  <default>
    <default class="visual">
      <geom conaffinity="0" contype="0" group="1" type="mesh"/>
    </default>
    <default class="collision">
      <geom group="0" rgba="0.5 0 0 0.5"/>
    </default>
    <default class="spawn">
      <geom group="0" rgba="1 1 1 0.5" contype="0" conaffinity="0"/>
      <site group="0" rgba="1 1 1 0.5"/>
    </default>
    <default class="region">
      <geom group="1" conaffinity="0" contype="0" rgba="0 1 0 0"/>
    </default>
  </default>
  <worldbody>
    <body>
      <body name="object">
        <geom mesh="Body001_vis" type="mesh" solimp="0.998 0.998 0.001" solref="0.001 1" friction="0.95 0.3 0.1" class="visual" material="Body001_material"/>
        <geom class="collision" type="box" pos="3.64379957318306e-08 0.012203969061374664 0.11969748884439468" size="0.19304823875427246 0.1445595771074295 0.00679768156260252" quat="1.0 0.0 0.0 0.0"/>
        <geom class="collision" type="box" pos="3.64379957318306e-08 0.017094584181904793 0.11010607331991196" size="0.19304832816123962 0.1396690458059311 0.003947537858039141" quat="1.0 0.0 0.0 0.0"/>
        <geom class="collision" type="box" pos="3.64379957318306e-08 0.017094584181904793 -0.11388709396123886" size="0.1930484026670456 0.13966912031173706 0.012608086690306664" quat="1.0 0.0 0.0 0.0"/>
        <geom class="collision" type="box" pos="-0.18800987303256989 0.017094584181904793 0.002114340662956238" size="0.005040289368480444 0.13966920971870422 0.10683458298444748" quat="1.0 0.0 0.0 0.0"/>
        <geom class="collision" type="box" pos="0.16797146201133728 0.008788986131548882 -0.006917132996022701" size="0.025078538805246353 0.14063630998134613 0.11957735568284988" quat="1.0 0.0 0.0 0.0"/>
        <geom class="collision" type="box" pos="0.15365858376026154 0.017094584181904793 0.002114340662956238" size="0.03939135745167732 0.13966938853263855 0.10683475434780121" quat="1.0 0.0 0.0 0.0"/>
        <geom class="collision" type="box" pos="-0.03421740233898163 0.1468842625617981 -0.0022094398736953735" size="0.14014197885990143 0.009881222620606422 0.11655104905366898" quat="1.0 0.0 0.0 0.0"/>
        <geom class="collision" type="box" pos="0.12259704619646072 0.019221343100070953 0.05575304105877876" size="0.04704725369811058 0.09811290353536606 0.0022972668521106243" quat="1.0 0.0 0.0 0.0"/>
        <geom class="collision" type="box" pos="0.12259704619646072 0.019221343100070953 0.017861761152744293" size="0.04704727604985237 0.09811294078826904 0.001453750184737146" quat="1.0 0.0 0.0 0.0"/>
        <geom class="collision" type="box" pos="0.12259704619646072 0.019221343100070953 -0.019631080329418182" size="0.04704729840159416 0.09811298549175262 0.0022972694132477045" quat="1.0 0.0 0.0 0.0"/>
        <geom class="collision" type="box" pos="0.12259704619646072 0.019221343100070953 -0.05784451588988304" size="0.047047317028045654 0.0981130301952362 0.001453751465305686" quat="1.0 0.0 0.0 0.0"/>
        <geom class="collision" type="box" pos="-0.16787351667881012 0.019221343100070953 -0.05784451588988304" size="0.024093976244330406 0.09811306744813919 0.001453752163797617" quat="1.0 0.0 0.0 0.0"/>
        <geom class="collision" type="box" pos="-0.16787351667881012 0.019221343100070953 -0.019147854298353195" size="0.0240939874202013 0.09811311215162277 0.0022972733713686466" quat="1.0 0.0 0.0 0.0"/>
        <geom class="collision" type="box" pos="-0.16787351667881012 0.019221343100070953 0.01705636829137802" size="0.024093998596072197 0.09811315685510635 0.0014537535607814789" quat="1.0 0.0 0.0 0.0"/>
        <geom class="collision" type="box" pos="-0.16787351667881012 0.019221343100070953 0.05628995969891548" size="0.024094007909297943 0.09811320155858994 0.0022972761653363705" quat="1.0 0.0 0.0 0.0"/>
        <body name="door">
          <joint axis="1.0 0.0 0.0" pos="-0.0246893260627985 -0.12751953303813934 -0.11927250772714615" limited="true" name="door_joint" range="0.0 1.3707963267948966" type="hinge" damping="1" frictionloss="-1" armature=".01" stiffness="0.3" springref="-0.5"/>
          <geom mesh="door_vis" type="mesh" solimp="0.998 0.998 0.001" solref="0.001 1" friction="0.95 0.3 0.1" class="visual" material="door_material"/>
          <geom class="collision" type="box" pos="-0.02538214810192585 -0.12978653609752655 -0.006237654015421867" size="0.167667418718338 0.0025777523405849934 0.118888720870018" quat="1.0 0.0 0.0 0.0" name="door_main"/>
          <geom class="collision" type="box" pos="-0.14305917918682098 -0.1430966705083847 0.09574396908283234" size="0.021940400823950768 0.006711089517921209 0.008941968902945518" quat="0.9704712629318237 0.0 -0.0 -0.2412167340517044"/>
          <geom class="collision" type="box" pos="-0.025079229846596718 -0.1507381647825241 0.09574396908283234" size="0.10060752928256989 0.006711089517921209 0.008941968902945518" quat="1.0 0.0 0.0 0.0" name="door_handle_main"/>
          <geom class="collision" type="box" pos="0.09323767572641373 -0.14281748235225677 0.09574396908283234" size="0.021940400823950768 0.006711089517921209 0.008941968902945518" quat="0.9704712629318237 0.0 0.0 0.2412167191505432"/>
          <body name="window">
            <geom mesh="window_vis" type="mesh" solimp="0.998 0.998 0.001" solref="0.001 1" friction="0.95 0.3 0.1" class="visual" material="window_material"/>
            <geom class="collision" type="box" pos="-0.025531478226184845 -0.12706252932548523 -0.005609186366200447" size="0.13587765395641327 0.003692775731906295 0.0877160057425499" quat="1.0 0.0 0.0 0.0"/>
          </body>
        </body>
        <body name="knob_temp">
          <joint axis="0.0 1.0 0.0" pos="0.16803999245166779 -0.13876289129257202 0.03713800013065338" limited="true" name="knob_temp_joint" range="0.0 5.323254218582705" type="hinge" damping="0.05" armature="0.001"/>
          <geom mesh="knob_temp_vis" type="mesh" solimp="0.998 0.998 0.001" solref="0.001 1" friction="0.95 0.3 0.1" class="visual" material="knob_temp_material"/>
          <geom class="collision" type="cylinder" pos="0.1680668294429779 -0.1350042074918747 0.0373394675552845" size="0.014141763560473919 0.0024611155968159437" quat="0.7071067094802856 0.7071068286895752 0.0 0.0"/>
          <geom class="collision" type="box" pos="0.16884516179561615 -0.14233483374118805 0.03685400262475014" size="0.013529120944440365 0.005517123732715845 0.0035898517817258835" quat="1.0 0.0 0.0 0.0" name="knob_temp_main"/>
        </body>
        <body name="knob_time">
          <joint axis="0.0 1.0 0.0" pos="0.16803999245166779 -0.13876289129257202 -0.03734299913048744" limited="true" name="knob_time_joint" range="0.0 4.71238898038469" type="hinge" damping="0.05" armature="0.001"/>
          <geom mesh="knob_time_vis" type="mesh" solimp="0.998 0.998 0.001" solref="0.001 1" friction="0.95 0.3 0.1" class="visual" material="knob_time_material"/>
          <geom class="collision" type="cylinder" pos="0.1680668294429779 -0.1350042074918747 -0.03711780533194542" size="0.014141763560473919 0.0024611155968159437" quat="0.7071067094802856 0.7071068286895752 0.0 0.0"/>
          <geom class="collision" type="box" pos="0.16801805794239044 -0.1422434002161026 -0.0375567302107811" size="0.012702028267085552 0.005425702780485153 0.0035221530124545097" quat="1.0 0.0 0.0 0.0" name="knob_time_main"/>
        </body>
        <body name="rack0">
          <geom class="region" name="reg_rack0" type="box" pos="-0.0343484990298748 0.015304241329431534 -0.016289510764181614" size="0.10898591747879982 0.08787395974993706 0.03529242130368948"/>
          <joint axis="0.0 -1.0 0.0" pos="-0.03493204340338707 0.016905417665839195 -0.04531083256006241" limited="true" name="rack0_joint" range="0.0 0.15" type="slide" damping="1" frictionloss="1" armature=".01" stiffness="0.05"/>
          <geom mesh="rack0_vis" type="mesh" solimp="0.998 0.998 0.001" solref="0.001 1" friction="0.95 0.3 0.1" class="visual" material="rack0_material"/>
          <geom class="collision" type="box" pos="-0.03447645530104637 0.0167081318795681 -0.05289747193455696" size="0.11861972510814667 0.09005417674779892 0.0023155161179602146" quat="1.0 0.0 0.0 0.0"/>
          <geom class="collision" type="box" pos="-0.03447645530104637 0.10486307740211487 -0.043829284608364105" size="0.11861972510814667 0.0018992406548932195 0.007552249822765589" quat="1.0 0.0 0.0 0.0"/>
        </body>
        <body name="rack1">
          <geom class="region" name="reg_rack1" type="box" pos="-0.0343484990298748 0.015304241329431534 0.06537657231092453" size="0.10898591747879982 0.08787395974993706 0.0414285192489624"/>
          <joint axis="0.0 -1.0 0.0" pos="-0.034932058304548264 0.016905417665839195 0.030193159356713295" limited="true" name="rack1_joint" range="0.0 0.15" type="slide" damping="1" frictionloss="1" armature=".01" stiffness="0.05"/>
          <geom mesh="rack1_vis" type="mesh" solimp="0.998 0.998 0.001" solref="0.001 1" friction="0.95 0.3 0.1" class="visual" material="rack1_material"/>
          <geom class="collision" type="box" pos="-0.03447645530104637 0.0167081318795681 0.022632505744695663" size="0.11861972510814667 0.09005417674779892 0.0023155161179602146" quat="1.0 0.0 0.0 0.0"/>
          <geom class="collision" type="box" pos="-0.03447645530104637 0.10486307740211487 0.03170069307088852" size="0.11861972510814667 0.0018992406548932195 0.007552249822765589" quat="1.0 0.0 0.0 0.0"/>
        </body>
        <geom class="region" name="reg_int" type="box" pos="-0.0343484990298748 0.006552781909704208 0.0024947822093963623" size="0.10898591747879982 0.1301065700352192 0.10462600535154343"/>
        <geom class="region" name="reg_main" type="box" pos="1.1175870895385742e-08 0.012200333178043365 0.0" size="0.19404963946342468 0.14556462860107422 0.12749522721767426"/>
      </body>
    </body>
  </worldbody>
  <actuator>
    <motor name="door_joint_actuator" joint="door_joint" gear="50"/>
    <motor name="knob_temp_joint_actuator" joint="knob_temp_joint" gear="50"/>
    <motor name="knob_time_joint_actuator" joint="knob_time_joint" gear="50"/>
    <motor name="rack0_joint_actuator" joint="rack0_joint" gear="50"/>
    <motor name="rack1_joint_actuator" joint="rack1_joint" gear="50"/>
  </actuator>
</mujoco>
