<?xml version='1.0' encoding='UTF-8'?>
<mujoco model="model">
  <option timestep="0.002" gravity="0.0 0.0 -9.81"/>
  <compiler angle="radian"/>
  <asset>
    <mesh file="visuals/knob_front_center.obj" name="knob_front_center_vis"/>
    <mesh file="visuals/knob_front_left.obj" name="knob_front_left_vis"/>
    <mesh file="visuals/knob_front_right.obj" name="knob_front_right_vis"/>
    <mesh file="visuals/knob_rear_center.obj" name="knob_rear_center_vis"/>
    <mesh file="visuals/Body001.obj" name="Body001_vis"/>
    <mesh file="visuals/Body002.obj" name="Body002_vis"/>
    <texture file="visuals/T_BC001.png" name="Body001_material" type="2d"/>
    <material name="Body001_material" rgba="1 1 1 1.0" texture="Body001_material" shininess="1" specular="1"/>
    <texture file="visuals/T_BC001.png" name="knob_front_center_material" type="2d"/>
    <material name="knob_front_center_material" rgba="1 1 1 1.0" texture="knob_front_center_material" shininess="1" specular="1"/>
    <texture file="visuals/T_BC001.png" name="knob_front_left_material" type="2d"/>
    <material name="knob_front_left_material" rgba="1 1 1 1.0" texture="knob_front_left_material" shininess="1" specular="1"/>
    <texture file="visuals/T_BC001.png" name="knob_front_right_material" type="2d"/>
    <material name="knob_front_right_material" rgba="1 1 1 1.0" texture="knob_front_right_material" shininess="1" specular="1"/>
    <texture file="visuals/T_BC001.png" name="knob_rear_center_material" type="2d"/>
    <material name="knob_rear_center_material" rgba="1 1 1 1.0" texture="knob_rear_center_material" shininess="1" specular="1"/>
    <texture file="visuals/T_BC001.png" name="Body002_material" type="2d"/>
    <material name="Body002_material" rgba="1 1 1 1.0" texture="Body002_material" shininess="10" specular="10"/>
  </asset>
  <default>
    <default class="visual">
      <geom conaffinity="0" contype="0" group="1" type="mesh"/>
    </default>
    <default class="collision">
      <geom group="0" rgba="0.5 0 0 0.5"/>
    </default>
    <default class="spawn">
      <geom group="0" rgba="1 1 1 0.5" contype="0" conaffinity="0"/>
      <site group="0" rgba="1 1 1 0.5"/>
    </default>
    <default class="region">
      <geom group="1" conaffinity="0" contype="0" rgba="0 1 0 0"/>
    </default>
  </default>
  <worldbody>
    <body>
      <body name="object">
        <geom mesh="Body001_vis" type="mesh" solimp="0.998 0.998 0.001" solref="0.001 1" friction="0.95 0.3 0.1" class="visual" material="Body001_material"/>
        <geom class="collision" type="box" pos="4.380980911378174e-09 0.0 -0.01332028117030859" size="0.3342317044734955 0.20851737260818481 0.0048271240666508675" quat="1.0 0.0 0.0 0.0"/>
        <geom class="collision" type="cylinder" pos="-0.22033053636550903 -0.012668903917074203 -0.006297476124018431" size="0.09286115318536758 0.0034886973444372416" quat="1.0 0.0 0.0 0.0"/>
        <geom class="collision" type="cylinder" pos="-0.22033053636550903 -0.012668903917074203 0.0036210580728948116" size="0.05264684557914734 0.007020096760243177" quat="1.0 0.0 0.0 0.0"/>
        <geom class="collision" type="cylinder" pos="0.22016026079654694 -0.012143885716795921 -0.006297476124018431" size="0.09286115318536758 0.0034886973444372416" quat="1.0 0.0 0.0 0.0"/>
        <geom class="collision" type="cylinder" pos="0.22016026079654694 -0.012143885716795921 0.0036210580728948116" size="0.05264684557914734 0.007020096760243177" quat="1.0 0.0 0.0 0.0"/>
        <geom class="collision" type="cylinder" pos="0.004366257227957249 -0.037866052240133286 -0.0040492527186870575" size="0.06666730344295502 0.0038189413025975227" quat="1.0 0.0 0.0 0.0"/>
        <geom class="collision" type="cylinder" pos="0.004366257227957249 -0.037866052240133286 0.005188675597310066" size="0.037796467542648315 0.005633363965898752" quat="1.0 0.0 0.0 0.0"/>
        <geom class="collision" type="cylinder" pos="0.004366257227957249 0.1288725584745407 -0.0040492527186870575" size="0.06666730344295502 0.0038189413025975227" quat="1.0 0.0 0.0 0.0"/>
        <geom class="collision" type="cylinder" pos="0.004366257227957249 0.1288725584745407 0.005188675597310066" size="0.037796467542648315 0.005633363965898752" quat="1.0 0.0 0.0 0.0"/>
        <body name="knob_front_center">
          <joint axis="0.0 0.0 1.0" pos="-0.051159366965293884 -0.16971886157989502 0.0006744418642483652" limited="true" name="knob_front_center_joint" range="0.0 3.6651914291880923" type="hinge" damping="0.05" armature="0.001"/>
          <geom mesh="knob_front_center_vis" type="mesh" solimp="0.998 0.998 0.001" solref="0.001 1" friction="0.95 0.3 0.1" class="visual" material="knob_front_center_material"/>
          <geom class="collision" type="cylinder" pos="-0.05127892270684242 -0.16964967548847198 -0.0053074052557349205" size="0.017160845920443535 0.002062341431155801" quat="1.0 0.0 0.0 0.0"/>
          <geom class="collision" type="box" pos="-0.05127892270684242 -0.1696496605873108 0.0033415518701076508" size="0.003390667960047722 0.015241791494190693 0.006311689503490925" quat="1.0 0.0 0.0 0.0" name="knob_front_center_main"/>
        </body>
        <body name="knob_front_left">
          <joint axis="0.0 0.0 1.0" pos="-0.15330645442008972 -0.16971886157989502 0.0011382149532437325" limited="true" name="knob_front_left_joint" range="0.0 3.6651914291880923" type="hinge" damping="0.05" armature="0.001"/>
          <geom mesh="knob_front_left_vis" type="mesh" solimp="0.998 0.998 0.001" solref="0.001 1" friction="0.95 0.3 0.1" class="visual" material="knob_front_left_material"/>
          <geom class="collision" type="cylinder" pos="-0.1531001776456833 -0.16964967548847198 -0.004816659726202488" size="0.017160845920443535 0.002062341431155801" quat="1.0 0.0 0.0 0.0"/>
          <geom class="collision" type="box" pos="-0.1531001776456833 -0.1696496605873108 0.0033415518701076508" size="0.003406719071790576 0.015241791494190693 0.006311689503490925" quat="1.0 0.0 0.0 0.0" name="knob_front_left_main"/>
        </body>
        <body name="knob_front_right">
          <joint axis="0.0 0.0 1.0" pos="0.15321055054664612 -0.16971886157989502 0.0006744418642483652" limited="true" name="knob_front_right_joint" range="0.0 3.6651914291880923" type="hinge" damping="0.05" armature="0.001"/>
          <geom mesh="knob_front_right_vis" type="mesh" solimp="0.998 0.998 0.001" solref="0.001 1" friction="0.95 0.3 0.1" class="visual" material="knob_front_right_material"/>
          <geom class="collision" type="cylinder" pos="0.15314362943172455 -0.16964967548847198 -0.005263169761747122" size="0.017160845920443535 0.002062341431155801" quat="1.0 0.0 0.0 0.0"/>
          <geom class="collision" type="box" pos="0.15314362943172455 -0.1696496605873108 0.0033415518701076508" size="0.0032751858234405518 0.015241791494190693 0.006311689503490925" quat="1.0 0.0 0.0 0.0" name="knob_front_right_main"/>
        </body>
        <body name="knob_rear_center">
          <joint axis="0.0 0.0 1.0" pos="0.051047395914793015 -0.16971886157989502 0.0006744418642483652" limited="true" name="knob_rear_center_joint" range="0.0 3.6651914291880923" type="hinge" damping="0.05" armature="0.001"/>
          <geom mesh="knob_rear_center_vis" type="mesh" solimp="0.998 0.998 0.001" solref="0.001 1" friction="0.95 0.3 0.1" class="visual" material="knob_rear_center_material"/>
          <geom class="collision" type="cylinder" pos="0.05120574310421944 -0.16964967548847198 -0.005203856620937586" size="0.017160845920443535 0.002062341431155801" quat="1.0 0.0 0.0 0.0"/>
          <geom class="collision" type="box" pos="0.05120574310421944 -0.1696496605873108 0.0033415518701076508" size="0.003308260580524802 0.015241791494190693 0.006311689503490925" quat="1.0 0.0 0.0 0.0" name="knob_rear_center_main"/>
        </body>
        <body name="Body002">
          <geom mesh="Body002_vis" type="mesh" solimp="0.998 0.998 0.001" solref="0.001 1" friction="0.95 0.3 0.1" class="visual" material="Body002_material"/>
          <geom class="collision" type="box" pos="-0.004291496239602566 0.04502124339342117 0.006296009290963411" size="0.3069351613521576 0.14653801918029785 0.010914182290434837" quat="1.0 0.0 0.0 0.0"/>
        </body>
        <site type="cylinder" rgba="0.3 0.4 1 0.5" size="0.05069379135966301 0.0025935920421034098" pos="0.22079916298389435 -0.012484343722462654 0.008430317044258118" name="burner_on_front_right"/>
        <site type="cylinder" rgba="0.3 0.4 1 0.5" size="0.05131968483328819 0.0027055712416768074" pos="-0.2201564759016037 -0.012484424747526646 0.008651169016957283" name="burner_on_front_left"/>
        <site type="cylinder" rgba="0.3 0.4 1 0.5" size="0.0366743728518486 0.0026551438495516777" pos="0.004639850463718176 0.12877649068832397 0.00839809887111187" name="burner_on_rear_center"/>
        <site type="cylinder" rgba="0.3 0.4 1 0.5" size="0.037556495517492294 0.0026233636308461428" pos="0.004639845807105303 -0.03729468956589699 0.008280633017420769" name="burner_on_front_center"/>
        <site type="cylinder" rgba="0.5 0 0 0" size="0.037556495517492294 4.999999873689376e-05" pos="0.004639849998056889 -0.03729468956589699 0.01747346855700016" name="burner_front_center_place_site"/>
        <site type="cylinder" rgba="0.5 0 0 0" size="0.05131968483328819 4.999999873689376e-05" pos="-0.2201564759016037 -0.012484424747526646 0.01747346855700016" name="burner_front_left_place_site"/>
        <site type="cylinder" rgba="0.5 0 0 0" size="0.05069379135966301 4.999999873689376e-05" pos="0.22079916298389435 -0.012484343722462654 0.01747346855700016" name="burner_front_right_place_site"/>
        <site type="cylinder" rgba="0.5 0 0 0" size="0.0366743728518486 4.999999873689376e-05" pos="0.004639850463718176 0.12877649068832397 0.01747346855700016" name="burner_rear_center_place_site"/>
        <geom class="region" name="reg_main" type="box" pos="-7.450580596923828e-09 0.0 -0.013320254161953926" size="0.3352316448688507 0.20951734280586243 0.005827149212360382"/>
      </body>
    </body>
  </worldbody>
  <actuator>
    <motor name="knob_front_center_joint_actuator" joint="knob_front_center_joint" gear="10"/>
    <motor name="knob_front_left_joint_actuator" joint="knob_front_left_joint" gear="10"/>
    <motor name="knob_front_right_joint_actuator" joint="knob_front_right_joint" gear="10"/>
    <motor name="knob_rear_center_joint_actuator" joint="knob_rear_center_joint" gear="10"/>
  </actuator>
</mujoco>
