<?xml version='1.0' encoding='UTF-8'?>
<mujoco model="model">
  <option timestep="0.002" gravity="0.0 0.0 -9.81"/>
  <compiler angle="radian"/>
  <asset>
    <mesh file="visuals/door.obj" name="door_vis"/>
    <mesh file="visuals/door_Clear.obj" name="door_Clear_vis"/>
    <mesh file="visuals/Body001.obj" name="Body001_vis"/>
    <mesh file="visuals/Disc001.obj" name="Disc001_vis"/>
    <texture file="visuals/T_BC001.png" name="Body001_material" type="2d"/>
    <material name="Body001_material" rgba="1 1 1 1.0" texture="Body001_material" shininess="0.141421377658844" specular="1"/>
    <texture file="visuals/T_BC001.png" name="door_material" type="2d"/>
    <material name="door_material" rgba="1 1 1 1.0" texture="door_material" shininess="1" specular="1"/>
    <material name="door_Clear_material" rgba="0.07379995286464691 0.07379995286464691 0.07379995286464691 0.800000011920929" shininess="0.141421377658844" specular="1"/>
    <texture file="visuals/T_BC001.png" name="Disc001_material" type="2d"/>
    <material name="Disc001_material" rgba="1 1 1 1.0" texture="Disc001_material" shininess="0.141421377658844" specular="1"/>
  </asset>
  <default>
    <default class="visual">
      <geom conaffinity="0" contype="0" group="1" type="mesh"/>
    </default>
    <default class="collision">
      <geom group="0" rgba="0.5 0 0 0.5"/>
    </default>
    <default class="spawn">
      <geom group="0" rgba="1 1 1 0.5" contype="0" conaffinity="0"/>
      <site group="0" rgba="1 1 1 0.5"/>
    </default>
    <default class="region">
      <geom group="1" conaffinity="0" contype="0" rgba="0 1 0 0"/>
    </default>
  </default>
  <worldbody>
    <body>
      <body name="object">
        <geom class="collision" type="cylinder" pos="-0.06085872 0.00446328 -0.12896933" size="0.14400441944599152 0.0028689817991107702" quat="1.0 0.0 0.0 0.0" name="tray" rgba="0 1 0 0.5"/>
        <geom class="collision" type="box" pos="0.26689107 -0.19022940 -0.08845361" size="0.012189998291432858 0.0006485347985289991 0.01066130306571722" quat="1.0 0.0 0.0 0.0" name="start_button" rgba="0.0 0.5 0 0.5"/>
        <geom class="collision" type="box" pos="0.21019979 -0.19022940 -0.08845361" size="0.012152982875704765 0.0006485349731519818 0.010661305859684944" quat="1.0 0.0 0.0 0.0" name="stop_button" rgba="0.0 0.5 0 0.5"/>
        <geom mesh="Body001_vis" type="mesh" solimp="0.998 0.998 0.001" solref="0.001 1" friction="0.95 0.3 0.1" class="visual" material="Body001_material"/>
        <geom class="collision" type="box" pos="0.15546685 0.02762628 0.00226799" size="0.024440431967377663 0.1902388334274292 0.14679104089736938" quat="1.0 0.0 0.0 0.0"/>
        <geom class="collision" type="box" pos="-0.06214744 0.02784108 -0.15128262" size="0.24141666293144226 0.19045361876487732 0.012947039678692818" quat="1.0 0.0 0.0 0.0"/>
        <geom class="collision" type="box" pos="-0.06214744 0.02784108 0.15600638" size="0.24141666293144226 0.19045361876487732 0.00822325237095356" quat="1.0 0.0 0.0 0.0"/>
        <geom class="collision" type="box" pos="-0.06204081 0.19578410 0.00814939" size="0.24152329564094543 0.02251059003174305 0.15125298500061035" quat="1.0 0.0 0.0 0.0"/>
        <geom class="collision" type="box" pos="-0.27918717 0.02784108 0.00431481" size="0.02437685988843441 0.19045361876487732 0.1474177986383438" quat="1.0 0.0 0.0 0.0"/>
        <geom class="collision" type="box" pos="0.24092068 0.01450604 0.00000000" size="0.0626436397433281 0.2037886679172516 0.16422969102859497" quat="1.0 0.0 0.0 0.0"/>
        <body name="door">
          <joint axis="0.0 0.0 1.0" pos="-0.27823880 -0.16256915 0.00000000" limited="true" name="microjoint" range="-1.5707963267948966 0.0" type="hinge" damping="1" frictionloss="1" armature=".01" stiffness="0.05"/>
          <geom mesh="door_vis" type="mesh" solimp="0.998 0.998 0.001" solref="0.001 1" friction="0.95 0.3 0.1" class="visual" material="door_material"/>
          <geom class="collision" type="box" pos="-0.04397308 -0.18410763 -0.00146337" size="0.2210087776184082 0.002577348845079541 0.16276666522026062" quat="1.0 0.0 0.0 0.0"/>
          <geom class="collision" type="box" pos="-0.04397308 -0.17866706 -0.00148614" size="0.21558405458927155 0.002143530873581767 0.1591014713048935" quat="1.0 0.0 0.0 0.0" name="door_main"/>
          <geom class="collision" type="box" pos="0.15720352 -0.19617351 0.13401455" size="0.019342176616191864 0.008749624714255333 0.021491196006536484" quat="0.9371328949928284 -0.3489726781845093 -0.0 0.0"/>
          <geom class="collision" type="box" pos="0.15720352 -0.21261705 0.00313177" size="0.019342176616191864 0.00790762435644865 0.1079619824886322" quat="1.0 0.0 0.0 0.0" name="door_handle_main"/>
          <geom class="collision" type="box" pos="0.15720352 -0.19858710 -0.12997498" size="0.019342176616191864 0.02148124948143959 0.01104703824967146" quat="0.9010329842567444 -0.43375056982040405 -0.0 0.0"/>
          <body name="door_Clear">
            <geom mesh="door_Clear_vis" type="mesh" solimp="0.998 0.998 0.001" solref="0.001 1" friction="0.95 0.3 0.1" class="visual" material="door_Clear_material"/>
            <geom class="collision" type="box" pos="-0.04397308 -0.18410763 -0.00146337" size="0.2210087776184082 0.002577348845079541 0.16276666522026062" quat="1.0 0.0 0.0 0.0"/>
          </body>
        </body>
        <body name="Disc001">
          <joint axis="0.0 0.0 1.0" pos="-0.06085871 0.00446328 -0.13270293" limited="false" name="Disc001_joint" range="0 360" type="hinge" damping="1" frictionloss="1" armature=".01" stiffness="0.05"/>
          <geom mesh="Disc001_vis" type="mesh" solimp="0.998 0.998 0.001" solref="0.001 1" friction="0.95 0.3 0.1" class="visual" material="Disc001_material"/>
          <geom class="collision" type="cylinder" pos="-0.06085872 0.00446329 -0.13405800" size="0.14400441944599152 0.001863789395429194" quat="1.0 0.0 0.0 0.0"/>
        </body>
        <geom class="region" name="reg_int" type="box" pos="-0.062081189999999994 0.006548750000000006 0.00724851" size="0.18819169000000002 0.16329907999999999 0.13434886000000001"/>
        <geom class="region" name="reg_main" type="box" pos="1.0500000000024379e-07 0.014506030000000003 0.0" size="0.304569345 0.2047921 0.16523248"/>
      <geom class="region" name="reg_tray" type="cylinder" pos="-0.06085872 0.00446328 0.007748510899555389" size="0.14400441944599152 0.1328488591004446"/></body>
    </body>
  </worldbody>
  <actuator>
    <motor name="microjoint_actuator" joint="microjoint" gear="10"/>
    <motor name="Disc001_joint_actuator" joint="Disc001_joint" gear="10"/>
  </actuator>
</mujoco>
