<?xml version='1.0' encoding='UTF-8'?>
<mujoco model="model">
  <option timestep="0.002" gravity="0.0 0.0 -9.81"/>
  <compiler angle="radian"/>
  <asset>
    <mesh file="visuals/door.obj" name="door_vis"/>
    <mesh file="visuals/door_Clear.obj" name="door_Clear_vis"/>
    <mesh file="visuals/Body001.obj" name="Body001_vis"/>
    <mesh file="visuals/Disc001.obj" name="Disc001_vis"/>
    <texture file="visuals/T_BC001.png" name="Body001_material" type="2d"/>
    <material name="Body001_material" rgba="1 1 1 1.0" texture="Body001_material" shininess="0.1" specular="5"/>
    <texture file="visuals/T_BC001.png" name="door_material" type="2d"/>
    <material name="door_material" rgba="1 1 1 1.0" texture="door_material" shininess="0.1" specular="5"/>
    <material name="door_Clear_material" rgba="0.03637973591685295 0.03637973591685295 0.03637973591685295 0.800000011920929" shininess="0.4472135901451111" specular="0.3103448502657381"/>
    <texture file="visuals/T_BC001.png" name="Disc001_material" type="2d"/>
    <material name="Disc001_material" rgba="1 1 1 1.0" texture="Disc001_material" shininess="0.1" specular="3"/>
  </asset>
  <default>
    <default class="visual">
      <geom conaffinity="0" contype="0" group="1" type="mesh"/>
    </default>
    <default class="collision">
      <geom group="0" rgba="0.5 0 0 0.5"/>
    </default>
    <default class="spawn">
      <geom group="0" rgba="1 1 1 0.5" contype="0" conaffinity="0"/>
      <site group="0" rgba="1 1 1 0.5"/>
    </default>
    <default class="region">
      <geom group="1" conaffinity="0" contype="0" rgba="0 1 0 0"/>
    </default>
  </default>
  <worldbody>
    <body>
      <body name="object">
        <geom class="collision" type="cylinder" pos="-0.05763543024659157 0.011082738637924194 -0.10156214982271194" size="0.11278744786977768 0.0015410884516313672" quat="1.0 0.0 0.0 0.0" name="tray" rgba="0 1 0 0.5"/>
        <geom class="collision" type="box" pos="0.18966542184352875 -0.14820145070552826 -0.07778368890285492" size="0.010899275541305542 0.0010898024775087833 0.007179934997111559" quat="1.0 0.0 0.0 0.0" name="stop_button" rgba="0.0 0.5 0 0.5"/>
        <geom class="collision" type="box" pos="0.24208709597587585 -0.14820145070552826 -0.07778368890285492" size="0.010918227955698967 0.0010898024775087833 0.007179934997111559" quat="1.0 0.0 0.0 0.0" name="start_button" rgba="0.0 0.5 0 0.5"/>
        <geom mesh="Body001_vis" type="mesh" solimp="0.998 0.998 0.001" solref="0.001 1" friction="0.95 0.3 0.1" class="visual" material="Body001_material"/>
        <geom class="collision" type="box" pos="-0.056501924991607666 0.02996804006397724 -0.13541220128536224" size="0.21580103039741516 0.14951494336128235 0.022396467626094818" quat="1.0 0.0 0.0 0.0"/>
        <geom class="collision" type="box" pos="-0.2644837498664856 0.02996806800365448 0.005621984601020813" size="0.007814238779246807 0.14951471984386444 0.12430824339389801" quat="1.0 0.0 0.0 0.0"/>
        <geom class="collision" type="box" pos="-0.056502893567085266 0.15837810933589935 0.009011216461658478" size="0.2158009260892868 0.02110275626182556 0.12627609074115753" quat="1.0 0.0 0.0 0.0"/>
        <geom class="collision" type="box" pos="-0.056502193212509155 -0.13249026238918304 0.16796237230300903" size="0.2157997041940689 0.015356896445155144 0.009088716469705105" quat="1.0 0.0 0.0 0.0"/>
        <geom class="collision" type="box" pos="0.21454721689224243 0.016870811581611633 0.009099608287215233" size="0.057752255350351334 0.1626121550798416 0.16829968988895416" quat="1.0 0.0 0.0 0.0"/>
        <geom class="collision" type="box" pos="-0.056502893567085266 0.02996855601668358 0.1527765989303589" size="0.21579933166503906 0.14951413869857788 0.024620866402983665" quat="1.0 0.0 0.0 0.0"/>
        <geom class="collision" type="box" pos="0.1473204791545868 0.02996855601668358 0.005621984601020813" size="0.011625275015830994 0.1495138555765152 0.12430691719055176" quat="1.0 0.0 0.0 0.0"/>
        <geom class="collision" type="box" pos="-0.0006951242685317993 -0.09923121333122253 -0.16784480214118958" size="0.24638335406780243 0.018072053790092468 0.00955224223434925" quat="1.0 0.0 0.0 0.0"/>
        <geom class="collision" type="box" pos="-0.0006951242685317993 0.1258891373872757 -0.16784480214118958" size="0.2463831752538681 0.018072042614221573 0.009552236646413803" quat="1.0 0.0 0.0 0.0"/>
        <body name="door">
          <joint axis="0.0 0.0 1.0" pos="-0.25876790285110474 -0.13358816504478455 -0.0004099905490875244" limited="true" name="microjoint" range="-1.5707963267948966 0.0" type="hinge" damping="1" frictionloss="1" armature=".01" stiffness="0.05"/>
          <geom mesh="door_vis" type="mesh" solimp="0.998 0.998 0.001" solref="0.001 1" friction="0.95 0.3 0.1" class="visual" material="door_material"/>
          <geom class="collision" type="box" pos="-0.05747814476490021 -0.1336144506931305 7.297919364646077e-05" size="0.2102060317993164 0.010283015668392181 0.15368500351905823" quat="1.0 0.0 0.0 0.0" name="door_main"/>
          <geom class="collision" type="box" pos="-0.056987322866916656 -0.1371203511953354 -0.0003347874735482037" size="0.15617835521697998 0.006391293369233608 0.09085484594106674" quat="1.0 0.0 0.0 0.0"/>
          <geom class="collision" type="box" pos="0.14707039296627045 -0.17343617975711823 -0.01623465120792389" size="0.008900480344891548 0.005757460370659828 0.08767075091600418" quat="1.0 0.0 0.0 0.0" name="door_handle_main"/>
          <geom class="collision" type="box" pos="0.14707039296627045 -0.15629811584949493 0.09394919127225876" size="0.008900480344891548 0.005757460370659828 0.011349364183843136" quat="0.823179304599762 -0.5677815079689026 -0.0 0.0"/>
          <geom class="collision" type="box" pos="0.14707039296627045 -0.16797927021980286 0.08249380439519882" size="0.008900480344891548 0.005757460370659828 0.009123585186898708" quat="0.969722330570221 -0.24421025812625885 -0.0 0.0"/>
          <geom class="collision" type="box" pos="0.14707039296627045 -0.16796772181987762 -0.11498462408781052" size="0.008900480344891548 0.005757460370659828 0.009099206887185574" quat="0.969722330570221 0.24421025812625885 0.0 0.0"/>
          <geom class="collision" type="box" pos="0.14707039296627045 -0.15629811584949493 -0.12641854584217072" size="0.008900480344891548 0.005757460370659828 0.011349364183843136" quat="0.823179304599762 0.5677815079689026 0.0 0.0"/>
          <body name="door_Clear">
            <geom mesh="door_Clear_vis" type="mesh" solimp="0.998 0.998 0.001" solref="0.001 1" friction="0.95 0.3 0.1" class="visual" material="door_Clear_material"/>
            <geom class="collision" type="box" pos="-0.056987322866916656 -0.1371203511953354 -0.0003347874735482037" size="0.15617835521697998 0.006391293369233608 0.09085484594106674" quat="1.0 0.0 0.0 0.0"/>
          </body>
        </body>
        <body name="Disc001">
          <joint axis="0.0 0.0 1.0" pos="-0.05763543024659157 0.011082738637924194 -0.10824134945869446" limited="false" name="Disc001_joint" range="0 360" type="hinge" damping="1" frictionloss="1" armature=".01" stiffness="0.05"/>
          <geom mesh="Disc001_vis" type="mesh" solimp="0.998 0.998 0.001" solref="0.001 1" friction="0.95 0.3 0.1" class="visual" material="Disc001_material"/>
          <geom class="collision" type="cylinder" pos="-0.05763543024659157 0.011082738637924194 -0.10780636221170425" size="0.11278744786977768 0.0032994139473885298" quat="1.0 0.0 0.0 0.0"/>
        </body>
        <geom class="region" name="reg_int" type="box" pos="-0.06023099273443222 0.009272120893001556 0.008165735751390457" size="0.19178583270311356 0.12373214012384415 0.11562149396538735"/>
        <geom class="region" name="reg_main" type="box" pos="0.0 0.015749968588352203 7.450580596923828e-09" size="0.27329833602905274 0.1647307107448578 0.17839704251289368"/>
      </body>
    </body>
  </worldbody>
  <actuator>
    <motor name="microjoint_actuator" joint="microjoint" gear="10"/>
    <motor name="Disc001_joint_actuator" joint="Disc001_joint" gear="10"/>
  </actuator>
</mujoco>
