<?xml version='1.0' encoding='UTF-8'?>
<mujoco model="model">
  <option timestep="0.002" gravity="0.0 0.0 -9.81"/>
  <compiler angle="radian"/>
  <asset>
    <mesh file="visuals/door.obj" name="door_vis"/>
    <mesh file="visuals/door_Clear.obj" name="door_Clear_vis"/>
    <mesh file="visuals/Body001.obj" name="Body001_vis"/>
    <mesh file="visuals/Button001.obj" name="Button001_vis"/>
    <mesh file="visuals/Button002.obj" name="Button002_vis"/>
    <mesh file="visuals/Disc001.obj" name="Disc001_vis"/>
    <texture file="visuals/T_BC001.png" name="Body001_material" type="2d"/>
    <material name="Body001_material" rgba="1 1 1 1.0" texture="Body001_material" shininess="1" specular="1"/>
    <texture file="visuals/T_BC001.png" name="door_material" type="2d"/>
    <material name="door_material" rgba="1 1 1 1.0" texture="door_material" shininess="1" specular="1"/>
    <texture file="visuals/T_BC001.png" name="door_Clear_material" type="2d"/>
    <material name="door_Clear_material" rgba="1 1 1 0.800000011920929" texture="door_Clear_material" shininess="0.5" specular="0.3103448502657381"/>
    <texture file="visuals/T_BC001.png" name="Button001_material" type="2d"/>
    <material name="Button001_material" rgba="1 1 1 1.0" texture="Button001_material" shininess="2" specular="2"/>
    <texture file="visuals/T_BC001.png" name="Button002_material" type="2d"/>
    <material name="Button002_material" rgba="1 1 1 1.0" texture="Button002_material" shininess="2" specular="2"/>
    <texture file="visuals/T_BC001.png" name="Disc001_material" type="2d"/>
    <material name="Disc001_material" rgba="1 1 1 1.0" texture="Disc001_material" shininess="0.5" specular="0.5"/>
  </asset>
  <default>
    <default class="visual">
      <geom conaffinity="0" contype="0" group="1" type="mesh"/>
    </default>
    <default class="collision">
      <geom group="0" rgba="0.5 0 0 0.5"/>
    </default>
    <default class="spawn">
      <geom group="0" rgba="1 1 1 0.5" contype="0" conaffinity="0"/>
      <site group="0" rgba="1 1 1 0.5"/>
    </default>
    <default class="region">
      <geom group="1" conaffinity="0" contype="0" rgba="0 1 0 0"/>
    </default>
  </default>
  <worldbody>
    <body>
      <body name="object">
        <geom class="collision" type="box" pos="0.2170172929763794 -0.2324933558702469 -0.12825287878513336" size="0.013190911151468754 0.0007031083223409951 0.00708899786695838" quat="1.0 0.0 0.0 0.0" name="start_button" rgba="0.0 0.5 0 0.5"/>
        <geom class="collision" type="box" pos="0.2730391323566437 -0.2324933558702469 -0.128305122256279" size="0.013190911151468754 0.0007031083223409951 0.00708899786695838" quat="1.0 0.0 0.0 0.0" name="stop_button" rgba="0.0 0.5 0 0.5"/>
        <geom class="collision" type="cylinder" pos="-0.06485994160175323 -0.003092189086601138 -0.13669924437999725" size="0.17225393652915955 0.0020208321511745453" quat="1.0 0.0 0.0 0.0" name="tray" rgba="0 1 0 0.5"/>
        <geom mesh="Body001_vis" type="mesh" solimp="0.998 0.998 0.001" solref="0.001 1" friction="0.95 0.3 0.1" class="visual" material="Body001_material"/>
        <geom class="collision" type="box" pos="-0.2810915410518646 0.04335606098175049 -0.004970035515725613" size="0.02083211950957775 0.23652443289756775 0.16998417675495148" quat="1.0 0.0 0.0 0.0"/>
        <geom class="collision" type="box" pos="0.2249555140733719 0.04335606098175049 -0.004970035515725613" size="0.07696817070245743 0.23652443289756775 0.16998417675495148" quat="1.0 0.0 0.0 0.0"/>
        <geom class="collision" type="box" pos="-0.056588929146528244 0.0433560386300087 0.14594468474388123" size="0.019069449976086617 0.23652443289756775 0.20546723902225494" quat="0.70710688829422 -4.7503014855010406e-08 0.7071066498756409 4.750300064415569e-08"/>
        <geom class="collision" type="box" pos="-0.056588925421237946 0.0433560386300087 -0.16193974018096924" size="0.013014478608965874 0.23652443289756775 0.20546723902225494" quat="0.70710688829422 -4.7503014855010406e-08 0.7071066498756409 4.750300064415569e-08"/>
        <geom class="collision" type="box" pos="-0.05658893287181854 0.23112283647060394 -0.009975007735192776" size="0.04875762015581131 0.1417888104915619 0.20546723902225494" quat="0.5000001788139343 0.4999999701976776 0.49999988079071045 0.4999999701976776"/>
        <geom class="collision" type="box" pos="-0.0026048514991998672 0.03995060920715332 0.17033837735652924" size="0.004890400916337967 0.1754380464553833 0.25124871730804443" quat="0.70710688829422 -4.7503014855010406e-08 0.7071066498756409 4.750300064415569e-08"/>
        <geom class="collision" type="box" pos="-0.3070313334465027 0.03993083909153938 -0.004857384599745274" size="0.00526044238358736 0.18542003631591797 0.1247829794883728" quat="1.0 -4.004205956609566e-15 -5.960462701182223e-08 -6.717943534795268e-08"/>
        <geom class="collision" type="box" pos="0.3070269525051117 0.03993083909153938 -0.004857384599745274" size="0.005264845676720142 0.18542003631591797 0.1247829794883728" quat="1.0 -4.004205956609566e-15 -5.960462701182223e-08 -6.717943534795268e-08"/>
        <geom class="collision" type="box" pos="0.24569323658943176 -0.21022270619869232 0.023446135222911835" size="0.05623043701052666 0.018931111320853233 0.14129340648651123" quat="1.0 0.0 0.0 0.0"/>
        <geom class="collision" type="box" pos="0.24569323658943176 -0.21022270619869232 -0.1576344519853592" size="0.05623043701052666 0.018931111320853233 0.017594337463378906" quat="1.0 0.0 0.0 0.0"/>
        <geom class="collision" type="box" pos="0.24569323658943176 -0.2079225480556488 -0.12884315848350525" size="0.05623043701052666 0.01457893755286932 0.011523762717843056" quat="1.0 0.0 0.0 0.0"/>
        <body name="door">
          <joint axis="0.0 0.0 1.0" pos="-0.283446729183197 -0.212793231010437 -0.005244613625109196" limited="true" name="microjoint" range="-1.5707963267948966 0.0" type="hinge" damping="1" frictionloss="1" armature=".01" stiffness="0.05"/>
          <geom mesh="door_vis" type="mesh" solimp="0.998 0.998 0.001" solref="0.001 1" friction="0.95 0.3 0.1" class="visual" material="door_material"/>
          <geom class="collision" type="box" pos="-0.06626242399215698 -0.2195109874010086 0.000930391252040863" size="0.004811004735529423 0.08865528553724289 0.16809029877185822" quat="0.5 0.5 0.5 0.4999999701976776"/>
          <geom class="collision" type="box" pos="-0.25767752528190613 -0.21287856996059418 -0.0052445982582867146" size="0.017992716282606125 0.16998417675495148 0.024036355316638947" quat="0.5000001192092896 0.5 0.4999999701976776 0.4999999403953552"/>
          <geom class="collision" type="box" pos="0.14439988136291504 -0.21287856996059418 -0.0052445996552705765" size="0.017992716282606125 0.16998417675495148 0.042897239327430725" quat="0.5000001192092896 0.5 0.4999999701976776 0.4999999403953552"/>
          <geom class="collision" type="box" pos="-0.06586045026779175 -0.21287858486175537 0.12792454659938812" size="0.017992716282606125 0.16998417675495148 0.03681502491235733" quat="7.472144858411411e-08 0.7071067094802856 0.7071068286895752 3.204871035222823e-08"/>
          <geom class="collision" type="box" pos="-0.06586045026779175 -0.21287858486175537 -0.1322387456893921" size="0.017992716282606125 0.16998417675495148 0.04299004003405571" quat="7.472144858411411e-08 0.7071067094802856 0.7071068286895752 3.204871035222823e-08"/>
          <geom class="collision" type="box" pos="0.14502070844173431 -0.239515021443367 0.12920789420604706" size="0.009858377277851105 0.007453942205756903 0.0165408905595541" quat="0.49999985098838806 0.5 -0.5000001788139343 -0.4999999403953552"/>
          <geom class="collision" type="box" pos="0.14502070844173431 -0.25534072518348694 0.10102148354053497" size="0.027371153235435486 0.004483749158680439 0.0165408905595541" quat="0.1339872181415558 0.6942963004112244 -0.13398760557174683 -0.6942963600158691"/>
          <geom class="collision" type="box" pos="0.14502070844173431 -0.2660098373889923 0.06678104400634766" size="0.013699657283723354 0.004483749158680439 0.0165408905595541" quat="0.06278831511735916 0.7043134570121765 -0.06278905272483826 -0.7043136358261108"/>
          <geom class="collision" type="box" pos="0.14502070844173431 -0.239515021443367 -0.14015492796897888" size="0.009858377277851105 0.007453942205756903 0.0165408905595541" quat="0.5000001192092896 -0.5 0.5 -0.49999988079071045"/>
          <geom class="collision" type="box" pos="0.14502070844173431 -0.25534072518348694 -0.11113370954990387" size="0.027371156960725784 0.004483749158680439 0.0165408905595541" quat="0.13398754596710205 -0.6942963004112244 0.1339874416589737 -0.6942963004112244"/>
          <geom class="collision" type="box" pos="0.14502070844173431 -0.2660098373889923 -0.07689327001571655" size="0.01369965635240078 0.004483748693019152 0.0165408905595541" quat="0.06278873980045319 -0.7043135762214661 0.06278879940509796 -0.7043135166168213"/>
          <geom class="collision" type="box" pos="0.14502070844173431 -0.2723143994808197 -0.005302442237734795" size="0.006134434603154659 0.05374417454004288 0.0165408905595541" quat="0.4999999403953552 0.4999999701976776 -0.5000001192092896 -0.4999999701976776" name="door_handle_main"/>
          <geom class="collision" type="box" pos="-0.06626242399215698 -0.2228299230337143 0.000930391252040863" size="0.004811004735529423 0.15572629868984222 0.2174280881881714" quat="0.5000001192092896 0.5 0.4999999701976776 0.4999999403953552" name="door_main"/>
          <body name="door_Clear">
            <geom mesh="door_Clear_vis" type="mesh" solimp="0.998 0.998 0.001" solref="0.001 1" friction="0.95 0.3 0.1" class="visual" material="door_Clear_material"/>
            <geom class="collision" type="box" pos="-0.06626242399215698 -0.2195109874010086 0.000930391252040863" size="0.004811004735529423 0.08865528553724289 0.16809029877185822" quat="0.5 0.5 0.5 0.4999999701976776"/>
          </body>
        </body>
        <body name="Button001">
          <joint axis="0.0 1.0 0.0" pos="0.2170172929763794 -0.2312849909067154 -0.12825287878513336" limited="true" name="Button001_joint" range="0.0 0.0025" type="slide" damping="1" frictionloss="1" armature=".01" stiffness="0.05"/>
          <geom mesh="Button001_vis" type="mesh" solimp="0.998 0.998 0.001" solref="0.001 1" friction="0.95 0.3 0.1" class="visual" material="Button001_material"/>
          <geom class="collision" type="box" pos="0.2170172929763794 -0.2301047444343567 -0.12825287878513336" size="0.013190911151468754 0.0007031083223409951 0.00708899786695838" quat="1.0 0.0 0.0 0.0"/>
        </body>
        <body name="Button002">
          <joint axis="0.0 1.0 0.0" pos="0.2730391323566437 -0.2312849909067154 -0.128305122256279" limited="true" name="Button002_joint" range="0.0 0.0025" type="slide" damping="1" frictionloss="1" armature=".01" stiffness="0.05"/>
          <geom mesh="Button002_vis" type="mesh" solimp="0.998 0.998 0.001" solref="0.001 1" friction="0.95 0.3 0.1" class="visual" material="Button002_material"/>
          <geom class="collision" type="box" pos="0.2730391323566437 -0.2301047444343567 -0.128305122256279" size="0.013190911151468754 0.0007031083223409951 0.00708899786695838" quat="1.0 0.0 0.0 0.0"/>
        </body>
        <body name="Disc001">
          <joint axis="0.0 0.0 1.0" pos="-0.06485994160175323 -0.003092189086601138 -0.14052611589431763" limited="false" name="Disc001_joint" range="0 360" type="hinge" damping="1" frictionloss="1" armature=".01" stiffness="0.05"/>
          <geom mesh="Disc001_vis" type="mesh" solimp="0.998 0.998 0.001" solref="0.001 1" friction="0.95 0.3 0.1" class="visual" material="Disc001_material"/>
          <geom class="collision" type="cylinder" pos="-0.06485994160175323 -0.003092189086601138 -0.1436263620853424" size="0.17225393652915955 0.002952506300061941" quat="1.0 0.0 0.0 0.0"/>
        </body>
        <geom class="region" name="reg_int" type="box" pos="-0.05545978248119354 -0.005378492176532745 -0.008351840078830719" size="0.1951920965909958 0.18022737449407578 0.12732658332586289"/>
        <geom class="region" name="reg_main" type="box" pos="-5.809317027427596e-09 0.02450425736606121 0.0" size="0.31329180097579956 0.2563762197494507 0.1762288043498993"/>
      </body>
    </body>
  </worldbody>
  <actuator>
    <motor name="microjoint_actuator" joint="microjoint" gear="10"/>
    <motor name="Button001_joint_actuator" joint="Button001_joint" gear="0.5"/>
    <motor name="Button002_joint_actuator" joint="Button002_joint" gear="0.5"/>
    <motor name="Disc001_joint_actuator" joint="Disc001_joint" gear="0.5"/>
  </actuator>
</mujoco>
