<?xml version='1.0' encoding='UTF-8'?>
<mujoco model="model">
  <option timestep="0.0005" gravity="0.0 0.0 -9.81"/>
  <compiler angle="radian"/>
  <asset>
    <mesh file="visuals/sideL_button_cancel.obj" name="sideL_button_cancel_vis"/>
    <mesh file="visuals/sideL_knob_doneness.obj" name="sideL_knob_doneness_vis"/>
    <mesh file="visuals/sideL_lever.obj" name="sideL_lever_vis"/>
    <mesh file="visuals/sideR_button_cancel.obj" name="sideR_button_cancel_vis"/>
    <mesh file="visuals/sideR_knob_doneness.obj" name="sideR_knob_doneness_vis"/>
    <mesh file="visuals/sideR_lever.obj" name="sideR_lever_vis"/>
    <mesh file="visuals/Body001.obj" name="Body001_vis"/>
    <mesh file="visuals/Body001_Clear.obj" name="Body001_Clear_vis"/>
    <mesh file="visuals/Body002.obj" name="Body002_vis"/>
    <texture file="visuals/T_BC001.png" name="Body001_material" type="2d"/>
    <material name="Body001_material" rgba="1 1 1 1.0" texture="Body001_material" shininess="0.5" specular="0.5"/>
    <texture file="visuals/T_BC001.png" name="sideL_button_cancel_material" type="2d"/>
    <material name="sideL_button_cancel_material" rgba="1 1 1 1.0" texture="sideL_button_cancel_material" shininess="0.5" specular="0.5"/>
    <texture file="visuals/T_BC001.png" name="sideL_knob_doneness_material" type="2d"/>
    <material name="sideL_knob_doneness_material" rgba="1 1 1 1.0" texture="sideL_knob_doneness_material" shininess="0.5" specular="0.5"/>
    <texture file="visuals/T_BC001.png" name="sideL_lever_material" type="2d"/>
    <material name="sideL_lever_material" rgba="1 1 1 1.0" texture="sideL_lever_material" shininess="0.5" specular="0.5"/>
    <texture file="visuals/T_BC001.png" name="sideR_button_cancel_material" type="2d"/>
    <material name="sideR_button_cancel_material" rgba="1 1 1 1.0" texture="sideR_button_cancel_material" shininess="0.5" specular="0.5"/>
    <texture file="visuals/T_BC001.png" name="sideR_knob_doneness_material" type="2d"/>
    <material name="sideR_knob_doneness_material" rgba="1 1 1 1.0" texture="sideR_knob_doneness_material" shininess="0.5" specular="0.5"/>
    <texture file="visuals/T_BC001.png" name="sideR_lever_material" type="2d"/>
    <material name="sideR_lever_material" rgba="1 1 1 1.0" texture="sideR_lever_material" shininess="0.5" specular="0.5"/>
    <texture file="visuals/T_BC001.png" name="Body001_Clear_material" type="2d"/>
    <material name="Body001_Clear_material" rgba="1 1 1 0.699999988079071" texture="Body001_Clear_material" shininess="0.5" specular="0.5"/>
    <texture file="visuals/T_BC001.png" name="Body002_material" type="2d"/>
    <material name="Body002_material" rgba="1 1 1 1.0" texture="Body002_material" shininess="0.5" specular="8"/>
  </asset>
  <default>
    <default class="visual">
      <geom conaffinity="0" contype="0" group="1" type="mesh"/>
    </default>
    <default class="collision_1">
      <geom group="0" rgba="0.5 0 0 0.5" solref="0.001 1" solimp="0.998 0.998 0.001"/>
    </default>
    <default class="collision_2">
      <geom group="0" rgba="0.5 0 0 0.5" solref="0.001 1" solimp="0.998 0.998 0.001"/>
    </default>
    <default class="collision_3">
      <geom group="0" rgba="0.5 0 0 0.5" solref="0.001 1" solimp="0.998 0.998 0.001"/>
    </default>
    <default class="collision_4">
      <geom group="0" rgba="0.5 0 0 0.5" solref="0.001 1" solimp="0.998 0.998 0.001"/>
    </default>
    <default class="collision_5">
      <geom group="0" rgba="0.5 0 0 0.5" solref="0.001 1" solimp="0.998 0.998 0.001"/>
    </default>
    <default class="collision_6">
      <geom group="0" rgba="0.5 0 0 0.5" solref="0.001 1" solimp="0.998 0.998 0.001"/>
    </default>
    <default class="collision_7">
      <geom group="0" rgba="0.5 0 0 0.5" solref="0.001 1" solimp="0.998 0.998 0.001"/>
    </default>
    <default class="collision_8">
      <geom group="0" rgba="0.5 0 0 0.5" solref="0.001 1" solimp="0.998 0.998 0.001"/>
    </default>
    <default class="collision_9">
      <geom group="0" rgba="0.5 0 0 0.5" solref="0.001 1" solimp="0.998 0.998 0.001"/>
    </default>
    <default class="spawn">
      <geom group="0" rgba="1 1 1 0.5" contype="0" conaffinity="0"/>
      <site group="0" rgba="1 1 1 0.5"/>
    </default>
    <default class="region">
      <geom group="1" conaffinity="0" contype="0" rgba="0 1 0 0" mass="0"/>
    </default>
  </default>
  <worldbody>
    <body>
      <body name="object">
        <geom mesh="Body001_vis" type="mesh" solimp="0.998 0.998 0.001" solref="0.001 1" friction="0.95 0.3 0.1" class="visual" material="Body001_material"/>
        <geom type="box" pos="0.0 0.02383670210838318 -0.07956255972385406" size="0.1396116316318512 0.1427888572216034 0.021233409643173218" quat="1.0 0.0 0.0 0.0" class="collision_1"/>
        <geom type="box" pos="-0.002511797472834587 0.024484198540449142 0.020840924233198166" size="0.012622736394405365 0.14278659224510193 0.07956795394420624" quat="1.0 0.0 0.0 0.0" class="collision_1"/>
        <geom type="box" pos="-0.05631228908896446 0.024484198540449142 0.020840924233198166" size="0.009034966118633747 0.1427888572216034 0.07956790179014206" quat="1.0 0.0 0.0 0.0" class="collision_1"/>
        <geom type="box" pos="0.05267892777919769 0.024484198540449142 0.020840924233198166" size="0.009521727450191975 0.1427888572216034 0.07956849783658981" quat="1.0 0.0 0.0 0.0" class="collision_1"/>
        <geom type="box" pos="0.1164533868432045 0.024484198540449142 0.020840924233198166" size="0.02191537246108055 0.1427888572216034 0.07956789433956146" quat="1.0 0.0 0.0 0.0" class="collision_1"/>
        <geom type="box" pos="-0.1181488037109375 0.024484198540449142 0.020840924233198166" size="0.022364497184753418 0.1427888572216034 0.07956793159246445" quat="1.0 0.0 0.0 0.0" class="collision_1"/>
        <geom type="box" pos="-0.0024718253407627344 0.14158692955970764 0.020840924233198166" size="0.14278772473335266 0.02127535082399845 0.07956849783658981" quat="1.0 0.0 0.0 0.0" class="collision_1"/>
        <geom type="box" pos="-0.0024718253407627344 -0.09994810074567795 0.020840924233198166" size="0.1427888721227646 0.017911167815327644 0.07956849783658981" quat="1.0 0.0 0.0 0.0" class="collision_1"/>
        <body name="sideL_button_cancel">
          <joint axis="0.0 1.0 0.0" pos="-0.038676097989082336 -0.1279504895210266 -0.061730995774269104" limited="true" name="sideL_button_cancel_joint" range="0.0 0.002" type="slide" damping="1" frictionloss="1" armature=".01" stiffness="0.05"/>
          <geom mesh="sideL_button_cancel_vis" type="mesh" solimp="0.998 0.998 0.001" solref="0.001 1" friction="0.95 0.3 0.1" class="visual" material="sideL_button_cancel_material"/>
          <geom class="collision_2" type="box" pos="-0.03865706920623779 -0.1282956600189209 -0.06188366562128067" size="0.010698146186769009 0.0017508299788460135 0.0060849785804748535" quat="1.0 0.0 0.0 0.0" name="sideL_button_cancel_main"/>
        </body>
        <body name="sideL_knob_doneness">
          <joint axis="0.0 1.0 0.0" pos="-0.0881413146853447 -0.13498832285404205 -0.06467341631650925" limited="true" name="sideL_knob_doneness_joint" range="0.0 1.3613568165555772" type="hinge" damping="0.05" armature="0.001"/>
          <geom mesh="sideL_knob_doneness_vis" type="mesh" solimp="0.998 0.998 0.001" solref="0.001 1" friction="0.95 0.3 0.1" class="visual" material="sideL_knob_doneness_material"/>
          <geom type="cylinder" pos="-0.08803896605968475 -0.12728014588356018 -0.06447699666023254" size="0.0105937160551548 0.007022842299193144" quat="0.7071067094802856 0.70710688829422 -1.5700925641616852e-16 1.2790027470567158e-23" class="collision_3"/>
          <geom class="collision_3" type="box" pos="-0.08849649131298065 -0.13935637474060059 -0.0644083321094513" size="0.009871277026832104 0.0052429018542170525 0.0041764602065086365" quat="0.913242757320404 -0.012167119421064854 0.4063149094581604 -0.027347063645720482" name="sideL_knob_doneness_main"/>
        </body>
        <body name="sideL_lever">
          <joint axis="0.0 0.0 -1.0" pos="-0.05561074614524841 -0.12576138973236084 0.04718846455216408" limited="true" name="sideL_lever_joint" range="0.0 0.06" type="slide" damping="1" frictionloss="1" armature=".01" stiffness="1" springref="-2"/>
          <geom class="region" name="reg_sideL_slotR" type="box" pos="-0.03221330139786005 0.01651814579963684 0.09982879273593426" size="0.01200150402635336 0.09634672647714615 0.07600007934868336"/>
          <geom class="region" name="reg_sideL_slotL" type="box" pos="-0.08070797100663185 0.01651814579963684 0.09982879273593426" size="0.012726837605237962 0.09634672647714615 0.07600007934868336"/>
          <geom mesh="sideL_lever_vis" type="mesh" solimp="0.998 0.998 0.001" solref="0.001 1" friction="0.95 0.3 0.1" class="visual" material="sideL_lever_material"/>
          <geom class="collision_4" type="box" pos="-0.05582137405872345 -0.14965349435806274 0.042099479585886" size="0.029944639652967453 0.012194793671369553 0.006245047319680452" quat="1.0 0.0 0.0 0.0" name="sideL_lever_handle"/>
          <geom type="box" pos="-0.05582137405872345 -0.1374954879283905 0.044318266212940216" size="0.03413311764597893 0.0022110927384346724 0.008191976696252823" quat="1.0 0.0 0.0 0.0" class="collision_4"/>
          <geom type="box" pos="-0.05582137405872345 -0.14618918299674988 0.05301307141780853" size="0.00586021738126874 0.010034912265837193 0.006292618345469236" quat="1.0 0.0 0.0 0.0" class="collision_4"/>
          <geom type="box" pos="-0.05582137778401375 -0.13273417949676514 0.048948291689157486" size="0.0011697284644469619 0.003333111060783267 0.008165816776454449" quat="1.0 0.0 0.0 0.0" class="collision_4"/>
          <geom class="collision_4" type="box" pos="-0.07968541234731674 0.017848428338766098 0.016633473336696625" size="0.012999999336898327 0.09567852318286896 0.0028953137807548046" quat="1.0 0.0 0.0 0.0" name="sideL_slotL_floor"/>
          <geom class="collision_4" type="box" pos="-0.03226739913225174 0.017848428338766098 0.016633473336696625" size="0.012999999336898327 0.0956784337759018 0.0028953133150935173" quat="1.0 0.0 0.0 0.0" name="sideL_slotR_floor"/>
        </body>
        <body name="sideR_button_cancel">
          <joint axis="0.0 1.0 0.0" pos="0.07016493380069733 -0.1279504895210266 -0.061730995774269104" limited="true" name="sideR_button_cancel_joint" range="0.0 0.002" type="slide" damping="1" frictionloss="1" armature=".01" stiffness="0.05"/>
          <geom mesh="sideR_button_cancel_vis" type="mesh" solimp="0.998 0.998 0.001" solref="0.001 1" friction="0.95 0.3 0.1" class="visual" material="sideR_button_cancel_material"/>
          <geom class="collision_5" type="box" pos="0.07016493380069733 -0.1282956600189209 -0.06188366562128067" size="0.010698146186769009 0.0017508299788460135 0.0060849785804748535" quat="1.0 0.0 0.0 0.0" name="sideR_button_cancel_main"/>
        </body>
        <body name="sideR_knob_doneness">
          <joint axis="0.0 1.0 0.0" pos="0.019079558551311493 -0.13498832285404205 -0.06467341631650925" limited="true" name="sideR_knob_doneness_joint" range="0.0 1.3613568165555772" type="hinge" damping="0.05" armature="0.001"/>
          <geom mesh="sideR_knob_doneness_vis" type="mesh" solimp="0.998 0.998 0.001" solref="0.001 1" friction="0.95 0.3 0.1" class="visual" material="sideR_knob_doneness_material"/>
          <geom type="cylinder" pos="0.019075173884630203 -0.12729212641716003 -0.06447699666023254" size="0.0105937160551548 0.007022842299193144" quat="0.7071067094802856 0.70710688829422 -1.5700925641616852e-16 1.2790027470567158e-23" class="collision_6"/>
          <geom class="collision_6" type="box" pos="0.01896749809384346 -0.1394963562488556 -0.06417219340801239" size="0.010065554641187191 0.00524289533495903 0.004181316588073969" quat="0.904408872127533 -0.012745060957968235 0.4256156384944916 -0.02708256058394909" name="sideR_knob_doneness_main"/>
        </body>
        <body name="sideR_lever">
          <joint axis="0.0 0.0 -1.0" pos="0.05279482901096344 -0.12591958045959473 0.04718847945332527" limited="true" name="sideR_lever_joint" range="0.0 0.06" type="slide" damping="1" frictionloss="1" armature=".01" stiffness="1" springref="-2"/>
          <geom class="region" name="reg_sideR_slotR" type="box" pos="0.07813480123877525 0.01651814579963684 0.09982879273593426" size="0.01450325718522072 0.09634672647714615 0.07600007934868336"/>
          <geom class="region" name="reg_sideR_slotL" type="box" pos="0.02685373369604349 0.01651814579963684 0.09982879273593426" size="0.01355114283412695 0.09634672647714615 0.07600007934868336"/>
          <geom mesh="sideR_lever_vis" type="mesh" solimp="0.998 0.998 0.001" solref="0.001 1" friction="0.95 0.3 0.1" class="visual" material="sideR_lever_material"/>
          <geom class="collision_7" type="box" pos="0.05283983051776886 -0.14965349435806274 0.042099479585886" size="0.02994448132812977 0.012194799259305 0.0062450505793094635" quat="1.0 0.0 0.0 0.0" name="sideR_lever_handle"/>
          <geom type="box" pos="0.05283983051776886 -0.1374954879283905 0.044318266212940216" size="0.03413292393088341 0.0022110939025878906 0.008191999979317188" quat="1.0 0.0 0.0 0.0" class="collision_7"/>
          <geom type="box" pos="0.05283983051776886 -0.14618918299674988 0.05301307141780853" size="0.00586021738126874 0.01003484521061182 0.006292618345469236" quat="1.0 0.0 0.0 0.0" class="collision_7"/>
          <geom type="box" pos="0.05283983051776886 -0.13273417949676514 0.048948291689157486" size="0.0011697284644469619 0.0031088492833077908 0.008165722712874413" quat="1.0 0.0 0.0 0.0" class="collision_7"/>
          <geom class="collision_7" type="box" pos="0.026323795318603516 0.017848428338766098 0.016633473336696625" size="0.012999999336898327 0.09567797183990479 0.0028953116852790117" quat="1.0 0.0 0.0 0.0" name="sideR_slotL_floor"/>
          <geom class="collision_7" type="box" pos="0.07960101217031479 0.017848428338766098 0.016633473336696625" size="0.012999999336898327 0.09567788243293762 0.0028953112196177244" quat="1.0 0.0 0.0 0.0" name="sideR_slotR_floor"/>
        </body>
        <body name="Body001_Clear">
          <geom mesh="Body001_Clear_vis" type="mesh" solimp="0.998 0.998 0.001" solref="0.001 1" friction="0.95 0.3 0.1" class="visual" material="Body001_Clear_material"/>
          <geom type="box" pos="-0.08873660862445831 -0.12673139572143555 -0.03657145798206329" size="0.02941889874637127 0.0005183819448575377 0.013261654414236546" quat="1.0 0.0 0.0 0.0" class="collision_8"/>
          <geom type="box" pos="0.016700049862265587 -0.12673139572143555 -0.03657145798206329" size="0.02941889874637127 0.0005183819448575377 0.013261654414236546" quat="1.0 0.0 0.0 0.0" class="collision_8"/>
        </body>
        <body name="Body002">
          <geom mesh="Body002_vis" type="mesh" solimp="0.998 0.998 0.001" solref="0.001 1" friction="0.95 0.3 0.1" class="visual" material="Body002_material"/>
        </body>
        <geom class="region" name="reg_main" type="box" pos="0.0 0.01704566180706024 0.0" size="0.1412430683374405 0.14566173946857452 0.10215334391593933"/>
      </body>
    </body>
  </worldbody>
  <actuator>
    <motor name="sideL_button_cancel_joint_actuator" joint="sideL_button_cancel_joint" gear="0.1"/>
    <motor name="sideL_knob_doneness_joint_actuator" joint="sideL_knob_doneness_joint" gear="5"/>
    <motor name="sideL_lever_joint_actuator" joint="sideL_lever_joint" gear="1.5"/>
    <motor name="sideR_button_cancel_joint_actuator" joint="sideR_button_cancel_joint" gear="0.1"/>
    <motor name="sideR_knob_doneness_joint_actuator" joint="sideR_knob_doneness_joint" gear="5"/>
    <motor name="sideR_lever_joint_actuator" joint="sideR_lever_joint" gear="1.5"/>
  </actuator>
</mujoco>
