<?xml version='1.0' encoding='UTF-8'?>
<mujoco model="model">
  <option timestep="0.002" gravity="0.0 0.0 -9.81"/>
  <compiler angle="radian"/>
  <asset>
    <mesh file="visuals/handle.obj" name="handle_vis"/>
    <mesh file="visuals/Body001.obj" name="Body001_vis"/>
    <mesh file="visuals/spout.obj" name="spout_vis"/>
    <texture file="visuals/T_BC001.png" name="Body001_material" type="2d"/>
    <material name="Body001_material" rgba="1 1 1 1.0" texture="Body001_material" shininess="0.228035569190979" specular="0.8"/>
    <texture file="visuals/T_BC001.png" name="handle_material" type="2d"/>
    <material name="handle_material" rgba="1 1 1 1.0" texture="handle_material" shininess="0.228035569190979" specular="0.8"/>
    <texture file="visuals/T_BC001.png" name="spout_material" type="2d"/>
    <material name="spout_material" rgba="1 1 1 1.0" texture="spout_material" shininess="0.228035569190979" specular="0.8"/>
  </asset>
  <default>
    <default class="visual">
      <geom conaffinity="0" contype="0" group="1" type="mesh"/>
    </default>
    <default class="collision">
      <geom group="0" rgba="0.5 0 0 0.5" solimp="0.998 0.998 0.001" solref="0.001 2"/>
    </default>
    <default class="spawn">
      <geom group="0" rgba="1 1 1 0.5" contype="0" conaffinity="0"/>
      <site group="0" rgba="1 1 1 0.5"/>
    </default>
    <default class="region">
      <geom group="1" conaffinity="0" contype="0" rgba="0 1 0 0"/>
    </default>
  </default>
  <worldbody>
    <body>
      <body name="object">
        <geom mesh="Body001_vis" type="mesh" solimp="0.998 0.998 0.001" solref="0.001 1" friction="0.95 0.3 0.1" class="visual" material="Body001_material"/>
        <geom type="box" pos="-0.49512535 0.00277162 -0.22844447" size="0.019095981493592262 0.3433080017566681 0.09792235493659973" quat="1.0 0.0 0.0 0.0" class="collision"/>
        <geom type="box" pos="0.49499223 -0.00008141 -0.22844448" size="0.019229060038924217 0.3459986448287964 0.09792245924472809" quat="1.0 0.0 0.0 0.0" class="collision"/>
        <geom type="box" pos="0.06663767 -0.05228325 -0.23323714" size="0.01861174777150154 0.2560826539993286 0.09312988072633743" quat="1.0 0.0 0.0 0.0" class="collision"/>
        <geom type="box" pos="0.00052798 0.27004288 -0.22844448" size="0.47443079948425293 0.07587803155183792 0.09792265295982361" quat="1.0 0.0 0.0 0.0" class="collision"/>
        <geom type="box" pos="0.00052798 -0.32402457 -0.22844448" size="0.47443121671676636 0.02185858227312565 0.09792274981737137" quat="1.0 0.0 0.0 0.0" class="collision"/>
        <geom type="box" pos="0.00903598 -0.05228325 -0.31280137" size="0.47789597511291504 0.25608471035957336 0.013566710986196995" quat="1.0 0.0 0.0 0.0" class="collision"/>
        <geom type="cylinder" pos="0.06846455 0.29048978 -0.04916907" size="0.030319422483444214 0.08116674423217773" quat="1.0 0.0 0.0 0.0" class="collision"/>
        <geom type="cylinder" pos="0.10383244 0.29048978 -0.01729725" size="0.03031948208808899 0.026350606232881546" quat="0.7071068286895752 -0.0 0.7071067690849304 0.0" class="collision"/>
        <body name="handle">
          <joint axis="1.0 0.0 0.0" pos="0.16602397 0.28931342 -0.01579874" limited="true" name="handle_temp_joint" type="hinge" range="-0.7853981633974483 0.7853981633974483" damping="0.5" frictionloss="1" armature="2"/>
          <joint axis="0.0 1.0 0.0" pos="0.16602397 0.28931342 -0.01579874" limited="true" name="handle_joint" type="hinge" range="0 0.5" damping="0.5" frictionloss="1" armature="2"/>
          <geom mesh="handle_vis" type="mesh" solimp="0.998 0.998 0.001" solref="0.001 1" friction="0.95 0.3 0.1" class="visual" material="handle_material"/>
          <geom type="cylinder" pos="0.17542005 0.28923248 -0.01596184" size="0.03340867534279823 0.014485578052699566" quat="0.7071068286895752 -0.0 0.7071067690849304 0.0" class="collision"/>
          <geom name="handle_main" type="cylinder" pos="0.17669702 0.28926976 0.05359236" size="0.006227125413715839 0.04342131316661835" quat="1.0 0.0 0.0 0.0" class="collision"/>
        </body>
        <body name="spout">
          <joint axis="0.0 0.0 1.0" pos="0.06750976 0.29330762 0.16373773" limited="true" name="spout_joint" range="-0.7853981633974483 0.7853981633974483" type="hinge" damping="10"/>
          <site type="cylinder" rgba="0.5 0.75 1 0.5" size="0.01151744183152914 0.21220138669013977" pos="0.06744872 -0.02004890 -0.09707112" name="water"/>
          <geom mesh="spout_vis" type="mesh" solimp="0.998 0.998 0.001" solref="0.001 1" friction="0.95 0.3 0.1" class="visual" material="spout_material"/>
          <geom type="cylinder" pos="0.06846455 0.29384326 0.11317538" size="0.019380977377295494 0.08024422079324722" quat="1.0 0.0 0.0 0.0" class="collision" name="spout_main"/>
          <geom type="cylinder" pos="0.06846455 0.27009921 0.24148520" size="0.019380977377295494 0.05237458273768425" quat="0.94241863489151 0.33443546295166016 -7.425959024402132e-17 -1.0411755019580105e-24" class="collision"/>
          <geom type="cylinder" pos="0.06846455 0.00961289 0.23700823" size="0.019380977377295494 0.03836783766746521" quat="0.94241863489151 -0.33443546295166016 -7.425958362657642e-17 2.1058400473437913e-23" class="collision"/>
          <geom type="cylinder" pos="0.06846455 -0.01559357 0.15699275" size="0.019380979239940643 0.04354899376630783" quat="0.9991522431373596 -0.041167572140693665 9.14103729170305e-18 -6.345926471025749e-25" class="collision"/>
          <geom type="cylinder" pos="0.06846455 0.18169849 0.30201467" size="0.019380977377295494 0.05733475089073181" quat="0.7834377288818359 0.6214703321456909 -1.740260556822788e-16 3.604969907408587e-17" class="collision"/>
          <geom type="cylinder" pos="0.06846455 0.07813357 0.29093822" size="0.019380977377295494 0.049684420228004456" quat="0.5714645385742188 0.8206267356872559 -1.2698036348411727e-16 -5.526257353101829e-17" class="collision"/>
        </body>
        <geom class="region" name="reg_basin_left" type="box" pos="-0.21517065 -0.05111445499999999 -0.2151284" size="0.25182275 0.24243153499999998 0.08350127"/>
        <geom class="region" name="reg_basin_right" type="box" pos="0.28159826 -0.054265594999999986 -0.2151284" size="0.18733766000000002 0.24073462499999998 0.08350127"/>
        <geom class="region" name="reg_main" type="box" pos="-1.3000000004259604e-07 -1.0000000000287557e-07 -0.22844396" size="0.51522149 0.34708218 0.0989234"/>
      </body>
    </body>
  </worldbody>
  <actuator>
    <motor name="handle_joint_actuator" joint="handle_joint" gear="10"/>
    <motor name="handle_temp_joint_actuator" joint="handle_temp_joint" gear="10"/>
    <motor name="spout_joint_actuator" joint="spout_joint" gear="10"/>
  </actuator>
</mujoco>
