<?xml version='1.0' encoding='UTF-8'?>
<mujoco model="model">
  <option timestep="0.002" gravity="0.0 0.0 -9.81"/>
  <compiler angle="radian"/>
  <asset>
    <mesh file="visuals/blender.obj" name="blender_vis"/>
    <mesh file="visuals/bowl.obj" name="bowl_vis"/>
    <mesh file="visuals/button_head_lock.obj" name="button_head_lock_vis"/>
    <mesh file="visuals/head.obj" name="head_vis"/>
    <mesh file="visuals/knob_speed.obj" name="knob_speed_vis"/>
    <mesh file="visuals/Body001.obj" name="Body001_vis"/>
    <texture file="visuals/T_BC001.png" name="Body001_material" type="2d"/>
    <material name="Body001_material" rgba="1 1 1 1.0" texture="Body001_material" shininess="0.6150577068328857" specular="1"/>
    <texture file="visuals/T_BC001.png" name="bowl_material" type="2d"/>
    <material name="bowl_material" rgba="1 1 1 1.0" texture="bowl_material" shininess="0.2150577068328857" specular="0.8"/>
    <texture file="visuals/T_BC001.png" name="button_head_lock_material" type="2d"/>
    <material name="button_head_lock_material" rgba="1 1 1 1.0" texture="button_head_lock_material" shininess="0.6150577068328857" specular="0.3103448502657381"/>
    <texture file="visuals/T_BC001.png" name="head_material" type="2d"/>
    <material name="head_material" rgba="1 1 1 1.0" texture="head_material" shininess="0.6150577068328857" specular="0.81"/>
    <texture file="visuals/T_BC001.png" name="blender_material" type="2d"/>
    <material name="blender_material" rgba="1 1 1 1.0" texture="blender_material" shininess="0.6150577068328857" specular="1"/>
    <texture file="visuals/T_BC001.png" name="knob_speed_material" type="2d"/>
    <material name="knob_speed_material" rgba="1 1 1 1.0" texture="knob_speed_material" shininess="0.6150577068328857" specular="0.3103448502657381"/>
  </asset>
  <default>
    <default class="visual">
      <geom conaffinity="0" contype="0" group="1" type="mesh"/>
    </default>
    <default class="collision">
      <geom group="0" rgba="0.5 0 0 0.5"/>
    </default>
    <default class="spawn">
      <geom group="0" rgba="1 1 1 0.5" contype="0" conaffinity="0"/>
      <site group="0" rgba="1 1 1 0.5"/>
    </default>
    <default class="region">
      <geom group="1" conaffinity="0" contype="0" rgba="0 1 0 0"/>
    </default>
  </default>
  <worldbody>
    <body>
      <body name="object">
        <geom mesh="Body001_vis" type="mesh" solimp="0.998 0.998 0.001" solref="0.001 1" friction="0.95 0.3 0.1" class="visual" material="Body001_material"/>
        <geom type="cylinder" pos="0.003460519015789032 -0.0849916860461235 -0.1610846072435379" size="0.10266918689012527 0.016178524121642113" quat="0.7071068286895752 0.0 0.0 0.7071067690849304" class="collision"/>
        <geom type="box" pos="0.0007541850209236145 0.08873350918292999 -0.16065005958080292" size="0.08596988767385483 0.09872075915336609 0.016632359474897385" quat="1.0 0.0 0.0 0.0" class="collision"/>
        <geom type="box" pos="0.0007541850209236145 0.10066592693328857 -0.11781147867441177" size="0.08596987277269363 0.056856244802474976 0.02410605363547802" quat="1.0 0.0 0.0 0.0" class="collision"/>
        <geom type="box" pos="-0.002644643187522888 0.10392031073570251 -0.028685398399829865" size="0.08257105201482773 0.0402195081114769 0.06867597997188568" quat="1.0 0.0 0.0 0.0" class="collision"/>
        <body name="bowl">
          <!-- <joint axis="0.0 0.0 1.0" pos="-1.2453834408177045e-08 -0.06627010554075241 -0.05105967074632645" limited="true" name="bowl_joint" range="0.0 0.08" type="slide" damping="1" frictionloss="1" armature=".01" stiffness="0.05"/> -->
          <geom mesh="bowl_vis" type="mesh" solimp="0.998 0.998 0.001" solref="0.001 1" friction="0.95 0.3 0.1" class="visual" material="bowl_material"/>
          <geom type="box" pos="0.09577890485525131 -0.06873269379138947 -0.010495379567146301" size="0.03732758015394211 0.005964502226561308 0.05343107879161835" quat="0.7229249477386475 0.0 0.0 0.6909265518188477" class="collision"/>
          <geom type="box" pos="0.07019632309675217 -0.06757412850856781 -0.09441077709197998" size="0.03732758015394211 0.005964502226561308 0.05343107879161835" quat="0.6964244842529297 0.19394183158874512 0.1853574812412262 0.6655990481376648" class="collision"/>
          <geom type="box" pos="0.050625551491975784 -0.017625704407691956 -0.09441077709197998" size="0.03732758015394211 0.005964501760900021 0.05343107879161835" quat="0.38930678367614746 0.10841494798660278 0.24539148807525635 0.8811750411987305" class="collision"/>
          <geom type="box" pos="0.06955821067094803 -0.00038145482540130615 -0.010495379567146301" size="0.03732758015394211 0.005964502226561308 0.05343107879161835" quat="0.40412062406539917 0.0 0.0 0.9147056937217712" class="collision"/>
          <geom type="box" pos="0.0009639021009206772 0.029535599052906036 -0.010495379567146301" size="0.03732758015394211 0.005964502226561308 0.05343107879161835" quat="0.014805447310209274 0.0 0.0 0.9998903870582581" class="collision"/>
          <geom type="box" pos="0.00020568561740219593 0.003938035108149052 -0.09441077709197998" size="0.03732758015394211 0.005964502226561308 0.05343107879161835" quat="0.014262717217206955 0.003971923608332872 0.26824429631233215 0.9632371664047241" class="collision"/>
          <geom type="box" pos="-0.04840046539902687 -0.01541125401854515 -0.09441077709197998" size="0.03732758015394211 0.005964502226561308 0.05343107879161835" quat="0.3456428349018097 0.0962553396821022 -0.2504110634326935 -0.8991997838020325" class="collision"/>
          <geom type="box" pos="-0.06555350869894028 0.0036040879786014557 -0.010495379567146301" size="0.03732758015394211 0.005964502226561308 0.05343107879161835" quat="0.3587951958179474 0.0 -0.0 -0.9334163069725037" class="collision"/>
          <geom type="box" pos="-0.09579715132713318 -0.0646655336022377 -0.010495379567146301" size="0.03732758015394211 0.005964502226561308 0.05343107879161835" quat="0.6941573023796082 0.0 -0.0 -0.7198233604431152" class="collision"/>
          <geom type="box" pos="-0.07020523399114609 -0.06559489667415619 -0.09441077709197998" size="0.03732757642865181 0.005964502226561308 0.05343107879161835" quat="0.6687114238739014 0.18622416257858276 -0.1931096762418747 -0.6934365630149841" class="collision"/>
          <geom type="box" pos="-0.04966125637292862 -0.11589860916137695 -0.09441077709197998" size="0.03732758015394211 0.005964502226561308 0.05343107879161835" quat="0.8849525451660156 0.24644345045089722 -0.10600192099809647 -0.3806418180465698" class="collision"/>
          <geom type="box" pos="-0.06825187802314758 -0.13351109623908997 -0.010495379567146301" size="0.03732758015394211 0.005964502226561308 0.05343107879161835" quat="0.9186269044876099 0.0 -0.0 -0.3951260447502136" class="collision"/>
          <geom type="box" pos="-0.0016660839319229126 -0.16206619143486023 -0.010495379567146301" size="0.03732758015394211 0.005964502226561308 0.05343107879161835" quat="0.9998294115066528 0.0 -0.0 -0.01846950501203537" class="collision"/>
          <geom type="box" pos="-0.0007202774286270142 -0.1364748775959015 -0.09441076964139938" size="0.03732758015394211 0.005964502226561308 0.05343107879161835" quat="0.9631783962249756 0.2682279348373413 -0.004954892210662365 -0.017792508006095886" class="collision"/>
          <geom type="box" pos="0.048427045345306396 -0.11710363626480103 -0.09441076964139938" size="0.03732758015394211 0.005964502226561308 0.05343107879161835" quat="0.8991093635559082 0.2503858208656311 0.09632080048322678 0.345878005027771" class="collision"/>
          <geom type="box" pos="0.0655900239944458 -0.13611000776290894 -0.010495379567146301" size="0.03732758015394211 0.005964502226561308 0.05343107879161835" quat="0.9333224296569824 0.0 0.0 0.35903939604759216" class="collision"/>
          <geom type="box" pos="0.08426949381828308 -0.14564931392669678 0.0063903117552399635" size="0.0066782101057469845 0.01395743153989315 0.006678210571408272" quat="0.9218466281890869 0.0 0.0 0.38755494356155396" class="collision"/>
          <geom type="box" pos="0.09352481365203857 -0.15466591715812683 -0.03930659592151642" size="0.006678210571408272 0.04591038078069687 0.006678210571408272" quat="0.6440426111221313 0.6409761309623718 0.2982119619846344 0.29228127002716064" class="collision"/>
          <geom type="box" pos="0.07861623167991638 -0.1401141732931137 -0.08530610799789429" size="0.0066782101057469845 0.02186926268041134 0.006678210571408272" quat="0.9218466281890869 0.0 0.0 0.38755494356155396" class="collision"/>
          <geom type="box" pos="-0.0007026446983218193 -0.06551114469766617 -0.1315988451242447" size="0.051356516778469086 0.051356516778469086 0.011334642767906189" quat="1.0 0.0 0.0 0.0" class="collision"/>
          <geom name="reg_bowl" type="ellipsoid" pos="-0.0021129229571670294 -0.06722154468297958 0.04105578735470772" size="0.08472844213247299 0.08634301275014877 0.1604800671339035" rgba="0 1 0 0.5" class="region"/>
        </body>
        <body name="button_head_lock">
          <joint axis="-1.0 0.0 0.0" pos="0.08683105558156967 0.10489334166049957 0.010110207833349705" limited="true" name="button_head_lock_joint" range="0.0 0.003" type="slide" damping="1" frictionloss="1" armature=".01" stiffness="0.2" springref="-0.00"/>
          <geom mesh="button_head_lock_vis" type="mesh" solimp="0.998 0.998 0.001" solref="0.001 1" friction="0.95 0.3 0.1" class="visual" material="button_head_lock_material"/>
          <geom class="collision" type="box" pos="0.08823489397764206 0.1049036830663681 0.00974784791469574" size="0.0011522301938384771 0.00662582740187645 0.010949372313916683" quat="1.0 0.0 0.0 0.0" name="button_head_lock_main"/>
        </body>
        <body name="head">
          <joint axis="-1.0 0.0 0.0" pos="1.0754204637919429e-08 0.14244376122951508 0.04130365327000618" limited="true" name="head_joint" range="0.0 1.5707963267948966" type="hinge" damping="1" frictionloss="1" armature=".01" stiffness="0.05"/>
          <geom mesh="head_vis" type="mesh" solimp="0.998 0.998 0.001" solref="0.001 1" friction="0.95 0.3 0.1" class="visual" material="head_material"/>
          <geom type="box" pos="0.00042625516653060913 -0.06595133244991302 0.036875221878290176" size="0.010289306752383709 0.029734713956713676 0.007034998387098312" quat="1.0 0.0 0.0 0.0" class="collision"/>
          <geom type="box" pos="-8.922815322875977e-05 0.11617272347211838 0.11218898743391037" size="0.08439835906028748 0.055622946470975876 0.06867597997188568" quat="1.0 0.0 0.0 0.0" class="collision"/>
          <geom type="cylinder" pos="0.0 -0.06626210361719131 0.056532151997089386" size="0.05091654881834984 0.0164863932877779" quat="0.7071068286895752 0.0 0.0 0.7071067690849304" class="collision"/>
          <geom type="box" pos="-8.924119174480438e-05 -0.027804773300886154 0.12384510040283203" size="0.08439836651086807 0.08912069350481033 0.05735771358013153" quat="1.0 0.0 0.0 0.0" class="collision"/>
          <body name="blender">
            <joint axis="0.0 0.0 1.0" pos="-1.7672549802227877e-05 -0.06669911742210388 -0.026015812531113625" limited="false" name="blender_joint" range="0 360" type="hinge" damping="1" frictionloss="1" armature=".01" stiffness="0.05"/>
            <geom mesh="blender_vis" type="mesh" solimp="0.998 0.998 0.001" solref="0.001 1" friction="0.95 0.3 0.1" class="visual" material="blender_material"/>
            <geom type="cylinder" pos="-8.93324613571167e-06 -0.06668905913829803 0.016672706231474876" size="0.044408053159713745 0.0015562321059405804" quat="0.7071068286895752 0.0 0.0 0.7071067690849304" class="collision"/>
            <geom type="cylinder" pos="-8.93324613571167e-06 -0.06668905913829803 0.010099751874804497" size="0.006662769243121147 0.022094683721661568" quat="0.7071068286895752 0.0 0.0 0.7071067690849304" class="collision"/>
            <geom type="box" pos="5.398690700531006e-05 -0.06601007282733917 -0.04471845179796219" size="0.0030582661274820566 0.046690359711647034 0.0377962552011013" quat="1.0 0.0 0.0 0.0" class="collision"/>
          </body>
        </body>
        <body name="knob_speed">
          <joint axis="-1.0 0.0 0.0" pos="0.09186919778585434 0.10499929636716843 -0.03084498643875122" limited="true" name="knob_speed_joint" range="0.0 5.288347633542818" type="hinge" damping="0.05" armature="0.001"/>
          <geom mesh="knob_speed_vis" type="mesh" solimp="0.998 0.998 0.001" solref="0.001 1" friction="0.95 0.3 0.1" class="visual" material="knob_speed_material"/>
          <geom type="cylinder" pos="0.08847013860940933 0.10506120324134827 -0.030731894075870514" size="0.02145657129585743 0.002870349446311593" quat="0.5000000596046448 0.5 0.4999999701976776 0.5" class="collision"/>
          <geom class="collision" type="box" pos="0.10003703087568283 0.10141026228666306 -0.030731894075870514" size="0.009205687791109085 0.012417934834957123 0.009205687791109085" quat="1.0 0.0 0.0 0.0" name="knob_speed_main"/>
        </body>
        <geom class="region" name="reg_main" type="box" pos="1.564621925354004e-05 0.0 7.450580596923828e-09" size="0.09994803166389465 0.18822178041934967 0.17863414978981018"/>
      </body>
    </body>
  </worldbody>
  <actuator>
    <!-- <motor name="bowl_joint_actuator" joint="bowl_joint" gear="100"/> -->
    <motor name="button_head_lock_joint_actuator" joint="button_head_lock_joint" gear="0.5"/>
    <motor name="head_joint_actuator" joint="head_joint" gear="20"/>
    <motor name="knob_speed_joint_actuator" joint="knob_speed_joint" gear="8"/>
    <motor name="blender_joint_actuator" joint="blender_joint" gear="20"/>
  </actuator>
</mujoco>
