<?xml version='1.0' encoding='UTF-8'?>
<mujoco model="model">
  <option timestep="0.002" gravity="0.0 0.0 -9.81"/>
  <compiler angle="radian"/>
  <asset>
    <mesh file="visuals/handle.obj" name="handle_vis"/>
    <mesh file="visuals/Body001.obj" name="Body001_vis"/>
    <mesh file="visuals/Shelf001.obj" name="Shelf001_vis"/>
    <mesh file="visuals/spout.obj" name="spout_vis"/>
    <texture file="visuals/T_BC001.png" name="Body001_material" type="2d"/>
    <material name="Body001_material" rgba="1 1 1 1.0" texture="Body001_material" shininess="0.1" specular="0.9"/>
    <texture file="visuals/T_BC001.png" name="handle_material" type="2d"/>
    <material name="handle_material" rgba="1 1 1 1.0" texture="handle_material" shininess="0.1" specular="0.9"/>
    <texture file="visuals/T_BC001.png" name="Shelf001_material" type="2d"/>
    <material name="Shelf001_material" rgba="1 1 1 1.0" texture="Shelf001_material" shininess="0.1" specular="0.9"/>
    <texture file="visuals/T_BC001.png" name="spout_material" type="2d"/>
    <material name="spout_material" rgba="1 1 1 1.0" texture="spout_material" shininess="0.1" specular="0.9"/>
  </asset>
  <default>
    <default class="visual">
      <geom conaffinity="0" contype="0" group="1" type="mesh"/>
    </default>
    <default class="collision">
      <geom group="0" rgba="0.5 0 0 0.5"/>
    </default>
    <default class="spawn">
      <geom group="0" rgba="1 1 1 0.5" contype="0" conaffinity="0"/>
      <site group="0" rgba="1 1 1 0.5"/>
    </default>
    <default class="region">
      <geom group="1" conaffinity="0" contype="0" rgba="0 1 0 0"/>
    </default>
  </default>
  <worldbody>
    <body>
      <body name="object">
        <geom mesh="Body001_vis" type="mesh" solimp="0.998 0.998 0.001" solref="0.001 1" friction="0.95 0.3 0.1" class="visual" material="Body001_material"/>
        <geom class="collision" type="box" pos="-0.29573947191238403 1.30385160446167e-08 -0.1457519680261612" size="0.013795404694974422 0.21250402927398682 0.10053214430809021" quat="1.0 0.0 0.0 0.0"/>
        <geom class="collision" type="box" pos="0.0006880920846015215 -0.19935894012451172 -0.1457519233226776" size="0.29166504740715027 0.01314515434205532 0.10053209215402603" quat="1.0 0.0 0.0 0.0"/>
        <geom class="collision" type="box" pos="0.0003312316257506609 0.1745346039533615 -0.145751953125" size="0.2884378731250763 0.03796948865056038 0.10053209215402603" quat="1.0 0.0 0.0 0.0"/>
        <geom class="collision" type="box" pos="0.29696571826934814 5.587935447692871e-09 -0.1457519233226776" size="0.012569138780236244 0.2125040888786316 0.10053212195634842" quat="1.0 0.0 0.0 0.0"/>
        <geom class="collision" type="cylinder" pos="-0.026681607589125633 0.18301281332969666 -0.027524076402187347" size="0.020769257098436356 0.018180131912231445" quat="1.0 0.0 0.0 0.0"/>
        <geom class="collision" type="cylinder" pos="-0.026623418554663658 0.1829071342945099 0.02004004642367363" size="0.0139413271099329 0.013050315901637077" quat="1.0 0.0 0.0 0.0"/>
        <geom class="collision" type="cylinder" pos="-0.03357614576816559 0.18287891149520874 -0.00751347653567791" size="0.02091388590633869 0.04293079674243927" quat="0.7071068286895752 -0.0 0.7071067690849304 0.0"/>
        <geom class="collision" type="box" pos="-0.01075032353401184 -0.023271121084690094 -0.22231754660606384" size="0.2943456470966339 0.1747555136680603 0.023966528475284576" quat="1.0 0.0 0.0 0.0"/>
        <body name="handle">
          <joint axis="1.0 0.0 0.0" pos="0.023546822369098663 0.1831321120262146 -0.007625986821949482" limited="true" name="handle_temp_joint" type="hinge" range="-0.7853981633974483 0.7853981633974483" damping="1" frictionloss="1" armature=".01" stiffness="0.05"/>
          <joint axis="0.0 1.0 0.0" pos="0.023546822369098663 0.1831321120262146 -0.007625986821949482" limited="true" name="handle_joint" type="hinge" range="0 0.5" damping="1" frictionloss="1" armature=".01" stiffness="0.05"/>
          <geom mesh="handle_vis" type="mesh" solimp="0.998 0.998 0.001" solref="0.001 1" friction="0.95 0.3 0.1" class="visual" material="handle_material"/>
          <geom name="handle_main" class="collision" type="cylinder" pos="0.02859884686768055 0.1829071193933487 0.05701674520969391" size="0.005644665565341711 0.043615445494651794" quat="1.0 0.0 0.0 0.0"/>
          <geom class="collision" type="cylinder" pos="0.033786993473768234 0.18287891149520874 -0.007513475604355335" size="0.021571222692728043 0.008113272488117218" quat="0.7071068286895752 -0.0 0.7071067690849304 0.0"/>
        </body>
        <body name="Shelf001">
          <joint axis="0.0 0.0 1.0" pos="-0.19791516661643982 -0.013705432415008545 -0.07553832232952118" limited="true" name="Shelf001_joint" range="0.0 0.1" type="slide" damping="1" frictionloss="1" armature=".01" stiffness="0.05"/>
          <geom mesh="Shelf001_vis" type="mesh" solimp="0.998 0.998 0.001" solref="0.001 1" friction="0.95 0.3 0.1" class="visual" material="Shelf001_material"/>
          <geom class="collision" type="box" pos="-0.13628754019737244 -0.02725769579410553 -0.07506629824638367" size="0.002058111596852541 0.15637513995170593 0.03274409845471382" quat="1.0 0.0 0.0 0.0"/>
          <geom class="collision" type="box" pos="-0.2589564323425293 -0.02725769579410553 -0.07506629824638367" size="0.0020581125281751156 0.15637564659118652 0.032744161784648895" quat="1.0 0.0 0.0 0.0"/>
          <geom class="collision" type="box" pos="-0.19831039011478424 -0.17819945514202118 -0.07506629824638367" size="0.0606623999774456 0.0025869891978800297 0.03274451568722725" quat="0.9984028935432434 0.05649510398507118 -2.965359116196859e-17 1.6343655813636579e-18"/>
          <geom class="collision" type="box" pos="-0.19831039011478424 0.12992987036705017 -0.07490633428096771" size="0.0606623999774456 0.002586992923170328 0.032744549214839935" quat="0.9993682503700256 -0.035540804266929626 2.114895850942301e-17 8.692025250440637e-19"/>
          <geom class="collision" type="box" pos="-0.19831039011478424 -0.02492409572005272 -0.10233265161514282" size="0.0606623999774456 0.1557116061449051 0.0010605186689645052" quat="1.0 0.0 0.0 0.0"/>
          <geom class="collision" type="box" pos="-0.19831039011478424 -0.19205521047115326 -0.04366682842373848" size="0.0606623999774456 0.012024065479636192 0.0010932263685390353" quat="1.0 0.0 0.0 0.0"/>
          <geom class="collision" type="box" pos="-0.19957883656024933 0.15746037662029266 -0.043339651077985764" size="0.06940069794654846 0.020449461415410042 0.0006955183343961835" quat="1.0 0.0 0.0 0.0"/>
          <geom class="collision" type="box" pos="-0.132585346698761 -0.015231795608997345 -0.04340459033846855" size="0.006222839001566172 0.19085927307605743 0.0006955178105272353" quat="1.0 0.0 0.0 0.0"/>
          <geom class="collision" type="box" pos="-0.26206278800964355 -0.01596555858850479 -0.04340459406375885" size="0.006222768686711788 0.18801914155483246 0.0006955089047551155" quat="1.0 0.0 0.0 0.0"/>
        </body>
        <body name="spout">
          <joint axis="0.0 0.0 1.0" pos="-0.026585448533296585 0.1829613447189331 0.1483708620071411" limited="true" name="spout_joint" range="-1.0471975511965976 1.0471975511965976" type="hinge" damping="1" frictionloss="1" armature=".01" stiffness="0.05"/>
          <site type="cylinder" rgba="0.5 0.75 1 0.5" size="0.005293175112456083 0.22727230191230774" pos="-0.02662898600101471 -0.0244566909968853 -0.0075023360550403595" name="water"/>
          <geom mesh="spout_vis" type="mesh" solimp="0.998 0.998 0.001" solref="0.001 1" friction="0.95 0.3 0.1" class="visual" material="spout_material"/>
          <geom class="collision" type="cylinder" pos="-0.026662632822990417 0.026742637157440186 0.23387353122234344" size="0.012544616125524044 0.06533466279506683" quat="0.7071067094802856 0.70710688829422 0.0 0.0" name="spout_main"/>
          <geom class="collision" type="cylinder" pos="-0.026662632822990417 0.1827104389667511 0.10122103244066238" size="0.012544616125524044 0.06533466279506683" quat="1.0 1.1920928955078125e-07 0.0 0.0"/>
          <geom class="collision" type="cylinder" pos="-0.026662632822990417 0.1802602857351303 0.17960378527641296" size="0.01254461519420147 0.015865996479988098" quat="0.9955674409866333 0.0940505638718605 2.5421713641451373e-17 -5.4599003453363965e-18"/>
          <geom class="collision" type="cylinder" pos="-0.026662632822990417 0.17033305764198303 0.20380142331123352" size="0.01254461519420147 0.015865996479988098" quat="0.9648149013519287 0.2629300355911255 -1.1825506385956092e-17 2.539792930370833e-18"/>
          <geom class="collision" type="cylinder" pos="-0.026662632822990417 0.15283629298210144 0.22142226994037628" size="0.01254461519420147 0.015865996479988098" quat="0.8722114562988281 0.4891289472579956 -6.405854746711117e-17 1.3758040179257605e-17"/>
          <geom class="collision" type="cylinder" pos="-0.026662632822990417 0.12777002155780792 0.23196996748447418" size="0.01254461519420147 0.015865996479988098" quat="0.772973895072937 0.6344377994537354 -9.942481337549348e-17 2.135374857675644e-17"/>
          <geom class="collision" type="cylinder" pos="-0.026662632822990417 0.10530964285135269 0.23395541310310364" size="0.01254461519420147 0.015865996479988098" quat="0.714352548122406 0.6997860074043274 -1.1596757197616188e-16 2.4906684522296256e-17"/>
        </body>
        <geom class="region" name="reg_basin" type="box" pos="0.07886886596679688 -0.025168873369693756 -0.1217707023024559" size="0.20058770275115967 0.15644139593839645 0.07245168632268906"/>
        <geom class="region" name="reg_main" type="box" pos="0.0 0.0 -0.145751953125" size="0.31053478813171387 0.21350402927398682 0.10153208470344544"/>
      </body>
    </body>
  </worldbody>
  <actuator>
    <motor name="handle_joint_actuator" joint="handle_joint" gear="10"/>
    <motor name="handle_temp_joint_actuator" joint="handle_temp_joint" gear="10"/>
    <motor name="Shelf001_joint_actuator" joint="Shelf001_joint" gear="10"/>
    <motor name="spout_joint_actuator" joint="spout_joint" gear="10"/>
  </actuator>
</mujoco>
