<?xml version='1.0' encoding='UTF-8'?>
<mujoco model="model">
  <option timestep="0.002" gravity="0.0 0.0 -9.81"/>
  <compiler angle="radian"/>
  <asset>
    <mesh file="visuals/button_cancel.obj" name="button_cancel_vis"/>
    <mesh file="visuals/knob_doneness.obj" name="knob_doneness_vis"/>
    <mesh file="visuals/lever.obj" name="lever_vis"/>
    <mesh file="visuals/Body001.obj" name="Body001_vis"/>
    <texture file="visuals/T_BC001.png" name="Body001_material" type="2d"/>
    <material name="Body001_material" rgba="1 1 1 1.0" texture="Body001_material" shininess="0.141421377658844" specular="0.3103448502657381"/>
    <texture file="visuals/T_BC001.png" name="button_cancel_material" type="2d"/>
    <material name="button_cancel_material" rgba="1 1 1 1.0" texture="button_cancel_material" shininess="0.141421377658844" specular="0.3103448502657381"/>
    <texture file="visuals/T_BC001.png" name="knob_doneness_material" type="2d"/>
    <material name="knob_doneness_material" rgba="1 1 1 1.0" texture="knob_doneness_material" shininess="0.141421377658844" specular="0.3103448502657381"/>
    <texture file="visuals/T_BC001.png" name="lever_material" type="2d"/>
    <material name="lever_material" rgba="1 1 1 1.0" texture="lever_material" shininess="0.141421377658844" specular="0.3103448502657381"/>
  </asset>
  <default>
    <default class="visual">
      <geom conaffinity="0" contype="0" group="1" type="mesh"/>
    </default>
    <default class="collision">
      <geom group="0" rgba="0.5 0 0 0.5" density="1.0" solref="0.004 1" solimp="0.998 0.998 0.001"/>
    </default>
    <default class="spawn">
      <geom group="0" rgba="1 1 1 0.5" contype="0" conaffinity="0"/>
      <site group="0" rgba="1 1 1 0.5"/>
    </default>
    <default class="region">
      <geom group="1" conaffinity="0" contype="0" rgba="0 1 0 0" mass="0"/>
    </default>
  </default>
  <worldbody>
    <body>
      <body name="object">
        <geom mesh="Body001_vis" type="mesh" solimp="0.998 0.998 0.001" solref="0.001 1" friction="0.95 0.3 0.1" class="visual" material="Body001_material"/>
        <geom type="box" pos="-0.12839209 0.00789733 0.00909332" size="0.14144612848758698 0.01274540089070797 0.16335052251815796" quat="0.7064355611801147 -0.030804580077528954 0.030804496258497238 -0.7064353823661804" class="collision"/>
        <geom type="box" pos="0.12582500 0.00789736 0.00957425" size="0.12422096729278564 0.015895145013928413 0.1643896996974945" quat="0.7064338326454163 0.03084356151521206 -0.03084355592727661 -0.7064337134361267" class="collision"/>
        <geom type="box" pos="0.00011970 0.00789735 0.08630466" size="0.01845981739461422 0.10339897125959396 0.08628589659929276" quat="1.0 0.0 0.0 0.0" class="collision"/>
        <geom type="box" pos="-0.00052364 0.00635268 -0.14747350" size="0.12363019585609436 0.10683106631040573 0.007478775456547737" quat="1.0 0.0 0.0 0.0" class="collision"/>
        <geom type="box" pos="-0.05589509 0.00789734 0.08655936" size="0.005722363479435444 0.10339897871017456 0.0865406021475792" quat="1.0 0.0 0.0 0.0" class="collision"/>
        <geom type="box" pos="0.05375786 0.00789736 0.08591124" size="0.005722363479435444 0.10339897871017456 0.08589247614145279" quat="1.0 0.0 0.0 0.0" class="collision"/>
        <geom type="box" pos="0.08441834 0.00492108 0.14748457" size="0.029066720977425575 0.1197349950671196 0.025846406817436218" quat="1.0 0.0 0.0 0.0" class="collision"/>
        <geom type="box" pos="-0.00052361 -0.14244482 -0.14747350" size="0.1236310824751854 0.04326910525560379 0.007478646468371153" quat="1.0 0.0 0.0 0.0" class="collision"/>
        <geom type="box" pos="-0.00052367 0.15569738 -0.14747350" size="0.12363123893737793 0.04326910525560379 0.007478662300854921" quat="1.0 0.0 0.0 0.0" class="collision"/>
        <geom type="box" pos="-0.00052368 0.22390929 -0.14747350" size="0.09864763170480728 0.023213988170027733 0.007478990592062473" quat="1.0 0.0 0.0 0.0" class="collision"/>
        <geom type="box" pos="-0.00052359 -0.21499221 -0.14747350" size="0.07698934525251389 0.027825381606817245 0.0074788425117731094" quat="1.0 0.0 0.0 0.0" class="collision"/>
        <geom type="box" pos="-0.00159198 0.00940109 0.00482604" size="0.059575051069259644 0.1183314248919487 0.0005297267343848944" quat="1.0 0.0 0.0 0.0" class="collision"/>
        <geom type="box" pos="0.12333384 0.15298110 0.00795435" size="0.04173025116324425 0.011884286068379879 0.16376978158950806" quat="0.7600297927856445 0.028310716152191162 -0.03318355977535248 -0.6484227180480957" class="collision"/>
        <geom type="box" pos="0.09811267 0.21028277 0.00674540" size="0.03452734649181366 0.011884287931025028 0.1636912077665329" quat="0.9342952370643616 0.040630511939525604 -0.019244840368628502 -0.35365405678749084" class="collision"/>
        <geom type="box" pos="0.04697333 0.24245347 0.00687522" size="0.03452734649181366 0.011884287931025028 0.16505186259746552" quat="0.9861531853675842 0.04596418887376785 -0.010331111960113049 -0.15900461375713348" class="collision"/>
        <geom type="box" pos="-0.01588949 0.24893260 0.00729002" size="0.03452735021710396 0.011884287931025028 0.16470132768154144" quat="0.9965984225273132 0.04677310585975647 0.0004663928702939302 0.06784994900226593" class="collision"/>
        <geom type="box" pos="-0.07701792 0.22706197 0.00689822" size="0.03452734649181366 0.011884286068379879 0.16534389555454254" quat="0.9517301321029663 0.05032274127006531 0.006126889027655125 0.30272069573402405" class="collision"/>
        <geom type="box" pos="-0.11767361 0.17865041 0.00720534" size="0.03452734649181366 0.011884287931025028 0.16637316346168518" quat="0.8476083874702454 0.04295797646045685 0.026764579117298126 0.5282028913497925" class="collision"/>
        <geom type="box" pos="0.11917782 -0.15170936 0.01133909" size="0.04173024743795395 0.011884286068379879 0.16509374976158142" quat="0.5522377490997314 0.029308753088116646 -0.037714868783950806 -0.8323172926902771" class="collision"/>
        <geom type="box" pos="0.07809885 -0.20889115 0.00890918" size="0.04173025116324425 0.010432533919811249 0.16503295302391052" quat="0.3188709020614624 0.011297330260276794 -0.05592277646064758 -0.9460794925689697" class="collision"/>
        <geom type="box" pos="-0.07508872 -0.21264949 0.00829758" size="0.034751467406749725 0.009053592570126057 0.16551105678081512" quat="0.30279412865638733 0.0040574343875050545 0.053809989243745804 0.9515270590782166" class="collision"/>
        <geom type="box" pos="-0.11484302 -0.16354251 0.00808155" size="0.04173025116324425 0.011884286068379879 0.16576552391052246" quat="0.537534773349762 0.027018805965781212 0.03096226043999195 0.8422396779060364" class="collision"/>
        <geom type="box" pos="-0.02375131 -0.25128478 -0.12305498" size="0.01302685122936964 0.007193822413682938 0.033476803451776505" quat="0.999358594417572 -0.03437207639217377 0.010040899738669395 -0.00034534247242845595" class="collision"/>
        <geom type="box" pos="0.03623589 -0.22781441 0.07465361" size="0.025410937145352364 0.005940437316894531 0.09384605288505554" quat="0.9952822923660278 -0.07028617709875107 0.004711255431175232 0.06671416014432907" class="collision"/>
        <geom type="box" pos="-0.03526556 -0.22593828 0.07551196" size="0.025410933420062065 0.005940437316894531 0.09635770320892334" quat="0.9888200759887695 -0.069829560816288 -0.009281068108975887 -0.13142527639865875" class="collision"/>
        <geom type="box" pos="-0.04518352 -0.24568242 -0.08653834" size="0.010348370298743248 0.00594043405726552 0.06792284548282623" quat="0.9895538091659546 -0.05383039265871048 0.012083004228770733 -0.13318996131420135" class="collision"/>
        <geom type="box" pos="0.04543179 -0.24779661 -0.08608830" size="0.010348370298743248 0.005940435919910669 0.06673044711351395" quat="0.994620144367218 -0.06181461736559868 -0.013686208054423332 0.08199001103639603" class="collision"/>
        <geom type="box" pos="-0.00405861 0.17586805 0.14745433" size="0.020532969385385513 0.0576057992875576 0.025816163048148155" quat="1.0 0.0 0.0 0.0" class="collision"/>
        <geom type="box" pos="-0.08600640 0.00492108 0.14678000" size="0.029067037627100945 0.11973679810762405 0.025141829624772072" quat="1.0 0.0 0.0 0.0" class="collision"/>
        <geom type="box" pos="0.02580316 0.17463064 0.14701626" size="0.020533081144094467 0.05546017736196518 0.025378085672855377" quat="0.99519282579422 0.0 -0.0 -0.09793465584516525" class="collision"/>
        <geom type="box" pos="0.05440508 0.17284821 0.14690260" size="0.020533081144094467 0.05365860462188721 0.025264432653784752" quat="0.985664427280426 0.0 -0.0 -0.16871750354766846" class="collision"/>
        <geom type="box" pos="0.07746127 0.15380196 0.14736543" size="0.015054473653435707 0.03940611332654953 0.025727270171046257" quat="0.9634147882461548 0.0 -0.0 -0.2680148482322693" class="collision"/>
        <geom type="box" pos="0.09362758 0.13767712 0.14818598" size="0.017706094309687614 0.02816912531852722 0.026547815650701523" quat="0.9634147882461548 0.0 -0.0 -0.2680148482322693" class="collision"/>
        <geom type="box" pos="-0.04166391 0.17837507 0.14681840" size="0.020533081144094467 0.0576057992875576 0.025180231779813766" quat="0.9997580647468567 0.0 0.0 0.021995650604367256" class="collision"/>
        <geom type="box" pos="-0.06914723 0.16909322 0.14736542" size="0.020533081144094467 0.04429369792342186 0.025727255269885063" quat="0.9881181120872498 0.0 0.0 0.15369655191898346" class="collision"/>
        <geom type="box" pos="-0.08559208 0.14887503 0.14709192" size="0.030398856848478317 0.032412976026535034 0.025453763082623482" quat="0.8110179305076599 0.0 0.0 0.5850213170051575" class="collision"/>
        <geom type="box" pos="0.00281777 -0.13142104 0.14825095" size="0.10841242223978043 0.03248751536011696 0.026612786576151848" quat="1.0 0.0 0.0 0.0" class="collision"/>
        <geom type="box" pos="-0.00035795 -0.20149824 0.14689374" size="0.047777652740478516 0.02039469964802265 0.02525557205080986" quat="1.0 0.0 0.0 0.0" class="collision"/>
        <geom type="box" pos="-0.00302598 -0.17204057 0.14708586" size="0.09098364412784576 0.021839411929249763 0.025447696447372437" quat="1.0 0.0 0.0 0.0" class="collision"/>
        <geom type="box" pos="0.03048181 -0.25077319 -0.12084855" size="0.01302685122936964 0.007193822413682938 0.033476803451776505" quat="0.9994068145751953 -0.034373484551906586 0.0021147695370018482 -7.273506344063208e-05" class="collision"/>
        <geom type="box" pos="0.00329789 -0.25077435 -0.13591110" size="0.013768055476248264 0.007193821016699076 0.019472084939479828" quat="0.9994068145751953 -0.034373484551906586 0.0021147695370018482 -7.273506344063208e-05" class="collision"/>
        <geom type="box" pos="-0.10197954 -0.20589033 -0.16333322" size="0.00821390375494957 0.0178651325404644 0.008573487401008606" quat="0.9225467443466187 0.0 0.0 0.38588541746139526" class="collision"/>
        <geom type="box" pos="0.10498157 -0.20311105 -0.16333322" size="0.008213902823626995 0.019728634506464005 0.008573487401008606" quat="0.9253305792808533 0.0 -0.0 -0.37916135787963867" class="collision"/>
        <geom type="box" pos="-0.10261019 0.22309904 -0.16333322" size="0.00821390375494957 0.0178651325404644 0.008573487401008606" quat="0.9230363965034485 0.0 -0.0 -0.38471266627311707" class="collision"/>
        <geom type="box" pos="0.10355650 0.22131294 -0.16333322" size="0.008213902823626995 0.02138938196003437 0.008573487401008606" quat="0.39746493101119995 0.0 -0.0 -0.9176173806190491" class="collision"/>
        <body name="button_cancel">
          <joint axis="0.0 1.0 0.0" pos="0.00378405 -0.25243592 -0.10674371" limited="true" name="button_cancel_joint" range="0.0 0.003" type="slide" damping="1" frictionloss="1" armature=".01" stiffness="0.05"/>
          <geom mesh="button_cancel_vis" type="mesh" solimp="0.998 0.998 0.001" solref="0.001 1" friction="0.95 0.3 0.1" class="visual" material="button_cancel_material"/>
          <geom class="collision" type="box" pos="0.00377033 -0.25328869 -0.10690443" size="0.011674778535962105 0.0019006102811545134 0.0063023255206644535" quat="1.0 0.0 0.0 0.0" name="button_cancel_main"/>
        </body>
        <body name="knob_doneness">
          <joint axis="0.0 1.0 0.0" pos="0.00076377 -0.25170308 -0.05679606" limited="true" name="knob_doneness_joint" range="0.0 4.153883619746504" type="hinge" damping="0.05" frictionloss="0.1" armature="0.001"/>
          <geom mesh="knob_doneness_vis" type="mesh" solimp="0.998 0.998 0.001" solref="0.001 1" friction="0.95 0.3 0.1" class="visual" material="knob_doneness_material"/>
          <geom type="cylinder" pos="0.00081063 -0.24853866 -0.05675789" size="0.030964963138103485 0.0012452210066840053" quat="0.5000000596046448 -0.5 -0.5 -0.4999999701976776" class="collision" density="0.001"/>
          <geom class="collision" type="box" pos="0.00059257 -0.26034275 -0.05596535" size="0.029718758538365364 0.010985721834003925 0.012968876399099827" quat="0.9604214429855347 0.0 -0.27855104207992554 0.0" name="knob_doneness_main" density="0.001"/>
        </body>
        <body name="lever">
          <joint axis="0.0 0.0 -1.0" pos="0.00063864 -0.24778864 0.09120349" limited="true" name="lever_joint" range="0.0 0.059000000000000004" type="slide" damping="1" frictionloss="1" armature=".01" stiffness="2" springref="-0.5"/>
          <geom class="region" name="reg_slotL" type="box" pos="-0.033291305 0.008216085000000005 0.171873925" size="0.014160714999999997 0.102178625 0.085999925"/>
          <geom class="region" name="reg_slotR" type="box" pos="0.033364695 0.008216085000000005 0.171873885" size="0.014352145 0.102178625 0.085999965"/>
          <geom mesh="lever_vis" type="mesh" solimp="0.998 0.998 0.001" solref="0.001 1" friction="0.95 0.3 0.1" class="visual" material="lever_material"/>
          <geom class="collision" type="box" pos="0.00092636 -0.26105016 0.09535336" size="0.01020729262381792 0.012192522175610065 0.012658373452723026" quat="1.0 0.0 0.0 0.0" name="lever_handle"/>
          <geom type="box" pos="0.00092636 -0.24065492 0.08604252" size="0.004578250925987959 0.004855124745517969 0.014432530850172043" quat="0.6074435114860535 0.36195623874664307 0.3619561195373535 -0.6074436902999878" class="collision"/>
          <geom class="collision" type="box" pos="0.03391259 0.00789735 0.09637880" size="0.012546599842607975 0.09999998658895493 0.00031480786856263876" quat="1.0 0.0 0.0 0.0" name="slotR_floor"/>
          <geom class="collision" type="box" pos="-0.03356905 0.00789734 0.09637880" size="0.01254673395305872 0.09999999403953552 0.00031480786856263876" quat="1.0 0.0 0.0 0.0" name="slotL_floor"/>
        </body>
        <geom class="region" name="reg_main" type="box" pos="0.0 0.008688299999999982 -2.7749999999965302e-06" size="0.15223123 0.26594676 0.17285908500000002"/>
      </body>
    </body>
  </worldbody>
  <actuator>
    <motor name="button_cancel_joint_actuator" joint="button_cancel_joint" gear="0.5"/>
    <motor name="knob_doneness_joint_actuator" joint="knob_doneness_joint" gear="0.5"/>
    <motor name="lever_joint_actuator" joint="lever_joint" gear="0.5"/>
  </actuator>
</mujoco>
