<?xml version='1.0' encoding='UTF-8'?>
<mujoco model="model">
  <option timestep="0.002" gravity="0.0 0.0 -9.81"/>
  <compiler angle="radian"/>
  <asset>
    <mesh file="visuals/door.obj" name="door_vis"/>
    <mesh file="visuals/door_Clear.obj" name="door_Clear_vis"/>
    <mesh file="visuals/Body001.obj" name="Body001_vis"/>
    <mesh file="visuals/Disc001.obj" name="Disc001_vis"/>
    <texture file="visuals/T_BC001.png" name="Body001_material" type="2d"/>
    <material name="Body001_material" rgba="1 1 1 1.0" texture="Body001_material" shininess="1" specular="1"/>
    <texture file="visuals/T_BC001.png" name="door_material" type="2d"/>
    <material name="door_material" rgba="1 1 1 1.0" texture="door_material" shininess="1" specular="1"/>
    <material name="door_Clear_material" rgba="0.013285331428050995 0.013285331428050995 0.013285331428050995 0.800000011920929" shininess="0.5" specular="0.3103448502657381"/>
    <texture file="visuals/T_BC001.png" name="Disc001_material" type="2d"/>
    <material name="Disc001_material" rgba="1 1 1 1.0" texture="Disc001_material" shininess="0.5" specular="0.5"/>
  </asset>
  <default>
    <default class="visual">
      <geom conaffinity="0" contype="0" group="1" type="mesh"/>
    </default>
    <default class="collision">
      <geom group="0" rgba="0.5 0 0 0.5"/>
    </default>
    <default class="spawn">
      <geom group="0" rgba="1 1 1 0.5" contype="0" conaffinity="0"/>
      <site group="0" rgba="1 1 1 0.5"/>
    </default>
    <default class="region">
      <geom group="1" conaffinity="0" contype="0" rgba="0 1 0 0"/>
    </default>
  </default>
  <worldbody>
    <body>
      <body name="object">
        <geom class="collision" type="cylinder" pos="-0.00043801116407848895 0.009111126884818077 -0.12990787625312805" size="0.1143873780965805 0.0030228393152356148" quat="1.0 0.0 0.0 0.0" name="tray" rgba="0 1 0 0.5"/>
        <geom class="collision" type="box" pos="0.2859203517436981 -0.15416117012500763 -0.06360133737325668" size="0.008171001449227333 0.0006866594776511192 0.004732870496809483" quat="7.549790126404332e-08 0.0 0.0 1.0" name="start_button" rgba="0.0 0.5 0 0.5"/>
        <geom class="collision" type="box" pos="0.26053735613822937 -0.15416115522384644 -0.06360133737325668" size="0.008208844810724258 0.0006866594776511192 0.004732870496809483" quat="7.549790126404332e-08 0.0 0.0 1.0" name="stop_button" rgba="0.0 0.5 0 0.5"/>
        <geom mesh="Body001_vis" type="mesh" solimp="0.998 0.998 0.001" solref="0.001 1" friction="0.95 0.3 0.1" class="visual" material="Body001_material"/>
        <geom class="collision" type="box" pos="3.253939695468944e-08 0.018499720841646194 0.15523725748062134" size="0.31808313727378845 0.16186517477035522 0.012483902275562286" quat="1.0 0.0 0.0 0.0"/>
        <geom class="collision" type="box" pos="3.253939695468944e-08 0.018499623984098434 -0.15546952188014984" size="0.31808313727378845 0.16186530888080597 0.012251685373485088" quat="1.0 0.0 0.0 0.0"/>
        <geom class="collision" type="box" pos="-0.2788164019584656 0.013070734217762947 -3.253939695468944e-08" size="0.03926675394177437 0.1672941893339157 0.16772116720676422" quat="1.0 0.0 0.0 0.0"/>
        <geom class="collision" type="box" pos="0.2789028286933899 0.01434268243610859 -3.253939695468944e-08" size="0.039180297404527664 0.16602225601673126 0.16772116720676422" quat="1.0 0.0 0.0 0.0"/>
        <geom class="collision" type="box" pos="0.0003017265989910811 0.162059023976326 0.0010020019253715873" size="0.23873817920684814 0.018305867910385132 0.1639925241470337" quat="1.0 0.0 0.0 0.0"/>
        <geom class="collision" type="box" pos="0.2749432623386383 -0.14892856776714325 0.05402635782957077" size="0.033825330436229706 0.006060019135475159 0.10926877707242966" quat="1.0 0.0 0.0 0.0"/>
        <geom class="collision" type="box" pos="0.2749432623386383 -0.14892856776714325 -0.1168941855430603" size="0.033825330436229706 0.006060019135475159 0.04430419206619263" quat="1.0 0.0 0.0 0.0"/>
        <body name="door">
          <joint axis="0.0 0.0 1.0" pos="-0.23723044991493225 -0.15519970655441284 0.00048129024798981845" limited="true" name="microjoint" range="-1.5707963267948966 0.0" type="hinge" damping="1" frictionloss="1" armature=".01" stiffness="0.05"/>
          <geom mesh="door_vis" type="mesh" solimp="0.998 0.998 0.001" solref="0.001 1" friction="0.95 0.3 0.1" class="visual" material="door_material"/>
          <geom class="collision" type="box" pos="0.0011700426694005728 -0.1502472460269928 0.0010020118206739426" size="0.2286289930343628 0.004954578820616007 0.15800361335277557" quat="1.0 0.0 0.0 0.0"/>
          <geom class="collision" type="box" pos="0.21823181211948395 -0.16456030309200287 0.13639391958713531" size="0.01294736098498106 0.007895815186202526 0.004122595302760601" quat="1.0 0.0 0.0 0.0"/>
          <geom class="collision" type="box" pos="0.21823181211948395 -0.16456030309200287 -0.1250927597284317" size="0.012947376817464828 0.007895831018686295 0.004122603219002485" quat="1.0 0.0 0.0 0.0"/>
          <geom class="collision" type="box" pos="0.2184962034225464 -0.17673154175281525 0.0054675801657140255" size="0.013367043808102608 0.0036603729240596294 0.12303414940834045" quat="1.0 0.0 0.0 0.0" name="door_handle_main"/>
          <geom class="collision" type="box" pos="0.0011700516333803535 -0.15024720132350922 0.0003162422508466989" size="0.22008176147937775 0.00495464401319623 0.1036490947008133" quat="1.0 0.0 0.0 0.0"/>
          <geom class="collision" type="box" pos="0.0011700554750859737 -0.15246789157390594 0.00031623951508663595" size="0.22524408996105194 0.0022762250155210495 0.15532046556472778" quat="1.0 0.0 0.0 0.0" name="door_main"/>
          <body name="door_Clear">
            <geom mesh="door_Clear_vis" type="mesh" solimp="0.998 0.998 0.001" solref="0.001 1" friction="0.95 0.3 0.1" class="visual" material="door_Clear_material"/>
            <geom class="collision" type="box" pos="0.0011700516333803535 -0.15024720132350922 0.0003162422508466989" size="0.22008176147937775 0.00495464401319623 0.1036490947008133" quat="1.0 0.0 0.0 0.0"/>
          </body>
        </body>
        <body name="Disc001">
          <joint axis="0.0 0.0 1.0" pos="0.0 0.009555255062878132 -0.13731707632541656" limited="false" name="Disc001_joint" range="0 360" type="hinge" damping="1" frictionloss="1" armature=".01" stiffness="0.05"/>
          <geom mesh="Disc001_vis" type="mesh" solimp="0.998 0.998 0.001" solref="0.001 1" friction="0.95 0.3 0.1" class="visual" material="Disc001_material"/>
          <geom class="collision" type="cylinder" pos="-0.0004380145692266524 0.009111134335398674 -0.1378362476825714" size="0.11438768357038498 0.0030228509567677975" quat="1.0 0.0 0.0 0.0"/>
        </body>
        <geom class="region" name="reg_int" type="box" pos="0.00023759901523590088 0.0006918385624885559 0.004116557538509369" size="0.23496271467208862 0.1382411623597145 0.1320015246272087"/>
        <geom class="region" name="reg_main" type="box" pos="7.450580596923828e-09 0.01258152723312378 0.0" size="0.31908313727378845 0.16878337955474854 0.168721226811409"/>
      <geom class="region" name="reg_tray" type="cylinder" pos="-0.00043801116407848895 0.009111126884818077 0.004616522613912821" size="0.1143873780965805 0.13050155955180526"/></body>
    </body>
  </worldbody>
  <actuator>
    <motor name="microjoint_actuator" joint="microjoint" gear="10"/>
    <motor name="Disc001_joint_actuator" joint="Disc001_joint" gear="10"/>
  </actuator>
</mujoco>
