<?xml version='1.0' encoding='UTF-8'?>
<mujoco model="model">
  <option timestep="0.002" gravity="0.0 0.0 -9.81"/>
  <compiler angle="radian"/>
  <asset>
    <mesh file="visuals/door.obj" name="door_vis"/>
    <mesh file="visuals/knob_temp.obj" name="knob_temp_vis"/>
    <mesh file="visuals/knob_time.obj" name="knob_time_vis"/>
    <mesh file="visuals/Body001.obj" name="Body001_vis"/>
    <mesh file="visuals/tray0.obj" name="tray0_vis"/>
    <mesh file="visuals/window.obj" name="window_vis"/>
    <texture file="visuals/T_BC001.png" name="Body001_material" type="2d"/>
    <material name="Body001_material" rgba="1 1 1 1.0" texture="Body001_material" shininess="0.4472135901451111" specular="0.5"/>
    <texture file="visuals/T_BC001.png" name="door_material" type="2d"/>
    <material name="door_material" rgba="1 1 1 1.0" texture="door_material" shininess="0.4472135901451111" specular="0.5"/>
    <texture file="visuals/T_BC001.png" name="window_material" type="2d"/>
    <material name="window_material" rgba="1 1 1 0.699999988079071" texture="window_material" shininess="0.4472135901451111" specular="0.3103448502657381"/>
    <texture file="visuals/T_BC001.png" name="knob_temp_material" type="2d"/>
    <material name="knob_temp_material" rgba="1 1 1 1.0" texture="knob_temp_material" shininess="0.4472135901451111" specular="0.3103448502657381"/>
    <texture file="visuals/T_BC001.png" name="knob_time_material" type="2d"/>
    <material name="knob_time_material" rgba="1 1 1 1.0" texture="knob_time_material" shininess="0.4472135901451111" specular="0.3103448502657381"/>
    <texture file="visuals/T_BC001.png" name="tray0_material" type="2d"/>
    <material name="tray0_material" rgba="1 1 1 1.0" texture="tray0_material" shininess="0.4472135901451111" specular="5"/>
  </asset>
  <default>
    <default class="visual">
      <geom conaffinity="0" contype="0" group="1" type="mesh"/>
    </default>
    <default class="collision">
      <geom group="0" rgba="0.5 0 0 0.5"/>
    </default>
    <default class="spawn">
      <geom group="0" rgba="1 1 1 0.5" contype="0" conaffinity="0"/>
      <site group="0" rgba="1 1 1 0.5"/>
    </default>
    <default class="region">
      <geom group="1" conaffinity="0" contype="0" rgba="0 1 0 0"/>
    </default>
  </default>
  <worldbody>
    <body>
      <body name="object">
        <geom mesh="Body001_vis" type="mesh" solimp="0.998 0.998 0.001" solref="0.001 1" friction="0.95 0.3 0.1" class="visual" material="Body001_material"/>
        <geom class="collision" type="box" pos="-0.00059125 0.14488910 0.00569573" size="0.2506652772426605 0.010694536380469799 0.13638395071029663" quat="1.0 0.0 0.0 0.0"/>
        <geom class="collision" type="box" pos="0.20685564 0.01597658 0.00647319" size="0.044854067265987396 0.13960707187652588 0.13716137409210205" quat="1.0 0.0 0.0 0.0"/>
        <geom class="collision" type="box" pos="-0.02986608 0.02405762 0.13717505" size="0.20402953028678894 0.13152606785297394 0.006459514610469341" quat="1.0 0.0 0.0 0.0"/>
        <geom class="collision" type="box" pos="-0.03877307 0.03065138 -0.11452362" size="0.21293650567531586 0.12493230402469635 0.01616460084915161" quat="1.0 0.0 0.0 0.0"/>
        <geom class="collision" type="box" pos="0.19909005 0.02363088 0.00647317" size="0.044854067265987396 0.13195276260375977 0.13716138899326324" quat="1.0 0.0 0.0 0.0"/>
        <geom class="collision" type="box" pos="-0.23840901 0.02892765 0.00647318" size="0.0133005166426301 0.12665598094463348 0.13716137409210205" quat="1.0 0.0 0.0 0.0"/>
        <geom class="collision" type="box" pos="-0.22257699 0.02520874 0.02768251" size="0.0060947914607822895 0.10913117974996567 0.0057051172479987144" quat="1.0 0.0 0.0 0.0"/>
        <geom class="collision" type="box" pos="-0.22257699 0.02520874 -0.01780193" size="0.0060947914607822895 0.10913117974996567 0.0057051172479987144" quat="1.0 0.0 0.0 0.0"/>
        <geom class="collision" type="box" pos="0.15056656 0.02520874 -0.01780193" size="0.0060947914607822895 0.10913117974996567 0.0057051172479987144" quat="1.0 0.0 0.0 0.0"/>
        <geom class="collision" type="box" pos="0.15056656 0.02520874 0.02768251" size="0.0060947914607822895 0.10913117974996567 0.0057051172479987144" quat="1.0 0.0 0.0 0.0"/>
        <geom class="collision" type="box" pos="-0.23861252 0.01565241 0.00647318" size="0.013097071088850498 0.13993124663829803 0.13716137409210205" quat="1.0 0.0 0.0 0.0"/>
        <geom class="collision" type="box" pos="-0.03877307 0.01660719 -0.12655438" size="0.21293650567531586 0.12613962590694427 0.00413384148851037" quat="1.0 0.0 0.0 0.0"/>
        <geom class="collision" type="box" pos="0.22448654 0.12675644 -0.13372813" size="0.009974041022360325 0.009974041022360325 0.009906613267958164" quat="1.0 0.0 0.0 0.0"/>
        <geom class="collision" type="box" pos="-0.22669877 -0.08361815 -0.13372813" size="0.009974027052521706 0.009974027052521706 0.00990660022944212" quat="1.0 0.0 0.0 0.0"/>
        <geom class="collision" type="box" pos="-0.22669877 0.12675644 -0.13372813" size="0.009974014014005661 0.009974014014005661 0.009906587190926075" quat="1.0 0.0 0.0 0.0"/>
        <geom class="collision" type="box" pos="0.22448654 -0.08361815 -0.13372813" size="0.009974000975489616 0.009974000975489616 0.00990657415241003" quat="1.0 0.0 0.0 0.0"/>
        <body name="door">
          <joint axis="1.0 0.0 0.0" pos="-0.03542544 -0.12256055 -0.12482603" limited="true" name="door_joint" range="0.0 1.5007963267948966" type="hinge" damping="1" frictionloss="1" armature=".01" stiffness="0.05"/>
          <geom mesh="door_vis" type="mesh" solimp="0.998 0.998 0.001" solref="0.001 1" friction="0.95 0.3 0.1" class="visual" material="door_material"/>
          <geom class="collision" type="box" pos="-0.03526337 -0.11748564 0.00639889" size="0.1890205442905426 0.0064972518011927605 0.13636209070682526" quat="1.0 0.0 0.0 0.0" name="door_main"/>
          <geom class="collision" type="box" pos="-0.21293676 -0.13845308 0.12351253" size="0.008080609142780304 0.013857000507414341 0.010371197946369648" quat="1.0 0.0 0.0 0.0"/>
          <geom class="collision" type="box" pos="0.14459327 -0.13797788 0.12299037" size="0.008163787424564362 0.013381817378103733 0.011532715521752834" quat="1.0 0.0 0.0 0.0"/>
          <geom class="collision" type="cylinder" pos="-0.03581104 -0.14162278 0.12434348" size="0.008574376814067364 0.1726255565881729" quat="0.7071068286895752 -4.750302551315144e-08 -0.7071067094802856 -4.7503014855010406e-08" name="door_handle_main"/>
          <body name="window">
            <geom mesh="window_vis" type="mesh" solimp="0.998 0.998 0.001" solref="0.001 1" friction="0.95 0.3 0.1" class="visual" material="window_material"/>
            <geom class="collision" type="box" pos="-0.03540860 -0.11673247 0.01337355" size="0.18871034681797028 0.0024410283658653498 0.10646211355924606" quat="1.0 0.0 0.0 0.0"/>
          </body>
        </body>
        <body name="knob_temp">
          <joint axis="0.0 1.0 0.0" pos="0.20639108 -0.13978750 0.06811700" limited="true" name="knob_temp_joint" range="0.0 4.363323129985823" type="hinge" damping="0.05" frictionloss="0.75" armature="1"/>
          <geom mesh="knob_temp_vis" type="mesh" solimp="0.998 0.998 0.001" solref="0.001 1" friction="0.95 0.3 0.1" class="visual" material="knob_temp_material"/>
          <geom class="collision" type="cylinder" pos="0.20678236 -0.13111629 0.06796739" size="0.027087995782494545 0.005860324949026108" quat="0.7071068286895752 0.7071067690849304 1.5700924318127872e-16 5.9269340452702814e-24" friction="100 0.5 0.01"/>
          <geom class="collision" type="box" pos="0.20609587 -0.14582746 0.06811240" size="0.020894603803753853 0.009981375187635422 0.006096269004046917" quat="1.0 0.0 0.0 0.0" name="knob_temp_main" friction="100 0.5 0.01"/>
        </body>
        <body name="knob_time">
          <joint axis="0.0 1.0 0.0" pos="0.20639108 -0.13978750 -0.05860511" limited="true" name="knob_time_joint" range="0.0 4.71238898038469" type="hinge" damping="0.05" frictionloss="0.75" armature="1"/>
          <geom mesh="knob_time_vis" type="mesh" solimp="0.998 0.998 0.001" solref="0.001 1" friction="0.95 0.3 0.1" class="visual" material="knob_time_material"/>
          <geom class="collision" type="box" pos="0.20609587 -0.14582746 -0.05832410" size="0.020894603803753853 0.009981375187635422 0.006096269004046917" quat="1.0 0.0 0.0 0.0" name="knob_time_main" friction="100 0.5 0.01"/>
          <geom class="collision" type="cylinder" pos="0.20657925 -0.13111629 -0.05848961" size="0.027087995782494545 0.005860324949026108" quat="0.7071068286895752 0.7071067690849304 1.5700924318127872e-16 5.9269340452702814e-24" friction="100 0.5 0.01"/>
        </body>
        <body name="tray0">
          <geom class="region" name="reg_tray0" type="box" pos="-0.034567385 0.021764690000000003 0.05311442500000001" size="0.158637805 0.09104215 0.07530392500000001"/>
          <joint axis="0.0 -1.0 0.0" pos="-0.03560957 0.02247225 -0.01746674" limited="true" name="tray0_joint" range="0.0 0.18" type="slide" damping="1" frictionloss="1" armature=".01" stiffness="0.05"/>
          <geom mesh="tray0_vis" type="mesh" solimp="0.998 0.998 0.001" solref="0.001 1" friction="0.95 0.3 0.1" class="visual" material="tray0_material"/>
          <geom class="collision" type="box" pos="0.13604307 0.02126916 -0.01737767" size="0.09847038239240646 0.008824340999126434 0.0015168222598731518" quat="0.5913967490196228 0.3876209557056427 -0.38762110471725464 -0.5913964509963989"/>
          <geom class="collision" type="box" pos="-0.03498271 0.02126916 -0.02556181" size="0.170340895652771 0.09846960008144379 0.0015168222598731518" quat="1.0 0.0 0.0 0.0"/>
          <geom class="collision" type="box" pos="-0.03420789 0.12466425 -0.01789094" size="0.1700173318386078 0.008824369870126247 0.001516826217994094" quat="1.7852143230356887e-07 1.0509911874123645e-07 0.6175944209098816 -0.7864967584609985"/>
          <geom class="collision" type="box" pos="-0.20705339 0.02126916 -0.01737767" size="0.09847038239240646 0.008824340999126434 0.0015168222598731518" quat="0.5913967490196228 -0.3876209557056427 0.38762110471725464 -0.5913964509963989"/>
          <geom class="collision" type="box" pos="-0.03420789 -0.07962590 -0.01789094" size="0.1700173318386078 0.008824369870126247 0.001516826217994094" quat="2.7227920895711577e-07 -3.147618343746217e-08 -0.6175944209098816 -0.7864967584609985"/>
          <geom class="collision" type="box" pos="-0.03031568 0.12891328 -0.00909508" size="0.16417618095874786 0.002867063507437706 0.0010925796814262867" quat="1.0 0.0 0.0 0.0"/>
          <geom class="collision" type="box" pos="-0.03031568 -0.08389456 -0.00909508" size="0.16417618095874786 0.002867063507437706 0.0010925796814262867" quat="1.0 0.0 0.0 0.0"/>
          <geom class="collision" type="box" pos="0.14340428 0.02154557 -0.00909508" size="0.004880692344158888 0.09095386415719986 0.0010925796814262867" quat="1.0 0.0 0.0 0.0"/>
          <geom class="collision" type="box" pos="0.13616538 -0.07599518 -0.00909508" size="0.01407044567167759 0.004880691412836313 0.0010925796814262867" quat="0.3579157590866089 0.0 -0.0 -0.9337539076805115"/>
          <geom class="collision" type="box" pos="0.13647191 0.12089193 -0.00909508" size="0.014070444740355015 0.004880690947175026 0.0010925796814262867" quat="0.35791587829589844 0.0 0.0 0.9337538480758667"/>
          <geom class="collision" type="box" pos="-0.20581017 0.12089193 -0.00909508" size="0.014070444740355015 0.004880690947175026 0.0010925796814262867" quat="0.35791587829589844 0.0 -0.0 -0.9337538480758667"/>
          <geom class="collision" type="box" pos="-0.20550364 -0.07599518 -0.00909508" size="0.014070444740355015 0.004880690947175026 0.0010925796814262867" quat="0.35791587829589844 0.0 0.0 0.9337538480758667"/>
          <geom class="collision" type="box" pos="-0.21274254 0.02154557 -0.00909508" size="0.004880692344158888 0.09095386415719986 0.0010925796814262867" quat="1.0 0.0 0.0 0.0"/>
        </body>
        <geom class="region" name="reg_main" type="box" pos="0.0 0.015572649999999993 0.0" size="0.25270904 0.141011 0.14463457"/>
      </body>
    </body>
  </worldbody>
  <actuator>
    <motor name="door_joint_actuator" joint="door_joint" gear="50"/>
    <motor name="knob_temp_joint_actuator" joint="knob_temp_joint" gear="50"/>
    <motor name="knob_time_joint_actuator" joint="knob_time_joint" gear="50"/>
    <motor name="tray0_joint_actuator" joint="tray0_joint" gear="50"/>
  </actuator>
</mujoco>