<?xml version='1.0' encoding='UTF-8'?>
<mujoco model="model">
  <option timestep="0.002" gravity="0.0 0.0 -9.81"/>
  <compiler angle="radian"/>
  <asset>
    <mesh file="visuals/door.obj" name="door_vis"/>
    <mesh file="visuals/knob_doneness.obj" name="knob_doneness_vis"/>
    <mesh file="visuals/knob_temp.obj" name="knob_temp_vis"/>
    <mesh file="visuals/knob_time.obj" name="knob_time_vis"/>
    <mesh file="visuals/rack0.obj" name="rack0_vis"/>
    <mesh file="visuals/Body001.obj" name="Body001_vis"/>
    <mesh file="visuals/window.obj" name="window_vis"/>
    <texture file="visuals/T_BC001.png" name="Body001_material" type="2d"/>
    <material name="Body001_material" rgba="1 1 1 1.0" texture="Body001_material" shininess="0.5" specular="1"/>
    <texture file="visuals/T_BC001.png" name="door_material" type="2d"/>
    <material name="door_material" rgba="1 1 1 1.0" texture="door_material" shininess="0.5" specular="0.3103448502657381"/>
    <material name="window_material" rgba="0.021757163107395172 0.021757163107395172 0.021757163107395172 0.800000011920929" shininess="0.4472135901451111" specular="0.3103448502657381"/>
    <texture file="visuals/T_BC001.png" name="knob_doneness_material" type="2d"/>
    <material name="knob_doneness_material" rgba="1 1 1 1.0" texture="knob_doneness_material" shininess="0.5" specular="1"/>
    <texture file="visuals/T_BC001.png" name="knob_temp_material" type="2d"/>
    <material name="knob_temp_material" rgba="1 1 1 1.0" texture="knob_temp_material" shininess="0.5" specular="1"/>
    <texture file="visuals/T_BC001.png" name="knob_time_material" type="2d"/>
    <material name="knob_time_material" rgba="1 1 1 1.0" texture="knob_time_material" shininess="0.5" specular="1"/>
    <texture file="visuals/T_BC001.png" name="rack0_material" type="2d"/>
    <material name="rack0_material" rgba="1 1 1 1.0" texture="rack0_material" shininess="0.1" specular="2"/>
  </asset>
  <default>
    <default class="visual">
      <geom conaffinity="0" contype="0" group="1" type="mesh"/>
    </default>
    <default class="collision">
      <geom group="0" rgba="0.5 0 0 0.5"/>
    </default>
    <default class="spawn">
      <geom group="0" rgba="1 1 1 0.5" contype="0" conaffinity="0"/>
      <site group="0" rgba="1 1 1 0.5"/>
    </default>
    <default class="region">
      <geom group="1" conaffinity="0" contype="0" rgba="0 1 0 0"/>
    </default>
  </default>
  <worldbody>
    <body>
      <body name="object">
        <geom mesh="Body001_vis" type="mesh" solimp="0.998 0.998 0.001" solref="0.001 1" friction="0.95 0.3 0.1" class="visual" material="Body001_material"/>
        <geom class="collision" type="box" pos="-0.00000001 0.02272006 0.12798309" size="0.17448489367961884 0.14800481498241425 0.05254647135734558" quat="1.0 0.0 0.0 0.0"/>
        <geom class="collision" type="box" pos="0.16007210 0.03728922 -0.04388251" size="0.014412807300686836 0.1334356665611267 0.11869251728057861" quat="1.0 0.0 0.0 0.0"/>
        <geom class="collision" type="box" pos="-0.16175087 0.03728922 -0.04388251" size="0.012734025716781616 0.1334356665611267 0.11869251728057861" quat="1.0 0.0 0.0 0.0"/>
        <geom class="collision" type="box" pos="-0.00108027 0.03728922 -0.13771476" size="0.15106576681137085 0.1334356665611267 0.024860244244337082" quat="1.0 0.0 0.0 0.0"/>
        <geom class="collision" type="box" pos="0.13047362 -0.06206644 -0.17682417" size="0.013797158375382423 0.020553654059767723 0.013229581527411938" quat="1.0 0.0 0.0 0.0"/>
        <geom class="collision" type="box" pos="-0.13088968 -0.06206644 -0.17682417" size="0.013797158375382423 0.020553654059767723 0.013229581527411938" quat="1.0 0.0 0.0 0.0"/>
        <geom class="collision" type="box" pos="-0.13088968 0.11990667 -0.17682417" size="0.013797158375382423 0.020553654059767723 0.013229581527411938" quat="1.0 0.0 0.0 0.0"/>
        <geom class="collision" type="box" pos="0.13047362 0.11990667 -0.17682417" size="0.013797158375382423 0.020553654059767723 0.013229581527411938" quat="1.0 0.0 0.0 0.0"/>
        <geom class="collision" type="box" pos="-0.00108027 0.15339508 -0.03179705" size="0.15106576681137085 0.017329802736639977 0.09266500920057297" quat="1.0 0.0 0.0 0.0"/>
        <geom class="collision" type="cylinder" pos="-0.12008297 -0.05085678 0.18588106" size="0.018852870911359787 0.004346936941146851" quat="1.0 0.0 0.0 0.0"/>
        <geom class="collision" type="box" pos="-0.00000001 0.03588265 0.06753710" size="0.17448489367961884 0.13484223186969757 0.006638281047344208" quat="1.0 0.0 0.0 0.0"/>
        <body name="door">
          <joint axis="1.0 0.0 0.0" pos="-0.00040425 -0.10061286 -0.16021864" limited="true" name="door_joint" range="0.0 1.3707963267948966" type="hinge" damping="1" frictionloss="1" armature=".01" stiffness="1" springref="-1"/>
          <geom mesh="door_vis" type="mesh" solimp="0.998 0.998 0.001" solref="0.001 1" friction="0.95 0.3 0.1" class="visual" material="door_material"/>
          <geom class="collision" type="box" pos="-0.00041651 -0.11221485 0.04770131" size="0.1740684062242508 0.012733486481010914 0.022895297035574913" quat="1.0 0.0 0.0 0.0" name="door_main"/>
          <geom class="collision" type="box" pos="-0.00041651 -0.11221485 -0.13547502" size="0.1740684062242508 0.012733486481010914 0.02649698220193386" quat="1.0 0.0 0.0 0.0"/>
          <geom class="collision" type="box" pos="0.15073443 -0.11221485 -0.04228939" size="0.022917453199625015 0.012733486481010914 0.06640858948230743" quat="1.0 0.0 0.0 0.0"/>
          <geom class="collision" type="box" pos="-0.15170371 -0.11221485 -0.04228939" size="0.02278120629489422 0.012733486481010914 0.06640858948230743" quat="1.0 0.0 0.0 0.0"/>
          <geom class="collision" type="box" pos="0.00007535 -0.16387016 0.04952180" size="0.11858848482370377 0.007239746395498514 0.0067580463364720345" quat="1.0 0.0 0.0 0.0" name="door_handle_main"/>
          <geom class="collision" type="box" pos="0.12718798 -0.15800486 0.04952180" size="0.011782891117036343 0.007239751052111387 0.0067580463364720345" quat="0.9546672701835632 0.0 0.0 0.2976749837398529"/>
          <geom class="collision" type="box" pos="0.13577394 -0.13777704 0.05033479" size="0.0072519825771451 0.012733486481010914 0.007151295896619558" quat="1.0 0.0 0.0 0.0"/>
          <geom class="collision" type="box" pos="-0.13682040 -0.13777704 0.05033479" size="0.0072519825771451 0.012733486481010914 0.007151295896619558" quat="1.0 0.0 0.0 0.0"/>
          <geom class="collision" type="box" pos="-0.12823444 -0.15800486 0.04952180" size="0.011782891117036343 0.0072397505864501 0.0067580463364720345" quat="0.954667329788208 0.0 -0.0 -0.29767486453056335"/>
          <body name="window">
            <geom mesh="window_vis" type="mesh" solimp="0.998 0.998 0.001" solref="0.001 1" friction="0.95 0.3 0.1" class="visual" material="window_material"/>
            <geom class="collision" type="box" pos="-0.00040422 -0.11185569 -0.04209067" size="0.13204176723957062 0.0008127555483952165 0.06750289350748062" quat="1.0 0.0 0.0 0.0"/>
          </body>
        </body>
        <body name="knob_doneness">
          <joint axis="0.0 1.0 0.0" pos="0.10064416 -0.13287525 0.12071139" limited="true" name="knob_doneness_joint" range="0.0 4.71238898038469" type="hinge" damping="0.05" frictionloss="0.1" armature="0.001"/>
          <geom mesh="knob_doneness_vis" type="mesh" solimp="0.998 0.998 0.001" solref="0.001 1" friction="0.95 0.3 0.1" class="visual" material="knob_doneness_material"/>
          <geom class="collision" type="cylinder" pos="0.10066740 -0.12915023 0.12072199" size="0.023851629346609116 0.002440948272123933" quat="0.7071067094802856 0.7071068286895752 0.0 0.0" density="0.001"/>
          <geom class="collision" type="box" pos="0.10062587 -0.13799687 0.12041463" size="0.009907152503728867 0.006859925575554371 0.022295232862234116" quat="1.0 0.0 0.0 0.0" name="knob_doneness_main" density="0.001"/>
        </body>
        <body name="knob_temp">
          <joint axis="0.0 1.0 0.0" pos="-0.00087003 -0.13294226 0.12034318" limited="true" name="knob_temp_joint" range="0.0 3.9269908169872414" type="hinge" damping="0.05" armature="0.001"/>
          <geom mesh="knob_temp_vis" type="mesh" solimp="0.998 0.998 0.001" solref="0.001 1" friction="0.95 0.3 0.1" class="visual" material="knob_temp_material"/>
          <geom class="collision" type="cylinder" pos="-0.00072928 -0.12920167 0.12037640" size="0.023851629346609116 0.002440948272123933" quat="0.7071067094802856 0.7071068286895752 0.0 0.0"/>
          <geom class="collision" type="box" pos="-0.00107895 -0.13799687 0.12041463" size="0.009907152503728867 0.006859925575554371 0.022295232862234116" quat="1.0 0.0 0.0 0.0" name="knob_temp_main"/>
        </body>
        <body name="knob_time">
          <joint axis="0.0 1.0 0.0" pos="-0.10013335 -0.13287525 0.12041463" limited="true" name="knob_time_joint" range="0.0 5.061454830783556" type="hinge" damping="0.05" frictionloss="0.1" armature="0.001"/>
          <geom mesh="knob_time_vis" type="mesh" solimp="0.998 0.998 0.001" solref="0.001 1" friction="0.95 0.3 0.1" class="visual" material="knob_time_material"/>
          <geom class="collision" type="cylinder" pos="-0.10018314 -0.12935688 0.12037640" size="0.023851629346609116 0.002440948272123933" quat="0.7071067094802856 0.7071068286895752 0.0 0.0" density="0.001"/>
          <geom class="collision" type="box" pos="-0.10013334 -0.13799687 0.12041463" size="0.009907152503728867 0.006859925575554371 0.022295232862234116" quat="1.0 0.0 0.0 0.0" name="knob_time_main" density="0.001"/>
        </body>
        <body name="rack0">
          <geom class="region" name="reg_rack0" type="box" pos="-0.002246275000000006 0.005007224999999997 -0.012154429999999997" size="0.118231505 0.070620615 0.07366643"/>
          <joint axis="0.0 -1.0 0.0" pos="-0.00220429 0.00410681 -0.08006415" limited="true" name="rack0_joint" range="0.0 0.15" type="slide" damping="1" frictionloss="1" armature=".01" stiffness="0.05"/>
          <geom mesh="rack0_vis" type="mesh" solimp="0.998 0.998 0.001" solref="0.001 1" friction="0.95 0.3 0.1" class="visual" material="rack0_material"/>
          <geom class="collision" type="box" pos="-0.00181768 0.00406032 -0.08660118" size="0.12071013450622559 0.07201956957578659 0.0015690032159909606" quat="1.0 0.0 0.0 0.0"/>
          <geom class="collision" type="box" pos="-0.14514127 0.00406032 -0.07314283" size="0.002135306829586625 0.07201956957578659 0.0020079300738871098" quat="1.0 0.0 0.0 0.0"/>
          <geom class="collision" type="box" pos="-0.13190224 0.07458864 -0.07700156" size="0.01336704846471548 0.0014912441838532686 0.003435014048591256" quat="0.9227885603904724 2.2248139864010667e-15 0.385306715965271 5.1769355025044206e-08"/>
          <geom class="collision" type="box" pos="-0.13190224 -0.06630195 -0.07700156" size="0.01336704846471548 0.0014912441838532686 0.003435014048591256" quat="0.9227885603904724 2.2248139864010667e-15 0.385306715965271 5.1769355025044206e-08"/>
          <geom class="collision" type="box" pos="0.12734095 -0.06630195 -0.07700156" size="0.013367047533392906 0.0014912441838532686 0.0034350142814219" quat="0.9227885603904724 1.0946873392296812e-14 -0.3853067457675934 -5.1769358577757885e-08"/>
          <geom class="collision" type="box" pos="0.12734095 0.07458864 -0.07700156" size="0.013367047533392906 0.0014912441838532686 0.0034350142814219" quat="0.9227885603904724 1.0946873392296812e-14 -0.3853067457675934 -5.1769358577757885e-08"/>
          <geom class="collision" type="box" pos="0.14057998 0.00406032 -0.07314283" size="0.002135306829586625 0.07201956957578659 0.0020079300738871098" quat="1.0 0.0 0.0 0.0"/>
        </body>
        <geom class="region" name="reg_main" type="box" pos="5.0994999999998125e-05 0.023709474999999994 -0.000264285000000003" size="0.186088545 0.15870885499999998 0.202614455"/>
      </body>
    </body>
  </worldbody>
  <actuator>
    <motor name="door_joint_actuator" joint="door_joint" gear="50"/>
    <motor name="knob_doneness_joint_actuator" joint="knob_doneness_joint" gear="50"/>
    <motor name="knob_temp_joint_actuator" joint="knob_temp_joint" gear="50"/>
    <motor name="knob_time_joint_actuator" joint="knob_time_joint" gear="50"/>
    <motor name="rack0_joint_actuator" joint="rack0_joint" gear="50"/>
  </actuator>
</mujoco>
