<?xml version='1.0' encoding='UTF-8'?>
<mujoco model="model">
  <option timestep="0.002" gravity="0.0 0.0 -9.81"/>
  <compiler angle="radian"/>
  <asset>
    <mesh file="visuals/handle.obj" name="handle_vis"/>
    <mesh file="visuals/Body001.obj" name="Body001_vis"/>
    <mesh file="visuals/Shelf001.obj" name="Shelf001_vis"/>
    <mesh file="visuals/spout.obj" name="spout_vis"/>
    <texture file="visuals/T_BC001.png" name="Body001_material" type="2d"/>
    <material name="Body001_material" rgba="1 1 1 1.0" texture="Body001_material" shininess="0.5" specular="1"/>
    <texture file="visuals/T_BC001.png" name="handle_material" type="2d"/>
    <material name="handle_material" rgba="1 1 1 1.0" texture="handle_material" shininess="0.5" specular="0.3103448502657381"/>
    <texture file="visuals/T_BC001.png" name="Shelf001_material" type="2d"/>
    <material name="Shelf001_material" rgba="1 1 1 1.0" texture="Shelf001_material" shininess="0.5" specular="2"/>
    <texture file="visuals/T_BC001.png" name="spout_material" type="2d"/>
    <material name="spout_material" rgba="1 1 1 1.0" texture="spout_material" shininess="0.5" specular="1"/>
  </asset>
  <default>
    <default class="visual">
      <geom conaffinity="0" contype="0" group="1" type="mesh"/>
    </default>
    <default class="collision">
      <geom group="0" rgba="0.5 0 0 0.5"/>
    </default>
    <default class="spawn">
      <geom group="0" rgba="1 1 1 0.5" contype="0" conaffinity="0"/>
      <site group="0" rgba="1 1 1 0.5"/>
    </default>
    <default class="region">
      <geom group="1" conaffinity="0" contype="0" rgba="0 1 0 0"/>
    </default>
  </default>
  <worldbody>
    <body>
      <body name="object">
        <geom mesh="Body001_vis" type="mesh" solimp="0.998 0.998 0.001" solref="0.001 1" friction="0.95 0.3 0.1" class="visual" material="Body001_material"/>
        <geom class="collision" type="box" pos="0.00000004 0.20637435 -0.06735937" size="0.39519259333610535 0.04176409915089607 0.004091817419975996" quat="1.0 0.0 0.0 0.0"/>
        <geom class="collision" type="box" pos="-0.00000002 -0.23008915 -0.06822311" size="0.39519232511520386 0.01815597340464592 0.004955556709319353" quat="1.0 0.0 0.0 0.0"/>
        <geom class="collision" type="box" pos="-0.37927532 -0.02353512 -0.06738956" size="0.015911314636468887 0.18962140381336212 0.004121942445635796" quat="1.0 0.0 0.0 0.0"/>
        <geom class="collision" type="box" pos="0.37956685 -0.02353512 -0.06736496" size="0.015619810670614243 0.1896211802959442 0.004097337834537029" quat="1.0 0.0 0.0 0.0"/>
        <geom class="collision" type="box" pos="0.36319739 -0.02948447 -0.16913989" size="0.004510981496423483 0.1830652505159378 0.10467592626810074" quat="1.0 0.0 0.0 0.0"/>
        <geom class="collision" type="box" pos="-0.36474544 -0.02948447 -0.16913989" size="0.005223824642598629 0.1830650120973587 0.10467581450939178" quat="1.0 0.0 0.0 0.0"/>
        <geom class="collision" type="box" pos="-0.00070086 -0.21607165 -0.16913989" size="0.369448184967041 0.004152165725827217 0.10467569530010223" quat="1.0 0.0 0.0 0.0"/>
        <geom class="collision" type="box" pos="-0.00092678 0.15651350 -0.16913989" size="0.36971351504325867 0.003984092269092798 0.10467558354139328" quat="1.0 0.0 0.0 0.0"/>
        <geom class="collision" type="box" pos="-0.00282185 -0.02706097 -0.26766643" size="0.36301255226135254 0.18428730964660645 0.0037265485152602196" quat="1.0 0.0 0.0 0.0"/>
        <geom class="collision" type="cylinder" pos="-0.00332899 0.19647934 -0.01538238" size="0.023983795195817947 0.04595727100968361" quat="1.0 0.0 0.0 0.0"/>
        <geom class="collision" type="cylinder" pos="0.01108128 0.19647934 -0.01658595" size="0.021613165736198425 0.038016535341739655" quat="0.7071068286895752 -0.0 0.7071067690849304 0.0"/>
        <geom class="collision" type="box" pos="0.22211067 0.06790739 -0.27878553" size="0.09791813045740128 0.04313885420560837 0.007659433409571648" quat="1.0 0.0 0.0 0.0"/>
        <geom class="collision" type="box" pos="0.26883179 -0.02330551 -0.27878553" size="0.05119697377085686 0.05309313163161278 0.007659432012587786" quat="1.0 0.0 0.0 0.0"/>
        <body name="handle">
          <joint axis="1.0 0.0 0.0" pos="0.07444862 0.19651009 -0.01711256" limited="true" name="handle_temp_joint" type="hinge" range="-0.7853981633974483 0.7853981633974483" damping="1" frictionloss="1" armature=".01" stiffness="0.05"/>
          <joint axis="0.0 1.0 0.0" pos="0.07444862 0.19651009 -0.01711256" limited="true" name="handle_joint" type="hinge" range="0 0.5" damping="1" frictionloss="1" armature=".01" stiffness="0.05"/>
          <geom mesh="handle_vis" type="mesh" solimp="0.998 0.998 0.001" solref="0.001 1" friction="0.95 0.3 0.1" class="visual" material="handle_material"/>
          <geom class="collision" type="cylinder" pos="0.07855663 0.19713252 -0.01680377" size="0.021303892135620117 0.011302345432341099" quat="0.7071068286895752 -0.0 0.7071067690849304 0.0"/>
          <geom class="collision" type="cylinder" pos="0.07769476 0.19686373 0.03081148" size="0.005681407637894154 0.024712152779102325" quat="1.0 0.0 0.0 0.0"/>
        </body>
        <body name="Shelf001">
          <joint axis="0.0 0.0 1.0" pos="-0.25478467 -0.01744983 -0.09954712" limited="true" name="Shelf001_joint" range="0.0 0.1" type="slide" damping="1" frictionloss="1" armature=".01" stiffness="0.05"/>
          <geom mesh="Shelf001_vis" type="mesh" solimp="0.998 0.998 0.001" solref="0.001 1" friction="0.95 0.3 0.1" class="visual" material="Shelf001_material"/>
          <geom class="collision" type="box" pos="-0.33398774 -0.02822587 -0.08729640" size="0.007228539790958166 0.1687678098678589 0.03499460965394974" quat="1.0 0.0 0.0 0.0"/>
          <geom class="collision" type="box" pos="-0.17308277 -0.03690955 -0.08729640" size="0.005995806772261858 0.16302910447120667 0.03499455377459526" quat="1.0 0.0 0.0 0.0"/>
          <geom class="collision" type="box" pos="-0.24860589 -0.20206940 -0.10036150" size="0.07432298362255096 0.0024261516518890858 0.03369440883398056" quat="0.9940372705459595 0.10904084146022797 0.0 0.0"/>
          <geom class="collision" type="box" pos="-0.24860589 0.14222980 -0.09760116" size="0.07432298362255096 0.0024261516518890858 0.03723553195595741" quat="0.9963814616203308 -0.08499402552843094 -0.0 0.0"/>
          <geom class="collision" type="box" pos="-0.25271779 -0.02975524 -0.13525485" size="0.07255373150110245 0.16592520475387573 0.0029326912481337786" quat="1.0 0.0 0.0 0.0"/>
          <geom class="collision" type="box" pos="-0.25245929 0.17150735 -0.05747816" size="0.08537273108959198 0.022228378802537918 0.004666319582611322" quat="1.0 0.0 0.0 0.0"/>
          <geom class="collision" type="box" pos="-0.25245929 -0.21764038 -0.05787031" size="0.08537261933088303 0.010309925302863121 0.005058464128524065" quat="1.0 0.0 0.0 0.0"/>
        </body>
        <body name="spout">
          <joint axis="0.0 0.0 1.0" pos="-0.00280519 0.19689568 0.13014515" limited="true" name="spout_joint" range="-1.1344640137963142 1.1344640137963142" type="hinge" damping="1" frictionloss="1" armature=".01" stiffness="0.05"/>
          <site type="cylinder" rgba="0.5 0.75 1 0.5" size="0.005716228857636452 0.21865792572498322" pos="-0.00350536 0.01167345 -0.05062795" name="water"/>
          <geom mesh="spout_vis" type="mesh" solimp="0.998 0.998 0.001" solref="0.001 1" friction="0.95 0.3 0.1" class="visual" material="spout_material"/>
          <geom class="collision" type="cylinder" pos="-0.00364665 0.19572318 0.11842547" size="0.015766173601150513 0.08489116281270981" quat="1.0 0.0 0.0 0.0" name="spout_main"/>
          <geom class="collision" type="cylinder" pos="-0.00364665 0.18448438 0.22890529" size="0.015766173601150513 0.020500902086496353" quat="0.9670015573501587 0.254770427942276 0.0 0.0"/>
          <geom class="collision" type="cylinder" pos="-0.00364665 0.16318922 0.25432944" size="0.015766173601150513 0.020500902086496353" quat="0.9004788994789124 0.4348997473716736 0.0 0.0"/>
          <geom class="collision" type="cylinder" pos="-0.00364665 0.19286940 0.20691466" size="0.015766173601150513 0.005798363126814365" quat="0.9954514503479004 0.09527008980512619 0.0 0.0"/>
          <geom class="collision" type="cylinder" pos="-0.00364665 0.13562762 0.26768228" size="0.015766173601150513 0.020500902086496353" quat="0.8072229027748108 0.5902467370033264 0.0 0.0"/>
          <geom class="collision" type="cylinder" pos="-0.00364665 0.09963213 0.27220744" size="0.015766173601150513 0.020500902086496353" quat="0.6380579471588135 0.7699883580207825 0.0 0.0"/>
          <geom class="collision" type="cylinder" pos="-0.00364665 0.06404803 0.26068890" size="0.015766173601150513 0.020500902086496353" quat="0.46678173542022705 0.8843725323677063 -2.902466588990982e-17 3.50260498311617e-17"/>
          <geom class="collision" type="cylinder" pos="-0.00364665 0.03504595 0.23497784" size="0.015766173601150513 0.020500902086496353" quat="0.3206758201122284 0.9471890330314636 -5.0641876454848075e-17 6.111298377558944e-17"/>
          <geom class="collision" type="cylinder" pos="-0.00364665 0.01599893 0.19159432" size="0.015766173601150513 0.02976146526634693" quat="0.15284669399261475 0.9882498979568481 -7.266236403818553e-17 8.768669034944749e-17"/>
        </body>
        <geom class="region" name="reg_basin" type="box" pos="0.09232056 -0.028024789999999994 -0.16308332" size="0.25805168 0.17850414 0.09915925"/>
        <geom class="region" name="reg_main" type="box" pos="-4.999999997368221e-09 -1.4500000000694513e-07 -0.17484919499999999" size="0.396186485 0.249244895 0.112596795"/>
      </body>
    </body>
  </worldbody>
  <actuator>
    <motor name="handle_joint_actuator" joint="handle_joint" gear="10"/>
    <motor name="handle_temp_joint_actuator" joint="handle_temp_joint" gear="10"/>
    <motor name="Shelf001_joint_actuator" joint="Shelf001_joint" gear="10"/>
    <motor name="spout_joint_actuator" joint="spout_joint" gear="10"/>
  </actuator>
</mujoco>
