<?xml version='1.0' encoding='UTF-8'?>
<mujoco model="model">
  <option timestep="0.002" gravity="0.0 0.0 -9.81"/>
  <compiler angle="radian"/>
  <asset>
    <mesh file="visuals/door.obj" name="door_vis"/>
    <mesh file="visuals/door_Clear.obj" name="door_Clear_vis"/>
    <mesh file="visuals/knob_temp.obj" name="knob_temp_vis"/>
    <mesh file="visuals/knob_time.obj" name="knob_time_vis"/>
    <mesh file="visuals/Body001.obj" name="Body001_vis"/>
    <mesh file="visuals/rack0.obj" name="rack0_vis"/>
    <mesh file="visuals/rack1.obj" name="rack1_vis"/>
    <texture file="visuals/T_BC001.png" name="Body001_material" type="2d"/>
    <material name="Body001_material" rgba="1 1 1 1.0" texture="Body001_material" shininess="0.5" specular="2"/>
    <texture file="visuals/T_BC001.png" name="door_material" type="2d"/>
    <material name="door_material" rgba="1 1 1 1.0" texture="door_material" shininess="0.5" specular="2"/>
    <texture file="visuals/T_BC001.png" name="door_Clear_material" type="2d"/>
    <material name="door_Clear_material" rgba="1 1 1 0.7090908885002136" texture="door_Clear_material" shininess="0.5" specular="2"/>
    <texture file="visuals/T_BC001.png" name="knob_temp_material" type="2d"/>
    <material name="knob_temp_material" rgba="1 1 1 1.0" texture="knob_temp_material" shininess="0.5" specular="2"/>
    <texture file="visuals/T_BC001.png" name="knob_time_material" type="2d"/>
    <material name="knob_time_material" rgba="1 1 1 1.0" texture="knob_time_material" shininess="0.5" specular="2"/>
    <texture file="visuals/T_BC001.png" name="rack0_material" type="2d"/>
    <material name="rack0_material" rgba="1 1 1 1.0" texture="rack0_material" shininess="0.5" specular="3"/>
    <texture file="visuals/T_BC001.png" name="rack1_material" type="2d"/>
    <material name="rack1_material" rgba="1 1 1 1.0" texture="rack1_material" shininess="0.5" specular="3"/>
  </asset>
  <default>
    <default class="visual">
      <geom conaffinity="0" contype="0" group="1" type="mesh"/>
    </default>
    <default class="collision">
      <geom group="0" rgba="0.5 0 0 0.5"/>
    </default>
    <default class="spawn">
      <geom group="0" rgba="1 1 1 0.5" contype="0" conaffinity="0"/>
      <site group="0" rgba="1 1 1 0.5"/>
    </default>
    <default class="region">
      <geom group="1" conaffinity="0" contype="0" rgba="0 1 0 0"/>
    </default>
  </default>
  <worldbody>
    <body>
      <body name="object">
        <geom mesh="Body001_vis" type="mesh" solimp="0.998 0.998 0.001" solref="0.001 1" friction="0.95 0.3 0.1" class="visual" material="Body001_material"/>
        <geom class="collision" type="box" pos="-0.33003697 0.03997060 0.00000000" size="0.028920480981469154 0.28983640670776367 0.34318095445632935" quat="1.0 0.0 0.0 0.0"/>
        <geom class="collision" type="box" pos="0.00152762 0.03997060 -0.30988106" size="0.3604850471019745 0.28983640670776367 0.03329990804195404" quat="1.0 0.0 0.0 0.0"/>
        <geom class="collision" type="box" pos="0.33346790 0.03997060 0.00000000" size="0.02854476496577263 0.28983640670776367 0.34318095445632935" quat="1.0 0.0 0.0 0.0"/>
        <geom class="collision" type="box" pos="0.00152762 0.03997060 0.26078877" size="0.3604850471019745 0.28983640670776367 0.08239217847585678" quat="1.0 0.0 0.0 0.0"/>
        <geom class="collision" type="box" pos="0.00152762 0.31351715 0.00000000" size="0.3604850471019745 0.01628987118601799 0.34318095445632935" quat="1.0 0.0 0.0 0.0"/>
        <geom class="collision" type="box" pos="-0.00018432 -0.25995258 0.29233542" size="0.36975643038749695 0.010069512762129307 0.060164764523506165" quat="1.0 0.0 0.0 0.0"/>
        <geom class="collision" type="box" pos="-0.29951438 0.02279972 0.06783497" size="0.003112552920356393 0.24076588451862335 0.003943608608096838" quat="1.0 0.0 0.0 0.0"/>
        <geom class="collision" type="box" pos="-0.30076510 0.02279972 0.07416253" size="0.0018618262838572264 0.24076588451862335 0.0024166179355233908" quat="1.0 0.0 0.0 0.0"/>
        <geom class="collision" type="box" pos="-0.29951438 0.02279972 -0.02258513" size="0.003112552920356393 0.24076588451862335 0.003943608608096838" quat="1.0 0.0 0.0 0.0"/>
        <geom class="collision" type="box" pos="-0.30076510 0.02279972 -0.01625757" size="0.0018618262838572264 0.24076588451862335 0.0024166179355233908" quat="1.0 0.0 0.0 0.0"/>
        <geom class="collision" type="box" pos="-0.29951438 0.02279972 -0.09944368" size="0.003112552920356393 0.24076588451862335 0.003943608608096838" quat="1.0 0.0 0.0 0.0"/>
        <geom class="collision" type="box" pos="-0.30076510 0.02279972 -0.10592052" size="0.0018618262838572264 0.24076588451862335 0.0024166179355233908" quat="1.0 0.0 0.0 0.0"/>
        <geom class="collision" type="box" pos="-0.29951438 0.02279972 -0.16229263" size="0.003112552920356393 0.24076588451862335 0.003943608608096838" quat="1.0 0.0 0.0 0.0"/>
        <geom class="collision" type="box" pos="-0.30076510 0.02279972 -0.16876946" size="0.0018618262838572264 0.24076588451862335 0.0024166179355233908" quat="1.0 0.0 0.0 0.0"/>
        <geom class="collision" type="box" pos="0.30232486 0.02279972 0.06783497" size="0.003112552920356393 0.24076588451862335 0.003943608608096838" quat="1.0 0.0 0.0 0.0"/>
        <geom class="collision" type="box" pos="0.30355090 0.02279972 0.07416253" size="0.0018618262838572264 0.24076588451862335 0.0024166179355233908" quat="1.0 0.0 0.0 0.0"/>
        <geom class="collision" type="box" pos="0.30232486 0.02279972 -0.02195488" size="0.003112552920356393 0.24076588451862335 0.003943608608096838" quat="1.0 0.0 0.0 0.0"/>
        <geom class="collision" type="box" pos="0.30355090 0.02279972 -0.01562732" size="0.0018618262838572264 0.24076588451862335 0.0024166179355233908" quat="1.0 0.0 0.0 0.0"/>
        <geom class="collision" type="box" pos="0.30232486 0.02279972 -0.09024069" size="0.003112552920356393 0.24076588451862335 0.003943608608096838" quat="1.0 0.0 0.0 0.0"/>
        <geom class="collision" type="box" pos="0.30355090 0.02279972 -0.09636574" size="0.0018618262838572264 0.24076588451862335 0.0024166179355233908" quat="1.0 0.0 0.0 0.0"/>
        <geom class="collision" type="box" pos="0.30232486 0.02279972 -0.16275841" size="0.003112552920356393 0.24076588451862335 0.003943608608096838" quat="1.0 0.0 0.0 0.0"/>
        <geom class="collision" type="box" pos="0.30355090 0.02279972 -0.16888346" size="0.0018618262838572264 0.24076588451862335 0.0024166179355233908" quat="1.0 0.0 0.0 0.0"/>
        <geom class="collision" type="box" pos="-0.33687115 -0.25257638 -0.05973272" size="0.033316634595394135 0.0025086624082177877 0.2924446165561676" quat="1.0 0.0 0.0 0.0"/>
        <geom class="collision" type="box" pos="0.33798417 -0.25257638 -0.05973272" size="0.03237505629658699 0.0025086624082177877 0.2924446165561676" quat="1.0 0.0 0.0 0.0"/>
        <geom class="collision" type="box" pos="0.00017665 -0.25257638 -0.32042581" size="0.3700258135795593 0.0025086624082177877 0.03108060732483864" quat="1.0 0.0 0.0 0.0"/>
        <geom class="collision" type="box" pos="0.00017665 -0.25257638 0.20794062" size="0.3700258135795593 0.0025086624082177877 0.02504580281674862" quat="1.0 0.0 0.0 0.0"/>
        <body name="door">
          <joint axis="1.0 0.0 0.0" pos="-0.0002061 -0.2714454162927723 -0.33475907831336976" limited="true" name="door_joint" range="0.0 1.15" type="hinge" damping="1" frictionloss="1" armature="1" stiffness="2"/>
          <geom mesh="door_vis" type="mesh" solimp="0.998 0.998 0.001" solref="0.001 1" friction="0.95 0.3 0.1" class="visual" material="door_material"/>
          <geom class="collision" type="box" pos="-0.00020610 -0.26399136 -0.05176752" size="0.36973434686660767 0.007454056292772293 0.28299155831336975" quat="1.0 0.0 0.0 0.0" name="door_main"/>
          <geom class="collision" type="box" pos="-0.29276612 -0.29357585 0.19392061" size="0.020844746381044388 0.023832838982343674 0.01592712663114071" quat="1.0 0.0 0.0 0.0"/>
          <geom class="collision" type="box" pos="0.28656062 -0.29357585 0.19384728" size="0.020844746381044388 0.02383282408118248 0.016000451520085335" quat="1.0 0.0 0.0 0.0"/>
          <geom class="collision" type="box" pos="-0.21927051 -0.31964767 0.19224752" size="0.0962480753660202 0.008052467368543148 0.014172614552080631" quat="1.0 0.0 0.0 0.0"/>
          <geom class="collision" type="box" pos="-0.00723155 -0.32351262 0.19209783" size="0.1442202627658844 0.010346781462430954 0.014322307892143726" quat="0.9998577237129211 0.0 -0.0 -0.01686682365834713" name="door_handle_main"/>
          <geom class="collision" type="box" pos="0.20587060 -0.31951359 0.19209783" size="0.10098174959421158 0.008831165730953217 0.014322307892143726" quat="1.0 0.0 0.0 0.0"/>
          <body name="door_Clear">
            <geom mesh="door_Clear_vis" type="mesh" solimp="0.998 0.998 0.001" solref="0.001 1" friction="0.95 0.3 0.1" class="visual" material="door_Clear_material"/>
          </body>
        </body>
        <body name="knob_temp">
          <joint axis="0.0 1.0 0.0" pos="0.19076806 -0.28089959 0.28625211" limited="true" name="knob_temp_joint" range="0.0 5.585053606381854" type="hinge" damping="0.05" frictionloss="0.75" armature="1"/>
          <geom mesh="knob_temp_vis" type="mesh" solimp="0.998 0.998 0.001" solref="0.001 1" friction="0.95 0.3 0.1" class="visual" material="knob_temp_material"/>
          <geom class="collision" type="box" pos="0.19090828 -0.28464747 0.28658870" size="0.0056254505179822445 0.0069765266962349415 0.021234922111034393" quat="1.0 0.0 0.0 0.0" friction="100 0.5 0.01"/>
          <geom class="collision" type="cylinder" pos="0.19143209 -0.27438587 0.28637275" size="0.02240707352757454 0.0038076224736869335" quat="0.7071067094802856 0.7071068286895752 0.0 0.0" name="knob_temp_main" friction="100 0.5 0.01"/>
        </body>
        <body name="knob_time">
          <joint axis="0.0 1.0 0.0" pos="-0.19305769 -0.28089956 0.28656864" limited="true" name="knob_time_joint" range="0.0 5.235987755982989" type="hinge" damping="0.05" frictionloss="0.75" armature="1"/>
          <geom mesh="knob_time_vis" type="mesh" solimp="0.998 0.998 0.001" solref="0.001 1" friction="0.95 0.3 0.1" class="visual" material="knob_time_material"/>
          <geom class="collision" type="box" pos="-0.19453174 -0.28464747 0.28646982" size="0.021234922111034393 0.0069765266962349415 0.005625448655337095" quat="1.0 0.0 0.0 0.0" friction="100 0.5 0.01"/>
          <geom class="collision" type="cylinder" pos="-0.19510065 -0.27438587 0.28637275" size="0.02240702696144581 0.003807611530646682" quat="0.7071067094802856 0.7071068286895752 0.0 0.0" name="knob_time_main" friction="100 0.5 0.01"/>
        </body>
        <body name="rack0">
          <geom class="region" name="reg_rack0" type="box" pos="0.0021639150000000162 0.026254625000000004 -0.084311615" size="0.291443925 0.235654275 0.06333802499999999"/>
          <joint axis="0.0 -1.0 0.0" pos="0.00036704 0.02595848 -0.15541413" limited="true" name="rack0_joint" range="0.0 0.35" type="slide" damping="1" frictionloss="1" armature=".01" stiffness="0.05"/>
          <geom mesh="rack0_vis" type="mesh" solimp="0.998 0.998 0.001" solref="0.001 1" friction="0.95 0.3 0.1" class="visual" material="rack0_material"/>
          <geom class="collision" type="box" pos="0.00060857 0.02584955 -0.15517819" size="0.2986590564250946 0.2399853765964508 0.0029299412854015827" quat="1.0 0.0 0.0 0.0"/>
        </body>
        <body name="rack1">
          <geom class="region" name="reg_rack1" type="box" pos="0.0021639150000000162 0.026254625000000004 0.083939925" size="0.291443925 0.235654275 0.08945165499999999"/>
          <joint axis="0.0 -1.0 0.0" pos="0.00036704 0.02595842 -0.01325671" limited="true" name="rack1_joint" range="0.0 0.35" type="slide" damping="1" frictionloss="1" armature=".01" stiffness="0.05"/>
          <geom mesh="rack1_vis" type="mesh" solimp="0.998 0.998 0.001" solref="0.001 1" friction="0.95 0.3 0.1" class="visual" material="rack1_material"/>
          <geom class="collision" type="box" pos="0.00060857 0.02660379 -0.01343382" size="0.2986590564250946 0.23923112452030182 0.0029299412854015827" quat="1.0 0.0 0.0 0.0"/>
        </body>
        <geom class="region" name="reg_int" type="box" pos="0.0010713350000000066 0.02317495500000001 -0.048895285" size="0.294870955 0.268051625 0.222300795"/>
        <geom class="region" name="reg_main" type="box" pos="0.0 0.02938885499999999 0.0" size="0.371 0.301418165 0.35350017"/>
      </body>
    </body>
  </worldbody>
  <actuator>
    <motor name="door_joint_actuator" joint="door_joint" gear="50"/>
    <motor name="knob_temp_joint_actuator" joint="knob_temp_joint" gear="10"/>
    <motor name="knob_time_joint_actuator" joint="knob_time_joint" gear="10"/>
    <motor name="rack0_joint_actuator" joint="rack0_joint" gear="50"/>
    <motor name="rack1_joint_actuator" joint="rack1_joint" gear="50"/>
  </actuator>
</mujoco>