<?xml version='1.0' encoding='UTF-8'?>
<mujoco model="model">
  <option timestep="0.002" gravity="0.0 0.0 -9.81"/>
  <compiler angle="radian"/>
  <asset>
    <mesh file="visuals/blender.obj" name="blender_vis"/>
    <mesh file="visuals/bowl.obj" name="bowl_vis"/>
    <mesh file="visuals/button_head_lock.obj" name="button_head_lock_vis"/>
    <mesh file="visuals/head.obj" name="head_vis"/>
    <mesh file="visuals/knob_speed.obj" name="knob_speed_vis"/>
    <mesh file="visuals/Body001.obj" name="Body001_vis"/>
    <texture file="visuals/T_BC001.png" name="Body001_material" type="2d"/>
    <material name="Body001_material" rgba="1 1 1 1.0" texture="Body001_material" shininess="0.5" specular="1"/>
    <texture file="visuals/T_BC001.png" name="bowl_material" type="2d"/>
    <material name="bowl_material" rgba="1 1 1 1.0" texture="bowl_material" shininess="0.5" specular="2"/>
    <texture file="visuals/T_BC001.png" name="button_head_lock_material" type="2d"/>
    <material name="button_head_lock_material" rgba="1 1 1 1.0" texture="button_head_lock_material" shininess="0.5" specular="0.3103448502657381"/>
    <texture file="visuals/T_BC001.png" name="head_material" type="2d"/>
    <material name="head_material" rgba="1 1 1 1.0" texture="head_material" shininess="0.5" specular="1"/>
    <texture file="visuals/T_BC001.png" name="blender_material" type="2d"/>
    <material name="blender_material" rgba="1 1 1 1.0" texture="blender_material" shininess="0.5" specular="2"/>
    <texture file="visuals/T_BC001.png" name="knob_speed_material" type="2d"/>
    <material name="knob_speed_material" rgba="1 1 1 1.0" texture="knob_speed_material" shininess="0.5" specular="0.3103448502657381"/>
  </asset>
  <default>
    <default class="visual">
      <geom conaffinity="0" contype="0" group="1" type="mesh"/>
    </default>
    <default class="collision">
      <geom group="0" rgba="0.5 0 0 0.5"/>
    </default>
    <default class="spawn">
      <geom group="0" rgba="1 1 1 0.5" contype="0" conaffinity="0"/>
      <site group="0" rgba="1 1 1 0.5"/>
    </default>
    <default class="region">
      <geom group="1" conaffinity="0" contype="0" rgba="0 1 0 0"/>
    </default>
  </default>
  <worldbody>
    <body>
      <body name="object">
        <geom mesh="Body001_vis" type="mesh" solimp="0.998 0.998 0.001" solref="0.001 1" friction="0.95 0.3 0.1" class="visual" material="Body001_material"/>
        <geom type="box" pos="-0.00267090 0.20007269 -0.01686699" size="0.17640313506126404 0.12497478723526001 0.17823748290538788" quat="1.0 0.0 0.0 0.0" class="collision"/>
        <geom type="box" pos="-0.00745859 0.00587236 -0.25808811" size="0.1895003318786621 0.34524524211883545 0.06353159993886948" quat="1.0 0.0 0.0 0.0" class="collision"/>
        <geom type="box" pos="-0.00745859 -0.21437366 -0.34285158" size="0.1895015686750412 0.1265411376953125 0.02537618577480316" quat="1.0 0.0 0.0 0.0" class="collision"/>
        <geom type="box" pos="-0.00745859 0.26803687 -0.34273580" size="0.1895015686750412 0.07797617465257645 0.02537618577480316" quat="1.0 0.0 0.0 0.0" class="collision"/>
        <geom type="cylinder" pos="0.16785968 0.14808685 0.09184745" size="0.022957801818847656 0.007240905426442623" quat="0.7071068286895752 -0.0 0.7071067690849304 0.0" class="collision"/>
        <body name="bowl">
          <!-- <joint axis="0.0 0.0 1.0" pos="-0.00670028 -0.14599445 -0.05463991" limited="true" name="bowl_joint" range="0.0 0.1" type="slide" damping="1" frictionloss="1" armature=".01" stiffness="0.05"/> -->
          <geom mesh="bowl_vis" type="mesh" solimp="0.998 0.998 0.001" solref="0.001 1" friction="0.95 0.3 0.1" class="visual" material="bowl_material"/>
          <geom type="cylinder" pos="-0.00670028 -0.13489270 -0.17508253" size="0.1814662218093872 0.006578970700502396" quat="1.0 0.0 0.0 5.960464477539063e-08" class="collision"/>
          <geom type="box" pos="-0.00315750 0.04243004 -0.04335925" size="0.05319305509328842 0.0033536939881742 0.13530996441841125" quat="1.0 0.0 0.0 0.0" class="collision"/>
          <geom type="box" pos="0.08502930 0.01690198 -0.04335925" size="0.05319305881857872 0.0033536935225129128 0.13530996441841125" quat="0.9659258127212524 0.0 0.0 -0.2588191628456116" class="collision"/>
          <geom type="box" pos="0.14863720 -0.04929943 -0.04335924" size="0.05319305881857872 0.003353693289682269 0.13530994951725006" quat="0.866025447845459 0.0 0.0 -0.4999999701976776" class="collision"/>
          <geom type="box" pos="0.17062255 -0.13843551 -0.04335925" size="0.003353703301399946 0.05319298431277275 0.13530996441841125" quat="1.0 0.0 0.0 0.0" class="collision"/>
          <geom type="box" pos="0.14509442 -0.22662228 -0.04335925" size="0.05319305881857872 0.0033536935225129128 0.13530996441841125" quat="0.49999988079071045 0.0 0.0 -0.8660255074501038" class="collision"/>
          <geom type="box" pos="0.07889302 -0.29023018 -0.04335925" size="0.05319306254386902 0.003353693289682269 0.13530996441841125" quat="0.2588190734386444 0.0 0.0 -0.9659258127212524" class="collision"/>
          <geom type="box" pos="-0.01024313 -0.31221551 -0.04335925" size="0.05319305509328842 0.0033537084236741066 0.13530996441841125" quat="1.0 0.0 0.0 0.0" class="collision"/>
          <geom type="box" pos="-0.09842989 -0.28668737 -0.04335925" size="0.05319306254386902 0.0033536935225129128 0.13530996441841125" quat="0.2588190734386444 0.0 0.0 0.9659258127212524" class="collision"/>
          <geom type="box" pos="-0.16203778 -0.22048596 -0.04335925" size="0.05319305509328842 0.003353693289682269 0.13530996441841125" quat="0.5000000596046448 0.0 0.0 0.8660253882408142" class="collision"/>
          <geom type="box" pos="-0.18402312 -0.13134995 -0.04335925" size="0.003353716107085347 0.05319303646683693 0.13530996441841125" quat="1.0 0.0 0.0 0.0" class="collision"/>
          <geom type="box" pos="-0.15849491 -0.04316300 -0.04335925" size="0.05319305881857872 0.0033536935225129128 0.13530996441841125" quat="0.8660256266593933 0.0 0.0 0.49999964237213135" class="collision"/>
          <geom type="box" pos="-0.09229353 0.02044480 -0.04335925" size="0.05319305509328842 0.003353693289682269 0.13530996441841125" quat="0.9659258723258972 0.0 0.0 0.25881892442703247" class="collision"/>
          <geom name="reg_bowl" type="ellipsoid" pos="-0.00670028 -0.13489270 0.09177814" size="0.16452902555465698 0.16766422986984253 0.2566817104816437" rgba="0 1 0 0.5" class="region"/>
        </body>
        <body name="button_head_lock">
          <joint axis="-1.0 0.0 0.0" pos="0.18252964 0.14910948 0.09110717" limited="true" name="button_head_lock_joint" range="0.0 1.3089969389957472" type="hinge" damping="1" frictionloss="1" armature=".01" stiffness="0.05"/>
          <geom mesh="button_head_lock_vis" type="mesh" solimp="0.998 0.998 0.001" solref="0.001 1" friction="0.95 0.3 0.1" class="visual" material="button_head_lock_material"/>
          <geom class="collision" type="cylinder" pos="0.19281889 0.18186405 0.11706350" size="0.006224953569471836 0.033076509833335876" quat="0.896519124507904 -0.4430050551891327 2.6802243979773266e-08 -5.3240494679585026e-08" name="button_head_lock_main"/>
          <geom type="cylinder" pos="0.19314839 0.14799933 0.09103338" size="0.008919178508222103 0.0055654654279351234" quat="0.6339347958564758 -0.31325194239616394 -0.633934736251831 0.313251793384552" class="collision"/>
          <geom type="cylinder" pos="0.18127180 0.14808685 0.09184745" size="0.017771020531654358 0.005604991223663092" quat="0.7071068286895752 -0.0 0.7071067690849304 0.0" class="collision"/>
        </body>
        <body name="head">
          <joint axis="-1.0 0.0 0.0" pos="0.00391560 0.32297707 0.17175800" limited="true" name="head_joint" range="0.0 1.5707963267948966" type="hinge" damping="1" frictionloss="1" armature=".01" stiffness="0.05"/>
          <geom mesh="head_vis" type="mesh" solimp="0.998 0.998 0.001" solref="0.001 1" friction="0.95 0.3 0.1" class="visual" material="head_material"/>
          <geom type="box" pos="-0.00563701 0.12132862 0.23743494" size="0.18423785269260406 0.20407572388648987 0.06432920694351196" quat="1.0 0.0 0.0 0.0" class="collision"/>
          <geom type="box" pos="-0.00011037 -0.13279633 0.23134264" size="0.13936132192611694 0.04869908466935158 0.055304598063230515" quat="1.0 0.0 0.0 0.0" class="collision"/>
          <geom type="box" pos="-0.00011037 0.11888495 0.31511831" size="0.13787944614887238 0.1650116741657257 0.05209336429834366" quat="1.0 0.0 0.0 0.0" class="collision"/>
          <geom type="box" pos="-0.00011037 -0.08365140 0.27762929" size="0.11760880798101425 0.009555584751069546 0.014604005962610245" quat="1.0 0.0 0.0 0.0" class="collision"/>
          <geom type="box" pos="-0.02386878 -0.25066048 0.17795789" size="0.05469752103090286 0.0042932783253490925 0.0926520973443985" quat="0.9129106998443604 -0.4081593453884125 3.326717745721908e-08 1.4873648979119025e-08" class="collision"/>
          <geom type="box" pos="-0.11067838 -0.21696413 0.18110809" size="0.054697513580322266 0.00429327879101038 0.08732059597969055" quat="0.8775176405906677 -0.345663458108902 0.12181943655014038 -0.3092564642429352" class="collision"/>
          <geom type="box" pos="-0.19022870 -0.08831722 0.19311045" size="0.05469752103090286 0.00429327879101038 0.08266056329011917" quat="0.7065261006355286 -0.02865460142493248 0.028654610738158226 -0.7065258026123047" class="collision"/>
          <geom type="box" pos="-0.13963871 -0.15884182 0.18049935" size="0.05469752103090286 0.00429327879101038 0.08321232348680496" quat="0.5672957897186279 0.2008899748325348 0.2665899991989136 0.752826988697052" class="collision"/>
          <geom type="box" pos="-0.06138411 -0.25066048 0.17795789" size="0.05469752475619316 0.0042932783253490925 0.0926520973443985" quat="0.9145877361297607 -0.3882194459438324 0.044231995940208435 -0.10420416295528412" class="collision"/>
          <geom type="box" pos="0.03733534 -0.25066048 0.17795789" size="0.05469753220677376 0.0042932783253490925 0.0926520973443985" quat="0.38821929693222046 0.9145877957344055 0.10420418530702591 0.04423201084136963" class="collision"/>
          <geom type="box" pos="0.11714215 -0.15928692 0.17850527" size="0.05469752103090286 0.0042932783253490925 0.08577822893857956" quat="0.20089010894298553 -0.5672956109046936 0.752826988697052 -0.26659026741981506" class="collision"/>
          <geom type="box" pos="0.17934410 -0.09389382 0.19120842" size="0.05469752103090286 0.00429327879101038 0.08453971147537231" quat="0.0035106476861983538 0.7070980668067932 0.7070980668067932 0.0035105894785374403" class="collision"/>
          <geom type="box" pos="0.08781093 -0.21843195 0.17908755" size="0.05469752103090286 0.0042932783253490925 0.09008330851793289" quat="0.34566324949264526 0.8775177001953125 0.30925655364990234 0.1218193769454956" class="collision"/>
          <geom type="box" pos="-0.00017999 -0.25066048 0.17795789" size="0.05469752103090286 0.0042932783253490925 0.0926520973443985" quat="0.40815937519073486 0.9129106998443604 7.852231753702199e-09 -1.7562717502528358e-08" class="collision"/>
          <geom type="cylinder" pos="0.18021585 0.14884874 0.23393658" size="0.04312162473797798 0.003263219492509961" quat="0.7071068286895752 -0.0 0.7071067690849304 0.0" class="collision"/>
          <body name="blender">
            <joint axis="0.0 0.0 1.0" pos="-0.01485415 -0.13735706 0.16844827" limited="false" name="blender_joint" range="0 360" type="hinge" damping="1" frictionloss="1" armature=".01" stiffness="0.05"/>
            <geom mesh="blender_vis" type="mesh" solimp="0.998 0.998 0.001" solref="0.001 1" friction="0.95 0.3 0.1" class="visual" material="blender_material"/>
            <geom type="cylinder" pos="-0.01485426 -0.13735706 0.02527136" size="0.03977133706212044 0.12904568016529083" quat="1.0 0.0 0.0 5.960464477539063e-08" class="collision"/>
            <geom type="cylinder" pos="-0.01485426 -0.13735706 0.15753005" size="0.04861937835812569 0.011234770528972149" quat="1.0 0.0 0.0 5.960464477539063e-08" class="collision"/>
          </body>
          <body name="knob_speed">
            <joint axis="-1.0 0.0 0.0" pos="0.19205622 0.14881469 0.23358227" limited="true" name="knob_speed_joint" range="0.0 3.141592653589793" type="hinge" damping="0.05" armature="0.001"/>
            <geom mesh="knob_speed_vis" type="mesh" solimp="0.998 0.998 0.001" solref="0.001 1" friction="0.95 0.3 0.1" class="visual" material="knob_speed_material"/>
            <geom type="cylinder" pos="0.18819046 0.14920551 0.23384427" size="0.023875655606389046 0.0037164839450269938" quat="0.25031644105911255 -0.6613181233406067 0.25031664967536926 -0.6613180637359619" class="collision"/>
            <geom class="collision" type="box" pos="0.19850100 0.14973517 0.23293169" size="0.006722669582813978 0.006722669582813978 0.020335135981440544" quat="0.9984014630317688 0.05652029812335968 3.368872292242031e-09 5.9509360994525196e-08" name="knob_speed_main"/>
          </body>
        </body>
        <geom class="region" name="reg_main" type="box" pos="-0.006446725 0.0 0.0" size="0.19106705499999999 0.34600009 0.36599977"/>
      </body>
    </body>
  </worldbody>
  <actuator>
    <!-- <motor name="bowl_joint_actuator" joint="bowl_joint" gear="10"/> -->
    <motor name="button_head_lock_joint_actuator" joint="button_head_lock_joint" gear="0.5"/>
    <motor name="head_joint_actuator" joint="head_joint" gear="0.5"/>
    <motor name="blender_joint_actuator" joint="blender_joint" gear="10"/>
    <motor name="knob_speed_joint_actuator" joint="knob_speed_joint" gear="0.5"/>
  </actuator>
</mujoco>
