<?xml version='1.0' encoding='UTF-8'?>
<mujoco model="model">
  <option timestep="0.002" gravity="0.0 0.0 -9.81"/>
  <compiler angle="radian"/>
  <asset>
    <mesh file="visuals/knob_center.obj" name="knob_center_vis"/>
    <mesh file="visuals/knob_front_left.obj" name="knob_front_left_vis"/>
    <mesh file="visuals/knob_front_right.obj" name="knob_front_right_vis"/>
    <mesh file="visuals/knob_rear_left.obj" name="knob_rear_left_vis"/>
    <mesh file="visuals/knob_rear_right.obj" name="knob_rear_right_vis"/>
    <mesh file="visuals/Body001.obj" name="Body001_vis"/>
    <texture file="visuals/T_BC001.png" name="Body001_material" type="2d"/>
    <material name="Body001_material" rgba="1 1 1 1.0" texture="Body001_material" shininess="0.1" specular="6"/>
    <texture file="visuals/T_BC001.png" name="knob_center_material" type="2d"/>
    <material name="knob_center_material" rgba="1 1 1 1.0" texture="knob_center_material" shininess="0.1" specular="6"/>
    <texture file="visuals/T_BC001.png" name="knob_front_left_material" type="2d"/>
    <material name="knob_front_left_material" rgba="1 1 1 1.0" texture="knob_front_left_material" shininess="0.1" specular="6"/>
    <texture file="visuals/T_BC001.png" name="knob_front_right_material" type="2d"/>
    <material name="knob_front_right_material" rgba="1 1 1 1.0" texture="knob_front_right_material" shininess="0.1" specular="6"/>
    <texture file="visuals/T_BC001.png" name="knob_rear_left_material" type="2d"/>
    <material name="knob_rear_left_material" rgba="1 1 1 1.0" texture="knob_rear_left_material" shininess="0.1" specular="6"/>
    <texture file="visuals/T_BC001.png" name="knob_rear_right_material" type="2d"/>
    <material name="knob_rear_right_material" rgba="1 1 1 1.0" texture="knob_rear_right_material" shininess="0.1" specular="6"/>
  </asset>
  <default>
    <default class="visual">
      <geom conaffinity="0" contype="0" group="1" type="mesh"/>
    </default>
    <default class="collision">
      <geom group="0" rgba="0.5 0 0 0.5"/>
    </default>
    <default class="spawn">
      <geom group="0" rgba="1 1 1 0.5" contype="0" conaffinity="0"/>
      <site group="0" rgba="1 1 1 0.5"/>
    </default>
    <default class="region">
      <geom group="1" conaffinity="0" contype="0" rgba="0 1 0 0"/>
    </default>
  </default>
  <worldbody>
    <body>
      <body name="object">
        <geom mesh="Body001_vis" type="mesh" solimp="0.998 0.998 0.001" solref="0.001 1" friction="0.95 0.3 0.1" class="visual" material="Body001_material"/>
        <geom class="collision" type="box" pos="0.00053957 -0.00004403 -0.00927619" size="0.4036475718021393 0.2670837938785553 0.0021160796750336885" quat="1.0 0.0 0.0 0.0"/>
        <body name="knob_center">
          <joint axis="0.0 0.0 1.0" pos="0.13505122 -0.22372733 0.00148319" limited="true" name="knob_center_joint" range="0.0 3.141592653589793" type="hinge" damping="0.05" armature="0.001"/>
          <geom mesh="knob_center_vis" type="mesh" solimp="0.998 0.998 0.001" solref="0.001 1" friction="0.95 0.3 0.1" class="visual" material="knob_center_material"/>
          <geom class="collision" type="box" pos="0.13501778 -0.22374751 0.00516564" size="0.004347840789705515 0.018760010600090027 0.006951689254492521" quat="1.0 0.0 0.0 0.0" name="knob_center_main"/>
          <geom class="collision" type="cylinder" pos="0.13512555 -0.22375976 -0.00315392" size="0.02065761387348175 0.0023114990908652544" quat="1.0 0.0 0.0 0.0"/>
        </body>
        <body name="knob_front_left">
          <joint axis="0.0 0.0 1.0" pos="-0.06837389 -0.22372735 0.00148319" limited="true" name="knob_front_left_joint" range="0.0 3.141592653589793" type="hinge" damping="0.05" armature="0.001"/>
          <geom mesh="knob_front_left_vis" type="mesh" solimp="0.998 0.998 0.001" solref="0.001 1" friction="0.95 0.3 0.1" class="visual" material="knob_front_left_material"/>
          <geom class="collision" type="box" pos="-0.06853234 -0.22374751 0.00516564" size="0.004347840789705515 0.018760010600090027 0.006951689254492521" quat="1.0 0.0 0.0 0.0" name="knob_front_left_main"/>
          <geom class="collision" type="cylinder" pos="-0.06818143 -0.22375976 -0.00315392" size="0.02065761387348175 0.0023114990908652544" quat="1.0 0.0 0.0 0.0"/>
        </body>
        <body name="knob_front_right">
          <joint axis="0.0 0.0 1.0" pos="0.34118456 -0.22372733 0.00148319" limited="true" name="knob_front_right_joint" range="0.0 3.141592653589793" type="hinge" damping="0.05" armature="0.001"/>
          <geom mesh="knob_front_right_vis" type="mesh" solimp="0.998 0.998 0.001" solref="0.001 1" friction="0.95 0.3 0.1" class="visual" material="knob_front_right_material"/>
          <geom class="collision" type="box" pos="0.34105673 -0.22374751 0.00516564" size="0.004347840789705515 0.018760010600090027 0.006951689254492521" quat="1.0 0.0 0.0 0.0" name="knob_front_right_main"/>
          <geom class="collision" type="cylinder" pos="0.34094676 -0.22375976 -0.00315392" size="0.02065761387348175 0.0023114990908652544" quat="1.0 0.0 0.0 0.0"/>
        </body>
        <body name="knob_rear_left">
          <joint axis="0.0 0.0 1.0" pos="0.03298588 -0.22372733 0.00148319" limited="true" name="knob_rear_left_joint" range="0.0 3.141592653589793" type="hinge" damping="0.05" armature="0.001"/>
          <geom mesh="knob_rear_left_vis" type="mesh" solimp="0.998 0.998 0.001" solref="0.001 1" friction="0.95 0.3 0.1" class="visual" material="knob_rear_left_material"/>
          <geom class="collision" type="box" pos="0.03274806 -0.22374751 0.00516564" size="0.004347840789705515 0.018760010600090027 0.006951689254492521" quat="1.0 0.0 0.0 0.0" name="knob_rear_left_main"/>
          <geom class="collision" type="cylinder" pos="0.03263119 -0.22375976 -0.00315392" size="0.02065761387348175 0.0023114990908652544" quat="1.0 0.0 0.0 0.0"/>
        </body>
        <body name="knob_rear_right">
          <joint axis="0.0 0.0 1.0" pos="0.23816346 -0.22372733 0.00148319" limited="true" name="knob_rear_right_joint" range="0.0 3.141592653589793" type="hinge" damping="0.05" armature="0.001"/>
          <geom mesh="knob_rear_right_vis" type="mesh" solimp="0.998 0.998 0.001" solref="0.001 1" friction="0.95 0.3 0.1" class="visual" material="knob_rear_right_material"/>
          <geom class="collision" type="box" pos="0.23790371 -0.22374751 0.00516564" size="0.004347840789705515 0.018760010600090027 0.006951689254492521" quat="1.0 0.0 0.0 0.0" name="knob_rear_right_main"/>
          <geom class="collision" type="cylinder" pos="0.23804982 -0.22375976 -0.00315392" size="0.02065761387348175 0.0023114990908652544" quat="1.0 0.0 0.0 0.0"/>
        </body>
        <site type="cylinder" rgba="0.5 0 0 0.5" size="0.13213768601417542 0.0001" pos="0.00030494 0.02093612 -0.00709722" name="burner_on_center"/>
        <site type="cylinder" rgba="0.5 0 0 0.5" size="0.09655672311782837 0.0001" pos="-0.24804516 0.13400862 -0.00709722" name="burner_on_rear_left"/>
        <site type="cylinder" rgba="0.5 0 0 0.5" size="0.11245042085647583 0.0001" pos="-0.25452325 -0.11759745 -0.00709722" name="burner_on_front_left"/>
        <site type="cylinder" rgba="0.5 0 0 0.5" size="0.07762499153614044 0.0001" pos="0.22599290 0.13550612 -0.00709722" name="burner_on_rear_right"/>
        <site type="cylinder" rgba="0.5 0 0 0.5" size="0.09673098474740982 0.0001" pos="0.25351262 -0.08145939 -0.00709722" name="burner_on_front_right"/>
        <site name="burner_center_place_site" type="cylinder" rgba="0.5 0 0 0" size="0.13213768601417542 4.999999873689376e-05" pos="0.00030494 0.02093612 -0.00709722"/>
        <site name="burner_rear_left_place_site" type="cylinder" rgba="0.5 0 0 0" size="0.09655672311782837 4.999999873689376e-05" pos="-0.24804516 0.13400862 -0.00709722"/>
        <site name="burner_front_left_place_site" type="cylinder" rgba="0.5 0 0 0" size="0.11245042085647583 4.999999873689376e-05" pos="-0.25452325 -0.11759745 -0.00709722"/>
        <site name="burner_rear_right_place_site" type="cylinder" rgba="0.5 0 0 0" size="0.07762499153614044 4.999999873689376e-05" pos="0.22599290 0.13550612 -0.00709722"/>
        <site name="burner_front_right_place_site" type="cylinder" rgba="0.5 0 0 0" size="0.09673098474740982 4.999999873689376e-05" pos="0.25351262 -0.08145939 -0.00709722"/>
        <geom class="region" name="reg_main" type="box" pos="0.000163980000000008 -4.404999999998993e-05 -0.00927617" size="0.40554012 0.26808414999999997 0.0031160999999999997"/>
      </body>
    </body>
  </worldbody>
  <actuator>
    <motor name="knob_center_joint_actuator" joint="knob_center_joint" gear="10"/>
    <motor name="knob_front_left_joint_actuator" joint="knob_front_left_joint" gear="10"/>
    <motor name="knob_front_right_joint_actuator" joint="knob_front_right_joint" gear="10"/>
    <motor name="knob_rear_left_joint_actuator" joint="knob_rear_left_joint" gear="10"/>
    <motor name="knob_rear_right_joint_actuator" joint="knob_rear_right_joint" gear="10"/>
  </actuator>
</mujoco>
