<?xml version='1.0' encoding='UTF-8'?>
<mujoco model="model">
  <compiler angle="radian"/>
  <asset>
    <mesh file="visuals/Body001.obj" name="Body001_vis"/>
    <mesh file="visuals/Button001.obj" name="Button001_vis"/>
    <mesh file="visuals/Button002.obj" name="Button002_vis"/>
    <mesh file="visuals/Container001_Clear.obj" name="Container001_Clear_vis"/>
    <mesh file="visuals/Lever001.obj" name="Lever001_vis"/>
    <mesh file="visuals/Lever002.obj" name="Lever002_vis"/>
    <mesh file="visuals/Lid001.obj" name="Lid001_vis"/>
    <mesh file="visuals/Lid002.obj" name="Lid002_vis"/>
    <texture file="visuals/T-BC001.png" name="Body001_material" type="2d"/>
    <material name="Body001_material" rgba="1 1 1 1.0" texture="Body001_material" shininess="0.4472135901451111" specular="0.3103448502657381"/>
    <texture file="visuals/T-BC001.png" name="Button001_material" type="2d"/>
    <material name="Button001_material" rgba="1 1 1 1.0" texture="Button001_material" shininess="0.4472135901451111" specular="0.3103448502657381"/>
    <texture file="visuals/T-BC001.png" name="Button002_material" type="2d"/>
    <material name="Button002_material" rgba="1 1 1 1.0" texture="Button002_material" shininess="0.4472135901451111" specular="0.3103448502657381"/>
    <material name="Container001_Clear_material" rgba="0.5 0.5 0.5 0.20000000298023224" shininess="0.4472135901451111" specular="0.3103448502657381"/>
    <texture file="visuals/T-BC001.png" name="Lid002_material" type="2d"/>
    <material name="Lid002_material" rgba="1 1 1 1.0" texture="Lid002_material" shininess="0.4472135901451111" specular="0.3103448502657381"/>
    <texture file="visuals/T-BC001.png" name="Lever001_material" type="2d"/>
    <material name="Lever001_material" rgba="1 1 1 1.0" texture="Lever001_material" shininess="0.4472135901451111" specular="0.3103448502657381"/>
    <texture file="visuals/T-BC001.png" name="Lever002_material" type="2d"/>
    <material name="Lever002_material" rgba="1 1 1 1.0" texture="Lever002_material" shininess="0.4472135901451111" specular="0.3103448502657381"/>
    <texture file="visuals/T-BC001.png" name="Lid001_material" type="2d"/>
    <material name="Lid001_material" rgba="1 1 1 1.0" texture="Lid001_material" shininess="0.4472135901451111" specular="0.3103448502657381"/>
  </asset>
  <default>
    <default class="visual">
      <geom conaffinity="0" contype="0" group="1" type="mesh"/>
    </default>
    <default class="collision">
      <geom group="0" rgba="0.5 0 0 0.5"/>
    </default>
    <default class="spawn">
      <geom group="0" rgba="1 1 1 0.5" contype="0" conaffinity="0"/>
      <site group="0" rgba="1 1 1 0.5"/>
    </default>
    <default class="region">
      <geom group="1" conaffinity="0" contype="0" rgba="0 1 0 0"/>
    </default>
  </default>
  <worldbody>
    <body>
      <body name="object">
        <geom class="collision" type="box" pos="-0.04119198 -0.10975699 0.14766202" size="0.00892726331949234 0.00892726518213749 0.00016084407980088145" quat="0.846511721611023 0.4653227925300598 -0.21786101162433624 -0.1393885612487793" name="start_button" rgba="0.0 0.5 0 0.5"/>
        <site rgba="0 0 0 0" size="0.009999999776482582 0.009999999776482582" pos="-0.00549065 -0.07 -0.12995383" name="receptacle_place_site"/>
        <site type="cylinder" rgba="0.8 0.5 0.25 1" size="0.0023485838901251554 0.0685235857963562" pos="-0.00614080 -0.05681664 -0.08769294" name="coffee_liquid"/>
        <geom mesh="Body001_vis" type="mesh" solimp="0.998 0.998 0.001" solref="0.001 1" density="100" friction="0.95 0.3 0.1" class="visual" material="Body001_material"/>
        <geom class="collision" type="box" pos="-0.00648268 -0.07188284 -0.16104250" size="0.07531660795211792 0.0637577474117279 0.007983927614986897" quat="1.0 0.0 0.0 0.0"/>
        <geom class="collision" type="box" pos="-0.00648268 0.07798040 -0.15182862" size="0.07531660795211792 0.08617395907640457 0.01719781756401062" quat="1.0 0.0 0.0 0.0"/>
        <geom class="collision" type="box" pos="-0.07063452 -0.04587103 -0.14376020" size="0.011048798449337482 0.03774593397974968 0.00920934695750475" quat="1.0 0.0 0.0 0.0"/>
        <geom class="collision" type="box" pos="0.05475039 -0.04419428 -0.14416677" size="0.008273176848888397 0.03606918454170227 0.009615909308195114" quat="1.0 0.0 0.0 0.0"/>
        <geom class="collision" type="box" pos="-0.00576614 -0.11927740 -0.14470567" size="0.031720150262117386 0.01010341290384531 0.01008792407810688" quat="1.0 0.0 0.0 0.0"/>
        <geom class="collision" type="box" pos="-0.00712524 0.04271124 -0.04106175" size="0.058642711490392685 0.04680358245968819 0.0934905856847763" quat="1.0 0.0 0.0 0.0"/>
        <geom class="collision" type="box" pos="-0.00672752 -0.00566396 0.10463570" size="0.06048281863331795 0.09517877548933029 0.051534704864025116" quat="1.0 0.0 0.0 0.0"/>
        <geom class="collision" type="box" pos="-0.00712524 -0.06201487 0.04160835" size="0.058642711490392685 0.0575593076646328 0.010820487514138222" quat="1.0 0.0 0.0 0.0"/>
        <geom class="collision" type="box" pos="-0.00712524 -0.11065914 0.09556516" size="0.058642711490392685 0.010886264964938164 0.04257867485284805" quat="1.0 0.0 0.0 0.0"/>
        <geom class="collision" type="cylinder" pos="-0.00619298 -0.05609461 0.02211486" size="0.03744764253497124 0.009673897176980972" quat="1.0 0.0 0.0 0.0"/>
        <geom class="collision" type="box" pos="0.04301859 -0.10081273 -0.14416677" size="0.0106677720323205 0.022961612790822983 0.009615909308195114" quat="0.9385688304901123 0.0 -0.0 -0.34509211778640747"/>
        <geom class="collision" type="box" pos="-0.05410570 -0.10167260 -0.14416677" size="0.0106677720323205 0.022961612790822983 0.009615909308195114" quat="0.9385688304901123 0.0 0.0 0.3450920879840851"/>
        <body name="Button001">
          <joint axis="0.3790660500526428 0.7952281832695007 -0.4732029438018799" pos="-0.03955052 -0.10776623 0.14645906" limited="true" name="Button001_joint" range="0.0 0.003" type="slide" damping="1" frictionloss="1" armature=".01" stiffness="0.05" springref="-0.1"/>
          <geom mesh="Button001_vis" type="mesh" solimp="0.998 0.998 0.001" solref="0.001 1" density="100" friction="0.95 0.3 0.1" class="visual" material="Button001_material"/>
          <geom class="collision" type="cylinder" pos="-0.04045169 -0.10867740 0.14696115" size="0.00892726331949234 0.0011526010930538177" quat="0.846511721611023 0.4653227925300598 -0.21786101162433624 -0.1393885612487793"/>
        </body>
        <body name="Button002">
          <joint axis="-0.46215391159057617 0.797650158405304 -0.3875150978565216" pos="0.02651327 -0.10776623 0.14645906" limited="true" name="Button002_joint" range="0.0 0.003" type="slide" damping="1" frictionloss="1" armature=".01" stiffness="0.05" springref="-0.1"/>
          <geom mesh="Button002_vis" type="mesh" solimp="0.998 0.998 0.001" solref="0.001 1" density="100" friction="0.95 0.3 0.1" class="visual" material="Button002_material"/>
          <geom class="collision" type="cylinder" pos="0.02738116 -0.10890987 0.14702545" size="0.009151086211204529 0.0014498068485409021" quat="0.8465116620063782 0.4653228521347046 0.2178611308336258 0.1393885463476181"/>
        </body>
        <body name="Container001_Clear">
          <!-- <joint axis="0.0 0.0 1.0" pos="-0.00651860 0.11962602 -0.00128072" limited="true" name="Container001_Clear_joint" range="0.0 0.1" type="slide" damping="1" frictionloss="1" armature=".01" stiffness="0.05"/> -->
          <geom mesh="Container001_Clear_vis" type="mesh" solimp="0.998 0.998 0.001" solref="0.001 1" density="100" friction="0.95 0.3 0.1" class="visual" material="Container001_Clear_material"/>
          <geom class="collision" type="box" pos="-0.00674177 0.09190939 -0.00119680" size="0.060055769979953766 0.0010053712176159024 0.13239671289920807" quat="1.0 0.0 0.0 0.0"/>
          <geom class="collision" type="box" pos="-0.00674177 0.12142853 -0.13000560" size="0.06005577743053436 0.028619131073355675 0.003588327905163169" quat="1.0 0.0 0.0 0.0"/>
          <geom class="collision" type="box" pos="-0.00626787 0.14646490 0.00251916" size="0.027414213865995407 0.0035828114487230778 0.12871545553207397" quat="1.0 0.0 0.0 0.0"/>
          <geom class="collision" type="box" pos="0.03534130 0.13453980 -0.00117957" size="0.016749773174524307 0.0040876781567931175 0.13241435587406158" quat="0.9247809052467346 0.0 -0.0 -0.38050004839897156"/>
          <geom class="collision" type="box" pos="0.04979453 0.10810204 -0.00117957" size="0.015352112241089344 0.0023015213664621115 0.13241435587406158" quat="0.7677953243255615 0.0 -0.0 -0.6406952142715454"/>
          <geom class="collision" type="box" pos="-0.06277980 0.10810204 -0.00117957" size="0.015352112241089344 0.0023015213664621115 0.13241435587406158" quat="0.7677953243255615 0.0 0.0 0.6406952142715454"/>
          <geom class="collision" type="box" pos="-0.04832659 0.13453980 -0.00117957" size="0.016749773174524307 0.0040876781567931175 0.13241435587406158" quat="0.9247809052467346 0.0 0.0 0.38050004839897156"/>
          <body name="Lid002">
            <!-- <joint axis="0.0 0.0 1.0" pos="-0.00651860 0.11958745 0.15031071" limited="true" name="Lid002_joint" range="0.0 0.05" type="slide" damping="1" frictionloss="1" armature=".01" stiffness="0.05"/> -->
            <geom mesh="Lid002_vis" type="mesh" solimp="0.998 0.998 0.001" solref="0.001 1" density="100" friction="0.95 0.3 0.1" class="visual" material="Lid002_material"/>
            <geom class="collision" type="box" pos="-0.00674177 0.12012108 0.14397721" size="0.06005576252937317 0.029217014089226723 0.012135030701756477" quat="1.0 0.0 0.0 0.0"/>
            <geom class="collision" type="box" pos="-0.00555172 0.10770810 0.16705634" size="0.021868998184800148 0.0020007893908768892 0.0019695404917001724" quat="1.0 0.0 0.0 0.0"/>
            <geom class="collision" type="box" pos="0.01271697 0.10774805 0.16059953" size="0.0024626492522656918 0.0014875272754579782 0.004465391393750906" quat="1.0 0.0 0.0 0.0"/>
            <geom class="collision" type="box" pos="-0.02450807 0.10774805 0.16059953" size="0.0024626492522656918 0.0014875272754579782 0.004465391393750906" quat="1.0 0.0 0.0 0.0"/>
          </body>
        </body>
        <body name="Lever001">
          <joint axis="0.0 0.0 -1.0" pos="-0.00617987 -0.05668195 0.00026346" limited="true" name="Lever001_joint" range="0.0 0.7853981633974483" type="hinge" damping="1" frictionloss="1" armature=".01" stiffness="0.01" springref="-0.1"/>
          <geom mesh="Lever001_vis" type="mesh" solimp="0.998 0.998 0.001" solref="0.001 1" density="100" friction="0.95 0.3 0.1" class="visual" material="Lever001_material"/>
          <geom class="collision" type="cylinder" pos="-0.00598489 -0.05655224 -0.00195731" size="0.027652401477098465 0.01362256333231926" quat="1.0 0.0 0.0 0.0"/>
          <geom class="collision" type="cylinder" pos="-0.00609570 -0.05668807 -0.01794093" size="0.004396958276629448 0.0023990387562662363" quat="1.0 0.0 0.0 0.0"/>
          <geom class="collision" type="cylinder" pos="-0.00598595 -0.12308839 -0.00078048" size="0.009592370130121708 0.041259489953517914" quat="0.7071067094802856 0.7071068286895752 0.0 0.0"/>
        </body>
        <body name="Lever002">
          <joint axis="0.0 0.0 -1.0" pos="0.03423073 -0.01487800 0.03292781" limited="true" name="Lever002_joint" range="-0.5235987755982988 0.5235987755982988" type="hinge" damping="1" frictionloss="1" armature=".01" stiffness="0.01" springref="-0.1"/>
          <geom mesh="Lever002_vis" type="mesh" solimp="0.998 0.998 0.001" solref="0.001 1" density="100" friction="0.95 0.3 0.1" class="visual" material="Lever002_material"/>
          <geom class="collision" type="cylinder" pos="0.07124514 -0.04626668 -0.03419752" size="0.008019386790692806 0.027639660984277725" quat="0.9960389137268066 -0.08891831338405609 1.9743831765962858e-17 -4.3224576227972346e-24"/>
          <geom class="collision" type="cylinder" pos="0.07124514 -0.04093296 -0.00456216" size="0.008619946427643299 0.0024311484303325415" quat="0.9960389137268066 -0.08891831338405609 1.9743831765962858e-17 -4.3224576227972346e-24"/>
          <geom class="collision" type="cylinder" pos="0.07124514 -0.03804792 0.01258879" size="0.011144055984914303 0.01516952645033598" quat="0.9960389137268066 -0.08891831338405609 1.9743831765962858e-17 -4.3224576227972346e-24"/>
          <geom class="collision" type="cylinder" pos="0.05087492 -0.02461615 0.02143835" size="0.004379558842629194 0.01350738201290369" quat="0.7029600143432617 0.36455032229423523 0.6106710433959961 -0.005580933764576912"/>
          <geom class="collision" type="cylinder" pos="0.03679824 -0.01643439 0.02470070" size="0.00349732069298625 0.004593165125697851" quat="0.28198710083961487 0.2681159973144531 0.9206628203392029 -0.03125828877091408"/>
        </body>
        <body name="Lid001">
          <!-- <joint axis="0.0 0.0 1.0" pos="-0.00651863 -0.06147917 -0.13041550" limited="true" name="Lid001_joint" range="0.0 0.03" type="slide" damping="1" frictionloss="1" armature=".01" stiffness="0.05" springref="-10"/> -->
          <geom mesh="Lid001_vis" type="mesh" solimp="0.998 0.998 0.001" solref="0.001 1" density="100" friction="0.95 0.3 0.1" class="visual" material="Lid001_material"/>
          <geom class="collision" type="box" pos="-0.00648298 -0.06203648 -0.13031641" size="0.0598076656460762 0.05761132761836052 0.003606165526434779" quat="1.0 0.0 0.0 0.0"/>
        </body>
        <geom class="region" name="reg_main" type="box" pos="-0.006446485000000002 0.014093175 -0.006420000000000009" size="0.076072155 0.151043235 0.16350028"/>
      </body>
    </body>
  </worldbody>
  <actuator>
    <motor name="Button001_joint_actuator" joint="Button001_joint" gear="0.5"/>
    <motor name="Button002_joint_actuator" joint="Button002_joint" gear="0.5"/>
    <!-- <motor name="Container001_Clear_joint_actuator" joint="Container001_Clear_joint" gear="10"/> -->
    <motor name="Lever001_joint_actuator" joint="Lever001_joint" gear="10"/>
    <motor name="Lever002_joint_actuator" joint="Lever002_joint" gear="10"/>
    <!-- <motor name="Lid001_joint_actuator" joint="Lid001_joint" gear="10"/> -->
    <!-- <motor name="Lid002_joint_actuator" joint="Lid002_joint" gear="10"/> -->
  </actuator>
</mujoco>
