<?xml version='1.0' encoding='UTF-8'?>
<mujoco model="model">
  <option timestep="0.002" gravity="0.0 0.0 -9.81"/>
  <compiler angle="radian"/>
  <asset>
    <mesh file="visuals/button_cancel.obj" name="button_cancel_vis"/>
    <mesh file="visuals/knob_doneness.obj" name="knob_doneness_vis"/>
    <mesh file="visuals/lever.obj" name="lever_vis"/>
    <mesh file="visuals/Body001.obj" name="Body001_vis"/>
    <mesh file="visuals/Body002.obj" name="Body002_vis"/>
    <texture file="visuals/T_BC001.png" name="Body001_material" type="2d"/>
    <material name="Body001_material" rgba="1 1 1 1.0" texture="Body001_material" shininess="0.141421377658844" specular="0.3103448502657381"/>
    <texture file="visuals/T_BC001.png" name="button_cancel_material" type="2d"/>
    <material name="button_cancel_material" rgba="1 1 1 1.0" texture="button_cancel_material" shininess="0.141421377658844" specular="0.3103448502657381"/>
    <texture file="visuals/T_BC001.png" name="knob_doneness_material" type="2d"/>
    <material name="knob_doneness_material" rgba="1 1 1 1.0" texture="knob_doneness_material" shininess="0.141421377658844" specular="0.3103448502657381"/>
    <texture file="visuals/T_BC001.png" name="lever_material" type="2d"/>
    <material name="lever_material" rgba="1 1 1 1.0" texture="lever_material" shininess="0.141421377658844" specular="0.3103448502657381"/>
    <texture file="visuals/T_BC001.png" name="Body002_material" type="2d"/>
    <material name="Body002_material" rgba="1 1 1 1.0" texture="Body002_material" shininess="1" specular="1"/>
  </asset>
  <default>
    <default class="visual">
      <geom conaffinity="0" contype="0" group="1" type="mesh"/>
    </default>
    <default class="collision_1">
      <geom group="0" rgba="0.5 0 0 0.5" solref="0.004 1" solimp="0.998 0.998 0.001"/>
    </default>
    <default class="collision_2">
      <geom group="0" rgba="0.5 0 0 0.5" solref="0.004 1" solimp="0.998 0.998 0.001"/>
    </default>
    <default class="collision_3">
      <geom group="0" rgba="0.5 0 0 0.5" solref="0.004 1" solimp="0.998 0.998 0.001"/>
    </default>
    <default class="collision_4">
      <geom group="0" rgba="0.5 0 0 0.5" solref="0.004 1" solimp="0.998 0.998 0.001"/>
    </default>
    <default class="collision_5">
      <geom group="0" rgba="0.5 0 0 0.5" solref="0.004 1" solimp="0.998 0.998 0.001"/>
    </default>
    <default class="spawn">
      <geom group="0" rgba="1 1 1 0.5" contype="0" conaffinity="0"/>
      <site group="0" rgba="1 1 1 0.5"/>
    </default>
    <default class="region">
      <geom group="1" conaffinity="0" contype="0" rgba="0 1 0 0" mass="0"/>
    </default>
  </default>
  <worldbody>
    <body>
      <body name="object">
        <geom mesh="Body001_vis" type="mesh" solimp="0.998 0.998 0.001" solref="0.001 1" friction="0.95 0.3 0.1" class="visual" material="Body001_material"/>
        <geom type="box" pos="-3.6107285268371925e-05 0.020393606275320053 -0.07308340072631836" size="0.07271113246679306 0.15268869698047638 0.04766560718417168" quat="1.0 0.0 0.0 0.0" class="collision_1"/>
        <geom type="box" pos="0.07554543763399124 0.016201067715883255 0.0003441762237343937" size="0.029112735763192177 0.10687019675970078 0.12074115127325058" quat="1.0 0.0 0.0 0.0" class="collision_1"/>
        <geom type="box" pos="-0.07748235762119293 0.01620105654001236 0.0003441762237343937" size="0.031209014356136322 0.10687022656202316 0.12074117362499237" quat="1.0 0.0 0.0 0.0" class="collision_1"/>
        <geom type="box" pos="0.000528864620719105 0.1457206904888153 0.0003441762237343937" size="0.04872778058052063 0.048025019466876984 0.12074119597673416" quat="1.0 0.0 0.0 0.0" class="collision_1"/>
        <geom type="box" pos="0.0005288839456625283 -0.11038106679916382 0.0003441762237343937" size="0.04872778430581093 0.03891860693693161 0.12074121832847595" quat="1.0 0.0 0.0 0.0" class="collision_1"/>
        <geom type="box" pos="-0.06080323085188866 -0.10723009705543518 0.0003441762237343937" size="0.03891861438751221 0.029805803671479225 0.12074137479066849" quat="0.8995000720024109 0.0 0.0 -0.4369206726551056" class="collision_1"/>
        <geom type="box" pos="0.05960759148001671 -0.10679752379655838 0.0003441762237343937" size="0.038918618112802505 0.029805809259414673 0.12074137479066849" quat="0.447503000497818 0.0 0.0 -0.8942824006080627" class="collision_1"/>
        <geom type="box" pos="0.0583539679646492 0.14013373851776123 0.0003441762237343937" size="0.03891861438751221 0.029805803671479225 0.12074137479066849" quat="0.8950638771057129 0.0 0.0 -0.44593796133995056" class="collision_1"/>
        <geom type="box" pos="-0.06130402162671089 0.14134547114372253 0.0003441762237343937" size="0.038918618112802505 0.029805809259414673 0.12074137479066849" quat="0.9127457737922668 0.0 0.0 0.40852802991867065" class="collision_1"/>
        <geom type="box" pos="-7.005915540503338e-05 0.014763657003641129 0.0003441762237343937" size="0.008299797773361206 0.08860282599925995 0.12074124068021774" quat="1.0 0.0 0.0 0.0" class="collision_1"/>
        <body name="button_cancel">
          <joint axis="0.0 1.0 0.0" pos="0.030514664947986603 -0.16445860266685486 -0.04799271374940872" limited="true" name="button_cancel_joint" range="0.0 0.0015" type="slide" damping="1" frictionloss="1" armature=".01" stiffness="0.05"/>
          <geom mesh="button_cancel_vis" type="mesh" solimp="0.998 0.998 0.001" solref="0.001 1" friction="0.95 0.3 0.1" class="visual" material="button_cancel_material"/>
          <geom class="collision_2" type="box" pos="0.030507957562804222 -0.16649582982063293 -0.04799039661884308" size="0.006886498536914587 0.005580628290772438 0.006886496674269438" quat="1.0 0.0 0.0 0.0" name="button_cancel_main"/>
        </body>
        <body name="knob_doneness">
          <joint axis="0.0 1.0 0.0" pos="-0.035046085715293884 -0.169930562376976 -0.04223669692873955" limited="true" name="knob_doneness_joint" range="0.0 4.625122517784973" type="hinge" damping="0.05" armature="0.001"/>
          <geom mesh="knob_doneness_vis" type="mesh" solimp="0.998 0.998 0.001" solref="0.001 1" friction="0.95 0.3 0.1" class="visual" material="knob_doneness_material"/>
          <geom type="cylinder" pos="-0.03526045382022858 -0.16673330962657928 -0.042219895869493484" size="0.012758868746459484 0.004955742508172989" quat="0.5000001788139343 0.5000000596046448 0.4999999403953552 -0.49999985098838806" class="collision_3"/>
          <geom class="collision_3" type="box" pos="-0.03526045382022858 -0.1763772964477539 -0.042219895869493484" size="0.005777078680694103 0.005000948905944824 0.012391713447868824" quat="0.6532816886901855 -0.2705979645252228 0.2705981135368347 -0.6532812714576721" name="knob_doneness_main"/>
        </body>
        <body name="lever">
          <joint axis="0.0 0.0 -1.0" pos="-4.842877388000488e-08 -0.17325285077095032 0.07667481899261475" limited="true" name="lever_joint" range="0.0 0.06" type="slide" damping="1" frictionloss="1" armature=".01" stiffness="1" springref="-1"/>
          <geom class="region" name="reg_slotR" type="box" pos="0.027504260651767254 0.013177476823329926 0.12029127590358257" size="0.017630777157843114 0.08341583406925202 0.07616454346477985"/>
          <geom class="region" name="reg_slotL" type="box" pos="-0.027814048808068037 0.013177469372749329 0.12029127590358257" size="0.017630776692181827 0.08341582661867142 0.07616454346477985"/>
          <geom mesh="lever_vis" type="mesh" solimp="0.998 0.998 0.001" solref="0.001 1" friction="0.95 0.3 0.1" class="visual" material="lever_material"/>
          <geom class="collision_4" type="box" pos="0.00011325774539727718 -0.18168222904205322 0.07672090828418732" size="0.014871207997202873 0.012361089698970318 0.005427742842584848" quat="1.0 0.0 0.0 0.0" name="lever_handle"/>
          <geom type="box" pos="-8.3709936006926e-05 -0.1618761420249939 0.07650603353977203" size="0.0026592821814119816 0.007874620147049427 0.004214613698422909" quat="1.0 0.0 0.0 0.0" class="collision_4"/>
          <geom class="collision_4" type="box" pos="0.02775546908378601 0.01278800331056118 0.0410880371928215" size="0.013377128168940544 0.08018035441637039 0.0012188962427899241" quat="1.0 0.0 0.0 0.0" name="slotR_floor"/>
          <geom class="collision_4" type="box" pos="-0.027562841773033142 0.012787999585270882 0.0410880371928215" size="0.013377128168940544 0.08018035441637039 0.0012188962427899241" quat="1.0 0.0 0.0 0.0" name="slotL_floor"/>
        </body>
        <body name="Body002">
          <geom mesh="Body002_vis" type="mesh" solimp="0.998 0.998 0.001" solref="0.001 1" friction="0.95 0.3 0.1" class="visual" material="Body002_material"/>
        </body>
        <geom class="region" name="reg_main" type="box" pos="1.862645149230957e-09 0.01152210682630539 0.0" size="0.11120301282405853 0.18404532766342163 0.12217145955562592"/>
      </body>
    </body>
  </worldbody>
  <actuator>
    <motor name="button_cancel_joint_actuator" joint="button_cancel_joint" gear="0.1"/>
    <motor name="knob_doneness_joint_actuator" joint="knob_doneness_joint" gear="10"/>
    <motor name="lever_joint_actuator" joint="lever_joint" gear="2"/>
  </actuator>
</mujoco>
