<?xml version='1.0' encoding='UTF-8'?>
<mujoco model="model">
  <option timestep="0.002" gravity="0.0 0.0 -9.81"/>
  <compiler angle="radian"/>
  <asset>
    <mesh file="visuals/freezer_door.obj" name="freezer_door_vis"/>
    <mesh file="visuals/freezer_drawer0.obj" name="freezer_drawer0_vis"/>
    <mesh file="visuals/freezer_drawer1.obj" name="freezer_drawer1_vis"/>
    <mesh file="visuals/freezer_drawer2.obj" name="freezer_drawer2_vis"/>
    <mesh file="visuals/fridge_door.obj" name="fridge_door_vis"/>
    <mesh file="visuals/fridge_door_Clear.obj" name="fridge_door_Clear_vis"/>
    <mesh file="visuals/fridge_drawer0.obj" name="fridge_drawer0_vis"/>
    <mesh file="visuals/fridge_drawer1.obj" name="fridge_drawer1_vis"/>
    <mesh file="visuals/fridge_drawer2.obj" name="fridge_drawer2_vis"/>
    <mesh file="visuals/Body001.obj" name="Body001_vis"/>
    <mesh file="visuals/Body001_Clear.obj" name="Body001_Clear_vis"/>
    <texture file="visuals/T_BC001.png" name="Body001_material" type="2d"/>
    <material name="Body001_material" rgba="1 1 1 1.0" texture="Body001_material" shininess="0.141421377658844" specular="1"/>
    <texture file="visuals/T_BC001.png" name="freezer_door_material" type="2d"/>
    <material name="freezer_door_material" rgba="1 1 1 1.0" texture="freezer_door_material" shininess="0.141421377658844" specular="1"/>
    <texture file="visuals/T_BC001.png" name="freezer_drawer0_material" type="2d"/>
    <material name="freezer_drawer0_material" rgba="1 1 1 1.0" texture="freezer_drawer0_material" shininess="0.141421377658844" specular="0.3103448502657381"/>
    <texture file="visuals/T_BC001.png" name="freezer_drawer1_material" type="2d"/>
    <material name="freezer_drawer1_material" rgba="1 1 1 1.0" texture="freezer_drawer1_material" shininess="0.141421377658844" specular="0.3103448502657381"/>
    <texture file="visuals/T_BC001.png" name="freezer_drawer2_material" type="2d"/>
    <material name="freezer_drawer2_material" rgba="1 1 1 1.0" texture="freezer_drawer2_material" shininess="0.141421377658844" specular="0.3103448502657381"/>
    <texture file="visuals/T_BC001.png" name="fridge_door_material" type="2d"/>
    <material name="fridge_door_material" rgba="1 1 1 1.0" texture="fridge_door_material" shininess="0.141421377658844" specular="1"/>
    <material name="fridge_door_Clear_material" rgba="0.986527681350708 0.9570953845977783 1.0 0.699999988079071" shininess="0.5" specular="0.3103448502657381"/>
    <material name="fridge_drawer0_material" rgba="0.986527681350708 0.9570953845977783 1.0 0.699999988079071" shininess="0.5" specular="0.3103448502657381"/>
    <material name="fridge_drawer1_material" rgba="0.986527681350708 0.9570953845977783 1.0 0.699999988079071" shininess="0.5" specular="0.3103448502657381"/>
    <material name="fridge_drawer2_material" rgba="0.986527681350708 0.9570953845977783 1.0 0.699999988079071" shininess="0.5" specular="0.3103448502657381"/>
    <material name="Body001_Clear_material" rgba="0.986527681350708 0.9570953845977783 1.0 0.699999988079071" shininess="0.5" specular="0.3103448502657381"/>
  </asset>
  <default>
    <default class="visual">
      <geom conaffinity="0" contype="0" group="1" type="mesh"/>
    </default>
    <default class="collision">
      <geom group="0" rgba="0.5 0 0 0.5"/>
    </default>
    <default class="spawn">
      <geom group="0" rgba="1 1 1 0.5" contype="0" conaffinity="0"/>
      <site group="0" rgba="1 1 1 0.5"/>
    </default>
    <default class="region">
      <geom group="1" conaffinity="0" contype="0" rgba="0 1 0 0"/>
    </default>
  </default>
  <worldbody>
    <body>
      <body name="object">
        <geom mesh="Body001_vis" type="mesh" solimp="0.998 0.998 0.001" solref="0.001 1" friction="0.95 0.3 0.1" class="visual" material="Body001_material"/>
        <geom class="collision" type="box" pos="-0.44029645 0.07299042 -0.00000009" size="0.019229425117373466 0.3426029682159424 0.9220287799835205" quat="1.0 0.0 0.0 0.0"/>
        <geom class="collision" type="box" pos="0.44024442 0.07369876 0.00000025" size="0.019229387864470482 0.3418939709663391 0.922028660774231" quat="1.0 0.0 0.0 0.0"/>
        <geom class="collision" type="box" pos="-0.00433641 0.07345114 0.88344325" size="0.4262402057647705 0.34214186668395996 0.03858550265431404" quat="1.0 0.0 0.0 0.0"/>
        <geom class="collision" type="box" pos="-0.24455771 0.09774806 0.48021628" size="0.18603147566318512 0.3110361397266388 0.004523452837020159" quat="1.0 0.0 0.0 0.0"/>
        <geom class="collision" type="box" pos="-0.00433641 0.08965314 -0.54117344" size="0.4262450635433197 0.3152131736278534 0.0045233238488435745" quat="1.0 0.0 0.0 0.0"/>
        <geom class="collision" type="box" pos="-0.00433620 0.06589624 -0.21340600" size="0.42624837160110474 0.2894558608531952 0.01199058536440134" quat="1.0 0.0 0.0 0.0"/>
        <geom class="collision" type="box" pos="-0.00433641 0.07142990 -0.88656061" size="0.42624595761299133 0.34410560131073 0.03546379506587982" quat="1.0 0.0 0.0 0.0"/>
        <geom class="collision" type="box" pos="-0.00433623 0.38055932 -0.03835144" size="0.42616522312164307 0.034979600459337234 0.8835586905479431" quat="1.0 0.0 0.0 0.0"/>
        <geom class="collision" type="box" pos="-0.04721737 0.07061660 0.01399101" size="0.011308899149298668 0.33306506276130676 0.8603859543800354" quat="1.0 0.0 0.0 0.0"/>
        <geom class="collision" type="box" pos="-0.24455771 0.09774806 0.12775709" size="0.18603147566318512 0.3110361397266388 0.004523472860455513" quat="1.0 0.0 0.0 0.0"/>
        <geom class="collision" type="box" pos="0.19255321 0.09774806 0.48059241" size="0.22846174240112305 0.3110361397266388 0.0045232828706502914" quat="1.0 0.0 0.0 0.0"/>
        <geom class="collision" type="box" pos="0.19255325 0.09774806 0.12741088" size="0.22846178710460663 0.3110361397266388 0.00452342489734292" quat="1.0 0.0 0.0 0.0"/>
        <body name="freezer_door">
          <joint axis="0.0 0.0 -1.0" pos="-0.43582399 -0.30161461 0.00381469" limited="true" name="freezer_door_joint" range="0.0 1.5707963267948966" type="hinge" damping="1" frictionloss="1" armature=".01" stiffness="0.05"/>
          <geom mesh="freezer_door_vis" type="mesh" solimp="0.998 0.998 0.001" solref="0.001 1" friction="0.95 0.3 0.1" class="visual" material="freezer_door_material"/>
          <geom class="collision" type="box" pos="-0.24527323 -0.31037167 0.01176730" size="0.1886346936225891 0.013732707127928734 0.9080168008804321" quat="1.0 0.0 0.0 0.0"/>
          <geom class="collision" type="box" pos="-0.11005497 -0.36936346 0.59073408" size="0.017864476889371872 0.04676021635532379 0.018915072083473206" quat="1.0 0.0 0.0 0.0" name="freezer_door_handle_1"/>
          <geom class="collision" type="box" pos="-0.11005497 -0.36936346 -0.22138882" size="0.01786448061466217 0.046760112047195435 0.01828717440366745" quat="1.0 0.0 0.0 0.0" name="freezer_door_handle_2"/>
          <geom class="collision" type="cylinder" pos="-0.10999465 -0.39803231 0.18546447" size="0.012440330348908901 0.38117796182632446" quat="1.0 0.0 0.0 0.0" name="freezer_door_handle_main"/>
          <geom class="collision" type="box" pos="-0.24527323 -0.31887871 0.01176730" size="0.18863710761070251 0.005225942004472017 0.9080268740653992" quat="1.0 0.0 0.0 0.0" name="freezer_door_main"/>
        </body>
        <body name="freezer_drawer0">
          <geom class="region" name="reg_freezer_drawer0" type="box" pos="-0.23705668 0.053448465 -0.704650835" size="0.15583863 0.244004235 0.11912540500000002"/>
          <joint axis="0.0 -1.0 0.0" pos="-0.23718981 0.05080346 -0.71145843" limited="true" name="freezer_drawer0_joint" range="0.0 0.5" type="slide" damping="1" frictionloss="1" armature=".01" stiffness="0.05"/>
          <geom mesh="freezer_drawer0_vis" type="mesh" solimp="0.998 0.998 0.001" solref="0.001 1" friction="0.95 0.3 0.1" class="visual" material="freezer_drawer0_material"/>
          <geom class="collision" type="box" pos="-0.09542157 -0.20951826 -0.62140523" size="0.030655868351459503 0.004229157231748104 0.04130857065320015" quat="1.0 0.0 0.0 0.0"/>
          <geom class="collision" type="box" pos="-0.37635614 -0.20951823 -0.62140523" size="0.03326001390814781 0.004229180049151182 0.04130863770842552" quat="1.0 0.0 0.0 0.0"/>
          <geom class="collision" type="box" pos="-0.23719075 -0.20951826 -0.75273721" size="0.17199008166790009 0.004229174926877022 0.09350917488336563" quat="1.0 0.0 0.0 0.0"/>
          <geom class="collision" type="box" pos="-0.23611471 -0.21029234 -0.58579402" size="0.17124305665493011 0.005002995487302542 0.008780749514698982" quat="1.0 0.0 0.0 0.0"/>
          <geom class="collision" type="box" pos="-0.40550233 0.05511924 -0.71049301" size="0.004421782214194536 0.26027509570121765 0.13347020745277405" quat="1.0 0.0 0.0 0.0"/>
          <geom class="collision" type="box" pos="-0.06888629 0.05443063 -0.71049301" size="0.004412725567817688 0.26016613841056824 0.13347002863883972" quat="1.0 0.0 0.0 0.0"/>
          <geom class="collision" type="box" pos="-0.23730394 0.05431512 -0.84074532" size="0.17213794589042664 0.2599739730358124 0.005510554648935795" quat="1.0 0.0 0.0 0.0"/>
          <geom class="collision" type="box" pos="-0.23557426 0.31103730 -0.71152966" size="0.1717817485332489 0.004624445457011461 0.13243302702903748" quat="1.0 0.0 0.0 0.0"/>
        </body>
        <body name="freezer_drawer1">
          <geom class="region" name="reg_freezer_drawer1" type="box" pos="-0.237281125 0.04942196 -0.39137205500000005" size="0.155313595 0.24492116000000003 0.12853738500000003"/>
          <joint axis="0.0 -1.0 0.0" pos="-0.23821859 0.05080346 -0.39431255" limited="true" name="freezer_drawer1_joint" range="0.0 0.5" type="slide" damping="1" frictionloss="1" armature=".01" stiffness="0.05"/>
          <geom mesh="freezer_drawer1_vis" type="mesh" solimp="0.998 0.998 0.001" solref="0.001 1" friction="0.95 0.3 0.1" class="visual" material="freezer_drawer1_material"/>
          <geom class="collision" type="box" pos="-0.23814030 0.30971357 -0.39571516" size="0.1725112348794937 0.006035050842911005 0.1380944699048996" quat="1.0 0.0 0.0 0.0"/>
          <geom class="collision" type="box" pos="-0.23916279 0.04564585 -0.53031598" size="0.1713675558567047 0.2571668326854706 0.0035026909317821264" quat="1.0 0.0 0.0 0.0"/>
          <geom class="collision" type="box" pos="-0.06971696 0.04875225 -0.39297255" size="0.004610856994986534 0.25452926754951477 0.13742603361606598" quat="1.0 0.0 0.0 0.0"/>
          <geom class="collision" type="box" pos="-0.40664495 0.04854984 -0.39297255" size="0.004535562824457884 0.25432777404785156 0.1374264806509018" quat="1.0 0.0 0.0 0.0"/>
          <geom class="collision" type="box" pos="-0.23776211 -0.20957890 -0.26431818" size="0.17344792187213898 0.004289875738322735 0.008780826814472675" quat="1.0 0.0 0.0 0.0"/>
          <geom class="collision" type="box" pos="-0.23776211 -0.20951826 -0.43578051" size="0.17344792187213898 0.00422922195866704 0.09802980720996857" quat="1.0 0.0 0.0 0.0"/>
          <geom class="collision" type="box" pos="-0.37907924 -0.20951826 -0.29992943" size="0.032130833715200424 0.004229207988828421 0.041309528052806854" quat="1.0 0.0 0.0 0.0"/>
          <geom class="collision" type="box" pos="-0.09779884 -0.20951826 -0.29992943" size="0.032130833715200424 0.0042292214930057526 0.04130959510803223" quat="1.0 0.0 0.0 0.0"/>
        </body>
        <body name="freezer_drawer2">
          <geom class="region" name="reg_freezer_drawer2" type="box" pos="-0.237281125 0.04942196 -0.054407925" size="0.155313595 0.24492116000000003 0.128537385"/>
          <joint axis="0.0 -1.0 0.0" pos="-0.23821859 0.05080346 -0.05734842" limited="true" name="freezer_drawer2_joint" range="0.0 0.5" type="slide" damping="1" frictionloss="1" armature=".01" stiffness="0.05"/>
          <geom mesh="freezer_drawer2_vis" type="mesh" solimp="0.998 0.998 0.001" solref="0.001 1" friction="0.95 0.3 0.1" class="visual" material="freezer_drawer2_material"/>
          <geom class="collision" type="box" pos="-0.23814030 0.30971357 -0.05875103" size="0.1725112348794937 0.006035119295120239 0.13809555768966675" quat="1.0 0.0 0.0 0.0"/>
          <geom class="collision" type="box" pos="-0.23916279 0.04564585 -0.19335185" size="0.1713675558567047 0.25716903805732727 0.0035027251578867435" quat="1.0 0.0 0.0 0.0"/>
          <geom class="collision" type="box" pos="-0.06971696 0.04875225 -0.05600841" size="0.004610856994986534 0.25453147292137146 0.13742712140083313" quat="1.0 0.0 0.0 0.0"/>
          <geom class="collision" type="box" pos="-0.40664495 0.04854984 -0.05600841" size="0.004535562824457884 0.25432997941970825 0.13742756843566895" quat="1.0 0.0 0.0 0.0"/>
          <geom class="collision" type="box" pos="-0.23776211 -0.20957890 0.07264595" size="0.17344792187213898 0.004289910197257996 0.008780894801020622" quat="1.0 0.0 0.0 0.0"/>
          <geom class="collision" type="box" pos="-0.23776211 -0.20951826 -0.09881638" size="0.17344792187213898 0.004229256417602301 0.09803090244531631" quat="1.0 0.0 0.0 0.0"/>
          <geom class="collision" type="box" pos="-0.37907924 -0.20951826 0.03703470" size="0.032130833715200424 0.004229242447763681 0.04131007567048073" quat="1.0 0.0 0.0 0.0"/>
          <geom class="collision" type="box" pos="-0.09779884 -0.20951826 0.03703470" size="0.032130833715200424 0.004229255486279726 0.0413101427257061" quat="1.0 0.0 0.0 0.0"/>
        </body>
        <body name="fridge_door">
          <joint axis="0.0 0.0 1.0" pos="0.43607892 -0.30210802 0.00381171" limited="true" name="fridge_door_joint" range="0.0 1.5707963267948966" type="hinge" damping="1" frictionloss="1" armature=".01" stiffness="0.05"/>
          <geom mesh="fridge_door_vis" type="mesh" solimp="0.998 0.998 0.001" solref="0.001 1" friction="0.95 0.3 0.1" class="visual" material="fridge_door_material"/>
          <geom class="collision" type="box" pos="0.20815335 -0.30797792 0.28864778" size="0.19955861568450928 0.0032243402674794197 0.03886110335588455" quat="1.0 0.0 0.0 0.0"/>
          <geom class="collision" type="box" pos="0.40373557 -0.25640343 0.65912087" size="0.005122740287333727 0.054292209446430206 0.038861196488142014" quat="1.0 0.0 0.0 0.0"/>
          <geom class="collision" type="box" pos="0.20866227 -0.20532571 0.65912087" size="0.2001325637102127 0.003224362852051854 0.038861289620399475" quat="1.0 0.0 0.0 0.0"/>
          <geom class="collision" type="box" pos="0.01252901 -0.25640343 0.65912087" size="0.005122786853462458 0.05429258570075035 0.03886138275265694" quat="1.0 0.0 0.0 0.0"/>
          <geom class="collision" type="box" pos="0.20817603 -0.25640343 0.62448837" size="0.20027346909046173 0.054292768239974976 0.0034381297882646322" quat="1.0 0.0 0.0 0.0"/>
          <geom class="collision" type="box" pos="0.20787233 -0.25640349 0.25308563" size="0.2000824213027954 0.054293155670166016 0.0034381533041596413" quat="1.0 0.0 0.0 0.0"/>
          <geom class="collision" type="box" pos="0.01291248 -0.25640343 0.28851332" size="0.005122868809849024 0.05429333820939064 0.03886175900697708" quat="1.0 0.0 0.0 0.0"/>
          <geom class="collision" type="box" pos="0.20846749 -0.20532571 0.28851332" size="0.19956250488758087 0.0032244313042610884 0.03886185213923454" quat="1.0 0.0 0.0 0.0"/>
          <geom class="collision" type="box" pos="0.40296249 -0.25640343 0.28851332" size="0.005122914910316467 0.054293710738420486 0.038861945271492004" quat="1.0 0.0 0.0 0.0"/>
          <geom class="collision" type="box" pos="0.20815335 -0.30827460 0.65963937" size="0.19956155121326447 0.0032243402674794197 0.03886110335588455" quat="1.0 0.0 0.0 0.0"/>
          <geom class="collision" type="box" pos="0.20551263 -0.31409335 0.01176548" size="0.24239735305309296 0.010585621930658817 0.9080493450164795" quat="1.0 0.0 0.0 0.0"/>
          <geom class="collision" type="box" pos="0.01142187 -0.36862108 0.58999719" size="0.017865004017949104 0.0467604361474514 0.01799345202744007" quat="1.0 0.0 0.0 0.0" name="fridge_door_handle_1"/>
          <geom class="collision" type="box" pos="0.01142187 -0.36862108 -0.22199521" size="0.017865007743239403 0.046760331839323044 0.017993396148085594" quat="1.0 0.0 0.0 0.0" name="fridge_door_handle_2"/>
          <geom class="collision" type="cylinder" pos="0.01148219 -0.39728993 0.18515198" size="0.012440330348908901 0.38117796182632446" quat="1.0 0.0 0.0 0.0" name="fridge_door_handle_main"/>
          <geom class="collision" type="box" pos="0.20551263 -0.31973300 0.01176548" size="0.24239735305309296 0.0049459729343652725 0.9080493450164795" quat="1.0 0.0 0.0 0.0" name="fridge_door_main"/>
          <body name="fridge_door_Clear">
            <geom mesh="fridge_door_Clear_vis" type="mesh" solimp="0.998 0.998 0.001" solref="0.001 1" friction="0.95 0.3 0.1" class="visual" material="fridge_door_Clear_material"/>
            <geom class="collision" type="box" pos="0.20815335 -0.30797792 0.28864778" size="0.19955861568450928 0.0032243402674794197 0.03886110335588455" quat="1.0 0.0 0.0 0.0"/>
            <geom class="collision" type="box" pos="0.40373557 -0.25640343 0.65912087" size="0.005122740287333727 0.054292209446430206 0.038861196488142014" quat="1.0 0.0 0.0 0.0"/>
            <geom class="collision" type="box" pos="0.20866227 -0.20532571 0.65912087" size="0.2001325637102127 0.003224362852051854 0.038861289620399475" quat="1.0 0.0 0.0 0.0"/>
            <geom class="collision" type="box" pos="0.01252901 -0.25640343 0.65912087" size="0.005122786853462458 0.05429258570075035 0.03886138275265694" quat="1.0 0.0 0.0 0.0"/>
            <geom class="collision" type="box" pos="0.20817603 -0.25640343 0.62448837" size="0.20027346909046173 0.054292768239974976 0.0034381297882646322" quat="1.0 0.0 0.0 0.0"/>
            <geom class="collision" type="box" pos="0.20787233 -0.25640349 0.25308563" size="0.2000824213027954 0.054293155670166016 0.0034381533041596413" quat="1.0 0.0 0.0 0.0"/>
            <geom class="collision" type="box" pos="0.01291248 -0.25640343 0.28851332" size="0.005122868809849024 0.05429333820939064 0.03886175900697708" quat="1.0 0.0 0.0 0.0"/>
            <geom class="collision" type="box" pos="0.20846749 -0.20532571 0.28851332" size="0.19956250488758087 0.0032244313042610884 0.03886185213923454" quat="1.0 0.0 0.0 0.0"/>
            <geom class="collision" type="box" pos="0.40296249 -0.25640343 0.28851332" size="0.005122914910316467 0.054293710738420486 0.038861945271492004" quat="1.0 0.0 0.0 0.0"/>
            <geom class="collision" type="box" pos="0.20815335 -0.30827460 0.65963937" size="0.19956155121326447 0.0032243402674794197 0.03886110335588455" quat="1.0 0.0 0.0 0.0"/>
          </body>
        </body>
        <body name="fridge_drawer0">
          <geom class="region" name="reg_fridge_drawer0" type="box" pos="0.194406055 0.053448465 -0.704650835" size="0.201015185 0.244004235 0.11912540500000002"/>
          <joint axis="0.0 -1.0 0.0" pos="0.19427289 0.05080346 -0.71145843" limited="true" name="fridge_drawer0_joint" range="0.0 0.5" type="slide" damping="1" frictionloss="1" armature=".01" stiffness="0.05"/>
          <geom mesh="fridge_drawer0_vis" type="mesh" solimp="0.998 0.998 0.001" solref="0.001 1" friction="0.95 0.3 0.1" class="visual" material="fridge_drawer0_material"/>
          <geom class="collision" type="box" pos="0.38121768 -0.20951826 -0.62140523" size="0.030655866488814354 0.004229260142892599 0.04131020978093147" quat="1.0 0.0 0.0 0.0"/>
          <geom class="collision" type="box" pos="0.00993004 -0.20951823 -0.62140523" size="0.03326001390814781 0.00422928249463439 0.041310280561447144" quat="1.0 0.0 0.0 0.0"/>
          <geom class="collision" type="box" pos="0.19427197 -0.20951826 -0.75273721" size="0.21716661751270294 0.0042292773723602295 0.09351245313882828" quat="1.0 0.0 0.0 0.0"/>
          <geom class="collision" type="box" pos="0.19534801 -0.21029234 -0.58579402" size="0.21641959249973297 0.005003200378268957 0.008780954405665398" quat="1.0 0.0 0.0 0.0"/>
          <geom class="collision" type="box" pos="-0.01921615 0.05511924 -0.71049301" size="0.004421780351549387 0.26028165221214294 0.1334734857082367" quat="1.0 0.0 0.0 0.0"/>
          <geom class="collision" type="box" pos="0.40775295 0.05443063 -0.71049301" size="0.004412724170833826 0.2601727247238159 0.13347330689430237" quat="1.0 0.0 0.0 0.0"/>
          <geom class="collision" type="box" pos="0.19415878 0.05431512 -0.84074532" size="0.2173144668340683 0.25998055934906006 0.00551075953990221" quat="1.0 0.0 0.0 0.0"/>
          <geom class="collision" type="box" pos="0.19588846 0.31103730 -0.71152966" size="0.21695828437805176 0.004624547902494669 0.13243630528450012" quat="1.0 0.0 0.0 0.0"/>
        </body>
        <body name="fridge_drawer1">
          <geom class="region" name="reg_fridge_drawer1" type="box" pos="0.19418158500000002 0.04942196 -0.39137205500000005" size="0.200490125 0.24492116000000003 0.12853738500000003"/>
          <joint axis="0.0 -1.0 0.0" pos="0.19324412 0.05080346 -0.39431255" limited="true" name="fridge_drawer1_joint" range="0.0 0.5" type="slide" damping="1" frictionloss="1" armature=".01" stiffness="0.05"/>
          <geom mesh="fridge_drawer1_vis" type="mesh" solimp="0.998 0.998 0.001" solref="0.001 1" friction="0.95 0.3 0.1" class="visual" material="fridge_drawer1_material"/>
          <geom class="collision" type="box" pos="0.19332242 0.30971357 -0.39571516" size="0.21768775582313538 0.00603525573387742 0.13809774816036224" quat="1.0 0.0 0.0 0.0"/>
          <geom class="collision" type="box" pos="0.19229993 0.04564585 -0.53031598" size="0.21654409170150757 0.2571733891963959 0.003502793377265334" quat="1.0 0.0 0.0 0.0"/>
          <geom class="collision" type="box" pos="0.40692230 0.04875225 -0.39297255" size="0.004610855598002672 0.25453582406044006 0.13742931187152863" quat="1.0 0.0 0.0 0.0"/>
          <geom class="collision" type="box" pos="-0.02035878 0.04854984 -0.39297255" size="0.004535564221441746 0.25433433055877686 0.13742975890636444" quat="1.0 0.0 0.0 0.0"/>
          <geom class="collision" type="box" pos="0.19370061 -0.20957890 -0.26431818" size="0.21862444281578064 0.0042899781838059425 0.00878103170543909" quat="1.0 0.0 0.0 0.0"/>
          <geom class="collision" type="box" pos="0.19370061 -0.20951826 -0.43578051" size="0.21862444281578064 0.004229324404150248 0.09803309291601181" quat="1.0 0.0 0.0 0.0"/>
          <geom class="collision" type="box" pos="0.00720695 -0.20951826 -0.29992943" size="0.032130829989910126 0.004229310434311628 0.04131116718053818" quat="1.0 0.0 0.0 0.0"/>
          <geom class="collision" type="box" pos="0.37884040 -0.20951826 -0.29992943" size="0.032130833715200424 0.00422932393848896 0.04131123796105385" quat="1.0 0.0 0.0 0.0"/>
        </body>
        <body name="fridge_drawer2">
          <geom class="region" name="reg_fridge_drawer2" type="box" pos="0.19418158500000002 0.04942196 -0.054407925" size="0.200490125 0.24492116000000003 0.128537385"/>
          <joint axis="0.0 -1.0 0.0" pos="0.19324412 0.05080346 -0.05734842" limited="true" name="fridge_drawer2_joint" range="0.0 0.5" type="slide" damping="1" frictionloss="1" armature=".01" stiffness="0.05"/>
          <geom mesh="fridge_drawer2_vis" type="mesh" solimp="0.998 0.998 0.001" solref="0.001 1" friction="0.95 0.3 0.1" class="visual" material="fridge_drawer2_material"/>
          <geom class="collision" type="box" pos="0.19332242 0.30971357 -0.05875103" size="0.21768775582313538 0.006035324186086655 0.1380988359451294" quat="1.0 0.0 0.0 0.0"/>
          <geom class="collision" type="box" pos="0.19229993 0.04564585 -0.19335185" size="0.21654409170150757 0.25717559456825256 0.0035028276033699512" quat="1.0 0.0 0.0 0.0"/>
          <geom class="collision" type="box" pos="0.40692230 0.04875225 -0.05600841" size="0.004610855598002672 0.25453802943229675 0.13743039965629578" quat="1.0 0.0 0.0 0.0"/>
          <geom class="collision" type="box" pos="-0.02035878 0.04854984 -0.05600841" size="0.004535564221441746 0.25433653593063354 0.1374308466911316" quat="1.0 0.0 0.0 0.0"/>
          <geom class="collision" type="box" pos="0.19370061 -0.20957890 0.07264595" size="0.21862444281578064 0.004290012642741203 0.008781099691987038" quat="1.0 0.0 0.0 0.0"/>
          <geom class="collision" type="box" pos="0.19370061 -0.20951826 -0.09881638" size="0.21862444281578064 0.004229358863085508 0.09803418070077896" quat="1.0 0.0 0.0 0.0"/>
          <geom class="collision" type="box" pos="0.00720695 -0.20951826 0.03703470" size="0.032130829989910126 0.004229344893246889 0.04131171479821205" quat="1.0 0.0 0.0 0.0"/>
          <geom class="collision" type="box" pos="0.37884040 -0.20951826 0.03703470" size="0.032130833715200424 0.004229357931762934 0.041311781853437424" quat="1.0 0.0 0.0 0.0"/>
        </body>
        <body name="Body001_Clear">
          <geom mesh="Body001_Clear_vis" type="mesh" solimp="0.998 0.998 0.001" solref="0.001 1" friction="0.95 0.3 0.1" class="visual" material="Body001_Clear_material"/>
          <geom class="collision" type="box" pos="0.19255321 0.09774806 0.48059241" size="0.22846174240112305 0.3110361397266388 0.0045232828706502914" quat="1.0 0.0 0.0 0.0"/>
          <geom class="collision" type="box" pos="0.19255325 0.09774806 0.12741088" size="0.22846178710460663 0.3110361397266388 0.00452342489734292" quat="1.0 0.0 0.0 0.0"/>
        </body>
        <geom class="region" name="reg_freezer_shelf0" type="box" pos="-0.23947380000000001 0.07577905500000001 0.303067075" size="0.17634095 0.264121925 0.16288624499999999"/>
        <geom class="region" name="reg_freezer_shelf1" type="box" pos="-0.23947380000000001 0.07577905500000001 0.666245295" size="0.17634095 0.264121925 0.17270202500000004"/>
        <geom class="region" name="reg_fridge_shelf0" type="box" pos="0.193035075 0.08013421000000001 0.30343562" size="0.22326584500000002 0.25995122000000004 0.16343840999999998"/>
        <geom class="region" name="reg_fridge_shelf1" type="box" pos="0.193035075 0.08013421000000001 0.6653561299999999" size="0.22326584500000002 0.25995122000000004 0.17168307"/>
        <geom class="region" name="reg_main" type="box" pos="-1.830000000008214e-06 0.04542838000000002 1.299999999870849e-07" size="0.46052415 0.37110771 0.9230289"/>
      </body>
    </body>
  </worldbody>
  <actuator>
    <motor name="freezer_door_joint_actuator" joint="freezer_door_joint" gear="50"/>
    <motor name="freezer_drawer0_joint_actuator" joint="freezer_drawer0_joint" gear="50"/>
    <motor name="freezer_drawer1_joint_actuator" joint="freezer_drawer1_joint" gear="50"/>
    <motor name="freezer_drawer2_joint_actuator" joint="freezer_drawer2_joint" gear="50"/>
    <motor name="fridge_door_joint_actuator" joint="fridge_door_joint" gear="50"/>
    <motor name="fridge_drawer0_joint_actuator" joint="fridge_drawer0_joint" gear="50"/>
    <motor name="fridge_drawer1_joint_actuator" joint="fridge_drawer1_joint" gear="50"/>
    <motor name="fridge_drawer2_joint_actuator" joint="fridge_drawer2_joint" gear="50"/>
  </actuator>
</mujoco>
