<?xml version='1.0' encoding='UTF-8'?>
<mujoco model="model">
  <option timestep="0.002" gravity="0.0 0.0 -9.81"/>
  <compiler angle="radian"/>
  <asset>
    <mesh file="visuals/blender.obj" name="blender_vis"/>
    <mesh file="visuals/bowl.obj" name="bowl_vis"/>
    <mesh file="visuals/button_head_lock.obj" name="button_head_lock_vis"/>
    <mesh file="visuals/head.obj" name="head_vis"/>
    <mesh file="visuals/knob_speed.obj" name="knob_speed_vis"/>
    <mesh file="visuals/Body001.obj" name="Body001_vis"/>
    <texture file="visuals/T_BC001.png" name="Body001_material" type="2d"/>
    <material name="Body001_material" rgba="1 1 1 1.0" texture="Body001_material" shininess="0.1" specular="0.9"/>
    <texture file="visuals/T_BC001.png" name="bowl_material" type="2d"/>
    <material name="bowl_material" rgba="1 1 1 1.0" texture="bowl_material" shininess="0.1" specular="0.9"/>
    <texture file="visuals/T_BC001.png" name="button_head_lock_material" type="2d"/>
    <material name="button_head_lock_material" rgba="1 1 1 1.0" texture="button_head_lock_material" shininess="0.1" specular="0.9"/>
    <texture file="visuals/T_BC001.png" name="head_material" type="2d"/>
    <material name="head_material" rgba="1 1 1 1.0" texture="head_material" shininess="0.1" specular="0.9"/>
    <texture file="visuals/T_BC001.png" name="blender_material" type="2d"/>
    <material name="blender_material" rgba="1 1 1 1.0" texture="blender_material" shininess="0.1" specular="0.9"/>
    <texture file="visuals/T_BC001.png" name="knob_speed_material" type="2d"/>
    <material name="knob_speed_material" rgba="1 1 1 1.0" texture="knob_speed_material" shininess="0.1" specular="0.9"/>
  </asset>
  <default>
    <default class="visual">
      <geom conaffinity="0" contype="0" group="1" type="mesh"/>
    </default>
    <default class="collision">
      <geom group="0" rgba="0.5 0 0 0.5"/>
    </default>
    <default class="spawn">
      <geom group="0" rgba="1 1 1 0.5" contype="0" conaffinity="0"/>
      <site group="0" rgba="1 1 1 0.5"/>
    </default>
    <default class="region">
      <geom group="1" conaffinity="0" contype="0" rgba="0 1 0 0"/>
    </default>
  </default>
  <worldbody>
    <body>
      <body name="object">
        <geom mesh="Body001_vis" type="mesh" solimp="0.998 0.998 0.001" solref="0.001 1" friction="0.95 0.3 0.1" class="visual" material="Body001_material"/>
        <geom type="box" pos="0.00479950 0.00000000 -0.28111044" size="0.19251543283462524 0.34842848777770996 0.08424658328294754" quat="1.0 0.0 0.0 0.0" class="collision"/>
        <geom type="box" pos="-0.01058882 0.19475512 -0.01122107" size="0.16297440230846405 0.12090107053518295 0.1839895248413086" quat="1.0 0.0 0.0 0.0" class="collision"/>
        <geom type="box" pos="0.16387165 0.27531415 -0.01122107" size="0.009846153669059277 0.04034204035997391 0.1839895248413086" quat="1.0 0.0 0.0 0.0" class="collision"/>
        <geom type="box" pos="0.16387165 0.11826086 -0.01122107" size="0.009846153669059277 0.04394160956144333 0.1839895248413086" quat="1.0 0.0 0.0 0.0" class="collision"/>
        <geom type="box" pos="0.16387165 0.19849299 -0.13267896" size="0.009846153669059277 0.03491780906915665 0.06253164261579514" quat="1.0 0.0 0.0 0.0" class="collision"/>
        <geom type="box" pos="0.16387165 0.19849299 0.14094439" size="0.009846153669059277 0.03491780906915665 0.03183937817811966" quat="1.0 0.0 0.0 0.0" class="collision"/>
        <geom type="box" pos="0.16387165 0.19849299 0.04133829" size="0.009846153669059277 0.03491780906915665 0.03183937817811966" quat="1.0 0.0 0.0 0.0" class="collision"/>
        <body name="bowl">
          <!-- <joint axis="0.0 0.0 1.0" pos="-0.00010132 -0.14019130 -0.05283890" limited="true" name="bowl_joint" range="0.0 0.12" type="slide" damping="1" frictionloss="1" armature=".01" stiffness="0.05"/> -->
          <geom mesh="bowl_vis" type="mesh" solimp="0.998 0.998 0.001" solref="0.001 1" friction="0.95 0.3 0.1" class="visual" material="bowl_material"/>
          <geom type="cylinder" pos="-0.00010131 -0.14019130 -0.18164055" size="0.18583239614963531 0.010407824069261551" quat="1.0 0.0 0.0 0.0" class="collision"/>
          <geom type="box" pos="0.18134426 -0.17216861 -0.03994373" size="0.0061767445877194405 0.033245980739593506 0.12993557751178741" quat="0.9961947202682495 0.0 -0.0 -0.08715573698282242" class="collision"/>
          <geom type="box" pos="-0.18136032 -0.10821400 -0.03994373" size="0.0061767445877194405 0.033245980739593506 0.12993557751178741" quat="0.9961947202682495 0.0 -0.0 -0.08715573698282242" class="collision"/>
          <geom type="box" pos="-0.00000805 -0.32434124 -0.03994373" size="0.033245980739593506 0.006176746916025877 0.1299353837966919" quat="1.0 0.0 0.0 0.0" class="collision"/>
          <geom type="box" pos="-0.00000802 0.04395865 -0.03994373" size="0.033245980739593506 0.006176746916025877 0.12993547320365906" quat="1.0 0.0 0.0 0.0" class="collision"/>
          <geom type="box" pos="-0.06299102 0.03285305 -0.03994373" size="0.0061767445877194405 0.033245980739593506 0.12993557751178741" quat="0.8191520571708679 0.0 -0.0 -0.5735764503479004" class="collision"/>
          <geom type="box" pos="0.06297496 -0.31323564 -0.03994373" size="0.0061767445877194405 0.033245980739593506 0.12993557751178741" quat="0.8191520571708679 0.0 -0.0 -0.5735764503479004" class="collision"/>
          <geom type="box" pos="0.11836127 -0.28125834 -0.03994373" size="0.0061767445877194405 0.033245980739593506 0.12993557751178741" quat="0.9063077569007874 0.0 -0.0 -0.4226183593273163" class="collision"/>
          <geom type="box" pos="-0.11837733 0.00087576 -0.03994373" size="0.0061767445877194405 0.033245980739593506 0.12993557751178741" quat="0.9063077569007874 0.0 -0.0 -0.4226183593273163" class="collision"/>
          <geom type="box" pos="-0.15948655 -0.04811631 -0.03994373" size="0.0061767445877194405 0.033245980739593506 0.12993557751178741" quat="0.9659258127212524 0.0 -0.0 -0.2588190734386444" class="collision"/>
          <geom type="box" pos="0.15947050 -0.23226628 -0.03994373" size="0.0061767445877194405 0.033245980739593506 0.12993557751178741" quat="0.9659258127212524 0.0 -0.0 -0.2588190734386444" class="collision"/>
          <geom type="box" pos="0.06297500 0.03285304 -0.03994373" size="0.0061767445877194405 0.033245980739593506 0.12993557751178741" quat="0.8191519975662231 0.0 0.0 0.5735765099525452" class="collision"/>
          <geom type="box" pos="-0.06299104 -0.31323564 -0.03994373" size="0.0061767445877194405 0.033245980739593506 0.12993557751178741" quat="0.8191519975662231 0.0 0.0 0.5735765099525452" class="collision"/>
          <geom type="box" pos="-0.11837734 -0.28125834 -0.03994373" size="0.0061767445877194405 0.033245980739593506 0.12993557751178741" quat="0.9063078165054321 0.0 0.0 0.42261821031570435" class="collision"/>
          <geom type="box" pos="0.11836131 0.00087573 -0.03994373" size="0.0061767445877194405 0.033245980739593506 0.12993557751178741" quat="0.9063078165054321 0.0 0.0 0.42261821031570435" class="collision"/>
          <geom type="box" pos="0.15947053 -0.04811636 -0.03994373" size="0.0061767445877194405 0.033245980739593506 0.12993557751178741" quat="0.9659258127212524 0.0 0.0 0.2588190734386444" class="collision"/>
          <geom type="box" pos="-0.15948656 -0.23226626 -0.03994373" size="0.0061767445877194405 0.033245980739593506 0.12993557751178741" quat="0.9659258127212524 0.0 0.0 0.2588190734386444" class="collision"/>
          <geom type="box" pos="-0.18136032 -0.17216858 -0.03994373" size="0.0061767445877194405 0.033245984464883804 0.12993557751178741" quat="0.9961947202682495 0.0 0.0 0.08715561032295227" class="collision"/>
          <geom type="box" pos="0.18134429 -0.10821403 -0.03994373" size="0.0061767445877194405 0.033245984464883804 0.12993557751178741" quat="0.9961947202682495 0.0 0.0 0.08715561032295227" class="collision"/>
          <geom name="reg_bowl" type="ellipsoid" pos="0.00087723 -0.14145979 0.08985191" size="0.16639654338359833 0.1710948646068573 0.2604679763317108" rgba="0 1 0 0.5" class="region"/>
        </body>
        <body name="button_head_lock">
          <joint axis="-1.0 0.0 0.0" pos="0.17874989 0.19904800 0.09049630" limited="true" name="button_head_lock_joint" range="0.0 0.003" type="slide" damping="1" frictionloss="1" armature=".01" stiffness="0.05"/>
          <geom mesh="button_head_lock_vis" type="mesh" solimp="0.998 0.998 0.001" solref="0.001 1" friction="0.95 0.3 0.1" class="visual" material="button_head_lock_material"/>
          <geom class="collision" type="cylinder" pos="0.17880759 0.19904798 0.09052038" size="0.014642302878201008 0.007393617648631334" quat="0.7071068286895752 -0.0 0.7071067690849304 0.0" name="button_head_lock_main"/>
        </body>
        <body name="head">
          <joint axis="-1.0 0.0 0.0" pos="0.00003790 0.31874591 0.17423128" limited="true" name="head_joint" range="0.0 1.5707963267948966" type="hinge" damping="1" frictionloss="1" armature=".01" stiffness="0.05"/>
          <geom mesh="head_vis" type="mesh" solimp="0.998 0.998 0.001" solref="0.001 1" friction="0.95 0.3 0.1" class="visual" material="head_material"/>
          <geom type="box" pos="-0.00045038 0.12257081 0.23727286" size="0.1943187117576599 0.2085888683795929 0.06351733207702637" quat="1.0 0.0 0.0 0.0" class="collision"/>
          <geom type="box" pos="0.00227256 -0.13702893 0.23727286" size="0.08539991080760956 0.04922421649098396 0.06351733207702637" quat="1.0 0.0 0.0 0.0" class="collision"/>
          <geom type="box" pos="0.10206094 -0.09596774 0.23727286" size="0.06879246234893799 0.04922395572066307 0.06351733207702637" quat="0.9238795042037964 0.0 0.0 0.3826834559440613" class="collision"/>
          <geom type="box" pos="-0.09825914 -0.10031419 0.23727286" size="0.06904993206262589 0.04922395944595337 0.06351733207702637" quat="0.9238795042037964 0.0 -0.0 -0.3826834559440613" class="collision"/>
          <geom type="box" pos="-0.00005446 0.12257081 0.33328357" size="0.16760961711406708 0.18835023045539856 0.03170707821846008" quat="1.0 0.0 0.0 0.0" class="collision"/>
          <geom type="box" pos="0.18941081 -0.06659175 0.15252440" size="0.007024100515991449 0.027991430833935738 0.04819820448756218" quat="1.0 0.0 0.0 0.0" class="collision"/>
          <geom type="box" pos="0.17969069 -0.13277429 0.13198212" size="0.007024114485830069 0.03573315963149071 0.02964690513908863" quat="0.9827542901039124 -0.005831497255712748 -0.1749138981103897 -0.059708282351493835" class="collision"/>
          <geom type="box" pos="-0.00067121 -0.27930495 0.15129133" size="0.007024114485830069 0.027991430833935738 0.06515268236398697" quat="0.6562364101409912 -0.26335108280181885 -0.2633510231971741 -0.6562364101409912" class="collision"/>
          <geom type="box" pos="0.04194896 -0.27303970 0.15218876" size="0.007024114485830069 0.027991430833935738 0.06515268236398697" quat="0.752773106098175 -0.20632094144821167 -0.30972301959991455 -0.5429880023002625" class="collision"/>
          <geom type="box" pos="0.08377919 -0.25307381 0.15199929" size="0.007024114951491356 0.027991430833935738 0.06515268236398697" quat="0.8307384252548218 -0.17888695001602173 -0.32604533433914185 -0.4142071008682251" class="collision"/>
          <geom type="box" pos="0.11528976 -0.22392008 0.15162727" size="0.007024114485830069 0.02799142710864544 0.06515268236398697" quat="0.8761871457099915 -0.10927364230155945 -0.35546261072158813 -0.3065970242023468" class="collision"/>
          <geom type="box" pos="0.14324707 -0.17901364 0.15572341" size="0.007024114951491356 0.027991432696580887 0.06515268236398697" quat="0.9231134653091431 -0.09359268844127655 -0.3090006113052368 -0.2088554948568344" class="collision"/>
          <geom type="box" pos="0.16209601 -0.12146801 0.18009305" size="0.007024114485830069 0.03573315590620041 0.0211629718542099" quat="0.911022961139679 -0.08539623022079468 -0.19718386232852936 -0.3519419729709625" class="collision"/>
          <geom type="box" pos="-0.16219972 -0.12146801 0.18009305" size="0.007024114485830069 0.03573315963149071 0.0211629718542099" quat="0.911022961139679 -0.08539625257253647 0.19718389213085175 0.3519419729709625" class="collision"/>
          <geom type="box" pos="-0.08388291 -0.25307378 0.15199928" size="0.007024114951491356 0.027991430833935738 0.06515268236398697" quat="0.8307384252548218 -0.17888695001602173 0.32604533433914185 0.4142071008682251" class="collision"/>
          <geom type="box" pos="-0.04205266 -0.27303970 0.15218876" size="0.007024114951491356 0.027991430833935738 0.06515267491340637" quat="0.752773106098175 -0.20632094144821167 0.3097230792045593 0.5429880023002625" class="collision"/>
          <geom type="box" pos="-0.11539346 -0.22392009 0.15162727" size="0.007024114485830069 0.02799142710864544 0.06515268236398697" quat="0.8761871457099915 -0.10927364975214005 0.35546255111694336 0.3065970838069916" class="collision"/>
          <geom type="box" pos="-0.14335072 -0.17901361 0.15572344" size="0.007024114951491356 0.027991432696580887 0.06515267491340637" quat="0.9231135249137878 -0.0935925841331482 0.30900055170059204 0.2088552713394165" class="collision"/>
          <geom type="box" pos="-0.17979439 -0.13277429 0.13198212" size="0.007024114485830069 0.03573315963149071 0.02964690513908863" quat="0.9827542901039124 -0.00583149679005146 0.1749138981103897 0.059708282351493835" class="collision"/>
          <geom type="box" pos="-0.18522781 -0.06659175 0.15252440" size="0.007024103309959173 0.027991430833935738 0.04819824546575546" quat="1.0 0.0 0.0 0.0" class="collision"/>
          <geom type="box" pos="0.00227256 -0.21233524 0.19651197" size="0.028944510966539383 0.023552678525447845 0.004796868190169334" quat="1.0 0.0 0.0 0.0" class="collision"/>
          <geom type="box" pos="-0.04435195 -0.20218417 0.19651197" size="0.01881283149123192 0.030994737520813942 0.004796868190169334" quat="0.8969359993934631 0.0 0.0 0.44216036796569824" class="collision"/>
          <geom type="box" pos="0.05077045 -0.20069826 0.19651197" size="0.01881283149123192 0.030994733795523643 0.004796868190169334" quat="0.8969359993934631 0.0 -0.0 -0.44216039776802063" class="collision"/>
          <body name="blender">
            <joint axis="0.0 0.0 1.0" pos="0.00002235 -0.12619527 0.17489170" limited="false" name="blender_joint" range="0 360" type="hinge" damping="1" frictionloss="1" armature=".01" stiffness="0.05"/>
            <geom mesh="blender_vis" type="mesh" solimp="0.998 0.998 0.001" solref="0.001 1" friction="0.95 0.3 0.1" class="visual" material="blender_material"/>
            <geom type="cylinder" pos="0.00070645 -0.12625912 0.16439107" size="0.0488768070936203 0.009077758528292179" quat="1.0 0.0 0.0 0.0" class="collision"/>
            <geom type="cylinder" pos="-0.02954750 -0.15007511 0.11570022" size="0.008038324303925037 0.03987272456288338" quat="1.0 0.0 0.0 0.0" class="collision"/>
            <geom type="cylinder" pos="0.00337470 -0.11204024 0.13533317" size="0.014936371706426144 0.03110305406153202" quat="0.9393659830093384 0.1000475212931633 0.3272119462490082 -0.02268061228096485" class="collision"/>
            <geom type="cylinder" pos="-0.02613318 -0.12335981 0.09436906" size="0.014777264557778835 0.030771734192967415" quat="0.7805690765380859 -0.282722145318985 0.31547272205352783 0.45962709188461304" class="collision"/>
            <geom type="cylinder" pos="-0.02215140 -0.16127753 0.06076413" size="0.014777264557778835 0.030771734192967415" quat="0.6745424866676331 -0.43157464265823364 -0.039401449263095856 0.5976481437683105" class="collision"/>
            <geom type="cylinder" pos="0.01683869 -0.17599301 0.02893255" size="0.014777264557778835 0.030771734192967415" quat="0.19706715643405914 -0.4277191758155823 -0.23005877435207367 0.851641833782196" class="collision"/>
            <geom type="cylinder" pos="0.05393789 -0.14575823 0.00171689" size="0.014777264557778835 0.030771736055612564" quat="0.13328370451927185 0.16134995222091675 0.4719087481498718 -0.8564483523368835" class="collision"/>
            <geom type="cylinder" pos="0.05036687 -0.09971950 -0.02445681" size="0.012846244499087334 0.026750639081001282" quat="0.2754901349544525 -0.10154769569635391 0.5268837809562683 -0.7976131439208984" class="collision"/>
            <geom type="cylinder" pos="0.01797492 -0.07159502 -0.04290097" size="0.012846244499087334 0.026750635355710983" quat="0.5539237260818481 -0.3012176752090454 0.4401063919067383 -0.6393299698829651" class="collision"/>
            <geom type="cylinder" pos="-0.03117903 -0.07434565 -0.06720261" size="0.010498244315385818 0.031561873853206635" quat="0.6597776412963867 -0.4777856171131134 0.25537940859794617 -0.5207645297050476" class="collision"/>
            <geom type="cylinder" pos="-0.06545527 -0.10750119 -0.08790368" size="0.010498244315385818 0.025174468755722046" quat="0.8097105622291565 -0.5601747632026672 0.12818746268749237 -0.11891600489616394" class="collision"/>
            <geom type="cylinder" pos="-0.07406759 -0.14670089 -0.10274010" size="0.007984554395079613 0.019868724048137665" quat="0.8177357316017151 -0.5725573301315308 -0.058064937591552734 0.010719173587858677" class="collision"/>
          </body>
        </body>
        <body name="knob_speed">
          <joint axis="-1.0 0.0 0.0" pos="0.18725231 0.19747312 -0.03105357" limited="true" name="knob_speed_joint" range="0.0 4.886921905584122" type="hinge" damping="0.05" armature="0.001"/>
          <geom mesh="knob_speed_vis" type="mesh" solimp="0.998 0.998 0.001" solref="0.001 1" friction="0.95 0.3 0.1" class="visual" material="knob_speed_material"/>
          <geom type="cylinder" pos="0.17420818 0.19784521 -0.03105356" size="0.03231373801827431 0.0012079408625140786" quat="0.7071068286895752 -0.0 0.7071067690849304 0.0" class="collision"/>
          <geom class="collision" type="box" pos="0.18498434 0.19784521 -0.03105356" size="0.009411806240677834 0.028818931430578232 0.005275980569422245" quat="0.9626153111457825 -0.27087217569351196 -6.014570523704953e-17 6.542199994625394e-25" name="knob_speed_main"/>
        </body>
        <geom class="region" name="reg_main" type="box" pos="1.8945000000006318e-05 0.0 1.4999999992104662e-08" size="0.189103395 0.34853513 0.36542893499999995"/>
      </body>
    </body>
  </worldbody>
  <actuator>
    <!-- <motor name="bowl_joint_actuator" joint="bowl_joint" gear="10"/> -->
    <motor name="button_head_lock_joint_actuator" joint="button_head_lock_joint" gear="0.5"/>
    <motor name="head_joint_actuator" joint="head_joint" gear="0.5"/>
    <motor name="knob_speed_joint_actuator" joint="knob_speed_joint" gear="0.5"/>
    <motor name="blender_joint_actuator" joint="blender_joint" gear="0.5"/>
  </actuator>
</mujoco>
