<?xml version='1.0' encoding='UTF-8'?>
<mujoco model="model">
  <option timestep="0.002" gravity="0.0 0.0 -9.81"/>
  <compiler angle="radian"/>
  <asset>
    <mesh file="visuals/button_lid.obj" name="button_lid_vis"/>
    <mesh file="visuals/Body001.obj" name="Body001_vis"/>
    <mesh file="visuals/kettle_main.obj" name="kettle_main_vis"/>
    <mesh file="visuals/lid.obj" name="lid_vis"/>
    <mesh file="visuals/switch.obj" name="switch_vis"/>
    <texture file="visuals/T_BC001.png" name="Body001_material" type="2d"/>
    <material name="Body001_material" rgba="1 1 1 1.0" texture="Body001_material" shininess="0.5" specular="0.3103448502657381"/>
    <texture file="visuals/T_BC001.png" name="kettle_main_material" type="2d"/>
    <material name="kettle_main_material" rgba="1 1 1 1.0" texture="kettle_main_material" shininess="0.5" specular="0.3103448502657381"/>
    <texture file="visuals/T_BC001.png" name="button_lid_material" type="2d"/>
    <material name="button_lid_material" rgba="1 1 1 1.0" texture="button_lid_material" shininess="0.5" specular="0.3103448502657381"/>
    <texture file="visuals/T_BC001.png" name="lid_material" type="2d"/>
    <material name="lid_material" rgba="1 1 1 1.0" texture="lid_material" shininess="0.5" specular="0.3103448502657381"/>
    <texture file="visuals/T_BC001.png" name="switch_material" type="2d"/>
    <material name="switch_material" rgba="1 1 1 1.0" texture="switch_material" shininess="0.5" specular="0.3103448502657381"/>
  </asset>
  <default>
    <default class="visual">
      <geom conaffinity="0" contype="0" group="1" type="mesh"/>
    </default>
    <default class="collision">
      <geom group="0" rgba="0.5 0 0 0.5" density="1.0" solref="0.004 1" solimp="0.998 0.998 0.001"/>
    </default>
    <default class="spawn">
      <geom group="0" rgba="1 1 1 0.5" contype="0" conaffinity="0"/>
      <site group="0" rgba="1 1 1 0.5"/>
    </default>
    <default class="region">
      <geom group="1" conaffinity="0" contype="0" rgba="0 1 0 0" mass="0"/>
    </default>
  </default>
  <worldbody>
    <body>
      <body name="object">
        <geom mesh="Body001_vis" type="mesh" solimp="0.998 0.998 0.001" solref="0.001 1" friction="0.95 0.3 0.1" class="visual" material="Body001_material"/>
        <geom type="cylinder" pos="-0.02806802 0.00056461 -0.12007976" size="0.08009783178567886 0.012889089994132519" quat="7.549790126404332e-08 0.0 0.0 -1.0" class="collision"/>
        <body name="kettle_main">
          <!-- <joint axis="0.0 0.0 1.0" pos="0.00023950 -0.00000000 -0.00056232" limited="true" name="kettle_main_joint" range="0.0 0.07" type="slide" damping="1" frictionloss="1" armature=".01" stiffness="0.05"/> -->
          <geom mesh="kettle_main_vis" type="mesh" solimp="0.998 0.998 0.001" solref="0.001 1" friction="0.95 0.3 0.1" class="visual" material="kettle_main_material"/>
          <geom type="box" pos="-0.03416502 -0.07529872 -0.00901757" size="0.021697411313652992 0.004031777381896973 0.0879552885890007" quat="1.0 0.0 0.0 0.0" class="collision"/>
          <geom type="box" pos="-0.07562212 -0.05982093 -0.00901757" size="0.02169741690158844 0.004031796008348465 0.08795532584190369" quat="0.27820244431495667 0.0 0.0 0.960522472858429" class="collision"/>
          <geom type="box" pos="-0.10826935 0.00907945 -0.00901757" size="0.02169741876423359 0.004031796474009752 0.08795532584190369" quat="0.6909513473510742 0.0 0.0 0.7229012846946716" class="collision"/>
          <geom type="box" pos="-0.05324413 0.07102929 -0.00901757" size="0.02169741876423359 0.004031796474009752 0.08795532584190369" quat="0.9823753237724304 0.0 0.0 0.1869191825389862" class="collision"/>
          <geom type="box" pos="-0.00651009 0.07358636 -0.00901757" size="0.023957490921020508 0.004048802424222231 0.08795532584190369" quat="0.995302677154541 0.0 0.0 -0.09681202471256256" class="collision"/>
          <geom type="box" pos="0.03587086 0.04644932 -0.00901757" size="0.024502277374267578 0.004031796474009752 0.08795532584190369" quat="0.8964644074440002 0.0 0.0 -0.4431157410144806" class="collision"/>
          <geom type="box" pos="0.00852330 -0.06614739 -0.01009050" size="0.02169741876423359 0.004031796474009752 0.08795532584190369" quat="0.2657346725463867 0.0 0.0 -0.9640461802482605" class="collision"/>
          <geom type="box" pos="0.04989149 -0.00384221 0.01219022" size="0.02169741876423359 0.004031796474009752 0.06674753874540329" quat="0.6941568851470947 0.0 0.0 -0.7198237776756287" class="collision"/>
          <geom type="box" pos="-0.02665413 -0.06483731 0.09016734" size="0.02169741876423359 0.004031796008348465 0.017500348389148712" quat="7.261022005877749e-08 2.0680648304960414e-08 -0.2739235460758209 -0.9617514610290527" class="collision"/>
          <geom type="box" pos="0.01612690 -0.04426841 0.09039219" size="0.02169741876423359 0.004031796008348465 0.017500348389148712" quat="0.40188682079315186 0.11446435004472733 -0.2488613873720169 -0.8737578988075256" class="collision"/>
          <geom type="box" pos="-0.01234312 0.06592190 0.09343173" size="0.02169741876423359 0.004031795542687178 0.01750035025179386" quat="0.9043024182319641 0.3939497172832489 -0.06188849359750748 -0.15235024690628052" class="collision"/>
          <geom type="box" pos="0.02560257 0.03980858 0.09003274" size="0.02169741876423359 0.004031796008348465 0.017500348389148712" quat="0.8161525726318359 0.32853493094444275 -0.15068449079990387 -0.45083698630332947" class="collision"/>
          <geom type="box" pos="-0.07596134 -0.05108020 0.09243228" size="0.022838424891233444 0.004243816249072552 0.016412906348705292" quat="0.3305305242538452 0.06446421146392822 0.21881256997585297 0.9158138632774353" class="collision"/>
          <geom class="collision" type="box" pos="0.10272706 0.00069039 0.03070326" size="0.02169955149292946 0.018044065684080124 0.05260666832327843" quat="0.702663242816925 0.030843505635857582 -0.026440011337399483 -0.710361897945404" name="handle_main"/>
          <geom class="collision" type="box" pos="0.06654883 -0.00025206 0.07596178" size="0.021699553355574608 0.019013550132513046 0.038298796862363815" quat="0.5390055775642395 0.45427554845809937 -0.4571070373058319 -0.5423650741577148" name="handle_1"/>
          <geom type="box" pos="-0.05516748 0.06021357 0.09372632" size="0.02169741876423359 0.004031796008348465 0.017500348389148712" quat="0.9309446811676025 0.23488211631774902 0.07750339061021805 0.26863667368888855" class="collision"/>
          <geom type="box" pos="-0.10232215 -0.02810671 -0.00901757" size="0.02169741876423359 0.004031796474009752 0.08795532584190369" quat="0.503608226776123 0.0 0.0 0.8639321327209473" class="collision"/>
          <geom type="box" pos="-0.08811775 0.04768248 -0.00901757" size="0.02169741876423359 0.004031796474009752 0.08795532584190369" quat="0.857904851436615 0.0 0.0 0.5138086080551147" class="collision"/>
          <geom type="box" pos="0.03387794 -0.04154588 -0.01009050" size="0.02169741876423359 0.004031796474009752 0.08795532584190369" quat="0.5237988233566284 0.0 0.0 -0.8518419861793518" class="collision"/>
          <geom type="box" pos="-0.08124342 0.04019463 0.09372632" size="0.012414224445819855 0.003891986794769764 0.017361877486109734" quat="0.8187540769577026 0.23250412940979004 0.09030118584632874 0.5171356797218323" class="collision"/>
          <geom type="box" pos="-0.09562566 -0.02647270 0.09578604" size="0.008230204693973064 0.002693294547498226 0.016519809141755104" quat="0.14230182766914368 -0.45794159173965454 -0.8355329632759094 0.26818719506263733" class="collision"/>
          <geom type="box" pos="-0.09331391 0.02496385 0.09468774" size="0.008230204693973064 0.0026932943146675825 0.016519811004400253" quat="0.189413383603096 -0.910895586013794 -0.26446810364723206 0.2538670003414154" class="collision"/>
          <geom type="box" pos="-0.08962586 0.00124632 0.10104365" size="0.008230205625295639 0.0026932943146675825 0.016519809141755104" quat="0.34048619866371155 0.3929964005947113 0.5911062955856323 -0.6166168451309204" class="collision"/>
          <geom type="cylinder" pos="-0.02806802 0.00056461 -0.10038736" size="0.08009783178567886 0.0038796693552285433" quat="7.549790126404332e-08 0.0 0.0 -1.0" class="collision"/>
          <geom type="box" pos="-0.05371566 -0.06544316 0.09288393" size="0.022838424891233444 0.004243816249072552 0.016412906348705292" quat="0.11664082109928131 0.013730018399655819 0.22769729793071747 0.9666231870651245" class="collision"/>
          <geom type="box" pos="-0.00340128 -0.06448478 0.09288393" size="0.022838419303297997 0.004243816249072552 0.016412906348705292" quat="0.23359708487987518 0.06787916272878647 -0.2177773118019104 -0.9451972842216492" class="collision"/>
          <geom type="box" pos="0.03014164 -0.03174051 0.09288393" size="0.022838423028588295 0.004243816249072552 0.016412906348705292" quat="0.47627586126327515 0.1232883408665657 -0.19192320108413696 -0.8491918444633484" class="collision"/>
          <geom type="box" pos="0.01297086 0.05810659 0.09288393" size="0.022838421165943146 0.004243816249072552 0.016412906348705292" quat="0.9285897612571716 0.22127045691013336 -0.055442988872528076 -0.2927226722240448" class="collision"/>
          <geom type="box" pos="-0.03794250 0.06988654 0.09288393" size="0.022838421165943146 0.004243816249072552 0.016412906348705292" quat="0.9689041972160339 0.2252521961927414 0.036000244319438934 0.09586469829082489" class="collision"/>
          <geom type="box" pos="-0.10442936 -0.01621043 0.08253402" size="0.022838424891233444 0.004243816249072552 0.01641290821135044" quat="0.02621924690902233 0.9493038058280945 -0.3063584268093109 -0.06541700661182404" class="collision"/>
          <geom type="box" pos="-0.10442936 0.01697658 0.08608630" size="0.022838424891233444 0.004243816249072552 0.016412906348705292" quat="0.9493038058280945 -0.026219135150313377 -0.06541696190834045 0.3063584268093109" class="collision"/>
          <body name="button_lid">
            <joint axis="0.0 0.0 -1.0" pos="0.06989294 -0.00000030 0.09650262" limited="true" name="button_lid_joint" range="0.0 0.004" type="slide" damping="1" frictionloss="1" armature=".01" stiffness="0.05" springref="-2"/>
            <geom mesh="button_lid_vis" type="mesh" solimp="0.998 0.998 0.001" solref="0.001 1" friction="0.95 0.3 0.1" class="visual" material="button_lid_material"/>
            <geom class="collision" type="box" pos="0.07185165 -0.00065097 0.10126077" size="0.007869250141084194 0.000941446574870497 0.018445638939738274" quat="0.5333261489868164 0.4616522490978241 -0.4673389196395874 -0.5329490900039673" name="button_lid_main"/>
          </body>
          <body name="lid">
            <joint axis="0.0 1.0 0.0" pos="0.02387301 -0.00000016 0.10970461" limited="true" name="lid_joint" range="0.0 1.5707963267948966" type="hinge" damping="1" frictionloss="0.1" armature=".01" stiffness="0.05" springref="-6"/>
            <geom mesh="lid_vis" type="mesh" solimp="0.998 0.998 0.001" solref="0.001 1" friction="0.95 0.3 0.1" class="visual" material="lid_material"/>
            <geom class="collision" type="cylinder" pos="-0.02806802 0.00056461 0.11270932" size="0.051645420491695404 0.0017763280775398016" quat="1.0 0.0 0.0 0.0" name="lid_main"/>
            <geom class="collision" type="cylinder" pos="-0.02806802 0.00056461 0.12130977" size="0.038984138518571854 0.0013408476952463388" quat="1.0 0.0 0.0 0.0" name="lid_1"/>
            <geom class="collision" type="cylinder" pos="-0.02806802 0.00056461 0.12706695" size="0.02984461933374405 0.0010264964075759053" quat="1.0 0.0 0.0 0.0" name="lid_2"/>
          </body>
          <body name="switch">
            <joint axis="0.0 0.0 -1.0" pos="0.06458240 -0.00068523 -0.06734439" limited="true" name="switch_joint" range="0.0 0.01" type="slide" damping="1" frictionloss="1" armature=".01" stiffness="0.05" springref="-2"/>
            <geom mesh="switch_vis" type="mesh" solimp="0.998 0.998 0.001" solref="0.001 1" friction="0.95 0.3 0.1" class="visual" material="switch_material"/>
            <geom class="collision" type="box" pos="0.06819979 -0.00038287 -0.06697415" size="0.02208857052028179 0.010510086081922054 0.0030917772091925144" quat="1.0 0.0 0.0 0.0" name="switch_main"/>
          </body>
        </body>
        <geom class="region" name="reg_main" type="box" pos="0.0002395000000000036 0.0 0.0" size="0.12201587 0.07886464 0.13327437"/>
      </body>
    </body>
  </worldbody>
  <actuator>
    <!-- <motor name="kettle_main_joint_actuator" joint="kettle_main_joint" gear="10"/> -->
    <motor name="button_lid_joint_actuator" joint="button_lid_joint" gear="0.5"/>
    <motor name="lid_joint_actuator" joint="lid_joint" gear="0.5"/>
    <motor name="switch_joint_actuator" joint="switch_joint" gear="0.5"/>
  </actuator>
</mujoco>
