<?xml version='1.0' encoding='UTF-8'?>
<mujoco model="model">
  <option timestep="0.002" gravity="0.0 0.0 -9.81"/>
  <compiler angle="radian"/>
  <asset>
    <mesh file="visuals/door.obj" name="door_vis"/>
    <mesh file="visuals/door_Clear.obj" name="door_Clear_vis"/>
    <mesh file="visuals/Body001.obj" name="Body001_vis"/>
    <mesh file="visuals/Button001.obj" name="Button001_vis"/>
    <mesh file="visuals/Button002.obj" name="Button002_vis"/>
    <mesh file="visuals/Disc001.obj" name="Disc001_vis"/>
    <mesh file="visuals/Knob001.obj" name="Knob001_vis"/>
    <texture file="visuals/T_BC001.png" name="Body001_material" type="2d"/>
    <material name="Body001_material" rgba="1 1 1 1.0" texture="Body001_material" shininess="0.5873101949691772" specular="2"/>
    <texture file="visuals/T_BC001.png" name="door_material" type="2d"/>
    <material name="door_material" rgba="1 1 1 1.0" texture="door_material" shininess="0.5873101949691772" specular="2"/>
    <material name="door_Clear_material" rgba="0.04224399849772453 0.04224399849772453 0.04224399849772453 0.8999999761581421" shininess="0.5" specular="1"/>
    <texture file="visuals/T_BC001.png" name="Button001_material" type="2d"/>
    <material name="Button001_material" rgba="1 1 1 1.0" texture="Button001_material" shininess="0.5873101949691772" specular="1"/>
    <texture file="visuals/T_BC001.png" name="Button002_material" type="2d"/>
    <material name="Button002_material" rgba="1 1 1 1.0" texture="Button002_material" shininess="0.5873101949691772" specular="1"/>
    <texture file="visuals/T_BC001.png" name="Disc001_material" type="2d"/>
    <material name="Disc001_material" rgba="1 1 1 1.0" texture="Disc001_material" shininess="0.5873101949691772" specular="3"/>
    <texture file="visuals/T_BC001.png" name="Knob001_material" type="2d"/>
    <material name="Knob001_material" rgba="1 1 1 1.0" texture="Knob001_material" shininess="0.5873101949691772" specular="1"/>
  </asset>
  <default>
    <default class="visual">
      <geom conaffinity="0" contype="0" group="1" type="mesh"/>
    </default>
    <default class="collision">
      <geom group="0" rgba="0.5 0 0 0.5"/>
    </default>
    <default class="spawn">
      <geom group="0" rgba="1 1 1 0.5" contype="0" conaffinity="0"/>
      <site group="0" rgba="1 1 1 0.5"/>
    </default>
    <default class="region">
      <geom group="1" conaffinity="0" contype="0" rgba="0 1 0 0"/>
    </default>
  </default>
  <worldbody>
    <body>
      <body name="object">
        <geom class="collision" type="cylinder" pos="-0.03615223 0.01071398 -0.13910060" size="0.10410761833190918 0.001198530662804842" quat="1.0 0.0 0.0 0.0" name="tray" rgba="0 1 0 0.5"/>
        <geom class="collision" type="box" pos="0.17483735 -0.16996883 -0.12013659" size="0.0088576078414917 0.0005799331120215356 0.005078091751784086" quat="1.0 0.0 0.0 0.0" name="start_button" rgba="0.0 0.5 0 0.5"/>
        <geom class="collision" type="box" pos="0.22248438 -0.16996883 -0.12013659" size="0.00885758362710476 0.0005799314822070301 0.005078091751784086" quat="1.0 0.0 0.0 0.0" name="stop_button" rgba="0.0 0.5 0 0.5"/>
        <geom mesh="Body001_vis" type="mesh" solimp="0.998 0.998 0.001" solref="0.001 1" friction="0.95 0.3 0.1" class="visual" material="Body001_material"/>
        <geom class="collision" type="box" pos="-0.24096069 0.00600094 0.00000028" size="0.011550054885447025 0.16924265027046204 0.16243954002857208" quat="1.0 0.0 0.0 0.0"/>
        <geom class="collision" type="box" pos="0.20031831 0.00871939 0.00000028" size="0.052180953323841095 0.16924265027046204 0.1624395102262497" quat="1.0 0.0 0.0 0.0"/>
        <geom class="collision" type="box" pos="-0.04141608 0.01124469 -0.15360054" size="0.19762252271175385 0.16671735048294067 0.008838735520839691" quat="1.0 0.0 0.0 0.0"/>
        <geom class="collision" type="box" pos="-0.04141608 0.00871939 0.15704207" size="0.19763053953647614 0.1692495048046112 0.005398265086114407" quat="1.0 0.0 0.0 0.0"/>
        <geom class="collision" type="box" pos="-0.05820107 0.18411710 -0.00325730" size="0.13412368297576904 0.013733087107539177 0.10394680500030518" quat="1.0 0.0 0.0 0.0"/>
        <geom class="collision" type="box" pos="-0.05186822 0.17463176 0.00000049" size="0.20064249634742737 0.0033645974472165108 0.16243976354599" quat="1.0 0.0 0.0 0.0"/>
        <body name="door">
          <joint axis="0.0 0.0 1.0" pos="-0.24267742 -0.16072838 -0.00065811" limited="true" name="microjoint" range="-1.5707963267948966 0.0" type="hinge" damping="1" frictionloss="1" armature=".01" stiffness="0.05"/>
          <geom mesh="door_vis" type="mesh" solimp="0.998 0.998 0.001" solref="0.001 1" friction="0.95 0.3 0.1" class="visual" material="door_material"/>
          <geom class="collision" type="box" pos="-0.04121793 -0.16428117 0.00104381" size="0.17912612855434418 0.0020712907426059246 0.14390848577022552" quat="1.0 0.0 0.0 0.0" name="door_main"/>
          <geom class="collision" type="box" pos="-0.04019934 -0.15466472 -0.00148154" size="0.1582401692867279 0.0020251176320016384 0.11149369180202484" quat="1.0 0.0 0.0 0.0"/>
          <geom class="collision" type="box" pos="0.13513076 -0.19472898 -0.00321870" size="0.012677142396569252 0.0042665922082960606 0.104315847158432" quat="1.0 0.0 0.0 0.0" name="door_handle_main"/>
          <geom class="collision" type="box" pos="0.13513076 -0.17821397 0.12440506" size="0.012677142396569252 0.00585625134408474 0.023739872500300407" quat="0.9399288296699524 -0.34137049317359924 2.8638572721555794e-18 1.0850559262752357e-18"/>
          <geom class="collision" type="box" pos="0.13488576 -0.17768816 -0.12730666" size="0.012432144954800606 0.004518064204603434 0.023084383457899094" quat="0.941739022731781 0.33634448051452637 4.691098418104605e-18 -1.796101931789467e-18"/>
          <body name="door_Clear">
            <geom mesh="door_Clear_vis" type="mesh" solimp="0.998 0.998 0.001" solref="0.001 1" friction="0.95 0.3 0.1" class="visual" material="door_Clear_material"/>
            <geom class="collision" type="box" pos="-0.04019934 -0.15466472 -0.00148154" size="0.1582401692867279 0.0020251176320016384 0.11149369180202484" quat="1.0 0.0 0.0 0.0"/>
          </body>
        </body>
        <body name="Button001">
          <joint axis="0.0 1.0 0.0" pos="0.17493886 -0.16539864 -0.12007669" limited="true" name="Button001_joint" range="0.0 0.003" type="slide" damping="1" frictionloss="1" armature=".01" stiffness="0.05"/>
          <geom mesh="Button001_vis" type="mesh" solimp="0.998 0.998 0.001" solref="0.001 1" friction="0.95 0.3 0.1" class="visual" material="Button001_material"/>
          <geom class="collision" type="box" pos="0.17483735 -0.16632901 -0.12013659" size="0.008857536129653454 0.002287296811118722 0.005078091751784086" quat="1.0 0.0 0.0 0.0"/>
        </body>
        <body name="Button002">
          <joint axis="0.0 1.0 0.0" pos="0.22241950 -0.16539864 -0.12007669" limited="true" name="Button002_joint" range="0.0 0.003" type="slide" damping="1" frictionloss="1" armature=".01" stiffness="0.05"/>
          <geom mesh="Button002_vis" type="mesh" solimp="0.998 0.998 0.001" solref="0.001 1" friction="0.95 0.3 0.1" class="visual" material="Button002_material"/>
          <geom class="collision" type="box" pos="0.22248438 -0.16632901 -0.12013659" size="0.008857560344040394 0.0022873012349009514 0.005078091751784086" quat="1.0 0.0 0.0 0.0"/>
        </body>
        <body name="Disc001">
          <joint axis="0.0 0.0 1.0" pos="-0.03615224 0.01071397 -0.14126298" limited="false" name="Disc001_joint" range="0 360" type="hinge" damping="1" frictionloss="1" armature=".01" stiffness="0.05"/>
          <geom mesh="Disc001_vis" type="mesh" solimp="0.998 0.998 0.001" solref="0.001 1" friction="0.95 0.3 0.1" class="visual" material="Disc001_material"/>
          <geom class="collision" type="cylinder" pos="-0.03615223 0.01071398 -0.14256822" size="0.10410761833190918 0.0018565341597422957" quat="1.0 0.0 0.0 0.0"/>
        </body>
        <body name="Knob001">
          <joint axis="0.0 1.0 0.0" pos="0.19801226 -0.17630480 -0.07596762" limited="true" name="Knob001_joint" range="0.0 3.9269908169872414" type="hinge" damping="0.05" armature="0.001"/>
          <geom mesh="Knob001_vis" type="mesh" solimp="0.998 0.998 0.001" solref="0.001 1" friction="0.95 0.3 0.1" class="visual" material="Knob001_material"/>
          <geom class="collision" type="cylinder" pos="0.19794825 -0.16970752 -0.07587153" size="0.01971447467803955 0.004739411640912294" quat="0.7071067094802856 0.70710688829422 0.0 0.0"/>
          <geom class="collision" type="box" pos="0.19794226 -0.17970584 -0.07618757" size="0.004080881364643574 0.008663568645715714 0.014815111644566059" quat="1.0 0.0 0.0 0.0"/>
        </body>
        <geom class="region" name="reg_int" type="box" pos="-0.040662155000000005 0.001241954999999989 0.003931174999999995" size="0.188276795 0.166753705 0.142833225"/>
        <geom class="region" name="reg_main" type="box" pos="0.0 0.01547549999999999 0.0" size="0.25350208 0.18337489 0.16343984"/>
      </body>
    </body>
  </worldbody>
  <actuator>
    <motor name="microjoint_actuator" joint="microjoint" gear="10"/>
    <motor name="Button001_joint_actuator" joint="Button001_joint" gear="0.5"/>
    <motor name="Button002_joint_actuator" joint="Button002_joint" gear="0.5"/>
    <motor name="Disc001_joint_actuator" joint="Disc001_joint" gear="20"/>
    <motor name="Knob001_joint_actuator" joint="Knob001_joint" gear="10"/>
  </actuator>
</mujoco>
