<?xml version='1.0' encoding='UTF-8'?>
<mujoco model="model">
  <option timestep="0.002" gravity="0.0 0.0 -9.81"/>
  <compiler angle="radian"/>
  <asset>
    <mesh file="visuals/door.obj" name="door_vis"/>
    <mesh file="visuals/door_Clear.obj" name="door_Clear_vis"/>
    <mesh file="visuals/Body001.obj" name="Body001_vis"/>
    <mesh file="visuals/Button001.obj" name="Button001_vis"/>
    <mesh file="visuals/Button002.obj" name="Button002_vis"/>
    <mesh file="visuals/Button003.obj" name="Button003_vis"/>
    <mesh file="visuals/Button004.obj" name="Button004_vis"/>
    <mesh file="visuals/Button005.obj" name="Button005_vis"/>
    <mesh file="visuals/Button006.obj" name="Button006_vis"/>
    <mesh file="visuals/Disc001.obj" name="Disc001_vis"/>
    <mesh file="visuals/Knob001.obj" name="Knob001_vis"/>
    <texture file="visuals/T_BC001.png" name="Body001_material" type="2d"/>
    <material name="Body001_material" rgba="1 1 1 1.0" texture="Body001_material" shininess="0.2512328028678894" specular="0.5"/>
    <texture file="visuals/T_BC001.png" name="door_material" type="2d"/>
    <material name="door_material" rgba="1 1 1 1.0" texture="door_material" shininess="0.2512328028678894" specular="0.5"/>
    <texture file="visuals/T_BC001.png" name="door_Clear_material" type="2d"/>
    <material name="door_Clear_material" rgba="1 1 1 0.699999988079071" texture="door_Clear_material" shininess="0.4472135901451111" specular="0.3103448502657381"/>
    <texture file="visuals/T_BC001.png" name="Button001_material" type="2d"/>
    <material name="Button001_material" rgba="1 1 1 1.0" texture="Button001_material" shininess="0.2512328028678894" specular="0.3103448502657381"/>
    <texture file="visuals/T_BC001.png" name="Button002_material" type="2d"/>
    <material name="Button002_material" rgba="1 1 1 1.0" texture="Button002_material" shininess="0.2512328028678894" specular="0.3103448502657381"/>
    <texture file="visuals/T_BC001.png" name="Button003_material" type="2d"/>
    <material name="Button003_material" rgba="1 1 1 1.0" texture="Button003_material" shininess="0.2512328028678894" specular="0.3103448502657381"/>
    <texture file="visuals/T_BC001.png" name="Button004_material" type="2d"/>
    <material name="Button004_material" rgba="1 1 1 1.0" texture="Button004_material" shininess="0.2512328028678894" specular="0.3103448502657381"/>
    <texture file="visuals/T_BC001.png" name="Button005_material" type="2d"/>
    <material name="Button005_material" rgba="1 1 1 1.0" texture="Button005_material" shininess="0.2512328028678894" specular="0.3103448502657381"/>
    <texture file="visuals/T_BC001.png" name="Button006_material" type="2d"/>
    <material name="Button006_material" rgba="1 1 1 1.0" texture="Button006_material" shininess="0.2512328028678894" specular="0.3103448502657381"/>
    <texture file="visuals/T_BC001.png" name="Disc001_material" type="2d"/>
    <material name="Disc001_material" rgba="1 1 1 1.0" texture="Disc001_material" shininess="0.2512328028678894" specular="0.3103448502657381"/>
    <texture file="visuals/T_BC001.png" name="Knob001_material" type="2d"/>
    <material name="Knob001_material" rgba="1 1 1 1.0" texture="Knob001_material" shininess="0.2512328028678894" specular="0.3103448502657381"/>
  </asset>
  <default>
    <default class="visual">
      <geom conaffinity="0" contype="0" group="1" type="mesh"/>
    </default>
    <default class="collision">
      <geom group="0" rgba="0.5 0 0 0.5"/>
    </default>
    <default class="spawn">
      <geom group="0" rgba="1 1 1 0.5" contype="0" conaffinity="0"/>
      <site group="0" rgba="1 1 1 0.5"/>
    </default>
    <default class="region">
      <geom group="1" conaffinity="0" contype="0" rgba="0 1 0 0"/>
    </default>
  </default>
  <worldbody>
    <body>
      <body name="object">
        <geom class="collision" type="cylinder" pos="-0.049486346542835236 0.028427844867110252 -0.12795056402683258" size="0.12629246711730957 0.0015484322793781757" quat="1.0 0.0 0.0 0.0" name="tray" rgba="0 1 0 0.5"/>
        <geom class="collision" type="box" pos="0.21474409103393555 -0.147808238863945 -0.08271971344947815" size="0.011546311900019646 0.0002732244902290404 0.007355997804552317" quat="1.0 0.0 0.0 0.0" name="stop_button" rgba="0.0 0.5 0 0.5"/>
        <geom class="collision" type="box" pos="0.1598050445318222 -0.14758211374282837 -0.08281735330820084" size="0.011595126241445541 0.0002732244902290404 0.00716072553768754" quat="1.0 0.0 0.0 0.0" name="start_button" rgba="0.0 0.5 0 0.5"/>
        <geom mesh="Body001_vis" type="mesh" solimp="0.998 0.998 0.001" solref="0.001 1" friction="0.95 0.3 0.1" class="visual" material="Body001_material"/>
        <geom class="collision" type="box" pos="-0.0706014633178711 0.02172013930976391 0.1348339319229126" size="0.17388677597045898 0.16072344779968262 0.0026097458321601152" quat="1.0 0.0 0.0 0.0"/>
        <geom class="collision" type="box" pos="-0.0706014633178711 0.02172013930976391 -0.13550342619419098" size="0.1738876849412918 0.16072434186935425 0.0019576263148337603" quat="1.0 0.0 0.0 0.0"/>
        <geom class="collision" type="box" pos="-0.22876307368278503 0.02172013930976391 -0.0011795125901699066" size="0.015735313296318054 0.16072483360767365 0.136280819773674" quat="1.0 0.0 0.0 0.0"/>
        <geom class="collision" type="box" pos="0.17131167650222778 0.022142408415675163 -5.678956767951604e-06" size="0.07318626344203949 0.1603030562400818 0.13745558261871338" quat="1.0 0.0 0.0 0.0"/>
        <geom class="collision" type="box" pos="-0.07174018025398254 0.17736266553401947 -0.0003470086958259344" size="0.17275722324848175 0.009522153995931149 0.13711294531822205" quat="1.0 0.0 0.0 0.0"/>
        <body name="door">
          <joint axis="0.0 0.0 1.0" pos="-0.22993920743465424 -0.14336863160133362 0.0006045997142791748" limited="true" name="microjoint" range="-1.5707963267948966 0.0" type="hinge" damping="1" frictionloss="1" armature=".01" stiffness="0.05"/>
          <geom mesh="door_vis" type="mesh" solimp="0.998 0.998 0.001" solref="0.001 1" friction="0.95 0.3 0.1" class="visual" material="door_material"/>
          <geom class="collision" type="box" pos="-0.04696047678589821 -0.14351913332939148 -1.321511808782816e-05" size="0.18577438592910767 0.002649904228746891 0.12520691752433777" quat="1.0 0.0 0.0 0.0"/>
          <geom class="collision" type="box" pos="0.12413503229618073 -0.1617792397737503 0.09582488238811493" size="0.01756284013390541 0.01146131381392479 0.023672543466091156" quat="0.9437553882598877 -0.3306444585323334 -0.0 0.0"/>
          <geom class="collision" type="box" pos="0.12413503229618073 -0.16497746109962463 -0.08885825425386429" size="0.01756284013390541 0.011082478798925877 0.02001846395432949" quat="0.9395060539245605 0.34253230690956116 0.0 0.0"/>
          <geom class="collision" type="box" pos="-0.044185325503349304 -0.14467108249664307 0.0011875256896018982" size="0.18271194398403168 0.001327464240603149 0.12164296209812164" quat="1.0 0.0 0.0 0.0" name="door_main"/>
          <geom class="collision" type="box" pos="-0.04811477288603783 -0.14364230632781982 -0.0012340329121798277" size="0.14932376146316528 0.002033068798482418 0.09587067365646362" quat="1.0 0.0 0.0 0.0"/>
          <geom class="collision" type="box" pos="0.12286815047264099 -0.17551285028457642 0.0013099480420351028" size="0.0158797949552536 0.011475786566734314 0.06650149822235107" quat="1.0 0.0 0.0 0.0" name="door_handle_main"/>
          <body name="door_Clear">
            <geom mesh="door_Clear_vis" type="mesh" solimp="0.998 0.998 0.001" solref="0.001 1" friction="0.95 0.3 0.1" class="visual" material="door_Clear_material"/>
            <geom class="collision" type="box" pos="-0.04811477288603783 -0.14364230632781982 -0.0012340329121798277" size="0.14932376146316528 0.002033068798482418 0.09587067365646362" quat="1.0 0.0 0.0 0.0"/>
          </body>
        </body>
        <body name="Button001">
          <joint axis="0.0 1.0 0.0" pos="0.15971553325653076 -0.14632542431354523 0.06611817330121994" limited="true" name="Button001_joint" range="0.0 0.0008" type="slide" damping="1" frictionloss="1" armature=".01" stiffness="0.05"/>
          <geom mesh="Button001_vis" type="mesh" solimp="0.998 0.998 0.001" solref="0.001 1" friction="0.95 0.3 0.1" class="visual" material="Button001_material"/>
          <geom class="collision" type="box" pos="0.15974293649196625 -0.1470450609922409 0.06624475866556168" size="0.011595126241445541 0.0008283754577860236 0.007098611444234848" quat="1.0 0.0 0.0 0.0"/>
        </body>
        <body name="Button002">
          <joint axis="0.0 1.0 0.0" pos="0.21473239362239838 -0.14632542431354523 0.06611817330121994" limited="true" name="Button002_joint" range="0.0 0.0008" type="slide" damping="1" frictionloss="1" armature=".01" stiffness="0.05"/>
          <geom mesh="Button002_vis" type="mesh" solimp="0.998 0.998 0.001" solref="0.001 1" friction="0.95 0.3 0.1" class="visual" material="Button002_material"/>
          <geom class="collision" type="box" pos="0.21481089293956757 -0.1470450609922409 0.06624475866556168" size="0.011595126241445541 0.0008283754577860236 0.00709866126999259" quat="1.0 0.0 0.0 0.0"/>
        </body>
        <body name="Button003">
          <joint axis="0.0 1.0 0.0" pos="0.21473239362239838 -0.14632542431354523 0.01943928375840187" limited="true" name="Button003_joint" range="0.0 0.0008" type="slide" damping="1" frictionloss="1" armature=".01" stiffness="0.05"/>
          <geom mesh="Button003_vis" type="mesh" solimp="0.998 0.998 0.001" solref="0.001 1" friction="0.95 0.3 0.1" class="visual" material="Button003_material"/>
          <geom class="collision" type="box" pos="0.21481089293956757 -0.1470450609922409 0.019612744450569153" size="0.011595126241445541 0.0008283754577860236 0.007098672911524773" quat="1.0 0.0 0.0 0.0"/>
        </body>
        <body name="Button004">
          <joint axis="0.0 1.0 0.0" pos="0.15971553325653076 -0.14632542431354523 0.01943928375840187" limited="true" name="Button004_joint" range="0.0 0.0008" type="slide" damping="1" frictionloss="1" armature=".01" stiffness="0.05"/>
          <geom mesh="Button004_vis" type="mesh" solimp="0.998 0.998 0.001" solref="0.001 1" friction="0.95 0.3 0.1" class="visual" material="Button004_material"/>
          <geom class="collision" type="box" pos="0.15974293649196625 -0.1470450609922409 0.019612744450569153" size="0.011595126241445541 0.0008283754577860236 0.007098684553056955" quat="1.0 0.0 0.0 0.0"/>
        </body>
        <body name="Button005">
          <joint axis="0.0 1.0 0.0" pos="0.15971553325653076 -0.14632542431354523 -0.08277631551027298" limited="true" name="Button005_joint" range="0.0 0.0008" type="slide" damping="1" frictionloss="1" armature=".01" stiffness="0.05"/>
          <geom mesh="Button005_vis" type="mesh" solimp="0.998 0.998 0.001" solref="0.001 1" friction="0.95 0.3 0.1" class="visual" material="Button005_material"/>
          <geom class="collision" type="box" pos="0.15974293649196625 -0.14668536186218262 -0.08270964026451111" size="0.011595126241445541 0.00046866884804330766 0.007098696194589138" quat="1.0 0.0 0.0 0.0"/>
        </body>
        <body name="Button006">
          <joint axis="0.0 1.0 0.0" pos="0.21473239362239838 -0.14632542431354523 -0.08277631551027298" limited="true" name="Button006_joint" range="0.0 0.0008" type="slide" damping="1" frictionloss="1" armature=".01" stiffness="0.05"/>
          <geom mesh="Button006_vis" type="mesh" solimp="0.998 0.998 0.001" solref="0.001 1" friction="0.95 0.3 0.1" class="visual" material="Button006_material"/>
          <geom class="collision" type="box" pos="0.21481089293956757 -0.14682964980602264 -0.08270964026451111" size="0.011595126241445541 0.0006129642715677619 0.007098707836121321" quat="1.0 0.0 0.0 0.0"/>
        </body>
        <body name="Disc001">
          <joint axis="0.0 0.0 1.0" pos="-0.04954634606838226 0.028565524145960808 -0.1278267502784729" limited="false" name="Disc001_joint" range="0 360" type="hinge" damping="1" frictionloss="1" armature=".01" stiffness="0.05"/>
          <geom mesh="Disc001_vis" type="mesh" solimp="0.998 0.998 0.001" solref="0.001 1" friction="0.95 0.3 0.1" class="visual" material="Disc001_material"/>
          <geom class="collision" type="cylinder" pos="-0.049486350268125534 0.028427844867110252 -0.13212239742279053" size="0.12629246711730957 0.0010014482541009784" quat="1.0 0.0 0.0 0.0"/>
        </body>
        <body name="Knob001">
          <joint axis="0.0 1.0 0.0" pos="0.18581019341945648 -0.15612822771072388 -0.03401125967502594" limited="true" name="Knob001_joint" range="0.0 4.729842272904633" type="hinge" damping="0.05" frictionloss="0.75" armature="0.5"/>
          <geom mesh="Knob001_vis" type="mesh" solimp="0.998 0.998 0.001" solref="0.001 1" friction="0.95 0.3 0.1" class="visual" material="Knob001_material"/>
          <geom class="collision" type="cylinder" pos="0.18582980334758759 -0.15132565796375275 -0.033968519419431686" size="0.022396370768547058 0.0027872722130268812" quat="0.7071067094802856 0.7071068286895752 0.0 0.0" friction="100 0.5 0.01"/>
          <geom class="collision" type="box" pos="0.18571440875530243 -0.16174644231796265 -0.03421032801270485" size="0.017466221004724503 0.007978677749633789 0.004965361673384905" quat="0.9238795042037964 -5.010813134862999e-15 -0.3826834559440613 -5.1416904511825123e-08" friction="100 0.5 0.01"/>
        </body>
        <geom class="region" name="reg_int" type="box" pos="-0.05705341696739197 0.027918532490730286 0.0001684054732322693" size="0.14999924397468567 0.1339173445701599 0.12757054513692856"/>
        <geom class="region" name="reg_main" type="box" pos="3.725290298461914e-09 0.020357578992843628 -7.450580596923828e-09" size="0.24550001120567322 0.16752783751487732 0.13848079538345337"/>
      <geom class="region" name="reg_tray" type="cylinder" pos="-0.049486346542835236 0.028427844867110252 0.0006684094313532118" size="0.12629246711730957 0.12607054117880762"/></body>
    </body>
  </worldbody>
  <actuator>
    <motor name="microjoint_actuator" joint="microjoint" gear="5"/>
    <motor name="Button001_joint_actuator" joint="Button001_joint" gear="0.1"/>
    <motor name="Button002_joint_actuator" joint="Button002_joint" gear="0.1"/>
    <motor name="Button003_joint_actuator" joint="Button003_joint" gear="0.1"/>
    <motor name="Button004_joint_actuator" joint="Button004_joint" gear="0.1"/>
    <motor name="Button005_joint_actuator" joint="Button005_joint" gear="0.1"/>
    <motor name="Button006_joint_actuator" joint="Button006_joint" gear="0.1"/>
    <motor name="Disc001_joint_actuator" joint="Disc001_joint" gear="10"/>
    <motor name="Knob001_joint_actuator" joint="Knob001_joint" gear="10"/>
  </actuator>
</mujoco>