<?xml version='1.0' encoding='UTF-8'?>
<mujoco model="model">
  <option timestep="0.002" gravity="0.0 0.0 -9.81"/>
  <compiler angle="radian"/>
  <asset>
    <mesh file="visuals/door.obj" name="door_vis"/>
    <mesh file="visuals/door_Clear.obj" name="door_Clear_vis"/>
    <mesh file="visuals/Body001.obj" name="Body001_vis"/>
    <mesh file="visuals/Disc001.obj" name="Disc001_vis"/>
    <texture file="visuals/T_BC001.png" name="Body001_material" type="2d"/>
    <material name="Body001_material" rgba="1 1 1 1.0" texture="Body001_material" shininess="3" specular="3"/>
    <texture file="visuals/T_BC001.png" name="door_material" type="2d"/>
    <material name="door_material" rgba="1 1 1 1.0" texture="door_material" shininess="3" specular="3"/>
    <material name="door_Clear_material" rgba="0.021756866946816444 0.021756866946816444 0.021756866946816444 0.75" shininess="0.5" specular="0.3103448502657381"/>
    <texture file="visuals/T_BC001.png" name="Disc001_material" type="2d"/>
    <material name="Disc001_material" rgba="1 1 1 1.0" texture="Disc001_material" shininess="0.5" specular="0.5"/>
  </asset>
  <default>
    <default class="visual">
      <geom conaffinity="0" contype="0" group="1" type="mesh"/>
    </default>
    <default class="collision">
      <geom group="0" rgba="0.5 0 0 0.5"/>
    </default>
    <default class="spawn">
      <geom group="0" rgba="1 1 1 0.5" contype="0" conaffinity="0"/>
      <site group="0" rgba="1 1 1 0.5"/>
    </default>
    <default class="region">
      <geom group="1" conaffinity="0" contype="0" rgba="0 1 0 0"/>
    </default>
  </default>
  <worldbody>
    <body>
      <body name="object">
        <geom class="collision" type="cylinder" pos="-0.03252720460295677 0.028008436784148216 -0.08517086505889893" size="0.08457642048597336 0.0012236254988238215" quat="1.0 0.0 0.0 0.0" name="tray" rgba="0 1 0 0.5"/>
        <geom class="collision" type="box" pos="0.16574476659297943 -0.1161891296505928 -0.05596323683857918" size="0.005486878100782633 0.0002612489624880254 0.004539588000625372" quat="1.0 0.0 0.0 0.0" name="stop_button" rgba="0.0 0.5 0 0.5"/>
        <geom class="collision" type="box" pos="0.19805380702018738 -0.11618360131978989 -0.05596323683857918" size="0.005571725312620401 0.0002571198856458068 0.00453959172591567" quat="1.0 0.0 0.0 0.0" name="start_button" rgba="0.0 0.5 0 0.5"/>
        <geom mesh="Body001_vis" type="mesh" solimp="0.998 0.998 0.001" solref="0.001 1" friction="0.95 0.3 0.1" class="visual" material="Body001_material"/>
        <geom class="collision" type="box" pos="-0.2184000015258789 0.031143836677074432 0.004777388647198677" size="0.008999974466860294 0.11223482340574265 0.12207884341478348" quat="1.0 0.0 0.0 0.0"/>
        <geom class="collision" type="box" pos="0.18787844479084015 0.01379941776394844 0.002333524404093623" size="0.03952150046825409 0.12958019971847534 0.12482412159442902" quat="1.0 0.0 0.0 0.0"/>
        <geom class="collision" type="box" pos="-0.03283274546265602 0.031143836677074432 0.11815764009952545" size="0.1839221566915512 0.11223499476909637 0.009000064805150032" quat="1.0 0.0 0.0 0.0"/>
        <geom class="collision" type="box" pos="-0.011722411960363388 0.031143836677074432 -0.11132598668336868" size="0.21567757427692413 0.11223503202199936 0.011610017158091068" quat="1.0 0.0 0.0 0.0"/>
        <geom class="collision" type="box" pos="-2.3164830054156482e-08 0.13221074640750885 0.003772694617509842" size="0.22739997506141663 0.011731338687241077 0.12200931459665298" quat="1.0 0.0 0.0 0.0"/>
        <body name="door">
          <joint axis="0.0 0.0 1.0" pos="-0.21203888952732086 -0.10168059170246124 0.004637617617845535" limited="true" name="microjoint" range="-1.5707963267948966 0.0" type="hinge" damping="1" frictionloss="1" armature=".01" stiffness="0.05"/>
          <geom mesh="door_vis" type="mesh" solimp="0.998 0.998 0.001" solref="0.001 1" friction="0.95 0.3 0.1" class="visual" material="door_material"/>
          <geom class="collision" type="box" pos="-0.03472866117954254 -0.10163944214582443 0.10286539047956467" size="0.18202747404575348 0.014235204085707664 0.02429230883717537" quat="1.0 0.0 0.0 0.0"/>
          <geom class="collision" type="box" pos="-0.03461878001689911 -0.10163944214582443 -0.09539831429719925" size="0.18213744461536407 0.014235207810997963 0.02170415222644806" quat="1.0 0.0 0.0 0.0"/>
          <geom class="collision" type="box" pos="-0.21376827359199524 -0.10163944214582443 0.012764652259647846" size="0.0059144748374819756 0.014235207810997963 0.11439303308725357" quat="1.0 0.0 0.0 0.0"/>
          <geom class="collision" type="box" pos="0.13258644938468933 -0.12506189942359924 0.06973672658205032" size="0.024160463362932205 0.009169811382889748 0.010521062649786472" quat="0.701056957244873 -0.09229596704244614 0.7010577917098999 -0.09229596704244614"/>
          <geom class="collision" type="box" pos="0.13258643448352814 -0.12531375885009766 -0.06104700639843941" size="0.02386256866157055 0.009169811382889748 0.010521062649786472" quat="0.701056957244873 0.09229596704244614 0.7010577917098999 0.09229596704244614"/>
          <geom class="collision" type="box" pos="0.13258644938468933 -0.13492941856384277 0.004807871766388416" size="0.010521060787141323 0.009169810451567173 0.03764721006155014" quat="1.0 0.0 0.0 0.0" name="door_handle_main"/>
          <geom class="collision" type="box" pos="-0.03623191639780998 -0.11003592610359192 0.003190736286342144" size="0.17416460812091827 0.0014627669006586075 0.08131732791662216" quat="7.549790126404332e-08 0.0 1.0 0.0"/>
          <geom class="collision" type="box" pos="-0.03623191639780998 -0.1139059066772461 0.005659903399646282" size="0.1816636025905609 0.0014627669006586075 0.12093916535377502" quat="7.549790126404332e-08 0.0 1.0 0.0" name="door_main"/>
          <body name="door_Clear">
            <geom mesh="door_Clear_vis" type="mesh" solimp="0.998 0.998 0.001" solref="0.001 1" friction="0.95 0.3 0.1" class="visual" material="door_Clear_material"/>
            <geom class="collision" type="box" pos="-0.03623191639780998 -0.11003592610359192 0.003190736286342144" size="0.17416460812091827 0.0014627669006586075 0.08131732791662216" quat="7.549790126404332e-08 0.0 1.0 0.0"/>
          </body>
        </body>
        <body name="Disc001">
          <joint axis="0.0 0.0 1.0" pos="-0.03252920135855675 0.028009196743369102 -0.09306520223617554" limited="false" name="Disc001_joint" range="0 360" type="hinge" damping="1" frictionloss="1" armature=".01" stiffness="0.05"/>
          <geom mesh="Disc001_vis" type="mesh" solimp="0.998 0.998 0.001" solref="0.001 1" friction="0.95 0.3 0.1" class="visual" material="Disc001_material"/>
          <geom class="collision" type="cylinder" pos="-0.03252720460295677 0.028008436784148216 -0.09201093763113022" size="0.08471949398517609 0.0032539304811507463" quat="1.0 0.0 0.0 0.0"/>
        </body>
        <geom class="region" name="reg_int" type="box" pos="-0.030537880957126617 0.01731541007757187 0.004643484950065613" size="0.17453978008031845 0.0986509228348732 0.09996167367696762"/>
        <geom class="region" name="reg_main" type="box" pos="0.0 0.014033660292625427 0.0" size="0.22929991579055786 0.13090833818912506 0.12815768814086914"/>
      </body>
    </body>
  </worldbody>
  <actuator>
    <motor name="microjoint_actuator" joint="microjoint" gear="10"/>
    <motor name="Disc001_joint_actuator" joint="Disc001_joint" gear="10"/>
  </actuator>
</mujoco>
