<?xml version='1.0' encoding='UTF-8'?>
<mujoco model="model">
  <option timestep="0.002" gravity="0.0 0.0 -9.81"/>
  <compiler angle="radian"/>
  <asset>
    <mesh file="visuals/handle.obj" name="handle_vis"/>
    <mesh file="visuals/Body001.obj" name="Body001_vis"/>
    <mesh file="visuals/Funnel001.obj" name="Funnel001_vis"/>
    <mesh file="visuals/Funnel002.obj" name="Funnel002_vis"/>
    <mesh file="visuals/Shelf001.obj" name="Shelf001_vis"/>
    <mesh file="visuals/spout.obj" name="spout_vis"/>
    <texture file="visuals/T_BC001.png" name="Body001_material" type="2d"/>
    <material name="Body001_material" rgba="1 1 1 1.0" texture="Body001_material" shininess="0.1" specular="6"/>
    <texture file="visuals/T_BC001.png" name="handle_material" type="2d"/>
    <material name="handle_material" rgba="1 1 1 1.0" texture="handle_material" shininess="0.1" specular="6"/>
    <texture file="visuals/T_BC001.png" name="Funnel001_material" type="2d"/>
    <material name="Funnel001_material" rgba="1 1 1 1.0" texture="Funnel001_material" shininess="0.1" specular="6"/>
    <texture file="visuals/T_BC001.png" name="Funnel002_material" type="2d"/>
    <material name="Funnel002_material" rgba="1 1 1 1.0" texture="Funnel002_material" shininess="0.1" specular="6"/>
    <texture file="visuals/T_BC001.png" name="Shelf001_material" type="2d"/>
    <material name="Shelf001_material" rgba="1 1 1 1.0" texture="Shelf001_material" shininess="0.1" specular="6"/>
    <texture file="visuals/T_BC001.png" name="spout_material" type="2d"/>
    <material name="spout_material" rgba="1 1 1 1.0" texture="spout_material" shininess="0.1" specular="6"/>
  </asset>
  <default>
    <default class="visual">
      <geom conaffinity="0" contype="0" group="1" type="mesh"/>
    </default>
    <default class="collision">
      <geom group="0" rgba="0.5 0 0 0.5"/>
    </default>
    <default class="spawn">
      <geom group="0" rgba="1 1 1 0.5" contype="0" conaffinity="0"/>
      <site group="0" rgba="1 1 1 0.5"/>
    </default>
    <default class="region">
      <geom group="1" conaffinity="0" contype="0" rgba="0 1 0 0"/>
    </default>
  </default>
  <worldbody>
    <body>
      <body name="object">
        <geom mesh="Body001_vis" type="mesh" solimp="0.998 0.998 0.001" solref="0.001 1" friction="0.95 0.3 0.1" class="visual" material="Body001_material"/>
        <geom class="collision" type="box" pos="-0.00000001 0.21959068 -0.09269838" size="0.4343355894088745 0.04159194231033325 0.0019503089133650064" quat="1.0 0.0 0.0 0.0"/>
        <geom class="collision" type="box" pos="-0.00000003 -0.24408982 -0.09269834" size="0.43433550000190735 0.01709236390888691 0.001950348261743784" quat="1.0 0.0 0.0 0.0"/>
        <geom class="collision" type="box" pos="-0.41879227 -0.02447526 -0.09269837" size="0.015541927888989449 0.20394548773765564 0.0019503155490383506" quat="1.0 0.0 0.0 0.0"/>
        <geom class="collision" type="box" pos="0.41818604 -0.02447526 -0.09269837" size="0.016148118302226067 0.20394544303417206 0.001950315199792385" quat="1.0 0.0 0.0 0.0"/>
        <geom class="collision" type="box" pos="0.40387682 -0.02447526 -0.16496660" size="0.0031250983010977507 0.20394541323184967 0.07081738859415054" quat="1.0 0.0 0.0 0.0"/>
        <geom class="collision" type="box" pos="-0.40555182 -0.02447526 -0.16496660" size="0.003121061949059367 0.2039453685283661 0.07081737369298935" quat="1.0 0.0 0.0 0.0"/>
        <geom class="collision" type="box" pos="-0.00040592 -0.23033389 -0.16496660" size="0.4084412157535553 0.0025401643943041563 0.07081735134124756" quat="1.0 0.0 0.0 0.0"/>
        <geom class="collision" type="box" pos="-0.00063184 0.18240607 -0.16496660" size="0.4087069034576416 0.003984049893915653 0.07081732898950577" quat="1.0 0.0 0.0 0.0"/>
        <geom class="collision" type="box" pos="-0.00126101 0.09436812 -0.23433171" size="0.4069119989871979 0.09264685958623886 0.0026720145251601934" quat="1.0 0.0 0.0 0.0"/>
        <geom class="collision" type="box" pos="-0.00126101 -0.16030505 -0.23433171" size="0.4069119095802307 0.07010563462972641 0.0026720138266682625" quat="1.0 0.0 0.0 0.0"/>
        <geom class="collision" type="box" pos="-0.29710450 -0.04433426 -0.23433179" size="0.11106777936220169 0.04724905639886856 0.002672080183401704" quat="1.0 0.0 0.0 0.0"/>
        <geom class="collision" type="box" pos="0.07008285 -0.04433426 -0.23433170" size="0.1567329615354538 0.04724905639886856 0.002671994036063552" quat="1.0 0.0 0.0 0.0"/>
        <geom class="collision" type="box" pos="0.36376736 -0.04433426 -0.23433174" size="0.041106171905994415 0.04724905639886856 0.0026720413006842136" quat="1.0 0.0 0.0 0.0"/>
        <geom class="collision" type="box" pos="0.13953832 -0.02447526 -0.16326587" size="0.0137025136500597 0.20394502580165863 0.07251790910959244" quat="1.0 0.0 0.0 0.0"/>
        <geom class="collision" type="cylinder" pos="0.08531411 0.22047810 -0.04586746" size="0.028146835044026375 0.04497091472148895" quat="1.0 0.0 0.0 0.0"/>
        <geom class="collision" type="cylinder" pos="0.07746895 0.22047810 -0.04586746" size="0.028146835044026375 0.049508947879076004" quat="0.7071068286895752 -0.0 0.7071067690849304 0.0"/>
        <body name="handle">
          <joint axis="1.0 0.0 0.0" pos="0.15564533 0.22090486 -0.04684061" limited="true" name="handle_temp_joint" type="hinge" range="-0.7853981633974483 0.7853981633974483" damping="1" frictionloss="1" armature=".01" stiffness="0.01" springref="-0.01"/>
          <joint axis="0.0 1.0 0.0" pos="0.15564533 0.22090486 -0.04684061" limited="true" name="handle_joint" type="hinge" range="0 0.5" damping="1" frictionloss="1" armature=".01" stiffness="0.01" springref="-0.01"/>
          <geom mesh="handle_vis" type="mesh" solimp="0.998 0.998 0.001" solref="0.001 1" friction="0.95 0.3 0.1" class="visual" material="handle_material"/>
          <geom class="collision" type="cylinder" pos="0.16359383 0.22057717 -0.04616467" size="0.025074021890759468 0.016494393348693848" quat="0.7071068286895752 -0.0 0.7071067690849304 0.0"/>
          <geom class="collision" type="cylinder" pos="0.16848556 0.22087974 0.00247903" size="0.005681407637894154 0.024712152779102325" quat="1.0 0.0 0.0 0.0"/>
        </body>
        <body name="Funnel001">
          <joint axis="0.0 0.0 1.0" pos="0.27545301 -0.04385014 -0.23521018" limited="true" name="Funnel001_joint" range="0.0 0.1" type="slide" damping="1" frictionloss="1" armature=".01" stiffness="0.05"/>
          <geom mesh="Funnel001_vis" type="mesh" solimp="0.998 0.998 0.001" solref="0.001 1" friction="0.95 0.3 0.1" class="visual" material="Funnel001_material"/>
          <geom class="collision" type="cylinder" pos="0.27509082 -0.04386085 -0.23407790" size="0.04357573762536049 0.0062309931963682175" quat="1.0 0.0 0.0 0.0"/>
        </body>
        <body name="Funnel002">
          <joint axis="0.0 0.0 1.0" pos="-0.13762812 -0.04385043 -0.23521024" limited="true" name="Funnel002_joint" range="0.0 0.1" type="slide" damping="1" frictionloss="1" armature=".01" stiffness="0.05"/>
          <geom mesh="Funnel002_vis" type="mesh" solimp="0.998 0.998 0.001" solref="0.001 1" friction="0.95 0.3 0.1" class="visual" material="Funnel002_material"/>
          <geom class="collision" type="cylinder" pos="-0.13736017 -0.04386085 -0.23407790" size="0.04357573762536049 0.0062309931963682175" quat="1.0 0.0 0.0 0.0"/>
        </body>
        <body name="Shelf001">
          <joint axis="0.0 0.0 1.0" pos="-0.31299823 -0.01496042 -0.12675798" limited="true" name="Shelf001_joint" range="0.0 0.1" type="slide" damping="1" frictionloss="1" armature=".01" stiffness="0.05"/>
          <geom mesh="Shelf001_vis" type="mesh" solimp="0.998 0.998 0.001" solref="0.001 1" friction="0.95 0.3 0.1" class="visual" material="Shelf001_material"/>
          <geom class="collision" type="box" pos="-0.38576856 -0.02591783 -0.12914345" size="0.003121054032817483 0.18550589680671692 0.034993961453437805" quat="1.0 0.0 0.0 0.0"/>
          <geom class="collision" type="box" pos="-0.23709647 -0.02591783 -0.12914345" size="0.003121054032817483 0.18550589680671692 0.034993961453437805" quat="1.0 0.0 0.0 0.0"/>
          <geom class="collision" type="box" pos="-0.31327086 -0.21439934 -0.13034298" size="0.07432298362255096 0.0024261516518890858 0.034993961453437805" quat="0.9940372705459595 0.10904084146022797 0.0 0.0"/>
          <geom class="collision" type="box" pos="-0.31327086 0.15936394 -0.12808326" size="0.07432298362255096 0.0024261516518890858 0.034993961453437805" quat="0.9963814616203308 -0.08499402552843094 -0.0 0.0"/>
          <geom class="collision" type="box" pos="-0.31256491 -0.02591783 -0.16120476" size="0.07255266606807709 0.18550589680671692 0.002932657953351736" quat="1.0 0.0 0.0 0.0"/>
        </body>
        <body name="spout">
          <joint axis="0.0 0.0 1.0" pos="0.08466801 0.22048787 0.12118351" limited="true" name="spout_joint" range="-1.2217304763960306 1.2217304763960306" type="hinge" damping="1" frictionloss="1" armature=".01" stiffness="0.01" springref="-0.01"/>
          <site type="cylinder" rgba="0.5 0.75 1 0.5" size="0.005716228857636452 0.222311332821846" pos="0.08421869 -0.01453175 -0.01146635" name="water"/>
          <geom mesh="spout_vis" type="mesh" solimp="0.998 0.998 0.001" solref="0.001 1" friction="0.95 0.3 0.1" class="visual" material="spout_material"/>
          <geom class="collision" type="cylinder" pos="0.08531411 0.22047810 0.08081535" size="0.015766173601150513 0.07984970510005951" quat="1.0 0.0 0.0 0.0"/>
          <geom class="collision" type="cylinder" pos="0.08531411 0.20923931 0.18625373" size="0.015766173601150513 0.020500902086496353" quat="0.9670015573501587 0.254770427942276 0.0 0.0"/>
          <geom class="collision" type="cylinder" pos="0.08531411 0.18794415 0.21167788" size="0.015766173601150513 0.020500902086496353" quat="0.9004788994789124 0.4348997473716736 0.0 0.0"/>
          <geom class="collision" type="cylinder" pos="0.08531411 0.21762432 0.16426310" size="0.015766173601150513 0.005798363126814365" quat="0.9954514503479004 0.09527008980512619 0.0 0.0"/>
          <geom class="collision" type="cylinder" pos="0.08531411 0.16038254 0.22503071" size="0.015766173601150513 0.020500902086496353" quat="0.8072229027748108 0.5902467370033264 0.0 0.0"/>
          <geom class="collision" type="cylinder" pos="0.08531411 0.05558127 0.22776975" size="0.015766173601150513 0.08815393596887589" quat="0.7071067094802856 0.7071068286895752 0.0 0.0"/>
        </body>
        <geom class="region" name="reg_basin_left" type="box" pos="-0.051064645000000006 -0.024452210000000002 -0.15938067" size="0.172672575 0.19825164 0.06704065000000001"/>
        <geom class="region" name="reg_basin_right" type="box" pos="0.27666979999999997 -0.024452210000000002 -0.15938067" size="0.11874925 0.19825164 0.06704065000000001"/>
        <geom class="region" name="reg_main" type="box" pos="-2.500000001459668e-08 1.599999999990498e-07 -0.163875875" size="0.435334155 0.26218224999999995 0.07412781499999999"/>
      </body>
    </body>
  </worldbody>
  <actuator>
    <motor name="handle_joint_actuator" joint="handle_joint" gear="10"/>
    <motor name="handle_temp_joint_actuator" joint="handle_temp_joint" gear="10"/>
    <motor name="Funnel001_joint_actuator" joint="Funnel001_joint" gear="10"/>
    <motor name="Funnel002_joint_actuator" joint="Funnel002_joint" gear="10"/>
    <motor name="Shelf001_joint_actuator" joint="Shelf001_joint" gear="80"/>
    <motor name="spout_joint_actuator" joint="spout_joint" gear="10"/>
  </actuator>
</mujoco>
