<?xml version='1.0' encoding='UTF-8'?>
<mujoco model="model">
  <option timestep="0.002" gravity="0.0 0.0 -9.81"/>
  <compiler angle="radian"/>
  <asset>
    <mesh file="visuals/door.obj" name="door_vis"/>
    <mesh file="visuals/door_Clear.obj" name="door_Clear_vis"/>
    <mesh file="visuals/knob_temp.obj" name="knob_temp_vis"/>
    <mesh file="visuals/knob_time.obj" name="knob_time_vis"/>
    <mesh file="visuals/Body001.obj" name="Body001_vis"/>
    <mesh file="visuals/rack0.obj" name="rack0_vis"/>
    <mesh file="visuals/rack1.obj" name="rack1_vis"/>
    <texture file="visuals/T_BC001.png" name="Body001_material" type="2d"/>
    <material name="Body001_material" rgba="1 1 1 1.0" texture="Body001_material" shininess="2" specular="2"/>
    <texture file="visuals/T_BC001.png" name="door_material" type="2d"/>
    <material name="door_material" rgba="1 1 1 1.0" texture="door_material" shininess="2" specular="2"/>
    <texture file="visuals/T_BC001.png" name="door_Clear_material" type="2d"/>
    <material name="door_Clear_material" rgba="1 1 1 0.800000011920929" texture="door_Clear_material" shininess="0.5" specular="0.3103448502657381"/>
    <texture file="visuals/T_BC001.png" name="knob_temp_material" type="2d"/>
    <material name="knob_temp_material" rgba="1 1 1 1.0" texture="knob_temp_material" shininess="2" specular="2"/>
    <texture file="visuals/T_BC001.png" name="knob_time_material" type="2d"/>
    <material name="knob_time_material" rgba="1 1 1 1.0" texture="knob_time_material" shininess="2" specular="2"/>
    <texture file="visuals/T_BC001.png" name="rack0_material" type="2d"/>
    <material name="rack0_material" rgba="1 1 1 1.0" texture="rack0_material" shininess="10" specular="10"/>
    <texture file="visuals/T_BC001.png" name="rack1_material" type="2d"/>
    <material name="rack1_material" rgba="1 1 1 1.0" texture="rack1_material" shininess="10" specular="10"/>
  </asset>
  <default>
    <default class="visual">
      <geom conaffinity="0" contype="0" group="1" type="mesh"/>
    </default>
    <default class="collision">
      <geom group="0" rgba="0.5 0 0 0.5"/>
    </default>
    <default class="spawn">
      <geom group="0" rgba="1 1 1 0.5" contype="0" conaffinity="0"/>
      <site group="0" rgba="1 1 1 0.5"/>
    </default>
    <default class="region">
      <geom group="1" conaffinity="0" contype="0" rgba="0 1 0 0"/>
    </default>
  </default>
  <worldbody>
    <body>
      <body name="object">
        <geom mesh="Body001_vis" type="mesh" solimp="0.998 0.998 0.001" solref="0.001 1" friction="0.95 0.3 0.1" class="visual" material="Body001_material"/>
        <geom class="collision" type="box" pos="0.004257142543792725 0.29582837224006653 -0.0529102087020874" size="0.22952304780483246 0.0017778400797396898 0.1740211695432663" quat="1.0 0.0 0.0 0.0"/>
        <geom class="collision" type="box" pos="0.23214790225028992 0.02717023715376854 -0.057257432490587234" size="0.0042505525052547455 0.2641582190990448 0.16595187783241272" quat="1.0 0.0 0.0 0.0"/>
        <geom class="collision" type="box" pos="-0.224727064371109 0.029989678412675858 -0.057878464460372925" size="0.0037652181927114725 0.26761651039123535 0.16595187783241272" quat="1.0 0.0 0.0 0.0"/>
        <geom class="collision" type="box" pos="0.003983643371611834 0.024439111351966858 0.11233504116535187" size="0.21423636376857758 0.26748934388160706 0.004080869723111391" quat="1.0 0.0 0.0 0.0"/>
        <geom class="collision" type="box" pos="0.0033500767312943935 0.026148568838834763 -0.22870412468910217" size="0.23182912170886993 0.27145856618881226 0.005052439868450165" quat="1.0 0.0 0.0 0.0"/>
        <geom class="collision" type="box" pos="2.8462620704772235e-08 -0.2542492747306824 0.2345203161239624" size="0.2994057536125183 0.0074152639135718346 0.05844840779900551" quat="1.0 0.0 0.0 0.0"/>
        <geom class="collision" type="box" pos="3.04707867826437e-08 -0.2471369355916977 0.14411506056785583" size="0.2994057536125183 0.0077019804157316685 0.033569641411304474" quat="1.0 0.0 0.0 0.0"/>
        <geom class="collision" type="box" pos="-3.902916745346374e-08 -0.2471369355916977 -0.2575114369392395" size="0.2994057536125183 0.007701977621763945 0.033569641411304474" quat="1.0 0.0 0.0 0.0"/>
        <geom class="collision" type="box" pos="0.2643807530403137 -0.2471369355916977 -0.057232510298490524" size="0.035025034099817276 0.007701974827796221 0.16634026169776917" quat="1.0 0.0 0.0 0.0"/>
        <geom class="collision" type="box" pos="-0.25912341475486755 -0.2471369355916977 -0.057232510298490524" size="0.03709207475185394 0.007701972499489784 0.16634026169776917" quat="1.0 0.0 0.0 0.0"/>
        <geom class="collision" type="box" pos="0.20026057958602905 0.015912054106593132 0.04335138201713562" size="0.013599753379821777 0.023424720391631126 0.003483806736767292" quat="1.0 0.0 0.0 0.0"/>
        <geom class="collision" type="box" pos="-0.20047149062156677 0.013488080352544785 0.04027305543422699" size="0.006780058611184359 0.2276025265455246 0.003483806736767292" quat="1.0 0.0 0.0 0.0"/>
        <geom class="collision" type="box" pos="0.20026057958602905 0.015912054106593132 -0.01690629869699478" size="0.013599753379821777 0.023424720391631126 0.003483806736767292" quat="1.0 0.0 0.0 0.0"/>
        <geom class="collision" type="box" pos="-0.20047149062156677 0.013488080352544785 -0.01998462900519371" size="0.006780058611184359 0.2276025265455246 0.003483806736767292" quat="1.0 0.0 0.0 0.0"/>
        <geom class="collision" type="box" pos="0.20026057958602905 0.015912054106593132 -0.07920662313699722" size="0.013599753379821777 0.023424720391631126 0.003483806736767292" quat="1.0 0.0 0.0 0.0"/>
        <geom class="collision" type="box" pos="-0.20047149062156677 0.013488080352544785 -0.08228495717048645" size="0.006780058611184359 0.2276025265455246 0.003483806736767292" quat="1.0 0.0 0.0 0.0"/>
        <geom class="collision" type="box" pos="0.20026057958602905 0.015912054106593132 -0.14017921686172485" size="0.013599753379821777 0.023424720391631126 0.003483806736767292" quat="1.0 0.0 0.0 0.0"/>
        <geom class="collision" type="box" pos="-0.20047149062156677 0.013488080352544785 -0.14006593823432922" size="0.006780058611184359 0.2276025265455246 0.003483806736767292" quat="1.0 0.0 0.0 0.0"/>
        <geom class="collision" type="box" pos="-0.20226171612739563 0.013488082215189934 0.021582961082458496" size="0.00794237107038498 0.2276025265455246 0.003483806736767292" quat="1.0 0.0 0.0 0.0"/>
        <geom class="collision" type="box" pos="-0.20226171612739563 0.013488082215189934 -0.038674719631671906" size="0.00794237107038498 0.2276025265455246 0.003483806736767292" quat="1.0 0.0 0.0 0.0"/>
        <geom class="collision" type="box" pos="-0.20226171612739563 0.013488082215189934 -0.10097505152225494" size="0.00794237107038498 0.2276025265455246 0.003483806736767292" quat="1.0 0.0 0.0 0.0"/>
        <geom class="collision" type="box" pos="-0.20226171612739563 0.013488082215189934 -0.15875603258609772" size="0.00794237107038498 0.2276025265455246 0.003483806736767292" quat="1.0 0.0 0.0 0.0"/>
        <geom class="collision" type="box" pos="0.2048565149307251 0.012451224029064178 0.024354897439479828" size="0.007159928325563669 0.23121151328086853 0.003483806736767292" quat="1.0 0.0 0.0 0.0"/>
        <geom class="collision" type="box" pos="0.2048565149307251 0.012451224029064178 -0.035902783274650574" size="0.007159928325563669 0.23121151328086853 0.003483806736767292" quat="1.0 0.0 0.0 0.0"/>
        <geom class="collision" type="box" pos="0.2048565149307251 0.012451224029064178 -0.09820310771465302" size="0.007159928325563669 0.23121151328086853 0.003483806736767292" quat="1.0 0.0 0.0 0.0"/>
        <geom class="collision" type="box" pos="0.2048565149307251 0.012451224029064178 -0.15917570888996124" size="0.007159928325563669 0.23121151328086853 0.003483806736767292" quat="1.0 0.0 0.0 0.0"/>
        <geom class="collision" type="box" pos="-0.1949082314968109 0.012826252728700638 0.04027305543422699" size="0.01252143457531929 0.015423857606947422 0.003483806736767292" quat="1.0 0.0 0.0 0.0"/>
        <geom class="collision" type="box" pos="-0.1949082314968109 0.012826252728700638 -0.01998462900519371" size="0.01252143457531929 0.015423857606947422 0.003483806736767292" quat="1.0 0.0 0.0 0.0"/>
        <geom class="collision" type="box" pos="-0.1949082314968109 0.012826252728700638 -0.08228495717048645" size="0.01252143457531929 0.015423857606947422 0.003483806736767292" quat="1.0 0.0 0.0 0.0"/>
        <geom class="collision" type="box" pos="-0.1949082314968109 0.012826252728700638 -0.14006593823432922" size="0.01252143457531929 0.015423857606947422 0.003483806736767292" quat="1.0 0.0 0.0 0.0"/>
        <geom class="collision" type="box" pos="0.2048565149307251 0.012451224029064178 0.0430198609828949" size="0.007159928325563669 0.23121151328086853 0.003483806736767292" quat="1.0 0.0 0.0 0.0"/>
        <geom class="collision" type="box" pos="0.2048565149307251 0.012451224029064178 -0.017237819731235504" size="0.007159928325563669 0.23121151328086853 0.003483806736767292" quat="1.0 0.0 0.0 0.0"/>
        <geom class="collision" type="box" pos="0.2048565149307251 0.012451224029064178 -0.07953814417123795" size="0.007159928325563669 0.23121151328086853 0.003483806736767292" quat="1.0 0.0 0.0 0.0"/>
        <geom class="collision" type="box" pos="0.2048565149307251 0.012451224029064178 -0.14051073789596558" size="0.007159928325563669 0.23121151328086853 0.003483806736767292" quat="1.0 0.0 0.0 0.0"/>
        <geom class="collision" type="box" pos="0.21503008902072906 -0.2173396646976471 -0.052010953426361084" size="0.007159928325563669 0.13969109952449799 0.003483806736767292" quat="0.7071068286895752 0.7071067690849304 -1.5700924318127872e-16 -5.9269340452702814e-24"/>
        <geom class="collision" type="box" pos="0.21503008902072906 0.24395039677619934 -0.052010953426361084" size="0.007159928325563669 0.13969109952449799 0.003483806736767292" quat="0.7071068286895752 0.7071067690849304 -1.5700924318127872e-16 -5.9269340452702814e-24"/>
        <geom class="collision" type="box" pos="-0.20704622566699982 -0.2173396646976471 -0.052010953426361084" size="0.007159928325563669 0.13969109952449799 0.003483806736767292" quat="0.7071068286895752 0.7071067690849304 -1.5700924318127872e-16 -5.9269340452702814e-24"/>
        <geom class="collision" type="box" pos="-0.20704622566699982 0.24395039677619934 -0.052010953426361084" size="0.007159928325563669 0.13969109952449799 0.003483806736767292" quat="0.7071068286895752 0.7071067690849304 -1.5700924318127872e-16 -5.9269340452702814e-24"/>
        <body name="door">
          <joint axis="1.0 0.0 0.0" pos="4.842877388000488e-08 -0.2616780996322632 -0.29297778010368347" limited="true" name="door_joint" range="0.0 1.15" type="hinge" damping="5" frictionloss="1" armature=".01" stiffness="0.5" springref="-0.8"/>
          <geom mesh="door_vis" type="mesh" solimp="0.998 0.998 0.001" solref="0.001 1" friction="0.95 0.3 0.1" class="visual" material="door_material"/>
          <geom class="collision" type="cylinder" pos="0.001624423312023282 -0.28852972388267517 0.12220831215381622" size="0.008250067941844463 0.27126771211624146" quat="0.7071068286895752 1.2101618374060763e-08 0.7071067690849304 -1.2101617485882343e-08" name="door_handle_main"/>
          <geom class="collision" type="box" pos="0.0003371572820469737 -0.26061785221099854 -0.06075669825077057" size="0.2993898391723633 0.0006073550903238356 0.22566035389900208" quat="1.0 0.0 0.0 0.0" name="door_main"/>
          <geom class="collision" type="box" pos="0.0003371572820469737 -0.2583934962749481 -0.06384003907442093" size="0.2099902182817459 0.0012809786712750793 0.13924762606620789" quat="1.0 0.0 0.0 0.0"/>
          <geom class="collision" type="box" pos="0.0003371572820469737 -0.26061785221099854 -0.06075669825077057" size="0.2993898391723633 0.0010464511578902602 0.22566035389900208" quat="1.0 0.0 0.0 0.0"/>
          <geom class="collision" type="cylinder" pos="0.26123130321502686 -0.2699773907661438 0.12220831215381622" size="0.008250067941844463 0.00860155001282692" quat="0.5 0.5 0.4999999701976776 -0.5"/>
          <geom class="collision" type="cylinder" pos="-0.2576301097869873 -0.2699773907661438 0.12220831215381622" size="0.008250067941844463 0.00860155001282692" quat="0.5 0.5 0.4999999701976776 -0.5"/>
          <body name="door_Clear">
            <geom mesh="door_Clear_vis" type="mesh" solimp="0.998 0.998 0.001" solref="0.001 1" friction="0.95 0.3 0.1" class="visual" material="door_Clear_material"/>
            <geom class="collision" type="box" pos="0.0003371572820469737 -0.2583934962749481 -0.06384003907442093" size="0.2099902182817459 0.0012809786712750793 0.13924762606620789" quat="1.0 0.0 0.0 0.0"/>
          </body>
        </body>
        <body name="knob_temp">
          <joint axis="0.0 1.0 0.0" pos="0.20315267145633698 -0.2786499857902527 0.2327795922756195" limited="true" name="knob_temp_joint" range="0.0 5.585053606381854" type="hinge" damping="0.05" armature="0.001"/>
          <geom mesh="knob_temp_vis" type="mesh" solimp="0.998 0.998 0.001" solref="0.001 1" friction="0.95 0.3 0.1" class="visual" material="knob_temp_material"/>
          <geom class="collision" type="cylinder" pos="0.20284394919872284 -0.2682937979698181 0.23267494142055511" size="0.03073807619512081 0.0048811412416398525" quat="0.7071067094802856 0.7071068286895752 -1.5700929612083792e-16 2.2148510003422914e-23"/>
          <geom class="collision" type="box" pos="0.20284393429756165 -0.2843724191188812 0.23267494142055511" size="0.005927907302975655 0.012706436216831207 0.02259235642850399" quat="1.9470718370939721e-07 -6.717942824252532e-08 -1.0 -1.3435884227419592e-07" name="knob_temp_main"/>
        </body>
        <body name="knob_time">
          <joint axis="0.0 1.0 0.0" pos="-0.20649613440036774 -0.2786499857902527 0.2327795922756195" limited="true" name="knob_time_joint" range="0.0 5.270894341022875" type="hinge" damping="1" frictionloss="0.1" armature="0.001"/>
          <geom mesh="knob_time_vis" type="mesh" solimp="0.998 0.998 0.001" solref="0.001 1" friction="0.95 0.3 0.1" class="visual" material="knob_time_material"/>
          <geom class="collision" type="cylinder" pos="-0.20620454847812653 -0.2682937979698181 0.23267494142055511" size="0.03073807619512081 0.0048811412416398525" quat="0.7071067094802856 0.7071068286895752 -1.5700929612083792e-16 2.2148510003422914e-23" density="0.000001"/>
          <geom class="collision" type="box" pos="-0.20620454847812653 -0.2843724191188812 0.23267494142055511" size="0.0065148877911269665 0.012706436216831207 0.02259235642850399" quat="0.7071068286895752 -4.750302551315144e-08 0.7071067094802856 4.7503014855010406e-08" name="knob_time_main" density="0.000001"/>
        </body>
        <body name="rack0">
          <geom class="region" name="reg_rack0" type="box" pos="0.00031485408544540405 -0.01823389157652855 -0.0840238481760025" size="0.14721704071760178 0.0975353213250637 0.05305988883972168"/>
          <joint axis="0.0 -1.0 0.0" pos="-0.0018711239099502563 -0.020450979471206665 -0.14011718332767487" limited="true" name="rack0_joint" range="0.0 0.3" type="slide" damping="1" frictionloss="1" armature=".01" stiffness="0.05"/>
          <geom mesh="rack0_vis" type="mesh" solimp="0.998 0.998 0.001" solref="0.001 1" friction="0.95 0.3 0.1" class="visual" material="rack0_material"/>
          <geom class="collision" type="box" pos="-0.0007319545838981867 -0.019534630700945854 -0.1443442702293396" size="0.1477791666984558 0.09949837625026703 0.002305444795638323" quat="1.0 0.0 0.0 0.0"/>
          <geom class="collision" type="box" pos="-0.16057223081588745 -0.019534630700945854 -0.1406985968351364" size="0.014118343591690063 0.11484713852405548 0.002305444562807679" quat="0.987217366695404 -1.9065227217454237e-15 0.1593797206878662 2.1414075845882508e-08"/>
          <geom class="collision" type="box" pos="0.1604328155517578 -0.019534630700945854 -0.1406985968351364" size="0.014118343591690063 0.11484713852405548 0.002305444562807679" quat="7.395976808766136e-08 0.1593797206878662 8.48315728774196e-09 -0.987217366695404"/>
          <geom class="collision" type="box" pos="-0.0018965154886245728 0.092120461165905 -0.1406985968351364" size="0.014118343591690063 0.16751767694950104 0.002305444562807679" quat="0.6980680823326111 0.11269848048686981 0.11269848793745041 -0.6980680823326111"/>
          <geom class="collision" type="box" pos="-0.0018965154886245728 -0.1278197169303894 -0.1406985968351364" size="0.014118343591690063 0.16751767694950104 0.002305444562807679" quat="0.6980680823326111 -0.11269848048686981 0.11269848793745041 0.6980680823326111"/>
        </body>
        <body name="rack1">
          <geom class="region" name="reg_rack1" type="box" pos="0.00031485408544540405 -0.01823389157652855 0.04346788255497813" size="0.14721704071760178 0.0975353213250637 0.059100756723433734"/>
          <joint axis="0.0 -1.0 0.0" pos="-0.0018711278680711985 -0.020450979471206665 -0.018302276730537415" limited="true" name="rack1_joint" range="0.0 0.3" type="slide" damping="1" frictionloss="1" armature=".01" stiffness="0.05"/>
          <geom mesh="rack1_vis" type="mesh" solimp="0.998 0.998 0.001" solref="0.001 1" friction="0.95 0.3 0.1" class="visual" material="rack1_material"/>
          <geom class="collision" type="box" pos="-0.0007319545838981867 -0.019534630700945854 -0.02270681783556938" size="0.1477791666984558 0.09949837625026703 0.002305444795638323" quat="1.0 0.0 0.0 0.0"/>
          <geom class="collision" type="box" pos="-0.16057223081588745 -0.019534630700945854 -0.019061144441366196" size="0.014118343591690063 0.11484713852405548 0.002305444562807679" quat="0.987217366695404 -1.9065227217454237e-15 0.1593797206878662 2.1414075845882508e-08"/>
          <geom class="collision" type="box" pos="0.1604328155517578 -0.019534630700945854 -0.019061144441366196" size="0.014118343591690063 0.11484713852405548 0.002305444562807679" quat="7.395976808766136e-08 0.1593797206878662 8.48315728774196e-09 -0.987217366695404"/>
          <geom class="collision" type="box" pos="-0.0018965154886245728 0.092120461165905 -0.019061144441366196" size="0.014118343591690063 0.16751767694950104 0.002305444562807679" quat="0.6980680823326111 0.11269848048686981 0.11269848793745041 -0.6980680823326111"/>
          <geom class="collision" type="box" pos="-0.0018965154886245728 -0.1278197169303894 -0.019061144441366196" size="0.014118343591690063 0.16751767694950104 0.002305444562807679" quat="0.6980680823326111 -0.11269848048686981 0.11269848793745041 0.6980680823326111"/>
        </body>
        <geom class="region" name="reg_int" type="box" pos="0.005122743546962738 0.022759638726711273 -0.05728103965520859" size="0.21342514997720718 0.26641710644960404 0.15656039661169052"/>
        <geom class="region" name="reg_main" type="box" pos="0.0 0.01797104999423027 0.0" size="0.3004058132171631 0.28063533997535706 0.29396907782554627"/>
      </body>
    </body>
  </worldbody>
  <actuator>
    <motor name="door_joint_actuator" joint="door_joint" gear="50"/>
    <motor name="knob_temp_joint_actuator" joint="knob_temp_joint" gear="50"/>
    <motor name="knob_time_joint_actuator" joint="knob_time_joint" gear="50"/>
    <motor name="rack0_joint_actuator" joint="rack0_joint" gear="50"/>
    <motor name="rack1_joint_actuator" joint="rack1_joint" gear="50"/>
  </actuator>
</mujoco>
