<?xml version='1.0' encoding='UTF-8'?>
<mujoco model="model">
  <option timestep="0.002" gravity="0.0 0.0 -9.81"/>
  <compiler angle="radian"/>
  <asset>
    <mesh file="visuals/door.obj" name="door_vis"/>
    <mesh file="visuals/door_Clear.obj" name="door_Clear_vis"/>
    <mesh file="visuals/knob_front_left.obj" name="knob_front_left_vis"/>
    <mesh file="visuals/knob_front_right.obj" name="knob_front_right_vis"/>
    <mesh file="visuals/knob_rear_left.obj" name="knob_rear_left_vis"/>
    <mesh file="visuals/knob_rear_right.obj" name="knob_rear_right_vis"/>
    <mesh file="visuals/knob_temp.obj" name="knob_temp_vis"/>
    <mesh file="visuals/knob_time.obj" name="knob_time_vis"/>
    <mesh file="visuals/rack0.obj" name="rack0_vis"/>
    <mesh file="visuals/rack1.obj" name="rack1_vis"/>
    <mesh file="visuals/Body001.obj" name="Body001_vis"/>
    <texture file="visuals/T_BC001.png" name="Body001_material" type="2d"/>
    <material name="Body001_material" rgba="1 1 1 1.0" texture="Body001_material" shininess="0.1" specular="0.5"/>
    <texture file="visuals/T_BC001.png" name="door_material" type="2d"/>
    <material name="door_material" rgba="1 1 1 1.0" texture="door_material" shininess="0.1" specular="5"/>
    <material name="door_Clear_material" rgba="0.12735895812511444 0.12735895812511444 0.12735895812511444 0.8" shininess="0.5" specular="0.3103448502657381"/>
    <texture file="visuals/T_BC001.png" name="knob_front_left_material" type="2d"/>
    <material name="knob_front_left_material" rgba="1 1 1 1.0" texture="knob_front_left_material" shininess="0.1" specular="5"/>
    <texture file="visuals/T_BC001.png" name="knob_front_right_material" type="2d"/>
    <material name="knob_front_right_material" rgba="1 1 1 1.0" texture="knob_front_right_material" shininess="0.1" specular="5"/>
    <texture file="visuals/T_BC001.png" name="knob_rear_left_material" type="2d"/>
    <material name="knob_rear_left_material" rgba="1 1 1 1.0" texture="knob_rear_left_material" shininess="0.1" specular="5"/>
    <texture file="visuals/T_BC001.png" name="knob_rear_right_material" type="2d"/>
    <material name="knob_rear_right_material" rgba="1 1 1 1.0" texture="knob_rear_right_material" shininess="0.1" specular="5"/>
    <texture file="visuals/T_BC001.png" name="knob_temp_material" type="2d"/>
    <material name="knob_temp_material" rgba="1 1 1 1.0" texture="knob_temp_material" shininess="0.1" specular="5"/>
    <texture file="visuals/T_BC001.png" name="knob_time_material" type="2d"/>
    <material name="knob_time_material" rgba="1 1 1 1.0" texture="knob_time_material" shininess="0.1" specular="5"/>
    <texture file="visuals/T_BC001.png" name="rack0_material" type="2d"/>
    <material name="rack0_material" rgba="1 1 1 1.0" texture="rack0_material" shininess="0.1" specular="5"/>
    <texture file="visuals/T_BC001.png" name="rack1_material" type="2d"/>
    <material name="rack1_material" rgba="1 1 1 1.0" texture="rack1_material" shininess="0.1" specular="5"/>
  </asset>
  <default>
    <default class="visual">
      <geom conaffinity="0" contype="0" group="1" type="mesh"/>
    </default>
    <default class="collision">
      <geom group="0" rgba="0.5 0 0 0.5"/>
    </default>
    <default class="spawn">
      <geom group="0" rgba="1 1 1 0.5" contype="0" conaffinity="0"/>
      <site group="0" rgba="1 1 1 0.5"/>
    </default>
    <default class="region">
      <geom group="1" conaffinity="0" contype="0" rgba="0 1 0 0"/>
    </default>
  </default>
  <worldbody>
    <body>
      <body name="object">
        <geom mesh="Body001_vis" type="mesh" solimp="0.998 0.998 0.001" solref="0.001 1" friction="0.95 0.3 0.1" class="visual" material="Body001_material"/>
        <geom class="collision" type="box" pos="0.00000000 0.28773725 -0.13877900" size="0.3806391656398773 0.06934699416160583 0.4276793599128723" quat="1.0 0.0 0.0 0.0"/>
        <geom class="collision" type="box" pos="0.00000000 0.31810200 0.43091512" size="0.38063934445381165 0.03898267447948456 0.14246723055839539" quat="1.0 0.0 0.0 0.0"/>
        <geom class="collision" type="box" pos="0.00000000 -0.04190081 0.27361840" size="0.38063955307006836 0.2578233480453491 0.01528517808765173" quat="1.0 0.0 0.0 0.0"/>
        <geom class="collision" type="box" pos="0.00000000 -0.04190084 -0.43425706" size="0.3806397318840027 0.25782346725463867 0.1322038769721985" quat="1.0 0.0 0.0 0.0"/>
        <geom class="collision" type="box" pos="-0.34366122 -0.02676387 -0.02269453" size="0.036980871111154556 0.24268659949302673 0.2797034680843353" quat="1.0 0.0 0.0 0.0"/>
        <geom class="collision" type="box" pos="0.34331039 -0.02676387 -0.02269454" size="0.037331726402044296 0.2426867038011551 0.27970367670059204" quat="1.0 0.0 0.0 0.0"/>
        <geom class="collision" type="box" pos="0.00152631 -0.02676387 -0.25557634" size="0.3090246319770813 0.24268679320812225 0.04682393744587898" quat="1.0 0.0 0.0 0.0"/>
        <geom class="collision" type="box" pos="0.00152631 -0.02676387 0.21112446" size="0.3090248107910156 0.2426868975162506 0.04414474591612816" quat="1.0 0.0 0.0 0.0"/>
        <geom class="collision" type="box" pos="0.30031326 -0.01840548 0.10591764" size="0.005835832562297583 0.23432861268520355 0.008943891152739525" quat="1.0 0.0 0.0 0.0"/>
        <geom class="collision" type="box" pos="0.30031326 -0.01840548 0.01064280" size="0.005835835821926594 0.23432870209217072 0.006055808626115322" quat="1.0 0.0 0.0 0.0"/>
        <geom class="collision" type="box" pos="0.30031326 -0.01840548 -0.16668797" size="0.005835838615894318 0.23432880640029907 0.008943903259932995" quat="1.0 0.0 0.0 0.0"/>
        <geom class="collision" type="box" pos="0.30031326 -0.01840548 -0.07734233" size="0.005835841875523329 0.23432889580726624 0.006055814679712057" quat="1.0 0.0 0.0 0.0"/>
        <geom class="collision" type="box" pos="-0.30044070 -0.01840548 -0.07734233" size="0.005835844669491053 0.2343290001153946 0.006055817939341068" quat="1.0 0.0 0.0 0.0"/>
        <geom class="collision" type="box" pos="-0.30044070 -0.01840548 -0.16668797" size="0.005835847929120064 0.23432908952236176 0.008943920955061913" quat="1.0 0.0 0.0 0.0"/>
        <geom class="collision" type="box" pos="-0.30044070 -0.01840548 0.01064280" size="0.005835850723087788 0.23432917892932892 0.006055823992937803" quat="1.0 0.0 0.0 0.0"/>
        <geom class="collision" type="box" pos="-0.30044070 -0.01840548 0.10591764" size="0.005835853982716799 0.23432928323745728 0.008943933062255383" quat="1.0 0.0 0.0 0.0"/>
        <body name="door">
          <joint axis="1.0 0.0 0.0" pos="0.00047386 -0.29872564 -0.29060480" limited="true" name="door_joint" range="0.0 1.5707963267948966" type="hinge" damping="1" frictionloss="1" armature=".01" stiffness="0.05"/>
          <geom mesh="door_vis" type="mesh" solimp="0.998 0.998 0.001" solref="0.001 1" friction="0.95 0.3 0.1" class="visual" material="door_material"/>
          <geom class="collision" type="box" pos="0.00000001 -0.28556258 -0.02133653" size="0.3806423842906952 0.014163072220981121 0.2701687812805176" quat="1.0 0.0 0.0 0.0" name="door_main"/>
          <geom class="collision" type="box" pos="0.00000001 -0.29241508 -0.00293571" size="0.3806423842906952 0.007310488261282444 0.1463773250579834" quat="1.0 0.0 0.0 0.0"/>
          <geom class="collision" type="box" pos="-0.33332205 -0.31626445 0.21169895" size="0.01340613141655922 0.012864393182098866 0.021215109154582024" quat="1.0 0.0 0.0 0.0"/>
          <geom class="collision" type="box" pos="0.33292553 -0.31626445 0.21169895" size="0.013406133279204369 0.012864393182098866 0.021215109154582024" quat="1.0 0.0 0.0 0.0"/>
          <geom class="collision" type="box" pos="-0.00019825 -0.34403739 0.21169895" size="0.34652987122535706 0.013490837998688221 0.021215109154582024" quat="1.0 0.0 0.0 0.0" name="door_handle_main"/>
          <body name="door_Clear">
            <geom mesh="door_Clear_vis" type="mesh" solimp="0.998 0.998 0.001" solref="0.001 1" friction="0.95 0.3 0.1" class="visual" material="door_Clear_material"/>
            <geom class="collision" type="box" pos="0.00000001 -0.29241508 -0.00293571" size="0.3806423842906952 0.007310488261282444 0.1463773250579834" quat="1.0 0.0 0.0 0.0"/>
          </body>
        </body>
        <body name="knob_front_left">
          <joint axis="0.0 -1.0 0.0" pos="-0.32836023 0.27114728 0.47613841" limited="true" name="knob_front_left_joint" range="0.0 3.6651914291880923" type="hinge" damping="0.05" armature="0.001"/>
          <geom mesh="knob_front_left_vis" type="mesh" solimp="0.998 0.998 0.001" solref="0.001 1" friction="0.95 0.3 0.1" class="visual" material="knob_front_left_material"/>
          <geom class="collision" type="cylinder" pos="-0.32802793 0.27478260 0.47624242" size="0.018600063398480415 0.0029888267163187265" quat="0.7071067094802856 0.7071068286895752 0.0 0.0"/>
          <geom class="collision" type="box" pos="-0.32804888 0.26617646 0.47623983" size="0.0049294340424239635 0.006057090125977993 0.013924617320299149" quat="1.0 0.0 0.0 0.0" name="knob_front_left_main"/>
        </body>
        <body name="knob_front_right">
          <joint axis="0.0 -1.0 0.0" pos="0.33267894 0.27114728 0.47613841" limited="true" name="knob_front_right_joint" range="0.0 3.6651914291880923" type="hinge" damping="0.05" frictionloss="0.1" armature="0.001"/>
          <geom mesh="knob_front_right_vis" type="mesh" solimp="0.998 0.998 0.001" solref="0.001 1" friction="0.95 0.3 0.1" class="visual" material="knob_front_right_material"/>
          <geom class="collision" type="box" pos="0.33227965 0.26617646 0.47623983" size="0.0049294340424239635 0.006057090125977993 0.013924617320299149" quat="1.0 0.0 0.0 0.0" name="knob_front_right_main"/>
          <geom class="collision" type="cylinder" pos="0.33230060 0.27478260 0.47624242" size="0.018600063398480415 0.0029888267163187265" quat="0.7071067094802856 0.7071068286895752 0.0 0.0"/>
        </body>
        <body name="knob_rear_left">
          <joint axis="0.0 -1.0 0.0" pos="-0.23796098 0.27114728 0.47613841" limited="true" name="knob_rear_left_joint" range="0.0 3.6651914291880923" type="hinge" damping="0.05" armature="0.001"/>
          <geom mesh="knob_rear_left_vis" type="mesh" solimp="0.998 0.998 0.001" solref="0.001 1" friction="0.95 0.3 0.1" class="visual" material="knob_rear_left_material"/>
          <geom class="collision" type="box" pos="-0.23812278 0.26617646 0.47623983" size="0.0049294340424239635 0.006057090125977993 0.013924617320299149" quat="1.0 0.0 0.0 0.0" name="knob_rear_left_main"/>
          <geom class="collision" type="cylinder" pos="-0.23810183 0.27478260 0.47624242" size="0.018600063398480415 0.0029888267163187265" quat="0.7071067094802856 0.7071068286895752 0.0 0.0"/>
        </body>
        <body name="knob_rear_right">
          <joint axis="0.0 -1.0 0.0" pos="0.24363425 0.27114728 0.47613841" limited="true" name="knob_rear_right_joint" range="0.0 3.6651914291880923" type="hinge" damping="0.05" frictionloss="0.1" armature="0.001"/>
          <geom mesh="knob_rear_right_vis" type="mesh" solimp="0.998 0.998 0.001" solref="0.001 1" friction="0.95 0.3 0.1" class="visual" material="knob_rear_right_material"/>
          <geom class="collision" type="box" pos="0.24296705 0.26617646 0.47623983" size="0.0049294340424239635 0.006057090125977993 0.013924617320299149" quat="1.0 0.0 0.0 0.0" name="knob_rear_right_main"/>
          <geom class="collision" type="cylinder" pos="0.24298801 0.27478260 0.47624242" size="0.018600063398480415 0.0029888267163187265" quat="0.7071067094802856 0.7071068286895752 0.0 0.0"/>
        </body>
        <body name="knob_temp">
          <joint axis="0.0 1.0 0.0" pos="0.15376928 0.27114728 0.47613841" limited="true" name="knob_temp_joint" range="0.0 5.602506898901798" type="hinge" damping="0.05" armature="0.001"/>
          <geom mesh="knob_temp_vis" type="mesh" solimp="0.998 0.998 0.001" solref="0.001 1" friction="0.95 0.3 0.1" class="visual" material="knob_temp_material"/>
          <geom class="collision" type="box" pos="0.15340966 0.26617646 0.47623983" size="0.0049294340424239635 0.006057090125977993 0.013924617320299149" quat="1.0 0.0 0.0 0.0" name="knob_temp_main"/>
          <geom class="collision" type="cylinder" pos="0.15343061 0.27478260 0.47624242" size="0.018600063398480415 0.0029888267163187265" quat="0.7071067094802856 0.7071068286895752 0.0 0.0"/>
        </body>
        <body name="knob_time">
          <joint axis="0.0 1.0 0.0" pos="-0.14835897 0.27114728 0.47548491" limited="true" name="knob_time_joint" range="0.0 5.235987755982989" type="hinge" damping="0.05" armature="0.001"/>
          <geom mesh="knob_time_vis" type="mesh" solimp="0.998 0.998 0.001" solref="0.001 1" friction="0.95 0.3 0.1" class="visual" material="knob_time_material"/>
          <geom class="collision" type="box" pos="-0.15047948 0.26617646 0.47555688" size="0.015314821153879166 0.006057090125977993 0.0049294354394078255" quat="1.0 0.0 0.0 0.0" name="knob_time_main"/>
          <geom class="collision" type="cylinder" pos="-0.14873384 0.27478260 0.47542113" size="0.018600063398480415 0.0029888267163187265" quat="0.7071067094802856 0.7071068286895752 0.0 0.0"/>
        </body>
        <body name="rack0">
          <geom class="region" name="reg_rack0" type="box" pos="-7.514999999999605e-05 -0.05177400500000001 -0.02026579" size="0.29338473 0.204263845 0.039631"/>
          <joint axis="0.0 -1.0 0.0" pos="0.00002085 -0.05290608 -0.06526963" limited="true" name="rack0_joint" range="0.0 0.37" type="slide" damping="1" frictionloss="1" armature=".01" stiffness="0.05"/>
          <geom mesh="rack0_vis" type="mesh" solimp="0.998 0.998 0.001" solref="0.001 1" friction="0.95 0.3 0.1" class="visual" material="rack0_material"/>
          <geom class="collision" type="box" pos="-0.00039496 -0.05307997 -0.06457140" size="0.30155226588249207 0.20644082129001617 0.0038607490714639425" quat="1.0 0.0 0.0 0.0"/>
        </body>
        <body name="rack1">
          <geom class="region" name="reg_rack1" type="box" pos="-7.514999999999605e-05 -0.05177400500000001 0.09753503999999999" size="0.29338473 0.204263845 0.06800844"/>
          <joint axis="0.0 -1.0 0.0" pos="0.00002085 -0.05290608 0.02302140" limited="true" name="rack1_joint" range="0.0 0.37" type="slide" damping="1" frictionloss="1" armature=".01" stiffness="0.05"/>
          <geom mesh="rack1_vis" type="mesh" solimp="0.998 0.998 0.001" solref="0.001 1" friction="0.95 0.3 0.1" class="visual" material="rack1_material"/>
          <geom class="collision" type="box" pos="-0.00039496 -0.05307997 0.02392154" size="0.30155226588249207 0.20644082129001617 0.0038607490714639425" quat="1.0 0.0 0.0 0.0"/>
        </body>
        <geom class="region" name="reg_int" type="box" pos="0.00101271 -0.02609689000000001 -0.01940158" size="0.29183088 0.23750866 0.18363595"/>
        <site type="cylinder" rgba="0.5 0 0 0.5" size="0.09734878689050674 0.0001" pos="-0.18913718 -0.12916026 0.28895366" name="burner_on_front_left"/>
        <site type="cylinder" rgba="0.5 0 0 0.5" size="0.07675307989120483 0.0001" pos="-0.19991663 0.12864677 0.28895366" name="burner_on_rear_left"/>
        <site type="cylinder" rgba="0.5 0 0 0.5" size="0.07978937029838562 0.0001" pos="0.19051448 -0.15064779 0.28895366" name="burner_on_front_right"/>
        <site type="cylinder" rgba="0.5 0 0 0.5" size="0.09814763814210892 0.0001" pos="0.19729567 0.11031708 0.28895366" name="burner_on_rear_right"/>
        <site name="burner_front_left_place_site" type="cylinder" rgba="0.5 0 0 0" size="0.09734878689050674 4.999999873689376e-05" pos="-0.18913718 -0.12916026 0.28895366"/>
        <site name="burner_rear_left_place_site" type="cylinder" rgba="0.5 0 0 0" size="0.07675307989120483 4.999999873689376e-05" pos="-0.19991663 0.12864677 0.28895366"/>
        <site name="burner_front_right_place_site" type="cylinder" rgba="0.5 0 0 0" size="0.07978937029838562 4.999999873689376e-05" pos="0.19051448 -0.15064779 0.28895366"/>
        <site name="burner_rear_right_place_site" type="cylinder" rgba="0.5 0 0 0" size="0.09814763814210892 4.999999509891495e-05" pos="0.19729567 0.11031708 0.28895366"/>
        <geom class="region" name="reg_main" type="box" pos="-9.999999994736442e-09 0.028679709999999997 -0.13877899999999999" size="0.38164241 0.32940537999999997 0.42868264"/>
      </body>
    </body>
  </worldbody>
  <actuator>
    <motor name="door_joint_actuator" joint="door_joint" gear="50"/>
    <motor name="knob_front_left_joint_actuator" joint="knob_front_left_joint" gear="50"/>
    <motor name="knob_front_right_joint_actuator" joint="knob_front_right_joint" gear="50"/>
    <motor name="knob_rear_left_joint_actuator" joint="knob_rear_left_joint" gear="50"/>
    <motor name="knob_rear_right_joint_actuator" joint="knob_rear_right_joint" gear="50"/>
    <motor name="knob_temp_joint_actuator" joint="knob_temp_joint" gear="50"/>
    <motor name="knob_time_joint_actuator" joint="knob_time_joint" gear="50"/>
    <motor name="rack0_joint_actuator" joint="rack0_joint" gear="50"/>
    <motor name="rack1_joint_actuator" joint="rack1_joint" gear="50"/>
  </actuator>
</mujoco>
