<?xml version='1.0' encoding='UTF-8'?>
<mujoco model="model">
  <option timestep="0.002" gravity="0.0 0.0 -9.81"/>
  <compiler angle="radian"/>
  <asset>
    <mesh file="visuals/freezer0.obj" name="freezer0_vis"/>
    <mesh file="visuals/fridge_door.obj" name="fridge_door_vis"/>
    <mesh file="visuals/fridge_door_Clear.obj" name="fridge_door_Clear_vis"/>
    <mesh file="visuals/fridge_drawer0.obj" name="fridge_drawer0_vis"/>
    <mesh file="visuals/Body001.obj" name="Body001_vis"/>
    <mesh file="visuals/Body001_Clear.obj" name="Body001_Clear_vis"/>
    <texture file="visuals/T_BC001.png" name="Body001_material" type="2d"/>
    <material name="Body001_material" rgba="1 1 1 1.0" texture="Body001_material" shininess="0.1" specular="5"/>
    <texture file="visuals/T_BC001.png" name="freezer0_material" type="2d"/>
    <material name="freezer0_material" rgba="1 1 1 1.0" texture="freezer0_material" shininess="0.1" specular="5"/>
    <texture file="visuals/T_BC001.png" name="fridge_door_material" type="2d"/>
    <material name="fridge_door_material" rgba="1 1 1 1.0" texture="fridge_door_material" shininess="0.1" specular="5"/>
    <material name="fridge_door_Clear_material" rgba="0.6450700759887695 0.6450700759887695 0.6450700759887695 0.699999988079071" shininess="0.5" specular="0.3103448502657381"/>
    <texture file="visuals/T_BC001.png" name="fridge_drawer0_material" type="2d"/>
    <material name="fridge_drawer0_material" rgba="1 1 1 1.0" texture="fridge_drawer0_material" shininess="0.1" specular="3"/>
    <material name="Body001_Clear_material" rgba="0.6450700759887695 0.6450700759887695 0.6450700759887695 0.699999988079071" shininess="0.5" specular="0.3103448502657381"/>
  </asset>
  <default>
    <default class="visual">
      <geom conaffinity="0" contype="0" group="1" type="mesh"/>
    </default>
    <default class="collision">
      <geom group="0" rgba="0.5 0 0 0.5"/>
    </default>
    <default class="spawn">
      <geom group="0" rgba="1 1 1 0.5" contype="0" conaffinity="0"/>
      <site group="0" rgba="1 1 1 0.5"/>
    </default>
    <default class="region">
      <geom group="1" conaffinity="0" contype="0" rgba="0 1 0 0"/>
    </default>
  </default>
  <worldbody>
    <body>
      <body name="object">
        <geom mesh="Body001_vis" type="mesh" solimp="0.998 0.998 0.001" solref="0.001 1" friction="0.95 0.3 0.1" class="visual" material="Body001_material"/>
        <geom class="collision" type="box" pos="-0.00000010 0.06226730 -0.87054509" size="0.3977836072444916 0.3265019655227661 0.030567556619644165" quat="1.0 0.0 0.0 0.0"/>
        <geom class="collision" type="box" pos="-0.00000010 0.37655068 -0.00563122" size="0.3978986442089081 0.02225613035261631 0.8913357257843018" quat="1.0 0.0 0.0 0.0"/>
        <geom class="collision" type="box" pos="0.38503176 0.06721333 -0.00563122" size="0.025028934702277184 0.33159351348876953 0.8913357257843018" quat="1.0 0.0 0.0 0.0"/>
        <geom class="collision" type="box" pos="-0.38610706 0.06721334 -0.00563122" size="0.025013392791152 0.33159351348876953 0.8913357257843018" quat="1.0 0.0 0.0 0.0"/>
        <geom class="collision" type="box" pos="-0.00170761 0.06721334 0.86624122" size="0.40111514925956726 0.3315935432910919 0.02416747249662876" quat="1.0 0.0 0.0 0.0"/>
        <geom class="collision" type="box" pos="-0.00076633 0.10481304 0.53163707" size="0.3590417206287384 0.2529040575027466 0.006610413547605276" quat="1.0 0.0 0.0 0.0"/>
        <geom class="collision" type="box" pos="-0.00076633 0.10212279 0.20541735" size="0.35904252529144287 0.25602906942367554 0.006610425654798746" quat="1.0 0.0 0.0 0.0"/>
        <geom class="collision" type="box" pos="-0.00002157 0.06883793 -0.13832755" size="0.3557049334049225 0.3299690783023834 0.029622908681631088" quat="1.0 0.0 0.0 0.0"/>
        <geom class="collision" type="box" pos="0.35061234 0.12823511 0.18080047" size="0.004796578083187342 0.19992709159851074 0.016412153840065002" quat="1.0 0.0 0.0 0.0"/>
        <geom class="collision" type="box" pos="0.35061234 0.12823511 0.50645566" size="0.0047965575940907 0.19992709159851074 0.016412153840065002" quat="1.0 0.0 0.0 0.0"/>
        <geom class="collision" type="box" pos="-0.35384405 0.12823511 0.50645566" size="0.0044158645905554295 0.19992709159851074 0.016412153840065002" quat="1.0 0.0 0.0 0.0"/>
        <geom class="collision" type="box" pos="-0.35330912 0.12823511 0.17864893" size="0.0049507757648825645 0.19992709159851074 0.016412153840065002" quat="1.0 0.0 0.0 0.0"/>
        <body name="freezer0">
          <geom class="region" name="reg_freezer0" type="box" pos="-0.0033376499999999976 -0.0027683299999999994 -0.5183605250000001" size="0.26670320000000003 0.23685787000000003 0.200375005"/>
          <joint axis="0.0 -1.0 0.0" pos="0.00033486 -0.06141864 -0.50902092" limited="true" name="freezer0_door_joint" range="0.0 0.5" type="slide" damping="1" frictionloss="1" armature=".01" stiffness="0.05"/>
          <geom mesh="freezer0_vis" type="mesh" solimp="0.998 0.998 0.001" solref="0.001 1" friction="0.95 0.3 0.1" class="visual" material="freezer0_material"/>
          <geom class="collision" type="box" pos="-0.29664779 -0.37693404 -0.19838613" size="0.010743711143732071 0.022466136142611504 0.022289980202913284" quat="1.0 0.0 0.0 0.0" name="freezer0_door_handle_1"/>
          <geom class="collision" type="box" pos="0.30421209 -0.37693404 -0.19838625" size="0.010743711143732071 0.022466136142611504 0.022289980202913284" quat="1.0 0.0 0.0 0.0" name="freezer0_door_handle_2"/>
          <geom class="collision" type="box" pos="0.00339945 -0.39041822 -0.19450402" size="0.2889271676540375 0.008723885752260685 0.018406620249152184" quat="1.0 0.0 0.0 0.0" name="freezer0_door_handle_main"/>
          <geom class="collision" type="box" pos="-0.00057559 -0.31501611 -0.51392329" size="0.4054991602897644 0.03805540129542351 0.3741016387939453" quat="1.0 0.0 0.0 0.0" name="freezer0_door_main"/>
          <geom class="collision" type="box" pos="0.00402964 -0.28899830 -0.51392329" size="0.31278368830680847 0.009650426916778088 0.37410208582878113" quat="1.0 0.0 0.0 0.0"/>
          <geom class="collision" type="box" pos="-0.00487806 0.00703855 -0.74308032" size="0.3122229278087616 0.2693924307823181 0.018875669687986374" quat="1.0 0.0 0.0 0.0"/>
          <geom class="collision" type="box" pos="0.28860590 0.00703855 -0.51638526" size="0.01873895712196827 0.2693924307823181 0.20780302584171295" quat="1.0 0.0 0.0 0.0"/>
          <geom class="collision" type="box" pos="-0.29645371 0.00703855 -0.51633507" size="0.019839731976389885 0.2693924307823181 0.20775285363197327" quat="1.0 0.0 0.0 0.0"/>
          <geom class="collision" type="box" pos="-0.00467552 0.25812814 -0.51633507" size="0.2765098810195923 0.01830284297466278 0.20775285363197327" quat="1.0 0.0 0.0 0.0"/>
          <geom class="collision" type="box" pos="0.00032192 -0.26399141 -0.50795209" size="0.35030752420425415 0.012249666266143322 0.328917920589447" quat="1.0 0.0 0.0 0.0"/>
        </body>
        <body name="fridge_door">
          <joint axis="0.0 0.0 1.0" pos="0.36623138 -0.31620973 0.44672972" limited="true" name="fridge_door_joint" range="0.0 1.5707963267948966" type="hinge" damping="1" frictionloss="1" armature=".01" stiffness="0.05"/>
          <geom mesh="fridge_door_vis" type="mesh" solimp="0.998 0.998 0.001" solref="0.001 1" friction="0.95 0.3 0.1" class="visual" material="fridge_door_material"/>
          <geom class="collision" type="box" pos="-0.01138821 -0.33405276 0.38632214" size="0.3680526614189148 0.01901877298951149 0.5154201984405518" quat="1.0 0.0 0.0 0.0" name="fridge_door_main"/>
          <geom class="collision" type="box" pos="-0.28425997 -0.39387458 0.35853699" size="0.02228936366736889 0.012253968976438046 0.3276068866252899" quat="1.0 0.0 0.0 0.0" name="fridge_door_handle_main"/>
          <geom class="collision" type="box" pos="-0.28426063 -0.38392048 0.04118982" size="0.022289982065558434 0.022466136142611504 0.010743709281086922" quat="1.0 0.0 0.0 0.0" name="fridge_door_handle_2"/>
          <geom class="collision" type="box" pos="-0.28426045 -0.38392048 0.67963934" size="0.022289982065558434 0.022466136142611504 0.010743709281086922" quat="1.0 0.0 0.0 0.0" name="fridge_door_handle_1"/>
          <geom class="collision" type="box" pos="0.01145817 -0.21528206 0.68677312" size="0.2946494519710541 0.029849542304873466 0.004677204415202141" quat="1.0 0.0 0.0 0.0"/>
          <geom class="collision" type="box" pos="0.00404008 -0.16789669 0.72590888" size="0.30405333638191223 0.006379380356520414 0.04044532775878906" quat="1.0 0.0 0.0 0.0"/>
          <geom class="collision" type="box" pos="0.00404007 -0.25276988 0.72886366" size="0.3040008544921875 0.0053335330449044704 0.041201893240213394" quat="1.0 0.0 0.0 0.0"/>
          <geom class="collision" type="box" pos="-0.29951131 -0.21528204 0.72988063" size="0.0063467444851994514 0.04173363372683525 0.038186654448509216" quat="1.0 0.0 0.0 0.0"/>
          <geom class="collision" type="box" pos="0.30275834 -0.21528204 0.72988063" size="0.006346755661070347 0.04173371195793152 0.03818652406334877" quat="1.0 0.0 0.0 0.0"/>
          <geom class="collision" type="box" pos="0.30275834 -0.21528204 0.58159924" size="0.006346768233925104 0.04173378273844719 0.024467360228300095" quat="1.0 0.0 0.0 0.0"/>
          <geom class="collision" type="box" pos="-0.29951137 -0.21528204 0.58159924" size="0.006346782203763723 0.04173386096954346 0.02446729503571987" quat="1.0 0.0 0.0 0.0"/>
          <geom class="collision" type="box" pos="0.00404003 -0.25276988 0.58058238" size="0.3040028512477875 0.005333579145371914 0.027482343837618828" quat="1.0 0.0 0.0 0.0"/>
          <geom class="collision" type="box" pos="0.00404004 -0.16809849 0.57762748" size="0.3040449023246765 0.006177580915391445 0.02672436833381653" quat="1.0 0.0 0.0 0.0"/>
          <geom class="collision" type="box" pos="0.01145816 -0.21528204 0.55220830" size="0.2946481704711914 0.04173408821225166 0.004676942713558674" quat="1.0 0.0 0.0 0.0"/>
          <geom class="collision" type="box" pos="0.01145812 -0.21528204 0.38782135" size="0.29464855790138245 0.04173416644334793 0.004676926881074905" quat="1.0 0.0 0.0 0.0"/>
          <geom class="collision" type="box" pos="0.00404000 -0.16722868 0.43042791" size="0.3040412962436676 0.0070473914965987206 0.043914034962654114" quat="1.0 0.0 0.0 0.0"/>
          <geom class="collision" type="box" pos="0.00403999 -0.25276988 0.43338269" size="0.30400487780570984 0.005333625245839357 0.04467136412858963" quat="1.0 0.0 0.0 0.0"/>
          <geom class="collision" type="box" pos="-0.29951143 -0.21528204 0.43439960" size="0.006346870679408312 0.041734375059604645 0.041656117886304855" quat="1.0 0.0 0.0 0.0"/>
          <geom class="collision" type="box" pos="0.30275828 -0.21528204 0.43439960" size="0.006346881855279207 0.04173445329070091 0.04165598750114441" quat="1.0 0.0 0.0 0.0"/>
          <geom class="collision" type="box" pos="0.30275816 -0.21528204 0.14418004" size="0.0063468944281339645 0.04173452407121658 0.04165585711598396" quat="1.0 0.0 0.0 0.0"/>
          <geom class="collision" type="box" pos="-0.29951149 -0.21528204 0.14418003" size="0.006346908397972584 0.04173460230231285 0.04165572673082352" quat="1.0 0.0 0.0 0.0"/>
          <geom class="collision" type="box" pos="0.00403991 -0.25276988 0.14316314" size="0.3040069043636322 0.005333671811968088 0.0446707159280777" quat="1.0 0.0 0.0 0.0"/>
          <geom class="collision" type="box" pos="0.00403991 -0.17024403 0.14020833" size="0.3040328621864319 0.0040320442058146 0.043912600725889206" quat="1.0 0.0 0.0 0.0"/>
          <geom class="collision" type="box" pos="0.01145803 -0.21528204 0.09760179" size="0.29465219378471375 0.04173482581973076 0.004676781129091978" quat="1.0 0.0 0.0 0.0"/>
          <geom class="collision" type="box" pos="-0.00324339 -0.31100076 0.38868397" size="0.31383344531059265 0.021568071097135544 0.5091606378555298" quat="1.0 0.0 0.0 0.0"/>
          <geom class="collision" type="box" pos="0.00071578 -0.26449730 0.36540526" size="0.34871506690979004 0.027882946655154228 0.4683062732219696" quat="1.0 0.0 0.0 0.0"/>
          <body name="fridge_door_Clear">
            <geom mesh="fridge_door_Clear_vis" type="mesh" solimp="0.998 0.998 0.001" solref="0.001 1" friction="0.95 0.3 0.1" class="visual" material="fridge_door_Clear_material"/>
            <geom class="collision" type="box" pos="0.01145817 -0.21528206 0.68677312" size="0.2946494519710541 0.029849542304873466 0.004677204415202141" quat="1.0 0.0 0.0 0.0"/>
            <geom class="collision" type="box" pos="0.00404008 -0.16789669 0.72590888" size="0.30405333638191223 0.006379380356520414 0.04044532775878906" quat="1.0 0.0 0.0 0.0"/>
            <geom class="collision" type="box" pos="0.00404007 -0.25276988 0.72886366" size="0.3040008544921875 0.0053335330449044704 0.041201893240213394" quat="1.0 0.0 0.0 0.0"/>
            <geom class="collision" type="box" pos="-0.29951131 -0.21528204 0.72988063" size="0.0063467444851994514 0.04173363372683525 0.038186654448509216" quat="1.0 0.0 0.0 0.0"/>
            <geom class="collision" type="box" pos="0.30275834 -0.21528204 0.72988063" size="0.006346755661070347 0.04173371195793152 0.03818652406334877" quat="1.0 0.0 0.0 0.0"/>
            <geom class="collision" type="box" pos="0.30275834 -0.21528204 0.58159924" size="0.006346768233925104 0.04173378273844719 0.024467360228300095" quat="1.0 0.0 0.0 0.0"/>
            <geom class="collision" type="box" pos="-0.29951137 -0.21528204 0.58159924" size="0.006346782203763723 0.04173386096954346 0.02446729503571987" quat="1.0 0.0 0.0 0.0"/>
            <geom class="collision" type="box" pos="0.00404003 -0.25276988 0.58058238" size="0.3040028512477875 0.005333579145371914 0.027482343837618828" quat="1.0 0.0 0.0 0.0"/>
            <geom class="collision" type="box" pos="0.00404004 -0.16809849 0.57762748" size="0.3040449023246765 0.006177580915391445 0.02672436833381653" quat="1.0 0.0 0.0 0.0"/>
            <geom class="collision" type="box" pos="0.01145816 -0.21528204 0.55220830" size="0.2946481704711914 0.04173408821225166 0.004676942713558674" quat="1.0 0.0 0.0 0.0"/>
            <geom class="collision" type="box" pos="0.01145812 -0.21528204 0.38782135" size="0.29464855790138245 0.04173416644334793 0.004676926881074905" quat="1.0 0.0 0.0 0.0"/>
            <geom class="collision" type="box" pos="0.00404000 -0.16722868 0.43042791" size="0.3040412962436676 0.0070473914965987206 0.043914034962654114" quat="1.0 0.0 0.0 0.0"/>
            <geom class="collision" type="box" pos="0.00403999 -0.25276988 0.43338269" size="0.30400487780570984 0.005333625245839357 0.04467136412858963" quat="1.0 0.0 0.0 0.0"/>
            <geom class="collision" type="box" pos="-0.29951143 -0.21528204 0.43439960" size="0.006346870679408312 0.041734375059604645 0.041656117886304855" quat="1.0 0.0 0.0 0.0"/>
            <geom class="collision" type="box" pos="0.30275828 -0.21528204 0.43439960" size="0.006346881855279207 0.04173445329070091 0.04165598750114441" quat="1.0 0.0 0.0 0.0"/>
            <geom class="collision" type="box" pos="0.30275816 -0.21528204 0.14418004" size="0.0063468944281339645 0.04173452407121658 0.04165585711598396" quat="1.0 0.0 0.0 0.0"/>
            <geom class="collision" type="box" pos="-0.29951149 -0.21528204 0.14418003" size="0.006346908397972584 0.04173460230231285 0.04165572673082352" quat="1.0 0.0 0.0 0.0"/>
            <geom class="collision" type="box" pos="0.00403991 -0.25276988 0.14316314" size="0.3040069043636322 0.005333671811968088 0.0446707159280777" quat="1.0 0.0 0.0 0.0"/>
            <geom class="collision" type="box" pos="0.00403991 -0.17024403 0.14020833" size="0.3040328621864319 0.0040320442058146 0.043912600725889206" quat="1.0 0.0 0.0 0.0"/>
            <geom class="collision" type="box" pos="0.01145803 -0.21528204 0.09760179" size="0.29465219378471375 0.04173482581973076 0.004676781129091978" quat="1.0 0.0 0.0 0.0"/>
          </body>
        </body>
        <body name="fridge_drawer0">
          <geom class="region" name="reg_fridge_drawer0" type="box" pos="-0.04453169000000001 0.09157899 0.00245803" size="0.25507402 0.2011457 0.0637544"/>
          <joint axis="0.0 -1.0 0.0" pos="-0.04488392 0.09107547 -0.01087648" limited="true" name="fridge_drawer0_joint" range="0.0 0.5" type="slide" damping="1" frictionloss="1" armature=".01" stiffness="0.05"/>
          <geom mesh="fridge_drawer0_vis" type="mesh" solimp="0.998 0.998 0.001" solref="0.001 1" friction="0.95 0.3 0.1" class="visual" material="fridge_drawer0_material"/>
          <geom class="collision" type="box" pos="-0.04911367 0.09023716 -0.08040467" size="0.2948463261127472 0.21845440566539764 0.014278902672231197" quat="1.0 0.0 0.0 0.0"/>
          <geom class="collision" type="box" pos="-0.32748601 0.09364101 -0.01058818" size="0.22013039886951447 0.0831819549202919 0.018035607412457466" quat="0.5145353078842163 -0.48502933979034424 0.4850291907787323 -0.5145353674888611"/>
          <geom class="collision" type="box" pos="0.23783022 0.09364100 -0.01093307" size="0.22013039886951447 0.08299592137336731 0.012971624732017517" quat="0.4723641872406006 -0.5261863470077515 0.5261863470077515 -0.472364217042923"/>
          <geom class="collision" type="box" pos="-0.04138430 0.32111735 -0.01038204" size="0.30322352051734924 0.015275704674422741 0.08243141323328018" quat="1.0 0.0 0.0 0.0"/>
          <geom class="collision" type="box" pos="-0.30509102 -0.13092888 -0.01276607" size="0.03656391054391861 0.08267837017774582 0.00840185210108757" quat="1.0655899984612915e-07 -6.711309730178527e-09 0.7501555681228638 -0.6612613797187805"/>
          <geom class="collision" type="box" pos="-0.04864023 -0.13092885 -0.01276603" size="0.08899256587028503 0.08267835527658463 0.008401861414313316" quat="1.0655899984612915e-07 -6.711309730178527e-09 0.7501555681228638 -0.6612613797187805"/>
          <geom class="collision" type="box" pos="0.21372859 -0.13092879 -0.01276599" size="0.04170628637075424 0.08267837017774582 0.00840185210108757" quat="1.0655899984612915e-07 -6.711309730178527e-09 0.7501555681228638 -0.6612613797187805"/>
          <geom class="collision" type="box" pos="0.10555298 -0.12886555 -0.02908066" size="0.06770288199186325 0.06623376160860062 0.00840185210108757" quat="1.0655899984612915e-07 -6.711309730178527e-09 0.7501555681228638 -0.6612613797187805"/>
          <geom class="collision" type="box" pos="-0.20273542 -0.12886559 -0.02908071" size="0.06770288199186325 0.06623376160860062 0.00840185210108757" quat="1.0655899984612915e-07 -6.711309730178527e-09 0.7501555681228638 -0.6612613797187805"/>
        </body>
        <body name="Body001_Clear">
          <geom mesh="Body001_Clear_vis" type="mesh" solimp="0.998 0.998 0.001" solref="0.001 1" friction="0.95 0.3 0.1" class="visual" material="Body001_Clear_material"/>
          <geom class="collision" type="box" pos="-0.00076633 0.10481304 0.53163707" size="0.3590417206287384 0.2529040575027466 0.006610413547605276" quat="1.0 0.0 0.0 0.0"/>
          <geom class="collision" type="box" pos="-0.00076633 0.10212279 0.20541735" size="0.35904252529144287 0.25602906942367554 0.006610425654798746" quat="1.0 0.0 0.0 0.0"/>
        </body>
        <geom class="region" name="reg_fridge_shelf0" type="box" pos="-0.0015748750000000034 0.101468915 0.368839555" size="0.34362025500000004 0.24720060500000002 0.151714345"/>
        <geom class="region" name="reg_fridge_shelf1" type="box" pos="4.233500000000445e-05 0.101468915 0.68996051" size="0.355789865 0.24720060500000002 0.14755021000000001"/>
        <geom class="region" name="reg_main" type="box" pos="-0.0005298599999999931 0.022867760000000015 0.0003144099999999872" size="0.41158877 0.37693913 0.90242709"/>
      </body>
    </body>
  </worldbody>
  <actuator>
    <motor name="freezer0_door_joint_actuator" joint="freezer0_door_joint" gear="50"/>
    <motor name="fridge_door_joint_actuator" joint="fridge_door_joint" gear="50"/>
    <motor name="fridge_drawer0_joint_actuator" joint="fridge_drawer0_joint" gear="50"/>
  </actuator>
</mujoco>
