<?xml version='1.0' encoding='UTF-8'?>
<mujoco model="model">
  <option timestep="0.002" gravity="0.0 0.0 -9.81"/>
  <compiler angle="radian"/>
  <asset>
    <mesh file="visuals/button_cancel.obj" name="button_cancel_vis"/>
    <mesh file="visuals/knob_doneness.obj" name="knob_doneness_vis"/>
    <mesh file="visuals/lever.obj" name="lever_vis"/>
    <mesh file="visuals/Body001.obj" name="Body001_vis"/>
    <texture file="visuals/T_BC001.png" name="Body001_material" type="2d"/>
    <material name="Body001_material" rgba="1 1 1 1.0" texture="Body001_material" shininess="0.1" specular="2"/>
    <texture file="visuals/T_BC001.png" name="button_cancel_material" type="2d"/>
    <material name="button_cancel_material" rgba="1 1 1 1.0" texture="button_cancel_material" shininess="0.1" specular="5"/>
    <texture file="visuals/T_BC001.png" name="knob_doneness_material" type="2d"/>
    <material name="knob_doneness_material" rgba="1 1 1 1.0" texture="knob_doneness_material" shininess="0.1" specular="5"/>
    <texture file="visuals/T_BC001.png" name="lever_material" type="2d"/>
    <material name="lever_material" rgba="1 1 1 1.0" texture="lever_material" shininess="0.1" specular="5"/>
  </asset>
  <default>
    <default class="visual">
      <geom conaffinity="0" contype="0" group="1" type="mesh"/>
    </default>
    <default class="collision">
      <geom group="0" rgba="0.5 0 0 0.5" density="1.0" solref="0.004 1" solimp="0.998 0.998 0.001"/>
    </default>
    <default class="spawn">
      <geom group="0" rgba="1 1 1 0.5" contype="0" conaffinity="0"/>
      <site group="0" rgba="1 1 1 0.5"/>
    </default>
    <default class="region">
      <geom group="1" conaffinity="0" contype="0" rgba="0 1 0 0" mass="0"/>
    </default>
  </default>
  <worldbody>
    <body>
      <body name="object">
        <geom mesh="Body001_vis" type="mesh" solimp="0.998 0.998 0.001" solref="0.001 1" friction="0.95 0.3 0.1" class="visual" material="Body001_material"/>
        <geom type="box" pos="0.07995411 0.01193782 -0.07610797" size="0.014542440883815289 0.10054586827754974 0.017481181770563126" quat="1.0 0.0 0.0 0.0" class="collision"/>
        <geom type="box" pos="0.00311299 0.03200804 -0.07755999" size="0.06174801290035248 0.1294039934873581 0.01602945849299431" quat="1.0 0.0 0.0 0.0" class="collision"/>
        <geom type="box" pos="-0.03007856 -0.11924477 -0.00821666" size="0.004592621233314276 0.022327106446027756 0.04812109097838402" quat="0.6995007991790771 -0.10343456268310547 -0.10343454033136368 -0.6995007395744324" class="collision"/>
        <geom type="box" pos="-0.05539701 0.01143686 0.01356997" size="0.021451249718666077 0.07161376625299454 0.07136571407318115" quat="1.0 0.0 0.0 0.0" class="collision"/>
        <geom type="box" pos="0.00817603 -0.08308579 0.05715346" size="0.002502724528312683 0.0726308599114418 0.02327120490372181" quat="0.6573383808135986 -0.26058828830718994 -0.26058831810951233 -0.6573383808135986" class="collision"/>
        <geom type="box" pos="0.00765685 0.10732802 0.05261945" size="0.0046866275370121 0.06454508751630783 0.024401754140853882" quat="0.6426793336868286 0.2948952317237854 0.2948951721191406 -0.6426794528961182" class="collision"/>
        <geom type="box" pos="0.00831358 0.14286351 -0.00553612" size="0.005211534909904003 0.05779324099421501 0.04224405437707901" quat="0.6941097974777222 0.13495059311389923 0.13495059311389923 -0.6941097378730774" class="collision"/>
        <geom type="box" pos="-0.06729573 0.01193782 -0.07610798" size="0.007737354375422001 0.09924645721912384 0.017481181770563126" quat="1.0 0.0 0.0 0.0" class="collision"/>
        <geom type="box" pos="0.07879391 0.01177473 0.01003026" size="0.020231017842888832 0.01929529942572117 0.06739110499620438" quat="1.0 0.0 0.0 0.0" class="collision"/>
        <geom type="box" pos="0.04466822 -0.11954803 -0.00821666" size="0.004592621233314276 0.022276654839515686 0.04812109097838402" quat="0.6995007991790771 -0.10343456268310547 -0.10343454033136368 -0.6995007395744324" class="collision"/>
        <geom type="box" pos="0.08637694 0.01177473 0.08507983" size="0.01264798641204834 0.01929529756307602 0.007232503034174442" quat="1.0 0.0 0.0 0.0" class="collision"/>
        <geom type="box" pos="0.07753234 0.04467372 0.01453649" size="0.018969442695379257 0.012852965854108334 0.07189734280109406" quat="1.0 0.0 0.0 0.0" class="collision"/>
        <geom type="box" pos="0.07401790 0.06425880 0.00991196" size="0.015615900978446007 0.006388598121702671 0.06727281212806702" quat="1.0 0.0 0.0 0.0" class="collision"/>
        <geom type="box" pos="0.07967458 0.08332032 0.00597270" size="0.00688891252502799 0.012129663489758968 0.06333354860544205" quat="1.0 0.0 0.0 0.0" class="collision"/>
        <geom type="box" pos="0.07569745 0.11273367 -0.01167273" size="0.0029117814265191555 0.018001191318035126 0.04792827367782593" quat="0.9785745143890381 0.0 0.0 0.2058929204940796" class="collision"/>
        <geom type="box" pos="0.07662286 -0.02727097 0.01324527" size="0.018188288435339928 0.01929529942572117 0.07042040675878525" quat="1.0 0.0 0.0 0.0" class="collision"/>
        <geom type="box" pos="0.07809008 -0.06650219 -0.00512851" size="0.007417436223477125 0.01929529383778572 0.0585048608481884" quat="1.0 0.0 0.0 0.0" class="collision"/>
        <geom type="box" pos="-0.06341299 -0.06461869 -0.01033434" size="0.015201675705611706 0.005573458503931761 0.04746139794588089" quat="0.8313593864440918 0.0 0.0 -0.555735170841217" class="collision"/>
        <geom type="box" pos="-0.05897756 0.10753660 -0.01552221" size="0.02807500772178173 0.005805022083222866 0.04227353259921074" quat="0.5618603825569153 0.0 0.0 -0.8272320628166199" class="collision"/>
        <geom type="box" pos="0.04986029 0.01143685 0.00527874" size="0.0032877642661333084 0.05927024409174919 0.06345353275537491" quat="1.0 0.0 0.0 0.0" class="collision"/>
        <geom type="box" pos="0.01537224 0.01143685 0.00527874" size="0.0032877642661333084 0.059270404279232025 0.06345353275537491" quat="1.0 0.0 0.0 0.0" class="collision"/>
        <geom type="box" pos="-0.00099103 0.01143685 0.00527874" size="0.0032877642661333084 0.05927056074142456 0.06345353275537491" quat="1.0 0.0 0.0 0.0" class="collision"/>
        <geom type="box" pos="0.00765641 0.08361254 0.00527874" size="0.04881077632308006 0.00226442888379097 0.06345444917678833" quat="1.0 0.0 0.0 0.0" class="collision"/>
        <geom type="box" pos="0.00742166 0.01143685 -0.08365900" size="0.041584741324186325 0.0592716820538044 0.0032878220081329346" quat="1.0 0.0 0.0 0.0" class="collision"/>
        <geom type="box" pos="0.00787915 0.01143685 0.00569410" size="0.005373402498662472 0.07400724291801453 0.06345353275537491" quat="1.0 0.0 0.0 0.0" class="collision"/>
        <geom type="box" pos="-0.02439034 -0.11795067 -0.07375142" size="0.024103136733174324 0.015007250010967255 0.020663296803832054" quat="1.0 0.0 0.0 0.0" class="collision"/>
        <geom type="box" pos="0.04034466 -0.11795067 -0.07345399" size="0.024103136733174324 0.015007233247160912 0.020365871489048004" quat="1.0 0.0 0.0 0.0" class="collision"/>
        <geom type="box" pos="0.00831358 0.15697702 -0.06382058" size="0.06075524911284447 0.008561155758798122 0.016415223479270935" quat="1.0 0.0 0.0 0.0" class="collision"/>
        <geom type="box" pos="-0.05370076 0.12809795 -0.06465111" size="0.02807500772178173 0.005805022083222866 0.016195213422179222" quat="0.5618603825569153 0.0 0.0 -0.8272320628166199" class="collision"/>
        <geom type="box" pos="-0.06134303 0.09898453 0.04252267" size="0.017378438264131546 0.005805022083222866 0.016195213422179222" quat="0.5618603825569153 0.0 0.0 -0.8272320628166199" class="collision"/>
        <geom type="box" pos="0.06939867 0.12976948 -0.05949153" size="0.0029117814265191555 0.018001191318035126 0.027560563758015633" quat="0.9785745143890381 0.0 0.0 0.2058929204940796" class="collision"/>
        <geom type="box" pos="-0.06140694 -0.08813035 -0.01844112" size="0.02807501144707203 0.003740153042599559 0.04227353259921074" quat="0.8322839736938477 3.382598715018226e-11 -6.188514978244797e-11 -0.5543495416641235" class="collision"/>
        <geom type="box" pos="-0.05755575 -0.10533379 -0.07333124" size="0.02807500772178173 0.003740153508260846 0.02017604000866413" quat="0.8322839736938477 3.382598715018226e-11 -6.188514978244797e-11 -0.5543495416641235" class="collision"/>
        <geom type="box" pos="-0.06446599 -0.07348762 0.04192634" size="0.015610792674124241 0.0037401539739221334 0.0159356277436018" quat="0.8322839736938477 3.382598715018226e-11 -6.188514978244797e-11 -0.5543495416641235" class="collision"/>
        <geom type="box" pos="0.07419545 -0.08480692 0.04192634" size="0.015610792674124241 0.00374015374109149 0.0159356277436018" quat="0.5618346333503723 7.995309275754536e-12 -7.007171232142895e-11 -0.8272495865821838" class="collision"/>
        <geom type="box" pos="0.07473908 -0.09567655 -0.01686900" size="0.02807501144707203 0.003740153042599559 0.04227353259921074" quat="0.5358457565307617 5.813076148913909e-12 -7.028639475992193e-11 -0.8443158864974976" class="collision"/>
        <geom type="box" pos="0.07192608 -0.10522326 -0.07449258" size="0.02807500772178173 0.003740153508260846 0.01844950206577778" quat="0.5495603680610657 6.959966023650788e-12 -7.018212400122792e-11 -0.8354540467262268" class="collision"/>
        <body name="button_cancel">
          <joint axis="1.0 0.0 0.0" pos="-0.08500830 0.01312438 0.01000324" limited="true" name="button_cancel_joint" range="0.0 0.002" type="slide" damping="1" frictionloss="1" armature=".01" stiffness="0.05"/>
          <geom mesh="button_cancel_vis" type="mesh" solimp="0.998 0.998 0.001" solref="0.001 1" friction="0.95 0.3 0.1" class="visual" material="button_cancel_material"/>
          <geom class="collision" type="box" pos="-0.08690453 0.01318413 0.01002965" size="0.0019101512152701616 0.012177031487226486 0.005377090536057949" quat="1.0 0.0 0.0 0.0" name="button_cancel_main"/>
        </body>
        <body name="knob_doneness">
          <joint axis="1.0 0.0 0.0" pos="-0.08609894 0.01071076 -0.04184528" limited="true" name="knob_doneness_joint" range="0.0 3.979350694547071" type="hinge" damping="0.05" armature="0.001"/>
          <geom mesh="knob_doneness_vis" type="mesh" solimp="0.998 0.998 0.001" solref="0.001 1" friction="0.95 0.3 0.1" class="visual" material="knob_doneness_material"/>
          <geom type="cylinder" pos="-0.08692267 0.01076015 -0.04184527" size="0.0195354912430048 0.0024004741571843624" quat="0.4999999701976776 0.5 -0.5 -0.5" class="collision"/>
          <geom class="collision" type="box" pos="-0.09418806 0.01101058 -0.04184405" size="0.005065132398158312 0.013607240281999111 0.0076972381211817265" quat="1.0 0.0 0.0 0.0" name="knob_doneness_main"/>
        </body>
        <body name="lever">
          <joint axis="0.0 0.0 -1.0" pos="0.00748828 -0.13677711 0.02645147" limited="true" name="lever_joint" range="0.0 0.057999999999999996" type="slide" damping="1" frictionloss="1" armature=".01" stiffness="2" springref="-0.5"/>
          <geom class="region" name="reg_slotL" type="box" pos="-0.01853674 0.009064249999999996 0.07333162" size="0.01455876 0.06996856 0.07599995999999999"/>
          <geom class="region" name="reg_slotR" type="box" pos="0.032481055 0.009064249999999996 0.07333162" size="0.014503105000000002 0.06996856 0.07599995999999999"/>
          <geom mesh="lever_vis" type="mesh" solimp="0.998 0.998 0.001" solref="0.001 1" friction="0.95 0.3 0.1" class="visual" material="lever_material"/>
          <geom class="collision" type="box" pos="0.03295042 0.01099688 -0.00219320" size="0.012846674770116806 0.06511877477169037 0.0004017333558294922" quat="1.0 0.0 0.0 0.0" name="slotR_floor"/>
          <geom class="collision" type="box" pos="0.00735475 -0.15952303 0.03060300" size="0.009018764831125736 0.013510518707334995 0.002691839588806033" quat="0.7032938003540039 -0.07333369553089142 -0.07333367317914963 -0.7032938003540039" name="lever_handle"/>
          <geom type="box" pos="0.00765657 -0.12821833 0.02461120" size="0.02304181642830372 0.0018287213752046227 0.0028551495634019375" quat="0.7046585083007812 -0.05879110470414162 -0.05879107862710953 -0.7046585083007812" class="collision"/>
          <geom class="collision" type="box" pos="-0.01914572 0.01099688 -0.00219320" size="0.012849891558289528 0.06512072682380676 0.0004017296014353633" quat="1.0 0.0 0.0 0.0" name="slotL_floor"/>
        </body>
        <geom class="region" name="reg_main" type="box" pos="0.007753155000000005 0.00948700000000001 0.0" size="0.096002595 0.16162326999999999 0.09458914"/>
      </body>
    </body>
  </worldbody>
  <actuator>
    <motor name="button_cancel_joint_actuator" joint="button_cancel_joint" gear="0.5"/>
    <motor name="knob_doneness_joint_actuator" joint="knob_doneness_joint" gear="0.5"/>
    <motor name="lever_joint_actuator" joint="lever_joint" gear="0.5"/>
  </actuator>
</mujoco>
