<?xml version='1.0' encoding='UTF-8'?>
<mujoco model="model">
  <option timestep="0.002" gravity="0.0 0.0 -9.81"/>
  <compiler angle="radian"/>
  <asset>
    <mesh file="visuals/handle.obj" name="handle_vis"/>
    <mesh file="visuals/Body001.obj" name="Body001_vis"/>
    <mesh file="visuals/Container001.obj" name="Container001_vis"/>
    <mesh file="visuals/Funnel001.obj" name="Funnel001_vis"/>
    <mesh file="visuals/spout.obj" name="spout_vis"/>
    <texture file="visuals/T_BC001.png" name="Body001_material" type="2d"/>
    <material name="Body001_material" rgba="1 1 1 1.0" texture="Body001_material" shininess="0.4472135901451111" specular="1"/>
    <texture file="visuals/T_BC001.png" name="handle_material" type="2d"/>
    <material name="handle_material" rgba="1 1 1 1.0" texture="handle_material" shininess="0.4472135901451111" specular="1"/>
    <texture file="visuals/T_BC001.png" name="Container001_material" type="2d"/>
    <material name="Container001_material" rgba="1 1 1 1.0" texture="Container001_material" shininess="0.4472135901451111" specular="1"/>
    <texture file="visuals/T_BC001.png" name="Funnel001_material" type="2d"/>
    <material name="Funnel001_material" rgba="1 1 1 1.0" texture="Funnel001_material" shininess="0.4472135901451111" specular="3"/>
    <texture file="visuals/T_BC001.png" name="spout_material" type="2d"/>
    <material name="spout_material" rgba="1 1 1 1.0" texture="spout_material" shininess="0.4472135901451111" specular="0.3103448502657381"/>
  </asset>
  <default>
    <default class="visual">
      <geom conaffinity="0" contype="0" group="1" type="mesh"/>
    </default>
    <default class="collision">
      <geom group="0" rgba="0.5 0 0 0.5"/>
    </default>
    <default class="spawn">
      <geom group="0" rgba="1 1 1 0.5" contype="0" conaffinity="0"/>
      <site group="0" rgba="1 1 1 0.5"/>
    </default>
    <default class="region">
      <geom group="1" conaffinity="0" contype="0" rgba="0 1 0 0"/>
    </default>
  </default>
  <worldbody>
    <body>
      <body name="object">
        <geom mesh="Body001_vis" type="mesh" solimp="0.998 0.998 0.001" solref="0.001 1" friction="0.95 0.3 0.1" class="visual" material="Body001_material"/>
        <geom class="collision" type="box" pos="0.07925006002187729 0.1450960338115692 -0.07569845020771027" size="0.1742602437734604 0.02266811951994896 0.0013388915685936809" quat="1.0 0.0 0.0 0.0"/>
        <geom class="collision" type="box" pos="-0.24390165507793427 -0.014135673642158508 -0.07569845020771027" size="0.009608655236661434 0.1381855607032776 0.0013388915685936809" quat="1.0 0.0 0.0 0.0"/>
        <geom class="collision" type="box" pos="0.06694533675909042 -0.1501362919807434 -0.15309575200080872" size="0.16059443354606628 0.0026066654827445745 0.0768933892250061" quat="1.0 0.0 0.0 0.0"/>
        <geom class="collision" type="box" pos="0.24397039413452148 -0.014135673642158508 -0.07569845020771027" size="0.009520158171653748 0.1381855607032776 0.0013388915685936809" quat="1.0 0.0 0.0 0.0"/>
        <geom class="collision" type="box" pos="0.07925005257129669 -0.15836353600025177 -0.07569845020771027" size="0.1742602437734604 0.009400634095072746 0.0013388915685936809" quat="1.0 0.0 0.0 0.0"/>
        <geom class="collision" type="box" pos="0.2301943302154541 0.11907685548067093 -0.15309575200080872" size="0.002092407550662756 0.007040669675916433 0.0768933892250061" quat="0.9178581237792969 0.0 0.0 0.3969086706638336"/>
        <geom class="collision" type="box" pos="0.06694533675909042 0.12310408055782318 -0.15309575200080872" size="0.16059443354606628 0.0026066654827445745 0.0768933892250061" quat="1.0 0.0 0.0 0.0"/>
        <geom class="collision" type="box" pos="-0.23540011048316956 -0.013311982154846191 -0.15309575200080872" size="0.0020924056880176067 0.12659867107868195 0.0768933892250061" quat="1.0 0.0 0.0 0.0"/>
        <geom class="collision" type="box" pos="0.23569124937057495 -0.011899441480636597 -0.15309575200080872" size="0.0020924056880176067 0.12801121175289154 0.0768933892250061" quat="1.0 0.0 0.0 0.0"/>
        <geom class="collision" type="box" pos="0.2301943302154541 -0.14587688446044922 -0.15309575200080872" size="0.002092407550662756 0.007040669675916433 0.0768933892250061" quat="6.929635532060274e-08 -0.3969086706638336 -0.9178581237792969 -2.9965775638629566e-08"/>
        <geom class="collision" type="box" pos="-0.23086193203926086 -0.14587688446044922 -0.15309575200080872" size="0.0020924073178321123 0.007040669210255146 0.0768933892250061" quat="0.3969087302684784 0.0 0.0 -0.9178580641746521"/>
        <geom class="collision" type="box" pos="-0.23086193203926086 0.11907685548067093 -0.15309575200080872" size="0.002092407550662756 0.007040669675916433 0.0768933892250061" quat="6.929635532060274e-08 0.9178581237792969 -0.3969086706638336 -2.9965775638629566e-08"/>
        <geom class="collision" type="box" pos="-0.1363869607448578 -0.013953879475593567 -0.22999568283557892" size="0.0985148623585701 0.13538309931755066 0.0013388987863436341" quat="1.0 0.0 0.0 0.0"/>
        <geom class="collision" type="box" pos="0.13695737719535828 -0.013953879475593567 -0.22999568283557892" size="0.09775062650442123 0.13538309931755066 0.0013388987863436341" quat="1.0 0.0 0.0 0.0"/>
        <geom class="collision" type="box" pos="0.003469545394182205 -0.08808547258377075 -0.22999568283557892" size="0.09775062650442123 0.06125152111053467 0.0013388987863436341" quat="1.0 0.0 0.0 0.0"/>
        <geom class="collision" type="box" pos="0.003469545394182205 0.08454857766628265 -0.22999568283557892" size="0.09775062650442123 0.03620132803916931 0.0013388987863436341" quat="1.0 0.0 0.0 0.0"/>
        <geom class="collision" type="cylinder" pos="-0.0008405912667512894 0.14307278394699097 -0.04296581447124481" size="0.014659702777862549 0.03382165729999542" quat="1.0 0.0 0.0 0.0"/>
        <geom class="collision" type="cylinder" pos="0.013336420990526676 0.14307278394699097 -0.04188588261604309" size="0.01393008790910244 0.011113598942756653" quat="0.7071068286895752 -0.0 0.7071067690849304 0.0"/>
        <geom class="collision" type="box" pos="-0.21935132145881653 0.12310408055782318 -0.15309575200080872" size="0.00652328971773386 0.0026066654827445745 0.0768933892250061" quat="1.0 0.0 0.0 0.0"/>
        <geom class="collision" type="box" pos="-0.23316916823387146 -0.15836353600025177 -0.07569845020771027" size="0.020341139286756516 0.009400634095072746 0.0013388915685936809" quat="1.0 0.0 0.0 0.0"/>
        <geom class="collision" type="box" pos="-0.21935132145881653 -0.1501362919807434 -0.15309575200080872" size="0.00652328971773386 0.0026066654827445745 0.0768933892250061" quat="1.0 0.0 0.0 0.0"/>
        <geom class="collision" type="box" pos="-0.23316916823387146 0.1450960338115692 -0.07569845020771027" size="0.020341139286756516 0.02266811951994896 0.0013388915685936809" quat="1.0 0.0 0.0 0.0"/>
        <geom class="collision" type="box" pos="-0.15328797698020935 -0.15080370008945465 -0.15351323783397675" size="0.0609254390001297 0.0019392507383599877 0.07647588849067688" quat="1.0 0.0 0.0 0.0"/>
        <geom class="collision" type="box" pos="-0.15328797698020935 0.12429545819759369 -0.15351323783397675" size="0.0609254390001297 0.0014152881922200322 0.07647588849067688" quat="1.0 0.0 0.0 0.0"/>
        <geom class="collision" type="box" pos="-0.15415233373641968 0.14863072335720062 -0.07569845020771027" size="0.06198527663946152 0.0191334281116724 0.0013388915685936809" quat="1.0 0.0 0.0 0.0"/>
        <geom class="collision" type="box" pos="-0.15415233373641968 -0.1617404818534851 -0.07569845020771027" size="0.06198527663946152 0.006023674737662077 0.0013388915685936809" quat="1.0 0.0 0.0 0.0"/>
        <geom class="collision" type="cylinder" pos="-1.8930062651634216e-05 0.011154770851135254 -0.2431403547525406" size="0.02953197993338108 0.0045744203962385654" quat="1.0 0.0 0.0 0.0"/>
        <body name="handle">
          <joint axis="0.0 1.0 0.0" pos="0.037631914019584656 0.1429593414068222 -0.04242062568664551" limited="true" name="handle_joint" type="hinge" range="0 0.5" damping="1" frictionloss="1" armature=".01"/>
          <joint axis="1.0 0.0 0.0" pos="0.037631914019584656 0.1429593414068222 -0.04242062568664551" limited="true" name="handle_temp_joint" type="hinge" range="-0.7853981633974483 0.7853981633974483" damping="1" frictionloss="1" armature=".01"/>
          <geom mesh="handle_vis" type="mesh" solimp="0.998 0.998 0.001" solref="0.001 1" friction="0.95 0.3 0.1" class="visual" material="handle_material"/>
          <geom class="collision" type="cylinder" pos="0.038987867534160614 0.14307278394699097 -0.04188588261604309" size="0.015159760601818562 0.006152501329779625" quat="0.7071068286895752 -0.0 0.7071067690849304 0.0" density="0.001"/>
          <geom class="collision" type="cylinder" pos="0.037625763565301895 0.142683744430542 -0.000681199599057436" size="0.0024957298301160336 0.025888843461871147" quat="1.0 0.0 0.0 0.0" density="0.001"/>
        </body>
        <body name="Container001">
          <joint axis="0.0 0.0 1.0" pos="-0.15404802560806274 -0.01304827630519867 -0.09694704413414001" limited="true" name="Container001_joint" range="0.0 0.05" type="slide" damping="1" frictionloss="1" armature=".01" stiffness="0.05"/>
          <geom mesh="Container001_vis" type="mesh" solimp="0.998 0.998 0.001" solref="0.001 1" friction="0.95 0.3 0.1" class="visual" material="Container001_material"/>
          <geom class="collision" type="box" pos="-0.20861363410949707 -0.013145402073860168 -0.09692299365997314" size="0.0016650656471028924 0.13463588058948517 0.02490539662539959" quat="1.0 0.0 0.0 0.0"/>
          <geom class="collision" type="box" pos="-0.15396377444267273 -0.013145402073860168 -0.11997489631175995" size="0.05309569835662842 0.1346360146999359 0.0018537138821557164" quat="1.0 0.0 0.0 0.0"/>
          <geom class="collision" type="box" pos="-0.15404289960861206 -0.14658337831497192 -0.09686517715454102" size="0.05623580142855644 0.0012342454865574837 0.024903645738959312" quat="1.0 0.0 0.0 0.0"/>
          <geom class="collision" type="box" pos="-0.15404289960861206 0.12038091570138931 -0.09686517715454102" size="0.05623580142855644 0.0012342468835413456 0.024903668090701103" quat="1.0 0.0 0.0 0.0"/>
          <geom class="collision" type="box" pos="-0.09946799278259277 -0.013145402073860168 -0.09692299365997314" size="0.0016650656471028924 0.1346365064382553 0.024905474856495857" quat="1.0 0.0 0.0 0.0"/>
        </body>
        <body name="Funnel001">
          <joint axis="0.0 0.0 1.0" pos="-5.84928784519434e-06 0.011282176710665226 -0.22756807506084442" limited="true" name="Funnel001_joint" range="0.0 0.05" type="slide" damping="0" frictionloss="0" armature="0" stiffness="0"/>
          <geom mesh="Funnel001_vis" type="mesh" solimp="0.998 0.998 0.001" solref="0.001 1" friction="0.95 0.3 0.1" class="visual" material="Funnel001_material"/>
          <geom class="collision" type="cylinder" pos="-1.8930062651634216e-05 0.011154770851135254 -0.22947248816490173" size="0.028829501941800117 0.0011463656555861235" quat="1.0 0.0 0.0 0.0"/>
          <geom class="collision" type="cylinder" pos="-1.8930062651634216e-05 0.011154770851135254 -0.22645652294158936" size="0.004685318563133478 0.0022396633867174387" quat="1.0 0.0 0.0 0.0"/>
        </body>
        <body name="spout">
          <joint axis="0.0 0.0 1.0" pos="-0.0007294630631804466 0.14254266023635864 0.09287675470113754" limited="true" name="spout_joint" range="-0.7853981633974483 0.7853981633974483" type="hinge" damping="1" frictionloss="1" armature=".01" stiffness="0.05"/>
          <site type="cylinder" rgba="0.5 0.75 1 0.5" size="0.0050875539891421795 0.16668647527694702" pos="-0.000716126523911953 -0.02056644856929779 -0.0780714750289917" name="water"/>
          <geom mesh="spout_vis" type="mesh" solimp="0.998 0.998 0.001" solref="0.001 1" friction="0.95 0.3 0.1" class="visual" material="spout_material"/>
          <geom class="collision" type="cylinder" pos="-0.0008405912667512894 0.13903528451919556 0.16723482310771942" size="0.009375008754432201 0.015106167644262314" quat="0.9924028515815735 0.12303092330694199 0.0 0.0"/>
          <geom class="collision" type="cylinder" pos="-0.0008405912667512894 0.1422400027513504 0.07334433495998383" size="0.009375008754432201 0.08105318993330002" quat="1.0 0.0 0.0 0.0"/>
          <geom class="collision" type="cylinder" pos="-0.0008405912667512894 0.12861675024032593 0.1926870495080948" size="0.009375008754432201 0.01510616671293974" quat="0.9599521160125732 0.28016406297683716 0.0 0.0"/>
          <geom class="collision" type="cylinder" pos="-0.0008405912667512894 0.11064057797193527 0.21295808255672455" size="0.009375008754432201 0.015106163918972015" quat="0.9006063342094421 0.4346356987953186 0.0 0.0"/>
          <geom class="collision" type="cylinder" pos="-0.0008405912667512894 0.08794724941253662 0.22570712864398956" size="0.009375008754432201 0.015106165781617165" quat="0.8086215853691101 0.5883290767669678 0.0 0.0"/>
          <geom class="collision" type="cylinder" pos="-0.0008405912667512894 0.0603242889046669 0.23042429983615875" size="0.009375008754432201 0.015106165781617165" quat="0.7107754945755005 0.7034189105033875 0.0 0.0"/>
          <geom class="collision" type="cylinder" pos="-0.0008405912667512894 0.03376374393701553 0.22596211731433868" size="0.009375008754432201 0.01510616671293974" quat="0.5772291421890259 0.816582202911377 0.0 0.0"/>
          <geom class="collision" type="cylinder" pos="-0.0008405912667512894 0.009922996163368225 0.21283058822155" size="0.009375008754432201 0.015106165781617165" quat="0.39552512764930725 0.918455183506012 0.0 0.0"/>
          <geom class="collision" type="cylinder" pos="-0.0008405912667512894 -0.007925689220428467 0.19166715443134308" size="0.009375008754432201 0.01510616671293974" quat="0.26599380373954773 0.9639747142791748 0.0 0.0"/>
          <geom class="collision" type="cylinder" pos="-0.0008405912667512894 -0.018634900450706482 0.16655151546001434" size="0.009375008754432201 0.015106165781617165" quat="0.09022616595029831 0.9959213137626648 0.0 0.0"/>
          <geom class="collision" type="cylinder" pos="-0.0008405912667512894 -0.02120049297809601 0.13681872189044952" size="0.009375008754432201 0.015106165781617165" quat="0.0050633493810892105 0.9999871850013733 0.0 0.0"/>
          <geom class="collision" type="cylinder" pos="-0.0008405912667512894 -0.02120049297809601 0.11544255912303925" size="0.0164983831346035 0.02413669228553772" quat="7.549790126404332e-08 0.0 0.0 1.0" name="spout_main"/>
        </body>
        <geom class="region" name="reg_basin" type="box" pos="0.06615446880459785 -0.013232812285423279 -0.15125945955514908" size="0.15863024613261223 0.12813879346847534 0.07273826545476914"/>
        <geom class="region" name="reg_main" type="box" pos="0.0 0.0 -0.1571895331144333" size="0.2545102963447571 0.16876415705680847 0.08361096477508545"/>
      </body>
    </body>
  </worldbody>
  <actuator>
    <motor name="handle_joint_actuator" joint="handle_joint" gear="10"/>
    <motor name="handle_temp_joint_actuator" joint="handle_temp_joint" gear="10"/>
    <motor name="Container001_joint_actuator" joint="Container001_joint" gear="10"/>
    <motor name="Funnel001_joint_actuator" joint="Funnel001_joint" gear="10"/>
    <motor name="spout_joint_actuator" joint="spout_joint" gear="10"/>
  </actuator>
</mujoco>
