<?xml version='1.0' encoding='UTF-8'?>
<mujoco model="model">
  <option timestep="0.002" gravity="0.0 0.0 -9.81"/>
  <compiler angle="radian"/>
  <asset>
    <mesh file="visuals/sideL_button_cancel.obj" name="sideL_button_cancel_vis"/>
    <mesh file="visuals/sideL_knob_doneness.obj" name="sideL_knob_doneness_vis"/>
    <mesh file="visuals/sideL_lever.obj" name="sideL_lever_vis"/>
    <mesh file="visuals/sideR_button_cancel.obj" name="sideR_button_cancel_vis"/>
    <mesh file="visuals/sideR_knob_doneness.obj" name="sideR_knob_doneness_vis"/>
    <mesh file="visuals/sideR_lever.obj" name="sideR_lever_vis"/>
    <mesh file="visuals/Body001.obj" name="Body001_vis"/>
    <mesh file="visuals/Body002.obj" name="Body002_vis"/>
    <texture file="visuals/T_BC001.png" name="Body001_material" type="2d"/>
    <material name="Body001_material" rgba="1 1 1 1.0" texture="Body001_material" shininess="0.5" specular="0.3103448502657381"/>
    <texture file="visuals/T_BC001.png" name="sideL_button_cancel_material" type="2d"/>
    <material name="sideL_button_cancel_material" rgba="1 1 1 1.0" texture="sideL_button_cancel_material" shininess="0.5" specular="0.3103448502657381"/>
    <texture file="visuals/T_BC001.png" name="sideL_knob_doneness_material" type="2d"/>
    <material name="sideL_knob_doneness_material" rgba="1 1 1 1.0" texture="sideL_knob_doneness_material" shininess="0.5" specular="0.3103448502657381"/>
    <texture file="visuals/T_BC001.png" name="sideL_lever_material" type="2d"/>
    <material name="sideL_lever_material" rgba="1 1 1 1.0" texture="sideL_lever_material" shininess="0.5" specular="0.3103448502657381"/>
    <texture file="visuals/T_BC001.png" name="sideR_button_cancel_material" type="2d"/>
    <material name="sideR_button_cancel_material" rgba="1 1 1 1.0" texture="sideR_button_cancel_material" shininess="0.5" specular="0.3103448502657381"/>
    <texture file="visuals/T_BC001.png" name="sideR_knob_doneness_material" type="2d"/>
    <material name="sideR_knob_doneness_material" rgba="1 1 1 1.0" texture="sideR_knob_doneness_material" shininess="0.5" specular="0.3103448502657381"/>
    <texture file="visuals/T_BC001.png" name="sideR_lever_material" type="2d"/>
    <material name="sideR_lever_material" rgba="1 1 1 1.0" texture="sideR_lever_material" shininess="0.5" specular="0.3103448502657381"/>
    <texture file="visuals/T_BC001.png" name="Body002_material" type="2d"/>
    <material name="Body002_material" rgba="1 1 1 1.0" texture="Body002_material" shininess="0.5" specular="0.3103448502657381"/>
  </asset>
  <default>
    <default class="visual">
      <geom conaffinity="0" contype="0" group="1" type="mesh"/>
    </default>
    <default class="collision">
      <geom group="0" rgba="0.5 0 0 0.5" density="1.0" solref="0.004 1" solimp="0.998 0.998 0.001"/>
    </default>
    <default class="spawn">
      <geom group="0" rgba="1 1 1 0.5" contype="0" conaffinity="0"/>
      <site group="0" rgba="1 1 1 0.5"/>
    </default>
    <default class="region">
      <geom group="1" conaffinity="0" contype="0" rgba="0 1 0 0" mass="0"/>
    </default>
  </default>
  <worldbody>
    <body>
      <body name="object">
        <geom mesh="Body001_vis" type="mesh" solimp="0.998 0.998 0.001" solref="0.001 1" friction="0.95 0.3 0.1" class="visual" material="Body001_material"/>
        <geom type="box" pos="0.08808132 0.17548943 -0.02372144" size="0.05539245530962944 0.013671533204615116 0.044668491929769516" quat="0.9996153712272644 0.0 0.0 -0.027732810005545616" class="collision"/>
        <geom type="box" pos="0.00078083 0.15894117 0.05363143" size="0.14131420850753784 0.012452433817088604 0.03535560145974159" quat="0.9929261803627014 0.11873321980237961 2.6364074191218734e-17 -5.226415306242255e-24" class="collision"/>
        <geom type="box" pos="-0.00190582 0.13734308 0.02017820" size="0.13808095455169678 0.015119913965463638 0.08606130629777908" quat="1.0 0.0 0.0 0.0" class="collision"/>
        <geom type="box" pos="-0.00189030 0.14290776 0.08729484" size="0.13664811849594116 0.01245243288576603 0.012800469063222408" quat="0.8860620260238647 0.46356672048568726 1.0293246945430214e-16 -2.890941714807063e-23" class="collision"/>
        <geom type="box" pos="-0.01612283 0.16736006 -0.02372153" size="0.05193859338760376 0.01423898059874773 0.04466821998357773" quat="1.0 0.0 0.0 0.0" class="collision"/>
        <geom type="box" pos="-0.10549028 0.16226612 -0.02372144" size="0.040267303586006165 0.01367128174751997 0.044668491929769516" quat="0.9964933395385742 0.0 0.0 0.08367206901311874" class="collision"/>
        <geom type="box" pos="0.08558135 0.17583222 -0.08202083" size="0.05303531140089035 0.011030254885554314 0.018221210688352585" quat="0.960905909538269 -0.27548280358314514 -0.007642851211130619 -0.026658808812499046" class="collision"/>
        <geom type="box" pos="-0.01609419 0.16704923 -0.08362869" size="0.05179201811552048 0.011061293072998524 0.01853199675679207" quat="0.9612611532211304 -0.2755846083164215 0.0015121020842343569 0.005274335388094187" class="collision"/>
        <geom type="box" pos="-0.10450549 0.16289156 -0.08089087" size="0.03971199318766594 0.011049107648432255 0.018412934616208076" quat="0.9579047560691833 -0.27462247014045715 0.023059016093611717 0.08043167740106583" class="collision"/>
        <geom type="box" pos="0.00006136 -0.00188917 0.03126461" size="0.02041749283671379 0.12112927436828613 0.07182000577449799" quat="1.0 0.0 0.0 0.0" class="collision"/>
        <geom type="box" pos="0.06159365 -0.00189203 0.03319461" size="0.01363546121865511 0.12112927436828613 0.07182001322507858" quat="1.0 0.0 0.0 0.0" class="collision"/>
        <geom type="box" pos="0.00113984 0.00960774 0.09805364" size="0.017653854563832283 0.04576921835541725 0.015127424150705338" quat="1.0 0.0 0.0 0.0" class="collision"/>
        <geom type="box" pos="0.00024599 -0.06325440 0.09557503" size="0.035033825784921646 0.017653875052928925 0.015127458609640598" quat="0.706587553024292 0.02709091082215309 0.027090897783637047 -0.7065877318382263" class="collision"/>
        <geom type="box" pos="0.00105836 -0.11600330 0.09064483" size="0.018966322764754295 0.017652755603194237 0.015002801083028316" quat="0.7045238614082336 0.06038448214530945 0.060384489595890045 -0.7045236229896545" class="collision"/>
        <geom type="box" pos="0.00212627 0.08844203 0.09498890" size="0.035033825784921646 0.017653875052928925 0.015127452090382576" quat="0.7066655158996582 -0.02497573383152485 -0.024975739419460297 -0.7066656351089478" class="collision"/>
        <geom type="box" pos="-0.06085578 0.01055571 0.09766559" size="0.0117497518658638 0.045767154544591904 0.015124957077205181" quat="1.0 0.0 0.0 0.0" class="collision"/>
        <geom type="box" pos="-0.06085578 -0.06230657 0.09518723" size="0.03503219410777092 0.011749749071896076 0.015124795958399773" quat="0.7065876722335815 0.027090899646282196 0.02709089405834675 -0.7065876126289368" class="collision"/>
        <geom type="box" pos="-0.06085546 -0.11555050 0.09015801" size="0.019475623965263367 0.01174900308251381 0.014999925158917904" quat="0.7045238018035889 0.06038447469472885 0.06038447469472885 -0.7045236825942993" class="collision"/>
        <geom type="box" pos="-0.06085578 0.08938950 0.09460166" size="0.035031162202358246 0.011749749071896076 0.015125235542654991" quat="0.7066655158996582 -0.02497573383152485 -0.02497573383152485 -0.7066656351089478" class="collision"/>
        <geom type="box" pos="0.06200540 0.00873595 0.09813914" size="0.0117497518658638 0.045767154544591904 0.01512496080249548" quat="1.0 0.0 0.0 0.0" class="collision"/>
        <geom type="box" pos="0.06200540 -0.06412633 0.09566078" size="0.03503219410777092 0.011749749071896076 0.015124795958399773" quat="0.7065876722335815 0.027090899646282196 0.02709089405834675 -0.7065876126289368" class="collision"/>
        <geom type="box" pos="0.06200572 -0.11693111 0.09070739" size="0.019029967486858368 0.01174900308251381 0.014999925158917904" quat="0.7045238018035889 0.06038447469472885 0.06038447469472885 -0.7045236825942993" class="collision"/>
        <geom type="box" pos="0.06200540 0.08756974 0.09507521" size="0.035031162202358246 0.011749749071896076 0.015125235542654991" quat="0.7066655158996582 -0.02497573383152485 -0.02497573383152485 -0.7066656351089478" class="collision"/>
        <geom type="box" pos="0.12445330 0.00789056 0.09856519" size="0.019254259765148163 0.045767076313495636 0.015124985948204994" quat="1.0 0.0 0.0 0.0" class="collision"/>
        <geom type="box" pos="0.12445330 -0.06497172 0.09608683" size="0.03503219410777092 0.019254254177212715 0.015124794095754623" quat="0.7065876722335815 0.027090901508927345 0.027090895920991898 -0.7065876126289368" class="collision"/>
        <geom type="box" pos="0.12445383 -0.11555208 0.08871978" size="0.02000635489821434 0.019253036007285118 0.01628694124519825" quat="0.7045238018035889 0.06038447469472885 0.06038447469472885 -0.7045236825942993" class="collision"/>
        <geom type="box" pos="0.12445330 0.08672436 0.09550126" size="0.03503115847706795 0.019254254177212715 0.015125235542654991" quat="0.7066655158996582 -0.024975741282105446 -0.024975737556815147 -0.7066656351089478" class="collision"/>
        <geom type="box" pos="0.00072345 -0.00188917 -0.09110297" size="0.15060628950595856 0.15525786578655243 0.014200753532350063" quat="1.0 0.0 0.0 0.0" class="collision"/>
        <geom type="box" pos="-0.12061944 0.01055570 0.09850307" size="0.017710208892822266 0.045767150819301605 0.015125014819204807" quat="1.0 0.0 0.0 0.0" class="collision"/>
        <geom type="box" pos="-0.12061945 -0.06230658 0.09602471" size="0.03503219410777092 0.017710205167531967 0.015124794095754623" quat="0.7065876722335815 0.027090901508927345 0.027090895920991898 -0.7065876126289368" class="collision"/>
        <geom type="box" pos="-0.12012235 -0.11276634 0.09147626" size="0.0166502445936203 0.018205633386969566 0.014999921433627605" quat="0.7045238018035889 0.06038447469472885 0.06038447469472885 -0.7045236825942993" class="collision"/>
        <geom type="box" pos="-0.12061945 0.08938950 0.09543913" size="0.03503115847706795 0.017710205167531967 0.015125235542654991" quat="0.7066655158996582 -0.024975741282105446 -0.024975737556815147 -0.7066656351089478" class="collision"/>
        <geom type="box" pos="-0.10502494 -0.00184917 0.01667647" size="0.0026891015004366636 0.09859595447778702 0.0918901190161705" quat="1.0 0.0 0.0 0.0" class="collision"/>
        <geom type="box" pos="-0.06141118 -0.00189203 0.03319461" size="0.01284023281186819 0.12112905085086823 0.07182008773088455" quat="1.0 0.0 0.0 0.0" class="collision"/>
        <geom type="box" pos="0.00124511 -0.11972908 0.10165553" size="0.01945185847580433 0.0029280728194862604 0.10654899477958679" quat="0.5688296556472778 -0.4200344383716583 0.5688364505767822 -0.4200344979763031" class="collision"/>
        <geom type="box" pos="-0.06871497 -0.14351609 0.08390970" size="0.01945185847580433 0.06606195867061615 0.002928077010437846" quat="0.5913438200950623 0.3811352849006653 0.37233296036720276 -0.6053235530853271" class="collision"/>
        <geom type="box" pos="-0.08082353 -0.15535549 0.04508172" size="0.020943447947502136 0.056785546243190765 0.0029280732851475477" quat="0.5432334542274475 0.4456195831298828 0.42652443051338196 -0.5695590376853943" class="collision"/>
        <geom type="box" pos="-0.07181485 -0.16762966 -0.07995644" size="0.01945185475051403 0.002928073052316904 0.06765502691268921" quat="0.6924258470535278 0.11927063018083572 0.7058899998664856 0.08966749906539917" class="collision"/>
        <geom type="box" pos="0.06631945 -0.16703885 -0.08079767" size="0.01945185475051403 0.0029280728194862604 0.07105861604213715" quat="0.6974658966064453 0.08476696908473969 0.6993010640144348 0.13165821135044098" class="collision"/>
        <geom type="box" pos="0.06636633 -0.14356967 0.08390970" size="0.01945185847580433 0.06841100007295609 0.002928080502897501" quat="0.5913495421409607 0.38113173842430115 -0.37233662605285645 0.6053178906440735" class="collision"/>
        <geom type="box" pos="0.08043786 -0.15510712 0.04568055" size="0.020330660045146942 0.05717505142092705 0.0029280681628733873" quat="0.5438447594642639 0.4451960623264313 -0.42696887254714966 0.5689736008644104" class="collision"/>
        <geom type="box" pos="0.08005232 -0.16814240 -0.03792912" size="0.025655826553702354 0.05666908249258995 0.0024713824968785048" quat="0.5049710869789124 0.4865931272506714 -0.4677930176258087 0.5379600524902344" class="collision"/>
        <geom type="box" pos="0.10495964 -0.00189203 0.03319461" size="0.0019342282321304083 0.12112928181886673 0.07182009518146515" quat="1.0 0.0 0.0 0.0" class="collision"/>
        <geom type="box" pos="0.00072346 -0.00188917 -0.04593225" size="0.10558580607175827 0.12112928926944733 0.010444018058478832" quat="1.0 0.0 0.0 0.0" class="collision"/>
        <geom type="box" pos="0.00002858 -0.17494933 -0.04831998" size="0.0017779064364731312 0.01576468162238598 0.01621513068675995" quat="0.7064796686172485 -0.02977382019162178 -0.02977382019162178 -0.7064796686172485" class="collision"/>
        <geom type="box" pos="0.00041775 -0.17200517 -0.01571321" size="0.0017779064364731312 0.01576468162238598 0.01621513068675995" quat="0.7064796686172485 -0.02977382019162178 -0.02977382019162178 -0.7064796686172485" class="collision"/>
        <geom type="box" pos="0.00041775 -0.16740441 0.01634714" size="0.0017531170742586255 0.015544874593615532 0.015989042818546295" quat="0.7041632533073425 -0.0644516572356224 -0.0644516721367836 -0.7041633725166321" class="collision"/>
        <geom type="box" pos="-0.00013958 -0.15941414 0.05010741" size="0.001753117423504591 0.015544874593615532 0.017158180475234985" quat="0.7020131945610046 -0.08471927791833878 -0.08471929281949997 -0.702013373374939" class="collision"/>
        <geom type="box" pos="-0.01985516 -0.15733392 0.05733850" size="0.0017531176563352346 0.004173330496996641 0.009792251512408257" quat="0.7020131945610046 -0.08471927791833878 -0.08471929281949997 -0.702013373374939" class="collision"/>
        <geom type="box" pos="0.01918859 -0.15733392 0.05733850" size="0.0017531176563352346 0.004173330496996641 0.009792251512408257" quat="0.7020131945610046 -0.08471927791833878 -0.08471929281949997 -0.702013373374939" class="collision"/>
        <geom type="box" pos="-0.07978241 -0.16384177 0.00715305" size="0.01945185847580433 0.057808902114629745 0.0029280793387442827" quat="0.5208864808082581 0.47154712677001953 0.45375627279281616 -0.5481111407279968" class="collision"/>
        <geom type="box" pos="-0.07969026 -0.16884394 -0.03807886" size="0.025615401566028595 0.05797916278243065 0.002928084461018443" quat="0.5146521925926208 0.47834324836730957 0.46091026067733765 -0.5421093702316284" class="collision"/>
        <geom type="box" pos="0.08092254 -0.16309030 0.00704048" size="0.01945185847580433 0.05808183178305626 0.0029280816670507193" quat="0.5208864808082581 0.47154712677001953 -0.45375627279281616 0.5481111407279968" class="collision"/>
        <geom type="box" pos="0.14880386 -0.14422661 0.04032895" size="0.01599324680864811 0.038283202797174454 0.004218402784317732" quat="0.7373143434524536 0.6024975180625916 0.21775461733341217 0.21435299515724182" class="collision"/>
        <geom type="box" pos="0.15029420 -0.15422414 -0.03770403" size="0.015993241220712662 0.03970905765891075 0.004218392539769411" quat="0.6675412058830261 0.6141427755355835 0.3240535855293274 0.2687128782272339" class="collision"/>
        <geom type="box" pos="0.16053556 0.07761304 0.04844677" size="0.040565941482782364 0.044129591435194016 0.008903085254132748" quat="0.5046805143356323 0.4523944854736328 0.4907858073711395 0.5475090146064758" class="collision"/>
        <geom type="box" pos="0.16563840 -0.01497026 0.04846619" size="0.04413215070962906 0.05179201066493988 0.0089121637865901" quat="0.005553995259106159 -0.6674209833145142 -0.004977995064109564 -0.7446432709693909" class="collision"/>
        <geom type="box" pos="0.15916729 -0.09846477 0.04846620" size="0.03423191234469414 0.044132113456726074 0.008912008255720139" quat="0.5624980926513672 0.5041662454605103 0.4373708963394165 0.4879743754863739" class="collision"/>
        <geom type="box" pos="0.15759571 0.10028882 -0.04277384" size="0.046757664531469345 0.06167353317141533 0.008912205696105957" quat="0.05947696790099144 -0.7098848819732666 -0.05946805700659752 -0.6992778182029724" class="collision"/>
        <geom type="box" pos="0.16960171 -0.01104440 -0.04077947" size="0.044131334871053696 0.05179202929139137 0.008912165649235249" quat="0.005848488304764032 -0.7121397852897644 -0.004623087123036385 -0.7019981145858765" class="collision"/>
        <geom type="box" pos="0.16163386 -0.10443973 -0.04044492" size="0.04026731848716736 0.04413210600614548 0.008911997079849243" quat="0.5344099998474121 0.5333434343338013 0.4712783992290497 0.4559028148651123" class="collision"/>
        <geom type="box" pos="0.14438052 0.14359686 0.04867360" size="0.00785065907984972 0.044126734137535095 0.008892967365682125" quat="0.16748973727226257 0.18874789774417877 0.6277308464050293 0.7363935112953186" class="collision"/>
        <geom type="box" pos="0.15063998 0.12735050 0.04943575" size="0.012968060560524464 0.04412464052438736 0.008885515853762627" quat="0.39171671867370605 0.4041488468647003 0.5350667834281921 0.630020022392273" class="collision"/>
        <geom type="box" pos="0.14686134 0.09499327 -0.08788407" size="0.017739688977599144 0.05048474296927452 0.014200737699866295" quat="0.0784950777888298 -0.2137913554906845 -0.009843683801591396 -0.9736708402633667" class="collision"/>
        <geom type="box" pos="0.15471007 -0.00188924 -0.08978872" size="0.017739690840244293 0.050484735518693924 0.014200742356479168" quat="6.602014934742328e-08 -0.21417465806007385 1.906587421274253e-08 -0.9767953753471375" class="collision"/>
        <geom type="box" pos="0.14506403 -0.10081666 -0.08813775" size="0.01773970201611519 0.05048474669456482 0.014200742356479168" quat="0.09398642182350159 0.21630987524986267 0.006197109818458557 0.9717706441879272" class="collision"/>
        <geom type="box" pos="0.15251595 0.00105984 0.10310409" size="0.016134342178702354 0.03503168001770973 0.0030713521409779787" quat="4.513292140018166e-08 -0.31964629888534546 5.4137906602136354e-08 -0.9475369453430176" class="collision"/>
        <geom type="box" pos="0.15151288 -0.07080055 0.09925286" size="0.016134344041347504 0.03503168001770973 0.003071340499445796" quat="0.017029883340001106 0.30914226174354553 -0.03724353760480881 0.9501336812973022" class="collision"/>
        <geom type="box" pos="0.15092070 0.07259713 0.10008595" size="0.016134347766637802 0.03503168746829033 0.003071340499445796" quat="0.015770696103572845 -0.32475802302360535 -0.038827378302812576 -0.9448682069778442" class="collision"/>
        <geom type="box" pos="0.14542732 -0.11952243 0.09755945" size="0.010261619463562965 0.013959992676973343 0.0026491584721952677" quat="0.7361759543418884 0.3175431489944458 0.1714431494474411 0.5725544095039368" class="collision"/>
        <geom type="box" pos="0.14226580 -0.13488823 0.08848710" size="0.009804214350879192 0.01857624389231205 0.0020469054579734802" quat="0.8055134415626526 0.5018000602722168 0.15257471799850464 0.2758001387119293" class="collision"/>
        <geom type="box" pos="0.14809330 0.11707154 0.09631984" size="0.010261621326208115 0.013959987089037895 0.002649166388437152" quat="0.6100725531578064 0.10540380328893661 0.3217537999153137 0.7163630723953247" class="collision"/>
        <geom type="box" pos="-0.15030716 -0.15419073 -0.03737599" size="0.01599324308335781 0.040039047598838806 0.0042183916084468365" quat="0.6675410866737366 0.614142894744873 -0.32405364513397217 -0.26871293783187866" class="collision"/>
        <geom type="box" pos="-0.14226580 -0.13488823 0.08848710" size="0.009804214350879192 0.01857624389231205 0.0020469054579734802" quat="0.8055134415626526 0.5018000602722168 -0.15257471799850464 -0.2758001387119293" class="collision"/>
        <geom type="box" pos="-0.16053556 0.07761304 0.04844677" size="0.040565941482782364 0.044129591435194016 0.008903085254132748" quat="0.5046805143356323 0.4523944854736328 -0.4907858073711395 -0.5475090146064758" class="collision"/>
        <geom type="box" pos="-0.16563840 -0.01497046 0.04846618" size="0.04413215443491936 0.051792021840810776 0.008912169374525547" quat="0.005553995259106159 -0.6674209833145142 0.004977995064109564 0.7446432709693909" class="collision"/>
        <geom type="box" pos="-0.15916729 -0.09846477 0.04846620" size="0.03423191234469414 0.044132113456726074 0.008912008255720139" quat="0.5624980926513672 0.5041662454605103 -0.4373708963394165 -0.4879743754863739" class="collision"/>
        <geom type="box" pos="-0.15759571 0.10028882 -0.04277384" size="0.046757664531469345 0.06167353317141533 0.008912205696105957" quat="0.05947696790099144 -0.7098848819732666 0.05946805700659752 0.6992778182029724" class="collision"/>
        <geom type="box" pos="-0.16960171 -0.01104440 -0.04077947" size="0.044131334871053696 0.05179202929139137 0.008912165649235249" quat="0.005848488304764032 -0.7121397852897644 0.004623087123036385 0.7019981145858765" class="collision"/>
        <geom type="box" pos="-0.16163386 -0.10443973 -0.04044492" size="0.04026731848716736 0.04413210600614548 0.008911997079849243" quat="0.5344099998474121 0.5333434343338013 -0.4712783992290497 -0.4559028148651123" class="collision"/>
        <geom type="box" pos="-0.14686134 0.09499327 -0.08788407" size="0.017739688977599144 0.05048474296927452 0.014200737699866295" quat="0.0784950777888298 -0.2137913554906845 0.009843683801591396 0.9736708402633667" class="collision"/>
        <geom type="box" pos="-0.15471007 -0.00188924 -0.08978872" size="0.017739690840244293 0.050484735518693924 0.014200742356479168" quat="6.602014934742328e-08 -0.21417465806007385 -1.906587421274253e-08 0.9767953753471375" class="collision"/>
        <geom type="box" pos="-0.14506403 -0.10081666 -0.08813775" size="0.01773970201611519 0.05048474669456482 0.014200742356479168" quat="0.09398642182350159 0.21630987524986267 -0.006197109818458557 -0.9717706441879272" class="collision"/>
        <geom type="box" pos="-0.15251595 0.00105984 0.10310409" size="0.016134342178702354 0.03503168001770973 0.0030713521409779787" quat="4.513292140018166e-08 -0.31964629888534546 -5.4137906602136354e-08 0.9475369453430176" class="collision"/>
        <geom type="box" pos="-0.15092070 0.07259713 0.10008595" size="0.016134347766637802 0.03503168746829033 0.003071340499445796" quat="0.015770696103572845 -0.32475802302360535 0.038827378302812576 0.9448682069778442" class="collision"/>
        <geom type="box" pos="-0.15151288 -0.07080055 0.09925286" size="0.016134344041347504 0.03503168001770973 0.003071340499445796" quat="0.017029883340001106 0.30914226174354553 0.03724353760480881 -0.9501336812973022" class="collision"/>
        <geom type="box" pos="-0.14542732 -0.11952243 0.09755945" size="0.010261619463562965 0.013959992676973343 0.0026491584721952677" quat="0.7361759543418884 0.3175431489944458 -0.1714431494474411 -0.5725544095039368" class="collision"/>
        <geom type="box" pos="-0.14438052 0.14359686 0.04867360" size="0.00785065907984972 0.044126734137535095 0.008892967365682125" quat="0.16748973727226257 0.18874789774417877 -0.6277308464050293 -0.7363935112953186" class="collision"/>
        <geom type="box" pos="-0.15063998 0.12735050 0.04943575" size="0.012968060560524464 0.04412464052438736 0.008885515853762627" quat="0.39171671867370605 0.4041488468647003 -0.5350667834281921 -0.630020022392273" class="collision"/>
        <geom type="box" pos="-0.14809330 0.11707154 0.09631984" size="0.010261621326208115 0.013959987089037895 0.002649166388437152" quat="0.6100725531578064 0.10540380328893661 -0.3217537999153137 -0.7163630723953247" class="collision"/>
        <geom type="box" pos="-0.14893202 -0.14274761 0.04214820" size="0.01599324680864811 0.038283202797174454 0.004218402784317732" quat="0.7559158802032471 0.588578999042511 -0.193276047706604 -0.21168452501296997" class="collision"/>
        <body name="sideL_button_cancel">
          <joint axis="0.0 0.9719247817993164 -0.23529194295406342" pos="-0.09371550 -0.16358690 0.03798619" limited="true" name="sideL_button_cancel_joint" range="0.0 0.0008" type="slide" damping="1" frictionloss="1" armature=".01" stiffness="0.2" springref="-0.1"/>
          <geom mesh="sideL_button_cancel_vis" type="mesh" solimp="0.998 0.998 0.001" solref="0.001 1" friction="0.95 0.3 0.1" class="visual" material="sideL_button_cancel_material"/>
          <geom class="collision" type="cylinder" pos="-0.09371550 -0.16338616 0.03783151" size="0.006280657835304737 0.00129419076256454" quat="0.6298929452896118 -0.7763615846633911 0.0018386580049991608 -0.022230222821235657" name="sideL_button_cancel_main"/>
        </body>
        <body name="sideL_knob_doneness">
          <joint axis="0.0 1.0 0.0" pos="-0.09371550 -0.18294444 -0.01039778" limited="true" name="sideL_knob_doneness_joint" range="0.0 4.537856055185257" type="hinge" damping="0.05" armature="0.001"/>
          <geom mesh="sideL_knob_doneness_vis" type="mesh" solimp="0.998 0.998 0.001" solref="0.001 1" friction="0.95 0.3 0.1" class="visual" material="sideL_knob_doneness_material"/>
          <geom type="cylinder" pos="-0.09378935 -0.17432792 -0.01037987" size="0.021372664719820023 0.0036418430972844362" quat="0.6453710794448853 0.6453714966773987 0.2889564633369446 -0.2889566123485565" class="collision"/>
          <geom class="collision" type="box" pos="-0.09442095 -0.18370479 -0.00956995" size="0.006168861407786608 0.006732618901878595 0.01794629544019699" quat="1.0 0.0 0.0 0.0" name="sideL_knob_doneness_main"/>
        </body>
        <body name="sideL_lever">
          <joint axis="0.0 0.0 -1.0" pos="0.00000000 0.00108150 0.00578150" limited="true" name="sideL_lever_joint" range="0.0 0.06" type="slide" damping="1" frictionloss="1" armature=".01" stiffness="2.5" springref="-0.5"/>
          <geom class="region" name="reg_sideL_slotL" type="box" pos="-0.08821970500000001 0.016599220000000005 0.113030805" size="0.014168745000000003 0.09560189 0.076000095"/>
          <geom class="region" name="reg_sideL_slotR" type="box" pos="-0.03469151 0.016599220000000005 0.113030805" size="0.014297879999999999 0.09560189 0.076000095"/>
          <geom mesh="sideL_lever_vis" type="mesh" solimp="0.998 0.998 0.001" solref="0.001 1" friction="0.95 0.3 0.1" class="visual" material="sideL_lever_material"/>
          <geom class="collision" type="box" pos="-0.01889326 -0.18545322 0.04046646" size="0.01545801293104887 0.007655643858015537 0.0034616717603057623" quat="0.9970527291297913 -0.07671903073787689 -2.96647150868462e-17 1.7054219469456115e-18" name="sideL_lever_handle"/>
          <geom class="collision" type="box" pos="-0.08843876 0.01643524 0.03410808" size="0.012550000101327896 0.09376424551010132 0.0032419152557849884" quat="1.0 0.0 0.0 0.0" name="sideL_slotL_floor"/>
          <geom class="collision" type="box" pos="-0.03471129 0.01643523 0.03410807" size="0.01254999078810215 0.09376414865255356 0.0032419110648334026" quat="1.0 0.0 0.0 0.0" name="sideL_slotR_floor"/>
          <geom type="box" pos="-0.01912496 -0.17401211 0.03796731" size="0.0017561395652592182 0.00499917333945632 0.0017561395652592182" quat="0.9923057556152344 -0.12381134927272797 -2.7210877182262745e-17 2.5638119806126883e-18" class="collision"/>
        </body>
        <body name="sideR_button_cancel">
          <joint axis="0.0 0.9728217124938965 -0.2315555065870285" pos="0.09338170 -0.16358691 0.03798620" limited="true" name="sideR_button_cancel_joint" range="0.0 0.0008" type="slide" damping="1" frictionloss="1" armature=".01" stiffness="0.2" springref="-0.1"/>
          <geom mesh="sideR_button_cancel_vis" type="mesh" solimp="0.998 0.998 0.001" solref="0.001 1" friction="0.95 0.3 0.1" class="visual" material="sideR_button_cancel_material"/>
          <geom class="collision" type="cylinder" pos="0.09328970 -0.16338616 0.03783151" size="0.0064547122456133366 0.0016535837203264236" quat="0.6298929452896118 -0.7763615846633911 0.0018386580049991608 -0.022230222821235657" name="sideR_button_cancel_main"/>
        </body>
        <body name="sideR_knob_doneness">
          <joint axis="0.0 1.0 0.0" pos="0.09338170 -0.17781390 -0.01039778" limited="true" name="sideR_knob_doneness_joint" range="0.0 4.537856055185257" type="hinge" damping="0.05" armature="0.001"/>
          <geom mesh="sideR_knob_doneness_vis" type="mesh" solimp="0.998 0.998 0.001" solref="0.001 1" friction="0.95 0.3 0.1" class="visual" material="sideR_knob_doneness_material"/>
          <geom type="cylinder" pos="0.09334530 -0.17432792 -0.01037987" size="0.021372664719820023 0.0036418430972844362" quat="0.6453710794448853 0.6453714966773987 0.2889564633369446 -0.2889566123485565" class="collision"/>
          <geom class="collision" type="box" pos="0.09271370 -0.18370479 -0.00956995" size="0.006168861407786608 0.006732617039233446 0.017946291714906693" quat="1.0 0.0 0.0 0.0" name="sideR_knob_doneness_main"/>
        </body>
        <body name="sideR_lever">
          <joint axis="0.0 0.0 -1.0" pos="0.01917880 -0.17697164 0.03900718" limited="true" name="sideR_lever_joint" range="0.0 0.06" type="slide" damping="1" frictionloss="1" armature=".01" stiffness="2.5" springref="-0.5"/>
          <geom class="region" name="reg_sideR_slotL" type="box" pos="0.034190780000000004 0.016599220000000005 0.113030805" size="0.014207090000000002 0.09560189 0.076000095"/>
          <geom class="region" name="reg_sideR_slotR" type="box" pos="0.089033535 0.016599220000000005 0.113030865" size="0.014162525000000002 0.09560189 0.076000155"/>
          <geom mesh="sideR_lever_vis" type="mesh" solimp="0.998 0.998 0.001" solref="0.001 1" friction="0.95 0.3 0.1" class="visual" material="sideR_lever_material"/>
          <geom class="collision" type="box" pos="0.01922064 -0.18545851 0.04044727" size="0.01545801293104887 0.007655643858015537 0.0034616717603057623" quat="0.9970527291297913 -0.07671903073787689 -2.96647150868462e-17 1.7054219469456115e-18" name="sideR_lever_handle"/>
          <geom class="collision" type="box" pos="0.08907282 0.01643524 0.03410808" size="0.0125499926507473 0.09376417100429535 0.0032419110648334026" quat="1.0 0.0 0.0 0.0" name="sideR_slotR_floor"/>
          <geom class="collision" type="box" pos="0.03419143 0.01643523 0.03410807" size="0.012550000101327896 0.09376424551010132 0.00324191153049469" quat="1.0 0.0 0.0 0.0" name="sideR_slotL_floor"/>
          <geom type="box" pos="0.01952616 -0.17396094 0.03781419" size="0.0017561395652592182 0.0049991728737950325 0.0017561395652592182" quat="0.9923057556152344 -0.12381134927272797 -2.3919414682712166e-17 1.8890298833455116e-18" class="collision"/>
        </body>
        <body name="Body002">
          <geom mesh="Body002_vis" type="mesh" solimp="0.998 0.998 0.001" solref="0.001 1" friction="0.95 0.3 0.1" class="visual" material="Body002_material"/>
        </body>
        <geom class="region" name="reg_main" type="box" pos="3.500000000933312e-08 0.008066755000000009 -4.400000000043258e-07" size="0.178933275 0.186526725 0.11386354"/>
      </body>
    </body>
  </worldbody>
  <actuator>
    <motor name="sideL_button_cancel_joint_actuator" joint="sideL_button_cancel_joint" gear="0.1"/>
    <motor name="sideL_knob_doneness_joint_actuator" joint="sideL_knob_doneness_joint" gear="5"/>
    <motor name="sideL_lever_joint_actuator" joint="sideL_lever_joint" gear="2"/>
    <motor name="sideR_button_cancel_joint_actuator" joint="sideR_button_cancel_joint" gear="0.1"/>
    <motor name="sideR_knob_doneness_joint_actuator" joint="sideR_knob_doneness_joint" gear="5"/>
    <motor name="sideR_lever_joint_actuator" joint="sideR_lever_joint" gear="2"/>
  </actuator>
</mujoco>
