<?xml version='1.0' encoding='UTF-8'?>
<mujoco model="model">
  <option timestep="0.002" gravity="0.0 0.0 -9.81"/>
  <compiler angle="radian"/>
  <asset>
    <mesh file="visuals/button_lid.obj" name="button_lid_vis"/>
    <mesh file="visuals/Body001.obj" name="Body001_vis"/>
    <mesh file="visuals/kettle_main.obj" name="kettle_main_vis"/>
    <mesh file="visuals/lid.obj" name="lid_vis"/>
    <mesh file="visuals/switch.obj" name="switch_vis"/>
    <texture file="visuals/T_BC001.png" name="Body001_material" type="2d"/>
    <material name="Body001_material" rgba="1 1 1 1.0" texture="Body001_material" shininess="0.2512328028678894" specular="0.3103448502657381"/>
    <texture file="visuals/T_BC001.png" name="kettle_main_material" type="2d"/>
    <material name="kettle_main_material" rgba="1 1 1 1.0" texture="kettle_main_material" shininess="0.2512328028678894" specular="0.3103448502657381"/>
    <texture file="visuals/T_BC001.png" name="button_lid_material" type="2d"/>
    <material name="button_lid_material" rgba="1 1 1 1.0" texture="button_lid_material" shininess="0.2512328028678894" specular="0.3103448502657381"/>
    <texture file="visuals/T_BC001.png" name="lid_material" type="2d"/>
    <material name="lid_material" rgba="1 1 1 1.0" texture="lid_material" shininess="0.2512328028678894" specular="0.3103448502657381"/>
    <texture file="visuals/T_BC001.png" name="switch_material" type="2d"/>
    <material name="switch_material" rgba="1 1 1 1.0" texture="switch_material" shininess="0.2512328028678894" specular="0.3103448502657381"/>
  </asset>
  <default>
    <default class="visual">
      <geom conaffinity="0" contype="0" group="1" type="mesh"/>
    </default>
    <default class="collision">
      <geom group="0" rgba="0.5 0 0 0.5" density="1.0" solref="0.004 1" solimp="0.998 0.998 0.001"/>
    </default>
    <default class="spawn">
      <geom group="0" rgba="1 1 1 0.5" contype="0" conaffinity="0"/>
      <site group="0" rgba="1 1 1 0.5"/>
    </default>
    <default class="region">
      <geom group="1" conaffinity="0" contype="0" rgba="0 1 0 0" mass="0"/>
    </default>
  </default>
  <worldbody>
    <body>
      <body name="object">
        <geom mesh="Body001_vis" type="mesh" solimp="0.998 0.998 0.001" solref="0.001 1" friction="0.95 0.3 0.1" class="visual" material="Body001_material"/>
        <geom type="cylinder" pos="-0.02671792 -0.00003802 -0.12844845" size="0.08444634824991226 0.010209722444415092" quat="1.0 0.0 0.0 0.0" class="collision"/>
        <body name="kettle_main">
          <!-- <joint axis="0.0 0.0 1.0" pos="0.00000000 0.00000000 0.00954518" limited="true" name="kettle_main_joint" range="0.0 0.1" type="slide" damping="1" frictionloss="1" armature=".01" stiffness="0.05"/> -->
          <geom mesh="kettle_main_vis" type="mesh" solimp="0.998 0.998 0.001" solref="0.001 1" friction="0.95 0.3 0.1" class="visual" material="kettle_main_material"/>
          <geom type="box" pos="-0.02673091 -0.07860982 0.00673660" size="0.0074759433045983315 0.004363123793154955 0.12471074610948563" quat="1.0 0.0 0.0 0.0" class="collision"/>
          <geom type="box" pos="0.00477392 -0.07180212 0.00673660" size="0.007475841790437698 0.004363126587122679 0.12471074610948563" quat="4.238201825046417e-07 0.20617419481277466 -0.9785153269767761 8.929941941460129e-08" class="collision"/>
          <geom type="box" pos="-0.01068780 -0.07686561 0.00673660" size="0.007475842721760273 0.004363126587122679 0.12471074610948563" quat="4.306424443711876e-07 0.10693040490150452 -0.9942665100097656 4.6314312385220546e-08" class="collision"/>
          <geom type="box" pos="0.01887936 -0.06330270 0.00673660" size="0.007475842721760273 0.004363126587122679 0.12471074610948563" quat="4.0854882854546304e-07 0.3320642113685608 -0.9432567954063416 1.4382553104042017e-07" class="collision"/>
          <geom type="box" pos="0.03108598 -0.05218111 0.00673660" size="0.007475842721760273 0.004363126587122679 0.12471074610948563" quat="3.938663155622635e-07 0.41601479053497314 -0.9093578457832336 1.801867171025151e-07" class="collision"/>
          <geom type="box" pos="0.04094170 -0.03919325 0.00673660" size="0.007475842721760273 0.004363126587122679 0.12471074610948563" quat="3.747649941487907e-07 0.5013291239738464 -0.865256667137146 2.1713849207571911e-07" class="collision"/>
          <geom type="box" pos="0.04766037 -0.02450411 0.00673660" size="0.007475842721760273 0.004363126587122679 0.12471074610948563" quat="3.501059211430402e-07 0.588738203048706 -0.8083238005638123 2.5499761591163406e-07" class="collision"/>
          <geom type="box" pos="0.05149063 -0.00894192 0.02229435" size="0.00747585529461503 0.004363126587122679 0.10915300250053406" quat="3.263175756273995e-07 0.6575611233711243 -0.7534012198448181 2.8480656055762665e-07" class="collision"/>
          <geom type="box" pos="0.05161621 0.00728335 0.02228536" size="0.0074758571572601795 0.004363126587122679 0.10916198045015335" quat="-2.147158397747262e-07 -0.7387588024139404 0.6739699244499207 -3.4737618648250645e-07" class="collision"/>
          <geom type="box" pos="0.04847665 0.02310675 0.00673660" size="0.007475841324776411 0.004363126587122679 0.12471074610948563" quat="2.970163279769622e-07 0.8089416027069092 -0.5878890156745911 2.802756000619411e-07" class="collision"/>
          <geom type="box" pos="0.04207194 0.03802596 0.00673660" size="0.007475842256098986 0.004363126587122679 0.12471074610948563" quat="-1.3982163693526672e-07 -0.8600683212280273 0.5101788640022278 -3.836969142412272e-07" class="collision"/>
          <geom type="box" pos="0.03265326 0.05121213 0.00673660" size="0.007475842256098986 0.004363127052783966 0.12471074610948563" quat="2.359989395017692e-07 0.9088815450668335 -0.4170543849468231 3.3328311133118405e-07" class="collision"/>
          <geom type="box" pos="0.02116245 0.06245177 0.00673660" size="0.007475841324776411 0.004363126587122679 0.12471074610948563" quat="2.0226659103173006e-07 0.945317804813385 -0.32615071535110474 3.5476944049150916e-07" class="collision"/>
          <geom type="box" pos="0.00713907 0.07071929 0.00673660" size="0.007475841790437698 0.0043631261214613914 0.12471074610948563" quat="1.578725346007559e-07 0.9778256416320801 -0.20942065119743347 3.7662911722691206e-07" class="collision"/>
          <geom type="box" pos="-0.00770409 0.07618736 0.00673660" size="0.007475842721760273 0.004363126587122679 0.12471074610948563" quat="1.288943423105593e-07 0.9908782243728638 -0.13476020097732544 3.875082654758444e-07" class="collision"/>
          <geom type="box" pos="-0.02353272 0.07858562 0.00673660" size="0.007475842721760273 0.004363127052783966 0.12471074610948563" quat="8.481143254357448e-08 0.9997295141220093 -0.02325654961168766 3.9948287167135277e-07" class="collision"/>
          <geom type="box" pos="-0.03949217 0.07749550 0.00673660" size="0.007475841324776411 0.004363126587122679 0.12471074610948563" quat="1.0430600383415367e-07 -0.9973849654197693 -0.07227186858654022 -3.9483333580392355e-07" class="collision"/>
          <geom type="box" pos="-0.05497196 0.07330942 0.00673660" size="0.007475842721760273 0.004363127052783966 0.12471074610948563" quat="5.120769919209067e-10 0.9829936623573303 0.18363963067531586 4.0837878145794093e-07" class="collision"/>
          <geom type="box" pos="-0.06931802 0.06594017 0.00673660" size="0.007475841790437698 0.004363126587122679 0.12471074610948563" quat="-4.540866882507544e-08 0.9561119079589844 0.2930017411708832 4.058462934608542e-07" class="collision"/>
          <geom type="box" pos="-0.08165824 0.05595462 0.00673660" size="0.007475842721760273 0.004363126587122679 0.12471074610948563" quat="2.232767712939676e-07 -0.9239467978477478 -0.38252103328704834 -3.419366407797497e-07" class="collision"/>
          <geom type="box" pos="-0.09186183 0.04378881 0.00673660" size="0.007475842721760273 0.004363127052783966 0.12471074610948563" quat="-1.2095752310870012e-07 0.8839080333709717 0.4676607847213745 3.9005453800200485e-07" class="collision"/>
          <geom type="box" pos="-0.09957993 0.02992240 0.00673660" size="0.007475842721760273 0.004363126587122679 0.12471074610948563" quat="2.830099958828214e-07 -0.8366203308105469 -0.5477831959724426 -2.944121320069826e-07" class="collision"/>
          <geom type="box" pos="-0.04285489 -0.07687679 0.00673660" size="0.00747584318742156 0.004363127052783966 0.12471074610948563" quat="4.301141984797141e-07 -0.11771966516971588 -0.9930468797683716 -5.0987374322630785e-08" class="collision"/>
          <geom type="box" pos="-0.05805038 -0.07210465 0.00673660" size="0.007475843653082848 0.004363126587122679 0.12471074610948563" quat="4.2420293766554096e-07 -0.2019345909357071 -0.9793990254402161 -8.746308566287553e-08" class="collision"/>
          <geom type="box" pos="-0.07224624 -0.06414773 0.00673660" size="0.007475842721760273 0.004363126587122679 0.12471074610948563" quat="4.1283601603936404e-07 -0.3024821877479553 -0.9531550407409668 -1.310127828446639e-07" class="collision"/>
          <geom type="box" pos="-0.08436496 -0.05372437 0.00673660" size="0.007475842721760273 0.004363126587122679 0.12471074610948563" quat="3.973850084548758e-07 -0.3977776765823364 -0.9174818396568298 -1.7228778403932665e-07" class="collision"/>
          <geom type="box" pos="-0.09397203 -0.04077890 0.00673660" size="0.007475842721760273 0.004363126587122679 0.12471074610948563" quat="3.7910510286565113e-07 -0.4836215674877167 -0.8752772212028503 -2.094689932619076e-07" class="collision"/>
          <geom type="box" pos="-0.10098371 -0.02644156 0.00673660" size="0.007475841790437698 0.004363126587122679 0.12471074610948563" quat="3.5722160873774556e-07 -0.5654937028884888 -0.8247526288032532 -2.4492990746693977e-07" class="collision"/>
          <geom type="box" pos="-0.10532677 -0.01074374 0.00673660" size="0.007475839927792549 0.004363126587122679 0.12471074610948563" quat="3.32345479137075e-07 -0.6412659883499146 -0.7673186659812927 -2.7774882482844987e-07" class="collision"/>
          <geom type="box" pos="-0.10621631 0.00537268 0.00673660" size="0.007475842721760273 0.004363127052783966 0.12471074610948563" quat="-2.2257719933804765e-07 0.7232064008712769 0.6906319856643677 3.423924113121757e-07" class="collision"/>
          <geom type="box" pos="-0.10431287 0.01805310 0.00673660" size="0.0043244315311312675 0.004363126587122679 0.12471074610948563" quat="3.087532149947947e-07 -0.7830078601837158 -0.6220118403434753 -2.6729119895207987e-07" class="collision"/>
          <geom class="collision" type="box" pos="0.07473324 -0.00844429 0.12016316" size="0.01504150778055191 0.017996322363615036 0.013837083242833614" quat="0.9994867444038391 0.0 0.0 -0.03203532472252846" name="handle_1"/>
          <geom class="collision" type="box" pos="0.08512285 -0.00833645 -0.01968333" size="0.02877083420753479 0.01722337305545807 0.010504625737667084" quat="0.9994867444038391 0.0 0.0 -0.03203532472252846" name="handle_2"/>
          <geom class="collision" type="box" pos="0.10820916 -0.00833645 0.03920008" size="0.010158251971006393 0.01841774210333824 0.06686317920684814" quat="0.9994867444038391 0.0 0.0 -0.03203532472252846" name="handle_main"/>
          <geom type="cylinder" pos="-0.02570136 -0.00000000 -0.10567633" size="0.08158671855926514 0.01201014593243599" quat="1.0 0.0 0.0 0.0" class="collision"/>
          <body name="button_lid">
            <joint axis="0.0 0.0 -1.0" pos="0.09977855 -0.00906681 0.12857996" limited="true" name="button_lid_joint" range="0.0 0.003" type="slide" damping="1" frictionloss="1" armature=".01" stiffness="0.05" springref="-2"/>
            <geom mesh="button_lid_vis" type="mesh" solimp="0.998 0.998 0.001" solref="0.001 1" friction="0.95 0.3 0.1" class="visual" material="button_lid_material"/>
            <geom class="collision" type="box" pos="0.10103051 -0.00943971 0.13090477" size="0.006649842951446772 0.0064285448752343655 0.0011010953458026052" quat="0.974043607711792 -0.006441115401685238 0.22453688085079193 -0.027941642329096794" name="button_lid_main"/>
          </body>
          <body name="lid">
            <joint axis="0.0 1.0 0.0" pos="0.06034513 -0.00677139 0.13657834" limited="true" name="lid_joint" range="0.0 1.5707963267948966" type="hinge" damping="1" frictionloss="0.1" armature=".01" stiffness="0.05" springref="-6"/>
            <geom mesh="lid_vis" type="mesh" solimp="0.998 0.998 0.001" solref="0.001 1" friction="0.95 0.3 0.1" class="visual" material="lid_material"/>
            <geom class="collision" type="cylinder" pos="-0.02726131 -0.00003802 0.12786896" size="0.06680486142635345 0.010236123576760292" quat="1.0 0.0 0.0 0.0" name="lid_main"/>
          </body>
          <body name="switch">
            <joint axis="0.0 0.0 -1.0" pos="0.04940099 -0.00502505 -0.09478355" limited="true" name="switch_joint" range="0.0 0.005" type="slide" damping="1" frictionloss="1" armature=".01" stiffness="0.05" springref="-2"/>
            <geom mesh="switch_vis" type="mesh" solimp="0.998 0.998 0.001" solref="0.001 1" friction="0.95 0.3 0.1" class="visual" material="switch_material"/>
            <geom class="collision" type="box" pos="0.07600000 -0.00541766 -0.09467880" size="0.017 0.010291109792888165 0.004289291333407164" quat="0.9995887875556946 0.0 0.0 -0.02867441438138485" name="switch_main"/>
          </body>
        </body>
        <geom class="region" name="reg_main" type="box" pos="-4.999999997368221e-09 0.0 3.099500000000588e-05" size="0.120302465 0.08567355 0.139705565"/>
      </body>
    </body>
  </worldbody>
  <actuator>
     <!-- <motor name="kettle_main_joint_actuator" joint="kettle_main_joint" gear="10"/> -->
     <motor name="button_lid_joint_actuator" joint="button_lid_joint" gear="0.5"/>
     <motor name="lid_joint_actuator" joint="lid_joint" gear="0.5"/>
     <motor name="switch_joint_actuator" joint="switch_joint" gear="0.1"/>
  </actuator>
</mujoco>
