<?xml version='1.0' encoding='UTF-8'?>
<mujoco model="model">
  <option timestep="0.002" gravity="0.0 0.0 -9.81"/>
  <compiler angle="radian"/>
  <asset>
    <mesh file="visuals/button_cancel.obj" name="button_cancel_vis"/>
    <mesh file="visuals/knob_doneness.obj" name="knob_doneness_vis"/>
    <mesh file="visuals/lever.obj" name="lever_vis"/>
    <mesh file="visuals/Body001.obj" name="Body001_vis"/>
    <mesh file="visuals/Body002.obj" name="Body002_vis"/>
    <texture file="visuals/T_BC001.png" name="Body001_material" type="2d"/>
    <material name="Body001_material" rgba="1 1 1 1.0" texture="Body001_material" shininess="0.141421377658844" specular="1"/>
    <texture file="visuals/T_BC001.png" name="button_cancel_material" type="2d"/>
    <material name="button_cancel_material" rgba="1 1 1 1.0" texture="button_cancel_material" shininess="0.141421377658844" specular="1"/>
    <texture file="visuals/T_BC001.png" name="knob_doneness_material" type="2d"/>
    <material name="knob_doneness_material" rgba="1 1 1 1.0" texture="knob_doneness_material" shininess="0.141421377658844" specular="1"/>
    <texture file="visuals/T_BC001.png" name="lever_material" type="2d"/>
    <material name="lever_material" rgba="1 1 1 1.0" texture="lever_material" shininess="0.141421377658844" specular="1"/>
    <texture file="visuals/T_BC001.png" name="Body002_material" type="2d"/>
    <material name="Body002_material" rgba="1 1 1 1.0" texture="Body002_material" shininess="0.141421377658844" specular="3"/>
  </asset>
  <default>
    <default class="visual">
      <geom conaffinity="0" contype="0" group="1" type="mesh"/>
    </default>
    <default class="collision_1">
      <geom group="0" rgba="0.5 0 0 0.5" solref="0.004 1" solimp="0.998 0.998 0.001"/>
    </default>
    <default class="collision_2">
      <geom group="0" rgba="0.5 0 0 0.5" solref="0.004 1" solimp="0.998 0.998 0.001"/>
    </default>
    <default class="collision_3">
      <geom group="0" rgba="0.5 0 0 0.5" solref="0.004 1" solimp="0.998 0.998 0.001"/>
    </default>
    <default class="collision_4">
      <geom group="0" rgba="0.5 0 0 0.5" solref="0.004 1" solimp="0.998 0.998 0.001"/>
    </default>
    <default class="collision_5">
      <geom group="0" rgba="0.5 0 0 0.5" solref="0.004 1" solimp="0.998 0.998 0.001"/>
    </default>
    <default class="spawn">
      <geom group="0" rgba="1 1 1 0.5" contype="0" conaffinity="0"/>
      <site group="0" rgba="1 1 1 0.5"/>
    </default>
    <default class="region">
      <geom group="1" conaffinity="0" contype="0" rgba="0 1 0 0" mass="0"/>
    </default>
  </default>
  <worldbody>
    <body>
      <body name="object">
        <geom mesh="Body001_vis" type="mesh" solimp="0.998 0.998 0.001" solref="0.001 1" friction="0.95 0.3 0.1" class="visual" material="Body001_material"/>
        <geom type="box" pos="0.07181938737630844 -0.00012785382568836212 -0.018579840660095215" size="0.017897849902510643 0.07558272033929825 0.11121884733438492" quat="1.0 0.0 0.0 0.0" class="collision_1"/>
        <geom type="box" pos="0.00088832201436162 -0.11155819147825241 0.12759704887866974" size="0.045503027737140656 0.012207301333546638 0.002414036775007844" quat="1.0 0.0 0.0 0.0" class="collision_1"/>
        <geom type="box" pos="6.33587478660047e-05 0.08737225085496902 -0.018579840660095215" size="0.08984652906656265 0.011873370967805386 0.11121884733438492" quat="1.0 0.0 0.0 0.0" class="collision_1"/>
        <geom type="box" pos="-0.07015519589185715 -0.00012785382568836212 -0.018579840660095215" size="0.019018039107322693 0.07558272033929825 0.11121884733438492" quat="1.0 0.0 0.0 0.0" class="collision_1"/>
        <geom type="box" pos="0.00015739095397293568 -0.00012785382568836212 -0.1143738403916359" size="0.041732896119356155 0.07558272033929825 0.015424847602844238" quat="1.0 0.0 0.0 0.0" class="collision_1"/>
        <geom type="box" pos="0.0395720973610878 -0.13860392570495605 -0.018579840660095215" size="0.010807800106704235 0.007547955960035324 0.11121699213981628" quat="1.0 0.0 0.0 0.0" class="collision_1"/>
        <geom type="box" pos="-0.045072488486766815 -0.13840648531913757 -0.11286623775959015" size="0.014666675589978695 0.008579140529036522 0.016932453960180283" quat="1.0 0.0 0.0 0.0" class="collision_1"/>
        <geom type="box" pos="-0.0005787424161098897 -0.138384610414505 0.08067131042480469" size="0.03038119524717331 0.008556865155696869 0.008924510329961777" quat="1.0 0.0 0.0 0.0" class="collision_1"/>
        <geom type="box" pos="-0.0005787423579022288 -0.13884201645851135 -0.1046939492225647" size="0.030382825061678886 0.007743623107671738 0.026408197358250618" quat="1.0 0.0 0.0 0.0" class="collision_1"/>
        <geom type="box" pos="0.0011345604434609413 -0.00012785382568836212 -0.018579840660095215" size="0.005468219053000212 0.07558751851320267 0.11122364550828934" quat="1.0 0.0 0.0 0.0" class="collision_1"/>
        <geom type="box" pos="3.0108087230473757e-05 -0.1030886322259903 -0.018579840660095215" size="0.08960377424955368 0.028282539919018745 0.11121305078268051" quat="1.0 0.0 0.0 0.0" class="collision_1"/>
        <geom type="box" pos="0.0009522776817902923 -0.005598044954240322 0.12401928007602692" size="0.0017291133990511298 0.10349177569150925 0.0015544283669441938" quat="1.0 0.0 0.0 0.0" class="collision_1"/>
        <geom type="box" pos="-0.05038544163107872 -0.005598044954240322 0.12401928007602692" size="0.0017291144467890263 0.10349177569150925 0.0015544283669441938" quat="1.0 0.0 0.0 0.0" class="collision_1"/>
        <geom type="box" pos="0.05354681983590126 -0.005598044954240322 0.12401928007602692" size="0.0017291196854785085 0.10349177569150925 0.0015544283669441938" quat="1.0 0.0 0.0 0.0" class="collision_1"/>
        <geom type="box" pos="-0.0021582453045994043 0.08499748259782791 0.12228640913963318" size="0.07560911029577255 0.001729295589029789 0.0015544859925284982" quat="1.0 0.0 0.0 0.0" class="collision_1"/>
        <geom type="box" pos="0.08034513890743256 0.08566483110189438 0.11339043825864792" size="0.001554414862766862 0.0017291834810748696 0.008288615383207798" quat="1.0 0.0 0.0 0.0" class="collision_1"/>
        <geom type="box" pos="0.0695924237370491 0.0857296735048294 0.10224182903766632" size="0.008288619108498096 0.0017291851108893752 0.0015544130001217127" quat="1.0 0.0 0.0 0.0" class="collision_1"/>
        <geom type="box" pos="0.05993738770484924 0.08574510365724564 0.09693772345781326" size="0.0015544689958915114 0.0017292702104896307 0.004351865034550428" quat="1.0 0.0 0.0 0.0" class="collision_1"/>
        <geom type="box" pos="0.0771556943655014 0.08566483110189438 0.12181064486503601" size="0.001729181269183755 0.005066163372248411 0.0015544126508757472" quat="0.09229595214128494 0.7010574340820312 -0.7010573148727417 -0.09229602664709091" class="collision_1"/>
        <geom type="box" pos="0.07837152481079102 0.08572965860366821 0.10367249697446823" size="0.001729181269183755 0.0035548803862184286 0.001554418238811195" quat="0.6644629240036011 0.24184469878673553 -0.2418447732925415 -0.6644631624221802" class="collision_1"/>
        <geom type="box" pos="0.07837153971195221 -0.08626195043325424 0.10367248207330704" size="0.001729181269183755 0.0035548803862184286 0.0015544155612587929" quat="0.6644629240036011 0.24184469878673553 -0.2418447732925415 -0.6644631624221802" class="collision_1"/>
        <geom type="box" pos="0.0771557092666626 -0.08632677793502808 0.12181062996387482" size="0.001729181269183755 0.005066165700554848 0.0015544126508757472" quat="0.09229595214128494 0.7010574340820312 -0.7010573148727417 -0.09229602664709091" class="collision_1"/>
        <geom type="box" pos="0.05993739888072014 -0.08624650537967682 0.09693770855665207" size="0.0015544637572020292 0.0017292611300945282 0.004351865034550428" quat="1.0 0.0 0.0 0.0" class="collision_1"/>
        <geom type="box" pos="0.0695924386382103 -0.08626193553209305 0.10224181413650513" size="0.008288617245852947 0.0017291851108893752 0.0015544239431619644" quat="1.0 0.0 0.0 0.0" class="collision_1"/>
        <geom type="box" pos="0.08034515380859375 -0.08632677793502808 0.11339042335748672" size="0.001554414862766862 0.0017291834810748696 0.008288615383207798" quat="1.0 0.0 0.0 0.0" class="collision_1"/>
        <geom type="box" pos="-0.08042479306459427 -0.08713598549365997 0.11339042335748672" size="0.001729181269183755 0.00828862190246582 0.001554418122395873" quat="0.47771456837654114 0.4777144491672516 0.5213338136672974 0.521333634853363" class="collision_1"/>
        <geom type="box" pos="-0.06970734149217606 -0.08626341819763184 0.10224181413650513" size="0.001729181269183755 0.00828862190246582 0.0015544126508757472" quat="0.6755902767181396 1.6573051198065514e-07 6.911207606208336e-08 0.7372772693634033" class="collision_1"/>
        <geom type="box" pos="-0.06008770316839218 -0.08543729782104492 0.09693770855665207" size="0.001729181269183755 0.004351858515292406 0.001554418122395873" quat="0.4777144491672516 -0.4777143895626068 -0.5213338732719421 0.5213337540626526" class="collision_1"/>
        <geom type="box" pos="-0.0772474855184555 -0.08685800433158875 0.12181062996387482" size="0.001729181269183755 0.005066166631877422 0.0015544126508757472" quat="0.08818227052688599 0.6698103547096252 0.7309699058532715 0.0962340235710144" class="collision_1"/>
        <geom type="box" pos="-0.07845304161310196 -0.08702855557203293 0.10367248207330704" size="0.001729181269183755 0.0035548803862184286 0.0015544176567345858" quat="0.6348472237586975 0.23106549680233002 0.25216373801231384 0.6928139925003052" class="collision_1"/>
        <geom type="box" pos="-0.0002545728057157248 -0.08732146769762039 0.12401928007602692" size="0.07181192189455032 0.0017291909316554666 0.0015544130001217127" quat="1.0 0.0 0.0 0.0" class="collision_1"/>
        <geom type="box" pos="-0.08042479306459427 0.08486264944076538 0.11339042335748672" size="0.001729181269183755 0.00828862190246582 0.001554418122395873" quat="0.47771456837654114 0.4777144491672516 0.5213338136672974 0.521333634853363" class="collision_1"/>
        <geom type="box" pos="-0.06970734149217606 0.08573521673679352 0.10224181413650513" size="0.001729181269183755 0.008288617245852947 0.0015544126508757472" quat="0.6755902767181396 1.6573051198065514e-07 6.911207606208336e-08 0.7372772693634033" class="collision_1"/>
        <geom type="box" pos="-0.06008770316839218 0.08656133711338043 0.09693770855665207" size="0.001729181269183755 0.004351858515292406 0.001554418122395873" quat="0.4777144491672516 -0.4777143895626068 -0.5213338732719421 0.5213337540626526" class="collision_1"/>
        <geom type="box" pos="-0.0772474855184555 0.08514063060283661 0.12181062996387482" size="0.001729181269183755 0.005066162906587124 0.0015544126508757472" quat="0.08818227052688599 0.6698103547096252 0.7309699058532715 0.0962340235710144" class="collision_1"/>
        <geom type="box" pos="-0.07845304161310196 0.08497007936239243 0.10367248207330704" size="0.001729181269183755 0.0035548803862184286 0.0015544156776741147" quat="0.6348472237586975 0.23106549680233002 0.25216373801231384 0.6928139925003052" class="collision_1"/>
        <geom type="box" pos="-0.03525840863585472 -0.1383792906999588 -0.0029623513109982014" size="0.006606541108340025 0.00855177640914917 0.09632734954357147" quat="1.0 0.0 0.0 0.0" class="collision_1"/>
        <geom type="box" pos="-0.0512857586145401 -0.13825386762619019 0.07924631237983704" size="0.011028056032955647 0.008426363579928875 0.013121865689754486" quat="1.0 0.0 0.0 0.0" class="collision_1"/>
        <geom type="box" pos="-0.0005787423579022288 -0.13828134536743164 0.046115692704916" size="0.030382825061678886 0.008454016409814358 0.00663308659568429" quat="1.0 0.0 0.0 0.0" class="collision_1"/>
        <geom type="box" pos="0.020912358537316322 -0.1384173333644867 0.06230780482292175" size="0.008266915567219257 0.008590007200837135 0.009143780916929245" quat="1.0 0.0 0.0 0.0" class="collision_1"/>
        <geom type="box" pos="-0.009236562997102737 -0.1383521556854248 0.062307801097631454" size="0.0234342273324728 0.00852483045309782 0.009143763221800327" quat="1.0 0.0 0.0 0.0" class="collision_1"/>
        <geom type="box" pos="-0.0005787424161098897 -0.1388709396123886 -0.04923849180340767" size="0.030382569879293442 0.008155247196555138 0.03149619698524475" quat="1.0 0.0 0.0 0.0" class="collision_1"/>
        <geom type="box" pos="0.049689557403326035 -0.11144767701625824 0.12759704887866974" size="0.0035432500299066305 0.012207640334963799 0.0024140961468219757" quat="1.0 0.0 0.0 0.0" class="collision_1"/>
        <geom type="box" pos="0.05665202811360359 -0.10646220296621323 0.12759704887866974" size="0.003543225349858403 0.006820063106715679 0.002414117567241192" quat="1.0 0.0 0.0 0.0" class="collision_1"/>
        <geom type="box" pos="0.05388658493757248 -0.11490435153245926 0.12759704887866974" size="0.003543225349858403 0.006820063106715679 0.0024140961468219757" quat="0.9250949621200562 0.0 -0.0 -0.37973588705062866" class="collision_1"/>
        <geom type="box" pos="0.06291968375444412 -0.10204926133155823 0.12759704887866974" size="0.003543225349858403 0.0020794805604964495 0.0024140961468219757" quat="0.9948719143867493 0.0 -0.0 -0.1011427640914917" class="collision_1"/>
        <geom type="box" pos="0.05895443260669708 -0.10754945129156113 0.12759704887866974" size="0.0035432251170277596 0.006820063106715679 0.0024140961468219757" quat="0.9510329365730286 0.0 -0.0 -0.3090895712375641" class="collision_1"/>
        <geom type="box" pos="0.03504627197980881 -0.1262751668691635 0.12759704887866974" size="0.003543225349858403 0.012207720428705215 0.0024140961468219757" quat="0.8435781598091125 0.0 -0.0 -0.5370064377784729" class="collision_1"/>
        <geom type="box" pos="0.015429794788360596 -0.12581469118595123 0.12759704887866974" size="0.003543225349858403 0.012207720428705215 0.0024140961468219757" quat="0.5103968977928162 0.0 -0.0 -0.8599389791488647" class="collision_1"/>
        <geom type="box" pos="0.0252472423017025 -0.12403465807437897 0.12759704887866974" size="0.0035432251170277596 0.006820063106715679 0.0024140961468219757" quat="0.7473390698432922 0.0 -0.0 -0.6644428968429565" class="collision_1"/>
        <geom type="box" pos="-0.013948876410722733 -0.12581469118595123 0.12759704887866974" size="0.003543225349858403 0.012207720428705215 0.0024140961468219757" quat="0.8435781598091125 0.0 -0.0 -0.5370064377784729" class="collision_1"/>
        <geom type="box" pos="-0.034652598202228546 -0.1259298175573349 0.12759704887866974" size="0.003543225349858403 0.012207720428705215 0.0024140961468219757" quat="0.5552929043769836 0.0 -0.0 -0.8316548466682434" class="collision_1"/>
        <geom type="box" pos="-0.02374790608882904 -0.12357417494058609 0.12759704887866974" size="0.0035432251170277596 0.006820063106715679 0.0024140961468219757" quat="0.7473390698432922 0.0 -0.0 -0.6644428968429565" class="collision_1"/>
        <geom type="box" pos="-0.04829985275864601 -0.10635311901569366 0.12759704887866974" size="0.003543225349858403 0.006820063106715679 0.0024141164030879736" quat="1.0 0.0 0.0 0.0" class="collision_1"/>
        <geom type="box" pos="-0.049519702792167664 -0.11495516449213028 0.12759704887866974" size="0.004441085737198591 0.008548281155526638 0.0021612581331282854" quat="0.9103667736053467 0.0 0.0 0.41380226612091064" class="collision_1"/>
        <geom type="box" pos="-0.058500781655311584 -0.10584858804941177 0.12759704887866974" size="0.006284430157393217 0.00368826393969357 0.0024433673825114965" quat="0.8612894415855408 0.0 -0.0 -0.5081146359443665" class="collision_1"/>
        <geom type="box" pos="-0.05548420175909996 -0.10637443512678146 0.12759704887866974" size="0.003543225349858403 0.0068200621753931046 0.0024140961468219757" quat="0.9997301697731018 0.0 -0.0 -0.02322978712618351" class="collision_1"/>
        <geom type="box" pos="0.0005964129231870174 0.10897926986217499 0.12747864425182343" size="0.04550359770655632 0.01220759842544794 0.0024140768218785524" quat="1.0 0.0 0.0 0.0" class="collision_1"/>
        <geom type="box" pos="-0.048128075897693634 0.10741057246923447 0.12747864425182343" size="0.003543228842318058 0.010384543798863888 0.0024140961468219757" quat="1.0 0.0 0.0 0.0" class="collision_1"/>
        <geom type="box" pos="-0.055167295038700104 0.1038832888007164 0.12747864425182343" size="0.0035432276781648397 0.006820064038038254 0.002414113376289606" quat="1.0 0.0 0.0 0.0" class="collision_1"/>
        <geom type="box" pos="-0.04940872639417648 0.11363013088703156 0.12747864425182343" size="0.003916915971785784 0.007539349142462015 0.0022580712102353573" quat="0.40163373947143555 0.0 0.0 0.9158003926277161" class="collision_1"/>
        <geom type="box" pos="-0.061434950679540634 0.0994703471660614 0.12747864425182343" size="0.003543225349858403 0.0020794805604964495 0.0024140961468219757" quat="0.10114292800426483 0.0 0.0 0.9948719143867493" class="collision_1"/>
        <geom type="box" pos="-0.057469699531793594 0.1049705371260643 0.12747864425182343" size="0.0035432251170277596 0.006820063106715679 0.0024140961468219757" quat="0.3090897500514984 0.0 0.0 0.9510328769683838" class="collision_1"/>
        <geom type="box" pos="-0.03356153890490532 0.12369624525308609 0.12747864425182343" size="0.003543225349858403 0.012207720428705215 0.0024140961468219757" quat="0.5370064973831177 0.0 0.0 0.8435781002044678" class="collision_1"/>
        <geom type="box" pos="-0.013945057988166809 0.12323576956987381 0.12747864425182343" size="0.0035432251170277596 0.012207720428705215 0.0024140961468219757" quat="0.8599390387535095 0.0 0.0 0.5103967785835266" class="collision_1"/>
        <geom type="box" pos="-0.023762505501508713 0.12145573645830154 0.12733027338981628" size="0.0035432251170277596 0.006820063106715679 0.0024140961468219757" quat="0.6644429564476013 0.0 0.0 0.7473390102386475" class="collision_1"/>
        <geom type="box" pos="0.015433616004884243 0.12323576956987381 0.12747864425182343" size="0.003543225349858403 0.012207720428705215 0.0024140961468219757" quat="0.5370064973831177 0.0 0.0 0.8435781002044678" class="collision_1"/>
        <geom type="box" pos="0.036137331277132034 0.12335089594125748 0.12747864425182343" size="0.003543225349858403 0.012207720428705215 0.0024140961468219757" quat="0.8316548466682434 0.0 0.0 0.5552929043769836" class="collision_1"/>
        <geom type="box" pos="0.025232642889022827 0.12099525332450867 0.12733027338981628" size="0.0035432251170277596 0.006820063106715679 0.0024140961468219757" quat="0.6644429564476013 0.0 0.0 0.7473390102386475" class="collision_1"/>
        <geom type="box" pos="0.0497845858335495 0.10377418994903564 0.12747864425182343" size="0.0035432276781648397 0.006820064038038254 0.002414112212136388" quat="1.0 0.0 0.0 0.0" class="collision_1"/>
        <geom type="box" pos="0.05100443586707115 0.11237623542547226 0.12794941663742065" size="0.004441085737198591 0.008548281155526638 0.0021612581331282854" quat="0.41380226612091064 0.0 -0.0 -0.9103667736053467" class="collision_1"/>
        <geom type="box" pos="0.05998551473021507 0.10326965898275375 0.12747864425182343" size="0.006284430157393217 0.00368826393969357 0.0024433673825114965" quat="0.5081146359443665 0.0 0.0 0.8612894415855408" class="collision_1"/>
        <geom type="box" pos="0.05696893483400345 0.10379550606012344 0.12747864425182343" size="0.003543225349858403 0.006820063106715679 0.0024140961468219757" quat="0.023229969665408134 0.0 0.0 0.9997301697731018" class="collision_1"/>
        <geom type="box" pos="0.05858074501156807 -0.13495691120624542 -0.018579840660095215" size="0.01080799289047718 0.006625041831284761 0.11121884733438492" quat="0.9966905117034912 0.0 0.0 0.08128968626260757" class="collision_1"/>
        <geom type="box" pos="0.0747159868478775 -0.131972998380661 -0.018579840660095215" size="0.00738156121224165 0.004729794804006815 0.11121884733438492" quat="0.956101655960083 0.0 0.0 0.2930351197719574" class="collision_1"/>
        <geom type="box" pos="-0.07831528782844543 -0.12788745760917664 -0.018579840660095215" size="0.009443521499633789 0.006625041831284761 0.11121884733438492" quat="0.952153205871582 0.0 -0.0 -0.30562111735343933" class="collision_1"/>
        <geom type="box" pos="-0.06629563868045807 -0.13566935062408447 -0.018579840660095215" size="0.007381560280919075 0.004729794804006815 0.11121884733438492" quat="0.9958137273788452 0.0 -0.0 -0.09140605479478836" class="collision_1"/>
        <geom type="box" pos="0.0005502346903085709 0.10983039438724518 -0.018579840660095215" size="0.059643153101205826 0.011873292736709118 0.11121822893619537" quat="1.0 0.0 0.0 0.0" class="collision_1"/>
        <geom type="box" pos="0.0008918401435948908 0.14489389955997467 -0.017163148149847984" size="0.023797927424311638 0.005012699868530035 0.11121886223554611" quat="0.9965649247169495 0.08246416598558426 -0.005023703910410404 -0.005724199116230011" class="collision_1"/>
        <geom type="box" pos="-0.03877222537994385 0.14360411465168 -0.017282359302043915" size="0.017651716247200966 0.004196143709123135 0.11121886968612671" quat="0.9943920373916626 0.08288134634494781 -0.004864958580583334 0.065509133040905" class="collision_1"/>
        <geom type="box" pos="-0.06750383973121643 0.13292372226715088 -0.019039876759052277" size="0.017651716247200966 0.00588522432371974 0.11121886223554611" quat="0.9567350745201111 0.07987119257450104 -0.02266186662018299 0.2788638472557068" class="collision_1"/>
        <geom type="box" pos="-0.08055631816387177 0.11285140365362167 -0.0192590169608593" size="0.01464123371988535 0.0040429821237921715 0.11121886968612671" quat="0.8164798021316528 0.053202804177999496 -0.032888736575841904 0.5739760994911194" class="collision_1"/>
        <geom type="box" pos="0.041694946587085724 0.14266666769981384 -0.016940981149673462" size="0.017651716247200966 0.00588522432371974 0.11121886968612671" quat="0.9946147203445435 0.08319374173879623 -0.00017087832384277135 -0.06180911883711815" class="collision_1"/>
        <geom type="box" pos="0.07025143504142761 0.1339177042245865 -0.01600014977157116" size="0.017651716247200966 0.005885224789381027 0.11121886968612671" quat="0.9847123026847839 0.08285678178071976 0.007482475135475397 -0.1530374139547348" class="collision_1"/>
        <geom type="box" pos="0.08158773183822632 0.10967597365379333 -0.01662706397473812" size="0.01453572977334261 0.00509297801181674 0.11121886968612671" quat="0.7479175329208374 0.04382636025547981 0.03129924088716507 -0.6616033315658569" class="collision_1"/>
        <geom type="box" pos="0.06611568480730057 0.10939447581768036 -0.018483377993106842" size="0.014535728842020035 0.017348647117614746 0.11121886968612671" quat="0.718610942363739 0.05031517520546913 0.024392085149884224 -0.6931606531143188" class="collision_1"/>
        <geom type="box" pos="-0.06836403906345367 0.10719054192304611 -0.017401019111275673" size="0.01622443087399006 0.009179049171507359 0.11121886968612671" quat="0.9683212637901306 0.017481839284300804 0.00994997937232256 0.24889615178108215" class="collision_1"/>
        <geom type="box" pos="-0.0006787058664485812 0.13837727904319763 -0.11804741621017456" size="0.059643544256687164 0.018674883991479874 0.012905346229672432" quat="1.0 0.0 0.0 0.0" class="collision_1"/>
        <geom type="box" pos="0.06798996776342392 0.14162804186344147 -0.11804741621017456" size="0.010031410492956638 0.018674764782190323 0.012905276380479336" quat="0.6182823181152344 0.0 -0.0 -0.785956084728241" class="collision_1"/>
        <geom type="box" pos="-0.06876785308122635 0.13275425136089325 -0.11804741621017456" size="0.010031410492956638 0.018674764782190323 0.012905276380479336" quat="0.9473262429237366 0.0 -0.0 -0.3202701807022095" class="collision_1"/>
        <geom type="box" pos="0.0715484544634819 0.10796735435724258 -0.0680193230509758" size="0.01774711161851883 0.010160927660763264 0.06114324927330017" quat="1.0 0.0 0.0 0.0" class="collision_1"/>
        <body name="button_cancel">
          <joint axis="0.0 1.0 0.0" pos="-0.0015356737421825528 -0.14885348081588745 0.06103966757655144" limited="true" name="button_cancel_joint" range="0.0 0.003" type="slide" damping="1" frictionloss="1" armature=".01" stiffness="4" springref="-1"/>
          <geom mesh="button_cancel_vis" type="mesh" solimp="0.998 0.998 0.001" solref="0.001 1" friction="0.95 0.3 0.1" class="visual" material="button_cancel_material"/>
          <geom class="collision_2" type="box" pos="-0.0013609036104753613 -0.14986763894557953 0.061323098838329315" size="0.01158258505165577 0.0013246641028672457 0.005231217015534639" quat="1.0 0.0 0.0 0.0" name="button_cancel_main"/>
        </body>
        <body name="knob_doneness">
          <joint axis="0.0 1.0 0.0" pos="0.0001651179773034528 -0.14988106489181519 -0.05366307869553566" limited="true" name="knob_doneness_joint" range="0.0 5.759586531581287" type="hinge" damping="0.05" frictionloss="0.75" armature="1"/>
          <geom mesh="knob_doneness_vis" type="mesh" solimp="0.998 0.998 0.001" solref="0.001 1" friction="0.95 0.3 0.1" class="visual" material="knob_doneness_material"/>
          <geom type="cylinder" pos="-0.00035743697662837803 -0.15020295977592468 -0.05358259752392769" size="0.02352958545088768 0.002197747817263007" quat="0.7071068286895752 0.7071067690849304 0.0 0.0" class="collision_3" friction="100 0.5 0.01"/>
          <geom class="collision_3" type="box" pos="1.6962294466793537e-06 -0.15773704648017883 -0.05341293290257454" size="0.004684708081185818 0.005968423560261726 0.02036171965301037" quat="1.0 0.0 0.0 0.0" name="knob_doneness_main" friction="100 0.5 0.01"/>
        </body>
        <body name="lever">
          <joint axis="0.0 0.0 -1.0" pos="-0.0500607043504715 -0.15344667434692383 0.04236011579632759" limited="true" name="lever_joint" range="0.0 0.06" type="slide" damping="1" frictionloss="1" armature=".1" stiffness="2" springref="-0.5"/>
          <geom class="region" name="reg_slotL" type="box" pos="-0.027204882353544235 0.00023833662271499634 0.09284894354641438" size="0.01049719175696373 0.07091716474294663 0.07600007562339306"/>
          <geom class="region" name="reg_slotR" type="box" pos="0.030156515538692474 0.00023833662271499634 0.09284894354641438" size="0.010849444031715394 0.07091716474294663 0.07600007562339306"/>
          <geom mesh="lever_vis" type="mesh" solimp="0.998 0.998 0.001" solref="0.001 1" friction="0.95 0.3 0.1" class="visual" material="lever_material"/>
          <geom class="collision_4" type="box" pos="-0.027228944003582 -0.00012785755097866058 0.012733090668916702" size="0.014000000432133675 0.07249999046325684 0.0004118361393921077" quat="1.0 0.0 0.0 0.0" name="slotL_floor"/>
          <geom class="collision_4" type="box" pos="0.029669951647520065 -0.00012785568833351135 0.012733090668916702" size="0.0139999995008111 0.07249999046325684 0.0004118361393921077" quat="1.0 0.0 0.0 0.0" name="slotR_floor"/>
          <geom class="collision_4" type="box" pos="-0.0498691201210022 -0.15945100784301758 0.042542289942502975" size="0.010252031497657299 0.009677259251475334 0.004635241813957691" quat="1.0 0.0 0.0 0.0" name="lever_handle"/>
          <geom type="box" pos="-0.05020032078027725 -0.14365297555923462 0.042542289942502975" size="0.002658987184986472 0.005694423336535692 0.0022419183515012264" quat="1.0 0.0 0.0 0.0" class="collision_4"/>
        </body>
        <body name="Body002">
          <geom mesh="Body002_vis" type="mesh" solimp="0.998 0.998 0.001" solref="0.001 1" friction="0.95 0.3 0.1" class="visual" material="Body002_material"/>
          <geom type="box" pos="-0.04564209282398224 -0.00012785382568836212 -0.018579840660095215" size="0.0029905959963798523 0.07558871805667877 0.11122484505176544" quat="1.0 0.0 0.0 0.0" class="collision_5"/>
          <geom type="box" pos="0.048161230981349945 -0.00012785382568836212 -0.018579840660095215" size="0.0029905959963798523 0.07558850944042206 0.11122463643550873" quat="1.0 0.0 0.0 0.0" class="collision_5"/>
          <geom type="box" pos="-0.008871513418853283 -0.00012785382568836212 -0.018579840660095215" size="0.0029905959963798523 0.07558796554803848 0.11122409999370575" quat="1.0 0.0 0.0 0.0" class="collision_5"/>
          <geom type="box" pos="0.011075875721871853 -0.00012785382568836212 -0.018579840660095215" size="0.0029905959963798523 0.07558794319629669 0.11122407764196396" quat="1.0 0.0 0.0 0.0" class="collision_5"/>
        </body>
        <geom class="region" name="reg_main" type="box" pos="1.862645149230957e-09 0.011066019535064697 0.0" size="0.09100001847743988 0.15912450647354126 0.1311838606595993"/>
      </body>
    </body>
  </worldbody>
  <actuator>
    <motor name="button_cancel_joint_actuator" joint="button_cancel_joint" gear="0.5"/>
    <motor name="knob_doneness_joint_actuator" joint="knob_doneness_joint" gear="10"/>
    <motor name="lever_joint_actuator" joint="lever_joint" gear="2"/>
  </actuator>
</mujoco>