<?xml version='1.0' encoding='UTF-8'?>
<mujoco model="model">
  <option timestep="0.005" gravity="0.0 0.0 -9.81"/>
  <compiler angle="radian"/>
  <asset>
    <mesh file="visuals/freezer_door.obj" name="freezer_door_vis"/>
    <mesh file="visuals/freezer_drawer0.obj" name="freezer_drawer0_vis"/>
    <mesh file="visuals/fridge_door.obj" name="fridge_door_vis"/>
    <mesh file="visuals/fridge_door_Clear.obj" name="fridge_door_Clear_vis"/>
    <mesh file="visuals/fridge_drawer0.obj" name="fridge_drawer0_vis"/>
    <mesh file="visuals/fridge_drawer0_Clear.obj" name="fridge_drawer0_Clear_vis"/>
    <mesh file="visuals/Body001.obj" name="Body001_vis"/>
    <mesh file="visuals/Body001_Clear.obj" name="Body001_Clear_vis"/>
    <texture file="visuals/T_BC001.png" name="Body001_material" type="2d"/>
    <material name="Body001_material" rgba="1 1 1 1.0" texture="Body001_material" shininess="0.5" specular="0.3103448502657381"/>
    <texture file="visuals/T_BC001.png" name="freezer_door_material" type="2d"/>
    <material name="freezer_door_material" rgba="1 1 1 1.0" texture="freezer_door_material" shininess="0.5" specular="0.3103448502657381"/>
    <texture file="visuals/T_BC001.png" name="freezer_drawer0_material" type="2d"/>
    <material name="freezer_drawer0_material" rgba="1 1 1 1.0" texture="freezer_drawer0_material" shininess="0.5" specular="0.3103448502657381"/>
    <texture file="visuals/T_BC001.png" name="fridge_door_material" type="2d"/>
    <material name="fridge_door_material" rgba="1 1 1 1.0" texture="fridge_door_material" shininess="0.5" specular="0.3103448502657381"/>
    <material name="fridge_door_Clear_material" rgba="0.7717612981796265 0.7717612981796265 0.7717612981796265 0.25" shininess="0.5" specular="0.3103448502657381"/>
    <texture file="visuals/T_BC001.png" name="fridge_drawer0_material" type="2d"/>
    <material name="fridge_drawer0_material" rgba="1 1 1 1.0" texture="fridge_drawer0_material" shininess="0.5" specular="0.3103448502657381"/>
    <material name="fridge_drawer0_Clear_material" rgba="0.7717612981796265 0.7717612981796265 0.7717612981796265 0.25" shininess="0.5" specular="0.3103448502657381"/>
    <material name="Body001_Clear_material" rgba="0.7717612981796265 0.7717612981796265 0.7717612981796265 0.25" shininess="0.5" specular="0.3103448502657381"/>
  </asset>
  <default>
    <default class="visual">
      <geom conaffinity="0" contype="0" group="1" type="mesh"/>
    </default>
    <default class="collision">
      <geom group="0" rgba="0.5 0 0 0.5"/>
    </default>
    <default class="spawn">
      <geom group="0" rgba="1 1 1 0.5" contype="0" conaffinity="0"/>
      <site group="0" rgba="1 1 1 0.5"/>
    </default>
    <default class="region">
      <geom group="1" conaffinity="0" contype="0" rgba="0 1 0 0"/>
    </default>
  </default>
  <worldbody>
    <body>
      <body name="object">
        <geom mesh="Body001_vis" type="mesh" solimp="0.998 0.998 0.001" solref="0.001 1" friction="0.95 0.3 0.1" class="visual" material="Body001_material"/>
        <geom class="collision" type="box" pos="-3.574727088562213e-05 0.4180082678794861 -0.0028153115417808294" size="0.45173972845077515 0.024893438443541527 0.938129723072052" quat="1.0 0.0 0.0 0.0"/>
        <geom class="collision" type="box" pos="-4.284229362383485e-06 0.03570566326379776 0.9094570875167847" size="0.45180371403694153 0.42542266845703125 0.025857482105493546" quat="1.0 0.0 0.0 0.0"/>
        <geom class="collision" type="box" pos="-3.574727088562213e-05 0.03566867113113403 -0.8937699794769287" size="0.45177221298217773 0.4254537522792816 0.047671034932136536" quat="1.0 0.0 0.0 0.0"/>
        <geom class="collision" type="box" pos="-0.42626821994781494 0.045118656009435654 0.0" size="0.025539742782711983 0.34963005781173706 0.8898904919624329" quat="1.0 0.0 0.0 0.0"/>
        <geom class="collision" type="box" pos="-0.04468351602554321 0.045118656009435654 0.0" size="0.026747845113277435 0.34963005781173706 0.8898904919624329" quat="1.0 0.0 0.0 0.0"/>
        <geom class="collision" type="box" pos="0.4241794943809509 0.045118656009435654 0.0" size="0.027567248791456223 0.34963005781173706 0.8898904919624329" quat="1.0 0.0 0.0 0.0"/>
        <geom class="collision" type="box" pos="-3.574727088562213e-05 0.03696683421730995 -0.8292543888092041" size="0.45177221298217773 0.35299330949783325 0.021167835220694542" quat="1.0 0.0 0.0 0.0"/>
        <geom class="collision" type="box" pos="-3.574727088562213e-05 0.03696683421730995 0.8663995265960693" size="0.45177221298217773 0.35299330949783325 0.021167870610952377" quat="1.0 0.0 0.0 0.0"/>
        <geom class="collision" type="box" pos="-0.2327532321214676 0.07044325768947601 0.5239828824996948" size="0.15743544697761536 0.31523481011390686 0.00892995297908783" quat="1.0 0.0 0.0 0.0"/>
        <geom class="collision" type="box" pos="-0.2371075600385666 0.06846123188734055 0.18351960182189941" size="0.16178977489471436 0.3172158896923065 0.007833733223378658" quat="1.0 0.0 0.0 0.0"/>
        <geom class="collision" type="box" pos="-0.2327532321214676 0.07632682472467422 -0.16383428871631622" size="0.15743544697761536 0.30934932827949524 0.0036680845078080893" quat="1.0 0.0 0.0 0.0"/>
        <geom class="collision" type="box" pos="0.18661412596702576 0.07020843774080276 -0.12300799787044525" size="0.20260027050971985 0.3154667317867279 0.008525255136191845" quat="1.0 0.0 0.0 0.0"/>
        <geom class="collision" type="box" pos="0.1887836456298828 0.07026404142379761 0.5248534083366394" size="0.2004307508468628 0.31541016697883606 0.009232099168002605" quat="1.0 0.0 0.0 0.0"/>
        <geom class="collision" type="box" pos="0.18661412596702576 0.07020843774080276 0.20216870307922363" size="0.20260027050971985 0.31543806195259094 0.008524703793227673" quat="1.0 0.0 0.0 0.0"/>
        <geom class="collision" type="box" pos="-0.23879718780517578 0.07471239566802979 -0.5143452286720276" size="0.16347941756248474 0.3109334707260132 0.005887000821530819" quat="1.0 0.0 0.0 0.0"/>
        <geom class="collision" type="box" pos="0.18661412596702576 0.07020843774080276 -0.4525694251060486" size="0.20260027050971985 0.3154364228248596 0.008524672128260136" quat="1.0 0.0 0.0 0.0"/>
        <geom class="collision" type="box" pos="0.39106428623199463 0.07020843774080276 -0.6527823209762573" size="0.01731051877140999 0.31543561816215515 0.1667531430721283" quat="1.0 0.0 0.0 0.0"/>
        <geom class="collision" type="box" pos="-0.3914681077003479 0.07020843774080276 -0.6786187887191772" size="0.01610194705426693 0.3154347836971283 0.14091645181179047" quat="1.0 0.0 0.0 0.0"/>
        <body name="freezer_door">
          <joint axis="0.0 0.0 -1.0" pos="-0.4102840721607208 -0.35707998275756836 0.017313480377197266" limited="true" name="freezer_door_joint" range="0.0 1.5707963267948966" type="hinge" damping="1" frictionloss="1" armature=".01" stiffness="0.05"/>
          <geom mesh="freezer_door_vis" type="mesh" solimp="0.998 0.998 0.001" solref="0.001 1" friction="0.95 0.3 0.1" class="visual" material="freezer_door_material"/>
          <geom class="collision" type="box" pos="-0.23308248817920685 -0.35859963297843933 -0.4716695249080658" size="0.17166855931282043 0.03511670231819153 0.352693647146225" quat="1.0 0.0 0.0 0.0"/>
          <geom class="collision" type="box" pos="-0.23299886286258698 -0.3585893213748932 0.5669393539428711" size="0.17159730195999146 0.035106416791677475 0.28844690322875977" quat="1.0 0.0 0.0 0.0"/>
          <geom class="collision" type="box" pos="-0.41679680347442627 -0.35731759667396545 0.07822703570127487" size="0.019492769613862038 0.03383245691657066 0.1951131522655487" quat="1.0 0.0 0.0 0.0"/>
          <geom class="collision" type="box" pos="-0.08572738617658615 -0.35731759667396545 0.07822703570127487" size="0.019492793828248978 0.03383249789476395 0.1951133906841278" quat="1.0 0.0 0.0 0.0"/>
          <geom class="collision" type="box" pos="-0.25087979435920715 -0.3297492265701294 0.07822703570127487" size="0.15072783827781677 0.007263421546667814 0.19512563943862915" quat="1.0 0.0 0.0 0.0"/>
          <geom class="collision" type="box" pos="-0.24829870462417603 -0.2896501123905182 0.6265910863876343" size="0.14127379655838013 0.034701839089393616 0.0047733657993376255" quat="1.0 0.0 0.0 0.0"/>
          <geom class="collision" type="box" pos="-0.11297552287578583 -0.2896501123905182 0.6709846258163452" size="0.005090788006782532 0.03470392897725105 0.05093911662697792" quat="1.0 0.0 0.0 0.0"/>
          <geom class="collision" type="box" pos="-0.38325318694114685 -0.2896501123905182 0.67098468542099" size="0.004545565228909254 0.03470395877957344 0.05093913525342941" quat="1.0 0.0 0.0 0.0"/>
          <geom class="collision" type="box" pos="-0.08284567296504974 -0.41582635045051575 0.4938046634197235" size="0.01949291117489338 0.046118322759866714 0.020017951726913452" quat="1.0 0.0 0.0 0.0" name="freezer_door_handle_1"/>
          <geom class="collision" type="box" pos="-0.08284567296504974 -0.41582635045051575 -0.43190082907676697" size="0.01949293538928032 0.04611838236451149 0.020017951726913452" quat="1.0 0.0 0.0 0.0" name="freezer_door_handle_2"/>
          <geom class="collision" type="box" pos="-0.24867546558380127 -0.3481717109680176 0.26166754961013794" size="0.0428679883480072 0.03457985445857048 0.008216096088290215" quat="1.0 0.0 0.0 0.0"/>
          <geom class="collision" type="cylinder" pos="-0.0821428969502449 -0.44111940264701843 0.030123282223939896" size="0.012613501399755478 0.4395133852958679" quat="1.0 0.0 0.0 0.0" name="freezer_door_handle_main"/>
          <geom class="collision" type="cylinder" pos="-0.22978299856185913 -0.3494099974632263 0.24432069063186646" size="0.009704225696623325 0.012385389767587185" quat="1.0 0.0 0.0 0.0"/>
          <geom class="collision" type="cylinder" pos="-0.26655343174934387 -0.3494099974632263 0.24432069063186646" size="0.009704225696623325 0.012385389767587185" quat="1.0 0.0 0.0 0.0"/>
          <geom class="collision" type="box" pos="-0.24728763103485107 -0.256744921207428 0.6854457259178162" size="0.11403132230043411 0.003913906402885914 0.039933834224939346" quat="1.0 0.0 0.0 0.0"/>
          <geom class="collision" type="box" pos="-0.23337888717651367 -0.3295137286186218 0.022493427619338036" size="0.17197094857692719 0.006030810996890068 0.8323107957839966" quat="1.0 0.0 0.0 0.0" name="freezer_door_main"/>
        </body>
        <body name="freezer_drawer0">
          <geom class="region" name="reg_freezer_drawer0" type="box" pos="-0.21742775663733482 0.09240100532770157 -0.6708606779575348" size="0.11544682255387306 0.2665270919203758 0.0784696171283722"/>
          <joint axis="0.0 -1.0 0.0" pos="-0.2195877581834793 0.08571161329746246 -0.6834301948547363" limited="true" name="freezer_drawer0_joint" range="0.0 0.45" type="slide" damping="1" frictionloss="1" armature=".01" stiffness="0.05"/>
          <geom mesh="freezer_drawer0_vis" type="mesh" solimp="0.998 0.998 0.001" solref="0.001 1" friction="0.95 0.3 0.1" class="visual" material="freezer_drawer0_material"/>
          <geom class="collision" type="box" pos="-0.2180977314710617 0.07664361596107483 -0.7688060998916626" size="0.14340153336524963 0.2927916646003723 0.013361509889364243" quat="1.0 0.0 0.0 0.0"/>
          <geom class="collision" type="box" pos="-0.35043060779571533 0.07654658704996109 -0.6819152235984802" size="0.01021281722933054 0.29288870096206665 0.09808265417814255" quat="1.0 0.0 0.0 0.0"/>
          <geom class="collision" type="box" pos="-0.08482231944799423 0.07624107599258423 -0.6819152235984802" size="0.01021282933652401 0.2931942045688629 0.0980827733874321" quat="1.0 0.0 0.0 0.0"/>
          <geom class="collision" type="box" pos="-0.21932147443294525 -0.2118675857782364 -0.6257953643798828" size="0.12007889896631241 0.0032866031397134066 0.040951162576675415" quat="1.0 0.0 0.0 0.0"/>
          <geom class="collision" type="box" pos="-0.21932147443294525 0.3699532747268677 -0.6692607402801514" size="0.12007889896631241 0.0033624242059886456 0.08441653102636337" quat="1.0 0.0 0.0 0.0"/>
          <geom class="collision" type="box" pos="-0.21932147443294525 -0.19866451621055603 -0.7251388430595398" size="0.12007889896631241 0.016489455476403236 0.02957073599100113" quat="1.0 0.0 0.0 0.0"/>
          <geom class="collision" type="box" pos="-0.13600067794322968 -0.19866442680358887 -0.6813681721687317" size="0.04086754098534584 0.016489485278725624 0.015216811560094357" quat="1.0 0.0 0.0 0.0"/>
          <geom class="collision" type="box" pos="-0.30223241448402405 -0.19866442680358887 -0.6813681721687317" size="0.03903937712311745 0.016489511355757713 0.015216811560094357" quat="1.0 0.0 0.0 0.0"/>
        </body>
        <body name="fridge_door">
          <joint axis="0.0 0.0 1.0" pos="0.41606083512306213 -0.3575720489025116 0.0173148512840271" limited="true" name="fridge_door_joint" range="0.0 1.5707963267948966" type="hinge" damping="1" frictionloss="1" armature=".01" stiffness="0.05"/>
          <geom mesh="fridge_door_vis" type="mesh" solimp="0.998 0.998 0.001" solref="0.001 1" friction="0.95 0.3 0.1" class="visual" material="fridge_door_material"/>
          <geom class="collision" type="box" pos="0.20484568178653717 -0.358371764421463 0.02460833638906479" size="0.20361001789569855 0.03488553315401077 0.8341906666755676" quat="1.0 0.0 0.0 0.0"/>
          <geom class="collision" type="cylinder" pos="0.041350577026605606 -0.44111940264701843 0.030123282223939896" size="0.012613501399755478 0.4395133852958679" quat="1.0 0.0 0.0 0.0" name="fridge_door_handle_main"/>
          <geom class="collision" type="box" pos="0.04180731624364853 -0.41582635045051575 -0.43190082907676697" size="0.01949300803244114 0.04611855372786522 0.020017951726913452" quat="1.0 0.0 0.0 0.0" name="fridge_door_handle_2"/>
          <geom class="collision" type="box" pos="0.04180731624364853 -0.41582635045051575 0.4938046634197235" size="0.01949303224682808 0.046118613332509995 0.020017951726913452" quat="1.0 0.0 0.0 0.0" name="fridge_door_handle_1"/>
          <geom class="collision" type="box" pos="0.2036997675895691 -0.2896501123905182 0.31993919610977173" size="0.18109509348869324 0.034702230244874954 0.004773653578013182" quat="1.0 0.0 0.0 0.0"/>
          <geom class="collision" type="box" pos="0.025358308106660843 -0.2896501123905182 0.3672685921192169" size="0.004545565228909254 0.03470395877957344 0.05049070343375206" quat="1.0 0.0 0.0 0.0"/>
          <geom class="collision" type="box" pos="0.38523954153060913 -0.2896501123905182 0.36726853251457214" size="0.005090788006782532 0.03470392897725105 0.05049068480730057" quat="1.0 0.0 0.0 0.0"/>
          <geom class="collision" type="box" pos="0.2036997675895691 -0.2896501123905182 0.6278215646743774" size="0.18109509348869324 0.0347023606300354 0.004773653578013182" quat="1.0 0.0 0.0 0.0"/>
          <geom class="collision" type="box" pos="0.025358308106660843 -0.2896501123905182 0.6742992997169495" size="0.004545565228909254 0.03470395505428314 0.04705320671200752" quat="1.0 0.0 0.0 0.0"/>
          <geom class="collision" type="box" pos="0.38523954153060913 -0.2896501421928406 0.6742992401123047" size="0.005091222934424877 0.03470689430832863 0.04705721139907837" quat="1.0 0.0 0.0 0.0"/>
          <geom class="collision" type="box" pos="0.2040991485118866 -0.25648218393325806 0.686622679233551" size="0.15500517189502716 0.0036017941311001778 0.03938532620668411" quat="1.0 0.0 0.0 0.0"/>
          <geom class="collision" type="box" pos="0.2040991485118866 -0.25648218393325806 0.38032856583595276" size="0.15500536561012268 0.0036017941311001778 0.03938537836074829" quat="1.0 0.0 0.0 0.0"/>
          <geom class="collision" type="box" pos="0.20709335803985596 -0.3892327547073364 0.02460833638906479" size="0.20585769414901733 0.004026219714432955 0.8342103362083435" quat="1.0 0.0 0.0 0.0" name="fridge_door_main"/>
          <body name="fridge_door_Clear">
            <geom mesh="fridge_door_Clear_vis" type="mesh" solimp="0.998 0.998 0.001" solref="0.001 1" friction="0.95 0.3 0.1" class="visual" material="fridge_door_Clear_material"/>
            <geom class="collision" type="box" pos="0.2040991485118866 -0.25648218393325806 0.686622679233551" size="0.15500517189502716 0.0036017941311001778 0.03938532620668411" quat="1.0 0.0 0.0 0.0"/>
            <geom class="collision" type="box" pos="0.2040991485118866 -0.25648218393325806 0.38032856583595276" size="0.15500536561012268 0.0036017941311001778 0.03938537836074829" quat="1.0 0.0 0.0 0.0"/>
          </body>
        </body>
        <body name="fridge_drawer0">
          <geom class="region" name="reg_fridge_drawer0" type="box" pos="0.17539689224213362 0.09208659082651138 -0.6685689687728882" size="0.1564819019511342 0.26594403928518295 0.07569844818115234"/>
          <joint axis="0.0 -1.0 0.0" pos="0.1754477322101593 0.08571018278598785 -0.6834186911582947" limited="true" name="fridge_drawer0_joint" range="0.0 0.45" type="slide" damping="1" frictionloss="1" armature=".01" stiffness="0.05"/>
          <geom mesh="fridge_drawer0_vis" type="mesh" solimp="0.998 0.998 0.001" solref="0.001 1" friction="0.95 0.3 0.1" class="visual" material="fridge_drawer0_material"/>
          <geom class="collision" type="box" pos="0.35627177357673645 0.0771859735250473 -0.678084135055542" size="0.010212794877588749 0.29224932193756104 0.09808243811130524" quat="1.0 0.0 0.0 0.0"/>
          <geom class="collision" type="box" pos="0.002265164628624916 0.07628963887691498 -0.678084135055542" size="0.010212807916104794 0.29314565658569336 0.09808256477117538" quat="1.0 0.0 0.0 0.0"/>
          <geom class="collision" type="box" pos="0.18242888152599335 0.07628963887691498 -0.7649750113487244" size="0.18522994220256805 0.2931334972381592 0.013362164609134197" quat="1.0 0.0 0.0 0.0"/>
          <geom class="collision" type="box" pos="0.17849116027355194 -0.2097601592540741 -0.625745952129364" size="0.1696891188621521 0.0033516890835016966 0.0394631028175354" quat="1.0 0.0 0.0 0.0"/>
          <geom class="collision" type="box" pos="0.15871365368366241 0.3699532151222229 -0.6684530973434448" size="0.1621493101119995 0.003362426068633795 0.0821695402264595" quat="1.0 0.0 0.0 0.0"/>
          <geom class="collision" type="box" pos="0.17849116027355194 -0.20140260457992554 -0.7291679978370667" size="0.16969282925128937 0.011709202080965042 0.03308255970478058" quat="1.0 0.0 0.0 0.0"/>
          <geom class="collision" type="box" pos="0.2886153757572174 -0.20140260457992554 -0.6881449818611145" size="0.059570569545030594 0.011709215119481087 0.03308259695768356" quat="1.0 0.0 0.0 0.0"/>
          <geom class="collision" type="box" pos="0.06517648696899414 -0.20140260457992554 -0.6881449818611145" size="0.05957064405083656 0.011709227226674557 0.033082637935876846" quat="1.0 0.0 0.0 0.0"/>
          <body name="fridge_drawer0_Clear">
            <geom mesh="fridge_drawer0_Clear_vis" type="mesh" solimp="0.998 0.998 0.001" solref="0.001 1" friction="0.95 0.3 0.1" class="visual" material="fridge_drawer0_Clear_material"/>
            <geom class="collision" type="box" pos="0.17849116027355194 -0.2097601592540741 -0.625745952129364" size="0.1696891188621521 0.0033516890835016966 0.0394631028175354" quat="1.0 0.0 0.0 0.0"/>
            <geom class="collision" type="box" pos="0.15871365368366241 0.3699532151222229 -0.6684530973434448" size="0.1621493101119995 0.003362426068633795 0.0821695402264595" quat="1.0 0.0 0.0 0.0"/>
            <geom class="collision" type="box" pos="0.17849116027355194 -0.20140260457992554 -0.7291679978370667" size="0.16969282925128937 0.011709202080965042 0.03308255970478058" quat="1.0 0.0 0.0 0.0"/>
            <geom class="collision" type="box" pos="0.2886153757572174 -0.20140260457992554 -0.6881449818611145" size="0.059570569545030594 0.011709215119481087 0.03308259695768356" quat="1.0 0.0 0.0 0.0"/>
            <geom class="collision" type="box" pos="0.06517648696899414 -0.20140260457992554 -0.6881449818611145" size="0.05957064405083656 0.011709227226674557 0.033082637935876846" quat="1.0 0.0 0.0 0.0"/>
          </body>
        </body>
        <body name="Body001_Clear">
          <geom mesh="Body001_Clear_vis" type="mesh" solimp="0.998 0.998 0.001" solref="0.001 1" friction="0.95 0.3 0.1" class="visual" material="Body001_Clear_material"/>
          <geom class="collision" type="box" pos="0.18661412596702576 0.07020843774080276 -0.12300799787044525" size="0.20260027050971985 0.3154667317867279 0.008525255136191845" quat="1.0 0.0 0.0 0.0"/>
          <geom class="collision" type="box" pos="0.1887836456298828 0.07026404142379761 0.5248534083366394" size="0.2004307508468628 0.31541016697883606 0.009232099168002605" quat="1.0 0.0 0.0 0.0"/>
          <geom class="collision" type="box" pos="0.18661412596702576 0.07020843774080276 0.20216870307922363" size="0.20260027050971985 0.31543806195259094 0.008524703793227673" quat="1.0 0.0 0.0 0.0"/>
        </body>
        <geom class="region" name="reg_freezer_shelf3" type="box" pos="-0.2324979528784752 0.07216125726699829 0.6865849196910858" size="0.15489344841241837 0.3108192811012268 0.14675520157814026"/>
        <geom class="region" name="reg_freezer_shelf2" type="box" pos="-0.23333770036697388 0.07167620211839676 0.3531992882490158" size="0.15538610315322876 0.3087182397246361 0.15605750477313995"/>
        <geom class="region" name="reg_freezer_shelf1" type="box" pos="-0.23500047624111176 0.07221735268831253 0.006542392075061798" size="0.15502163565158844 0.30723798817396164 0.1602712327837944"/>
        <geom class="region" name="reg_freezer_shelf0" type="box" pos="-0.23454882949590683 0.06945423781871796 -0.3425944522023201" size="0.15648742562532425 0.2998444119691849 0.158168410718441"/>
        <geom class="region" name="reg_fridge_shelf3" type="box" pos="0.19161811866797507 0.07112450897693634 0.6856733560562134" size="0.19389660057984293 0.30931854045391083 0.14570809698104858"/>
        <geom class="region" name="reg_fridge_shelf2" type="box" pos="0.19245707197114825 0.06962138414382935 0.3628503233194351" size="0.19315700821951032 0.30975566601753235 0.14469623363018036"/>
        <geom class="region" name="reg_fridge_shelf1" type="box" pos="0.19210258522070944 0.0664680153131485 0.03841426596045494" size="0.1945901006218046 0.3115565458536148 0.14362429252266884"/>
        <geom class="region" name="reg_fridge_shelf0" type="box" pos="0.18930003605782986 0.07200044393539429 -0.2902291417121887" size="0.19337651862204075 0.30944777822494507 0.1444662938117981"/>
        <geom class="region" name="reg_main" type="box" pos="-9.492039680480957e-06 0.032752200961112976 0.00012764334678649902" size="0.45281429386138916 0.4294836947917938 0.9425686130523682"/>
      </body>
    </body>
  </worldbody>
  <actuator>
    <motor name="freezer_door_joint_actuator" joint="freezer_door_joint" gear="50"/>
    <motor name="freezer_drawer0_joint_actuator" joint="freezer_drawer0_joint" gear="50"/>
    <motor name="fridge_door_joint_actuator" joint="fridge_door_joint" gear="50"/>
    <motor name="fridge_drawer0_joint_actuator" joint="fridge_drawer0_joint" gear="50"/>
  </actuator>
</mujoco>
