<?xml version='1.0' encoding='UTF-8'?>
<mujoco model="model">
  <option timestep="0.002" gravity="0.0 0.0 -9.81"/>
  <compiler angle="radian"/>
  <asset>
    <mesh file="visuals/Body001.obj" name="Body001_vis"/>
    <mesh file="visuals/Button001.obj" name="Button001_vis"/>
    <mesh file="visuals/Button002.obj" name="Button002_vis"/>
    <mesh file="visuals/Container001_Clear.obj" name="Container001_Clear_vis"/>
    <mesh file="visuals/Lid001.obj" name="Lid001_vis"/>
    <mesh file="visuals/Lid002.obj" name="Lid002_vis"/>
    <mesh file="visuals/Lid003.obj" name="Lid003_vis"/>
    <mesh file="visuals/Lid004.obj" name="Lid004_vis"/>
    <texture file="visuals/T_BC001.png" name="Body001_material" type="2d"/>
    <material name="Body001_material" rgba="1 1 1 1.0" texture="Body001_material" shininess="0.1" specular="5"/>
    <texture file="visuals/T_BC001.png" name="Button001_material" type="2d"/>
    <material name="Button001_material" rgba="1 1 1 1.0" texture="Button001_material" shininess="0.1" specular="5"/>
    <texture file="visuals/T_BC001.png" name="Button002_material" type="2d"/>
    <material name="Button002_material" rgba="1 1 1 1.0" texture="Button002_material" shininess="0.1" specular="5"/>
    <texture file="visuals/T_BC001.png" name="Container001_Clear_material" type="2d"/>
    <material name="Container001_Clear_material" rgba="1 1 1 0.699999988079071" texture="Container001_Clear_material" shininess="0.4472135901451111" specular="0.3103448502657381"/>
    <texture file="visuals/T_BC001.png" name="Lid004_material" type="2d"/>
    <material name="Lid004_material" rgba="1 1 1 1.0" texture="Lid004_material" shininess="0.1" specular="5"/>
    <texture file="visuals/T_BC001.png" name="Lid001_material" type="2d"/>
    <material name="Lid001_material" rgba="1 1 1 1.0" texture="Lid001_material" shininess="0.1" specular="5"/>
    <texture file="visuals/T_BC001.png" name="Lid002_material" type="2d"/>
    <material name="Lid002_material" rgba="1 1 1 1.0" texture="Lid002_material" shininess="0.1" specular="5"/>
    <texture file="visuals/T_BC001.png" name="Lid003_material" type="2d"/>
    <material name="Lid003_material" rgba="1 1 1 1.0" texture="Lid003_material" shininess="0.1" specular="5"/>
  </asset>
  <default>
    <default class="visual">
      <geom conaffinity="0" contype="0" group="1" type="mesh"/>
    </default>
    <default class="collision">
      <geom group="0" rgba="0.5 0 0 0.5"/>
    </default>
    <default class="spawn">
      <geom group="0" rgba="1 1 1 0.5" contype="0" conaffinity="0"/>
      <site group="0" rgba="1 1 1 0.5"/>
    </default>
    <default class="region">
      <geom group="1" conaffinity="0" contype="0" rgba="0 1 0 0"/>
    </default>
  </default>
  <worldbody>
    <body>
      <body name="object">
        <geom class="collision" type="box" pos="-0.03277810 -0.24702284 0.03117188" size="0.010365952737629414 0.00039687592652626336 0.008961374871432781" quat="1.0 0.0 0.0 0.0" name="start_button_1" rgba="0.0 0.5 0 0.5"/>
        <geom class="collision" type="box" pos="0.03039741 -0.24702686 0.03125390" size="0.010388100519776344 0.0003994692815467715 0.008916223421692848" quat="1.0 0.0 0.0 0.0" name="start_button_2" rgba="0.0 0.5 0 0.5"/>
        <geom mesh="Body001_vis" type="mesh" solimp="0.998 0.998 0.001" solref="0.001 1" friction="0.95 0.3 0.1" class="visual" material="Body001_material"/>
        <geom class="collision" type="box" pos="-0.00079956 -0.13104488 -0.04166740" size="0.12418649345636368 0.023384904488921165 0.14223738014698029" quat="0.9986448884010315 0.05204177647829056 1.8828349623019795e-17 -4.988197395703159e-19"/>
        <geom class="collision" type="cylinder" pos="-0.01617602 -0.21258181 -0.02041707" size="0.008289889432489872 0.009650186635553837" quat="1.0 0.0 0.0 0.0"/>
        <geom class="collision" type="cylinder" pos="0.01544465 -0.21258181 -0.02041707" size="0.008289889432489872 0.009650186635553837" quat="1.0 0.0 0.0 0.0"/>
        <geom class="collision" type="box" pos="0.00000131 -0.20035318 -0.17397491" size="0.12336799502372742 0.06358985602855682 0.009515829384326935" quat="1.0 0.0 0.0 0.0"/>
        <geom class="collision" type="box" pos="0.00000131 0.02862743 -0.05654930" size="0.1233702301979065 0.14413173496723175 0.13094238936901093" quat="1.0 0.0 0.0 0.0"/>
        <geom class="collision" type="box" pos="0.00000131 -0.06144758 0.09927225" size="0.12343863397836685 0.06841201335191727 0.052273787558078766" quat="1.0 0.0 0.0 0.0"/>
        <geom class="collision" type="box" pos="0.00000131 0.07920269 0.08817737" size="0.12343679368495941 0.08908391743898392 0.03534024953842163" quat="1.0 0.0 0.0 0.0"/>
        <geom class="collision" type="box" pos="0.00000131 -0.13639206 0.11642957" size="0.12343863397836685 0.016342399641871452 0.03268228843808174" quat="0.3122599422931671 0.9499967098236084 1.1613617346411883e-23 -6.933561566806467e-17"/>
        <geom class="collision" type="box" pos="-0.00088095 -0.23598468 0.02737226" size="0.04432997852563858 0.0020263853948563337 0.039324481040239334" quat="1.0 0.0 0.0 0.0"/>
        <geom class="collision" type="box" pos="-0.00093327 -0.17053027 0.04890529" size="0.040293291211128235 0.01328221708536148 0.01780789904296398" quat="1.0 0.0 0.0 0.0"/>
        <geom class="collision" type="box" pos="0.00000131 0.15497166 0.12159006" size="0.12343762069940567 0.013314936310052872 0.033546287566423416" quat="1.0 0.0 0.0 0.0"/>
        <geom class="collision" type="box" pos="-0.00053904 0.03835376 0.11763922" size="0.03857843577861786 0.03424255922436714 0.02959546633064747" quat="1.0 0.0 0.0 0.0"/>
        <geom class="collision" type="box" pos="-0.10990709 0.08078247 0.12090885" size="0.013529595918953419 0.08750413358211517 0.03286510333418846" quat="1.0 0.0 0.0 0.0"/>
        <geom class="collision" type="box" pos="0.10945836 0.08078247 0.12136628" size="0.013529603369534016 0.08750413358211517 0.033322542905807495" quat="1.0 0.0 0.0 0.0"/>
        <geom class="collision" type="box" pos="0.00000131 -0.00511359 0.11892665" size="0.12343785166740417 0.015962105244398117 0.030882928520441055" quat="1.0 0.0 0.0 0.0"/>
        <geom class="collision" type="box" pos="-0.04574231 -0.21286230 0.02692528" size="0.004310887306928635 0.028898626565933228 0.03887750953435898" quat="0.9970703721046448 0.0 0.0 0.07648999243974686"/>
        <geom class="collision" type="box" pos="0.04475864 -0.21179524 0.02692528" size="0.004310887306928635 0.028898626565933228 0.03887750953435898" quat="0.9970703721046448 0.0 -0.0 -0.07649000734090805"/>
        <geom class="collision" type="box" pos="-0.00088095 -0.21019919 0.02043218" size="0.04432974383234978 0.026971854269504547 0.03238440677523613" quat="1.0 0.0 0.0 0.0"/>
        <geom class="collision" type="box" pos="-0.00088095 -0.18451279 0.02736832" size="0.04432972893118858 0.0020263853948563337 0.03932054713368416" quat="1.0 0.0 0.0 0.0"/>
        <body name="Button001">
          <joint axis="0.0 1.0 0.0" pos="-0.03272741 -0.24426828 0.03109809" limited="true" name="Button001_joint" range="0.0 0.003" type="slide" damping="1" frictionloss="1" armature=".01" stiffness="0.05"/>
          <geom mesh="Button001_vis" type="mesh" solimp="0.998 0.998 0.001" solref="0.001 1" friction="0.95 0.3 0.1" class="visual" material="Button001_material"/>
          <geom class="collision" type="box" pos="-0.03277810 -0.24445345 0.03117188" size="0.010365952737629414 0.001881095813587308 0.008961409330368042" quat="1.0 0.0 0.0 0.0"/>
        </body>
        <body name="Button002">
          <joint axis="0.0 1.0 0.0" pos="0.03040877 -0.24426813 0.03103423" limited="true" name="Button002_joint" range="0.0 0.003" type="slide" damping="1" frictionloss="1" armature=".01" stiffness="0.05"/>
          <geom mesh="Button002_vis" type="mesh" solimp="0.998 0.998 0.001" solref="0.001 1" friction="0.95 0.3 0.1" class="visual" material="Button002_material"/>
          <geom class="collision" type="box" pos="0.03039741 -0.24444944 0.03125390" size="0.010388100519776344 0.001885919482447207 0.008916257880628109" quat="1.0 0.0 0.0 0.0"/>
        </body>
        <body name="Container001_Clear">
          <joint axis="0.0 0.0 1.0" pos="-0.00000020 0.22599930 -0.02047880" limited="true" name="Container001_Clear_joint" range="0.0 0.08" type="slide" damping="1" frictionloss="1" armature=".01" stiffness="0.05"/>
          <geom mesh="Container001_Clear_vis" type="mesh" solimp="0.998 0.998 0.001" solref="0.001 1" friction="0.95 0.3 0.1" class="visual" material="Container001_Clear_material"/>
          <geom class="collision" type="box" pos="-0.12213637 0.22671829 -0.02588235" size="0.006022981368005276 0.04276315122842789 0.15839701890945435" quat="1.0 0.0 0.0 0.0"/>
          <geom class="collision" type="box" pos="0.12270178 0.22671829 -0.02588235" size="0.006022981368005276 0.04276315122842789 0.15839701890945435" quat="1.0 0.0 0.0 0.0"/>
          <geom class="collision" type="box" pos="0.00058116 0.26598537 -0.02588235" size="0.1277509480714798 0.0034960575867444277 0.15839701890945435" quat="1.0 0.0 0.0 0.0"/>
          <geom class="collision" type="box" pos="0.00058116 0.18823653 -0.02588235" size="0.1277509480714798 0.0034960575867444277 0.15839701890945435" quat="1.0 0.0 0.0 0.0"/>
          <geom class="collision" type="box" pos="-0.00009430 0.22671829 -0.17501872" size="0.12759384512901306 0.04276315122842789 0.009260643273591995" quat="1.0 0.0 0.0 0.0"/>
          <body name="Lid004">
            <joint axis="0.0 0.0 1.0" pos="0.00000141 0.22599946 0.15324088" limited="true" name="Lid004_joint" range="0.0 0.08" type="slide" damping="1" frictionloss="1" armature=".01" stiffness="0.05"/>
            <geom mesh="Lid004_vis" type="mesh" solimp="0.998 0.998 0.001" solref="0.001 1" friction="0.95 0.3 0.1" class="visual" material="Lid004_material"/>
            <geom class="collision" type="box" pos="0.00000000 0.22664431 0.14481170" size="0.12762826681137085 0.042917173355817795 0.008660576306283474" quat="1.0 0.0 0.0 0.0"/>
            <geom class="collision" type="box" pos="0.04415660 0.22821458 0.16407102" size="0.0024624888319522142 0.0048407018184661865 0.012383795343339443" quat="1.0 0.0 0.0 0.0"/>
            <geom class="collision" type="box" pos="-0.04423017 0.22821458 0.16407100" size="0.0024624888319522142 0.0048407018184661865 0.012383794412016869" quat="1.0 0.0 0.0 0.0"/>
            <geom class="collision" type="box" pos="0.00000000 0.22821458 0.18028548" size="0.046692654490470886 0.0048407018184661865 0.003866489278152585" quat="1.0 0.0 0.0 0.0"/>
          </body>
        </body>
        <body name="Lid001">
          <joint axis="1.0 0.0 0.0" pos="0.00000375 0.00902189 0.15152376" limited="true" name="Lid001_joint" range="0.0 1.5707963267948966" type="hinge" damping="1" frictionloss="1" armature=".01" stiffness="0.05"/>
          <geom mesh="Lid001_vis" type="mesh" solimp="0.998 0.998 0.001" solref="0.001 1" friction="0.95 0.3 0.1" class="visual" material="Lid001_material"/>
          <geom class="collision" type="box" pos="0.00044029 0.07383892 0.15178419" size="0.0946911945939064 0.06126794219017029 0.003488620975986123" quat="1.0 0.0 0.0 0.0"/>
        </body>
        <body name="Lid002">
          <joint axis="0.0 0.0 1.0" pos="0.00024912 -0.20541283 -0.15342011" limited="true" name="Lid002_joint" range="0.0 0.05" type="slide" damping="1" frictionloss="1" armature=".01" stiffness="0.05" springref="-15"/>
          <geom mesh="Lid002_vis" type="mesh" solimp="0.998 0.998 0.001" solref="0.001 1" friction="0.95 0.3 0.1" class="visual" material="Lid002_material"/>
          <geom class="collision" type="box" pos="0.00063344 -0.20927380 -0.15118849" size="0.12173115462064743 0.05168413370847702 0.009040155448019505" quat="1.0 0.0 0.0 0.0"/>
        </body>
        <body name="Lid003">
          <joint axis="-1.0 0.0 0.0" pos="-0.00045279 -0.18430237 0.06775667" limited="true" name="Lid003_joint" range="0.0 1.5707963267948966" type="hinge" damping="1" frictionloss="1" armature=".01" stiffness="0.05"/>
          <geom mesh="Lid003_vis" type="mesh" solimp="0.998 0.998 0.001" solref="0.001 1" friction="0.95 0.3 0.1" class="visual" material="Lid003_material"/>
          <geom class="collision" type="box" pos="-0.00031635 -0.21336108 0.07383061" size="0.05325286462903023 0.030133746564388275 0.004937498364597559" quat="1.0 0.0 0.0 0.0"/>
          <geom class="collision" type="box" pos="0.02009840 -0.23522358 0.08393444" size="0.001121948123909533 0.002205498982220888 0.0056422497145831585" quat="1.0 0.0 0.0 0.0"/>
          <geom class="collision" type="box" pos="-0.02017198 -0.23522358 0.08393443" size="0.001121948123909533 0.002205498982220888 0.005642249248921871" quat="1.0 0.0 0.0 0.0"/>
          <geom class="collision" type="box" pos="-0.00002003 -0.23522358 0.09132200" size="0.02127389796078205 0.002205498982220888 0.0017616326222196221" quat="1.0 0.0 0.0 0.0"/>
        </body>
        <site type="cylinder" rgba="0.8 0.5 0.25 1" size="0.0025506746023893356 0.08439545333385468" pos="-0.01722473 -0.21304743 -0.09830014" name="coffee_liquid_left"/>
        <site type="cylinder" rgba="0.8 0.5 0.25 1" size="0.0025484999641776085 0.08385958522558212" pos="0.01484864 -0.21315731 -0.09846249" name="coffee_liquid_right"/>
        <site rgba="0 0 0 0" size="0.019999999552965164 0.019999999552965164" pos="-0.0011000449999999991 -0.213318065 -0.14946408" name="receptacle_place_site"/>
        <geom class="region" name="reg_main" type="box" pos="0.0 1.0000000022492017e-08 -0.014302505000000007" size="0.12811106 0.26894103 0.17084938500000002"/>
      </body>
    </body>
  </worldbody>
  <actuator>
    <motor name="Button001_joint_actuator" joint="Button001_joint" gear="0.5"/>
    <motor name="Button002_joint_actuator" joint="Button002_joint" gear="0.5"/>
    <motor name="Container001_Clear_joint_actuator" joint="Container001_Clear_joint" gear="10"/>
    <motor name="Lid001_joint_actuator" joint="Lid001_joint" gear="10"/>
    <motor name="Lid002_joint_actuator" joint="Lid002_joint" gear="10"/>
    <motor name="Lid003_joint_actuator" joint="Lid003_joint" gear="10"/>
    <motor name="Lid004_joint_actuator" joint="Lid004_joint" gear="10"/>
  </actuator>
</mujoco>
