<?xml version='1.0' encoding='UTF-8'?>
<mujoco model="model">
  <option timestep="0.002" gravity="0.0 0.0 -9.81"/>
  <compiler angle="radian"/>
  <asset>
    <mesh file="visuals/knob_center.obj" name="knob_center_vis"/>
    <mesh file="visuals/knob_front_left.obj" name="knob_front_left_vis"/>
    <mesh file="visuals/knob_front_right.obj" name="knob_front_right_vis"/>
    <mesh file="visuals/knob_rear_left.obj" name="knob_rear_left_vis"/>
    <mesh file="visuals/knob_rear_right.obj" name="knob_rear_right_vis"/>
    <mesh file="visuals/Body001.obj" name="Body001_vis"/>
    <mesh file="visuals/Body002.obj" name="Body002_vis"/>
    <texture file="visuals/T_BC001.png" name="Body001_material" type="2d"/>
    <material name="Body001_material" rgba="1 1 1 1.0" texture="Body001_material" shininess="0.2512328028678894" specular="1"/>
    <texture file="visuals/T_BC001.png" name="knob_center_material" type="2d"/>
    <material name="knob_center_material" rgba="1 1 1 1.0" texture="knob_center_material" shininess="0.2512328028678894" specular="0.3103448502657381"/>
    <texture file="visuals/T_BC001.png" name="knob_front_left_material" type="2d"/>
    <material name="knob_front_left_material" rgba="1 1 1 1.0" texture="knob_front_left_material" shininess="0.2512328028678894" specular="0.3103448502657381"/>
    <texture file="visuals/T_BC001.png" name="knob_front_right_material" type="2d"/>
    <material name="knob_front_right_material" rgba="1 1 1 1.0" texture="knob_front_right_material" shininess="0.2512328028678894" specular="0.3103448502657381"/>
    <texture file="visuals/T_BC001.png" name="knob_rear_left_material" type="2d"/>
    <material name="knob_rear_left_material" rgba="1 1 1 1.0" texture="knob_rear_left_material" shininess="0.2512328028678894" specular="0.3103448502657381"/>
    <texture file="visuals/T_BC001.png" name="knob_rear_right_material" type="2d"/>
    <material name="knob_rear_right_material" rgba="1 1 1 1.0" texture="knob_rear_right_material" shininess="0.2512328028678894" specular="0.3103448502657381"/>
    <texture file="visuals/T_BC001.png" name="Body002_material" type="2d"/>
    <material name="Body002_material" rgba="1 1 1 1.0" texture="Body002_material" shininess="0.2512328028678894" specular="3"/>
  </asset>
  <default>
    <default class="visual">
      <geom conaffinity="0" contype="0" group="1" type="mesh"/>
    </default>
    <default class="collision">
      <geom group="0" rgba="0.5 0 0 0.5"/>
    </default>
    <default class="spawn">
      <geom group="0" rgba="1 1 1 0.5" contype="0" conaffinity="0"/>
      <site group="0" rgba="1 1 1 0.5"/>
    </default>
    <default class="region">
      <geom group="1" conaffinity="0" contype="0" rgba="0 1 0 0"/>
    </default>
  </default>
  <worldbody>
    <body>
      <body name="object">
        <geom mesh="Body001_vis" type="mesh" solimp="0.998 0.998 0.001" solref="0.001 1" friction="0.95 0.3 0.1" class="visual" material="Body001_material"/>
        <geom class="collision" type="box" pos="-0.00000002 -0.00000004 -0.01375558" size="0.35133975744247437 0.19492700695991516 0.0033905429299920797" quat="1.0 0.0 0.0 0.0"/>
        <geom class="collision" type="box" pos="0.01146940 0.01616270 0.00339708" size="0.3201993405818939 0.16035503149032593 0.013762135989964008" quat="1.0 0.0 0.0 0.0"/>
        <body name="knob_center">
          <joint axis="0.0 0.0 1.0" pos="-0.02171858 -0.16454811 -0.00384272" limited="true" name="knob_center_joint" range="0.0 3.6651914291880923" type="hinge" damping="0.2" armature="0.01" frictionloss="1"/>
          <geom mesh="knob_center_vis" type="mesh" solimp="0.998 0.998 0.001" solref="0.001 1" friction="0.95 0.3 0.1" class="visual" material="knob_center_material"/>
          <geom class="collision" type="cylinder" pos="-0.02172021 -0.16453014 -0.00818815" size="0.014798812568187714 0.0009359997930005193" quat="1.0 0.0 0.0 0.0" friction="100 0.5 0.01"/>
          <geom class="collision" type="box" pos="-0.02166770 -0.16444397 -0.00230392" size="0.0029218827839940786 0.013743828050792217 0.005035351496189833" quat="1.0 0.0 0.0 0.0" name="knob_center_main" friction="100 0.5 0.01"/>
        </body>
        <body name="knob_front_left">
          <joint axis="0.0 0.0 1.0" pos="-0.19387552 -0.16454796 -0.00384268" limited="true" name="knob_front_left_joint" range="0.0 3.6651914291880923" type="hinge" damping="0.2" armature="0.01" frictionloss="1"/>
          <geom mesh="knob_front_left_vis" type="mesh" solimp="0.998 0.998 0.001" solref="0.001 1" friction="0.95 0.3 0.1" class="visual" material="knob_front_left_material"/>
          <geom class="collision" type="cylinder" pos="-0.19387773 -0.16453014 -0.00818815" size="0.014798812568187714 0.0009359997930005193" quat="1.0 0.0 0.0 0.0" friction="100 0.5 0.01"/>
          <geom class="collision" type="box" pos="-0.19382520 -0.16444397 -0.00230392" size="0.0029218827839940786 0.013743828050792217 0.005035351496189833" quat="1.0 0.0 0.0 0.0" name="knob_front_left_main" friction="100 0.5 0.01"/>
        </body>
        <body name="knob_front_right">
          <joint axis="0.0 0.0 1.0" pos="0.14702818 -0.16454808 -0.00384234" limited="true" name="knob_front_right_joint" range="0.0 3.6651914291880923" type="hinge" damping="0.2" armature="0.01" frictionloss="1"/>
          <geom mesh="knob_front_right_vis" type="mesh" solimp="0.998 0.998 0.001" solref="0.001 1" friction="0.95 0.3 0.1" class="visual" material="knob_front_right_material"/>
          <geom class="collision" type="cylinder" pos="0.14708915 -0.16453014 -0.00818815" size="0.014798812568187714 0.0009359997930005193" quat="1.0 0.0 0.0 0.0" friction="100 0.5 0.01"/>
          <geom class="collision" type="box" pos="0.14714165 -0.16444397 -0.00230392" size="0.0029218827839940786 0.013743828050792217 0.005035351496189833" quat="1.0 0.0 0.0 0.0" name="knob_front_right_main" friction="100 0.5 0.01"/>
        </body>
        <body name="knob_rear_left">
          <joint axis="0.0 0.0 1.0" pos="-0.10653371 -0.16454779 -0.00384285" limited="true" name="knob_rear_left_joint" range="0.0 3.6651914291880923" type="hinge" damping="0.2" armature="0.01" frictionloss="1"/>
          <geom mesh="knob_rear_left_vis" type="mesh" solimp="0.998 0.998 0.001" solref="0.001 1" friction="0.95 0.3 0.1" class="visual" material="knob_rear_left_material"/>
          <geom class="collision" type="cylinder" pos="-0.10649148 -0.16453014 -0.00818815" size="0.014798812568187714 0.0009359997930005193" quat="1.0 0.0 0.0 0.0" friction="100 0.5 0.01"/>
          <geom class="collision" type="box" pos="-0.10643896 -0.16444397 -0.00230392" size="0.0029218827839940786 0.013743828050792217 0.005035351496189833" quat="1.0 0.0 0.0 0.0" name="knob_rear_left_main" friction="100 0.5 0.01"/>
        </body>
        <body name="knob_rear_right">
          <joint axis="0.0 0.0 1.0" pos="0.06127256 -0.16454810 -0.00384248" limited="true" name="knob_rear_right_joint" range="0.0 3.6651914291880923" type="hinge" damping="0.2" armature="0.01" frictionloss="1"/>
          <geom mesh="knob_rear_right_vis" type="mesh" solimp="0.998 0.998 0.001" solref="0.001 1" friction="0.95 0.3 0.1" class="visual" material="knob_rear_right_material"/>
          <geom class="collision" type="cylinder" pos="0.06128004 -0.16453014 -0.00818815" size="0.014798812568187714 0.0009359997930005193" quat="1.0 0.0 0.0 0.0" friction="100 0.5 0.01"/>
          <geom class="collision" type="box" pos="0.06133255 -0.16444397 -0.00230392" size="0.0029218827839940786 0.013743828050792217 0.005035351496189833" quat="1.0 0.0 0.0 0.0" name="knob_rear_right_main" friction="100 0.5 0.01"/>
        </body>
        <body name="Body002">
          <geom mesh="Body002_vis" type="mesh" solimp="0.998 0.998 0.001" solref="0.001 1" friction="0.95 0.3 0.1" class="visual" material="Body002_material"/>
        </body>
        <site type="cylinder" rgba="0.3 0.4 1 0.5" size="0.031039979308843613 0.0026827813126146793" pos="-0.23412663 -0.06868687 0.00526870" name="burner_on_front_left"/>
        <site type="cylinder" rgba="0.3 0.4 1 0.5" size="0.0388636477291584 0.0029999760445207357" pos="0.22262686 -0.05143708 0.00566337" name="burner_on_front_right"/>
        <site type="cylinder" rgba="0.3 0.4 1 0.5" size="0.03170698881149292 0.0026528744492679834" pos="-0.19920354 0.10191014 0.00538281" name="burner_on_rear_left"/>
        <site type="cylinder" rgba="0.3 0.4 1 0.5" size="0.02689894661307335 0.002362231258302927" pos="0.19548251 0.11091150 0.00538078" name="burner_on_rear_right"/>
        <site type="cylinder" rgba="0.3 0.4 1 0.5" size="0.03561927750706673 0.0027672413270920515" pos="-0.00185037 0.03284667 0.00501985" name="burner_on_center"/>
        <site type="cylinder" rgba="0.5 0 0 0" size="0.03561927750706673 4.999999873689376e-05" pos="-0.00185037 0.03284667 0.01715920" name="burner_center_place_site"/>
        <site type="cylinder" rgba="0.5 0 0 0" size="0.031039979308843613 4.999999873689376e-05" pos="-0.23412663 -0.06868687 0.01715921" name="burner_front_left_place_site"/>
        <site type="cylinder" rgba="0.5 0 0 0" size="0.0388636477291584 4.999999873689376e-05" pos="0.22262686 -0.05143708 0.01715920" name="burner_front_right_place_site"/>
        <site type="cylinder" rgba="0.5 0 0 0" size="0.03170698881149292 4.999999873689376e-05" pos="-0.19920354 0.10191014 0.01715920" name="burner_rear_left_place_site"/>
        <site type="cylinder" rgba="0.5 0 0 0" size="0.02689894661307335 4.999999873689376e-05" pos="0.19548251 0.11091150 0.01715920" name="burner_rear_right_place_site"/>
        <geom class="region" name="reg_main" type="box" pos="4.999999997368221e-09 -9.999999994736442e-09 -0.01375559" size="0.35233975500000003 0.19592692 0.004390539999999999"/>
      </body>
    </body>
  </worldbody>
  <actuator>
    <motor name="knob_center_joint_actuator" joint="knob_center_joint" gear="10"/>
    <motor name="knob_front_left_joint_actuator" joint="knob_front_left_joint" gear="10"/>
    <motor name="knob_front_right_joint_actuator" joint="knob_front_right_joint" gear="10"/>
    <motor name="knob_rear_left_joint_actuator" joint="knob_rear_left_joint" gear="10"/>
    <motor name="knob_rear_right_joint_actuator" joint="knob_rear_right_joint" gear="10"/>
  </actuator>
</mujoco>