<?xml version='1.0' encoding='UTF-8'?>
<mujoco model="model">
  <option timestep="0.002" gravity="0.0 0.0 -9.81"/>
  <compiler angle="radian"/>
  <asset>
    <mesh file="visuals/button_lid.obj" name="button_lid_vis"/>
    <mesh file="visuals/Body001.obj" name="Body001_vis"/>
    <mesh file="visuals/kettle_main.obj" name="kettle_main_vis"/>
    <mesh file="visuals/lid.obj" name="lid_vis"/>
    <mesh file="visuals/switch.obj" name="switch_vis"/>
    <texture file="visuals/T_BC001.png" name="Body001_material" type="2d"/>
    <material name="Body001_material" rgba="1 1 1 1.0" texture="Body001_material" shininess="0.5" specular="0.3103448502657381"/>
    <texture file="visuals/T_BC001.png" name="kettle_main_material" type="2d"/>
    <material name="kettle_main_material" rgba="1 1 1 1.0" texture="kettle_main_material" shininess="0.5" specular="0.3103448502657381"/>
    <texture file="visuals/T_BC001.png" name="button_lid_material" type="2d"/>
    <material name="button_lid_material" rgba="1 1 1 1.0" texture="button_lid_material" shininess="0.5" specular="0.3103448502657381"/>
    <texture file="visuals/T_BC001.png" name="lid_material" type="2d"/>
    <material name="lid_material" rgba="1 1 1 1.0" texture="lid_material" shininess="0.5" specular="0.3103448502657381"/>
    <texture file="visuals/T_BC001.png" name="switch_material" type="2d"/>
    <material name="switch_material" rgba="1 1 1 1.0" texture="switch_material" shininess="0.5" specular="0.3103448502657381"/>
  </asset>
  <default>
    <default class="visual">
      <geom conaffinity="0" contype="0" group="1" type="mesh"/>
    </default>
    <default class="collision">
      <geom group="0" rgba="0.5 0 0 0.5"/>
    </default>
    <default class="spawn">
      <geom group="0" rgba="1 1 1 0.5" contype="0" conaffinity="0"/>
      <site group="0" rgba="1 1 1 0.5"/>
    </default>
    <default class="region">
      <geom group="1" conaffinity="0" contype="0" rgba="0 1 0 0" mass="0"/>
    </default>
  </default>
  <worldbody>
    <body>
      <body name="object">
        <geom mesh="Body001_vis" type="mesh" solimp="0.998 0.998 0.001" solref="0.001 1" friction="0.95 0.3 0.1" class="visual" material="Body001_material"/>
        <geom type="cylinder" pos="-0.04934823 -0.00056727 -0.24220326" size="0.15319550037384033 0.010539539158344269" quat="0.9925832152366638 3.1118056048606846e-11 8.99330476755722e-09 0.12156697362661362" class="collision"/>
        <body name="kettle_main">
          <joint axis="0.0 0.0 1.0" pos="0.00000016 -0.00040705 0.01601267" limited="true" name="kettle_main_joint" range="0.0 0.1" type="slide" damping="1" frictionloss="1" armature=".01" stiffness="0.05"/>
          <geom mesh="kettle_main_vis" type="mesh" solimp="0.998 0.998 0.001" solref="0.001 1" friction="0.95 0.3 0.1" class="visual" material="kettle_main_material"/>
          <geom type="cylinder" pos="-0.04934823 -0.00056727 -0.21769720" size="0.153195321559906 0.00859247799962759" quat="0.9925832152366638 3.1118056048606846e-11 8.99330476755722e-09 0.12156697362661362" class="collision"/>
          <geom type="box" pos="-0.04681783 -0.13738767 0.01065584" size="0.05016103386878967 0.01536363735795021 0.2227715104818344" quat="1.0 0.0 0.0 0.0" class="collision"/>
          <geom type="box" pos="-0.13316240 -0.10760645 0.01065584" size="0.010152064263820648 0.050161123275756836 0.22259505093097687" quat="0.9023288488388062 -0.005047536455094814 0.010570093058049679 0.43088915944099426" class="collision"/>
          <geom type="box" pos="-0.18170822 -0.02964404 0.01065584" size="0.010152065195143223 0.050161123275756836 0.22259505093097687" quat="0.9945631623268127 -0.0012121195904910564 0.01165055576711893 0.10347403585910797" class="collision"/>
          <geom type="box" pos="-0.17083769 0.05997668 0.01065584" size="0.010152065195143223 0.050161127001047134 0.22259505093097687" quat="0.973112940788269 0.0026946321595460176 0.01139928214251995 -0.23003041744232178" class="collision"/>
          <geom type="box" pos="-0.10543854 0.12389828 0.01065584" size="0.010152065195143223 0.050161127001047134 0.22259505093097687" quat="0.8405178189277649 0.006345106288790703 0.009846033528447151 -0.5416573286056519" class="collision"/>
          <geom type="box" pos="-0.01306965 0.13208089 0.01065584" size="0.010152065195143223 0.050161127001047134 0.22259505093097687" quat="0.6075727939605713 0.009303187020123005 0.007117252331227064 -0.7941776514053345" class="collision"/>
          <geom type="box" pos="0.06176675 0.08170518 0.01065584" size="0.010152065195143223 0.050161127001047134 0.22259505093097687" quat="0.3121856451034546 0.011127935722470284 0.0036570196971297264 -0.9499489068984985" class="collision"/>
          <geom type="box" pos="0.08831079 -0.00657713 0.03858026" size="0.010152065195143223 0.050161123275756836 0.19466298818588257" quat="0.026527434587478638 -0.011709306389093399 0.00031074826256372035 0.9995794296264648" class="collision"/>
          <geom type="box" pos="0.05458725 -0.09132070 0.01065584" size="0.010152065195143223 0.050161127001047134 0.22259505093097687" quat="0.3585485816001892 -0.010934511199593544 0.004200125113129616 0.9334375858306885" class="collision"/>
          <geom type="box" pos="0.00809588 -0.12546318 0.01065584" size="0.010152065195143223 0.015005323104560375 0.22259505093097687" quat="0.5347365140914917 -0.009897803887724876 0.006264031864702702 0.8449376821517944" class="collision"/>
          <geom class="collision" type="box" pos="0.13043668 -0.00356584 0.22212885" size="0.029746653512120247 0.03134914115071297 0.030624259263277054" quat="1.0 0.0 0.0 0.0" name="handle_6"/>
          <geom class="collision" type="box" pos="0.17117275 -0.00356584 0.19748609" size="0.03134913742542267 0.0355534553527832 0.02197188138961792" quat="0.6696721315383911 0.22702263295650482 0.22702261805534363 0.6696720719337463" name="handle_2"/>
          <geom class="collision" type="box" pos="0.20631122 -0.00356585 0.19538029" size="0.009490305557847023 0.03134913742542267 0.02767837978899479" quat="1.0 0.0 0.0 0.0" name="handle_1"/>
          <geom class="collision" type="box" pos="0.19243986 -0.00356584 0.07325474" size="0.02345595695078373 0.03134914115071297 0.10568643361330032" quat="1.0 0.0 0.0 0.0" name="handle_main"/>
          <geom class="collision" type="box" pos="0.13399833 -0.00356584 -0.07451055" size="0.03774268180131912 0.03134913742542267 0.025011377409100533" quat="1.0 0.0 0.0 0.0" name="handle_5"/>
          <geom class="collision" type="box" pos="0.17749398 -0.00356584 -0.05992023" size="0.03134913742542267 0.02665935456752777 0.026784004643559456" quat="0.6408565044403076 0.2988361716270447 0.2988361120223999 0.6408563256263733" name="handle_4"/>
          <geom class="collision" type="box" pos="0.19144962 -0.00356584 -0.03791006" size="0.03134913742542267 0.02665935456752777 0.026784004643559456" quat="0.6999636888504028 0.10025401413440704 0.10025400668382645 0.6999636292457581" name="handle_3"/>
          <body name="button_lid">
            <joint axis="0.0 0.0 -1.0" pos="0.18074461 -0.00442379 0.23688264" limited="true" name="button_lid_joint" range="0.0 0.008" type="slide" damping="100" frictionloss="1" armature=".01" stiffness="1" springref="-0.5"/>
            <geom mesh="button_lid_vis" type="mesh" solimp="0.998 0.998 0.001" solref="0.001 1" friction="0.95 0.3 0.1" class="visual" material="button_lid_material"/>
            <geom class="collision" type="box" pos="0.18020124 -0.00458804 0.23664619" size="0.013496940955519676 0.012868782505393028 0.007086337078362703" quat="0.6870449781417847 0.16723966598510742 0.16723966598510742 0.6870450973510742" name="button_lid_main"/>
          </body>
          <body name="lid">
            <joint axis="0.0 1.0 0.0" pos="0.10149171 -0.00079914 0.25052171" limited="true" name="lid_joint" range="0.0 1.5707963267948966" type="hinge" damping="1" frictionloss="1" armature=".01" stiffness="0.05"/>
            <geom mesh="lid_vis" type="mesh" solimp="0.998 0.998 0.001" solref="0.001 1" friction="0.95 0.3 0.1" class="visual" material="lid_material"/>
            <geom class="collision" type="cylinder" pos="-0.04877632 -0.00056839 0.24701281" size="0.13979527354240417 0.005358262453228235" quat="0.9925832152366638 3.1117417670367686e-11 8.99330476755722e-09 0.12156695872545242" name="lid_main"/>
          </body>
          <body name="switch">
            <joint axis="0.0 0.0 -1.0" pos="0.10964334 -0.00309735 -0.17119339" limited="true" name="switch_joint" range="0.0 0.008" type="slide" damping="100" frictionloss="1" armature=".01" stiffness="2" springref="-1"/>
            <geom mesh="switch_vis" type="mesh" solimp="0.998 0.998 0.001" solref="0.001 1" friction="0.95 0.3 0.1" class="visual" material="switch_material"/>
            <geom class="collision" type="box" pos="0.13642257 -0.00322041 -0.17162852" size="0.05087071284651756 0.02275552973151207 0.008647226728498936" quat="0.9998746514320374 0.0019454614957794547 -0.01431172527372837 -0.006486942991614342" name="switch_main"/>
          </body>
        </body>
        <geom class="region" name="reg_main" type="box" pos="1.5500000000168157e-07 2.2500000000647002e-07 1.4500000000694513e-07" size="0.216449885 0.151226235 0.253441225"/>
      </body>
    </body>
  </worldbody>
  <actuator>
    <motor name="kettle_main_joint_actuator" joint="kettle_main_joint" gear="10"/>
    <motor name="button_lid_joint_actuator" joint="button_lid_joint" gear="50"/>
    <motor name="lid_joint_actuator" joint="lid_joint" gear="0.5"/>
    <motor name="switch_joint_actuator" joint="switch_joint" gear="50"/>
  </actuator>
</mujoco>
