<?xml version='1.0' encoding='UTF-8'?>
<mujoco model="model">
  <option timestep="0.002" gravity="0.0 0.0 -9.81"/>
  <compiler angle="radian"/>
  <asset>
    <mesh file="visuals/door.obj" name="door_vis"/>
    <mesh file="visuals/door_Clear.obj" name="door_Clear_vis"/>
    <mesh file="visuals/Body001.obj" name="Body001_vis"/>
    <mesh file="visuals/Button001.obj" name="Button001_vis"/>
    <mesh file="visuals/Button002.obj" name="Button002_vis"/>
    <mesh file="visuals/Button003.obj" name="Button003_vis"/>
    <mesh file="visuals/Button004.obj" name="Button004_vis"/>
    <mesh file="visuals/Disc001.obj" name="Disc001_vis"/>
    <mesh file="visuals/Knob001.obj" name="Knob001_vis"/>
    <texture file="visuals/T_BC001.png" name="Body001_material" type="2d"/>
    <material name="Body001_material" rgba="1 1 1 1.0" texture="Body001_material" shininess="0.4472135901451111" specular="0.6"/>
    <texture file="visuals/T_BC001.png" name="door_material" type="2d"/>
    <material name="door_material" rgba="1 1 1 1.0" texture="door_material" shininess="0.4472135901451111" specular="0.6"/>
    <texture file="visuals/T_BC001.png" name="door_Clear_material" type="2d"/>
    <material name="door_Clear_material" rgba="1 1 1 0.800000011920929" texture="door_Clear_material" shininess="0.5" specular="0.3103448502657381"/>
    <texture file="visuals/T_BC001.png" name="Button001_material" type="2d"/>
    <material name="Button001_material" rgba="1 1 1 1.0" texture="Button001_material" shininess="0.4472135901451111" specular="0.3103448502657381"/>
    <texture file="visuals/T_BC001.png" name="Button002_material" type="2d"/>
    <material name="Button002_material" rgba="1 1 1 1.0" texture="Button002_material" shininess="0.4472135901451111" specular="0.3103448502657381"/>
    <texture file="visuals/T_BC001.png" name="Button003_material" type="2d"/>
    <material name="Button003_material" rgba="1 1 1 1.0" texture="Button003_material" shininess="0.4472135901451111" specular="0.3103448502657381"/>
    <texture file="visuals/T_BC001.png" name="Button004_material" type="2d"/>
    <material name="Button004_material" rgba="1 1 1 1.0" texture="Button004_material" shininess="0.4472135901451111" specular="0.3103448502657381"/>
    <texture file="visuals/T_BC001.png" name="Disc001_material" type="2d"/>
    <material name="Disc001_material" rgba="1 1 1 1.0" texture="Disc001_material" shininess="0.4472135901451111" specular="0.3103448502657381"/>
    <texture file="visuals/T_BC001.png" name="Knob001_material" type="2d"/>
    <material name="Knob001_material" rgba="1 1 1 1.0" texture="Knob001_material" shininess="0.4472135901451111" specular="0.3103448502657381"/>
  </asset>
  <default>
    <default class="visual">
      <geom conaffinity="0" contype="0" group="1" type="mesh"/>
    </default>
    <default class="collision">
      <geom group="0" rgba="0.5 0 0 0.5"/>
    </default>
    <default class="spawn">
      <geom group="0" rgba="1 1 1 0.5" contype="0" conaffinity="0"/>
      <site group="0" rgba="1 1 1 0.5"/>
    </default>
    <default class="region">
      <geom group="1" conaffinity="0" contype="0" rgba="0 1 0 0"/>
    </default>
  </default>
  <worldbody>
    <body>
      <body name="object">
        <geom class="collision" type="box" pos="0.23226194 -0.17492282 -0.00080308" size="0.010865318588912487 0.0003564048674888909 0.007287237793207169" quat="1.0 0.0 0.0 0.0" name="stop_button" rgba="0.0 0.5 0 0.5" density="1000.0"/>
        <geom class="collision" type="box" pos="0.17957030 -0.17492282 -0.00087545" size="0.010752649046480656 0.0003564048674888909 0.007287243846803904" quat="1.0 0.0 0.0 0.0" name="start_button" rgba="0.0 0.5 0 0.5" density="1000.0"/>
        <geom class="collision" type="cylinder" pos="-0.04343949 0.00609910 -0.11175275" size="0.1445775032043457 0.0020862373057752848" quat="1.0 0.0 0.0 0.0" name="tray" rgba="0 1 0 0.5" density="1000.0"/>
        <geom mesh="Body001_vis" type="mesh" solimp="0.998 0.998 0.001" solref="0.001 1" friction="0.95 0.3 0.1" class="visual" material="Body001_material"/>
        <geom class="collision" type="box" pos="0.00000000 0.01976723 -0.13037679" size="0.2561173439025879 0.16050338745117188 0.009735439904034138" quat="1.0 0.0 0.0 0.0" density="1000.0"/>
        <geom class="collision" type="box" pos="-0.25098914 0.01976723 -0.00040135" size="0.009735459461808205 0.16050338745117188 0.13971087336540222" quat="1.0 0.0 0.0 0.0" density="1000.0"/>
        <geom class="collision" type="box" pos="0.20362362 0.02169219 -0.00208206" size="0.05675646662712097 0.1624283492565155 0.13803021609783173" quat="1.0 0.0 0.0 0.0" density="1000.0"/>
        <geom class="collision" type="box" pos="-0.00095456 0.01976723 0.13124931" size="0.25599798560142517 0.16050338745117188 0.009735514409840107" quat="1.0 0.0 0.0 0.0" density="1000.0"/>
        <geom class="collision" type="box" pos="0.20890890 -0.15583068 0.09594884" size="0.05112596973776817 0.016179263591766357 0.04533351957798004" quat="1.0 0.0 0.0 0.0" density="1000.0"/>
        <geom class="collision" type="box" pos="0.20890890 -0.15583067 -0.12315992" size="0.05112596973776817 0.016179248690605164 0.015614388510584831" quat="1.0 0.0 0.0 0.0" density="1000.0"/>
        <geom class="collision" type="box" pos="-0.00095456 0.17264286 -0.00041758" size="0.2559981048107147 0.011477652937173843 0.13969483971595764" quat="1.0 0.0 0.0 0.0" density="1000.0"/>
        <geom class="collision" type="box" pos="0.25108978 -0.15326962 -0.03127562" size="0.009634836576879025 0.017295151948928833 0.0828639417886734" quat="1.0 0.0 0.0 0.0" density="1000.0"/>
        <geom class="collision" type="box" pos="0.20723997 -0.15178923 -0.02871906" size="0.05279489979147911 0.012137813493609428 0.0843416228890419" quat="1.0 0.0 0.0 0.0" density="1000.0"/>
        <geom class="collision" type="box" pos="-0.06028022 0.19340326 -0.00371723" size="0.13738931715488434 0.011110029183328152 0.08140583336353302" quat="1.0 0.0 0.0 0.0" density="1000.0"/>
        <body name="door">
          <joint axis="0.0 0.0 1.0" pos="-0.24642402 -0.15854581 0.00176600" limited="true" name="microjoint" range="-1.5707963267948966 0.0" type="hinge" damping="1" frictionloss="1" armature=".01" stiffness="0.05"/>
          <geom mesh="door_vis" type="mesh" solimp="0.998 0.998 0.001" solref="0.001 1" friction="0.95 0.3 0.1" class="visual" material="door_material"/>
          <geom class="collision" type="box" pos="-0.23008050 -0.16423556 0.00967478" size="0.018940173089504242 0.00777437724173069 0.12963473796844482" quat="1.0 0.0 0.0 0.0" density="1000.0"/>
          <geom class="collision" type="box" pos="0.13918962 -0.16690987 0.00153841" size="0.013055304065346718 0.005100064445286989 0.10477712750434875" quat="1.0 0.0 0.0 0.0" density="1000.0"/>
          <geom class="collision" type="box" pos="-0.04434631 -0.16690984 0.11590888" size="0.16593848168849945 0.0051000542007386684 0.023612966760993004" quat="1.0 0.0 0.0 0.0" density="1000.0"/>
          <geom class="collision" type="box" pos="-0.04434631 -0.16690986 -0.11910865" size="0.16593848168849945 0.005100075621157885 0.01936274580657482" quat="1.0 0.0 0.0 0.0" density="1000.0"/>
          <geom class="collision" type="box" pos="0.13918962 -0.20149144 0.00119166" size="0.013055302202701569 0.005230289418250322 0.07266724854707718" quat="1.0 0.0 0.0 0.0" name="door_handle_main" density="1000.0"/>
          <geom class="collision" type="box" pos="0.13918962 -0.18560883 0.10048172" size="0.028987692669034004 0.005230325739830732 0.013055308721959591" quat="0.24476705491542816 0.6633921265602112 -0.24476711452007294 -0.6633920669555664" density="1000.0"/>
          <geom class="collision" type="box" pos="0.13918965 -0.18890262 -0.09872164" size="0.028987696394324303 0.005230325274169445 0.013055308721959591" quat="0.23891746997833252 -0.6655211448669434 -0.23891784250736237 0.6655210852622986" density="1000.0"/>
          <geom class="collision" type="box" pos="-0.05030357 -0.17102933 0.00180240" size="0.1985093206167221 0.000980594428256154 0.13694004714488983" quat="1.0 0.0 0.0 0.0" name="door_main" density="1000.0"/>
          <body name="door_Clear">
            <geom mesh="door_Clear_vis" type="mesh" solimp="0.998 0.998 0.001" solref="0.001 1" friction="0.95 0.3 0.1" class="visual" material="door_Clear_material"/>
            <geom class="collision" type="box" pos="-0.04336450 -0.16622159 -0.00116957" size="0.16303934156894684 0.005230299197137356 0.08998294919729233" quat="1.0 0.0 0.0 0.0" density="1000.0"/>
          </body>
        </body>
        <body name="Button001">
          <joint axis="0.0 1.0 0.0" pos="0.17988761 -0.17231548 0.04328461" limited="true" name="Button001_joint" range="0.0 0.002" type="slide" damping="1" frictionloss="1" armature=".01" stiffness="0.05"/>
          <geom mesh="Button001_vis" type="mesh" solimp="0.998 0.998 0.001" solref="0.001 1" friction="0.95 0.3 0.1" class="visual" material="Button001_material"/>
          <geom class="collision" type="box" pos="0.17961366 -0.17262451 0.04328701" size="0.011165895499289036 0.0019255145452916622 0.006943767890334129" quat="1.0 0.0 0.0 0.0" density="1000.0"/>
        </body>
        <body name="Button002">
          <joint axis="0.0 1.0 0.0" pos="0.23231645 -0.17231548 0.04328461" limited="true" name="Button002_joint" range="0.0 0.002" type="slide" damping="1" frictionloss="1" armature=".01" stiffness="0.05"/>
          <geom mesh="Button002_vis" type="mesh" solimp="0.998 0.998 0.001" solref="0.001 1" friction="0.95 0.3 0.1" class="visual" material="Button002_material"/>
          <geom class="collision" type="box" pos="0.23250706 -0.17262451 0.04322955" size="0.010951997712254524 0.0019255145452916622 0.006847924552857876" quat="1.0 0.0 0.0 0.0" density="1000.0"/>
        </body>
        <body name="Button003">
          <joint axis="0.0 1.0 0.0" pos="0.23231645 -0.17231548 -0.00100187" limited="true" name="Button003_joint" range="0.0 0.002" type="slide" damping="1" frictionloss="1" armature=".01" stiffness="0.05"/>
          <geom mesh="Button003_vis" type="mesh" solimp="0.998 0.998 0.001" solref="0.001 1" friction="0.95 0.3 0.1" class="visual" material="Button003_material"/>
          <geom class="collision" type="box" pos="0.17977649 -0.17231575 -0.00091366" size="0.011165895499289036 0.0019255145452916622 0.007382688112556934" quat="1.0 0.0 0.0 0.0" density="1000.0"/>
        </body>
        <body name="Button004">
          <joint axis="0.0 1.0 0.0" pos="0.17988761 -0.17231548 -0.00100187" limited="true" name="Button004_joint" range="0.0 0.002" type="slide" damping="1" frictionloss="1" armature=".01" stiffness="0.05"/>
          <geom mesh="Button004_vis" type="mesh" solimp="0.998 0.998 0.001" solref="0.001 1" friction="0.95 0.3 0.1" class="visual" material="Button004_material"/>
          <geom class="collision" type="box" pos="0.23223570 -0.17231575 -0.00079394" size="0.011111618019640446 0.0019255145452916622 0.007342796307057142" quat="1.0 0.0 0.0 0.0" density="1000.0"/>
        </body>
        <body name="Disc001">
          <joint axis="0.0 0.0 1.0" pos="-0.04343949 0.00609909 -0.11422905" limited="false" name="Disc001_joint" range="0 360" type="hinge" damping="1" frictionloss="1" armature=".01" stiffness="0.05"/>
          <geom mesh="Disc001_vis" type="mesh" solimp="0.998 0.998 0.001" solref="0.001 1" friction="0.95 0.3 0.1" class="visual" material="Disc001_material"/>
          <geom class="collision" type="cylinder" pos="-0.04343949 0.00609910 -0.11716770" size="0.1445775032043457 0.0016238843090832233" quat="1.0 0.0 0.0 0.0" density="1000.0"/>
        </body>
        <body name="Knob001">
          <joint axis="0.0 1.0 0.0" pos="0.20450345 -0.18421864 -0.06694476" limited="true" name="Knob001_joint" range="0.0 3.961897402027128" type="hinge" damping="0.05" armature="0.001"/>
          <geom mesh="Knob001_vis" type="mesh" solimp="0.998 0.998 0.001" solref="0.001 1" friction="0.95 0.3 0.1" class="visual" material="Knob001_material"/>
          <geom class="collision" type="cylinder" pos="0.20511398 -0.17747596 -0.06854089" size="0.025236716493964195 0.004440062679350376" quat="0.7071068286895752 0.7071067690849304 0.0 0.0" density="1000.0"/>
          <geom class="collision" type="box" pos="0.20461299 -0.19011152 -0.06735441" size="0.004965366329997778 0.00836547464132309 0.018377626314759254" quat="1.0 0.0 0.0 0.0" density="1000.0"/>
        </body>
        <geom class="region" name="reg_int" type="box" pos="-0.04719327500000001 0.008356274999999996 0.0004324599999999956" size="0.195827855 0.153808965 0.12284879"/>
        <geom class="region" name="reg_main" type="box" pos="0.0 0.016251719999999997 1.000000000861423e-08" size="0.2617246 0.18926166 0.14228232000000002"/>
      </body>
    </body>
  </worldbody>
  <actuator>
    <motor name="microjoint_actuator" joint="microjoint" gear="10"/>
    <motor name="Button001_joint_actuator" joint="Button001_joint" gear="0.2"/>
    <motor name="Button002_joint_actuator" joint="Button002_joint" gear="0.2"/>
    <motor name="Button003_joint_actuator" joint="Button003_joint" gear="0.2"/>
    <motor name="Button004_joint_actuator" joint="Button004_joint" gear="0.2"/>
    <motor name="Disc001_joint_actuator" joint="Disc001_joint" gear="10"/>
    <motor name="Knob001_joint_actuator" joint="Knob001_joint" gear="10"/>
  </actuator>
</mujoco>
