<?xml version='1.0' encoding='UTF-8'?>
<mujoco model="model">
  <option timestep="0.002" gravity="0.0 0.0 -9.81"/>
  <compiler angle="radian"/>
  <asset>
    <mesh file="visuals/handle.obj" name="handle_vis"/>
    <mesh file="visuals/Body001.obj" name="Body001_vis"/>
    <mesh file="visuals/spout.obj" name="spout_vis"/>
    <texture file="visuals/T_BC001.png" name="Body001_material" type="2d"/>
    <material name="Body001_material" rgba="1 1 1 1.0" texture="Body001_material" shininess="0.1" specular="1"/>
    <texture file="visuals/T_BC001.png" name="handle_material" type="2d"/>
    <material name="handle_material" rgba="1 1 1 1.0" texture="handle_material" shininess="0.1" specular="5"/>
    <texture file="visuals/T_BC001.png" name="spout_material" type="2d"/>
    <material name="spout_material" rgba="1 1 1 1.0" texture="spout_material" shininess="0.1" specular="5"/>
  </asset>
  <default>
    <default class="visual">
      <geom conaffinity="0" contype="0" group="1" type="mesh"/>
    </default>
    <default class="collision">
      <geom group="0" rgba="0.5 0 0 0.5" solimp="0.998 0.998 0.001" solref="0.001 2"/>
    </default>
    <default class="spawn">
      <geom group="0" rgba="1 1 1 0.5" contype="0" conaffinity="0"/>
      <site group="0" rgba="1 1 1 0.5"/>
    </default>
    <default class="region">
      <geom group="1" conaffinity="0" contype="0" rgba="0 1 0 0"/>
    </default>
  </default>
  <worldbody>
    <body>
      <body name="object">
        <geom mesh="Body001_vis" type="mesh" solimp="0.998 0.998 0.001" solref="0.001 1" friction="0.95 0.3 0.1" class="visual" material="Body001_material"/>
        <geom type="box" pos="-0.5425845980644226 7.902330253273249e-06 -0.1493872106075287" size="0.031223518773913383 0.26477763056755066 0.09092898666858673" quat="1.0 0.0 0.0 0.0" class="collision"/>
        <geom type="box" pos="0.44802284240722656 8.672941476106644e-09 -0.149386927485466" size="0.12578429281711578 0.26478567719459534 0.09092932939529419" quat="1.0 0.0 0.0 0.0" class="collision"/>
        <geom type="box" pos="0.044925495982170105 0.2201080322265625 -0.1493866890668869" size="0.2815152406692505 0.04467969015240669 0.09093040972948074" quat="1.0 0.0 0.0 0.0" class="collision"/>
        <geom type="box" pos="-0.3737524151802063 0.22272610664367676 -0.1493871510028839" size="0.1422635167837143 0.04206153377890587 0.09092926979064941" quat="1.0 0.0 0.0 0.0" class="collision"/>
        <geom type="box" pos="-0.3737524151802063 -0.22431381046772003 -0.14938713610172272" size="0.1422635167837143 0.04047383368015289 0.09092938154935837" quat="1.0 0.0 0.0 0.0" class="collision"/>
        <geom type="box" pos="0.044587209820747375 -0.22442656755447388 -0.14938707649707794" size="0.2803761959075928 0.0403607040643692 0.09092944115400314" quat="1.0 0.0 0.0 0.0" class="collision"/>
        <geom type="box" pos="-0.22452354431152344 3.945129719795659e-05 -0.15915919840335846" size="0.012242678552865982 0.11001994460821152 0.0807158425450325" quat="1.0 0.0 0.0 0.0" class="collision"/>
        <geom type="box" pos="-0.11120790243148804 -0.006130542140454054 -0.219935804605484" size="0.43618446588516235 0.19349530339241028 0.02038153074681759" quat="1.0 0.0 0.0 0.0" class="collision"/>
        <geom type="box" pos="0.0449255034327507 0.14416059851646423 -0.12857580184936523" size="0.2815152108669281 0.03699162229895592 0.05423280969262123" quat="1.0 0.0 0.0 0.0" class="collision"/>
        <geom type="box" pos="0.044925507158041 -0.14806045591831207 -0.12857580184936523" size="0.2815152406692505 0.03928794339299202 0.05423332750797272" quat="1.0 0.0 0.0 0.0" class="collision"/>
        <geom type="box" pos="-0.3714817464351654 -0.0020226642955094576 -0.18452565371990204" size="0.13997656106948853 0.18450702726840973 0.016315434128046036" quat="1.0 0.0 0.0 0.0" class="collision"/>
        <geom type="box" pos="0.05122475326061249 -0.004113413393497467 -0.1845254749059677" size="0.27167677879333496 0.11409635841846466 0.016315411776304245" quat="1.0 0.0 0.0 0.0" class="collision"/>
        <geom type="cylinder" pos="-0.17936426401138306 0.23260730504989624 -0.005379015579819679" size="0.022757161408662796 0.05625209957361221" quat="1.0 0.0 0.0 0.0" class="collision"/>
        <geom type="cylinder" pos="-0.1532038450241089 0.23260730504989624 -0.004038915503770113" size="0.022515717893838882 0.021582122892141342" quat="0.70710688829422 -4.7503021960437763e-08 0.7071066498756409 4.750300774958305e-08" class="collision"/>
        <geom type="cylinder" pos="-0.20414118468761444 0.23260730504989624 -0.004038915503770113" size="0.015823092311620712 0.01029928307980299" quat="0.70710688829422 -4.7503021960437763e-08 0.7071066498756409 4.750300774958305e-08" class="collision"/>
        <geom type="box" pos="0.044469986110925674 -0.17451250553131104 -0.08727122843265533" size="0.025082286447286606 0.28010547161102295 0.0169523973017931" quat="0.6668866276741028 -0.23507952690124512 -0.23507942259311676 -0.6668864488601685" class="collision"/>
        <geom type="box" pos="0.044201962649822235 0.17448177933692932 -0.08703859895467758" size="0.025082286447286606 0.2803735136985779 0.0169523973017931" quat="0.6681765913963318 0.23138730227947235 -0.231387197971344 0.668176531791687" class="collision"/>
        <body name="handle">
          <joint axis="1.0 0.0 0.0" pos="-0.10735443979501724 0.23287050426006317 -0.004628328140825033" limited="true" name="handle_temp_joint" type="hinge" range="-0.7853981633974483 0.7853981633974483" damping="0.5" frictionloss="1" armature="2"/>
          <joint axis="0.0 1.0 0.0" pos="-0.10735443979501724 0.23287050426006317 -0.004628328140825033" limited="true" name="handle_joint" type="hinge" range="0 0.5" damping="0.5" frictionloss="1" armature="2"/>
          <geom mesh="handle_vis" type="mesh" solimp="0.998 0.998 0.001" solref="0.001 1" friction="0.95 0.3 0.1" class="visual" material="handle_material"/>
          <geom type="cylinder" pos="-0.10246364772319794 0.23258903622627258 -0.0045079998672008514" size="0.02655804716050625 0.015345869585871696" quat="0.70710688829422 -4.750302551315144e-08 0.7071066498756409 4.750301130229673e-08" class="collision"/>
          <geom name="handle_main" type="cylinder" pos="-0.09641560167074203 0.23321902751922607 0.054930999875068665" size="0.004774205852299929 0.0363352932035923" quat="1.9470718370939721e-07 -6.717942824252532e-08 1.0 1.3435884227419592e-07" class="collision"/>
        </body>
        <body name="spout">
          <joint axis="0.0 0.0 1.0" pos="-0.17921459674835205 0.23191876709461212 0.14382076263427734" limited="true" name="spout_joint" range="-0.7853981633974483 0.7853981633974483" type="hinge" damping="10"/>
          <site type="cylinder" rgba="0.5 0.75 1 0.5" size="0.006393761839717627 0.16631513833999634" pos="-0.17886139452457428 0.07469233125448227 -0.0020990287885069847" name="water"/>
          <geom mesh="spout_vis" type="mesh" solimp="0.998 0.998 0.001" solref="0.001 1" friction="0.95 0.3 0.1" class="visual" material="spout_material"/>
          <geom type="cylinder" pos="-0.1792595535516739 0.23246406018733978 0.10873384773731232" size="0.009934265166521072 0.056256648153066635" quat="1.0 0.0 0.0 0.0" class="collision" name="spout_main"/>
          <geom type="cylinder" pos="-0.1792595535516739 0.22869440913200378 0.17583346366882324" size="0.009934265166521072 0.014502867124974728" quat="0.9899696707725525 0.14128001034259796 -3.13704640803265e-17 -4.065071242085344e-24" class="collision"/>
          <geom type="cylinder" pos="-0.1792595535516739 0.21768707036972046 0.19830051064491272" size="0.009934265166521072 0.014502864331007004" quat="0.9445487856864929 0.3283711075782776 -7.29130262335687e-17 5.9858797042606585e-24" class="collision"/>
          <geom type="cylinder" pos="-0.1792595535516739 0.1989896446466446 0.21624398231506348" size="0.009934265166521072 0.014502864331007004" quat="0.876102864742279 0.4821242392063141 -1.070530796019024e-16 9.944945395624213e-24" class="collision"/>
          <geom type="cylinder" pos="-0.1792595535516739 0.17561787366867065 0.22770369052886963" size="0.009934265166521072 0.014502865262329578" quat="0.8088570237159729 0.5880053639411926 -1.3056340549523157e-16 1.820550552008966e-24" class="collision"/>
          <geom type="cylinder" pos="-0.1792595535516739 0.1511905938386917 0.23011627793312073" size="0.009934265166521072 0.01450286339968443" quat="0.6837475895881653 0.7297186255455017 -1.6203009715057759e-16 -3.6817580484399365e-23" class="collision"/>
          <geom type="cylinder" pos="-0.1792595535516739 0.12510468065738678 0.2242356538772583" size="0.009934265166521072 0.014502864331007004" quat="0.5643213987350464 0.8255552053451538 -1.8330994706576976e-16 -6.399909879377924e-23" class="collision"/>
          <geom type="cylinder" pos="-0.1792595535516739 0.10354234278202057 0.2115696668624878" size="0.009934265166521072 0.01450286339968443" quat="0.3973284065723419 0.9176765084266663 -2.0376498541368327e-16 -1.1974745720364122e-22" class="collision"/>
          <geom type="cylinder" pos="-0.1792595535516739 0.08755906671285629 0.19241991639137268" size="0.009934265166521072 0.01450286339968443" quat="0.2732285261154175 0.9619491696357727 -2.1359563656462687e-16 6.021812634037838e-23" class="collision"/>
          <geom type="cylinder" pos="-0.1792595535516739 0.08001978695392609 0.17492878437042236" size="0.009934265166521072 0.014502864331007004" quat="0.15607759356498718 0.9877448081970215 -2.1932345864241766e-16 -3.2741813866161035e-23" class="collision"/>
        </body>
        <geom class="region" name="reg_basin_left" type="box" pos="-0.37393657118082047 -0.0016002431511878967 -0.11614048853516579" size="0.13265082782506943 0.17697999423742294 0.05179412087798119"/>
        <geom class="region" name="reg_basin_right" type="box" pos="0.05600747466087341 -0.0005536414682865143 -0.1257910281419754" size="0.2627759704589844 0.10332969745993614 0.04264980351924896"/>
        <geom class="region" name="reg_main" type="box" pos="1.4901161193847656e-08 0.0 -0.149386927485466" size="0.5748086104393005 0.26578761434555054 0.09193023836612702"/>
      </body>
    </body>
  </worldbody>
  <actuator>
    <motor name="handle_joint_actuator" joint="handle_joint" gear="10"/>
    <motor name="handle_temp_joint_actuator" joint="handle_temp_joint" gear="10"/>
    <motor name="spout_joint_actuator" joint="spout_joint" gear="10"/>
  </actuator>
</mujoco>
