<?xml version='1.0' encoding='UTF-8'?>
<mujoco model="model">
  <option timestep="0.002" gravity="0.0 0.0 -9.81"/>
  <compiler angle="radian"/>
  <asset>
    <mesh file="visuals/button_cancel.obj" name="button_cancel_vis"/>
    <mesh file="visuals/knob_doneness.obj" name="knob_doneness_vis"/>
    <mesh file="visuals/lever.obj" name="lever_vis"/>
    <mesh file="visuals/Body001.obj" name="Body001_vis"/>
    <mesh file="visuals/Body002.obj" name="Body002_vis"/>
    <texture file="visuals/T_BC001.png" name="Body001_material" type="2d"/>
    <material name="Body001_material" rgba="1 1 1 1.0" texture="Body001_material" shininess="0.4472135901451111" specular="0.3103448502657381"/>
    <texture file="visuals/T_BC001.png" name="button_cancel_material" type="2d"/>
    <material name="button_cancel_material" rgba="1 1 1 1.0" texture="button_cancel_material" shininess="0.4472135901451111" specular="0.3103448502657381"/>
    <texture file="visuals/T_BC001.png" name="knob_doneness_material" type="2d"/>
    <material name="knob_doneness_material" rgba="1 1 1 1.0" texture="knob_doneness_material" shininess="0.4472135901451111" specular="0.3103448502657381"/>
    <texture file="visuals/T_BC001.png" name="lever_material" type="2d"/>
    <material name="lever_material" rgba="1 1 1 1.0" texture="lever_material" shininess="0.4472135901451111" specular="0.3103448502657381"/>
    <texture file="visuals/T_BC001.png" name="Body002_material" type="2d"/>
    <material name="Body002_material" rgba="1 1 1 1.0" texture="Body002_material" shininess="0.4472135901451111" specular="3"/>
  </asset>
  <default>
    <default class="visual">
      <geom conaffinity="0" contype="0" group="1" type="mesh"/>
    </default>
    <default class="collision_1">
      <geom group="0" rgba="0.5 0 0 0.5" solref="0.004 1" solimp="0.998 0.998 0.001"/>
    </default>
    <default class="collision_2">
      <geom group="0" rgba="0.5 0 0 0.5" solref="0.004 1" solimp="0.998 0.998 0.001"/>
    </default>
    <default class="collision_3">
      <geom group="0" rgba="0.5 0 0 0.5" solref="0.004 1" solimp="0.998 0.998 0.001"/>
    </default>
    <default class="collision_4">
      <geom group="0" rgba="0.5 0 0 0.5" solref="0.004 1" solimp="0.998 0.998 0.001"/>
    </default>
    <default class="collision_5">
      <geom group="0" rgba="0.5 0 0 0.5" solref="0.004 1" solimp="0.998 0.998 0.001"/>
    </default>
    <default class="spawn">
      <geom group="0" rgba="1 1 1 0.5" contype="0" conaffinity="0"/>
      <site group="0" rgba="1 1 1 0.5"/>
    </default>
    <default class="region">
      <geom group="1" conaffinity="0" contype="0" rgba="0 1 0 0" mass="0"/>
    </default>
  </default>
  <worldbody>
    <body>
      <body name="object">
        <geom mesh="Body001_vis" type="mesh" solimp="0.998 0.998 0.001" solref="0.001 1" friction="0.95 0.3 0.1" class="visual" material="Body001_material"/>
        <geom type="box" pos="-0.055946242064237595 0.021821707487106323 7.450580596923828e-09" size="0.017723383381962776 0.1287723183631897 0.10059751570224762" quat="1.0 0.0 0.0 0.0" class="collision_1"/>
        <geom type="box" pos="0.057172831147909164 0.021125435829162598 7.450580596923828e-09" size="0.017723383381962776 0.12946851551532745 0.10059745609760284" quat="1.0 0.0 0.0 0.0" class="collision_1"/>
        <geom type="box" pos="-4.952516174938637e-09 0.1272965669631958 7.450580596923828e-09" size="0.04071595519781113 0.030456967651844025 0.10059739649295807" quat="1.0 0.0 0.0 0.0" class="collision_1"/>
        <geom type="box" pos="3.703138906629988e-09 -0.0829356387257576 7.450580596923828e-09" size="0.04071595147252083 0.03092188946902752 0.10059686750173569" quat="1.0 0.0 0.0 0.0" class="collision_1"/>
        <geom type="box" pos="-3.690570349323963e-10 0.022439245134592056 0.02093360759317875" size="0.006363640073686838 0.07561708241701126 0.07569602876901627" quat="1.0 0.0 0.0 0.0" class="collision_1"/>
        <geom type="box" pos="9.078436891130082e-10 -0.006772836670279503 -0.07402293384075165" size="0.04040299728512764 0.10382997244596481 0.026396626606583595" quat="1.0 0.0 0.0 0.0" class="collision_1"/>
        <body name="button_cancel">
          <joint axis="0.4370834231376648 0.8994210362434387 0.0" pos="-0.048416655510663986 -0.11593509465456009 -0.019691836088895798" limited="true" name="button_cancel_joint" range="0.0 0.001" type="slide" damping="1" frictionloss="1" armature=".01" stiffness="0.05"/>
          <geom mesh="button_cancel_vis" type="mesh" solimp="0.998 0.998 0.001" solref="0.001 1" friction="0.95 0.3 0.1" class="visual" material="button_cancel_material"/>
          <geom class="collision_2" type="box" pos="-0.04771571233868599 -0.11617827415466309 -0.019709717482328415" size="0.009501594118773937 0.002825995208695531 0.003922949079424143" quat="0.9681476354598999 0.0 0.0 -0.2503799796104431" name="button_cancel_main"/>
        </body>
        <body name="knob_doneness">
          <joint axis="0.0 1.0 0.0" pos="1.638755202293396e-05 -0.13269715011119843 -0.04218493774533272" limited="true" name="knob_doneness_joint" range="0.0 4.101523742186674" type="hinge" damping="0.05" armature="0.001"/>
          <geom mesh="knob_doneness_vis" type="mesh" solimp="0.998 0.998 0.001" solref="0.001 1" friction="0.95 0.3 0.1" class="visual" material="knob_doneness_material"/>
          <geom type="cylinder" pos="-0.00023147495812736452 -0.12644612789154053 -0.041845038533210754" size="0.01947701908648014 0.003175688674673438" quat="0.6946583986282349 0.7193397879600525 0.0 0.0" class="collision_3"/>
          <geom class="collision_3" type="box" pos="-0.0006442344165407121 -0.13251668214797974 -0.043026115745306015" size="0.004428433254361153 0.009646240621805191 0.01562546379864216" quat="0.57569819688797 -0.0 -0.8176622986793518 -0.0" name="knob_doneness_main"/>
        </body>
        <body name="lever">
          <joint axis="0.0 0.0 -1.0" pos="0.0 -0.12861935794353485 0.05759614333510399" limited="true" name="lever_joint" range="0.0 0.06" type="slide" damping="1" frictionloss="1" armature=".01" stiffness="1" springref="-1.4"/>
          <geom class="region" name="reg_slotL" type="box" pos="-0.022260630503296852 0.022926490753889084 0.10001123696565628" size="0.015137452468276025 0.07418171486258507 0.07599996572732926"/>
          <geom class="region" name="reg_slotR" type="box" pos="0.022318080067634583 0.022926490753889084 0.10001123696565628" size="0.015404546469449998 0.07418171486258507 0.07599996572732926"/>
          <geom mesh="lever_vis" type="mesh" solimp="0.998 0.998 0.001" solref="0.001 1" friction="0.95 0.3 0.1" class="visual" material="lever_material"/>
          <geom class="collision_4" type="box" pos="-9.033897367771715e-05 -0.1474333107471466 0.05777434632182121" size="0.022096822038292885 0.011113028042018414 0.005966719705611467" quat="1.0 0.0 0.0 0.0" name="lever_handle"/>
          <geom type="box" pos="-1.2785009426738003e-17 -0.1285804957151413 0.057578571140766144" size="0.005304453428834677 0.009310588240623474 0.005593227222561836" quat="1.0 0.0 0.0 0.0" class="collision_4"/>
          <geom class="collision_4" type="box" pos="-0.02235770970582962 0.023186175152659416 0.02045106515288353" size="0.01266517024487257 0.07211378961801529 0.003379613859578967" quat="1.0 0.0 0.0 0.0" name="slotL_floor"/>
          <geom class="collision_4" type="box" pos="0.021620038896799088 0.023186175152659416 0.02045106515288353" size="0.01266517024487257 0.07211378961801529 0.003379613859578967" quat="1.0 0.0 0.0 0.0" name="slotR_floor"/>
        </body>
        <body name="Body002">
          <geom mesh="Body002_vis" type="mesh" solimp="0.998 0.998 0.001" solref="0.001 1" friction="0.95 0.3 0.1" class="visual" material="Body002_material"/>
        </body>
        <geom class="region" name="reg_main" type="box" pos="0.0 0.013944357633590698 0.0" size="0.07378843224048615 0.145669309258461 0.10047514533996582"/>
      </body>
    </body>
  </worldbody>
  <actuator>
    <motor name="button_cancel_joint_actuator" joint="button_cancel_joint" gear="0.5"/>
    <motor name="knob_doneness_joint_actuator" joint="knob_doneness_joint" gear="10"/>
    <motor name="lever_joint_actuator" joint="lever_joint" gear="1.5"/>
  </actuator>
</mujoco>
