<?xml version='1.0' encoding='UTF-8'?>
<mujoco model="model">
  <compiler angle="radian"/>
  <asset>
    <mesh file="visuals/Body001.obj" name="Body001_vis"/>
    <mesh file="visuals/Button001.obj" name="Button001_vis"/>
    <mesh file="visuals/Button002.obj" name="Button002_vis"/>
    <mesh file="visuals/Container001_Clear.obj" name="Container001_Clear_vis"/>
    <mesh file="visuals/Lid001.obj" name="Lid001_vis"/>
    <mesh file="visuals/Lid002.obj" name="Lid002_vis"/>
    <mesh file="visuals/Lid003.obj" name="Lid003_vis"/>
    <texture file="visuals/T_BC001.png" name="Body001_material" type="2d"/>
    <material name="Body001_material" rgba="1 1 1 1.0" texture="Body001_material" shininess="0.4472135901451111" specular="0.3103448502657381"/>
    <texture file="visuals/T_BC001.png" name="Button001_material" type="2d"/>
    <material name="Button001_material" rgba="1 1 1 1.0" texture="Button001_material" shininess="0.4472135901451111" specular="0.3103448502657381"/>
    <texture file="visuals/T_BC001.png" name="Button002_material" type="2d"/>
    <material name="Button002_material" rgba="1 1 1 1.0" texture="Button002_material" shininess="0.4472135901451111" specular="0.3103448502657381"/>
    <texture file="visuals/T_BC001.png" name="Container001_Clear_material" type="2d"/>
    <material name="Container001_Clear_material" rgba="1 1 1 0.04680854082107544" texture="Container001_Clear_material" shininess="0.4472135901451111" specular="0.3103448502657381"/>
    <texture file="visuals/T_BC001.png" name="Lid001_material" type="2d"/>
    <material name="Lid001_material" rgba="1 1 1 1.0" texture="Lid001_material" shininess="0.4472135901451111" specular="0.3103448502657381"/>
    <texture file="visuals/T_BC001.png" name="Lid002_material" type="2d"/>
    <material name="Lid002_material" rgba="1 1 1 1.0" texture="Lid002_material" shininess="0.4472135901451111" specular="0.3103448502657381"/>
    <texture file="visuals/T_BC001.png" name="Lid003_material" type="2d"/>
    <material name="Lid003_material" rgba="1 1 1 1.0" texture="Lid003_material" shininess="0.4472135901451111" specular="0.3103448502657381"/>
  </asset>
  <default>
    <default class="visual">
      <geom conaffinity="0" contype="0" group="1" type="mesh"/>
    </default>
    <default class="collision">
      <geom group="0" rgba="0.5 0 0 0.5"/>
    </default>
    <default class="spawn">
      <geom group="0" rgba="1 1 1 0.5" contype="0" conaffinity="0"/>
      <site group="0" rgba="1 1 1 0.5"/>
    </default>
    <default class="region">
      <geom group="1" conaffinity="0" contype="0" rgba="0 1 0 0"/>
    </default>
  </default>
  <worldbody>
    <body>
      <body name="object">
        <geom class="collision" type="box" pos="-0.03002791 -0.15020518 0.05937444" size="0.00745377317070961 0.007453771773725748 0.0006153107970021665" quat="0.6908296942710876 0.6908298134803772 -0.15084503591060638 -0.1508450210094452" name="start_button_1" rgba="0.0 0.5 0 0.5"/>
        <geom class="collision" type="box" pos="0.03020227 -0.15022534 0.05943433" size="0.00745377317070961 0.007453771773725748 0.0006153107970021665" quat="0.6903252005577087 0.6903253793716431 0.15313728153705597 0.1531372368335724" name="start_button_2" rgba="0.0 0.5 0 0.5"/>
        <site type="cylinder" rgba="0.8 0.5 0.25 1" size="0.0025999878998845816 0.08099177479743958" pos="-0.00001226 -0.13657184 -0.04593290" name="coffee_liquid"/>
        <site rgba="0 0 0 0" size="0.009999999776482582 0.009999999776482582" pos="-0.00005336 -0.15675133 -0.11922139" name="receptacle_place_site"/>
        <geom mesh="Body001_vis" type="mesh" solimp="0.998 0.998 0.001" solref="0.001 1" density="100" friction="0.95 0.3 0.1" class="visual" material="Body001_material"/>
        <geom class="collision" type="box" pos="0.00138182 0.04424987 -0.01136835" size="0.07155651599168777 0.07745305448770523 0.14616787433624268" quat="1.0 0.0 0.0 0.0"/>
        <geom class="collision" type="box" pos="0.00012854 -0.08125629 -0.14873506" size="0.07030323892831802 0.048140060156583786 0.008801165036857128" quat="1.0 0.0 0.0 0.0"/>
        <geom class="collision" type="box" pos="-0.00045377 -0.07317622 -0.05913555" size="0.05402809754014015 0.04005999490618706 0.08209266513586044" quat="1.0 0.0 0.0 0.0"/>
        <geom class="collision" type="box" pos="0.00001247 -0.06715337 -0.05913555" size="0.0061247264966368675 0.03403715044260025 0.08209266513586044" quat="1.0 0.0 0.0 0.0"/>
        <geom class="collision" type="cylinder" pos="0.00159278 -0.15846852 -0.13786579" size="0.04566127061843872 0.014569255523383617" quat="1.0 0.0 0.0 0.0"/>
        <geom class="collision" type="cylinder" pos="-0.00000050 -0.07727387 0.04776575" size="0.07117266207933426 0.02634253539144993" quat="1.0 0.0 0.0 0.0"/>
        <geom class="collision" type="cylinder" pos="-0.00000050 -0.08271821 0.07891291" size="0.07117266207933426 0.0044973185285925865" quat="1.0 0.0 0.0 0.0"/>
        <geom class="collision" type="cylinder" pos="-0.00000050 0.16419142 -0.14865768" size="0.04009465500712395 0.008819321170449257" quat="1.0 0.0 0.0 0.0"/>
        <geom class="collision" type="box" pos="-0.02863973 -0.03187104 0.09556499" size="0.02024535834789276 0.012357999570667744 0.04943403974175453" quat="0.9644211530685425 0.0 0.0 0.2643706798553467"/>
        <geom class="collision" type="box" pos="-0.04893109 -0.05091510 0.09556499" size="0.02024535834789276 0.012357999570667744 0.04943403974175453" quat="0.8735739588737488 0.0 0.0 0.486691415309906"/>
        <geom class="collision" type="box" pos="-0.05832182 -0.08065348 0.09556499" size="0.02024535834789276 0.012357999570667744 0.04943403974175453" quat="0.7117714881896973 0.0 0.0 0.7024111151695251"/>
        <geom class="collision" type="box" pos="-0.05183770 -0.10952389 0.09556499" size="0.02024535834789276 0.012357999570667744 0.04943403974175453" quat="0.5104440450668335 0.0 0.0 0.8599109649658203"/>
        <geom class="collision" type="box" pos="-0.02959786 -0.13301370 0.10692340" size="0.02024535834789276 0.012357999570667744 0.038075633347034454" quat="0.2521234154701233 0.0 0.0 0.9676950573921204"/>
        <geom class="collision" type="box" pos="-0.00062688 -0.14107271 0.10678403" size="0.020385123789310455 0.012588322162628174 0.03821500018239021" quat="1.0 0.0 0.0 0.0"/>
        <geom class="collision" type="box" pos="0.02858641 -0.13359481 0.10659143" size="0.02024535834789276 0.012357999570667744 0.03840760141611099" quat="0.2638746201992035 0.0 -0.0 -0.9645569920539856"/>
        <geom class="collision" type="box" pos="0.05041724 -0.11210684 0.09556499" size="0.02024535834789276 0.012357999570667744 0.04943403974175453" quat="0.5077721476554871 0.0 -0.0 -0.8614913821220398"/>
        <geom class="collision" type="box" pos="0.05835726 -0.08260813 0.09556499" size="0.012841008603572845 0.020536525174975395 0.04943403974175453" quat="1.0 0.0 0.0 0.0"/>
        <geom class="collision" type="box" pos="0.04982714 -0.05233982 0.09556499" size="0.02024535834789276 0.012357999570667744 0.04943403974175453" quat="0.8773074150085449 0.0 -0.0 -0.4799288809299469"/>
        <geom class="collision" type="box" pos="0.02722184 -0.03109860 0.09556499" size="0.02024535834789276 0.012357999570667744 0.04943403974175453" quat="0.9733062982559204 0.0 -0.0 -0.22950996458530426"/>
        <geom class="collision" type="box" pos="0.00129203 -0.02437467 0.09556499" size="0.02024535834789276 0.012357999570667744 0.04943403974175453" quat="1.0 0.0 0.0 0.0"/>
        <body name="Button001">
          <joint axis="0.4067366421222687 0.9135454297065735 0.0" pos="-0.02909341 -0.14822757 0.05944484" limited="true" name="Button001_joint" range="0.0 0.003" type="slide" damping="1" frictionloss="1" armature=".01" stiffness="0.05"/>
          <geom mesh="Button001_vis" type="mesh" solimp="0.998 0.998 0.001" solref="0.001 1" density="100" friction="0.95 0.3 0.1" class="visual" material="Button001_material"/>
          <geom class="collision" type="cylinder" pos="-0.02891002 -0.14776743 0.05937444" size="0.00745377317070961 0.0018070159712806344" quat="0.6908296942710876 0.6908298134803772 -0.15084503591060638 -0.1508450210094452"/>
        </body>
        <body name="Button002">
          <joint axis="-0.4067366421222687 0.9135454297065735 0.0" pos="0.02906646 -0.14816915 0.05944484" limited="true" name="Button002_joint" range="0.0 0.003" type="slide" damping="1" frictionloss="1" armature=".01" stiffness="0.05"/>
          <geom mesh="Button002_vis" type="mesh" solimp="0.998 0.998 0.001" solref="0.001 1" density="100" friction="0.95 0.3 0.1" class="visual" material="Button002_material"/>
          <geom class="collision" type="cylinder" pos="0.02906823 -0.14779504 0.05943433" size="0.00745377317070961 0.0018070159712806344" quat="0.6903252005577087 0.6903253793716431 0.15313728153705597 0.1531372368335724"/>
        </body>
        <body name="Container001_Clear">
          <joint axis="0.0 0.0 1.0" pos="-0.00000781 0.16426864 -0.03202870" limited="true" name="Container001_Clear_joint" range="0.0 0.05" type="slide" damping="1" frictionloss="1" armature=".01" stiffness="0.05"/>
          <geom mesh="Container001_Clear_vis" type="mesh" solimp="0.998 0.998 0.001" solref="0.001 1" density="100" friction="0.95 0.3 0.1" class="visual" material="Container001_Clear_material"/>
          <geom class="collision" type="cylinder" pos="0.00007180 0.16436869 -0.13649968" size="0.0393361821770668 0.002993212081491947" quat="1.0 0.0 0.0 0.0"/>
          <geom class="collision" type="box" pos="-0.03676581 0.16489255 -0.03190737" size="0.0018441455904394388 0.008451677858829498 0.1062384843826294" quat="1.0 0.0 0.0 0.0"/>
          <geom class="collision" type="box" pos="-0.03676581 0.16489255 0.00000250" size="0.0018441475694999099 0.008451677858829498 0.016558147966861725" quat="1.0 0.0 0.0 0.0"/>
          <geom class="collision" type="box" pos="-0.03429714 0.15109990 -0.03190737" size="0.0018441455904394388 0.008451677858829498 0.10623849183320999" quat="0.9817522168159485 0.0 0.0 0.19016456604003906"/>
          <geom class="collision" type="box" pos="-0.02651324 0.13886340 -0.03190737" size="0.0018441455904394388 0.008451677858829498 0.10623849183320999" quat="0.9251194596290588 0.0 0.0 0.3796762228012085"/>
          <geom class="collision" type="box" pos="-0.01503605 0.13076754 -0.03190737" size="0.0018441455904394388 0.008451677858829498 0.1062384843826294" quat="0.8357836008071899 0.0 0.0 0.5490589737892151"/>
          <geom class="collision" type="box" pos="-0.00434184 0.12779267 -0.03190737" size="0.0018441457068547606 0.008451678790152073 0.1062384843826294" quat="0.7435294985771179 0.0 0.0 0.6687031388282776"/>
          <geom class="collision" type="box" pos="0.01066482 0.12908310 -0.03190737" size="0.0018441455904394388 0.008451677858829498 0.1062384843826294" quat="0.5911339521408081 0.0 0.0 0.8065733909606934"/>
          <geom class="collision" type="box" pos="0.02404349 0.13639292 -0.03190737" size="0.0018441455904394388 0.008451677858829498 0.10623849183320999" quat="0.41145753860473633 0.0 0.0 0.9114289283752441"/>
          <geom class="collision" type="box" pos="0.03322882 0.14830950 -0.03190737" size="0.0018441455904394388 0.008451677858829498 0.1062384843826294" quat="0.21667729318141937 0.0 0.0 0.976243257522583"/>
          <geom class="collision" type="box" pos="0.03690507 0.16359706 -0.03190737" size="0.001900948933325708 0.008463891223073006 0.1062384694814682" quat="1.0 0.0 0.0 0.0"/>
          <geom class="collision" type="box" pos="0.03448592 0.17751989 -0.03190737" size="0.0018441455904394388 0.008451677858829498 0.1062384843826294" quat="0.1884860396385193 0.0 -0.0 -0.9820758700370789"/>
          <geom class="collision" type="box" pos="0.02714823 0.18935174 -0.03190737" size="0.0018441455904394388 0.008451677858829498 0.1062384843826294" quat="0.3706550598144531 0.0 -0.0 -0.9287706017494202"/>
          <geom class="collision" type="box" pos="0.01616867 0.19750742 -0.03190737" size="0.0018441455904394388 0.008451677858829498 0.1062384694814682" quat="0.5366145372390747 0.0 -0.0 -0.843827486038208"/>
          <geom class="collision" type="box" pos="0.00293667 0.20109847 -0.03190737" size="0.0018441455904394388 0.008451677858829498 0.1062384843826294" quat="0.6842595934867859 0.0 -0.0 -0.7292385101318359"/>
          <geom class="collision" type="box" pos="-0.01059971 0.19963062 -0.03190737" size="0.0018441455904394388 0.008451677858829498 0.1062384694814682" quat="0.8072304725646973 0.0 -0.0 -0.5902363657951355"/>
          <geom class="collision" type="box" pos="-0.02384793 0.19238888 -0.03190737" size="0.0018441455904394388 0.008451677858829498 0.1062384843826294" quat="0.9110468626022339 0.0 -0.0 -0.4123028516769409"/>
          <geom class="collision" type="box" pos="-0.03333473 0.17990214 -0.03190737" size="0.0018441455904394388 0.008451677858829498 0.1062384843826294" quat="0.977924108505249 0.0 -0.0 -0.2089603841304779"/>
          <body name="Lid001">
            <joint axis="0.0 0.0 1.0" pos="-0.00000782 0.16426867 0.07628532" limited="true" name="Lid001_joint" range="0.0 0.05" type="slide" damping="1" frictionloss="1" armature=".01" stiffness="0.05"/>
            <geom mesh="Lid001_vis" type="mesh" solimp="0.998 0.998 0.001" solref="0.001 1" density="100" friction="0.95 0.3 0.1" class="visual" material="Lid001_material"/>
            <geom class="collision" type="cylinder" pos="0.00000774 0.16418527 0.07632672" size="0.03883073478937149 0.0007054820889607072" quat="1.0 0.0 0.0 0.0"/>
            <geom class="collision" type="box" pos="0.02980289 0.16431068 0.08508246" size="0.0036717012990266085 0.0023889916483312845 0.008473222143948078" quat="1.0 0.0 0.0 0.0"/>
            <geom class="collision" type="box" pos="0.00064336 0.16431068 0.09037026" size="0.025550926104187965 0.0023889916483312845 0.003185421694070101" quat="1.0 0.0 0.0 0.0"/>
            <geom class="collision" type="box" pos="-0.02843952 0.16431068 0.08508246" size="0.0036717012990266085 0.0023889916483312845 0.008473222143948078" quat="1.0 0.0 0.0 0.0"/>
          </body>
        </body>
        <body name="Lid002">
          <joint axis="0.0 -1.0 0.0" pos="-0.04962938 -0.08253604 0.14596891" limited="true" name="Lid002_joint" range="0.0 1.5707963267948966" type="hinge" damping="1" frictionloss="1" armature=".01" stiffness="0.05"/>
          <geom mesh="Lid002_vis" type="mesh" solimp="0.998 0.998 0.001" solref="0.001 1" density="100" friction="0.95 0.3 0.1" class="visual" material="Lid002_material"/>
          <geom class="collision" type="box" pos="0.05984352 -0.08267363 0.15104854" size="0.0104537857696414 0.0061253877356648445 0.0061182258650660515" quat="1.0 0.0 0.0 0.0"/>
          <geom class="collision" type="cylinder" pos="-0.00052705 -0.08288134 0.15156120" size="0.05014911666512489 0.005898127797991037" quat="1.0 0.0 0.0 0.0"/>
        </body>
        <body name="Lid003">
          <joint axis="0.0 0.0 1.0" pos="0.00136557 -0.15873926 -0.12192352" limited="true" name="Lid003_joint" range="0.0 0.05" type="slide" damping="1" frictionloss="1" armature=".01" stiffness="0.05"/>
          <geom mesh="Lid003_vis" type="mesh" solimp="0.998 0.998 0.001" solref="0.001 1" density="100" friction="0.95 0.3 0.1" class="visual" material="Lid003_material"/>
          <geom class="collision" type="cylinder" pos="0.00140762 -0.15896048 -0.12113179" size="0.04154263436794281 0.0014191875234246254" quat="1.0 0.0 0.0 0.0"/>
        </body>
        <geom class="region" name="reg_main" type="box" pos="-5.000000000005e-07 0.0001370000000000121 2.5000000000025002e-06" size="0.07162808 0.20451139000000002 0.15777129"/>
      </body>
    </body>
  </worldbody>
  <actuator>
    <motor name="Button001_joint_actuator" joint="Button001_joint" gear="0.5"/>
    <motor name="Button002_joint_actuator" joint="Button002_joint" gear="0.5"/>
    <motor name="Container001_Clear_joint_actuator" joint="Container001_Clear_joint" gear="10"/>
    <motor name="Lid002_joint_actuator" joint="Lid002_joint" gear="10"/>
    <motor name="Lid003_joint_actuator" joint="Lid003_joint" gear="10"/>
    <motor name="Lid001_joint_actuator" joint="Lid001_joint" gear="10"/>
  </actuator>
</mujoco>
