<?xml version='1.0' encoding='UTF-8'?>
<mujoco model="model">
  <option timestep="0.002" gravity="0.0 0.0 -9.81"/>
  <compiler angle="radian"/>
  <asset>
    <mesh file="visuals/sideL_button_cancel.obj" name="sideL_button_cancel_vis"/>
    <mesh file="visuals/sideL_knob_doneness.obj" name="sideL_knob_doneness_vis"/>
    <mesh file="visuals/sideL_lever.obj" name="sideL_lever_vis"/>
    <mesh file="visuals/sideR_button_cancel.obj" name="sideR_button_cancel_vis"/>
    <mesh file="visuals/sideR_knob_doneness.obj" name="sideR_knob_doneness_vis"/>
    <mesh file="visuals/sideR_lever.obj" name="sideR_lever_vis"/>
    <mesh file="visuals/Body001.obj" name="Body001_vis"/>
    <mesh file="visuals/Body002.obj" name="Body002_vis"/>
    <texture file="visuals/T_BC001.png" name="Body001_material" type="2d"/>
    <material name="Body001_material" rgba="1 1 1 1.0" texture="Body001_material" shininess="0.5" specular="0.3"/>
    <texture file="visuals/T_BC001.png" name="sideL_button_cancel_material" type="2d"/>
    <material name="sideL_button_cancel_material" rgba="1 1 1 1.0" texture="sideL_button_cancel_material" shininess="0.5" specular="0.3103448502657381"/>
    <texture file="visuals/T_BC001.png" name="sideL_knob_doneness_material" type="2d"/>
    <material name="sideL_knob_doneness_material" rgba="1 1 1 1.0" texture="sideL_knob_doneness_material" shininess="0.5" specular="0.3103448502657381"/>
    <texture file="visuals/T_BC001.png" name="sideL_lever_material" type="2d"/>
    <material name="sideL_lever_material" rgba="1 1 1 1.0" texture="sideL_lever_material" shininess="0.5" specular="0.3103448502657381"/>
    <texture file="visuals/T_BC001.png" name="sideR_button_cancel_material" type="2d"/>
    <material name="sideR_button_cancel_material" rgba="1 1 1 1.0" texture="sideR_button_cancel_material" shininess="0.5" specular="0.3103448502657381"/>
    <texture file="visuals/T_BC001.png" name="sideR_knob_doneness_material" type="2d"/>
    <material name="sideR_knob_doneness_material" rgba="1 1 1 1.0" texture="sideR_knob_doneness_material" shininess="0.5" specular="0.3103448502657381"/>
    <texture file="visuals/T_BC001.png" name="sideR_lever_material" type="2d"/>
    <material name="sideR_lever_material" rgba="1 1 1 1.0" texture="sideR_lever_material" shininess="0.5" specular="0.3103448502657381"/>
    <texture file="visuals/T_BC001.png" name="Body002_material" type="2d"/>
    <material name="Body002_material" rgba="1 1 1 1.0" texture="Body002_material" shininess="0.5" specular="5"/>
  </asset>
  <default>
    <default class="visual">
      <geom conaffinity="0" contype="0" group="1" type="mesh"/>
    </default>
    <default class="collision_1">
      <geom group="0" rgba="0.5 0 0 0.5" solref="0.004 1" solimp="0.998 0.998 0.001"/>
    </default>
    <default class="collision_2">
      <geom group="0" rgba="0.5 0 0 0.5" solref="0.004 1" solimp="0.998 0.998 0.001"/>
    </default>
    <default class="collision_3">
      <geom group="0" rgba="0.5 0 0 0.5" solref="0.004 1" solimp="0.998 0.998 0.001"/>
    </default>
    <default class="collision_4">
      <geom group="0" rgba="0.5 0 0 0.5" solref="0.004 1" solimp="0.998 0.998 0.001"/>
    </default>
    <default class="collision_5">
      <geom group="0" rgba="0.5 0 0 0.5" solref="0.004 1" solimp="0.998 0.998 0.001"/>
    </default>
    <default class="collision_6">
      <geom group="0" rgba="0.5 0 0 0.5" solref="0.004 1" solimp="0.998 0.998 0.001"/>
    </default>
    <default class="collision_7">
      <geom group="0" rgba="0.5 0 0 0.5" solref="0.004 1" solimp="0.998 0.998 0.001"/>
    </default>
    <default class="collision_8">
      <geom group="0" rgba="0.5 0 0 0.5" solref="0.004 1" solimp="0.998 0.998 0.001"/>
    </default>
    <default class="spawn">
      <geom group="0" rgba="1 1 1 0.5" contype="0" conaffinity="0"/>
      <site group="0" rgba="1 1 1 0.5"/>
    </default>
    <default class="region">
      <geom group="1" conaffinity="0" contype="0" rgba="0 1 0 0" mass="0"/>
    </default>
  </default>
  <worldbody>
    <body>
      <body name="object">
        <geom mesh="Body001_vis" type="mesh" solimp="0.998 0.998 0.001" solref="0.001 1" friction="0.95 0.3 0.1" class="visual" material="Body001_material"/>
        <geom type="box" pos="-0.00044674641685560346 0.12026488780975342 -0.09392673522233963" size="0.13447068631649017 0.00393036799505353 0.019632775336503983" quat="0.9799838662147522 -0.1990768313407898 -0.0 0.0" class="collision_1"/>
        <geom type="box" pos="-0.00044674641685560346 -0.06252574175596237 -0.09489482641220093" size="0.13447068631649017 0.00393036799505353 0.019632775336503983" quat="0.975192666053772 0.22135789692401886 0.0 0.0" class="collision_1"/>
        <geom type="box" pos="0.1409631073474884 0.030339915305376053 -0.09131582826375961" size="0.006311427336186171 0.08797916024923325 0.02123778685927391" quat="0.9626746773719788 0.0 0.2706611156463623 0.0" class="collision_1"/>
        <geom type="box" pos="-0.14122942090034485 0.030339915305376053 -0.09276559948921204" size="0.006311427336186171 0.08797916024923325 0.02123778685927391" quat="0.9673653244972229 0.0 -0.2533857524394989 0.0" class="collision_1"/>
        <geom type="box" pos="-0.11325013637542725 -0.03796686977148056 -0.11897148936986923" size="0.011780587956309319 0.011780587956309319 0.005922116804867983" quat="1.0 0.0 0.0 0.0" class="collision_1"/>
        <geom type="box" pos="0.11429183185100555 -0.03796686977148056 -0.11897148936986923" size="0.011780587956309319 0.011780587956309319 0.005922116804867983" quat="1.0 0.0 0.0 0.0" class="collision_1"/>
        <geom type="box" pos="-0.11325013637542725 0.0884881243109703 -0.11897148936986923" size="0.011780587956309319 0.011780587956309319 0.005922116804867983" quat="1.0 0.0 0.0 0.0" class="collision_1"/>
        <geom type="box" pos="0.11429183185100555 0.0884881243109703 -0.11897148936986923" size="0.011780587956309319 0.011780587956309319 0.005922116804867983" quat="1.0 0.0 0.0 0.0" class="collision_1"/>
        <geom type="box" pos="0.13939955830574036 0.03420979157090187 0.04827224835753441" size="0.010647835209965706 0.08951014280319214 0.0805027037858963" quat="0.9954463839530945 0.0 -0.09532330930233002 0.0" class="collision_1"/>
        <geom type="box" pos="0.15416470170021057 0.03115106374025345 -0.052045706659555435" size="0.010647837072610855 0.10399692505598068 0.02255273051559925" quat="0.9999216794967651 0.0 -0.012517278082668781 0.0" class="collision_1"/>
        <geom type="box" pos="-0.1394502818584442 0.03421943262219429 0.048004716634750366" size="0.01064783614128828 0.0826282873749733 0.0805027037858963" quat="0.9953948855400085 0.0 0.09585954248905182 0.0" class="collision_1"/>
        <geom type="box" pos="-0.15400944650173187 0.034196414053440094 -0.053195323795080185" size="0.011610445566475391 0.10006249696016312 0.02299119159579277" quat="1.0 0.0 0.0 0.0" class="collision_1"/>
        <geom type="box" pos="0.0008880893001332879 0.11890549212694168 0.04633348807692528" size="0.13319306075572968 0.012511109001934528 0.0805027037858963" quat="0.9988362789154053 0.048229116946458817 0.0 0.0" class="collision_1"/>
        <geom type="box" pos="-0.00032237544655799866 0.1267222762107849 -0.05385943502187729" size="0.1542205959558487 0.010496157221496105 0.02122410573065281" quat="0.9998803734779358 -0.015469263307750225 -0.0 0.0" class="collision_1"/>
        <geom type="box" pos="-0.004979799035936594 -0.06478356570005417 -0.01428462378680706" size="0.1455572247505188 0.012511109933257103 0.0184781551361084" quat="0.9997701048851013 -0.021442122757434845 -0.0 0.0" class="collision_1"/>
        <geom type="box" pos="-0.002841375535354018 -0.06756524741649628 -0.052719760686159134" size="0.16078045964241028 0.010827445425093174 0.02138606086373329" quat="1.0 0.0 0.0 0.0" class="collision_1"/>
        <geom type="box" pos="-0.0026012654416263103 -0.05928958207368851 0.06512191146612167" size="0.1367025375366211 0.012511109001934528 0.061788905411958694" quat="0.9992153644561768 -0.039606720209121704 -0.0 0.0" class="collision_1"/>
        <geom type="box" pos="0.00032845139503479004 0.02971804141998291 -0.108138307929039" size="0.14030978083610535 0.08675547689199448 0.005922204814851284" quat="1.0 0.0 0.0 0.0" class="collision_1"/>
        <geom type="box" pos="0.1464659571647644 -0.057390689849853516 -0.09268210083246231" size="0.0031624019611626863 0.004117121919989586 0.021120190620422363" quat="0.9464960694313049 0.059724461287260056 0.27581343054771423 -0.15654131770133972" class="collision_1"/>
        <geom type="box" pos="-0.10911621898412704 0.02752969041466713 0.046505801379680634" size="0.005207378417253494 0.07103536278009415 0.07608040422201157" quat="1.0 0.0 0.0 0.0" class="collision_1"/>
        <geom type="box" pos="-0.06283487379550934 0.02752969041466713 0.046795669943094254" size="0.014857487753033638 0.07103536278009415 0.07636824995279312" quat="1.0 0.0 0.0 0.0" class="collision_1"/>
        <geom type="box" pos="-0.002341354265809059 0.02752969041466713 0.046795669943094254" size="0.019084839150309563 0.07103536278009415 0.07637011259794235" quat="1.0 0.0 0.0 0.0" class="collision_1"/>
        <geom type="box" pos="0.05908895283937454 0.02752969041466713 0.046795669943094254" size="0.016136080026626587 0.0710362121462822 0.07636921852827072" quat="1.0 0.0 0.0 0.0" class="collision_1"/>
        <geom type="box" pos="0.10914602130651474 0.02752969041466713 0.046505801379680634" size="0.005973801016807556 0.07103536278009415 0.0760800763964653" quat="1.0 0.0 0.0 0.0" class="collision_1"/>
        <geom type="box" pos="-0.07091841846704483 -0.07970783859491348 0.053236499428749084" size="0.0027334047481417656 0.010841797105967999 0.033434223383665085" quat="0.987780749797821 0.003852688940241933 -0.0117016127333045 0.15536220371723175" class="collision_1"/>
        <geom type="box" pos="-0.05002918466925621 -0.08060146123170853 0.052149973809719086" size="0.0023296447470784187 0.011139070615172386 0.033431366086006165" quat="0.9844239354133606 0.00915802177041769 0.001750251860357821 -0.1755637228488922" class="collision_1"/>
        <geom type="box" pos="-0.06045627221465111 -0.0799240991473198 0.0919889509677887" size="0.003909409511834383 0.015574048273265362 0.0017762052593752742" quat="0.9199158549308777 0.39211586117744446 0.0 0.0" class="collision_1"/>
        <geom type="box" pos="-0.06045627221465111 -0.0810844674706459 0.014271676540374756" size="0.010975378565490246 0.008613021112978458 0.0038106541614979506" quat="0.9888113141059875 -0.1491716057062149 -0.0 0.0" class="collision_1"/>
        <geom type="box" pos="0.14365535974502563 -0.061014533042907715 -0.09142813086509705" size="0.0031624017283320427 0.004117121919989586 0.0205256137996912" quat="0.9081395864486694 0.11606573313474655 0.294817179441452 -0.2736678719520569" class="collision_1"/>
        <geom type="box" pos="0.13684366643428802 -0.06407270580530167 -0.09433968365192413" size="0.0031624024268239737 0.004117121919989586 0.02069542184472084" quat="0.7354452013969421 0.18512742221355438 0.2251061499118805 -0.6116988062858582" class="collision_1"/>
        <geom type="box" pos="0.14234477281570435 -0.06447140127420425 -0.09276073426008224" size="0.0031624017283320427 0.004117121919989586 0.0205256137996912" quat="0.8550456166267395 0.1904042661190033 0.23266524076461792 -0.42250457406044006" class="collision_1"/>
        <geom type="box" pos="-0.13692668080329895 -0.06513560563325882 -0.09358090162277222" size="0.0031624019611626863 0.004117121919989586 0.021120190620422363" quat="0.5760980248451233 0.2337408810853958 0.15813055634498596 -0.7671186327934265" class="collision_1"/>
        <geom type="box" pos="-0.14067403972148895 -0.062491945922374725 -0.09232693165540695" size="0.0031624017283320427 0.004117121919989586 0.0205256137996912" quat="0.46744412183761597 0.28760191798210144 0.13294190168380737 -0.8252924084663391" class="collision_1"/>
        <geom type="box" pos="-0.1449662446975708 -0.05844539776444435 -0.09357921779155731" size="0.0031624024268239737 0.004117121919989586 0.021619513630867004" quat="0.10904650390148163 0.2893645167350769 0.03482958301901817 -0.9503493905067444" class="collision_1"/>
        <geom type="box" pos="-0.1440049558877945 -0.06467307358980179 -0.0912436842918396" size="0.0031624019611626863 0.004117121919989586 0.0205256137996912" quat="0.2321225255727768 0.2970905303955078 0.07213438302278519 -0.923392117023468" class="collision_1"/>
        <geom type="box" pos="-0.14460401237010956 0.1171574667096138 -0.09381018579006195" size="0.0031624019611626863 0.004117121919989586 0.021120190620422363" quat="0.20623697340488434 -0.2722799777984619 0.07418638467788696 0.9369238615036011" class="collision_1"/>
        <geom type="box" pos="-0.14142736792564392 0.12046512961387634 -0.09255621582269669" size="0.0031624017283320427 0.004117121919989586 0.0205256137996912" quat="0.3211776614189148 -0.2882862091064453 0.1314513236284256 0.8924441337585449" class="collision_1"/>
        <geom type="box" pos="-0.13678191602230072 0.1241006925702095 -0.09380850195884705" size="0.0031624019611626863 0.004117121919989586 0.0198535043746233" quat="0.6496307253837585 -0.2150305062532425 0.1967407464981079 0.7021644115447998" class="collision_1"/>
        <geom type="box" pos="-0.14288872480392456 0.12300888448953629 -0.09319306164979935" size="0.0031624017283320427 0.004117121919989586 0.018914194777607918" quat="0.5489631295204163 -0.2483569085597992 0.1782834827899933 0.77792888879776" class="collision_1"/>
        <geom type="box" pos="0.13727596402168274 0.12121548503637314 -0.09327942878007889" size="0.0031624019611626863 0.004117121919989586 0.021120190620422363" quat="0.7339819073677063 -0.1708524525165558 0.2246096134185791 0.6177625060081482" class="collision_1"/>
        <geom type="box" pos="0.14129310846328735 0.11900316923856735 -0.09202545881271362" size="0.0031624017283320427 0.004117121919989586 0.0205256137996912" quat="0.7980930209159851 -0.14869031310081482 0.2797849476337433 0.5125027894973755" class="collision_1"/>
        <geom type="box" pos="0.14600712060928345 0.1154569610953331 -0.09327774494886398" size="0.0031624017283320427 0.004117121919989586 0.0198535043746233" quat="0.9428374171257019 -0.050826843827962875 0.2869871258735657 0.16159389913082123" class="collision_1"/>
        <geom type="box" pos="0.14337195456027985 0.12107310444116592 -0.09266230463981628" size="0.0031624017283320427 0.004117121919989586 0.018914194777607918" quat="0.9090948104858398 -0.08850280195474625 0.29263195395469666 0.2829849123954773" class="collision_1"/>
        <geom type="box" pos="0.13670752942562103 -0.06878319382667542 0.04974736273288727" size="0.00865440908819437 0.005012230481952429 0.08033323287963867" quat="0.9791340827941895 -0.03711995109915733 -0.05296817794442177 0.19264717400074005" class="collision_1"/>
        <geom type="box" pos="0.14546415209770203 -0.0627499595284462 0.04974736273288727" size="0.008654408156871796 0.005012230947613716 0.08033324033021927" quat="0.8364589214324951 -0.05639462545514107 -0.053623031824827194 0.5424764752388" class="collision_1"/>
        <geom type="box" pos="0.14436012506484985 0.12271402776241302 0.04757818952202797" size="0.00865440908819437 0.005012230481952429 0.08033324033021927" quat="0.4838537871837616 -0.03958134725689888 -0.06159912422299385 0.8720805048942566" class="collision_1"/>
        <geom type="box" pos="0.13612137734889984 0.12779466807842255 0.046435002237558365" size="0.00865440908819437 0.005012230481952429 0.08033323287963867" quat="0.12437501549720764 -0.04715656861662865 -0.055987101048231125 0.9895314574241638" class="collision_1"/>
        <geom type="box" pos="-0.13884337246418 0.1251833438873291 0.04757818952202797" size="0.00865440908819437 0.0050122300162911415 0.08033324033021927" quat="0.1917499154806137 -0.014288317412137985 0.0478287898004055 -0.9801735877990723" class="collision_1"/>
        <geom type="box" pos="-0.14797596633434296 0.12035005539655685 0.046435002237558365" size="0.00865440908819437 0.005012230481952429 0.08033323287963867" quat="0.7093334197998047 -0.015710432082414627 0.07149460166692734 -0.7010619044303894" class="collision_1"/>
        <geom type="box" pos="-0.1466149240732193 -0.05657394975423813 0.04757818952202797" size="0.00865440908819437 0.005012230947613716 0.08033324033021927" quat="0.802619218826294 -0.058406613767147064 0.04670156538486481 -0.5917854309082031" class="collision_1"/>
        <geom type="box" pos="-0.14259599149227142 -0.0674305334687233 0.04796357452869415" size="0.00865440908819437 0.005012230481952429 0.08033323287963867" quat="0.9979035258293152 -0.03159482032060623 0.043148621916770935 -0.03644896671175957" class="collision_1"/>
        <geom type="box" pos="-0.06592980772256851 -0.07991290837526321 0.09256616234779358" size="0.0038907870184630156 0.015574048273265362 0.0017762051429599524" quat="0.8960186839103699 0.3767300546169281 -0.23089206218719482 0.04374747350811958" class="collision_1"/>
        <geom type="box" pos="-0.07169084250926971 -0.0791320875287056 0.08981968462467194" size="0.003890787251293659 0.015574049204587936 0.0017762051429599524" quat="0.87903892993927 0.3058508634567261 -0.3611479699611664 0.05760198086500168" class="collision_1"/>
        <geom type="box" pos="-0.05315784737467766 -0.07887665927410126 0.09104868769645691" size="0.003909409511834383 0.015574048273265362 0.0017762052593752742" quat="0.8970921039581299 0.3964369595050812 0.1949540227651596 0.007511969655752182" class="collision_1"/>
        <geom type="box" pos="-0.049283940345048904 -0.07934129238128662 0.08806617558002472" size="0.003909409511834383 0.015574048273265362 0.0017762052593752742" quat="0.7933098077774048 0.2993110120296478 0.5294592380523682 -0.02730184607207775" class="collision_1"/>
        <geom type="box" pos="0.05896570533514023 -0.07970783859491348 0.053236499428749084" size="0.002625924302265048 0.010963121429085732 0.03343268856406212" quat="0.9849674105644226 0.00633706571534276 -0.008766614831984043 0.17240123450756073" class="collision_1"/>
        <geom type="box" pos="0.0806637853384018 -0.08060146123170853 0.052149973809719086" size="0.0023296447470784187 0.011139070615172386 0.033431366086006165" quat="0.9844239354133606 0.00915802177041769 0.001750251860357821 -0.1755637228488922" class="collision_1"/>
        <geom type="box" pos="0.0702366977930069 -0.0799240991473198 0.0919889509677887" size="0.003909409511834383 0.015574048273265362 0.0017762052593752742" quat="0.9199158549308777 0.39211586117744446 0.0 0.0" class="collision_1"/>
        <geom type="box" pos="0.0702366977930069 -0.0810844674706459 0.014271676540374756" size="0.010975378565490246 0.008613021112978458 0.0038106541614979506" quat="0.9888113141059875 -0.1491716057062149 -0.0 0.0" class="collision_1"/>
        <geom type="box" pos="0.06476316601037979 -0.07991290837526321 0.09256616234779358" size="0.0038907870184630156 0.015574048273265362 0.0017762051429599524" quat="0.8960186839103699 0.3767300546169281 -0.23089206218719482 0.04374747350811958" class="collision_1"/>
        <geom type="box" pos="0.05900213122367859 -0.0791320875287056 0.08981968462467194" size="0.003890787251293659 0.015574049204587936 0.0017762051429599524" quat="0.87903892993927 0.3058508634567261 -0.3611479699611664 0.05760198086500168" class="collision_1"/>
        <geom type="box" pos="0.07753512263298035 -0.07887665927410126 0.09104868769645691" size="0.003909409511834383 0.015574048273265362 0.0017762052593752742" quat="0.8970921039581299 0.3964369595050812 0.1949540227651596 0.007511969655752182" class="collision_1"/>
        <geom type="box" pos="0.0814090371131897 -0.07934129238128662 0.08806617558002472" size="0.003909409511834383 0.015574048273265362 0.0017762052593752742" quat="0.7933098077774048 0.2993110120296478 0.5294592380523682 -0.02730184607207775" class="collision_1"/>
        <geom type="box" pos="0.0 -0.048256926238536835 0.042633622884750366" size="0.11826896667480469 0.008620768785476685 0.08299725502729416" quat="1.0 0.0 0.0 0.0" class="collision_1"/>
        <geom type="box" pos="0.0 0.10581551492214203 0.042633622884750366" size="0.11826896667480469 0.008620768785476685 0.08299720287322998" quat="1.0 0.0 0.0 0.0" class="collision_1"/>
        <body name="sideL_button_cancel">
          <joint axis="0.0 1.0 0.0" pos="-0.03575551509857178 -0.08017919957637787 -0.05030425637960434" limited="true" name="sideL_button_cancel_joint" range="0.0 0.003" type="slide" damping="1" frictionloss="1" armature=".01" stiffness="0.05"/>
          <geom mesh="sideL_button_cancel_vis" type="mesh" solimp="0.998 0.998 0.001" solref="0.001 1" friction="0.95 0.3 0.1" class="visual" material="sideL_button_cancel_material"/>
          <geom class="collision_2" type="box" pos="-0.03601318597793579 -0.08363092690706253 -0.05012350156903267" size="0.015511701814830303 0.0025674805510789156 0.006430113222450018" quat="1.0 0.0 0.0 0.0" name="sideL_button_cancel_main"/>
        </body>
        <body name="sideL_knob_doneness">
          <joint axis="0.0 1.0 0.0" pos="-0.10707026720046997 -0.08434509485960007 -0.03358955308794975" limited="true" name="sideL_knob_doneness_joint" range="0.0 5.201081170943102" type="hinge" damping="0.05" frictionloss="0.1" armature="0.001"/>
          <geom mesh="sideL_knob_doneness_vis" type="mesh" solimp="0.998 0.998 0.001" solref="0.001 1" friction="0.95 0.3 0.1" class="visual" material="sideL_knob_doneness_material"/>
          <geom type="cylinder" pos="-0.10715775191783905 -0.08115532994270325 -0.03383712098002434" size="0.017344027757644653 0.0025102447252720594" quat="0.7071068286895752 -0.7071067690849304 -0.0 0.0" class="collision_3" density="0.001"/>
          <geom class="collision_3" type="box" pos="-0.10666624456644058 -0.08937132358551025 -0.03361452743411064" size="0.006066915113478899 0.005955501925200224 0.014460868202149868" quat="1.0 0.0 0.0 0.0" name="sideL_knob_doneness_main" density="0.001"/>
        </body>
        <body name="sideL_lever">
          <joint axis="0.0 0.0 -1.0" pos="-0.06070128083229065 -0.09401111304759979 0.0756411999464035" limited="true" name="sideL_lever_joint" range="0.0 0.05" type="slide" damping="1" frictionloss="1" armature=".01" stiffness="1" springref="-1"/>
          <geom class="region" name="reg_sideL_slotR" type="box" pos="-0.034039558842778206 0.027982596307992935 0.12544087134301662" size="0.012141059920191766 0.06485151669383049 0.07600008679926396"/>
          <geom class="region" name="reg_sideL_slotL" type="box" pos="-0.08720257133245468 0.027982596307992935 0.12544087134301662" size="0.015308445155620576 0.06485151669383049 0.07600008679926396"/>
          <geom mesh="sideL_lever_vis" type="mesh" solimp="0.998 0.998 0.001" solref="0.001 1" friction="0.95 0.3 0.1" class="visual" material="sideL_lever_material"/>
          <geom class="collision_4" type="cylinder" pos="-0.06061257794499397 -0.11512642353773117 0.07574426382780075" size="0.005340807605534792 0.021487968042492867" quat="0.7071068286895752 -0.7071067690849304 -0.0 0.0" name="sideL_lever_handle"/>
          <geom type="cylinder" pos="-0.060659583657979965 -0.09300929307937622 0.07557299733161926" size="0.0035236342810094357 0.010406561195850372" quat="0.7071068286895752 -0.7071067690849304 -0.0 0.0" class="collision_4"/>
          <geom class="collision_4" type="box" pos="-0.0908137634396553 0.028542371466755867 0.04555044323205948" size="0.012499998323619366 0.0668611153960228 0.0010043121874332428" quat="1.0 0.0 0.0 0.0" name="sideL_slotL_floor"/>
          <geom class="collision_4" type="box" pos="-0.03456781432032585 0.028542371466755867 0.04555044323205948" size="0.012499998323619366 0.0668611153960228 0.0010043015936389565" quat="1.0 0.0 0.0 0.0" name="sideL_slotR_floor"/>
        </body>
        <body name="sideR_button_cancel">
          <joint axis="0.0 1.0 0.0" pos="0.03482136130332947 -0.08017919957637787 -0.05030425637960434" limited="true" name="sideR_button_cancel_joint" range="0.0 0.003" type="slide" damping="1" frictionloss="1" armature=".01" stiffness="0.05"/>
          <geom mesh="sideR_button_cancel_vis" type="mesh" solimp="0.998 0.998 0.001" solref="0.001 1" friction="0.95 0.3 0.1" class="visual" material="sideR_button_cancel_material"/>
          <geom class="collision_5" type="box" pos="0.03484227508306503 -0.08363092690706253 -0.05012350156903267" size="0.015511712990701199 0.0025674805510789156 0.006430113222450018" quat="1.0 0.0 0.0 0.0" name="sideR_button_cancel_main"/>
        </body>
        <body name="sideR_knob_doneness">
          <joint axis="0.0 1.0 0.0" pos="0.10801281034946442 -0.08434509485960007 -0.03433068469166756" limited="true" name="sideR_knob_doneness_joint" range="0.0 5.201081170943102" type="hinge" damping="0.05" frictionloss="0.1" armature="0.001"/>
          <geom mesh="sideR_knob_doneness_vis" type="mesh" solimp="0.998 0.998 0.001" solref="0.001 1" friction="0.95 0.3 0.1" class="visual" material="sideR_knob_doneness_material"/>
          <geom class="collision_6" type="box" pos="0.10850415378808975 -0.08937132358551025 -0.03399918973445892" size="0.006066915113478899 0.005955501925200224 0.014460868202149868" quat="1.0 0.0 0.0 0.0" name="sideR_knob_doneness_main" density="0.001"/>
          <geom type="cylinder" pos="0.10801264643669128 -0.08115532994270325 -0.03422178328037262" size="0.017344027757644653 0.0025102447252720594" quat="0.7071068286895752 -0.7071067690849304 -0.0 0.0" class="collision_6" density="0.001"/>
        </body>
        <body name="sideR_lever">
          <joint axis="0.0 0.0 -1.0" pos="0.06959846615791321 -0.09401111304759979 0.0756411999464035" limited="true" name="sideR_lever_joint" range="0.0 0.05" type="slide" damping="1" frictionloss="1" armature=".01" stiffness="1" springref="-1"/>
          <geom class="region" name="reg_sideR_slotR" type="box" pos="0.08918516337871552 0.027982596307992935 0.12544087134301662" size="0.01287737286090851 0.06485151669383049 0.07600008679926396"/>
          <geom class="region" name="reg_sideR_slotL" type="box" pos="0.030072106048464775 0.027982596307992935 0.12544087134301662" size="0.012219954118132592 0.06485151669383049 0.07600008679926396"/>
          <geom mesh="sideR_lever_vis" type="mesh" solimp="0.998 0.998 0.001" solref="0.001 1" friction="0.95 0.3 0.1" class="visual" material="sideR_lever_material"/>
          <geom class="collision_7" type="cylinder" pos="0.06966513395309448 -0.11512642353773117 0.07569434493780136" size="0.005340807605534792 0.021487968042492867" quat="0.7071068286895752 -0.7071067690849304 -0.0 0.0" name="sideR_lever_handle"/>
          <geom type="cylinder" pos="0.06956285983324051 -0.09300929307937622 0.07567412406206131" size="0.0035236342810094357 0.010406561195850372" quat="0.7071068286895752 -0.7071067690849304 -0.0 0.0" class="collision_7"/>
          <geom class="collision_7" type="box" pos="0.029887543991208076 0.028542371466755867 0.04555044323205948" size="0.012499998323619366 0.06686118245124817 0.001004313351586461" quat="1.0 0.0 0.0 0.0" name="sideR_slotL_floor"/>
          <geom class="collision_7" type="box" pos="0.08926278352737427 0.028542371466755867 0.045550450682640076" size="0.012499998323619366 0.06686105579137802 0.001004310674034059" quat="1.0 0.0 0.0 0.0" name="sideR_slotR_floor"/>
        </body>
        <body name="Body002">
          <geom mesh="Body002_vis" type="mesh" solimp="0.998 0.998 0.001" solref="0.001 1" friction="0.95 0.3 0.1" class="visual" material="Body002_material"/>
        </body>
        <geom class="region" name="reg_main" type="box" pos="3.725290298461914e-09 0.028689749538898468 0.0" size="0.16393542087078095 0.10725100880861282 0.12576745247840881"/>
      </body>
    </body>
  </worldbody>
  <actuator>
    <motor name="sideL_button_cancel_joint_actuator" joint="sideL_button_cancel_joint" gear="0.2"/>
    <motor name="sideL_knob_doneness_joint_actuator" joint="sideL_knob_doneness_joint" gear="5"/>
    <motor name="sideL_lever_joint_actuator" joint="sideL_lever_joint" gear="1.5"/>
    <motor name="sideR_button_cancel_joint_actuator" joint="sideR_button_cancel_joint" gear="0.2"/>
    <motor name="sideR_knob_doneness_joint_actuator" joint="sideR_knob_doneness_joint" gear="5"/>
    <motor name="sideR_lever_joint_actuator" joint="sideR_lever_joint" gear="1.5"/>
  </actuator>
</mujoco>
