<?xml version='1.0' encoding='UTF-8'?>
<mujoco model="model">
  <compiler angle="radian"/>
  <asset>
    <mesh file="visuals/Body001.obj" name="Body001_vis"/>
    <mesh file="visuals/Button001.obj" name="Button001_vis"/>
    <mesh file="visuals/Container001_Clear.obj" name="Container001_Clear_vis"/>
    <mesh file="visuals/Lid001.obj" name="Lid001_vis"/>
    <mesh file="visuals/Lid002.obj" name="Lid002_vis"/>
    <mesh file="visuals/Lid003.obj" name="Lid003_vis"/>
    <texture file="visuals/T_BC001.png" name="Body001_material" type="2d"/>
    <material name="Body001_material" rgba="1 1 1 1.0" texture="Body001_material" shininess="0.4472135901451111" specular="0.3103448502657381"/>
    <texture file="visuals/T_BC001.png" name="Button001_material" type="2d"/>
    <material name="Button001_material" rgba="1 1 1 1.0" texture="Button001_material" shininess="0.4472135901451111" specular="0.3103448502657381"/>
    <texture file="visuals/T_BC001.png" name="Container001_Clear_material" type="2d"/>
    <material name="Container001_Clear_material" rgba="1 1 1 0.5" texture="Container001_Clear_material" shininess="0.5" specular="0.3103448502657381"/>
    <texture file="visuals/T_BC001.png" name="Lid003_material" type="2d"/>
    <material name="Lid003_material" rgba="1 1 1 1.0" texture="Lid003_material" shininess="0.4472135901451111" specular="0.3103448502657381"/>
    <texture file="visuals/T_BC001.png" name="Lid001_material" type="2d"/>
    <material name="Lid001_material" rgba="1 1 1 1.0" texture="Lid001_material" shininess="0.4472135901451111" specular="0.3103448502657381"/>
    <texture file="visuals/T_BC001.png" name="Lid002_material" type="2d"/>
    <material name="Lid002_material" rgba="1 1 1 1.0" texture="Lid002_material" shininess="0.4472135901451111" specular="0.3103448502657381"/>
  </asset>
  <default>
    <default class="visual">
      <geom conaffinity="0" contype="0" group="1" type="mesh"/>
    </default>
    <default class="collision">
      <geom group="0" rgba="0.5 0 0 0.5"/>
    </default>
    <default class="spawn">
      <geom group="0" rgba="1 1 1 0.5" contype="0" conaffinity="0"/>
      <site group="0" rgba="1 1 1 0.5"/>
    </default>
    <default class="region">
      <geom group="1" conaffinity="0" contype="0" rgba="0 1 0 0"/>
    </default>
  </default>
  <worldbody>
    <body>
      <body name="object">
        <geom class="collision" type="box" pos="0.11969487 -0.31822094 0.06074095" size="0.011253004893660545 0.0011331994319334626 0.010624666698276997" quat="0.9990482330322266 -0.04361938312649727 -0.0 0.0" name="start_button" rgba="0.0 0.5 0 0.5"/>
        <site rgba="0 0 0 0" size="0.009999999776482582 0.009999999776482582" pos="0.00152135 -0.27331036 -0.21436115" name="receptacle_place_site"/>
        <site type="cylinder" rgba="0.8 0.5 0.25 1" size="0.0024999999441206455 0.09999999403953552" pos="0.00152135 -0.27331039 -0.12164882" name="coffee_liquid"/>
        <geom mesh="Body001_vis" type="mesh" solimp="0.998 0.998 0.001" solref="0.001 1" density="100" friction="0.95 0.3 0.1" class="visual" material="Body001_material"/>
        <geom class="collision" type="box" pos="-0.13482280 -0.26258367 -0.24122265" size="0.04780609533190727 0.0627865344285965 0.029584329575300217" quat="1.0 0.0 0.0 0.0"/>
        <geom class="collision" type="box" pos="-0.04169501 -0.29072571 0.14186096" size="0.14093397557735443 0.015021247789263725 0.12811273336410522" quat="0.9990295767784119 -0.0440446212887764 -1.0805361907287307e-17 4.996576412190894e-20"/>
        <geom class="collision" type="box" pos="0.00128906 -0.09666919 0.03865990" size="0.18133977055549622 0.18675203621387482 0.0388786718249321" quat="1.0 0.0 0.0 0.0"/>
        <geom class="collision" type="box" pos="0.13169864 -0.26258367 -0.24122265" size="0.050210438668727875 0.06278654932975769 0.029584338888525963" quat="1.0 0.0 0.0 0.0"/>
        <geom class="collision" type="box" pos="0.00033823 -0.26537967 -0.25123590" size="0.08754803240299225 0.059990547597408295 0.019571099430322647" quat="1.0 0.0 0.0 0.0"/>
        <geom class="collision" type="cylinder" pos="0.00051027 -0.26053312 0.00906882" size="0.04037771001458168 0.023910516873002052" quat="1.0 0.0 0.0 0.0"/>
        <geom class="collision" type="cylinder" pos="0.00051027 -0.27254623 -0.01843776" size="0.008941007778048515 0.007940022274851799" quat="1.0 0.0 0.0 0.0"/>
        <geom class="collision" type="cylinder" pos="0.11774265 -0.25044778 -0.01136247" size="0.01128160860389471 0.028964461758732796" quat="1.0 0.0 0.0 0.0"/>
        <geom class="collision" type="cylinder" pos="-0.12087111 -0.25061786 -0.08050466" size="0.007660144008696079 0.07949106395244598" quat="1.0 0.0 0.0 0.0"/>
        <geom class="collision" type="cylinder" pos="-0.12087111 -0.25051510 -0.17636432" size="0.010353024117648602 0.018009692430496216" quat="1.0 0.0 0.0 0.0"/>
        <geom class="collision" type="box" pos="-0.10185541 -0.25029108 -0.02232642" size="0.011885647661983967 0.003399388864636421 0.0022346018813550472" quat="1.0 0.0 0.0 0.0"/>
        <geom class="collision" type="box" pos="-0.10185541 -0.25029108 -0.04909454" size="0.011885648593306541 0.003399389795958996 0.0022346023470163345" quat="1.0 0.0 0.0 0.0"/>
        <geom class="collision" type="box" pos="-0.08925864 -0.25029108 -0.03577894" size="0.0033965324983000755 0.0033993904944509268 0.015550194308161736" quat="1.0 0.0 0.0 0.0"/>
        <geom class="collision" type="cylinder" pos="-0.12087111 -0.25061786 0.01753925" size="0.015312847681343555 0.010616145096719265" quat="1.0 0.0 0.0 0.0"/>
        <geom class="collision" type="box" pos="0.00129554 -0.01232523 0.25496390" size="0.12438777089118958 0.09775403141975403 0.001296260510571301" quat="1.0 0.0 0.0 0.0"/>
        <geom class="collision" type="box" pos="0.15329914 -0.09436595 0.16549988" size="0.029329705983400345 0.18281696736812592 0.09076027572154999" quat="1.0 0.0 0.0 0.0"/>
        <geom class="collision" type="box" pos="0.00018185 0.19461425 -0.25124946" size="0.16807852685451508 0.10855495184659958 0.01955723762512207" quat="1.0 0.0 0.0 0.0"/>
        <geom class="collision" type="box" pos="0.00010650 -0.05153753 -0.13367376" size="0.18049804866313934 0.1410188376903534 0.13559068739414215" quat="1.0 0.0 0.0 0.0"/>
        <geom class="collision" type="box" pos="-0.15224974 -0.09371310 0.16549988" size="0.028279060497879982 0.18346981704235077 0.09076027572154999" quat="1.0 0.0 0.0 0.0"/>
        <geom class="collision" type="box" pos="0.16058962 -0.29072571 0.14186096" size="0.021833641454577446 0.015021247789263725 0.12811273336410522" quat="0.9990295767784119 -0.0440446212887764 -1.0805361907287307e-17 4.996576412190894e-20"/>
        <geom class="collision" type="box" pos="0.11846649 -0.28804040 0.17225611" size="0.021833641454577446 0.015021247789263725 0.09759920090436935" quat="0.9990295767784119 -0.0440446212887764 -1.0805361907287307e-17 4.996576412190894e-20"/>
        <geom class="collision" type="box" pos="0.11846649 -0.30077574 0.02810400" size="0.021833641454577446 0.0150212487205863 0.013912685215473175" quat="0.9990295767784119 -0.0440446212887764 -1.0805361907287307e-17 4.996576412190894e-20"/>
        <geom class="collision" type="box" pos="0.11846649 -0.29183963 0.05845792" size="0.021833641454577446 0.00879106018692255 0.017746800556778908" quat="0.9990295767784119 -0.0440446212887764 -1.0805361907287307e-17 4.996576412190894e-20"/>
        <body name="Button001">
          <joint axis="-9.694627089473551e-19 0.9956339001655579 -0.0933440551161766" pos="0.11966845 -0.31626236 0.06053684" limited="true" name="Button001_joint" range="0.0 0.005" type="slide" damping="1" frictionloss="1" armature=".01" stiffness="0.2" springref="-0.1"/>
          <geom mesh="Button001_vis" type="mesh" solimp="0.998 0.998 0.001" solref="0.001 1" density="100" friction="0.95 0.3 0.1" class="visual" material="Button001_material"/>
          <geom class="collision" type="box" pos="0.11969487 -0.31514060 0.06031599" size="0.011253004893660545 0.0014834600733593106 0.010624666698276997" quat="0.9990482330322266 -0.04361938312649727 -0.0 0.0"/>
        </body>
        <body name="Container001_Clear">
          <!-- <joint axis="0.0 0.0 1.0" pos="0.00088234 0.20799887 -0.00305720" limited="true" name="Container001_Clear_joint" range="0.0 0.1" type="slide" damping="1" frictionloss="1" armature=".01" stiffness="0.05"/> -->
          <geom mesh="Container001_Clear_vis" type="mesh" solimp="0.998 0.998 0.001" solref="0.001 1" density="100" friction="0.95 0.3 0.1" class="visual" material="Container001_Clear_material"/>
          <geom class="collision" type="box" pos="-0.15524165 0.16101864 -0.00698387" size="0.003073263680562377 0.06835802644491196 0.22219760715961456" quat="1.0 0.0 0.0 0.0"/>
          <geom class="collision" type="box" pos="0.15681182 0.16101864 -0.00698387" size="0.003073263680562377 0.06835802644491196 0.22219760715961456" quat="1.0 0.0 0.0 0.0"/>
          <geom class="collision" type="box" pos="-0.00006290 0.30790138 -0.00698387" size="0.003073263680562377 0.07720185816287994 0.22219760715961456" quat="0.706840455532074 -0.019407251849770546 -0.019407249987125397 -0.7068403959274292"/>
          <geom class="collision" type="box" pos="-0.11717859 0.27377483 -0.00698387" size="0.0030732634477317333 0.05834748595952988 0.22219757735729218" quat="0.9163600206375122 -0.010966429486870766 -0.025159889832139015 -0.3994133472442627"/>
          <geom class="collision" type="box" pos="0.11773485 0.27377483 -0.00698387" size="0.0030732634477317333 0.05834748595952988 0.22219757735729218" quat="0.40577176213264465 -0.025083079934120178 -0.011141007766127586 -0.9135622382164001"/>
          <geom class="collision" type="box" pos="-0.00073008 0.09573855 -0.00698387" size="0.003073263680562377 0.15569299459457397 0.22219760715961456" quat="0.7071068286895752 0.0 -0.0 -0.7071067690849304"/>
          <geom class="collision" type="box" pos="-0.00073008 0.16426449 -0.22610714" size="0.003073263680562377 0.15569299459457397 0.07212930917739868" quat="0.5 -0.5 -0.4999999701976776 -0.5"/>
          <geom class="collision" type="box" pos="-0.00073008 0.26180801 -0.22610714" size="0.003073263680562377 0.07902587950229645 0.03594767302274704" quat="0.5 -0.5 -0.4999999701976776 -0.5"/>
          <geom class="collision" type="box" pos="-0.09431710 0.22972335 -0.22610714" size="0.003073263680562377 0.055044565349817276 0.03594767302274704" quat="0.6541367769241333 -0.2685239613056183 -0.6541367173194885 -0.2685239613056183"/>
          <geom class="collision" type="box" pos="0.09654466 0.22972335 -0.22610714" size="0.003073263680562377 0.055044565349817276 0.03594767302274704" quat="0.6541368961334229 -0.26852402091026306 0.654136598110199 0.2685239017009735"/>
          <body name="Lid003">
            <joint axis="1.0 0.0 0.0" pos="0.00088482 0.09434001 0.25387853" limited="true" name="Lid003_joint" range="0.0 1.5707963267948966" type="hinge" damping="1" frictionloss="1" armature=".01" stiffness="0.05"/>
            <geom mesh="Lid003_vis" type="mesh" solimp="0.998 0.998 0.001" solref="0.001 1" density="100" friction="0.95 0.3 0.1" class="visual" material="Lid003_material"/>
            <geom class="collision" type="box" pos="0.00023444 0.20653673 0.23912041" size="0.15742236375808716 0.1126856729388237 0.01591619849205017" quat="1.0 0.0 0.0 0.0"/>
          </body>
        </body>
        <body name="Lid001">
          <!-- <joint axis="0.0 0.0 1.0" pos="-0.00242650 -0.26321959 -0.22054850" limited="true" name="Lid001_joint" range="0.0 0.05" type="slide" damping="1" frictionloss="1" armature=".01" stiffness="0.05"/> -->
          <geom mesh="Lid001_vis" type="mesh" solimp="0.998 0.998 0.001" solref="0.001 1" density="100" friction="0.95 0.3 0.1" class="visual" material="Lid001_material"/>
          <geom class="collision" type="box" pos="-0.00206058 -0.26350522 -0.22063024" size="0.08113859593868256 0.05987848713994026 0.007675427012145519" quat="1.0 0.0 0.0 0.0"/>
        </body>
        <body name="Lid002">
          <joint axis="-1.0 0.0 0.0" pos="-0.00119689 -0.11452691 0.25418198" limited="true" name="Lid002_joint" range="0.0 1.5707963267948966" type="hinge" damping="1" frictionloss="1" armature=".01" stiffness="0.05"/>
          <geom mesh="Lid002_vis" type="mesh" solimp="0.998 0.998 0.001" solref="0.001 1" density="100" friction="0.95 0.3 0.1" class="visual" material="Lid002_material"/>
          <geom class="collision" type="box" pos="-0.00039639 -0.18935283 0.25614926" size="0.12341208010911942 0.07487358152866364 0.0022152543533593416" quat="1.0 0.0 0.0 0.0"/>
        </body>
        <geom class="region" name="reg_main" type="box" pos="-4.999999997368221e-09 -0.00010550000000000836 0.0" size="0.180811985 0.32441009 0.26919903"/>
      </body>
    </body>
  </worldbody>
  <actuator>
    <motor name="Button001_joint_actuator" joint="Button001_joint" gear="0.1"/>
    <!-- <motor name="Container001_Clear_joint_actuator" joint="Container001_Clear_joint" gear="30"/> -->
    <!-- <motor name="Lid001_joint_actuator" joint="Lid001_joint" gear="5"/> -->
    <motor name="Lid002_joint_actuator" joint="Lid002_joint" gear="5"/>
    <motor name="Lid003_joint_actuator" joint="Lid003_joint" gear="10"/>
  </actuator>
</mujoco>
