<?xml version='1.0' encoding='UTF-8'?>
<mujoco model="model">
  <option timestep="0.002" gravity="0.0 0.0 -9.81"/>
  <compiler angle="radian"/>
  <asset>
    <mesh file="visuals/freezer_door.obj" name="freezer_door_vis"/>
    <mesh file="visuals/freezer_drawer0.obj" name="freezer_drawer0_vis"/>
    <mesh file="visuals/freezer_drawer1.obj" name="freezer_drawer1_vis"/>
    <mesh file="visuals/fridge_door.obj" name="fridge_door_vis"/>
    <mesh file="visuals/fridge_door_Clear.obj" name="fridge_door_Clear_vis"/>
    <mesh file="visuals/Body001.obj" name="Body001_vis"/>
    <mesh file="visuals/Body001_Clear.obj" name="Body001_Clear_vis"/>
    <texture file="visuals/T_BC001.png" name="Body001_material" type="2d"/>
    <material name="Body001_material" rgba="1 1 1 1.0" texture="Body001_material" shininess="0.4472135901451111" specular="1"/>
    <texture file="visuals/T_BC001.png" name="freezer_door_material" type="2d"/>
    <material name="freezer_door_material" rgba="1 1 1 1.0" texture="freezer_door_material" shininess="0.4472135901451111" specular="1"/>
    <texture file="visuals/T_BC001.png" name="freezer_drawer0_material" type="2d"/>
    <material name="freezer_drawer0_material" rgba="1 1 1 1.0" texture="freezer_drawer0_material" shininess="0.4472135901451111" specular="0.3103448502657381"/>
    <texture file="visuals/T_BC001.png" name="freezer_drawer1_material" type="2d"/>
    <material name="freezer_drawer1_material" rgba="1 1 1 1.0" texture="freezer_drawer1_material" shininess="0.4472135901451111" specular="0.3103448502657381"/>
    <texture file="visuals/T_BC001.png" name="fridge_door_material" type="2d"/>
    <material name="fridge_door_material" rgba="1 1 1 1.0" texture="fridge_door_material" shininess="0.4472135901451111" specular="1"/>
    <material name="fridge_door_Clear_material" rgba="0.828483521938324 0.828483521938324 0.828483521938324 0.699999988079071" shininess="0.39411622285842896" specular="0.3103448502657381"/>
    <material name="Body001_Clear_material" rgba="0.828483521938324 0.828483521938324 0.828483521938324 0.699999988079071" shininess="0.39411622285842896" specular="0.3103448502657381"/>
  </asset>
  <default>
    <default class="visual">
      <geom conaffinity="0" contype="0" group="1" type="mesh"/>
    </default>
    <default class="collision">
      <geom group="0" rgba="0.5 0 0 0.5"/>
    </default>
    <default class="spawn">
      <geom group="0" rgba="1 1 1 0.5" contype="0" conaffinity="0"/>
      <site group="0" rgba="1 1 1 0.5"/>
    </default>
    <default class="region">
      <geom group="1" conaffinity="0" contype="0" rgba="0 1 0 0"/>
    </default>
  </default>
  <worldbody>
    <body>
      <body name="object">
        <geom mesh="Body001_vis" type="mesh" solimp="0.998 0.998 0.001" solref="0.001 1" friction="0.95 0.3 0.1" class="visual" material="Body001_material"/>
        <geom class="collision" type="box" pos="0.26825335 0.14537452 0.52756329" size="0.1583569496870041 0.20739924907684326 0.006352466065436602" quat="1.0 0.0 0.0 0.0"/>
        <geom class="collision" type="box" pos="0.26825335 0.14539319 0.19879727" size="0.1583569496870041 0.20741790533065796 0.0060075754299759865" quat="1.0 0.0 0.0 0.0"/>
        <geom class="collision" type="box" pos="0.00000007 0.07124696 0.87991293" size="0.4594999849796295 0.3646564185619354 0.015579096972942352" quat="1.0 0.0 0.0 0.0"/>
        <geom class="collision" type="box" pos="0.07109994 0.07065879 -0.00725337" size="0.0370812825858593 0.3652450144290924 0.8882202506065369" quat="1.0 0.0 0.0 0.0"/>
        <geom class="collision" type="box" pos="-0.00006200 0.04101218 -0.89549206" size="0.4595121145248413 0.33518141508102417 4.427561606235031e-08" quat="1.0 0.0 0.0 0.0"/>
        <geom class="collision" type="box" pos="0.00000001 0.07086730 -0.87782948" size="0.4595000743865967 0.3650367856025696 0.017662016674876213" quat="1.0 0.0 0.0 0.0"/>
        <geom class="collision" type="box" pos="0.44421988 0.07081735 -0.00725732" size="0.015280088409781456 0.3650869131088257 0.8882173895835876" quat="1.0 0.0 0.0 0.0"/>
        <geom class="collision" type="box" pos="0.41765266 0.14903526 0.18643174" size="0.009552940726280212 0.2150000035762787 0.005428791046142578" quat="1.0 0.0 0.0 0.0"/>
        <geom class="collision" type="box" pos="0.41764389 0.13348802 -0.18507709" size="0.009552940726280212 0.19945275783538818 0.005428791046142578" quat="1.0 0.0 0.0 0.0"/>
        <geom class="collision" type="box" pos="0.41764389 0.14903526 -0.35634099" size="0.009552940726280212 0.2150000035762787 0.005428791046142578" quat="1.0 0.0 0.0 0.0"/>
        <geom class="collision" type="box" pos="0.41760706 0.14383061 0.51368310" size="0.009552940726280212 0.20979535579681396 0.005428791046142578" quat="1.0 0.0 0.0 0.0"/>
        <geom class="collision" type="box" pos="0.36396884 0.13381525 -0.62773155" size="0.07021956145763397 0.19978000223636627 0.0053086490370333195" quat="1.0 0.0 0.0 0.0"/>
        <geom class="collision" type="box" pos="0.17792134 0.13329500 -0.62773155" size="0.06877085566520691 0.19925974309444427 0.005308619234710932" quat="1.0 0.0 0.0 0.0"/>
        <geom class="collision" type="box" pos="0.11870343 0.14903526 -0.35634099" size="0.009552940726280212 0.2150000035762787 0.005428791046142578" quat="1.0 0.0 0.0 0.0"/>
        <geom class="collision" type="box" pos="0.11866656 0.14403078 0.51368310" size="0.009552940726280212 0.20999552309513092 0.005428791046142578" quat="1.0 0.0 0.0 0.0"/>
        <geom class="collision" type="box" pos="0.11870343 0.13348802 -0.18507709" size="0.009552940726280212 0.19945275783538818 0.005428791046142578" quat="1.0 0.0 0.0 0.0"/>
        <geom class="collision" type="box" pos="-0.44612671 0.07081803 -0.00725861" size="0.01337326318025589 0.36508822441101074 0.8882200121879578" quat="1.0 0.0 0.0 0.0"/>
        <geom class="collision" type="box" pos="0.11871216 0.14903526 0.18643174" size="0.009552940726280212 0.2150000035762787 0.005428791046142578" quat="1.0 0.0 0.0 0.0"/>
        <geom class="collision" type="box" pos="0.02331202 0.14903526 0.18643174" size="0.009552940726280212 0.2150000035762787 0.005428791046142578" quat="1.0 0.0 0.0 0.0"/>
        <geom class="collision" type="box" pos="0.02331202 0.13348802 -0.18507709" size="0.009552940726280212 0.19945275783538818 0.005428791046142578" quat="1.0 0.0 0.0 0.0"/>
        <geom class="collision" type="box" pos="0.02331202 0.14903526 -0.54353784" size="0.009552940726280212 0.2150000035762787 0.005428791046142578" quat="1.0 0.0 0.0 0.0"/>
        <geom class="collision" type="box" pos="0.02331202 0.13362147 0.50757326" size="0.009552940726280212 0.19958621263504028 0.005428791046142578" quat="1.0 0.0 0.0 0.0"/>
        <geom class="collision" type="box" pos="-0.42616762 0.14903526 -0.54353784" size="0.009552940726280212 0.2150000035762787 0.005428791046142578" quat="1.0 0.0 0.0 0.0"/>
        <geom class="collision" type="box" pos="-0.42616762 0.13348802 -0.18507709" size="0.009552940726280212 0.19945275783538818 0.005428791046142578" quat="1.0 0.0 0.0 0.0"/>
        <geom class="collision" type="box" pos="-0.42616762 0.13346578 0.18643174" size="0.009552940726280212 0.19943052530288696 0.005428791046142578" quat="1.0 0.0 0.0 0.0"/>
        <geom class="collision" type="box" pos="-0.42616762 0.13335458 0.50757326" size="0.009552940726280212 0.19931933283805847 0.005428791046142578" quat="1.0 0.0 0.0 0.0"/>
        <geom class="collision" type="box" pos="0.26825335 0.14557469 -0.17093336" size="0.1583569496870041 0.20759940147399902 0.006224427837878466" quat="1.0 0.0 0.0 0.0"/>
        <geom class="collision" type="box" pos="-0.00002492 0.42431526 0.00000019" size="0.45947501063346863 0.011597595177590847 0.8954831957817078" quat="1.0 0.0 0.0 0.0"/>
        <geom class="collision" type="box" pos="-0.20152099 0.14501499 -0.52559729" size="0.23340408504009247 0.20751787722110748 0.006699406076222658" quat="1.0 0.0 0.0 0.0"/>
        <geom class="collision" type="box" pos="-0.20152099 0.14478651 -0.17385027" size="0.23340408504009247 0.2072894126176834 0.006051766686141491" quat="1.0 0.0 0.0 0.0"/>
        <geom class="collision" type="box" pos="-0.20152099 0.14020018 0.20170614" size="0.23340408504009247 0.21236062049865723 0.0060075754299759865" quat="1.0 0.0 0.0 0.0"/>
        <geom class="collision" type="box" pos="-0.20144091 0.14492050 0.51914246" size="0.23340408504009247 0.20735614001750946 0.0067987944930791855" quat="1.0 0.0 0.0 0.0"/>
        <body name="freezer_door">
          <joint axis="0.0 0.0 1.0" pos="0.43604301 -0.32064514 -0.00846946" limited="true" name="freezer_door_joint" range="0.0 1.5707963267948966" type="hinge" damping="1" frictionloss="1" armature=".01" stiffness="0.05"/>
          <geom mesh="freezer_door_vis" type="mesh" solimp="0.998 0.998 0.001" solref="0.001 1" friction="0.95 0.3 0.1" class="visual" material="freezer_door_material"/>
          <geom class="collision" type="box" pos="0.24010653 -0.32957272 0.00111090" size="0.18864116072654724 0.013158445246517658 0.8892094492912292" quat="1.0 0.0 0.0 0.0"/>
          <geom class="collision" type="box" pos="0.26302867 -0.29267449 0.01537086" size="0.1313161700963974 0.03054771199822426 0.14166441559791565" quat="1.0 0.0 0.0 0.0"/>
          <geom class="collision" type="box" pos="0.08608573 -0.39085899 0.56080683" size="0.01786511205136776 0.04676021635532379 0.018915072083473206" quat="1.0 0.0 0.0 0.0" name="freezer_door_handle_1"/>
          <geom class="collision" type="box" pos="0.08608573 -0.39085899 -0.25131604" size="0.017865093424916267 0.046760112047195435 0.01828717440366745" quat="1.0 0.0 0.0 0.0" name="freezer_door_handle_2"/>
          <geom class="collision" type="cylinder" pos="0.08602540 -0.41952784 0.15553725" size="0.012440330348908901 0.38117796182632446" quat="1.0 0.0 0.0 0.0" name="freezer_door_handle_main"/>
          <geom class="collision" type="box" pos="0.24010653 -0.33828120 0.00111090" size="0.18864288926124573 0.00485289515927434 0.8892166614532471" quat="1.0 0.0 0.0 0.0" name="freezer_door_main"/>
        </body>
        <body name="freezer_drawer0">
          <geom class="region" name="reg_freezer_drawer0" type="box" pos="0.26956082 0.13843671000000002 -0.74334265" size="0.12860301000000002 0.2131848 0.09834752999999996"/>
          <joint axis="0.0 -1.0 0.0" pos="0.26945110 0.13625695 -0.74895279" limited="true" name="freezer_drawer0_joint" range="0.0 0.5" type="slide" damping="1" frictionloss="1" armature=".01" stiffness="0.05"/>
          <geom mesh="freezer_drawer0_vis" type="mesh" solimp="0.998 0.998 0.001" solref="0.001 1" friction="0.95 0.3 0.1" class="visual" material="freezer_drawer0_material"/>
          <geom class="collision" type="box" pos="0.27078249 0.36264073 -0.74901150" size="0.14156587421894073 0.0038112641777843237 0.10914629697799683" quat="1.0 0.0 0.0 0.0"/>
          <geom class="collision" type="box" pos="0.26935704 0.13915091 -0.85549854" size="0.14185942709445953 0.22618547081947327 0.00454176077619195" quat="1.0 0.0 0.0 0.0"/>
          <geom class="collision" type="box" pos="0.40815057 0.13924611 -0.74815719" size="0.0036365410778671503 0.2263440638780594 0.1100011095404625" quat="1.0 0.0 0.0 0.0"/>
          <geom class="collision" type="box" pos="0.13074421 0.13981360 -0.74815719" size="0.0036440046969801188 0.22643408179283142 0.11000137031078339" quat="1.0 0.0 0.0 0.0"/>
          <geom class="collision" type="box" pos="0.27033709 -0.09083720 -0.64539234" size="0.14112193882465363 0.004123501013964415 0.00723676010966301" quat="1.0 0.0 0.0 0.0"/>
          <geom class="collision" type="box" pos="0.26945033 -0.09019924 -0.78297077" size="0.14173756539821625 0.003485538298264146 0.07706958055496216" quat="1.0 0.0 0.0 0.0"/>
          <geom class="collision" type="box" pos="0.15476370 -0.09019923 -0.67473970" size="0.027409683912992477 0.0034855457488447428 0.034046825021505356" quat="1.0 0.0 0.0 0.0"/>
          <geom class="collision" type="box" pos="0.38628276 -0.09019925 -0.67473970" size="0.025263600051403046 0.003485530847683549 0.034046825021505356" quat="1.0 0.0 0.0 0.0"/>
        </body>
        <body name="freezer_drawer1">
          <geom class="region" name="reg_freezer_drawer1" type="box" pos="0.26937585999999997 0.135118445 -0.50436287" size="0.12817031 0.213940455 0.10610396999999996"/>
          <joint axis="0.0 -1.0 0.0" pos="0.26860328 0.13625695 -0.50678612" limited="true" name="freezer_drawer1_joint" range="0.0 0.5" type="slide" damping="1" frictionloss="1" armature=".01" stiffness="0.05"/>
          <geom mesh="freezer_drawer1_vis" type="mesh" solimp="0.998 0.998 0.001" solref="0.001 1" friction="0.95 0.3 0.1" class="visual" material="freezer_drawer1_material"/>
          <geom class="collision" type="box" pos="0.38432365 -0.09019925 -0.42900471" size="0.026479121297597885 0.003485530847683549 0.034046825021505356" quat="1.0 0.0 0.0 0.0"/>
          <geom class="collision" type="box" pos="0.15251960 -0.09019925 -0.42900471" size="0.026479121297597885 0.003485523397102952 0.034046825021505356" quat="1.0 0.0 0.0 0.0"/>
          <geom class="collision" type="box" pos="0.26897948 -0.09019924 -0.54096000" size="0.1429389864206314 0.003485538298264146 0.08079381287097931" quat="1.0 0.0 0.0 0.0"/>
          <geom class="collision" type="box" pos="0.26897948 -0.09024924 -0.39965735" size="0.1429389864206314 0.003535526804625988 0.00723676010966301" quat="1.0 0.0 0.0 0.0"/>
          <geom class="collision" type="box" pos="0.12980260 0.13439973 -0.50568183" size="0.0037377718836069107 0.22153130173683167 0.11326095461845398" quat="1.0 0.0 0.0 0.0"/>
          <geom class="collision" type="box" pos="0.40746601 0.13456654 -0.50568183" size="0.003799821948632598 0.2216975837945938 0.11326070129871368" quat="1.0 0.0 0.0 0.0"/>
          <geom class="collision" type="box" pos="0.26782518 0.13200654 -0.61886702" size="0.14122454822063446 0.22387142479419708 0.0028868159279227257" quat="1.0 0.0 0.0 0.0"/>
          <geom class="collision" type="box" pos="0.26866781 0.36154981 -0.50794203" size="0.14216706156730652 0.004973985254764557 0.11381178349256516" quat="1.0 0.0 0.0 0.0"/>
        </body>
        <body name="fridge_door">
          <joint axis="0.0 0.0 -1.0" pos="-0.43586005 -0.32113854 -0.00847244" limited="true" name="fridge_door_joint" range="0.0 1.5707963267948966" type="hinge" damping="1" frictionloss="1" armature=".01" stiffness="0.05"/>
          <geom mesh="fridge_door_vis" type="mesh" solimp="0.998 0.998 0.001" solref="0.001 1" friction="0.95 0.3 0.1" class="visual" material="fridge_door_material"/>
          <geom class="collision" type="box" pos="-0.20974664 -0.30843122 0.50262059" size="0.2195487767457962 0.0032243402674794197 0.03886110335588455" quat="1.0 0.0 0.0 0.0"/>
          <geom class="collision" type="box" pos="-0.42423118 -0.25745536 0.50262059" size="0.005122859496623278 0.054292209446430206 0.038861196488142014" quat="1.0 0.0 0.0 0.0"/>
          <geom class="collision" type="box" pos="-0.20974664 -0.20637764 0.50262059" size="0.21955111622810364 0.003224362852051854 0.038861289620399475" quat="1.0 0.0 0.0 0.0"/>
          <geom class="collision" type="box" pos="0.00579786 -0.25745536 0.50262059" size="0.005122896283864975 0.05429258570075035 0.03886138275265694" quat="1.0 0.0 0.0 0.0"/>
          <geom class="collision" type="box" pos="-0.20915149 -0.25745536 0.46719284" size="0.22007636725902557 0.054292768239974976 0.0034381297882646322" quat="1.0 0.0 0.0 0.0"/>
          <geom class="collision" type="box" pos="-0.20915149 -0.25745542 -0.14123751" size="0.220078244805336 0.054293155670166016 0.0034381533041596413" quat="1.0 0.0 0.0 0.0"/>
          <geom class="collision" type="box" pos="0.00579786 -0.25745536 -0.10580981" size="0.005122962407767773 0.05429333820939064 0.03886175900697708" quat="1.0 0.0 0.0 0.0"/>
          <geom class="collision" type="box" pos="-0.20974664 -0.20637764 -0.10580981" size="0.21955770254135132 0.0032244313042610884 0.03886185213923454" quat="1.0 0.0 0.0 0.0"/>
          <geom class="collision" type="box" pos="-0.42423118 -0.25745536 -0.10580981" size="0.00512299919500947 0.054293710738420486 0.038861945271492004" quat="1.0 0.0 0.0 0.0"/>
          <geom class="collision" type="box" pos="-0.20060719 -0.33293010 0.00164314" size="0.24239735305309296 0.01077963039278984 0.8894217014312744" quat="1.0 0.0 0.0 0.0"/>
          <geom class="collision" type="box" pos="0.01148505 -0.38893629 0.56124719" size="0.017865315079689026 0.0467604361474514 0.01799345202744007" quat="1.0 0.0 0.0 0.0" name="fridge_door_handle_1"/>
          <geom class="collision" type="box" pos="0.01148505 -0.38893629 -0.25074519" size="0.017865294590592384 0.046760331839323044 0.017993396148085594" quat="1.0 0.0 0.0 0.0" name="fridge_door_handle_2"/>
          <geom class="collision" type="cylinder" pos="0.01142473 -0.41760514 0.15640198" size="0.012440330348908901 0.38117796182632446" quat="1.0 0.0 0.0 0.0" name="fridge_door_handle_main"/>
          <geom class="collision" type="box" pos="-0.20060719 -0.33856980 0.00164314" size="0.24239735305309296 0.005140047054737806 0.8894217014312744" quat="1.0 0.0 0.0 0.0" name="fridge_door_main"/>
          <body name="fridge_door_Clear">
            <geom mesh="fridge_door_Clear_vis" type="mesh" solimp="0.998 0.998 0.001" solref="0.001 1" friction="0.95 0.3 0.1" class="visual" material="fridge_door_Clear_material"/>
            <geom class="collision" type="box" pos="-0.20974664 -0.30843122 0.50262059" size="0.2195487767457962 0.0032243402674794197 0.03886110335588455" quat="1.0 0.0 0.0 0.0"/>
            <geom class="collision" type="box" pos="-0.42423118 -0.25745536 0.50262059" size="0.005122859496623278 0.054292209446430206 0.038861196488142014" quat="1.0 0.0 0.0 0.0"/>
            <geom class="collision" type="box" pos="-0.20974664 -0.20637764 0.50262059" size="0.21955111622810364 0.003224362852051854 0.038861289620399475" quat="1.0 0.0 0.0 0.0"/>
            <geom class="collision" type="box" pos="0.00579786 -0.25745536 0.50262059" size="0.005122896283864975 0.05429258570075035 0.03886138275265694" quat="1.0 0.0 0.0 0.0"/>
            <geom class="collision" type="box" pos="-0.20915149 -0.25745536 0.46719284" size="0.22007636725902557 0.054292768239974976 0.0034381297882646322" quat="1.0 0.0 0.0 0.0"/>
            <geom class="collision" type="box" pos="-0.20915149 -0.25745542 -0.14123751" size="0.220078244805336 0.054293155670166016 0.0034381533041596413" quat="1.0 0.0 0.0 0.0"/>
            <geom class="collision" type="box" pos="0.00579786 -0.25745536 -0.10580981" size="0.005122962407767773 0.05429333820939064 0.03886175900697708" quat="1.0 0.0 0.0 0.0"/>
            <geom class="collision" type="box" pos="-0.20974664 -0.20637764 -0.10580981" size="0.21955770254135132 0.0032244313042610884 0.03886185213923454" quat="1.0 0.0 0.0 0.0"/>
            <geom class="collision" type="box" pos="-0.42423118 -0.25745536 -0.10580981" size="0.00512299919500947 0.054293710738420486 0.038861945271492004" quat="1.0 0.0 0.0 0.0"/>
          </body>
        </body>
        <body name="Body001_Clear">
          <geom mesh="Body001_Clear_vis" type="mesh" solimp="0.998 0.998 0.001" solref="0.001 1" friction="0.95 0.3 0.1" class="visual" material="Body001_Clear_material"/>
          <geom class="collision" type="box" pos="-0.20152099 0.14501499 -0.52559729" size="0.23340408504009247 0.20751787722110748 0.006699406076222658" quat="1.0 0.0 0.0 0.0"/>
          <geom class="collision" type="box" pos="-0.20152099 0.14478651 -0.17385027" size="0.23340408504009247 0.2072894126176834 0.006051766686141491" quat="1.0 0.0 0.0 0.0"/>
          <geom class="collision" type="box" pos="-0.20152099 0.14020018 0.20170614" size="0.23340408504009247 0.21236062049865723 0.0060075754299759865" quat="1.0 0.0 0.0 0.0"/>
          <geom class="collision" type="box" pos="-0.20144091 0.14492050 0.51914246" size="0.23340408504009247 0.20735614001750946 0.0067987944930791855" quat="1.0 0.0 0.0 0.0"/>
        </body>
        <geom class="region" name="reg_fridge_shelf4" type="box" pos="-0.20017965499999998 0.146582115 0.691873985" size="0.222729125 0.194320545 0.158904145"/>
        <geom class="region" name="reg_fridge_shelf3" type="box" pos="-0.199908435 0.14701219000000001 0.35333592999999996" size="0.224583735 0.19498636 0.13842596"/>
        <geom class="region" name="reg_fridge_shelf2" type="box" pos="-0.20092761499999998 0.147064035 0.005933735000000009" size="0.224197915 0.192779265 0.164783625"/>
        <geom class="region" name="reg_fridge_shelf1" type="box" pos="-0.19970886000000002 0.14598032000000002 -0.35382278" size="0.22531111 0.19378913 0.15612216"/>
        <geom class="region" name="reg_fridge_shelf0" type="box" pos="-0.19931853000000002 0.168344105 -0.704547155" size="0.22543757 0.226198555 0.148404135"/>
        <geom class="region" name="reg_freezer_shelf2" type="box" pos="0.27106536000000003 0.14650687 0.695220215" size="0.15028694 0.1943242 0.154725775"/>
        <geom class="region" name="reg_freezer_shelf1" type="box" pos="0.26896889 0.145336075 0.354961545" size="0.15012219 0.196847965 0.144518435"/>
        <geom class="region" name="reg_freezer_shelf0" type="box" pos="0.268541275 0.14423136 0.007109304999999996" size="0.149694565 0.19574325 0.16567874500000002"/>
        <geom class="region" name="reg_main" type="box" pos="1.0500000000024379e-07 0.04609457 3.4500000001269626e-07" size="0.46049995499999996 0.39080442 0.896492375"/>
      </body>
    </body>
  </worldbody>
  <actuator>
    <motor name="freezer_door_joint_actuator" joint="freezer_door_joint" gear="50"/>
    <motor name="freezer_drawer0_joint_actuator" joint="freezer_drawer0_joint" gear="50"/>
    <motor name="freezer_drawer1_joint_actuator" joint="freezer_drawer1_joint" gear="50"/>
    <motor name="fridge_door_joint_actuator" joint="fridge_door_joint" gear="50"/>
  </actuator>
</mujoco>
