<?xml version='1.0' encoding='UTF-8'?>
<mujoco model="model">
  <option timestep="0.002" gravity="0.0 0.0 -9.81"/>
  <compiler angle="radian"/>
  <asset>
    <mesh file="visuals/handle.obj" name="handle_vis"/>
    <mesh file="visuals/Body001.obj" name="Body001_vis"/>
    <mesh file="visuals/spout.obj" name="spout_vis"/>
    <texture file="visuals/T_BC001.png" name="Body001_material" type="2d"/>
    <material name="Body001_material" rgba="1 1 1 1.0" texture="Body001_material" shininess="0.2" specular="0.3"/>
    <texture file="visuals/T_BC001.png" name="handle_material" type="2d"/>
    <material name="handle_material" rgba="1 1 1 1.0" texture="handle_material" shininess="0.5" specular="0.8"/>
    <texture file="visuals/T_BC001.png" name="spout_material" type="2d"/>
    <material name="spout_material" rgba="1 1 1 1.0" texture="spout_material" shininess="0.5" specular="0.8"/>
  </asset>
  <default>
    <default class="visual">
      <geom conaffinity="0" contype="0" group="1" type="mesh"/>
    </default>
    <default class="collision">
      <geom group="0" rgba="0.5 0 0 0.5" solimp="0.998 0.998 0.001" solref="0.001 2"/>
    </default>
    <default class="spawn">
      <geom group="0" rgba="1 1 1 0.5" contype="0" conaffinity="0"/>
      <site group="0" rgba="1 1 1 0.5"/>
    </default>
    <default class="region">
      <geom group="1" conaffinity="0" contype="0" rgba="0 1 0 0"/>
    </default>
  </default>
  <worldbody>
    <body>
      <body name="object">
        <geom mesh="Body001_vis" type="mesh" solimp="0.998 0.998 0.001" solref="0.001 1" friction="0.95 0.3 0.1" class="visual" material="Body001_material"/>
        <geom class="collision" type="box" pos="0.0 0.21197830140590668 -0.15333899855613708" size="0.28999999165534973 0.0379241518676281 0.12788496911525726" quat="1.0 0.0 0.0 0.0"/>
        <geom class="collision" type="box" pos="-0.27640557289123535 -3.521563485264778e-09 -0.15333907306194305" size="0.013594459742307663 0.24990248680114746 0.12788505852222443" quat="1.0 0.0 0.0 0.0"/>
        <geom class="collision" type="box" pos="-0.007811218500137329 -0.005923365242779255 -0.2481245994567871" size="0.28218886256217957 0.24397926032543182 0.03309953957796097" quat="1.0 0.0 0.0 0.0"/>
        <geom class="collision" type="box" pos="0.27690646052360535 7.9016899690032e-09 -0.1533389687538147" size="0.013093541376292706 0.24990244209766388 0.12788502871990204" quat="1.0 0.0 0.0 0.0"/>
        <geom class="collision" type="box" pos="-2.2817403078079224e-08 -0.23811925947666168 -0.15333914756774902" size="0.28999999165534973 0.011783124879002571 0.127885103225708" quat="1.0 0.0 0.0 0.0"/>
        <geom class="collision" type="cylinder" pos="-0.008521336130797863 0.22017937898635864 0.003657592460513115" size="0.016683461144566536 0.02757469192147255" quat="0.7071068286895752 0.0 0.0 0.7071067690849304"/>
        <geom class="collision" type="cylinder" pos="0.004015771672129631 0.2198953628540039 0.009904640726745129" size="0.012313892133533955 0.013861095532774925" quat="0.49999722838401794 0.5000000596046448 0.5000027418136597 0.4999999403953552"/>
        <body name="handle">
          <joint axis="1.0 0.0 0.0" pos="0.026260405778884888 0.21996662020683289 0.010362421162426472" limited="true" name="handle_temp_joint" type="hinge" range="-0.7853981633974483 0.7853981633974483" damping="0.5" frictionloss="1" armature="2"/>
          <joint axis="0.0 1.0 0.0" pos="0.026260405778884888 0.21996662020683289 0.010362421162426472" limited="true" name="handle_joint" type="hinge" range="0 0.5" damping="0.5" frictionloss="1" armature="2"/>
          <geom mesh="handle_vis" type="mesh" solimp="0.998 0.998 0.001" solref="0.001 1" friction="0.95 0.3 0.1" class="visual" material="handle_material"/>
          <geom name="handle_main" class="collision" type="cylinder" pos="0.03340592980384827 0.21956302225589752 0.05337700992822647" size="0.0040099951438605785 0.030342772603034973" quat="0.7071068286895752 0.0 0.0 0.7071067690849304"/>
          <geom class="collision" type="cylinder" pos="0.03601875528693199 0.2199769765138626 0.00971183367073536" size="0.014395428821444511 0.0036695136222988367" quat="0.49999722838401794 0.5000000596046448 0.5000027418136597 0.4999999403953552"/>
        </body>
        <body name="spout">
          <joint axis="0.0 0.0 1.0" pos="-0.008934499695897102 0.21987931430339813 0.15196599066257477" limited="true" name="spout_joint" range="-1.0471975511965976 1.0471975511965976" type="hinge" damping="10"/>
          <site type="cylinder" rgba="0.5 0.75 1 0.5" size="0.006065879482775927 0.2152324616909027" pos="-0.009099733084440231 0.027332251891493797 -0.03505042940378189" name="water"/>
          <geom mesh="spout_vis" type="mesh" solimp="0.998 0.998 0.001" solref="0.001 1" friction="0.95 0.3 0.1" class="visual" material="spout_material"/>
          <geom class="collision" type="cylinder" pos="-0.00886296946555376 0.21938465535640717 0.11024174839258194" size="0.010048693045973778 0.0785842090845108" quat="1.0 0.0 0.0 0.0" name="spout_main"/>
          <geom class="collision" type="cylinder" pos="-0.00886296946555376 0.20319879055023193 0.22848886251449585" size="0.010048693045973778 0.017451457679271698" quat="0.9656886458396912 0.25970259308815 5.766556629770934e-17 -1.7851537715460202e-24"/>
          <geom class="collision" type="cylinder" pos="-0.00886296946555376 0.18345436453819275 0.25120916962623596" size="0.010048693045973778 0.019898122176527977" quat="0.8884070515632629 0.459056556224823 1.0193105151752095e-16 1.3295278680864922e-23"/>
          <geom class="collision" type="cylinder" pos="-0.00886296946555376 0.14356428384780884 0.2693922221660614" size="0.010048693045973778 0.020374983549118042" quat="0.7983346581459045 0.6022140383720398 1.3371837823062722e-16 1.0411496667633645e-23"/>
          <geom class="collision" type="cylinder" pos="-0.00886296946555376 0.09494275599718094 0.26721125841140747" size="0.010048693045973778 0.018348298966884613" quat="0.5963873863220215 0.8026967644691467 1.782344991760424e-16 -4.541982032717364e-25"/>
          <geom class="collision" type="cylinder" pos="-0.00886296946555376 0.05173811689019203 0.23765726387500763" size="0.010048693045973778 0.017533086240291595" quat="0.33013781905174255 0.9439327120780945 2.0959697930909653e-16 9.331002089905839e-23"/>
          <geom class="collision" type="cylinder" pos="-0.00886296946555376 0.03132658079266548 0.19109773635864258" size="0.010048693045973778 0.023006346076726913" quat="0.10297983139753342 0.9946834444999695 2.2086407922457523e-16 2.1929968316975463e-24"/>
          <geom class="collision" type="cylinder" pos="-0.00886296946555376 0.0715356096625328 0.2561853229999542" size="0.010048693045973778 0.018348298966884613" quat="0.4717880189418793 0.881712019443512 1.9577941024987594e-16 2.2470153838030487e-23"/>
          <geom class="collision" type="cylinder" pos="-0.00886296946555376 0.037656936794519424 0.2161986231803894" size="0.010048693045973778 0.017533086240291595" quat="0.1843382567167282 0.9828628897666931 2.1823940205371997e-16 2.4115640377952806e-23"/>
          <geom class="collision" type="cylinder" pos="-0.00886296946555376 0.12046951055526733 0.27161917090415955" size="0.010048693045973778 0.020374981686472893" quat="0.7158699631690979 0.6982336044311523 1.550390048412958e-16 -7.198455945476696e-24"/>
          <geom class="collision" type="cylinder" pos="-0.00886296946555376 0.1646672785282135 0.2623564898967743" size="0.010048693045973778 0.019898122176527977" quat="0.8523038625717163 0.5230469703674316 1.1613975789247092e-16 1.8351938614482215e-23"/>
          <geom class="collision" type="cylinder" pos="-0.00886296946555376 0.21559345722198486 0.20255321264266968" size="0.010048693045973778 0.017451457679271698" quat="0.9905076622962952 0.13745738565921783 3.052168081889604e-17 -1.780933119184055e-25"/>
        </body>
        <geom class="region" name="reg_basin" type="box" pos="0.000559389591217041 -0.024840429425239563 -0.12024475447833538" size="0.25643034076690674 0.19348773157596588 0.09030480666458607"/>
        <geom class="region" name="reg_main" type="box" pos="-7.450580596923828e-09 -1.4901161193847656e-08 -0.15333902835845947" size="0.29099999165534973 0.25090250170230866 0.12888501381874085"/>
      </body>
    </body>
  </worldbody>
  <actuator>
    <motor name="handle_joint_actuator" joint="handle_joint" gear="10"/>
    <motor name="handle_temp_joint_actuator" joint="handle_temp_joint" gear="10"/>
    <motor name="spout_joint_actuator" joint="spout_joint" gear="10"/>
  </actuator>
</mujoco>
