<?xml version='1.0' encoding='UTF-8'?>
<mujoco model="model">
  <option timestep="0.002" gravity="0.0 0.0 -9.81"/>
  <compiler angle="radian"/>
  <asset>
    <mesh file="visuals/handle.obj" name="handle_vis"/>
    <mesh file="visuals/Body001.obj" name="Body001_vis"/>
    <mesh file="visuals/Funnel001.obj" name="Funnel001_vis"/>
    <mesh file="visuals/spout.obj" name="spout_vis"/>
    <texture file="visuals/T_BC001.png" name="Body001_material" type="2d"/>
    <material name="Body001_material" rgba="1 1 1 1.0" texture="Body001_material" shininess="0.1" specular="5"/>
    <texture file="visuals/T_BC001.png" name="handle_material" type="2d"/>
    <material name="handle_material" rgba="1 1 1 1.0" texture="handle_material" shininess="0.1" specular="5"/>
    <texture file="visuals/T_BC001.png" name="Funnel001_material" type="2d"/>
    <material name="Funnel001_material" rgba="1 1 1 1.0" texture="Funnel001_material" shininess="0.1" specular="5"/>
    <texture file="visuals/T_BC001.png" name="spout_material" type="2d"/>
    <material name="spout_material" rgba="1 1 1 1.0" texture="spout_material" shininess="0.1" specular="5"/>
  </asset>
  <default>
    <default class="visual">
      <geom conaffinity="0" contype="0" group="1" type="mesh"/>
    </default>
    <default class="collision">
      <geom group="0" rgba="0.5 0 0 0.5"/>
    </default>
    <default class="spawn">
      <geom group="0" rgba="1 1 1 0.5" contype="0" conaffinity="0"/>
      <site group="0" rgba="1 1 1 0.5"/>
    </default>
    <default class="region">
      <geom group="1" conaffinity="0" contype="0" rgba="0 1 0 0"/>
    </default>
  </default>
  <worldbody>
    <body>
      <body name="object">
        <geom mesh="Body001_vis" type="mesh" solimp="0.998 0.998 0.001" solref="0.001 1" friction="0.95 0.3 0.1" class="visual" material="Body001_material"/>
        <geom class="collision" type="box" pos="-0.23326551 -0.02170394 -0.02609063" size="0.019691692665219307 0.18195466697216034 0.004977830220013857" quat="1.0 0.0 0.0 0.0"/>
        <geom class="collision" type="box" pos="0.17659145 0.13603707 -0.08852666" size="0.01873820275068283 0.004184445831924677 0.06828301399946213" quat="0.9469715356826782 -0.0522906668484211 0.017479630187153816 -0.3165518045425415"/>
        <geom class="collision" type="box" pos="0.20680367 0.14562433 -0.02609066" size="0.031084969639778137 0.01889955997467041 0.0049778735265135765" quat="1.810242054034461e-07 -0.3682537376880646 -0.9297253489494324 -7.17016561679884e-08"/>
        <geom class="collision" type="box" pos="0.23289556 -0.02170394 -0.02609064" size="0.019691715016961098 0.18195484578609467 0.004977833479642868" quat="1.0 0.0 0.0 0.0"/>
        <geom class="collision" type="box" pos="-0.00054685 0.19522588 -0.02609064" size="0.2524089217185974 0.04307527840137482 0.004977836739271879" quat="1.0 0.0 0.0 0.0"/>
        <geom class="collision" type="box" pos="-0.00143667 0.14400281 -0.08852666" size="0.16310478746891022 0.004184445831924677 0.06828301399946213" quat="0.9984789490699768 -0.05513473600149155 0.0 0.0"/>
        <geom class="collision" type="box" pos="0.20016033 0.10974322 -0.08847781" size="0.01873820833861828 0.004184445831924677 0.06823503226041794" quat="0.8756998181343079 -0.04835504665970802 0.02648831345140934 -0.4796978235244751"/>
        <geom class="collision" type="box" pos="0.20516958 -0.02719934 -0.08852666" size="0.1264975368976593 0.004184448625892401 0.06828301399946213" quat="0.7060312628746033 -0.03898615017533302 0.038986146450042725 -0.7060312032699585"/>
        <geom class="collision" type="box" pos="-0.20512099 -0.02719934 -0.08852666" size="0.1264975368976593 0.004184448625892401 0.06828301399946213" quat="0.038986172527074814 0.7060312628746033 0.7060312032699585 0.038986172527074814"/>
        <geom class="collision" type="box" pos="-0.20011174 0.10974322 -0.08847781" size="0.01873820833861828 0.004184445831924677 0.06823503226041794" quat="0.04835505783557892 0.8756998181343079 0.4796978235244751 0.026488326489925385"/>
        <geom class="collision" type="box" pos="-0.17654284 0.13603707 -0.08852666" size="0.01873820275068283 0.004184445831924677 0.06828301399946213" quat="0.052290596067905426 0.9469715356826782 0.3165518045425415 0.017479605972766876"/>
        <geom class="collision" type="box" pos="-0.17654285 -0.18375493 -0.08852667" size="0.01873820275068283 0.004184445831924677 0.06828300654888153" quat="0.31655192375183105 -0.017479615285992622 -0.0522906519472599 0.9469715356826782"/>
        <geom class="collision" type="box" pos="-0.20011175 -0.15746112 -0.08847781" size="0.01873820275068283 0.004184445831924677 0.06823503226041794" quat="0.4796978831291199 -0.026488324627280235 -0.04835505783557892 0.8756997585296631"/>
        <geom class="collision" type="box" pos="0.20016035 -0.15746112 -0.08847780" size="0.01873820275068283 0.004184445831924677 0.06823503971099854" quat="0.026488494127988815 0.4796978235244751 -0.8756998181343079 -0.048354972153902054"/>
        <geom class="collision" type="box" pos="-0.00143667 -0.19172068 -0.08852663" size="0.16310478746891022 0.004184445831924677 0.06828304380178452" quat="1.944110294971324e-07 -1.0735088373792223e-08 -0.9984789490699768 -0.05513444170355797"/>
        <geom class="collision" type="box" pos="0.17659146 -0.18375492 -0.08852666" size="0.018738223239779472 0.004184445831924677 0.06828301399946213" quat="0.017479773610830307 0.31655168533325195 -0.946971595287323 -0.052290525287389755"/>
        <geom class="collision" type="box" pos="-0.00027545 0.03384300 -0.18732715" size="0.05459703505039215 0.05459703505039215 0.003132421290501952" quat="1.0 0.0 0.0 0.0"/>
        <geom class="collision" type="box" pos="-0.12861209 -0.02488668 -0.15661687" size="0.0735040083527565 0.16078205406665802 0.01009487546980381" quat="1.0 0.0 0.0 0.0"/>
        <geom class="collision" type="box" pos="0.12624610 -0.02488668 -0.15669571" size="0.07350409030914307 0.16078223288059235 0.010016046464443207" quat="1.0 0.0 0.0 0.0"/>
        <geom class="collision" type="box" pos="-0.00440339 -0.10092083 -0.15624744" size="0.07350417971611023 0.08474872261285782 0.01046433299779892" quat="1.0 0.0 0.0 0.0"/>
        <geom class="collision" type="box" pos="-0.00440339 0.11155559 -0.15671648" size="0.0735042616724968 0.024150533601641655 0.009995300322771072" quat="1.0 0.0 0.0 0.0"/>
        <geom class="collision" type="cylinder" pos="-0.01916733 0.19129604 0.00715631" size="0.021768789738416672 0.03878086805343628" quat="1.0 0.0 0.0 0.0"/>
        <geom class="collision" type="cylinder" pos="0.00648358 0.19129604 0.02940734" size="0.017791669815778732 0.017488157376646996" quat="0.7071068286895752 -0.0 0.7071067690849304 0.0"/>
        <geom class="collision" type="box" pos="-0.00054685 -0.21928985 -0.02609065" size="0.252409964799881 0.019011426717042923 0.004977856297045946" quat="1.0 0.0 0.0 0.0"/>
        <geom class="collision" type="box" pos="0.20680369 -0.19438828 -0.02609066" size="0.031084967777132988 0.018899550661444664 0.004977867007255554" quat="0.9297253489494324 0.0 0.0 0.3682537376880646"/>
        <geom class="collision" type="box" pos="-0.20600364 -0.19438828 -0.02609066" size="0.031084967777132988 0.018899550661444664 0.004977870266884565" quat="1.810242054034461e-07 0.9297253489494324 -0.3682537376880646 -7.17016561679884e-08"/>
        <geom class="collision" type="box" pos="-0.20600363 0.14562433 -0.02609066" size="0.031084971502423286 0.018899550661444664 0.004977867007255554" quat="0.3682536780834198 0.0 0.0 -0.9297253489494324"/>
        <body name="handle">
          <joint axis="1.0 0.0 0.0" pos="0.03676817 0.19216751 0.02903756" limited="true" name="handle_temp_joint" type="hinge" range="-0.7853981633974483 0.7853981633974483" damping="1" frictionloss="1" armature=".01"/>
          <joint axis="0.0 1.0 0.0" pos="0.03676817 0.19216751 0.02903756" limited="true" name="handle_joint" type="hinge" range="0 0.5" damping="1" frictionloss="1" armature=".01"/>
          <geom mesh="handle_vis" type="mesh" solimp="0.998 0.998 0.001" solref="0.001 1" friction="0.95 0.3 0.1" class="visual" material="handle_material"/>
          <geom class="collision" type="cylinder" pos="0.04258959 0.19210886 0.02913160" size="0.0174186360090971 0.0069199479185044765" quat="0.7064290046691895 0.0 0.7077838778495789 0.0" density="0.001"/>
          <geom class="collision" type="cylinder" pos="0.04124236 0.19210886 0.06579839" size="0.00414998596534133 0.021215196698904037" quat="0.9999995231628418 0.0 0.0009582710918039083 0.0" density="0.001"/>
        </body>
        <body name="Funnel001">
          <joint axis="0.0 0.0 1.0" pos="-0.00010467 0.03371446 -0.16636202" limited="true" name="Funnel001_joint" range="0.0 0.06" type="slide" damping="0" frictionloss="0" armature="0" stiffness="0"/>
          <geom mesh="Funnel001_vis" type="mesh" solimp="0.998 0.998 0.001" solref="0.001 1" friction="0.95 0.3 0.1" class="visual" material="Funnel001_material"/>
          <geom class="collision" type="cylinder" pos="-0.00010467 0.03371449 -0.16619776" size="0.03388557210564613 0.004320512525737286" quat="1.0 0.0 0.0 0.0"/>
        </body>
        <body name="spout">
          <joint axis="0.0 0.0 1.0" pos="-0.01554897 0.19138819 0.10896765" limited="true" name="spout_joint" range="-0.7853981633974483 0.7853981633974483" type="hinge" damping="1" frictionloss="1" armature=".01" stiffness="0.05"/>
          <site type="cylinder" rgba="0.5 0.75 1 0.5" size="0.007027625571936369 0.167381152510643" pos="-0.01553626 0.01828695 -0.00236525" name="water"/>
          <geom mesh="spout_vis" type="mesh" solimp="0.998 0.998 0.001" solref="0.001 1" friction="0.95 0.3 0.1" class="visual" material="spout_material"/>
          <geom class="collision" type="cylinder" pos="-0.01562401 0.19101101 0.10182855" size="0.01354062557220459 0.053485482931137085" quat="0.9999995231628418 0.0 -0.0009582709753885865 0.0"/>
          <geom class="collision" type="cylinder" pos="-0.01557614 0.17872526 0.17095765" size="0.01354062557220459 0.010568520985543728" quat="0.9064923524856567 0.42222118377685547 -0.0009546542423777282 -8.309984696097672e-05"/>
          <geom class="collision" type="cylinder" pos="-0.01554175 0.19011414 0.15680996" size="0.01354062557220459 0.010568520054221153" quat="0.9660386443138123 0.2583959698677063 -0.0009257207857444882 -0.00024761143140494823"/>
          <geom class="collision" type="cylinder" pos="-0.01567287 0.08878232 0.17738391" size="0.01354062557220459 0.0882638618350029" quat="0.7078102827072144 0.7064019441604614 -0.0009256413904950023 0.0002479060203768313" name="spout_main"/>
          <geom class="collision" type="cylinder" pos="-0.01559375 0.01761998 0.16692658" size="0.012687318958342075 0.005486423149704933" quat="0.9999990463256836 -0.000995798734948039 -0.00047923243255354464 0.0008298233151435852"/>
        </body>
        <geom class="region" name="reg_basin" type="box" pos="-0.0023312149999999976 -0.023758150000000006 -0.08205305" size="0.173625325 0.13959493 0.06187224000000001"/>
        <geom class="region" name="reg_main" type="box" pos="2.950000000112585e-07 -3.499999999545533e-08 -0.10562358999999999" size="0.25403554500000003 0.239301245 0.08551079"/>
      </body>
    </body>
  </worldbody>
  <actuator>
    <motor name="handle_joint_actuator" joint="handle_joint" gear="10"/>
    <motor name="handle_temp_joint_actuator" joint="handle_temp_joint" gear="10"/>
    <motor name="Funnel001_joint_actuator" joint="Funnel001_joint" gear="10"/>
    <motor name="spout_joint_actuator" joint="spout_joint" gear="10"/>
  </actuator>
</mujoco>
