<?xml version='1.0' encoding='UTF-8'?>
<mujoco model="model">
  <option timestep="0.002" gravity="0.0 0.0 -9.81"/>
  <compiler angle="radian"/>
  <asset>
    <mesh file="visuals/freezer_door.obj" name="freezer_door_vis"/>
    <mesh file="visuals/freezer_door_Clear.obj" name="freezer_door_Clear_vis"/>
    <mesh file="visuals/freezer_drawer0.obj" name="freezer_drawer0_vis"/>
    <mesh file="visuals/freezer_drawer1.obj" name="freezer_drawer1_vis"/>
    <mesh file="visuals/fridge_door.obj" name="fridge_door_vis"/>
    <mesh file="visuals/fridge_door_Clear.obj" name="fridge_door_Clear_vis"/>
    <mesh file="visuals/fridge_drawer0.obj" name="fridge_drawer0_vis"/>
    <mesh file="visuals/fridge_drawer0_Clear.obj" name="fridge_drawer0_Clear_vis"/>
    <mesh file="visuals/fridge_drawer1.obj" name="fridge_drawer1_vis"/>
    <mesh file="visuals/fridge_drawer1_Clear.obj" name="fridge_drawer1_Clear_vis"/>
    <mesh file="visuals/Body001.obj" name="Body001_vis"/>
    <mesh file="visuals/Body001_Clear.obj" name="Body001_Clear_vis"/>
    <texture file="visuals/T_BC001.png" name="Body001_material" type="2d"/>
    <material name="Body001_material" rgba="1 1 1 1.0" texture="Body001_material" shininess="0.141421377658844" specular="0.5"/>
    <texture file="visuals/T_BC001.png" name="freezer_door_material" type="2d"/>
    <material name="freezer_door_material" rgba="1 1 1 1.0" texture="freezer_door_material" shininess="0.141421377658844" specular="0.5"/>
    <material name="freezer_door_Clear_material" rgba="0.5879999995231628 0.5879999995231628 0.5879999995231628 0.699999988079071" shininess="0.141421377658844" specular="0.3103448502657381"/>
    <texture file="visuals/T_BC001.png" name="freezer_drawer0_material" type="2d"/>
    <material name="freezer_drawer0_material" rgba="1 1 1 1.0" texture="freezer_drawer0_material" shininess="0.141421377658844" specular="0.3103448502657381"/>
    <texture file="visuals/T_BC001.png" name="freezer_drawer1_material" type="2d"/>
    <material name="freezer_drawer1_material" rgba="1 1 1 1.0" texture="freezer_drawer1_material" shininess="0.141421377658844" specular="0.3103448502657381"/>
    <texture file="visuals/T_BC001.png" name="fridge_door_material" type="2d"/>
    <material name="fridge_door_material" rgba="1 1 1 1.0" texture="fridge_door_material" shininess="0.141421377658844" specular="0.5"/>
    <material name="fridge_door_Clear_material" rgba="0.5879999995231628 0.5879999995231628 0.5879999995231628 0.699999988079071" shininess="0.141421377658844" specular="0.3103448502657381"/>
    <texture file="visuals/T_BC001.png" name="fridge_drawer0_material" type="2d"/>
    <material name="fridge_drawer0_material" rgba="1 1 1 1.0" texture="fridge_drawer0_material" shininess="0.141421377658844" specular="0.3103448502657381"/>
    <material name="fridge_drawer0_Clear_material" rgba="0.5879999995231628 0.5879999995231628 0.5879999995231628 0.699999988079071" shininess="0.141421377658844" specular="0.3103448502657381"/>
    <texture file="visuals/T_BC001.png" name="fridge_drawer1_material" type="2d"/>
    <material name="fridge_drawer1_material" rgba="1 1 1 1.0" texture="fridge_drawer1_material" shininess="0.141421377658844" specular="0.3103448502657381"/>
    <material name="fridge_drawer1_Clear_material" rgba="0.5879999995231628 0.5879999995231628 0.5879999995231628 0.699999988079071" shininess="0.141421377658844" specular="0.3103448502657381"/>
    <material name="Body001_Clear_material" rgba="0.5879999995231628 0.5879999995231628 0.5879999995231628 0.699999988079071" shininess="0.141421377658844" specular="0.3103448502657381"/>
  </asset>
  <default>
    <default class="visual">
      <geom conaffinity="0" contype="0" group="1" type="mesh"/>
    </default>
    <default class="collision">
      <geom group="0" rgba="0.5 0 0 0.5"/>
    </default>
    <default class="spawn">
      <geom group="0" rgba="1 1 1 0.5" contype="0" conaffinity="0"/>
      <site group="0" rgba="1 1 1 0.5"/>
    </default>
    <default class="region">
      <geom group="1" conaffinity="0" contype="0" rgba="0 1 0 0"/>
    </default>
  </default>
  <worldbody>
    <body>
      <body name="object">
        <geom mesh="Body001_vis" type="mesh" solimp="0.998 0.998 0.001" solref="0.001 1" friction="0.95 0.3 0.1" class="visual" material="Body001_material"/>
        <geom class="collision" type="box" pos="0.19542397 0.05402053 0.51480396" size="0.1840987205505371 0.2656129002571106 0.004253195133060217" quat="1.0 0.0 0.0 0.0"/>
        <geom class="collision" type="box" pos="0.19542397 0.05402053 0.12956363" size="0.1840987205505371 0.2656129002571106 0.004253092687577009" quat="1.0 0.0 0.0 0.0"/>
        <geom class="collision" type="box" pos="-0.01681286 0.38212408 0.04810228" size="0.44352519512176514 0.03413248062133789 0.8702205419540405" quat="1.0 0.0 0.0 0.0"/>
        <geom class="collision" type="box" pos="0.42115360 0.06064789 -0.00058767" size="0.03891677409410477 0.3556351959705353 0.918910562992096" quat="1.0 0.0 0.0 0.0"/>
        <geom class="collision" type="box" pos="-0.42054674 0.05798549 -0.00058767" size="0.039790909737348557 0.35297250747680664 0.918910562992096" quat="1.0 0.0 0.0 0.0"/>
        <geom class="collision" type="box" pos="-0.01632173 0.06064789 -0.83528869" size="0.4430340528488159 0.3556345999240875 0.032738711684942245" quat="1.0 0.0 0.0 0.0"/>
        <geom class="collision" type="box" pos="-0.00179176 0.04797573 -0.88933615" size="0.4585462510585785 0.3683064877986908 0.0301620252430439" quat="1.0 0.0 0.0 0.0"/>
        <geom class="collision" type="box" pos="-0.01681286 0.05798552 0.88619424" size="0.44352519512176514 0.3529716730117798 0.03212868049740791" quat="1.0 0.0 0.0 0.0"/>
        <geom class="collision" type="box" pos="0.02225573 0.07450574 0.47040062" size="0.005047741811722517 0.28755342960357666 0.038640059530735016" quat="1.0 0.0 0.0 0.0"/>
        <geom class="collision" type="box" pos="0.40386575 0.07450574 0.59664036" size="0.005047741811722517 0.2875531315803528 0.038640059530735016" quat="1.0 0.0 0.0 0.0"/>
        <geom class="collision" type="box" pos="-0.40314907 0.07450574 0.59664036" size="0.005047741811722517 0.2875528335571289 0.038640059530735016" quat="1.0 0.0 0.0 0.0"/>
        <geom class="collision" type="box" pos="-0.40314907 0.07450574 0.26510491" size="0.005047741811722517 0.28755253553390503 0.038640059530735016" quat="1.0 0.0 0.0 0.0"/>
        <geom class="collision" type="box" pos="0.40386575 0.07450574 0.26510491" size="0.005047741811722517 0.28755220770835876 0.038640059530735016" quat="1.0 0.0 0.0 0.0"/>
        <geom class="collision" type="box" pos="0.02380894 0.07450574 0.08800076" size="0.005047741811722517 0.2875519096851349 0.038640059530735016" quat="1.0 0.0 0.0 0.0"/>
        <geom class="collision" type="box" pos="-0.00019994 0.05215137 0.03325643" size="0.021367784589529037 0.3023695945739746 0.8420110940933228" quat="1.0 0.0 0.0 0.0"/>
        <geom class="collision" type="box" pos="-0.37698105 0.07450574 0.08800076" size="0.005047741811722517 0.28755131363868713 0.038640059530735016" quat="1.0 0.0 0.0 0.0"/>
        <geom class="collision" type="box" pos="0.37815750 0.07450574 0.08800076" size="0.005047741811722517 0.28755101561546326 0.038640059530735016" quat="1.0 0.0 0.0 0.0"/>
        <geom class="collision" type="box" pos="-0.37698105 0.07450574 0.47040062" size="0.005047741811722517 0.2875507175922394 0.038640059530735016" quat="1.0 0.0 0.0 0.0"/>
        <geom class="collision" type="box" pos="0.37815750 0.07450574 0.47040062" size="0.005047741811722517 0.2875504195690155 0.038640059530735016" quat="1.0 0.0 0.0 0.0"/>
        <geom class="collision" type="box" pos="0.00053404 0.03642872 -0.23298666" size="0.3867661654949188 0.3257085084915161 0.0333593413233757" quat="1.0 0.0 0.0 0.0"/>
        <geom class="collision" type="box" pos="-0.02431719 0.07450574 0.08800076" size="0.005047741811722517 0.28754982352256775 0.038640059530735016" quat="1.0 0.0 0.0 0.0"/>
        <geom class="collision" type="box" pos="-0.02217671 0.07450574 0.47040062" size="0.005047741811722517 0.28754952549934387 0.038640059530735016" quat="1.0 0.0 0.0 0.0"/>
        <geom class="collision" type="box" pos="-0.20000947 0.05402053 0.51480396" size="0.1840987205505371 0.2656129002571106 0.004253195133060217" quat="1.0 0.0 0.0 0.0"/>
        <geom class="collision" type="box" pos="-0.20000947 0.05402053 0.12956363" size="0.1840987205505371 0.2656129002571106 0.004253092687577009" quat="1.0 0.0 0.0 0.0"/>
        <body name="freezer_door">
          <joint axis="0.0 0.0 1.0" pos="0.42246142 -0.32628955 0.01685005" limited="true" name="freezer_door_joint" range="0.0 1.5707963267948966" type="hinge" damping="1" frictionloss="1" armature=".01" stiffness="0.05"/>
          <geom mesh="freezer_door_vis" type="mesh" solimp="0.998 0.998 0.001" solref="0.001 1" friction="0.95 0.3 0.1" class="visual" material="freezer_door_material"/>
          <geom class="collision" type="box" pos="0.35427150 -0.22472968 0.68077304" size="0.0037848034407943487 0.06044527888298035 0.03261616453528404" quat="1.0 0.0 0.0 0.0"/>
          <geom class="collision" type="box" pos="0.35427150 -0.22472968 0.45229678" size="0.003784806001931429 0.06044532731175423 0.03261616453528404" quat="1.0 0.0 0.0 0.0"/>
          <geom class="collision" type="box" pos="0.35427150 -0.22472968 0.21860476" size="0.003784808563068509 0.060445379465818405 0.03261616453528404" quat="1.0 0.0 0.0 0.0"/>
          <geom class="collision" type="box" pos="0.09434172 -0.22472968 0.68077304" size="0.0037848111242055893 0.060445427894592285 0.03261616453528404" quat="1.0 0.0 0.0 0.0"/>
          <geom class="collision" type="box" pos="0.09434172 -0.22472968 0.45229678" size="0.0037848136853426695 0.060445480048656464 0.03261616453528404" quat="1.0 0.0 0.0 0.0"/>
          <geom class="collision" type="box" pos="0.09434172 -0.22472968 0.21860476" size="0.0037848164793103933 0.060445528477430344 0.03261616453528404" quat="1.0 0.0 0.0 0.0"/>
          <geom class="collision" type="box" pos="0.22425026 -0.16862466 0.68077304" size="0.13380013406276703 0.002221064642071724 0.03261615335941315" quat="1.0 0.0 0.0 0.0"/>
          <geom class="collision" type="box" pos="0.22425026 -0.16862466 0.45229678" size="0.1338002234697342 0.002221066039055586 0.03261615335941315" quat="1.0 0.0 0.0 0.0"/>
          <geom class="collision" type="box" pos="0.22425026 -0.16862466 0.21860476" size="0.13380029797554016 0.0022210676688700914 0.03261615335941315" quat="1.0 0.0 0.0 0.0"/>
          <geom class="collision" type="box" pos="0.22425026 -0.22581150 0.65079941" size="0.13380038738250732 0.05747317150235176 0.00264250161126256" quat="1.0 0.0 0.0 0.0"/>
          <geom class="collision" type="box" pos="0.22425026 -0.22581150 0.42232312" size="0.1338004767894745 0.05747317150235176 0.00264250161126256" quat="1.0 0.0 0.0 0.0"/>
          <geom class="collision" type="box" pos="0.22425026 -0.22581150 0.18863110" size="0.13380055129528046 0.05747317150235176 0.00264250161126256" quat="1.0 0.0 0.0 0.0"/>
          <geom class="collision" type="box" pos="0.22425026 -0.28422268 0.68077304" size="0.13380064070224762 0.0022210744209587574 0.03261615335941315" quat="1.0 0.0 0.0 0.0"/>
          <geom class="collision" type="box" pos="0.22425026 -0.28422268 0.45229678" size="0.1338007152080536 0.0022210758179426193 0.03261615335941315" quat="1.0 0.0 0.0 0.0"/>
          <geom class="collision" type="box" pos="0.22425026 -0.28422268 0.21860476" size="0.13380080461502075 0.002221077447757125 0.03261615335941315" quat="1.0 0.0 0.0 0.0"/>
          <geom class="collision" type="box" pos="0.36258858 -0.27246134 0.47030334" size="0.007261377759277821 0.034429892897605896 0.37150201201438904" quat="1.0 0.0 0.0 0.0"/>
          <geom class="collision" type="box" pos="0.22248134 -0.27246140 0.10995691" size="0.13923145830631256 0.03443457931280136 0.010292775928974152" quat="1.0 0.0 0.0 0.0"/>
          <geom class="collision" type="box" pos="0.08361362 -0.27246134 0.47030334" size="0.007261377759277821 0.034429967403411865 0.3715025782585144" quat="1.0 0.0 0.0 0.0"/>
          <geom class="collision" type="box" pos="0.22248134 -0.27246140 0.82779022" size="0.13923145830631256 0.03443450480699539 0.010292775928974152" quat="1.0 0.0 0.0 0.0"/>
          <geom class="collision" type="box" pos="0.01858399 -0.40234156 -0.03055562" size="0.014525260776281357 0.0745832622051239 0.00947658997029066" quat="5.559254034892547e-08 5.108230993755569e-08 0.7363455295562744 -0.6766057014465332" name="freezer_door_handle_1"/>
          <geom class="collision" type="box" pos="0.01858399 -0.40187999 0.23478355" size="0.014525260776281357 0.0745832622051239 0.00947658997029066" quat="0.7363455891609192 0.6766056418418884 0.0 0.0" name="freezer_door_handle_2"/>
          <geom class="collision" type="box" pos="0.01816337 -0.37520449 -0.07808439" size="0.007846806198358536 0.015975087881088257 0.009277496486902237" quat="1.0 0.0 0.0 0.0" name="freezer_door_handle_3"/>
          <geom class="collision" type="box" pos="0.01816337 -0.37520449 0.27924223" size="0.00784681923687458 0.01597508229315281 0.009277504868805408" quat="1.0 0.0 0.0 0.0" name="freezer_door_handle_4"/>
          <geom class="collision" type="box" pos="0.01858399 -0.40784522 0.09996226" size="0.014525260776281357 0.0745718777179718 0.009477976709604263" quat="5.366500488435122e-08 5.310367257038706e-08 0.7108145952224731 -0.7033794522285461" name="freezer_door_handle_main"/>
          <geom class="collision" type="box" pos="0.19407464 -0.33310692 0.03200897" size="0.23424962162971497 0.02347022481262684 0.8841925859451294" quat="1.0 0.0 0.0 0.0" name="freezer_door_main"/>
          <body name="freezer_door_Clear">
            <geom mesh="freezer_door_Clear_vis" type="mesh" solimp="0.998 0.998 0.001" solref="0.001 1" friction="0.95 0.3 0.1" class="visual" material="freezer_door_Clear_material"/>
            <geom class="collision" type="box" pos="0.35427150 -0.22472968 0.68077304" size="0.0037848034407943487 0.06044527888298035 0.03261616453528404" quat="1.0 0.0 0.0 0.0"/>
            <geom class="collision" type="box" pos="0.35427150 -0.22472968 0.45229678" size="0.003784806001931429 0.06044532731175423 0.03261616453528404" quat="1.0 0.0 0.0 0.0"/>
            <geom class="collision" type="box" pos="0.35427150 -0.22472968 0.21860476" size="0.003784808563068509 0.060445379465818405 0.03261616453528404" quat="1.0 0.0 0.0 0.0"/>
            <geom class="collision" type="box" pos="0.09434172 -0.22472968 0.68077304" size="0.0037848111242055893 0.060445427894592285 0.03261616453528404" quat="1.0 0.0 0.0 0.0"/>
            <geom class="collision" type="box" pos="0.09434172 -0.22472968 0.45229678" size="0.0037848136853426695 0.060445480048656464 0.03261616453528404" quat="1.0 0.0 0.0 0.0"/>
            <geom class="collision" type="box" pos="0.09434172 -0.22472968 0.21860476" size="0.0037848164793103933 0.060445528477430344 0.03261616453528404" quat="1.0 0.0 0.0 0.0"/>
            <geom class="collision" type="box" pos="0.22425026 -0.16862466 0.68077304" size="0.13380013406276703 0.002221064642071724 0.03261615335941315" quat="1.0 0.0 0.0 0.0"/>
            <geom class="collision" type="box" pos="0.22425026 -0.16862466 0.45229678" size="0.1338002234697342 0.002221066039055586 0.03261615335941315" quat="1.0 0.0 0.0 0.0"/>
            <geom class="collision" type="box" pos="0.22425026 -0.16862466 0.21860476" size="0.13380029797554016 0.0022210676688700914 0.03261615335941315" quat="1.0 0.0 0.0 0.0"/>
            <geom class="collision" type="box" pos="0.22425026 -0.22581150 0.65079941" size="0.13380038738250732 0.05747317150235176 0.00264250161126256" quat="1.0 0.0 0.0 0.0"/>
            <geom class="collision" type="box" pos="0.22425026 -0.22581150 0.42232312" size="0.1338004767894745 0.05747317150235176 0.00264250161126256" quat="1.0 0.0 0.0 0.0"/>
            <geom class="collision" type="box" pos="0.22425026 -0.22581150 0.18863110" size="0.13380055129528046 0.05747317150235176 0.00264250161126256" quat="1.0 0.0 0.0 0.0"/>
            <geom class="collision" type="box" pos="0.22425026 -0.28422268 0.68077304" size="0.13380064070224762 0.0022210744209587574 0.03261615335941315" quat="1.0 0.0 0.0 0.0"/>
            <geom class="collision" type="box" pos="0.22425026 -0.28422268 0.45229678" size="0.1338007152080536 0.0022210758179426193 0.03261615335941315" quat="1.0 0.0 0.0 0.0"/>
            <geom class="collision" type="box" pos="0.22425026 -0.28422268 0.21860476" size="0.13380080461502075 0.002221077447757125 0.03261615335941315" quat="1.0 0.0 0.0 0.0"/>
          </body>
        </body>
        <body name="freezer_drawer0">
          <geom class="region" name="reg_freezer_drawer0" type="box" pos="0.20402288000000002 0.08360336499999999 -0.676607145" size="0.15793972 0.215243205 0.08774314499999997"/>
          <joint axis="0.0 -1.0 0.0" pos="0.20245659 0.09520830 -0.66563158" limited="true" name="freezer_drawer0_joint" range="0.0 0.5" type="slide" damping="1" frictionloss="1" armature=".01" stiffness="0.05"/>
          <geom mesh="freezer_drawer0_vis" type="mesh" solimp="0.998 0.998 0.001" solref="0.001 1" friction="0.95 0.3 0.1" class="visual" material="freezer_drawer0_material"/>
          <geom class="collision" type="box" pos="0.20283447 0.32223828 -0.67989670" size="0.1698264330625534 0.0019848705269396305 0.10074243694543839" quat="1.0 0.0 0.0 0.0"/>
          <geom class="collision" type="box" pos="0.20257865 0.09086576 -0.78080796" size="0.16906554996967316 0.23100794851779938 0.0019431012915447354" quat="1.0 0.0 0.0 0.0"/>
          <geom class="collision" type="box" pos="0.03558399 0.08814210 -0.67989670" size="0.0016467495588585734 0.2353828251361847 0.10074256360530853" quat="1.0 0.0 0.0 0.0"/>
          <geom class="collision" type="box" pos="0.36932921 0.08814210 -0.67989670" size="0.001646683900617063 0.235383078455925 0.10074262320995331" quat="1.0 0.0 0.0 0.0"/>
          <geom class="collision" type="box" pos="0.08758903 -0.14777947 -0.65895419" size="0.061102770268917084 0.009535233490169048 0.12168292701244354" quat="1.0 0.0 0.0 0.0"/>
          <geom class="collision" type="box" pos="0.31687108 -0.14777947 -0.65895419" size="0.061103302985429764 0.009535313583910465 0.12168419361114502" quat="1.0 0.0 0.0 0.0"/>
          <geom class="collision" type="box" pos="0.20256232 -0.14777947 -0.59504227" size="0.061103396117687225 0.009535327553749084 0.0577726848423481" quat="1.0 0.0 0.0 0.0"/>
          <geom class="collision" type="box" pos="0.20256232 -0.14777947 -0.73731790" size="0.06110348924994469 0.009535341523587704 0.04263819009065628" quat="1.0 0.0 0.0 0.0"/>
        </body>
        <body name="freezer_drawer1">
          <geom class="region" name="reg_freezer_drawer1" type="box" pos="0.20402288000000002 0.08360336499999999 -0.41421339" size="0.15793972 0.215243205 0.08796194000000002"/>
          <joint axis="0.0 -1.0 0.0" pos="0.20245659 0.09520830 -0.40246685" limited="true" name="freezer_drawer1_joint" range="0.0 0.5" type="slide" damping="1" frictionloss="1" armature=".01" stiffness="0.05"/>
          <geom mesh="freezer_drawer1_vis" type="mesh" solimp="0.998 0.998 0.001" solref="0.001 1" friction="0.95 0.3 0.1" class="visual" material="freezer_drawer1_material"/>
          <geom class="collision" type="box" pos="0.08758903 -0.14777947 -0.39831243" size="0.06110285222530365 0.009535240940749645 0.11997127532958984" quat="1.0 0.0 0.0 0.0"/>
          <geom class="collision" type="box" pos="0.36932918 0.08814210 -0.41754325" size="0.0016466740053147078 0.23538383841514587 0.10074280947446823" quat="1.0 0.0 0.0 0.0"/>
          <geom class="collision" type="box" pos="0.03558401 0.08814210 -0.41754325" size="0.001646780176088214 0.23538409173488617 0.100742869079113" quat="1.0 0.0 0.0 0.0"/>
          <geom class="collision" type="box" pos="0.20257865 0.09086576 -0.51764332" size="0.16906628012657166 0.23100882768630981 0.0019430284155532718" quat="1.0 0.0 0.0 0.0"/>
          <geom class="collision" type="box" pos="0.20283447 0.32223825 -0.41754325" size="0.16982737183570862 0.001984876347705722 0.10074299573898315" quat="1.0 0.0 0.0 0.0"/>
          <geom class="collision" type="box" pos="0.31687108 -0.14777947 -0.39831243" size="0.06110338494181633 0.009535321965813637 0.11997253447771072" quat="1.0 0.0 0.0 0.0"/>
          <geom class="collision" type="box" pos="0.20256232 -0.14777947 -0.33364378" size="0.06110347807407379 0.009535335935652256 0.055304378271102905" quat="1.0 0.0 0.0 0.0"/>
          <geom class="collision" type="box" pos="0.20256232 -0.14777947 -0.47450982" size="0.06110357120633125 0.009535349905490875 0.04157937318086624" quat="1.0 0.0 0.0 0.0"/>
        </body>
        <body name="fridge_door">
          <joint axis="0.0 0.0 -1.0" pos="-0.42331839 -0.33092516 0.01685005" limited="true" name="fridge_door_joint" range="0.0 1.5707963267948966" type="hinge" damping="1" frictionloss="1" armature=".01" stiffness="0.05"/>
          <geom mesh="fridge_door_vis" type="mesh" solimp="0.998 0.998 0.001" solref="0.001 1" friction="0.95 0.3 0.1" class="visual" material="fridge_door_material"/>
          <geom class="collision" type="box" pos="-0.09397809 -0.22659101 0.21860476" size="0.0037848607171326876 0.062307704240083694 0.03261616453528404" quat="1.0 0.0 0.0 0.0"/>
          <geom class="collision" type="box" pos="-0.35390782 -0.22659101 0.21860476" size="0.0037848632782697678 0.06230775639414787 0.03261616453528404" quat="1.0 0.0 0.0 0.0"/>
          <geom class="collision" type="box" pos="-0.22399931 -0.16862466 0.21860476" size="0.1338016390800476 0.002221092814579606 0.03261615335941315" quat="1.0 0.0 0.0 0.0"/>
          <geom class="collision" type="box" pos="-0.22399931 -0.22767284 0.18863110" size="0.13380172848701477 0.05933448672294617 0.00264250161126256" quat="1.0 0.0 0.0 0.0"/>
          <geom class="collision" type="box" pos="-0.22399931 -0.28794532 0.21860476" size="0.13380180299282074 0.002221096074208617 0.03261615335941315" quat="1.0 0.0 0.0 0.0"/>
          <geom class="collision" type="box" pos="-0.09397809 -0.22659101 0.45229678" size="0.003784873755648732 0.06230795755982399 0.03261616453528404" quat="1.0 0.0 0.0 0.0"/>
          <geom class="collision" type="box" pos="-0.35390782 -0.22659101 0.45229678" size="0.0037848763167858124 0.06230800971388817 0.03261616453528404" quat="1.0 0.0 0.0 0.0"/>
          <geom class="collision" type="box" pos="-0.22399931 -0.16862466 0.45229678" size="0.13380205631256104 0.0022211007308214903 0.03261615335941315" quat="1.0 0.0 0.0 0.0"/>
          <geom class="collision" type="box" pos="-0.22399931 -0.22767284 0.42232312" size="0.1338021457195282 0.05933448672294617 0.00264250161126256" quat="1.0 0.0 0.0 0.0"/>
          <geom class="collision" type="box" pos="-0.22399931 -0.28794532 0.45229678" size="0.13380222022533417 0.002221103757619858 0.03261615335941315" quat="1.0 0.0 0.0 0.0"/>
          <geom class="collision" type="box" pos="-0.09397809 -0.22659101 0.68077304" size="0.003784886794164777 0.062308210879564285 0.03261616453528404" quat="1.0 0.0 0.0 0.0"/>
          <geom class="collision" type="box" pos="-0.35390782 -0.22659101 0.68077304" size="0.0037848895881325006 0.062308259308338165 0.03261616453528404" quat="1.0 0.0 0.0 0.0"/>
          <geom class="collision" type="box" pos="-0.22399931 -0.16862466 0.68077304" size="0.13380247354507446 0.0022211086470633745 0.03261615335941315" quat="1.0 0.0 0.0 0.0"/>
          <geom class="collision" type="box" pos="-0.22399931 -0.22767284 0.65079941" size="0.13380256295204163 0.05933448672294617 0.00264250161126256" quat="1.0 0.0 0.0 0.0"/>
          <geom class="collision" type="box" pos="-0.22399931 -0.28794532 0.68077304" size="0.1338026374578476 0.002221111673861742 0.03261615335941315" quat="1.0 0.0 0.0 0.0"/>
          <geom class="collision" type="box" pos="-0.08552612 -0.27246134 0.47030334" size="0.007261377759277821 0.03443143889307976 0.37151411175727844" quat="1.0 0.0 0.0 0.0"/>
          <geom class="collision" type="box" pos="-0.22563340 -0.27246140 0.10995691" size="0.13923145830631256 0.0344330333173275 0.010292775928974152" quat="1.0 0.0 0.0 0.0"/>
          <geom class="collision" type="box" pos="-0.36450112 -0.27246134 0.47030334" size="0.007261377759277821 0.03443151339888573 0.3715147078037262" quat="1.0 0.0 0.0 0.0"/>
          <geom class="collision" type="box" pos="-0.22563340 -0.27246140 0.82779022" size="0.13923145830631256 0.03443295881152153 0.010292775928974152" quat="1.0 0.0 0.0 0.0"/>
          <geom class="collision" type="box" pos="-0.10630156 -0.37520449 0.27924223" size="0.007847015745937824 0.015974530950188637 0.009277479723095894" quat="1.0 0.0 0.0 0.0" name="fridge_door_handle_1"/>
          <geom class="collision" type="box" pos="-0.10630156 -0.37520449 -0.07808439" size="0.007847027853131294 0.01597452722489834 0.009277488104999065" quat="1.0 0.0 0.0 0.0" name="fridge_door_handle_2"/>
          <geom class="collision" type="box" pos="-0.10588094 -0.40187999 0.23478355" size="0.014525260776281357 0.0745832622051239 0.00947658997029066" quat="0.7363455891609192 0.6766056418418884 0.0 0.0" name="fridge_door_handle_3"/>
          <geom class="collision" type="box" pos="-0.10588094 -0.40234156 -0.03055562" size="0.014525260776281357 0.0745832622051239 0.00947658997029066" quat="5.559254034892547e-08 5.108230993755569e-08 0.7363455295562744 -0.6766057014465332" name="fridge_door_handle_4"/>
          <geom class="collision" type="box" pos="-0.10588094 -0.40784522 0.09996226" size="0.014525260776281357 0.0745718777179718 0.009477976709604263" quat="5.366500488435122e-08 5.310367257038706e-08 0.7108145952224731 -0.7033794522285461" name="fridge_door_handle_main"/>
          <geom class="collision" type="box" pos="-0.22748268 -0.33215012 0.03200897" size="0.18134984374046326 0.022514168173074722 0.8842410445213318" quat="1.0 0.0 0.0 0.0" name="fridge_door_main"/>
          <body name="fridge_door_Clear">
            <geom mesh="fridge_door_Clear_vis" type="mesh" solimp="0.998 0.998 0.001" solref="0.001 1" friction="0.95 0.3 0.1" class="visual" material="fridge_door_Clear_material"/>
            <geom class="collision" type="box" pos="-0.09397809 -0.22659101 0.21860476" size="0.0037848607171326876 0.062307704240083694 0.03261616453528404" quat="1.0 0.0 0.0 0.0"/>
            <geom class="collision" type="box" pos="-0.35390782 -0.22659101 0.21860476" size="0.0037848632782697678 0.06230775639414787 0.03261616453528404" quat="1.0 0.0 0.0 0.0"/>
            <geom class="collision" type="box" pos="-0.22399931 -0.16862466 0.21860476" size="0.1338016390800476 0.002221092814579606 0.03261615335941315" quat="1.0 0.0 0.0 0.0"/>
            <geom class="collision" type="box" pos="-0.22399931 -0.22767284 0.18863110" size="0.13380172848701477 0.05933448672294617 0.00264250161126256" quat="1.0 0.0 0.0 0.0"/>
            <geom class="collision" type="box" pos="-0.22399931 -0.28794532 0.21860476" size="0.13380180299282074 0.002221096074208617 0.03261615335941315" quat="1.0 0.0 0.0 0.0"/>
            <geom class="collision" type="box" pos="-0.09397809 -0.22659101 0.45229678" size="0.003784873755648732 0.06230795755982399 0.03261616453528404" quat="1.0 0.0 0.0 0.0"/>
            <geom class="collision" type="box" pos="-0.35390782 -0.22659101 0.45229678" size="0.0037848763167858124 0.06230800971388817 0.03261616453528404" quat="1.0 0.0 0.0 0.0"/>
            <geom class="collision" type="box" pos="-0.22399931 -0.16862466 0.45229678" size="0.13380205631256104 0.0022211007308214903 0.03261615335941315" quat="1.0 0.0 0.0 0.0"/>
            <geom class="collision" type="box" pos="-0.22399931 -0.22767284 0.42232312" size="0.1338021457195282 0.05933448672294617 0.00264250161126256" quat="1.0 0.0 0.0 0.0"/>
            <geom class="collision" type="box" pos="-0.22399931 -0.28794532 0.45229678" size="0.13380222022533417 0.002221103757619858 0.03261615335941315" quat="1.0 0.0 0.0 0.0"/>
            <geom class="collision" type="box" pos="-0.09397809 -0.22659101 0.68077304" size="0.003784886794164777 0.062308210879564285 0.03261616453528404" quat="1.0 0.0 0.0 0.0"/>
            <geom class="collision" type="box" pos="-0.35390782 -0.22659101 0.68077304" size="0.0037848895881325006 0.062308259308338165 0.03261616453528404" quat="1.0 0.0 0.0 0.0"/>
            <geom class="collision" type="box" pos="-0.22399931 -0.16862466 0.68077304" size="0.13380247354507446 0.0022211086470633745 0.03261615335941315" quat="1.0 0.0 0.0 0.0"/>
            <geom class="collision" type="box" pos="-0.22399931 -0.22767284 0.65079941" size="0.13380256295204163 0.05933448672294617 0.00264250161126256" quat="1.0 0.0 0.0 0.0"/>
            <geom class="collision" type="box" pos="-0.22399931 -0.28794532 0.68077304" size="0.1338026374578476 0.002221111673861742 0.03261615335941315" quat="1.0 0.0 0.0 0.0"/>
          </body>
        </body>
        <body name="fridge_drawer0">
          <geom class="region" name="reg_fridge_drawer0" type="box" pos="-0.20126202499999998 0.08360336499999999 -0.676607145" size="0.156658365 0.215243205 0.08774314499999997"/>
          <joint axis="0.0 -1.0 0.0" pos="-0.20121150 -0.14823974 -0.66563158" limited="true" name="fridge_drawer0_joint" range="0.0 0.5" type="slide" damping="1" frictionloss="1" armature=".01" stiffness="0.05"/>
          <geom mesh="fridge_drawer0_vis" type="mesh" solimp="0.998 0.998 0.001" solref="0.001 1" friction="0.95 0.3 0.1" class="visual" material="fridge_drawer0_material"/>
          <geom class="collision" type="box" pos="-0.31933493 -0.14777947 -0.66018711" size="0.06024886295199394 0.009535280056297779 0.1204507052898407" quat="1.0 0.0 0.0 0.0"/>
          <geom class="collision" type="box" pos="-0.03683698 0.08814210 -0.67874180" size="0.001646753284148872 0.23538510501384735 0.09958821535110474" quat="1.0 0.0 0.0 0.0"/>
          <geom class="collision" type="box" pos="-0.36887339 0.08814210 -0.67874180" size="0.0016467426903545856 0.23538535833358765 0.0995882898569107" quat="1.0 0.0 0.0 0.0"/>
          <geom class="collision" type="box" pos="-0.20434532 0.09086576 -0.77638774" size="0.1682124137878418 0.23100945353507996 0.0019430170068517327" quat="1.0 0.0 0.0 0.0"/>
          <geom class="collision" type="box" pos="-0.20408949 0.32186128 -0.67874180" size="0.16897349059581757 0.0019848905503749847 0.09958837181329727" quat="1.0 0.0 0.0 0.0"/>
          <geom class="collision" type="box" pos="-0.09005290 -0.14777947 -0.66018711" size="0.06024930253624916 0.009535347111523151 0.12045174837112427" quat="1.0 0.0 0.0 0.0"/>
          <geom class="collision" type="box" pos="-0.20436166 -0.14777947 -0.59413849" size="0.06024939566850662 0.00953536108136177 0.05440362170338631" quat="1.0 0.0 0.0 0.0"/>
          <geom class="collision" type="box" pos="-0.20436166 -0.14777947 -0.73333524" size="0.060249488800764084 0.00953537505120039 0.04234789311885834" quat="1.0 0.0 0.0 0.0"/>
          <body name="fridge_drawer0_Clear">
            <geom mesh="fridge_drawer0_Clear_vis" type="mesh" solimp="0.998 0.998 0.001" solref="0.001 1" friction="0.95 0.3 0.1" class="visual" material="fridge_drawer0_Clear_material"/>
          </body>
        </body>
        <body name="fridge_drawer1">
          <geom class="region" name="reg_fridge_drawer1" type="box" pos="-0.20126202499999998 0.08360336499999999 -0.41421339" size="0.156658365 0.215243205 0.08796194000000002"/>
          <joint axis="0.0 -1.0 0.0" pos="-0.20121150 -0.14816334 -0.40246685" limited="true" name="fridge_drawer1_joint" range="0.0 0.5" type="slide" damping="1" frictionloss="1" armature=".01" stiffness="0.05"/>
          <geom mesh="fridge_drawer1_vis" type="mesh" solimp="0.998 0.998 0.001" solref="0.001 1" friction="0.95 0.3 0.1" class="visual" material="fridge_drawer1_material"/>
          <geom class="collision" type="box" pos="-0.20408949 0.32169599 -0.41598262" size="0.16897359490394592 0.0019849182572215796 0.09918273240327835" quat="1.0 0.0 0.0 0.0"/>
          <geom class="collision" type="box" pos="-0.20434532 0.09086576 -0.51322304" size="0.16821272671222687 0.231009840965271 0.0019430523971095681" quat="1.0 0.0 0.0 0.0"/>
          <geom class="collision" type="box" pos="-0.36887339 0.08814210 -0.41598262" size="0.0016467507230117917 0.23538661003112793 0.0991828590631485" quat="1.0 0.0 0.0 0.0"/>
          <geom class="collision" type="box" pos="-0.03683699 0.08814210 -0.41598259" size="0.0016467721434310079 0.23538686335086823 0.09918289631605148" quat="1.0 0.0 0.0 0.0"/>
          <geom class="collision" type="box" pos="-0.31933493 -0.14777947 -0.39912952" size="0.06024959310889244 0.009535351768136024 0.11915590614080429" quat="1.0 0.0 0.0 0.0"/>
          <geom class="collision" type="box" pos="-0.09005290 -0.14777947 -0.39912952" size="0.060249850153923035 0.009535389952361584 0.11915650963783264" quat="1.0 0.0 0.0 0.0"/>
          <geom class="collision" type="box" pos="-0.20436166 -0.14777947 -0.33268033" size="0.060249943286180496 0.009535403922200203 0.0527077279984951" quat="1.0 0.0 0.0 0.0"/>
          <geom class="collision" type="box" pos="-0.20436166 -0.14777947 -0.47012542" size="0.06025003641843796 0.009535417892038822 0.0424036867916584" quat="1.0 0.0 0.0 0.0"/>
          <body name="fridge_drawer1_Clear">
            <geom mesh="fridge_drawer1_Clear_vis" type="mesh" solimp="0.998 0.998 0.001" solref="0.001 1" friction="0.95 0.3 0.1" class="visual" material="fridge_drawer1_Clear_material"/>
          </body>
        </body>
        <body name="Body001_Clear">
          <geom mesh="Body001_Clear_vis" type="mesh" solimp="0.998 0.998 0.001" solref="0.001 1" friction="0.95 0.3 0.1" class="visual" material="Body001_Clear_material"/>
          <geom class="collision" type="box" pos="-0.20000947 0.05402053 0.51480396" size="0.1840987205505371 0.2656129002571106 0.004253195133060217" quat="1.0 0.0 0.0 0.0"/>
          <geom class="collision" type="box" pos="-0.20000947 0.05402053 0.12956363" size="0.1840987205505371 0.2656129002571106 0.004253092687577009" quat="1.0 0.0 0.0 0.0"/>
        </body>
        <geom class="region" name="reg_freezer_shelf0" type="box" pos="0.202015695 0.09718169000000002 -0.037989274999999996" size="0.167293835 0.24479754 0.155484495"/>
        <geom class="region" name="reg_freezer_shelf1" type="box" pos="0.20109230499999997 0.084739755 0.32191384" size="0.168082275 0.232355605 0.18191108"/>
        <geom class="region" name="reg_freezer_shelf2" type="box" pos="0.200586765 0.08591054 0.686400695" size="0.17407993500000002 0.22983183000000001 0.160602495"/>
        <geom class="region" name="reg_fridge_shelf0" type="box" pos="-0.19805271500000002 0.09718169000000002 -0.037989274999999996" size="0.165838695 0.24479754 0.155484495"/>
        <geom class="region" name="reg_fridge_shelf1" type="box" pos="-0.199618035 0.084739755 0.32191384" size="0.16726907500000002 0.232355605 0.18191108"/>
        <geom class="region" name="reg_fridge_shelf2" type="box" pos="-0.200177135 0.08591054 0.686400635" size="0.17321313500000002 0.22983183000000001 0.16060255500000004"/>
        <geom class="region" name="reg_main" type="box" pos="-3.9500000001413405e-07 0.026825409999999994 -1.5000000019860238e-08" size="0.461337635 0.39042781 0.920498205"/>
      </body>
    </body>
  </worldbody>
  <actuator>
    <motor name="freezer_door_joint_actuator" joint="freezer_door_joint" gear="50"/>
    <motor name="freezer_drawer0_joint_actuator" joint="freezer_drawer0_joint" gear="50"/>
    <motor name="freezer_drawer1_joint_actuator" joint="freezer_drawer1_joint" gear="50"/>
    <motor name="fridge_door_joint_actuator" joint="fridge_door_joint" gear="50"/>
    <motor name="fridge_drawer0_joint_actuator" joint="fridge_drawer0_joint" gear="50"/>
    <motor name="fridge_drawer1_joint_actuator" joint="fridge_drawer1_joint" gear="50"/>
  </actuator>
</mujoco>
