<?xml version='1.0' encoding='UTF-8'?>
<mujoco model="model">
  <option timestep="0.002" gravity="0.0 0.0 -9.81"/>
  <compiler angle="radian"/>
  <asset>
    <mesh file="visuals/handle.obj" name="handle_vis"/>
    <mesh file="visuals/Body001.obj" name="Body001_vis"/>
    <mesh file="visuals/spout.obj" name="spout_vis"/>
    <texture file="visuals/T_BC001.png" name="Body001_material" type="2d"/>
    <material name="Body001_material" rgba="1 1 1 1.0" texture="Body001_material" shininess="0.1" specular="5"/>
    <texture file="visuals/T_BC001.png" name="handle_material" type="2d"/>
    <material name="handle_material" rgba="1 1 1 1.0" texture="handle_material" shininess="0.1" specular="5"/>
    <texture file="visuals/T_BC001.png" name="spout_material" type="2d"/>
    <material name="spout_material" rgba="1 1 1 1.0" texture="spout_material" shininess="0.1" specular="5"/>
  </asset>
  <default>
    <default class="visual">
      <geom conaffinity="0" contype="0" group="1" type="mesh"/>
    </default>
    <default class="collision">
      <geom group="0" rgba="0.5 0 0 0.5"/>
    </default>
    <default class="spawn">
      <geom group="0" rgba="1 1 1 0.5" contype="0" conaffinity="0"/>
      <site group="0" rgba="1 1 1 0.5"/>
    </default>
    <default class="region">
      <geom group="1" conaffinity="0" contype="0" rgba="0 1 0 0"/>
    </default>
  </default>
  <worldbody>
    <body>
      <body name="object">
        <geom mesh="Body001_vis" type="mesh" solimp="0.998 0.998 0.001" solref="0.001 1" friction="0.95 0.3 0.1" class="visual" material="Body001_material"/>
        <geom type="box" pos="0.03568168 -0.00033898 -0.13640268" size="0.015563767403364182 0.227515310049057 0.08199891448020935" quat="1.0 0.0 0.0 0.0" class="collision"/>
        <geom type="box" pos="0.36693436 0.00000013 -0.13923340" size="0.01528544258326292 0.24295544624328613 0.09282014518976212" quat="1.0 0.0 0.0 0.0" class="collision"/>
        <geom type="box" pos="-0.36688540 0.00000013 -0.13923340" size="0.015334184281527996 0.24295544624328613 0.09282014518976212" quat="1.0 0.0 0.0 0.0" class="collision"/>
        <geom type="box" pos="0.00814485 -0.22680522 -0.13923340" size="0.3691226840019226 0.01615010015666485 0.09282014518976212" quat="1.0 0.0 0.0 0.0" class="collision"/>
        <geom type="box" pos="0.00814485 0.22683115 -0.13923340" size="0.3691226840019226 0.01593775860965252 0.09282014518976212" quat="1.0 0.0 0.0 0.0" class="collision"/>
        <geom type="box" pos="-0.00050204 -0.00033898 -0.22008143" size="0.3762187957763672 0.227515310049057 0.011674664914608002" quat="1.0 0.0 0.0 0.0" class="collision"/>
        <geom type="cylinder" pos="0.03617212 0.19606145 -0.01595760" size="0.020531006157398224 0.043195951730012894" quat="1.0 0.0 0.0 0.0" class="collision"/>
        <geom type="cylinder" pos="0.05978877 0.19606145 -0.01595760" size="0.019330136477947235 0.023642554879188538" quat="0.7071068286895752 -0.0 0.7071067690849304 0.0" class="collision"/>
        <geom type="box" pos="0.34889546 0.20877515 -0.13923340" size="0.018279265612363815 0.024715591222047806 0.09282014518976212" quat="0.9288605451583862 0.0 0.0 0.3704295754432678" class="collision"/>
        <geom type="box" pos="0.34655371 -0.20816794 -0.13923340" size="0.018279265612363815 0.027491698041558266 0.09282014518976212" quat="0.9187368750572205 0.0 -0.0 -0.3948703110218048" class="collision"/>
        <geom type="box" pos="0.05018213 -0.20454733 -0.13923340" size="0.018279265612363815 0.035641081631183624 0.09282014518976212" quat="0.9187368750572205 0.0 0.0 0.3948703110218048" class="collision"/>
        <geom type="box" pos="0.05123286 0.20081723 -0.13967647" size="0.018279265612363815 0.03848198428750038 0.09282014518976212" quat="0.9288605451583862 0.0 -0.0 -0.3704295754432678" class="collision"/>
        <geom type="box" pos="-0.34538630 0.20630622 -0.13923340" size="0.018279265612363815 0.028469815850257874 0.09282014518976212" quat="0.9288605451583862 0.0 -0.0 -0.3704295754432678" class="collision"/>
        <geom type="box" pos="-0.34853605 -0.20889786 -0.13923340" size="0.018279265612363815 0.025328487157821655 0.09282014518976212" quat="0.9187368750572205 0.0 0.0 0.3948703110218048" class="collision"/>
        <geom type="box" pos="0.01690199 -0.20400129 -0.13923340" size="0.018279265612363815 0.035124652087688446 0.09282008558511734" quat="0.9187368750572205 0.0 -0.0 -0.3948703110218048" class="collision"/>
        <geom type="box" pos="0.01808428 0.20708442 -0.13923340" size="0.018279265612363815 0.02950967103242874 0.09282014518976212" quat="0.9288605451583862 0.0 0.0 0.3704295754432678" class="collision"/>
        <body name="handle">
          <joint axis="1.0 0.0 0.0" pos="0.10422280 0.19604491 -0.01582434" limited="true" name="handle_temp_joint" type="hinge" range="-0.7853981633974483 0.7853981633974483" damping="1" frictionloss="1" armature=".01"/>
          <joint axis="0.0 1.0 0.0" pos="0.10422280 0.19604491 -0.01582434" limited="true" name="handle_joint" type="hinge" range="0 0.5" damping="1" frictionloss="1" armature=".01"/>
          <geom mesh="handle_vis" type="mesh" solimp="0.998 0.998 0.001" solref="0.001 1" friction="0.95 0.3 0.1" class="visual" material="handle_material"/>
          <geom type="cylinder" pos="0.11228790 0.19606145 -0.01595760" size="0.019330138340592384 0.012952927500009537" quat="0.7071068286895752 -0.0 0.7071067690849304 0.0" class="collision" density="0.001"/>
          <geom name="handle_main" type="cylinder" pos="0.10866187 0.19606145 0.02707352" size="0.004705752711743116 0.025899672880768776" quat="1.0 0.0 0.0 0.0" class="collision" density="0.001"/>
        </body>
        <body name="spout">
          <joint axis="0.0 0.0 1.0" pos="0.03626749 0.19569555 0.11866485" limited="true" name="spout_joint" range="-1.0471975511965976 1.0471975511965976" type="hinge" damping="1" frictionloss="1" armature=".01" stiffness="0.01" springref="-0.01"/>
          <site type="cylinder" rgba="0.5 0.75 1 0.5" size="0.0063364868983626366 0.16602979600429535" pos="0.03443996 0.02061348 -0.04503134" name="water"/>
          <geom mesh="spout_vis" type="mesh" solimp="0.998 0.998 0.001" solref="0.001 1" friction="0.95 0.3 0.1" class="visual" material="spout_material"/>
          <geom type="cylinder" pos="0.03617212 0.19561376 0.09106597" size="0.00973040983080864 0.06362255662679672" quat="1.0 0.0 0.0 0.0" class="collision" name="spout_main"/>
          <geom type="cylinder" pos="0.03617212 0.18964827 0.16977249" size="0.00973040983080864 0.021186772733926773" quat="0.9831604957580566 0.18274420499801636 0.0 0.0" class="collision"/>
          <geom type="cylinder" pos="0.03617212 0.16832306 0.20132129" size="0.00973040983080864 0.021186772733926773" quat="0.9046697020530701 0.426113486289978 0.0 0.0" class="collision"/>
          <geom type="cylinder" pos="0.03617212 0.13507462 0.21813807" size="0.00973040983080864 0.021186772733926773" quat="0.8061753511428833 0.5916767120361328 0.0 0.0" class="collision"/>
          <geom type="cylinder" pos="0.03617212 0.09660570 0.22102645" size="0.00973040983080864 0.021186772733926773" quat="0.6601064205169678 0.7511721253395081 0.0 0.0" class="collision"/>
          <geom type="cylinder" pos="0.03581233 0.05993400 0.20891665" size="0.00973040983080864 0.021186772733926773" quat="0.4968041479587555 0.8678627014160156 0.0 0.0" class="collision"/>
          <geom type="cylinder" pos="0.03527266 0.03361766 0.18337055" size="0.00973040983080864 0.021186772733926773" quat="0.2905207574367523 0.9568687081336975 0.0 0.0" class="collision"/>
          <geom type="cylinder" pos="0.03527266 0.02176164 0.14594592" size="0.00973040983080864 0.028721407055854797" quat="0.03713774308562279 0.9993101358413696 0.0 0.0" class="collision"/>
        </body>
        <geom class="region" name="reg_basin_left" type="box" pos="-0.167326775 -0.0019000849999999958 -0.131895325" size="0.166017495 0.187833775 0.075080015"/>
        <geom class="region" name="reg_basin_right" type="box" pos="0.20149085 -0.001900075000000001 -0.13185774" size="0.13150341 0.187833785 0.07511757999999999"/>
        <geom class="region" name="reg_main" type="box" pos="1.0000000000287557e-07 1.2500000000359446e-07 -0.13860583" size="0.38321967 0.243955445 0.09354889000000001"/>
      </body>
    </body>
  </worldbody>
  <actuator>
    <motor name="handle_joint_actuator" joint="handle_joint" gear="10"/>
    <motor name="handle_temp_joint_actuator" joint="handle_temp_joint" gear="10"/>
    <motor name="spout_joint_actuator" joint="spout_joint" gear="10"/>
  </actuator>
</mujoco>
