<?xml version='1.0' encoding='UTF-8'?>
<mujoco model="model">
  <option timestep="0.002" gravity="0.0 0.0 -9.81"/>
  <compiler angle="radian"/>
  <asset>
    <mesh file="visuals/door.obj" name="door_vis"/>
    <mesh file="visuals/knob_function.obj" name="knob_function_vis"/>
    <mesh file="visuals/knob_temp.obj" name="knob_temp_vis"/>
    <mesh file="visuals/knob_time.obj" name="knob_time_vis"/>
    <mesh file="visuals/rack0.obj" name="rack0_vis"/>
    <mesh file="visuals/Body001.obj" name="Body001_vis"/>
    <mesh file="visuals/window.obj" name="window_vis"/>
    <texture file="visuals/T_BC001.png" name="Body001_material" type="2d"/>
    <material name="Body001_material" rgba="1 1 1 1.0" texture="Body001_material" shininess="0.141421377658844" specular="0.71"/>
    <texture file="visuals/T_BC001.png" name="door_material" type="2d"/>
    <material name="door_material" rgba="1 1 1 1.0" texture="door_material" shininess="0.141421377658844" specular="0.81"/>
    <texture file="visuals/T_BC001.png" name="window_material" type="2d"/>
    <material name="window_material" rgba="1 1 1 0.800000011920929" texture="window_material" shininess="0.141421377658844" specular="0.3103448502657381"/>
    <texture file="visuals/T_BC001.png" name="knob_function_material" type="2d"/>
    <material name="knob_function_material" rgba="1 1 1 1.0" texture="knob_function_material" shininess="0.141421377658844" specular="0.3103448502657381"/>
    <texture file="visuals/T_BC001.png" name="knob_temp_material" type="2d"/>
    <material name="knob_temp_material" rgba="1 1 1 1.0" texture="knob_temp_material" shininess="0.141421377658844" specular="0.3103448502657381"/>
    <texture file="visuals/T_BC001.png" name="knob_time_material" type="2d"/>
    <material name="knob_time_material" rgba="1 1 1 1.0" texture="knob_time_material" shininess="0.141421377658844" specular="0.3103448502657381"/>
    <texture file="visuals/T_BC001.png" name="rack0_material" type="2d"/>
    <material name="rack0_material" rgba="1 1 1 1.0" texture="rack0_material" shininess="0.141421377658844" specular="10"/>
  </asset>
  <default>
    <default class="visual">
      <geom conaffinity="0" contype="0" group="1" type="mesh"/>
    </default>
    <default class="collision">
      <geom group="0" rgba="0.5 0 0 0.5"/>
    </default>
    <default class="spawn">
      <geom group="0" rgba="1 1 1 0.5" contype="0" conaffinity="0"/>
      <site group="0" rgba="1 1 1 0.5"/>
    </default>
    <default class="region">
      <geom group="1" conaffinity="0" contype="0" rgba="0 1 0 0"/>
    </default>
  </default>
  <worldbody>
    <body>
      <body name="object">
        <geom mesh="Body001_vis" type="mesh" solimp="0.998 0.998 0.001" solref="0.001 1" friction="0.95 0.3 0.1" class="visual" material="Body001_material"/>
        <geom class="collision" type="box" pos="-0.2039780169725418 0.02983897738158703 0.02243412286043167" size="0.012105473317205906 0.1663031131029129 0.14247852563858032" quat="1.0 0.0 0.0 0.0"/>
        <geom class="collision" type="box" pos="-0.03818407282233238 0.03018273413181305 -0.1412220299243927" size="0.17800679802894592 0.16640129685401917 0.02400331199169159" quat="1.0 0.0 0.0 0.0"/>
        <geom class="collision" type="box" pos="-0.03884332999587059 0.18181969225406647 0.018248729407787323" size="0.17590925097465515 0.01430332288146019 0.14666391909122467" quat="1.0 0.0 0.0 0.0"/>
        <geom class="collision" type="box" pos="0.17522159218788147 0.01642169989645481 -0.0005831364542245865" size="0.040945589542388916 0.1794576495885849 0.16464221477508545" quat="1.0 0.0 0.0 0.0"/>
        <geom class="collision" type="box" pos="-0.0372847244143486 0.02990785986185074 0.15587566792964935" size="0.1778637319803238 0.16637198626995087 0.00870265532284975" quat="1.0 0.0 0.0 0.0"/>
        <geom class="collision" type="box" pos="-0.18916746973991394 0.011614857241511345 0.00022486294619739056" size="0.0054938457906246185 0.12701140344142914 0.015096782706677914" quat="1.0 0.0 0.0 0.0"/>
        <geom class="collision" type="box" pos="-0.18958930671215057 0.011614857241511345 -0.03713352233171463" size="0.00549384905025363 0.1270114928483963 0.015096793882548809" quat="1.0 0.0 0.0 0.0"/>
        <geom class="collision" type="box" pos="0.1319262534379959 0.011614857241511345 -0.03713352233171463" size="0.005493852309882641 0.12701156735420227 0.015096805058419704" quat="1.0 0.0 0.0 0.0"/>
        <geom class="collision" type="box" pos="0.1319262534379959 0.011614857241511345 0.000516153872013092" size="0.005493855569511652 0.12701164186000824 0.015096817165613174" quat="1.0 0.0 0.0 0.0"/>
        <body name="door">
          <joint axis="1.0 0.0 0.0" pos="-0.04003842920064926 -0.1410684585571289 -0.13804776966571808" limited="true" name="door_joint" range="0.0 1.5707963267948966" type="hinge" damping="1" frictionloss="1" armature=".01" stiffness="0.05" springref="-30"/>
          <geom mesh="door_vis" type="mesh" solimp="0.998 0.998 0.001" solref="0.001 1" friction="0.95 0.3 0.1" class="visual" material="door_material"/>
          <geom class="collision" type="box" pos="-0.04012495279312134 -0.15384447574615479 0.013099052011966705" size="0.17264078557491302 0.00944715365767479 0.14747866988182068" quat="1.0 0.0 0.0 0.0" name="door_main"/>
          <geom class="collision" type="box" pos="0.11159782111644745 -0.1786157786846161 0.14393894374370575" size="0.02029900625348091 0.005172309931367636 0.013131000101566315" quat="6.815625397393887e-08 0.9027569890022278 0.43015095591545105 3.2475490741035173e-08"/>
          <geom class="collision" type="box" pos="-0.04032646492123604 -0.19220224022865295 0.14393894374370575" size="0.14049792289733887 0.005172271281480789 0.01313092466443777" quat="1.0 0.0 0.0 0.0" name="door_handle_main"/>
          <geom class="collision" type="box" pos="-0.1917712241411209 -0.17856614291667938 0.14393894374370575" size="0.02029900625348091 0.005172309931367636 0.013131000101566315" quat="0.9027569890022278 0.0 0.0 -0.43015095591545105"/>
          <body name="window">
            <geom mesh="window_vis" type="mesh" solimp="0.998 0.998 0.001" solref="0.001 1" friction="0.95 0.3 0.1" class="visual" material="window_material"/>
            <geom class="collision" type="box" pos="-0.040320515632629395 -0.16180023550987244 -0.0015764464624226093" size="0.15256385505199432 0.002023582113906741 0.11862297356128693" quat="1.0 0.0 0.0 0.0"/>
          </body>
        </body>
        <body name="knob_function">
          <joint axis="0.0 1.0 0.0" pos="0.17913579940795898 -0.17962169647216797 -0.0010332679376006126" limited="true" name="knob_function_joint" range="0.0 3.961897402027128" type="hinge" damping="0.05" frictionloss="0.1" armature="0.001"/>
          <geom mesh="knob_function_vis" type="mesh" solimp="0.998 0.998 0.001" solref="0.001 1" friction="0.95 0.3 0.1" class="visual" material="knob_function_material"/>
          <geom class="collision" type="cylinder" pos="0.17913579940795898 -0.17404791712760925 -0.0007199756801128387" size="0.019237585365772247 0.007395401131361723" quat="0.7071068286895752 0.7071067690849304 0.0 0.0" density="0.001"/>
          <geom class="collision" type="box" pos="0.17912283539772034 -0.1865006983280182 -0.0009346618317067623" size="0.004002058412879705 0.006478690076619387 0.01813562400639057" quat="0.549201488494873 -2.0483782855670873e-13 -0.8356899619102478 -1.1228221552528339e-07" name="knob_function_main" density="0.001"/>
        </body>
        <body name="knob_temp">
          <joint axis="0.0 1.0 0.0" pos="0.17913579940795898 -0.1798498034477234 0.09543565660715103" limited="true" name="knob_temp_joint" range="0.0 4.4156830075456535" type="hinge" damping="0.05" frictionloss="0.1" armature="0.001"/>
          <geom mesh="knob_temp_vis" type="mesh" solimp="0.998 0.998 0.001" solref="0.001 1" friction="0.95 0.3 0.1" class="visual" material="knob_temp_material"/>
          <geom class="collision" type="cylinder" pos="0.17913579940795898 -0.17404791712760925 0.09452540427446365" size="0.019237585365772247 0.007395401131361723" quat="0.7071068286895752 0.7071067690849304 0.0 0.0" density="0.001"/>
          <geom class="collision" type="box" pos="0.1793217957019806 -0.1865006983280182 0.09543345123529434" size="0.004002058412879705 0.006478690076619387 0.01813562400639057" quat="0.46072059869766235 2.18099057694085e-14 -0.8875452280044556 -1.1924949205877056e-07" name="knob_temp_main" density="0.001"/>
        </body>
        <body name="knob_time">
          <joint axis="0.0 1.0 0.0" pos="0.17913579940795898 -0.17962771654129028 -0.09254294633865356" limited="true" name="knob_time_joint" range="0.0 4.014257279586958" type="hinge" damping="0.05" armature="0.001"/>
          <geom mesh="knob_time_vis" type="mesh" solimp="0.998 0.998 0.001" solref="0.001 1" friction="0.95 0.3 0.1" class="visual" material="knob_time_material"/>
          <geom class="collision" type="cylinder" pos="0.17913579940795898 -0.17404791712760925 -0.09294281899929047" size="0.019237585365772247 0.007395401131361723" quat="0.7071068286895752 0.7071067690849304 0.0 0.0"/>
          <geom class="collision" type="box" pos="0.17882436513900757 -0.1865006983280182 -0.0927700400352478" size="0.004002058412879705 0.006478690076619387 0.01813572086393833" quat="1.0 0.0 0.0 0.0" name="knob_time_main"/>
        </body>
        <body name="rack0">
          <geom class="region" name="reg_rack0" type="box" pos="-0.02807624638080597 0.008608207106590271 0.05945906229317188" size="0.13636839187145233 0.1237162778377533 0.08605147509276867"/>
          <joint axis="0.0 -1.0 0.0" pos="-0.02863200753927231 0.008345536887645721 -0.02480681613087654" limited="true" name="rack0_joint" range="0.0 0.25" type="slide" damping="1" frictionloss="1" armature=".01" stiffness="0.05"/>
          <geom mesh="rack0_vis" type="mesh" solimp="0.998 0.998 0.001" solref="0.001 1" friction="0.95 0.3 0.1" class="visual" material="rack0_material"/>
          <geom class="collision" type="box" pos="-0.028050508350133896 0.008563034236431122 -0.028848711401224136" size="0.13570380210876465 0.12284987419843674 0.0030371074099093676" quat="1.0 0.0 0.0 0.0"/>
          <geom class="collision" type="box" pos="-0.18249717354774475 0.008482776582241058 -0.019134825095534325" size="0.008577265776693821 0.12300089001655579 0.001667578355409205" quat="1.0 0.0 0.0 0.0"/>
          <geom class="collision" type="box" pos="-0.16859766840934753 0.008476205170154572 -0.0239250548183918" size="0.008577265776693821 0.12300733476877213 0.0016675618244335055" quat="0.9440328478813171 -2.0632491271044273e-08 0.3298514783382416 7.209132402152818e-09"/>
          <geom class="collision" type="box" pos="0.11243189126253128 0.008476205170154572 -0.0239250585436821" size="0.008577265776693821 0.12300733476877213 0.0016675632214173675" quat="7.127249546101666e-08 -0.9440328478813171 -2.4903092921135794e-08 -0.3298514783382416"/>
          <geom class="collision" type="box" pos="0.12554088234901428 0.008482776582241058 -0.019134825095534325" size="0.008577265776693821 0.12300089001655579 0.0016675770748406649" quat="1.0 0.0 0.0 0.0"/>
        </body>
        <geom class="region" name="reg_int" type="box" pos="-0.028990082442760468 0.013765305280685425 0.014842260628938675" size="0.1541737521290779 0.15403681790828705 0.13272071799635887"/>
        <geom class="region" name="reg_main" type="box" pos="-3.725290298461914e-09 0.015343382954597473 0.0" size="0.2174328396320343 0.1828493753671646 0.1662253419160843"/>
      </body>
    </body>
  </worldbody>
  <actuator>
    <motor name="door_joint_actuator" joint="door_joint" gear="50"/>
    <motor name="knob_function_joint_actuator" joint="knob_function_joint" gear="50"/>
    <motor name="knob_temp_joint_actuator" joint="knob_temp_joint" gear="50"/>
    <motor name="knob_time_joint_actuator" joint="knob_time_joint" gear="50"/>
    <motor name="rack0_joint_actuator" joint="rack0_joint" gear="50"/>
  </actuator>
</mujoco>
