<?xml version='1.0' encoding='UTF-8'?>
<mujoco model="model">
  <option timestep="0.002" gravity="0.0 0.0 -9.81"/>
  <compiler angle="radian"/>
  <asset>
    <mesh file="visuals/button_power.obj" name="button_power_vis"/>
    <mesh file="visuals/Body001.obj" name="Body001_vis"/>
    <mesh file="visuals/door.obj" name="door_vis"/>
    <mesh file="visuals/rack0.obj" name="rack0_vis"/>
    <mesh file="visuals/rack1.obj" name="rack1_vis"/>
    <texture file="visuals/T_BC001.png" name="Body001_material" type="2d"/>
    <material name="Body001_material" rgba="1 1 1 1.0" texture="Body001_material" shininess="0.1" specular="6"/>
    <texture file="visuals/T_BC001.png" name="door_material" type="2d"/>
    <material name="door_material" rgba="1 1 1 1.0" texture="door_material" shininess="0.1" specular="6"/>
    <texture file="visuals/T_BC001.png" name="button_power_material" type="2d"/>
    <material name="button_power_material" rgba="1 1 1 1.0" texture="button_power_material" shininess="0.1" specular="6"/>
    <texture file="visuals/T_BC001.png" name="rack0_material" type="2d"/>
    <material name="rack0_material" rgba="1 1 1 1.0" texture="rack0_material" shininess="0.1" specular="6"/>
    <texture file="visuals/T_BC001.png" name="rack1_material" type="2d"/>
    <material name="rack1_material" rgba="1 1 1 1.0" texture="rack1_material" shininess="0.1" specular="6"/>
  </asset>
  <default>
    <default class="visual">
      <geom conaffinity="0" contype="0" group="1" type="mesh"/>
    </default>
    <default class="collision">
      <geom group="0" rgba="0.5 0 0 0.5"/>
    </default>
    <default class="spawn">
      <geom group="0" rgba="1 1 1 0.5" contype="0" conaffinity="0"/>
      <site group="0" rgba="1 1 1 0.5"/>
    </default>
    <default class="region">
      <geom group="1" conaffinity="0" contype="0" rgba="0 1 0 0"/>
    </default>
  </default>
  <worldbody>
    <body>
      <body name="object">
        <geom mesh="Body001_vis" type="mesh" solimp="0.998 0.998 0.001" solref="0.001 1" friction="0.95 0.3 0.1" class="visual" material="Body001_material"/>
        <geom class="collision" type="box" pos="-0.00000002 -0.27696897 -0.42335901" size="0.3244858980178833 0.012244201265275478 0.061163902282714844" quat="1.0 0.0 0.0 0.0"/>
        <geom class="collision" type="box" pos="0.00038822 0.04619240 -0.42070463" size="0.2991548180580139 0.3115966320037842 0.05850958824157715" quat="1.0 0.0 0.0 0.0"/>
        <geom class="collision" type="box" pos="0.00038822 0.04619240 -0.33293474" size="0.29915493726730347 0.3115968406200409 0.03304149955511093" quat="1.0 0.0 0.0 0.0"/>
        <geom class="collision" type="box" pos="0.00038822 0.24968736 0.05879498" size="0.29915502667427063 0.10810777544975281 0.3550553023815155" quat="1.0 0.0 0.0 0.0"/>
        <geom class="collision" type="box" pos="0.00038822 0.04619240 0.44873157" size="0.29915517568588257 0.3115972578525543 0.032823991030454636" quat="1.0 0.0 0.0 0.0"/>
        <geom class="collision" type="box" pos="0.27927663 -0.06196933 0.05755318" size="0.02027086168527603 0.20343931019306183 0.35505545139312744" quat="1.0 0.0 0.0 0.0"/>
        <geom class="collision" type="box" pos="-0.27810726 -0.06196933 0.05755318" size="0.020895369350910187 0.20343941450119019 0.3550555109977722" quat="1.0 0.0 0.0 0.0"/>
        <geom class="collision" type="box" pos="0.24990419 -0.03828324 -0.14343232" size="0.011768651194870472 0.1806776374578476 0.002298763720318675" quat="1.0 0.0 0.0 0.0"/>
        <geom class="collision" type="box" pos="0.24990419 -0.03828324 0.07840847" size="0.011768658645451069 0.18067774176597595 0.002298763021826744" quat="1.0 0.0 0.0 0.0"/>
        <geom class="collision" type="box" pos="-0.24425244 -0.03828324 0.07840847" size="0.015683652833104134 0.1806778460741043 0.0022987646516412497" quat="1.0 0.0 0.0 0.0"/>
        <geom class="collision" type="box" pos="-0.24425244 -0.03828324 -0.14343232" size="0.01568366028368473 0.18067795038223267 0.002298768376931548" quat="1.0 0.0 0.0 0.0"/>
        <body name="door">
          <joint axis="1.0 0.0 0.0" pos="-0.00000002 -0.28729368 -0.36070549" limited="true" name="door_joint" range="0.0 0.6235987755982988" type="hinge" damping="1" frictionloss="1" armature=".01" stiffness="0.05"/>
          <geom mesh="door_vis" type="mesh" solimp="0.998 0.998 0.001" solref="0.001 1" friction="0.95 0.3 0.1" class="visual" material="door_material"/>
          <geom class="collision" type="box" pos="-0.00000002 -0.27800624 0.06247582" size="0.3244870901107788 0.011327194049954414 0.42204156517982483" quat="1.0 0.0 0.0 0.0" name="door_main"/>
          <geom class="collision" type="box" pos="-0.25857393 -0.31318618 0.35702610" size="0.05091876536607742 0.022817475721240044 0.009476338513195515" quat="1.0 0.0 0.0 0.0"/>
          <geom class="collision" type="box" pos="0.25483140 -0.31318618 0.35702610" size="0.050294287502765656 0.022817488759756088 0.009476345032453537" quat="1.0 0.0 0.0 0.0"/>
          <geom class="collision" type="box" pos="-0.00168355 -0.34621603 0.35702610" size="0.295711487531662 0.012319796718657017 0.00947635155171156" quat="1.0 0.0 0.0 0.0" name="door_handle_main"/>
          <body name="button_power">
            <joint axis="0.0 1.0 0.0" pos="0.11635070 -0.29049234 0.42535225" limited="true" name="button_power_joint" range="0.0 0.002" type="slide" damping="1" frictionloss="1" armature=".01" stiffness="0.05"/>
            <geom mesh="button_power_vis" type="mesh" solimp="0.998 0.998 0.001" solref="0.001 1" friction="0.95 0.3 0.1" class="visual" material="button_power_material"/>
            <geom class="collision" type="cylinder" pos="0.11636769 -0.29136355 0.42533377" size="0.009846530854701996 0.0015546578215435147" quat="0.7071067094802856 0.7071068286895752 0.0 0.0"/>
          </body>
        </body>
        <body name="rack0">
          <geom class="region" name="reg_rack0" type="box" pos="0.007693975000000006 -0.042310509999999996 -0.015250935" size="0.223213275 0.15854236 0.10228237500000001"/>
          <joint axis="0.0 -1.0 0.0" pos="0.00152424 -0.04322837 -0.08390982" limited="true" name="rack0_joint" range="0.0 0.2" type="slide" damping="1" frictionloss="1" armature=".01" stiffness="0.05"/>
          <geom mesh="rack0_vis" type="mesh" solimp="0.998 0.998 0.001" solref="0.001 1" friction="0.95 0.3 0.1" class="visual" material="rack0_material"/>
          <geom class="collision" type="box" pos="-0.03531636 -0.04029504 -0.09657510" size="0.0019118215423077345 0.13336151838302612 0.0261716078966856" quat="1.0 0.0 0.0 0.0"/>
          <geom class="collision" type="box" pos="0.03205111 -0.04029504 -0.09657510" size="0.0019118215423077345 0.13336151838302612 0.0261716078966856" quat="1.0 0.0 0.0 0.0"/>
          <geom class="collision" type="box" pos="0.10122308 -0.04029504 -0.09657510" size="0.0019118215423077345 0.13336151838302612 0.0261716078966856" quat="1.0 0.0 0.0 0.0"/>
          <geom class="collision" type="box" pos="0.16735027 -0.04029504 -0.09657510" size="0.0019118215423077345 0.13336151838302612 0.0261716078966856" quat="1.0 0.0 0.0 0.0"/>
          <geom class="collision" type="box" pos="0.00182250 0.12420084 -0.07674162" size="0.23673833906650543 0.003599451156333089 0.04600508511066437" quat="1.0 0.0 0.0 0.0"/>
          <geom class="collision" type="box" pos="0.00182250 -0.20953585 -0.07674162" size="0.23673833906650543 0.003599451156333089 0.04600508511066437" quat="1.0 0.0 0.0 0.0"/>
          <geom class="collision" type="box" pos="-0.24072131 -0.04413319 -0.07674162" size="0.0057272110134363174 0.16507881879806519 0.04600508511066437" quat="1.0 0.0 0.0 0.0"/>
          <geom class="collision" type="box" pos="0.24326123 -0.04413319 -0.07674162" size="0.0057272110134363174 0.16507881879806519 0.04600508511066437" quat="1.0 0.0 0.0 0.0"/>
          <geom class="collision" type="box" pos="-0.16390234 -0.04029504 -0.09657510" size="0.0019118215423077345 0.13336151838302612 0.0261716078966856" quat="1.0 0.0 0.0 0.0"/>
          <geom class="collision" type="box" pos="-0.10004316 -0.04029504 -0.09657510" size="0.0019118215423077345 0.13336151838302612 0.0261716078966856" quat="1.0 0.0 0.0 0.0"/>
          <geom class="collision" type="box" pos="0.00153467 -0.04413319 -0.12555444" size="0.24041961133480072 0.16507881879806519 0.0023818393237888813" quat="1.0 0.0 0.0 0.0"/>
        </body>
        <body name="rack1">
          <geom class="region" name="reg_rack1" type="box" pos="0.007693975000000006 -0.042310509999999996 0.251831845" size="0.223213275 0.15854236 0.150193005"/>
          <joint axis="0.0 -1.0 0.0" pos="0.00152424 -0.04322835 0.13654485" limited="true" name="rack1_joint" range="0.0 0.3" type="slide" damping="1" frictionloss="1" armature=".01" stiffness="0.05"/>
          <geom mesh="rack1_vis" type="mesh" solimp="0.998 0.998 0.001" solref="0.001 1" friction="0.95 0.3 0.1" class="visual" material="rack1_material"/>
          <geom class="collision" type="box" pos="0.00153467 -0.04413319 0.09445150" size="0.24041961133480072 0.16507881879806519 0.0023818393237888813" quat="1.0 0.0 0.0 0.0"/>
          <geom class="collision" type="box" pos="0.24326123 -0.04413319 0.14326432" size="0.0057272110134363174 0.16507881879806519 0.04600507766008377" quat="1.0 0.0 0.0 0.0"/>
          <geom class="collision" type="box" pos="-0.24072131 -0.04413319 0.14326432" size="0.0057272110134363174 0.16507881879806519 0.04600507766008377" quat="1.0 0.0 0.0 0.0"/>
          <geom class="collision" type="box" pos="0.00182250 -0.20953585 0.14326432" size="0.23673833906650543 0.003599451156333089 0.04600507766008377" quat="1.0 0.0 0.0 0.0"/>
          <geom class="collision" type="box" pos="0.00182250 0.12420084 0.14326432" size="0.23673833906650543 0.003599451156333089 0.04600507766008377" quat="1.0 0.0 0.0 0.0"/>
          <geom class="collision" type="box" pos="0.16735027 -0.04029504 0.12343085" size="0.0019118215423077345 0.13336151838302612 0.02617160975933075" quat="1.0 0.0 0.0 0.0"/>
          <geom class="collision" type="box" pos="0.10122308 -0.04029504 0.12343085" size="0.0019118215423077345 0.13336151838302612 0.02617160975933075" quat="1.0 0.0 0.0 0.0"/>
          <geom class="collision" type="box" pos="0.03205111 -0.04029504 0.12343085" size="0.0019118215423077345 0.13336151838302612 0.02617160975933075" quat="1.0 0.0 0.0 0.0"/>
          <geom class="collision" type="box" pos="-0.03531636 -0.04029504 0.12343085" size="0.0019118215423077345 0.13336151838302612 0.02617160975933075" quat="1.0 0.0 0.0 0.0"/>
          <geom class="collision" type="box" pos="-0.10004316 -0.04029504 0.12343085" size="0.0019118215423077345 0.13336151838302612 0.02617160975933075" quat="1.0 0.0 0.0 0.0"/>
          <geom class="collision" type="box" pos="-0.16390234 -0.04029504 0.12343085" size="0.0019118215423077345 0.13336151838302612 0.02617160975933075" quat="1.0 0.0 0.0 0.0"/>
        </body>
        <geom class="region" name="reg_int" type="box" pos="0.0012928900000000049 -0.058422769999999985 0.05706724499999999" size="0.23349109 0.20139873 0.344957605"/>
        <geom class="region" name="reg_main" type="box" pos="-2.500000001459668e-08 0.034231695000000006 -1.8999999998325912e-07" size="0.325490785 0.324565365 0.48552377"/>
      </body>
    </body>
  </worldbody>
  <actuator>
    <motor name="door_joint_actuator" joint="door_joint" gear="50"/>
    <motor name="rack0_joint_actuator" joint="rack0_joint" gear="50"/>
    <motor name="rack1_joint_actuator" joint="rack1_joint" gear="50"/>
    <motor name="button_power_joint_actuator" joint="button_power_joint" gear="0.5"/>
  </actuator>
</mujoco>
