<?xml version='1.0' encoding='UTF-8'?>
<mujoco model="model">
  <option timestep="0.002" gravity="0.0 0.0 -9.81"/>
  <compiler angle="radian"/>
  <asset>
    <mesh file="visuals/door.obj" name="door_vis"/>
    <mesh file="visuals/knob_temp.obj" name="knob_temp_vis"/>
    <mesh file="visuals/knob_time.obj" name="knob_time_vis"/>
    <mesh file="visuals/rack0.obj" name="rack0_vis"/>
    <mesh file="visuals/Body001.obj" name="Body001_vis"/>
    <mesh file="visuals/window.obj" name="window_vis"/>
    <texture file="visuals/T_BC001.png" name="Body001_material" type="2d"/>
    <material name="Body001_material" rgba="1 1 1 1.0" texture="Body001_material" shininess="0.1" specular="4"/>
    <texture file="visuals/T_BC001.png" name="door_material" type="2d"/>
    <material name="door_material" rgba="1 1 1 1.0" texture="door_material" shininess="0.1" specular="4"/>
    <material name="window_material" rgba="0.08873672038316727 0.08873672038316727 0.08873672038316727 0.699999988079071" shininess="0.141421377658844" specular="0.3103448502657381"/>
    <texture file="visuals/T_BC001.png" name="knob_temp_material" type="2d"/>
    <material name="knob_temp_material" rgba="1 1 1 1.0" texture="knob_temp_material" shininess="0.1" specular="4"/>
    <texture file="visuals/T_BC001.png" name="knob_time_material" type="2d"/>
    <material name="knob_time_material" rgba="1 1 1 1.0" texture="knob_time_material" shininess="0.1" specular="4"/>
    <texture file="visuals/T_BC001.png" name="rack0_material" type="2d"/>
    <material name="rack0_material" rgba="1 1 1 1.0" texture="rack0_material" shininess="0.1" specular="4"/>
  </asset>
  <default>
    <default class="visual">
      <geom conaffinity="0" contype="0" group="1" type="mesh"/>
    </default>
    <default class="collision">
      <geom group="0" rgba="0.5 0 0 0.5"/>
    </default>
    <default class="spawn">
      <geom group="0" rgba="1 1 1 0.5" contype="0" conaffinity="0"/>
      <site group="0" rgba="1 1 1 0.5"/>
    </default>
    <default class="region">
      <geom group="1" conaffinity="0" contype="0" rgba="0 1 0 0"/>
    </default>
  </default>
  <worldbody>
    <body>
      <body name="object">
        <geom mesh="Body001_vis" type="mesh" solimp="0.998 0.998 0.001" solref="0.001 1" friction="0.95 0.3 0.1" class="visual" material="Body001_material"/>
        <geom type="box" pos="-0.19915375113487244 0.023692751303315163 0.019506996497511864" size="0.01134636253118515 0.13945986330509186 0.09349346905946732" quat="1.0 0.0 0.0 0.0" class="collision"/>
        <geom type="box" pos="-0.023264974355697632 0.023692751303315163 -0.07780774682760239" size="0.16671471297740936 0.13945895433425903 0.011364622972905636" quat="1.0 0.0 0.0 0.0" class="collision"/>
        <geom type="box" pos="-0.03292854130268097 0.16241781413555145 0.021472088992595673" size="0.1775723546743393 0.002849917858839035 0.09152837097644806" quat="1.0 0.0 0.0 0.0" class="collision"/>
        <geom type="box" pos="0.1396062970161438 0.023692751303315163 0.019507044926285744" size="0.011800045147538185 0.13945969939231873 0.09349343180656433" quat="1.0 0.0 0.0 0.0" class="collision"/>
        <geom type="box" pos="-0.03292854130268097 0.023692751303315163 0.10178637504577637" size="0.17757223546504974 0.13945963978767395 0.011213717982172966" quat="1.0 0.0 0.0 0.0" class="collision"/>
        <geom type="box" pos="-0.030011050403118134 0.17500577867031097 0.008379187434911728" size="0.11408746987581253 0.009935717098414898 0.06044715642929077" quat="1.0 0.0 0.0 0.0" class="collision"/>
        <geom type="box" pos="0.17786118388175964 0.01931707188487053 2.6345707837549526e-08" size="0.032639019191265106 0.143835186958313 0.11300036311149597" quat="1.0 0.0 0.0 0.0" class="collision"/>
        <geom type="box" pos="-0.032928597182035446 -0.12176620215177536 -0.09873336553573608" size="0.1775721311569214 0.008292383514344692 0.014266709797084332" quat="1.0 0.0 0.0 0.0" class="collision"/>
        <geom type="box" pos="-0.1976035237312317 0.025271344929933548 -0.09316490590572357" size="0.012896561995148659 0.138315811753273 0.019835161045193672" quat="1.0 0.0 0.0 0.0" class="collision"/>
        <geom type="box" pos="0.1369469165802002 0.025271344929933548 -0.09357748925685883" size="0.009070739150047302 0.13831554353237152 0.01942254789173603" quat="1.0 0.0 0.0 0.0" class="collision"/>
        <geom type="box" pos="-0.186309814453125 0.023692749440670013 0.02976948767900467" size="0.004095414653420448 0.11066891252994537 0.013503777794539928" quat="1.0 0.0 0.0 0.0" class="collision"/>
        <geom type="box" pos="-0.186309814453125 0.023692749440670013 -0.010365255177021027" size="0.004095414653420448 0.11066892743110657 0.013503780588507652" quat="1.0 0.0 0.0 0.0" class="collision"/>
        <geom type="box" pos="0.12682807445526123 0.023692749440670013 0.02976948767900467" size="0.004095414653420448 0.11066894978284836 0.013503783382475376" quat="1.0 0.0 0.0 0.0" class="collision"/>
        <geom type="box" pos="0.12682807445526123 0.023692749440670013 -0.010365255177021027" size="0.004095414653420448 0.11066896468400955 0.0135037861764431" quat="1.0 0.0 0.0 0.0" class="collision"/>
        <body name="door">
          <joint axis="1.0 0.0 0.0" pos="-0.034499987959861755 -0.1284104287624359 -0.08070763945579529" limited="true" name="door_joint" range="0.0 1.4307963267948966" type="hinge" damping="1" frictionloss="1" armature=".01" stiffness="0.05" springref="-3"/>
          <geom mesh="door_vis" type="mesh" solimp="0.998 0.998 0.001" solref="0.001 1" friction="0.95 0.3 0.1" class="visual" material="door_material"/>
          <geom type="box" pos="-0.1616303026676178 -0.15656162798404694 0.09874646365642548" size="0.010255392640829086 0.02860903926193714 0.012028321623802185" quat="1.0 0.0 0.0 0.0" class="collision"/>
          <geom type="box" pos="0.09226434677839279 -0.15656162798404694 0.09874646365642548" size="0.010255392640829086 0.028609031811356544 0.012028317898511887" quat="1.0 0.0 0.0 0.0" class="collision"/>
          <geom class="collision" type="cylinder" pos="-0.03468139097094536 -0.17494115233421326 0.09922613203525543" size="0.008183791302144527 0.11429895460605621" quat="0.7071068286895752 0.0 -0.7071067690849304 0.0" name="door_handle_main"/>
          <geom class="collision" type="box" pos="-0.03427824005484581 -0.12261099368333817 0.01597590744495392" size="0.17340099811553955 0.003546656109392643 0.09479881078004837" quat="1.0 0.0 0.0 0.0" name="door_main"/>
          <body name="window">
            <geom mesh="window_vis" type="mesh" solimp="0.998 0.998 0.001" solref="0.001 1" friction="0.95 0.3 0.1" class="visual" material="window_material"/>
          </body>
        </body>
        <body name="knob_temp">
          <joint axis="0.0 1.0 0.0" pos="0.17749997973442078 -0.13413533568382263 -0.03509907424449921" limited="true" name="knob_temp_joint" range="0.0 4.537856055185257" type="hinge" damping="0.05" frictionloss="0.75" armature="1"/>
          <geom mesh="knob_temp_vis" type="mesh" solimp="0.998 0.998 0.001" solref="0.001 1" friction="0.95 0.3 0.1" class="visual" material="knob_temp_material"/>
          <geom type="cylinder" pos="0.17749997973442078 -0.13024592399597168 -0.03509907424449921" size="0.014455029740929604 0.003352796658873558" quat="0.7071068286895752 0.7071067690849304 0.0 0.0" class="collision" friction="100 0.5 0.01"/>
          <geom class="collision" type="box" pos="0.17749997973442078 -0.13762956857681274 -0.03509907424449921" size="0.0028757485561072826 0.004862802568823099 0.010511142201721668" quat="1.0 0.0 0.0 0.0" name="knob_temp_main" friction="100 0.5 0.01"/>
        </body>
        <body name="knob_time">
          <joint axis="0.0 1.0 0.0" pos="0.17749997973442078 -0.13410982489585876 0.04776974022388458" limited="true" name="knob_time_joint" range="0.0 5.323254218582705" type="hinge" damping="0.05" frictionloss="0.75" armature="1"/>
          <geom mesh="knob_time_vis" type="mesh" solimp="0.998 0.998 0.001" solref="0.001 1" friction="0.95 0.3 0.1" class="visual" material="knob_time_material"/>
          <geom type="cylinder" pos="0.17749997973442078 -0.13022786378860474 0.04776974022388458" size="0.014455029740929604 0.003352796658873558" quat="0.7071068286895752 0.7071067690849304 0.0 0.0" class="collision" friction="100 0.5 0.01"/>
          <geom class="collision" type="box" pos="0.17749997973442078 -0.1376115083694458 0.04776974022388458" size="0.010511142201721668 0.0048628030344843864 0.002875745762139559" quat="1.0 0.0 0.0 0.0" name="knob_time_main" friction="100 0.5 0.01"/>
        </body>
        <body name="rack0">
          <geom class="region" name="reg_rack0" type="box" pos="-0.029716338962316513 0.027002640068531036 0.04332981340121478" size="0.13080616465210915 0.12689719146490097 0.0471426965193823"/>
          <joint axis="0.0 -1.0 0.0" pos="-0.029804488644003868 0.027116667479276657 0.00047825463116168976" limited="true" name="rack0_joint" range="0.0 0.25" type="slide" damping="1" frictionloss="1" armature=".01" stiffness="0.05"/>
          <geom mesh="rack0_vis" type="mesh" solimp="0.998 0.998 0.001" solref="0.001 1" friction="0.95 0.3 0.1" class="visual" material="rack0_material"/>
          <geom type="box" pos="-0.03072410449385643 0.02707163244485855 -0.006946139968931675" size="0.13582004606723785 0.1287454217672348 0.003292788052931428" quat="1.0 0.0 0.0 0.0" class="collision"/>
          <geom type="box" pos="0.11883842945098877 0.027066843584179878 0.009048592299222946" size="0.007618641015142202 0.12887655198574066 0.002635304583236575" quat="1.0 0.0 0.0 0.0" class="collision"/>
          <geom type="box" pos="0.11046212166547775 0.027066843584179878 0.0004183817654848099" size="0.01061615813523531 0.12887655198574066 0.0026352968998253345" quat="0.8631649017333984 -7.031371040966405e-08 -0.5049221515655518 -4.113108786896191e-08" class="collision"/>
          <geom type="box" pos="-0.16996705532073975 0.02706684172153473 0.00041838083416223526" size="0.01061615813523531 0.12887655198574066 0.0026352968998253345" quat="2.709616353513411e-07 0.8631649017333984 1.5850329759814485e-07 -0.5049221515655518" class="collision"/>
          <geom type="box" pos="-0.17815768718719482 0.02706684172153473 0.009048592299222946" size="0.007618641015142202 0.12887655198574066 0.002635364653542638" quat="1.0 0.0 0.0 0.0" class="collision"/>
        </body>
        <geom class="region" name="reg_int" type="box" pos="-0.029740698635578156 0.023170601576566696 0.011767208576202393" size="0.14847335761785507 0.1366564797461033 0.07870530134439468"/>
        <geom class="region" name="reg_main" type="box" pos="0.0 0.02744145691394806 0.0" size="0.2115000615119934 0.1584999988079071 0.1140000501871109"/>
      </body>
    </body>
  </worldbody>
  <actuator>
    <motor name="door_joint_actuator" joint="door_joint" gear="50"/>
    <motor name="knob_temp_joint_actuator" joint="knob_temp_joint" gear="50"/>
    <motor name="knob_time_joint_actuator" joint="knob_time_joint" gear="50"/>
    <motor name="rack0_joint_actuator" joint="rack0_joint" gear="50"/>
  </actuator>
</mujoco>