<?xml version='1.0' encoding='UTF-8'?>
<mujoco model="model">
  <option timestep="0.002" gravity="0.0 0.0 -9.81"/>
  <compiler angle="radian"/>
  <asset>
    <mesh file="visuals/door.obj" name="door_vis"/>
    <mesh file="visuals/door_Clear.obj" name="door_Clear_vis"/>
    <mesh file="visuals/Body001.obj" name="Body001_vis"/>
    <mesh file="visuals/Button001.obj" name="Button001_vis"/>
    <mesh file="visuals/Button002.obj" name="Button002_vis"/>
    <mesh file="visuals/Disc001.obj" name="Disc001_vis"/>
    <mesh file="visuals/Knob001.obj" name="Knob001_vis"/>
    <texture file="visuals/T_BC001.png" name="Body001_material" type="2d"/>
    <material name="Body001_material" rgba="1 1 1 1.0" texture="Body001_material" shininess="1" specular="1"/>
    <texture file="visuals/T_BC001.png" name="door_material" type="2d"/>
    <material name="door_material" rgba="1 1 1 1.0" texture="door_material" shininess="1" specular="1"/>
    <texture file="visuals/T_BC001.png" name="door_Clear_material" type="2d"/>
    <material name="door_Clear_material" rgba="1 1 1 0.75" texture="door_Clear_material" shininess="0.5" specular="0.3"/>
    <texture file="visuals/T_BC001.png" name="Button001_material" type="2d"/>
    <material name="Button001_material" rgba="1 1 1 1.0" texture="Button001_material" shininess="1" specular="1"/>
    <texture file="visuals/T_BC001.png" name="Button002_material" type="2d"/>
    <material name="Button002_material" rgba="1 1 1 1.0" texture="Button002_material" shininess="1" specular="1"/>
    <texture file="visuals/T_BC001.png" name="Disc001_material" type="2d"/>
    <material name="Disc001_material" rgba="1 1 1 1.0" texture="Disc001_material" shininess="0.5" specular="0.5"/>
    <texture file="visuals/T_BC001.png" name="Knob001_material" type="2d"/>
    <material name="Knob001_material" rgba="1 1 1 1.0" texture="Knob001_material" shininess="1" specular="1"/>
  </asset>
  <default>
    <default class="visual">
      <geom conaffinity="0" contype="0" group="1" type="mesh"/>
    </default>
    <default class="collision">
      <geom group="0" rgba="0.5 0 0 0.5"/>
    </default>
    <default class="spawn">
      <geom group="0" rgba="1 1 1 0.5" contype="0" conaffinity="0"/>
      <site group="0" rgba="1 1 1 0.5"/>
    </default>
    <default class="region">
      <geom group="1" conaffinity="0" contype="0" rgba="0 1 0 0"/>
    </default>
  </default>
  <worldbody>
    <body>
      <body name="object">
        <geom class="collision" type="cylinder" pos="-0.0748702883720398 0.03600567579269409 -0.13489985466003418" size="0.17178954184055328 0.0008063041022978723" quat="1.0 0.0 0.0 0.0" name="tray" rgba="0 1 0 0.5"/>
        <geom class="collision" type="box" pos="0.2570140063762665 -0.19964851438999176 -0.13752494752407074" size="0.018102804198861122 0.0008529985207132995 0.005535766948014498" quat="1.0 0.0 0.0 0.0" name="start_button" rgba="0.0 0.5 0 0.5"/>
        <geom class="collision" type="box" pos="0.2570140063762665 -0.19964851438999176 -0.08242230117321014" size="0.018102804198861122 0.0008529983460903168 0.005535766948014498" quat="1.0 0.0 0.0 0.0" name="stop_button" rgba="0.0 0.5 0 0.5"/>
        <geom mesh="Body001_vis" type="mesh" solimp="0.998 0.998 0.001" solref="0.001 1" friction="0.95 0.3 0.1" class="visual" material="Body001_material"/>
        <geom class="collision" type="box" pos="-0.00016293494263663888 0.0386246033012867 0.16017907857894897" size="0.32676026225090027 0.20521831512451172 0.01475370954722166" quat="1.0 0.0 0.0 0.0"/>
        <geom class="collision" type="box" pos="-0.00030748944845981896 0.038624562323093414 -0.16079194843769073" size="0.3259720504283905 0.20521825551986694 0.014110074378550053" quat="1.0 0.0 0.0 0.0"/>
        <geom class="collision" type="box" pos="-0.3161245584487915 0.03900117054581642 -0.009116819128394127" size="0.010146103799343109 0.20622709393501282 0.15733598172664642" quat="1.0 0.0 0.0 0.0"/>
        <geom class="collision" type="box" pos="0.24198691546916962 0.03842874616384506 -0.009116818197071552" size="0.08474898338317871 0.20541329681873322 0.15733616054058075" quat="1.0 0.0 0.0 0.0"/>
        <geom class="collision" type="box" pos="-0.00022453791461884975 0.23693059384822845 -0.00021847523748874664" size="0.3266970217227936 0.006912285927683115 0.17488478124141693" quat="1.0 0.0 0.0 0.0"/>
        <geom class="collision" type="box" pos="0.2595246136188507 -0.18159101903438568 0.05348791182041168" size="0.06720907986164093 0.013442549854516983 0.12142477929592133" quat="1.0 0.0 0.0 0.0"/>
        <geom class="collision" type="box" pos="0.2596195936203003 -0.17715835571289062 -0.12140179425477982" size="0.06730376183986664 0.009009863249957561 0.05346515029668808" quat="1.0 0.0 0.0 0.0"/>
        <geom class="collision" type="box" pos="0.31130266189575195 -0.19060537219047546 -0.12140191346406937" size="0.015620670281350613 0.004428177606314421 0.053464990109205246" quat="1.0 0.0 0.0 0.0"/>
        <geom class="collision" type="box" pos="0.20696860551834106 -0.19059166312217712 -0.12140168249607086" size="0.014652776531875134 0.004441662225872278 0.05346501246094704" quat="1.0 0.0 0.0 0.0"/>
        <geom class="collision" type="box" pos="0.25865164399147034 -0.19059975445270538 -0.1623072773218155" size="0.0370304174721241 0.004433778114616871 0.0125596197322011" quat="1.0 0.0 0.0 0.0"/>
        <body name="door">
          <joint axis="0.0 0.0 1.0" pos="-0.3103099465370178 -0.18405452370643616 -9.821634739637375e-05" limited="true" name="microjoint" range="-1.5707963267948966 0.0" type="hinge" damping="1" frictionloss="1" armature=".01" stiffness="0.05"/>
          <geom mesh="door_vis" type="mesh" solimp="0.998 0.998 0.001" solref="0.001 1" friction="0.95 0.3 0.1" class="visual" material="door_material"/>
          <geom class="collision" type="box" pos="-0.059202488511800766 -0.186150923371315 3.386009484529495e-05" size="0.24441814422607422 0.007231732364743948 0.17490069568157196" quat="1.0 0.0 0.0 0.0"/>
          <geom class="collision" type="box" pos="0.17370536923408508 -0.20389440655708313 0.09579389542341232" size="0.006420867517590523 0.01820179633796215 0.006403615232557058" quat="1.0 0.0 0.0 0.0"/>
          <geom class="collision" type="box" pos="0.17370536923408508 -0.20389440655708313 -0.0911797508597374" size="0.006420867517590523 0.01820179633796215 0.006453994195908308" quat="1.0 0.0 0.0 0.0"/>
          <geom class="collision" type="cylinder" pos="0.1737346202135086 -0.23522968590259552 0.0028021996840834618" size="0.010333633981645107 0.15185929834842682" quat="1.0 0.0 0.0 0.0" name="door_handle_main"/>
          <geom class="collision" type="box" pos="-0.059202488511800766 -0.186150923371315 3.386009484529495e-05" size="0.2476932853460312 0.0036931107752025127 0.14038217067718506" quat="1.0 0.0 0.0 0.0"/>
          <geom class="collision" type="box" pos="-0.059202488511800766 -0.18910345435142517 3.386009484529495e-05" size="0.24441814422607422 0.0026239571161568165 0.17490069568157196" quat="1.0 0.0 0.0 0.0" name="door_main"/>
          <body name="door_Clear">
            <geom mesh="door_Clear_vis" type="mesh" solimp="0.998 0.998 0.001" solref="0.001 1" friction="0.95 0.3 0.1" class="visual" material="door_Clear_material"/>
            <geom class="collision" type="box" pos="-0.059202488511800766 -0.186150923371315 3.386009484529495e-05" size="0.2476932853460312 0.0036931107752025127 0.14038217067718506" quat="1.0 0.0 0.0 0.0"/>
          </body>
        </body>
        <body name="Button001">
          <joint axis="0.0 1.0 0.0" pos="0.2570140063762665 -0.19760066270828247 -0.08242230862379074" limited="true" name="Button001_joint" range="0.0 0.003" type="slide" damping="1" frictionloss="1" armature=".01" stiffness="0.05"/>
          <geom mesh="Button001_vis" type="mesh" solimp="0.998 0.998 0.001" solref="0.001 1" friction="0.95 0.3 0.1" class="visual" material="Button001_material"/>
          <geom class="collision" type="box" pos="0.2570140063762665 -0.19683273136615753 -0.08242230117321014" size="0.018102804198861122 0.0008728747488930821 0.005535772070288658" quat="1.0 0.0 0.0 0.0"/>
        </body>
        <body name="Button002">
          <joint axis="0.0 1.0 0.0" pos="0.2570140063762665 -0.19760066270828247 -0.13752494752407074" limited="true" name="Button002_joint" range="0.0 0.003" type="slide" damping="1" frictionloss="1" armature=".01" stiffness="0.05"/>
          <geom mesh="Button002_vis" type="mesh" solimp="0.998 0.998 0.001" solref="0.001 1" friction="0.95 0.3 0.1" class="visual" material="Button002_material"/>
          <geom class="collision" type="box" pos="0.2570140063762665 -0.19683273136615753 -0.13752494752407074" size="0.018102804198861122 0.0008728749235160649 0.005535772070288658" quat="1.0 0.0 0.0 0.0"/>
        </body>
        <body name="Disc001">
          <joint axis="0.0 0.0 1.0" pos="-0.07487017661333084 0.03600551187992096 -0.1442800909280777" limited="false" name="Disc001_joint" range="0 360" type="hinge" damping="1" frictionloss="1" armature=".01" stiffness="0.05"/>
          <geom mesh="Disc001_vis" type="mesh" solimp="0.998 0.998 0.001" solref="0.001 1" friction="0.95 0.3 0.1" class="visual" material="Disc001_material"/>
          <geom class="collision" type="cylinder" pos="-0.0748702883720398 0.03600567579269409 -0.14049065113067627" size="0.17178954184055328 0.0027493364177644253" quat="1.0 0.0 0.0 0.0"/>
        </body>
        <body name="Knob001">
          <joint axis="0.0 1.0 0.0" pos="0.2570140063762665 -0.20813234150409698 -0.007349255494773388" limited="true" name="Knob001_joint" range="0.0 5.235987755982989" type="hinge" damping="0.05" armature="0.001"/>
          <geom mesh="Knob001_vis" type="mesh" solimp="0.998 0.998 0.001" solref="0.001 1" friction="0.95 0.3 0.1" class="visual" material="Knob001_material"/>
          <geom class="collision" type="cylinder" pos="0.2570140063762665 -0.20078666508197784 -0.007349255494773388" size="0.02304663322865963 0.004026531707495451" quat="0.7071068286895752 0.7071067690849304 0.0 0.0"/>
          <geom class="collision" type="box" pos="0.2570140063762665 -0.21293427050113678 -0.007349255494773388" size="0.0047026523388922215 0.008965497836470604 0.01865711621940136" quat="1.0 0.0 0.0 0.0"/>
        </body>
        <geom class="region" name="reg_int" type="box" pos="-0.0749911516904831 0.03155732899904251 0.0028175488114356995" size="0.22615828907489777 0.1925648952126503 0.137911042034626"/>
        <geom class="region" name="reg_main" type="box" pos="0.0 0.022718816995620728 0.0" size="0.3279231915473938 0.22352124547958374 0.17613464391231537"/>
      </body>
    </body>
  </worldbody>
  <actuator>
    <motor name="microjoint_actuator" joint="microjoint" gear="10"/>
    <motor name="Button001_joint_actuator" joint="Button001_joint" gear="0.5"/>
    <motor name="Button002_joint_actuator" joint="Button002_joint" gear="0.5"/>
    <motor name="Disc001_joint_actuator" joint="Disc001_joint" gear="0.5"/>
    <motor name="Knob001_joint_actuator" joint="Knob001_joint" gear="0.5"/>
  </actuator>
</mujoco>
