<?xml version='1.0' encoding='UTF-8'?>
<mujoco model="model">
  <option timestep="0.002" gravity="0.0 0.0 -9.81"/>
  <compiler angle="radian"/>
  <asset>
    <mesh file="visuals/door.obj" name="door_vis"/>
    <mesh file="visuals/knob_temp.obj" name="knob_temp_vis"/>
    <mesh file="visuals/knob_time.obj" name="knob_time_vis"/>
    <mesh file="visuals/rack0.obj" name="rack0_vis"/>
    <mesh file="visuals/rack1.obj" name="rack1_vis"/>
    <mesh file="visuals/Body001.obj" name="Body001_vis"/>
    <mesh file="visuals/Button001.obj" name="Button001_vis"/>
    <mesh file="visuals/window.obj" name="window_vis"/>
    <texture file="visuals/T_BC001.png" name="Body001_material" type="2d"/>
    <material name="Body001_material" rgba="1 1 1 1.0" texture="Body001_material" shininess="0.1" specular="2"/>
    <texture file="visuals/T_BC001.png" name="door_material" type="2d"/>
    <material name="door_material" rgba="1 1 1 1.0" texture="door_material" shininess="0.1" specular="2"/>
    <texture file="visuals/T_BC001.png" name="window_material" type="2d"/>
    <material name="window_material" rgba="1 1 1 0.8799999952316284" texture="window_material" shininess="0.5" specular="0.3103448502657381"/>
    <texture file="visuals/T_BC001.png" name="knob_temp_material" type="2d"/>
    <material name="knob_temp_material" rgba="1 1 1 1.0" texture="knob_temp_material" shininess="0.4472135901451111" specular="0.3103448502657381"/>
    <texture file="visuals/T_BC001.png" name="knob_time_material" type="2d"/>
    <material name="knob_time_material" rgba="1 1 1 1.0" texture="knob_time_material" shininess="0.4472135901451111" specular="0.3103448502657381"/>
    <texture file="visuals/T_BC001.png" name="rack0_material" type="2d"/>
    <material name="rack0_material" rgba="1 1 1 1.0" texture="rack0_material" shininess="0.1" specular="4"/>
    <texture file="visuals/T_BC001.png" name="rack1_material" type="2d"/>
    <material name="rack1_material" rgba="1 1 1 1.0" texture="rack1_material" shininess="0.1" specular="4"/>
    <texture file="visuals/T_BC001.png" name="Button001_material" type="2d"/>
    <material name="Button001_material" rgba="1 1 1 1.0" texture="Button001_material" shininess="0.4472135901451111" specular="0.3103448502657381"/>
  </asset>
  <default>
    <default class="visual">
      <geom conaffinity="0" contype="0" group="1" type="mesh"/>
    </default>
    <default class="collision">
      <geom group="0" rgba="0.5 0 0 0.5"/>
    </default>
    <default class="spawn">
      <geom group="0" rgba="1 1 1 0.5" contype="0" conaffinity="0"/>
      <site group="0" rgba="1 1 1 0.5"/>
    </default>
    <default class="region">
      <geom group="1" conaffinity="0" contype="0" rgba="0 1 0 0"/>
    </default>
  </default>
  <worldbody>
    <body>
      <body name="object">
        <geom mesh="Body001_vis" type="mesh" solimp="0.998 0.998 0.001" solref="0.001 1" friction="0.95 0.3 0.1" class="visual" material="Body001_material"/>
        <geom class="collision" type="box" pos="-0.21388867497444153 0.024633608758449554 0.01936226710677147" size="0.005097392946481705 0.15109364688396454 0.1019260510802269" quat="1.0 0.0 0.0 0.0"/>
        <geom class="collision" type="box" pos="0.0003485039051156491 0.024633608758449554 0.12800443172454834" size="0.21872644126415253 0.15109364688396454 0.004818652756512165" quat="1.0 0.0 0.0 0.0"/>
        <geom class="collision" type="box" pos="0.18478648364543915 0.024633608758449554 -0.005674505606293678" size="0.04508014768362045 0.15109364688396454 0.1269628256559372" quat="1.0 0.0 0.0 0.0"/>
        <geom class="collision" type="box" pos="0.0003485038469079882 0.024559304118156433 -0.10282242298126221" size="0.19078472256660461 0.15116684138774872 0.010271656326949596" quat="1.0 0.0 0.0 0.0"/>
        <geom class="collision" type="box" pos="0.00465347757562995 0.17561514675617218 0.012308325618505478" size="0.21260076761245728 0.004715824965387583 0.1177997961640358" quat="1.0 0.0 0.0 0.0"/>
        <geom class="collision" type="box" pos="-0.21128518879413605 0.0403459295630455 -0.10771039128303528" size="0.021700631827116013 0.1353817880153656 0.024899370968341827" quat="1.0 0.0 0.0 0.0"/>
        <geom class="collision" type="box" pos="0.1295267641544342 0.026771117001771927 0.03681083768606186" size="0.009109459817409515 0.1222139224410057 0.0011643223697319627" quat="1.0 0.0 0.0 0.0"/>
        <geom class="collision" type="box" pos="0.1295267641544342 0.026771117001771927 -0.03029731661081314" size="0.009109459817409515 0.1222139224410057 0.0011643223697319627" quat="1.0 0.0 0.0 0.0"/>
        <geom class="collision" type="box" pos="-0.19369499385356903 0.026771117001771927 -0.03029731661081314" size="0.009109459817409515 0.1222139224410057 0.0011643223697319627" quat="1.0 0.0 0.0 0.0"/>
        <geom class="collision" type="box" pos="-0.19369499385356903 0.026771117001771927 0.03681083768606186" size="0.009109459817409515 0.1222139224410057 0.0011643223697319627" quat="1.0 0.0 0.0 0.0"/>
        <body name="door">
          <joint axis="1.0 0.0 0.0" pos="-0.033929310739040375 -0.12793278694152832 -0.08867983520030975" limited="true" name="door_joint" range="0.0 1.5707963267948966" type="hinge" damping="1" frictionloss="1" armature=".01" stiffness="0.5" springref="-0.2"/>
          <geom mesh="door_vis" type="mesh" solimp="0.998 0.998 0.001" solref="0.001 1" friction="0.95 0.3 0.1" class="visual" material="door_material"/>
          <geom class="collision" type="box" pos="-0.033796943724155426 -0.12656928598880768 0.013413598760962486" size="0.16915710270404816 0.0014045265270397067 0.09980838000774384" quat="1.0 0.0 0.0 0.0" name="door_main"/>
          <geom class="collision" type="box" pos="-0.1908259242773056 -0.15587416291236877 0.10044907033443451" size="0.009960582479834557 0.02580532617866993 0.014558535069227219" quat="0.9938510060310364 -0.11072570830583572 0.0 0.0"/>
          <geom class="collision" type="box" pos="0.12117913365364075 -0.15587416291236877 0.10044907033443451" size="0.009960582479834557 0.02580532617866993 0.014558535069227219" quat="0.9938510060310364 -0.11072570830583572 0.0 0.0"/>
          <geom class="collision" type="box" pos="-0.0334632508456707 -0.17135095596313477 0.10360601544380188" size="0.010575702413916588 0.010575702413916588 0.1418868452310562" quat="0.7071068286895752 -0.0 0.7071067690849304 0.0" name="door_handle_main"/>
          <body name="window">
            <geom mesh="window_vis" type="mesh" solimp="0.998 0.998 0.001" solref="0.001 1" friction="0.95 0.3 0.1" class="visual" material="window_material"/>
            <geom class="collision" type="box" pos="-0.03869171440601349 -0.12665095925331116 0.016832157969474792" size="0.1437849998474121 0.001322838244959712 0.07191884517669678" quat="1.0 0.0 0.0 0.0"/>
          </body>
        </body>
        <body name="knob_temp">
          <joint axis="0.0 1.0 0.0" pos="0.17760075628757477 -0.1364355981349945 -0.017171379178762436" limited="true" name="knob_temp_joint" range="0.0 3.2288591161895095" type="hinge" damping="0.05" armature="0.001"/>
          <geom mesh="knob_temp_vis" type="mesh" solimp="0.998 0.998 0.001" solref="0.001 1" friction="0.95 0.3 0.1" class="visual" material="knob_temp_material"/>
          <geom class="collision" type="cylinder" pos="0.17776861786842346 -0.13182459771633148 -0.017217790707945824" size="0.02046120911836624 0.002508010948076844" quat="0.7071068286895752 0.7071067690849304 0.0 0.0"/>
          <geom class="collision" type="box" pos="0.17746473848819733 -0.14123669266700745 -0.017171189188957214" size="0.015455257147550583 0.007103573996573687 0.004262663424015045" quat="1.0 0.0 0.0 0.0" name="knob_temp_main"/>
        </body>
        <body name="knob_time">
          <joint axis="0.0 1.0 0.0" pos="0.17868000268936157 -0.1364355981349945 0.08212599903345108" limited="true" name="knob_time_joint" range="0.0 5.497787143782138" type="hinge" damping="0.05" armature="0.001"/>
          <geom mesh="knob_time_vis" type="mesh" solimp="0.998 0.998 0.001" solref="0.001 1" friction="0.95 0.3 0.1" class="visual" material="knob_time_material"/>
          <geom class="collision" type="cylinder" pos="0.17856664955615997 -0.13182459771633148 0.08204465359449387" size="0.020150480791926384 0.002394000068306923" quat="0.7071068286895752 0.7071067690849304 0.0 0.0"/>
          <geom class="collision" type="box" pos="0.17866390943527222 -0.14123669266700745 0.08204598724842072" size="0.015455257147550583 0.007103573996573687 0.004262663424015045" quat="0.38268330693244934 0.0 0.9238795638084412 0.0" name="knob_time_main"/>
        </body>
        <body name="rack0">
          <geom class="region" name="reg_rack0" type="box" pos="-0.03182778134942055 0.013169333338737488 0.005198134109377861" size="0.1535549702346325 0.08781841939687729 0.030273038730025292"/>
          <joint axis="0.0 -1.0 0.0" pos="-0.03397946432232857 0.012722387909889221 -0.025537166744470596" limited="true" name="rack0_joint" range="0.0 0.15" type="slide" damping="1" frictionloss="1" armature=".01" stiffness="0.05"/>
          <geom mesh="rack0_vis" type="mesh" solimp="0.998 0.998 0.001" solref="0.001 1" friction="0.95 0.3 0.1" class="visual" material="rack0_material"/>
          <geom class="collision" type="box" pos="-0.033648520708084106 0.0139149259775877 -0.02599250338971615" size="0.16542015969753265 0.08682708442211151 0.0009401241550222039" quat="1.0 0.0 0.0 0.0"/>
        </body>
        <body name="rack1">
          <geom class="region" name="reg_rack1" type="box" pos="-0.03182778134942055 0.013169333338737488 0.0809216108173132" size="0.1535549702346325 0.08781841939687729 0.03795068694651127"/>
          <joint axis="0.0 -1.0 0.0" pos="-0.03397946432232857 0.012722387909889221 0.0423637293279171" limited="true" name="rack1_joint" range="0.0 0.15" type="slide" damping="1" frictionloss="1" armature=".01" stiffness="0.05"/>
          <geom mesh="rack1_vis" type="mesh" solimp="0.998 0.998 0.001" solref="0.001 1" friction="0.95 0.3 0.1" class="visual" material="rack1_material"/>
          <geom class="collision" type="box" pos="-0.03534368425607681 0.011622956022620201 0.0407845713198185" size="0.16372498869895935 0.08707385510206223 0.002469924744218588" quat="1.0 0.0 0.0 0.0"/>
        </body>
        <body name="Button001">
          <joint axis="0.0 1.0 0.0" pos="0.17780716717243195 -0.13106781244277954 -0.05901690572500229" limited="true" name="Button001_joint" range="0.0 0.002" type="slide" damping="1" frictionloss="1" armature=".01" stiffness="0.05"/>
          <geom mesh="Button001_vis" type="mesh" solimp="0.998 0.998 0.001" solref="0.001 1" friction="0.95 0.3 0.1" class="visual" material="Button001_material"/>
          <geom class="collision" type="box" pos="0.17810724675655365 -0.13366685807704926 -0.05904971435666084" size="0.014250644482672215 0.00359069905243814 0.005966955330222845" quat="1.0 0.0 0.0 0.0"/>
        </body>
        <geom class="region" name="reg_int" type="box" pos="-0.03182778134942055 0.016870960593223572 0.017591457813978195" size="0.1535549702346325 0.13116878068447113 0.10124094954133034"/>
        <geom class="region" name="reg_main" type="box" pos="-3.725290298461914e-09 0.026178568601608276 0.0" size="0.23398580944538117 0.15515236353874207 0.13382307982444763"/>
      </body>
    </body>
  </worldbody>
  <actuator>
    <motor name="door_joint_actuator" joint="door_joint" gear="50"/>
    <motor name="knob_temp_joint_actuator" joint="knob_temp_joint" gear="50"/>
    <motor name="knob_time_joint_actuator" joint="knob_time_joint" gear="50"/>
    <motor name="rack0_joint_actuator" joint="rack0_joint" gear="50"/>
    <motor name="rack1_joint_actuator" joint="rack1_joint" gear="50"/>
    <motor name="Button001_joint_actuator" joint="Button001_joint" gear="0.5"/>
  </actuator>
</mujoco>
