<?xml version='1.0' encoding='UTF-8'?>
<mujoco model="model">
  <option timestep="0.002" gravity="0.0 0.0 -9.81"/>
  <compiler angle="radian"/>
  <asset>
    <mesh file="visuals/freezer0.obj" name="freezer0_vis"/>
    <mesh file="visuals/freezer1.obj" name="freezer1_vis"/>
    <mesh file="visuals/fridge_drawer0.obj" name="fridge_drawer0_vis"/>
    <mesh file="visuals/fridge_left_door.obj" name="fridge_left_door_vis"/>
    <mesh file="visuals/fridge_left_door_Clear.obj" name="fridge_left_door_Clear_vis"/>
    <mesh file="visuals/fridge_right_door.obj" name="fridge_right_door_vis"/>
    <mesh file="visuals/fridge_right_door_Clear.obj" name="fridge_right_door_Clear_vis"/>
    <mesh file="visuals/Body001.obj" name="Body001_vis"/>
    <mesh file="visuals/Body001_Clear.obj" name="Body001_Clear_vis"/>
    <texture file="visuals/T_BC001.png" name="Body001_material" type="2d"/>
    <material name="Body001_material" rgba="1 1 1 1.0" texture="Body001_material" shininess="2" specular="2"/>
    <texture file="visuals/T_BC001.png" name="freezer0_material" type="2d"/>
    <material name="freezer0_material" rgba="1 1 1 1.0" texture="freezer0_material" shininess="2" specular="2"/>
    <texture file="visuals/T_BC001.png" name="freezer1_material" type="2d"/>
    <material name="freezer1_material" rgba="1 1 1 1.0" texture="freezer1_material" shininess="2" specular="2"/>
    <texture file="visuals/T_BC001.png" name="fridge_drawer0_material" type="2d"/>
    <material name="fridge_drawer0_material" rgba="1 1 1 1.0" texture="fridge_drawer0_material" shininess="0.141421377658844" specular="0.3103448502657381"/>
    <texture file="visuals/T_BC001.png" name="fridge_left_door_material" type="2d"/>
    <material name="fridge_left_door_material" rgba="1 1 1 1.0" texture="fridge_left_door_material" shininess="2" specular="2"/>
    <texture file="visuals/T_BC001.png" name="fridge_left_door_Clear_material" type="2d"/>
    <material name="fridge_left_door_Clear_material" rgba="1 1 1 0.699999988079071" texture="fridge_left_door_Clear_material" shininess="0.141421377658844" specular="0.3103448502657381"/>
    <texture file="visuals/T_BC001.png" name="fridge_right_door_material" type="2d"/>
    <material name="fridge_right_door_material" rgba="1 1 1 1.0" texture="fridge_right_door_material" shininess="2" specular="2"/>
    <texture file="visuals/T_BC001.png" name="fridge_right_door_Clear_material" type="2d"/>
    <material name="fridge_right_door_Clear_material" rgba="1 1 1 0.699999988079071" texture="fridge_right_door_Clear_material" shininess="0.141421377658844" specular="0.3103448502657381"/>
    <texture file="visuals/T_BC001.png" name="Body001_Clear_material" type="2d"/>
    <material name="Body001_Clear_material" rgba="1 1 1 0.699999988079071" texture="Body001_Clear_material" shininess="0.141421377658844" specular="0.3103448502657381"/>
  </asset>
  <default>
    <default class="visual">
      <geom conaffinity="0" contype="0" group="1" type="mesh"/>
    </default>
    <default class="collision">
      <geom group="0" rgba="0.5 0 0 0.5"/>
    </default>
    <default class="spawn">
      <geom group="0" rgba="1 1 1 0.5" contype="0" conaffinity="0"/>
      <site group="0" rgba="1 1 1 0.5"/>
    </default>
    <default class="region">
      <geom group="1" conaffinity="0" contype="0" rgba="0 1 0 0"/>
    </default>
  </default>
  <worldbody>
    <body>
      <body name="object">
        <geom mesh="Body001_vis" type="mesh" solimp="0.998 0.998 0.001" solref="0.001 1" friction="0.95 0.3 0.1" class="visual" material="Body001_material"/>
        <geom class="collision" type="box" pos="-0.00000500 0.09229907 0.57492310" size="0.3865222930908203 0.25105828046798706 0.00804629921913147" quat="7.907536314633035e-07 0.0 0.0 1.0"/>
        <geom class="collision" type="box" pos="-0.00000500 0.09229907 0.18067828" size="0.3865222930908203 0.25105828046798706 0.008046314120292664" quat="7.907536314633035e-07 0.0 0.0 1.0"/>
        <geom class="collision" type="box" pos="-0.00000777 0.07838923 0.93401116" size="0.41649341583251953 0.32925528287887573 0.014988978393375874" quat="1.0 0.0 0.0 0.0"/>
        <geom class="collision" type="box" pos="-0.40176218 0.07838858 -0.00386390" size="0.014738986268639565 0.32925575971603394 0.9433139562606812" quat="1.0 0.0 0.0 0.0"/>
        <geom class="collision" type="box" pos="0.40152237 0.07838842 -0.00386390" size="0.014963148161768913 0.3292555809020996 0.9433139562606812" quat="1.0 0.0 0.0 0.0"/>
        <geom class="collision" type="box" pos="-0.00005920 0.07838900 -0.19218449" size="0.4164549708366394 0.32925504446029663 0.032401636242866516" quat="1.0 0.0 0.0 0.0"/>
        <geom class="collision" type="box" pos="-0.00005981 0.07838906 -0.54202980" size="0.41645556688308716 0.329255074262619 0.0348663255572319" quat="1.0 0.0 0.0 0.0"/>
        <geom class="collision" type="box" pos="-0.00006677 0.38919809 0.00091116" size="0.4164625108242035 0.01844640076160431 0.9480890035629272" quat="1.0 0.0 0.0 0.0"/>
        <geom class="collision" type="box" pos="-0.00008013 -0.15216632 0.18067828" size="0.39623501896858215 0.007086039055138826 0.008046308532357216" quat="1.0 0.0 0.0 0.0"/>
        <geom class="collision" type="box" pos="-0.00008013 0.34259105 0.18067828" size="0.3962337374687195 0.020284226164221764 0.008046307601034641" quat="1.0 0.0 0.0 0.0"/>
        <geom class="collision" type="box" pos="-0.00008013 -0.15216632 0.57492304" size="0.396234929561615 0.007086039055138826 0.008046306669712067" quat="1.0 0.0 0.0 0.0"/>
        <geom class="collision" type="box" pos="-0.00008013 0.34259105 0.57492304" size="0.3962337374687195 0.020284226164221764 0.008046305738389492" quat="1.0 0.0 0.0 0.0"/>
        <geom class="collision" type="box" pos="-0.00006001 0.07838959 -0.93533456" size="0.4164552092552185 0.3292548656463623 0.013665575534105301" quat="1.0 0.0 0.0 0.0"/>
        <body name="freezer0">
          <geom class="region" name="reg_freezer0" type="box" pos="-2.6024999999985088e-05 -0.007402619999999999 -0.733692945" size="0.344893365 0.2408342 0.134862315"/>
          <joint axis="0.0 -1.0 0.0" pos="0.00002935 -0.07678489 -0.74568111" limited="true" name="freezer0_door_joint" range="0.0 0.45" type="slide" damping="1" frictionloss="1" armature=".01" stiffness="0.05"/>
          <geom mesh="freezer0_vis" type="mesh" solimp="0.998 0.998 0.001" solref="0.001 1" friction="0.95 0.3 0.1" class="visual" material="freezer0_material"/>
          <geom class="collision" type="box" pos="0.00000898 -0.30273789 -0.74586034" size="0.4164569675922394 0.04146213456988335 0.19742357730865479" quat="1.0 0.0 0.0 0.0"/>
          <geom class="collision" type="box" pos="0.00012476 0.24489823 -0.73623079" size="0.37471258640289307 0.006229674909263849 0.14289504289627075" quat="1.0 0.0 0.0 0.0"/>
          <geom class="collision" type="box" pos="0.00012476 -0.00452843 -0.88003427" size="0.37471258640289307 0.25812333822250366 0.006092144642025232" quat="1.0 0.0 0.0 0.0"/>
          <geom class="collision" type="box" pos="-0.36229586 -0.00440892 -0.73842365" size="0.012077601626515388 0.2581234276294708 0.1450880467891693" quat="1.0 0.0 0.0 0.0"/>
          <geom class="collision" type="box" pos="0.36205000 0.00041294 -0.73765224" size="0.012077481485903263 0.2581234574317932 0.14431658387184143" quat="1.0 0.0 0.0 0.0"/>
          <geom class="collision" type="cylinder" pos="0.28619952 -0.36209306 -0.59203577" size="0.005370182916522026 0.02105906419456005" quat="0.5 0.5 0.4999999701976776 -0.5" name="freezer0_door_handle_1"/>
          <geom class="collision" type="cylinder" pos="-0.28642725 -0.36209306 -0.59192932" size="0.005370182916522026 0.02105906419456005" quat="0.5 0.5 0.4999999701976776 -0.5" name="freezer0_door_handle_2"/>
          <geom class="collision" type="cylinder" pos="-0.00080416 -0.39213988 -0.59188688" size="0.011875895783305168 0.30248749256134033" quat="0.7071068286895752 1.2101620150417602e-08 0.7071067690849304 -1.2101619262239183e-08" name="freezer0_door_handle_main"/>
          <geom class="collision" type="box" pos="0.00012476 -0.33555222 -0.74580020" size="0.41660720109939575 0.0073650432750582695 0.19748368859291077" quat="1.0 0.0 0.0 0.0" name="freezer0_door_main"/>
        </body>
        <body name="freezer1">
          <geom class="region" name="reg_freezer1" type="box" pos="-2.6024999999985088e-05 -0.007402619999999999 -0.357985345" size="0.344893365 0.2408342 0.11676831500000001"/>
          <joint axis="0.0 -1.0 0.0" pos="0.00002937 -0.07678489 -0.36917987" limited="true" name="freezer1_door_joint" range="0.0 0.45" type="slide" damping="1" frictionloss="1" armature=".01" stiffness="0.05"/>
          <geom mesh="freezer1_vis" type="mesh" solimp="0.998 0.998 0.001" solref="0.001 1" friction="0.95 0.3 0.1" class="visual" material="freezer1_material"/>
          <geom class="collision" type="box" pos="0.00000901 -0.30273789 -0.36922628" size="0.41645699739456177 0.04146212711930275 0.16630305349826813" quat="1.0 0.0 0.0 0.0"/>
          <geom class="collision" type="box" pos="-0.00012301 0.24489835 -0.36400971" size="0.3742504417896271 0.006229751743376255 0.12733876705169678" quat="1.0 0.0 0.0 0.0"/>
          <geom class="collision" type="box" pos="-0.00012291 -0.00576176 -0.48559526" size="0.3742504119873047 0.25688987970352173 0.00671402458101511" quat="1.0 0.0 0.0 0.0"/>
          <geom class="collision" type="box" pos="-0.36229583 -0.00677354 -0.36449009" size="0.012077567167580128 0.25790175795555115 0.12781912088394165" quat="1.0 0.0 0.0 0.0"/>
          <geom class="collision" type="box" pos="0.36204982 -0.00574673 -0.36449015" size="0.012077613733708858 0.25687485933303833 0.12781918048858643" quat="1.0 0.0 0.0 0.0"/>
          <geom class="collision" type="cylinder" pos="-0.28642725 -0.36209306 -0.24844496" size="0.005370182916522026 0.02105906419456005" quat="0.5 0.5 0.4999999701976776 -0.5" name="freezer1_door_handle_1"/>
          <geom class="collision" type="cylinder" pos="0.28619952 -0.36209306 -0.24855144" size="0.005370182916522026 0.02105906419456005" quat="0.5 0.5 0.4999999701976776 -0.5" name="freezer1_door_handle_2"/>
          <geom class="collision" type="cylinder" pos="-0.00080416 -0.39213988 -0.24840255" size="0.011875895783305168 0.30248749256134033" quat="0.7071068286895752 1.2101620150417602e-08 0.7071067690849304 -1.2101619262239183e-08" name="freezer1_door_handle_main"/>
          <geom class="collision" type="box" pos="0.00012476 -0.33555222 -0.36854529" size="0.41660720109939575 0.0073650432750582695 0.1657266914844513" quat="1.0 0.0 0.0 0.0" name="freezer1_door_main"/>
        </body>
        <body name="fridge_drawer0">
          <geom class="region" name="reg_fridge_drawer0" type="box" pos="0.0006514350000000058 0.059609099999999984 0.008021225" size="0.240148225 0.24819636 0.11190556500000001"/>
          <joint axis="0.0 -1.0 0.0" pos="-0.00012377 0.05742796 -0.00747948" limited="true" name="fridge_drawer0_joint" range="0.0 0.45" type="slide" damping="1" frictionloss="1" armature=".01" stiffness="0.05"/>
          <geom mesh="fridge_drawer0_vis" type="mesh" solimp="0.998 0.998 0.001" solref="0.001 1" friction="0.95 0.3 0.1" class="visual" material="fridge_drawer0_material"/>
          <geom class="collision" type="box" pos="0.00009464 -0.21360207 0.11129444" size="0.24822469055652618 0.010727659799158573 0.015751799568533897" quat="1.0 0.0 0.0 0.0"/>
          <geom class="collision" type="box" pos="-0.27585816 0.05801702 -0.00686345" size="0.025742271915078163 0.2861771881580353 0.13409139215946198" quat="1.0 0.0 0.0 0.0"/>
          <geom class="collision" type="box" pos="-0.00082589 0.33109656 -0.00686345" size="0.24606665968894958 0.014968637377023697 0.13409285247325897" quat="1.0 0.0 0.0 0.0"/>
          <geom class="collision" type="box" pos="-0.00170093 0.05468362 -0.12610245" size="0.29805031418800354 0.28284740447998047 0.01615889184176922" quat="1.0 0.0 0.0 0.0"/>
          <geom class="collision" type="box" pos="0.00009464 -0.22601292 0.09873659" size="0.24822473526000977 0.0026132056955248117 0.028008803725242615" quat="1.0 0.0 0.0 0.0"/>
          <geom class="collision" type="box" pos="0.00009464 -0.21557903 -0.04496174" size="0.24822278320789337 0.012643336318433285 0.05312157794833183" quat="1.0 0.0 0.0 0.0"/>
          <geom class="collision" type="box" pos="0.00009464 -0.20079246 0.01509019" size="0.24822473526000977 0.0023075242061167955 0.111183762550354" quat="1.0 0.0 0.0 0.0"/>
          <geom class="collision" type="box" pos="0.21229011 -0.21352637 0.06040787" size="0.03714979439973831 0.015225662849843502 0.0505049042403698" quat="1.0 0.0 0.0 0.0"/>
          <geom class="collision" type="box" pos="0.27584130 0.05799255 -0.00686345" size="0.025972966104745865 0.28615522384643555 0.13409239053726196" quat="1.0 0.0 0.0 0.0"/>
          <geom class="collision" type="box" pos="-0.00192049 -0.20153016 0.05372828" size="0.1784302145242691 0.003469259012490511 0.04872036352753639" quat="1.0 0.0 0.0 0.0"/>
          <geom class="collision" type="box" pos="-0.21560978 -0.21352637 0.06040787" size="0.03714979439973831 0.015225747600197792 0.05050506815314293" quat="1.0 0.0 0.0 0.0"/>
        </body>
        <body name="fridge_left_door">
          <joint axis="0.0 0.0 -1.0" pos="-0.37535121 -0.30750814 0.38153228" limited="true" name="fridge_left_door_joint" range="0.0 1.5707963267948966" type="hinge" damping="1" frictionloss="1" armature=".01" stiffness="0.05"/>
          <geom mesh="fridge_left_door_vis" type="mesh" solimp="0.998 0.998 0.001" solref="0.001 1" friction="0.95 0.3 0.1" class="visual" material="fridge_left_door_material"/>
          <geom class="collision" type="cylinder" pos="-0.06425043 -0.36526123 0.59618366" size="0.005370182916522026 0.02105906419456005" quat="0.7071067094802856 0.70710688829422 -1.5700925641616852e-16 -1.247691989981498e-24" name="fridge_left_door_handle_1"/>
          <geom class="collision" type="cylinder" pos="-0.06425043 -0.36526123 0.02358168" size="0.005370182916522026 0.02105906419456005" quat="0.7071067094802856 0.70710688829422 -1.5700925641616852e-16 -1.247691989981498e-24" name="fridge_left_door_handle_2"/>
          <geom class="collision" type="cylinder" pos="-0.06439940 -0.39530805 0.30975339" size="0.011875895783305168 0.30248749256134033" quat="1.0 0.0 0.0 0.0" name="fridge_left_door_handle_main"/>
          <geom class="collision" type="box" pos="-0.19734033 -0.33534917 0.37613836" size="0.193319633603096 0.00827835500240326 0.5620813965797424" quat="1.0 0.0 0.0 0.0" name="fridge_left_door_main"/>
          <geom class="collision" type="box" pos="-0.20349256 -0.21271853 0.82866931" size="0.17405283451080322 0.003400996793061495 0.0340593047440052" quat="0.9986742734909058 0.05147518590092659 -1.1429785662452561e-17 -1.0327812330655537e-24"/>
          <geom class="collision" type="box" pos="-0.20349256 -0.22922479 0.79759383" size="0.17405283451080322 0.02237233892083168 0.003458016784861684" quat="1.0 0.0 0.0 0.0"/>
          <geom class="collision" type="box" pos="-0.37654307 -0.25070798 0.82979667" size="0.03272543102502823 0.003400996793061495 0.043013185262680054" quat="0.47605305910110474 0.5228517055511475 -0.5216343998908997 0.4773856997489929"/>
          <geom class="collision" type="box" pos="-0.03086848 -0.23877546 0.83088648" size="0.03272542729973793 0.0034009963274002075 0.029008248820900917" quat="0.47605258226394653 0.5228517651557922 -0.5216347575187683 0.4773857593536377"/>
          <geom class="collision" type="box" pos="-0.20349256 -0.21153781 0.39291659" size="0.17405283451080322 0.003400996793061495 0.0340593047440052" quat="0.9986742734909058 0.05147518590092659 -1.1429785662452561e-17 -1.0327812330655537e-24"/>
          <geom class="collision" type="box" pos="-0.20349256 -0.22804406 0.36184111" size="0.17405283451080322 0.022372335195541382 0.003458016784861684" quat="1.0 0.0 0.0 0.0"/>
          <geom class="collision" type="box" pos="-0.37656166 -0.24226187 0.39470753" size="0.03272542729973793 0.003400996793061495 0.03316066041588783" quat="0.47605347633361816 0.5228511095046997 -0.5216351747512817 0.47738516330718994"/>
          <geom class="collision" type="box" pos="-0.03088708 -0.23032935 0.39579734" size="0.03272542357444763 0.003400996560230851 0.022363685071468353" quat="0.47605326771736145 0.5228512287139893 -0.5216350555419922 0.4773852825164795"/>
          <geom class="collision" type="box" pos="-0.19734033 -0.31316757 0.37613836" size="0.193319633603096 0.031898852437734604 0.5620813965797424" quat="1.0 0.0 0.0 0.0"/>
          <geom class="collision" type="box" pos="-0.18746745 -0.26777858 0.38717163" size="0.165060892701149 0.012230315245687962 0.532565176486969" quat="1.0 0.0 0.0 0.0"/>
          <body name="fridge_left_door_Clear">
            <geom mesh="fridge_left_door_Clear_vis" type="mesh" solimp="0.998 0.998 0.001" solref="0.001 1" friction="0.95 0.3 0.1" class="visual" material="fridge_left_door_Clear_material"/>
            <geom class="collision" type="box" pos="-0.20349256 -0.21271853 0.82866931" size="0.17405283451080322 0.003400996793061495 0.0340593047440052" quat="0.9986742734909058 0.05147518590092659 -1.1429785662452561e-17 -1.0327812330655537e-24"/>
            <geom class="collision" type="box" pos="-0.20349256 -0.22922479 0.79759383" size="0.17405283451080322 0.02237233892083168 0.003458016784861684" quat="1.0 0.0 0.0 0.0"/>
            <geom class="collision" type="box" pos="-0.37654307 -0.25070798 0.82979667" size="0.03272543102502823 0.003400996793061495 0.043013185262680054" quat="0.47605305910110474 0.5228517055511475 -0.5216343998908997 0.4773856997489929"/>
            <geom class="collision" type="box" pos="-0.03086848 -0.23877546 0.83088648" size="0.03272542729973793 0.0034009963274002075 0.029008248820900917" quat="0.47605258226394653 0.5228517651557922 -0.5216347575187683 0.4773857593536377"/>
            <geom class="collision" type="box" pos="-0.20349256 -0.21153781 0.39291659" size="0.17405283451080322 0.003400996793061495 0.0340593047440052" quat="0.9986742734909058 0.05147518590092659 -1.1429785662452561e-17 -1.0327812330655537e-24"/>
            <geom class="collision" type="box" pos="-0.20349256 -0.22804406 0.36184111" size="0.17405283451080322 0.022372335195541382 0.003458016784861684" quat="1.0 0.0 0.0 0.0"/>
            <geom class="collision" type="box" pos="-0.37656166 -0.24226187 0.39470753" size="0.03272542729973793 0.003400996793061495 0.03316066041588783" quat="0.47605347633361816 0.5228511095046997 -0.5216351747512817 0.47738516330718994"/>
            <geom class="collision" type="box" pos="-0.03088708 -0.23032935 0.39579734" size="0.03272542357444763 0.003400996560230851 0.022363685071468353" quat="0.47605326771736145 0.5228512287139893 -0.5216350555419922 0.4773852825164795"/>
          </body>
        </body>
        <body name="fridge_right_door">
          <joint axis="0.0 0.0 1.0" pos="0.37534545 -0.30750802 0.38152799" limited="true" name="fridge_right_door_joint" range="0.0 1.5707963267948966" type="hinge" damping="1" frictionloss="1" armature=".01" stiffness="0.05"/>
          <geom mesh="fridge_right_door_vis" type="mesh" solimp="0.998 0.998 0.001" solref="0.001 1" friction="0.95 0.3 0.1" class="visual" material="fridge_right_door_material"/>
          <geom class="collision" type="cylinder" pos="0.06649378 -0.36526123 0.59618366" size="0.005370182916522026 0.02105906419456005" quat="0.7071067094802856 0.70710688829422 -1.5700925641616852e-16 -1.247691989981498e-24" name="fridge_right_door_handle_1"/>
          <geom class="collision" type="cylinder" pos="0.06638730 -0.36526123 0.02358168" size="0.005370182916522026 0.02105906419456005" quat="0.7071067094802856 0.70710688829422 -1.5700925641616852e-16 -1.247691989981498e-24" name="fridge_right_door_handle_2"/>
          <geom class="collision" type="cylinder" pos="0.06634489 -0.39530805 0.30975339" size="0.011875895783305168 0.30248749256134033" quat="1.0 0.0 0.0 0.0" name="fridge_right_door_handle_main"/>
          <geom class="collision" type="box" pos="0.20093859 -0.33531287 0.37600929" size="0.18959581851959229 0.00838713999837637 0.5622107982635498" quat="1.0 0.0 0.0 0.0" name="fridge_right_door_main"/>
          <geom class="collision" type="box" pos="0.20954176 -0.21271853 0.82866931" size="0.16922004520893097 0.003400996793061495 0.0340593047440052" quat="0.9986742734909058 0.05147518590092659 -1.1429785662452561e-17 -1.0327812330655537e-24"/>
          <geom class="collision" type="box" pos="0.20954176 -0.22922479 0.79759383" size="0.16922004520893097 0.022372325882315636 0.003458016784861684" quat="1.0 0.0 0.0 0.0"/>
          <geom class="collision" type="box" pos="0.04129568 -0.23965357 0.83080631" size="0.03272542729973793 0.0034009963274002075 0.029008248820900917" quat="0.47605258226394653 0.5228517651557922 -0.5216347575187683 0.4773857593536377"/>
          <geom class="collision" type="box" pos="0.37712566 -0.24982986 0.82987684" size="0.03272543102502823 0.003400996793061495 0.043013185262680054" quat="0.47605305910110474 0.5228517055511475 -0.5216343998908997 0.4773856997489929"/>
          <geom class="collision" type="box" pos="0.20954176 -0.21153781 0.39291659" size="0.16922004520893097 0.003400996793061495 0.0340593047440052" quat="0.9986742734909058 0.05147518590092659 -1.1429785662452561e-17 -1.0327812330655537e-24"/>
          <geom class="collision" type="box" pos="0.20954176 -0.22804406 0.36184111" size="0.16922004520893097 0.022372322157025337 0.003458016784861684" quat="1.0 0.0 0.0 0.0"/>
          <geom class="collision" type="box" pos="0.04127708 -0.23120746 0.39571717" size="0.03272542357444763 0.003400996560230851 0.022363685071468353" quat="0.47605326771736145 0.5228512287139893 -0.5216350555419922 0.4773852825164795"/>
          <geom class="collision" type="box" pos="0.37785817 -0.24138376 0.39478770" size="0.03272542729973793 0.003400996793061495 0.03316066041588783" quat="0.47605347633361816 0.5228511095046997 -0.5216351747512817 0.47738516330718994"/>
          <geom class="collision" type="box" pos="0.20093859 -0.31288803 0.37600929" size="0.18959581851959229 0.032178349792957306 0.5622107982635498" quat="1.0 0.0 0.0 0.0"/>
          <geom class="collision" type="box" pos="0.19030721 -0.26777858 0.38717163" size="0.1607256531715393 0.012230283580720425 0.5325640439987183" quat="1.0 0.0 0.0 0.0"/>
          <body name="fridge_right_door_Clear">
            <geom mesh="fridge_right_door_Clear_vis" type="mesh" solimp="0.998 0.998 0.001" solref="0.001 1" friction="0.95 0.3 0.1" class="visual" material="fridge_right_door_Clear_material"/>
            <geom class="collision" type="box" pos="0.20954176 -0.21271853 0.82866931" size="0.16922004520893097 0.003400996793061495 0.0340593047440052" quat="0.9986742734909058 0.05147518590092659 -1.1429785662452561e-17 -1.0327812330655537e-24"/>
            <geom class="collision" type="box" pos="0.20954176 -0.22922479 0.79759383" size="0.16922004520893097 0.022372325882315636 0.003458016784861684" quat="1.0 0.0 0.0 0.0"/>
            <geom class="collision" type="box" pos="0.04129568 -0.23965357 0.83080631" size="0.03272542729973793 0.0034009963274002075 0.029008248820900917" quat="0.47605258226394653 0.5228517651557922 -0.5216347575187683 0.4773857593536377"/>
            <geom class="collision" type="box" pos="0.37712566 -0.24982986 0.82987684" size="0.03272543102502823 0.003400996793061495 0.043013185262680054" quat="0.47605305910110474 0.5228517055511475 -0.5216343998908997 0.4773856997489929"/>
            <geom class="collision" type="box" pos="0.20954176 -0.21153781 0.39291659" size="0.16922004520893097 0.003400996793061495 0.0340593047440052" quat="0.9986742734909058 0.05147518590092659 -1.1429785662452561e-17 -1.0327812330655537e-24"/>
            <geom class="collision" type="box" pos="0.20954176 -0.22804406 0.36184111" size="0.16922004520893097 0.022372322157025337 0.003458016784861684" quat="1.0 0.0 0.0 0.0"/>
            <geom class="collision" type="box" pos="0.04127708 -0.23120746 0.39571717" size="0.03272542357444763 0.003400996560230851 0.022363685071468353" quat="0.47605326771736145 0.5228512287139893 -0.5216350555419922 0.4773852825164795"/>
            <geom class="collision" type="box" pos="0.37785817 -0.24138376 0.39478770" size="0.03272542729973793 0.003400996793061495 0.03316066041588783" quat="0.47605347633361816 0.5228511095046997 -0.5216351747512817 0.47738516330718994"/>
          </body>
        </body>
        <body name="Body001_Clear">
          <geom mesh="Body001_Clear_vis" type="mesh" solimp="0.998 0.998 0.001" solref="0.001 1" friction="0.95 0.3 0.1" class="visual" material="Body001_Clear_material"/>
          <geom class="collision" type="box" pos="-0.00000500 0.09229907 0.57492310" size="0.3865222930908203 0.25105828046798706 0.00804629921913147" quat="7.907536314633035e-07 0.0 0.0 1.0"/>
          <geom class="collision" type="box" pos="-0.00000500 0.09229907 0.18067828" size="0.3865222930908203 0.25105828046798706 0.008046314120292664" quat="7.907536314633035e-07 0.0 0.0 1.0"/>
        </body>
        <geom class="region" name="reg_fridge_shelf0" type="box" pos="-0.0002585750000000109 0.10178798 0.378062695" size="0.382228225 0.26148685 0.18441985500000002"/>
        <geom class="region" name="reg_fridge_shelf1" type="box" pos="5.1309999999998857e-05 0.10178798 0.74999997" size="0.38191834 0.26148685 0.16215943"/>
        <geom class="region" name="reg_main" type="box" pos="-4.990000000010264e-06 0.03131276500000002 0.0" size="0.41752426 0.377378985 0.95000012"/>
      </body>
    </body>
  </worldbody>
  <actuator>
    <motor name="freezer0_door_joint_actuator" joint="freezer0_door_joint" gear="50"/>
    <motor name="freezer1_door_joint_actuator" joint="freezer1_door_joint" gear="50"/>
    <motor name="fridge_drawer0_joint_actuator" joint="fridge_drawer0_joint" gear="50"/>
    <motor name="fridge_left_door_joint_actuator" joint="fridge_left_door_joint" gear="50"/>
    <motor name="fridge_right_door_joint_actuator" joint="fridge_right_door_joint" gear="50"/>
  </actuator>
</mujoco>
