<?xml version='1.0' encoding='UTF-8'?>
<mujoco model="model">
  <option timestep="0.002" gravity="0.0 0.0 -9.81"/>
  <compiler angle="radian"/>
  <asset>
    <mesh file="visuals/knob_front_center.obj" name="knob_front_center_vis"/>
    <mesh file="visuals/knob_front_left.obj" name="knob_front_left_vis"/>
    <mesh file="visuals/knob_front_right.obj" name="knob_front_right_vis"/>
    <mesh file="visuals/knob_rear_center.obj" name="knob_rear_center_vis"/>
    <mesh file="visuals/knob_rear_left.obj" name="knob_rear_left_vis"/>
    <mesh file="visuals/knob_rear_right.obj" name="knob_rear_right_vis"/>
    <mesh file="visuals/Body001.obj" name="Body001_vis"/>
    <mesh file="visuals/Door001.obj" name="Door001_vis"/>
    <mesh file="visuals/Door001_Clear.obj" name="Door001_Clear_vis"/>
    <mesh file="visuals/Knob001.obj" name="Knob001_vis"/>
    <mesh file="visuals/Knob002.obj" name="Knob002_vis"/>
    <mesh file="visuals/Shelf001.obj" name="Shelf001_vis"/>
    <texture file="visuals/T_BC001.png" name="Body001_material" type="2d"/>
    <material name="Body001_material" rgba="1 1 1 1.0" texture="Body001_material" shininess="0.5" specular="1.5"/>
    <texture file="visuals/T_BC001.png" name="knob_front_center_material" type="2d"/>
    <material name="knob_front_center_material" rgba="1 1 1 1.0" texture="knob_front_center_material" shininess="2" specular="0.3103448502657381"/>
    <texture file="visuals/T_BC001.png" name="knob_front_left_material" type="2d"/>
    <material name="knob_front_left_material" rgba="1 1 1 1.0" texture="knob_front_left_material" shininess="2" specular="0.3103448502657381"/>
    <texture file="visuals/T_BC001.png" name="knob_front_right_material" type="2d"/>
    <material name="knob_front_right_material" rgba="1 1 1 1.0" texture="knob_front_right_material" shininess="2" specular="0.3103448502657381"/>
    <texture file="visuals/T_BC001.png" name="knob_rear_center_material" type="2d"/>
    <material name="knob_rear_center_material" rgba="1 1 1 1.0" texture="knob_rear_center_material" shininess="2" specular="0.3103448502657381"/>
    <texture file="visuals/T_BC001.png" name="knob_rear_left_material" type="2d"/>
    <material name="knob_rear_left_material" rgba="1 1 1 1.0" texture="knob_rear_left_material" shininess="2" specular="0.3103448502657381"/>
    <texture file="visuals/T_BC001.png" name="knob_rear_right_material" type="2d"/>
    <material name="knob_rear_right_material" rgba="1 1 1 1.0" texture="knob_rear_right_material" shininess="2" specular="0.3103448502657381"/>
    <texture file="visuals/T_BC001.png" name="Door001_material" type="2d"/>
    <material name="Door001_material" rgba="1 1 1 1.0" texture="Door001_material" shininess="2" specular="0.3103448502657381"/>
    <material name="Door001_Clear_material" rgba="0.3485074043273926 0.3485074043273926 0.3485074043273926 0.5" shininess="0.5" specular="0.3103448502657381"/>
    <texture file="visuals/T_BC001.png" name="Knob001_material" type="2d"/>
    <material name="Knob001_material" rgba="1 1 1 1.0" texture="Knob001_material" shininess="2" specular="0.3103448502657381"/>
    <texture file="visuals/T_BC001.png" name="Knob002_material" type="2d"/>
    <material name="Knob002_material" rgba="1 1 1 1.0" texture="Knob002_material" shininess="2" specular="0.3103448502657381"/>
    <texture file="visuals/T_BC001.png" name="Shelf001_material" type="2d"/>
    <material name="Shelf001_material" rgba="1 1 1 1.0" texture="Shelf001_material" shininess="2" specular="0.3103448502657381"/>
  </asset>
  <default>
    <default class="visual">
      <geom conaffinity="0" contype="0" group="1" type="mesh"/>
    </default>
    <default class="collision">
      <geom group="0" rgba="0.5 0 0 0.5"/>
    </default>
    <default class="spawn">
      <geom group="0" rgba="1 1 1 0.5" contype="0" conaffinity="0"/>
      <site group="0" rgba="1 1 1 0.5"/>
    </default>
    <default class="region">
      <geom group="1" conaffinity="0" contype="0" rgba="0 1 0 0"/>
    </default>
  </default>
  <worldbody>
    <body>
      <body name="object">
        <geom mesh="Body001_vis" type="mesh" solimp="0.998 0.998 0.001" solref="0.001 1" friction="0.95 0.3 0.1" class="visual" material="Body001_material"/>
        <geom class="collision" type="box" pos="-0.46557632 0.03037344 -0.02053916" size="0.02281191758811474 0.32583460211753845 0.39364221692085266" quat="1.0 0.0 0.0 0.0"/>
        <geom class="collision" type="box" pos="0.46285307 0.03037491 -0.03739854" size="0.027301158756017685 0.3258262276649475 0.37675875425338745" quat="1.0 0.0 0.0 0.0"/>
        <geom class="collision" type="box" pos="-0.00782833 0.03028879 -0.34304366" size="0.44293954968452454 0.3259124755859375 0.07090509682893753" quat="1.0 0.0 0.0 0.0"/>
        <geom class="collision" type="box" pos="0.00088328 0.34156246 0.09581313" size="0.4892715811729431 0.014645854011178017 0.3746751844882965" quat="1.0 0.0 0.0 0.0"/>
        <geom class="collision" type="box" pos="-0.00782833 0.03093835 0.30107823" size="0.44297242164611816 0.3018209934234619 0.06149294227361679" quat="1.0 0.0 0.0 0.0"/>
        <geom class="collision" type="box" pos="-0.00782833 -0.26168780 0.23148760" size="0.4429900646209717 0.034098684787750244 0.01047856267541647" quat="1.0 0.0 0.0 0.0"/>
        <geom class="collision" type="box" pos="-0.43528351 0.01754342 0.36980954" size="0.026038331910967827 0.25064918398857117 0.022860659286379814" quat="1.0 0.0 0.0 0.0"/>
        <geom class="collision" type="box" pos="-0.00782833 0.02411066 0.21539354" size="0.4429723918437958 0.28328001499176025 0.010477830655872822" quat="1.0 0.0 0.0 0.0"/>
        <geom class="collision" type="box" pos="-0.00782833 0.02411066 -0.25896937" size="0.4429723918437958 0.28328001499176025 0.010477830655872822" quat="1.0 0.0 0.0 0.0"/>
        <geom class="collision" type="box" pos="-0.42434916 0.02411063 -0.02233807" size="0.010477871634066105 0.28328001499176025 0.23162606358528137" quat="1.0 0.0 0.0 0.0"/>
        <geom class="collision" type="box" pos="0.42353889 0.02411063 -0.02233807" size="0.011447512544691563 0.28328001499176025 0.23162606358528137" quat="1.0 0.0 0.0 0.0"/>
        <geom class="collision" type="box" pos="-0.00276939 0.29940675 -0.02496565" size="0.41781947016716003 0.010477843694388866 0.23594778776168823" quat="1.0 0.0 0.0 0.0"/>
        <geom class="collision" type="box" pos="-0.40847227 0.00387519 -0.00110251" size="0.01244853064417839 0.20002445578575134 0.004354590084403753" quat="1.0 0.0 0.0 0.0"/>
        <geom class="collision" type="box" pos="0.40884671 0.00387519 -0.00110251" size="0.01244853064417839 0.20002445578575134 0.004354590084403753" quat="1.0 0.0 0.0 0.0"/>
        <geom class="collision" type="cylinder" pos="-0.40363693 -0.24192940 -0.43896979" size="0.02651587501168251 0.02479064092040062" quat="1.0 0.0 0.0 0.0"/>
        <geom class="collision" type="cylinder" pos="0.40865371 -0.24343015 -0.43896979" size="0.02651587501168251 0.02479064092040062" quat="1.0 0.0 0.0 0.0"/>
        <geom class="collision" type="cylinder" pos="0.40865371 0.30158268 -0.43896979" size="0.02651587501168251 0.02479064092040062" quat="1.0 0.0 0.0 0.0"/>
        <geom class="collision" type="cylinder" pos="-0.40363693 0.30308343 -0.43896979" size="0.02651587501168251 0.02479064092040062" quat="1.0 0.0 0.0 0.0"/>
        <geom class="collision" type="box" pos="-0.00087470 0.03000620 0.37108278" size="0.49102887511253357 0.32619598507881165 0.021587489172816277" quat="1.0 0.0 0.0 0.0"/>
        <geom class="collision" type="box" pos="0.00249667 0.02214989 0.38566324" size="0.4245339334011078 0.2689008116722107 0.02895054593682289" quat="1.0 0.0 0.0 0.0"/>
        <body name="knob_front_center">
          <joint axis="0.0 -1.0 0.0" pos="0.07875201 -0.29099901 0.28478876" limited="true" name="knob_front_center_joint" range="0.0 3.141592653589793" type="hinge" damping="0.05" armature="0.001"/>
          <geom mesh="knob_front_center_vis" type="mesh" solimp="0.998 0.998 0.001" solref="0.001 1" friction="0.95 0.3 0.1" class="visual" material="knob_front_center_material"/>
          <geom class="collision" type="cylinder" pos="0.07924981 -0.28817983 0.28478876" size="0.02351096272468567 0.006129719782620668" quat="0.7071068286895752 0.7071067690849304 -1.5700924318127872e-16 -5.9269340452702814e-24"/>
          <geom class="collision" type="box" pos="0.07924976 -0.30182295 0.28478879" size="0.005404462572187185 0.009122075513005257 0.019020233303308487" quat="1.0 0.0 0.0 0.0" name="knob_front_center_main"/>
        </body>
        <body name="knob_front_left">
          <joint axis="0.0 -1.0 0.0" pos="-0.37760913 -0.29099901 0.28478876" limited="true" name="knob_front_left_joint" range="0.0 3.141592653589793" type="hinge" damping="0.05" armature="0.001"/>
          <geom mesh="knob_front_left_vis" type="mesh" solimp="0.998 0.998 0.001" solref="0.001 1" friction="0.95 0.3 0.1" class="visual" material="knob_front_left_material"/>
          <geom class="collision" type="cylinder" pos="-0.37760913 -0.28817983 0.28478876" size="0.02351096272468567 0.006129719782620668" quat="0.7071068286895752 0.7071067690849304 -1.5700924318127872e-16 -5.9269340452702814e-24"/>
          <geom class="collision" type="box" pos="-0.37760916 -0.30182295 0.28478879" size="0.005404462572187185 0.009122075513005257 0.019020244479179382" quat="1.0 0.0 0.0 0.0" name="knob_front_left_main"/>
        </body>
        <body name="knob_front_right">
          <joint axis="0.0 -1.0 0.0" pos="0.39764524 -0.29099901 0.28478876" limited="true" name="knob_front_right_joint" range="0.0 3.141592653589793" type="hinge" damping="0.05" armature="0.001"/>
          <geom mesh="knob_front_right_vis" type="mesh" solimp="0.998 0.998 0.001" solref="0.001 1" friction="0.95 0.3 0.1" class="visual" material="knob_front_right_material"/>
          <geom class="collision" type="cylinder" pos="0.39790887 -0.28817983 0.28478876" size="0.02351096272468567 0.006129719782620668" quat="0.7071068286895752 0.7071067690849304 -1.5700924318127872e-16 -5.9269340452702814e-24"/>
          <geom class="collision" type="box" pos="0.39790884 -0.30182295 0.28478879" size="0.005404462572187185 0.009122075513005257 0.019020257517695427" quat="1.0 0.0 0.0 0.0" name="knob_front_right_main"/>
        </body>
        <body name="knob_rear_center">
          <joint axis="0.0 -1.0 0.0" pos="0.18508483 -0.29099901 0.28478876" limited="true" name="knob_rear_center_joint" range="0.0 3.141592653589793" type="hinge" damping="0.05" frictionloss="0.1" armature="0.001"/>
          <geom mesh="knob_rear_center_vis" type="mesh" solimp="0.998 0.998 0.001" solref="0.001 1" friction="0.95 0.3 0.1" class="visual" material="knob_rear_center_material"/>
          <geom class="collision" type="cylinder" pos="0.18477298 -0.28817983 0.28478876" size="0.02351096272468567 0.006129719782620668" quat="0.7071068286895752 0.7071067690849304 -1.5700924318127872e-16 -5.9269340452702814e-24" density="0.001"/>
          <geom class="collision" type="box" pos="0.18477294 -0.30182295 0.28478879" size="0.005404462572187185 0.009122075513005257 0.01902027055621147" quat="1.0 0.0 0.0 0.0" name="knob_rear_center_main" density="0.001"/>
        </body>
        <body name="knob_rear_left">
          <joint axis="0.0 -1.0 0.0" pos="-0.27108979 -0.29099901 0.28478876" limited="true" name="knob_rear_left_joint" range="0.0 3.141592653589793" type="hinge" damping="0.05" armature="0.001"/>
          <geom mesh="knob_rear_left_vis" type="mesh" solimp="0.998 0.998 0.001" solref="0.001 1" friction="0.95 0.3 0.1" class="visual" material="knob_rear_left_material"/>
          <geom class="collision" type="cylinder" pos="-0.27098790 -0.28817983 0.28478876" size="0.02351096272468567 0.006129719782620668" quat="0.7071068286895752 0.7071067690849304 -1.5700924318127872e-16 -5.9269340452702814e-24"/>
          <geom class="collision" type="box" pos="-0.27098793 -0.30182295 0.28478879" size="0.005404462572187185 0.009122075513005257 0.019020283594727516" quat="1.0 0.0 0.0 0.0" name="knob_rear_left_main"/>
        </body>
        <body name="knob_rear_right">
          <joint axis="0.0 -1.0 0.0" pos="0.29134342 -0.29099901 0.28478876" limited="true" name="knob_rear_right_joint" range="0.0 3.141592653589793" type="hinge" damping="0.05" armature="0.001"/>
          <geom mesh="knob_rear_right_vis" type="mesh" solimp="0.998 0.998 0.001" solref="0.001 1" friction="0.95 0.3 0.1" class="visual" material="knob_rear_right_material"/>
          <geom class="collision" type="cylinder" pos="0.29149604 -0.28817983 0.28478876" size="0.02351096272468567 0.006129719782620668" quat="0.7071068286895752 0.7071067690849304 -1.5700924318127872e-16 -5.9269340452702814e-24"/>
          <geom class="collision" type="box" pos="0.29149601 -0.30182295 0.28478879" size="0.005404462572187185 0.009122075513005257 0.01902029477059841" quat="1.0 0.0 0.0 0.0" name="knob_rear_right_main"/>
        </body>
        <body name="Door001">
          <joint axis="1.0 0.0 0.0" pos="-0.00052806 -0.29638438 -0.27039319" limited="true" name="Door001_joint" range="0.0 1.5707963267948966" type="hinge" damping="1" frictionloss="1" armature=".01" stiffness="0.05"/>
          <geom mesh="Door001_vis" type="mesh" solimp="0.998 0.998 0.001" solref="0.001 1" friction="0.95 0.3 0.1" class="visual" material="Door001_material"/>
          <geom class="collision" type="box" pos="0.00000000 -0.27965726 -0.01189002" size="0.35245248675346375 0.011737411841750145 0.18250882625579834" quat="1.0 0.0 0.0 0.0"/>
          <geom class="collision" type="box" pos="0.00000000 -0.28151061 -0.02251863" size="0.4303256869316101 0.014502870850265026 0.22068661451339722" quat="1.0 0.0 0.0 0.0"/>
          <geom class="collision" type="box" pos="-0.31346905 -0.31929864 0.17928532" size="0.034942544996738434 0.02483963780105114 0.0110614700242877" quat="1.0 0.0 0.0 0.0"/>
          <geom class="collision" type="box" pos="0.30681890 -0.31929864 0.17928532" size="0.034942567348480225 0.024839654564857483 0.011061477474868298" quat="1.0 0.0 0.0 0.0"/>
          <geom class="collision" type="cylinder" pos="-0.00000000 -0.35074781 0.17993012" size="0.011870450340211391 0.3469732999801636" quat="0.7071068286895752 -4.7503018407724085e-08 -0.7071067094802856 -4.750301130229673e-08"/>
          <body name="Door001_Clear">
            <geom mesh="Door001_Clear_vis" type="mesh" solimp="0.998 0.998 0.001" solref="0.001 1" friction="0.95 0.3 0.1" class="visual" material="Door001_Clear_material"/>
            <geom class="collision" type="box" pos="0.00000000 -0.27965726 -0.01189002" size="0.35245248675346375 0.011737411841750145 0.18250882625579834" quat="1.0 0.0 0.0 0.0"/>
          </body>
        </body>
        <body name="Knob001">
          <joint axis="0.0 1.0 0.0" pos="-0.14159927 -0.29099901 0.28478876" limited="true" name="Knob001_joint" range="0.0 5.235987755982989" type="hinge" damping="0.05" frictionloss="0.1" armature="0.001"/>
          <geom mesh="Knob001_vis" type="mesh" solimp="0.998 0.998 0.001" solref="0.001 1" friction="0.95 0.3 0.1" class="visual" material="Knob001_material"/>
          <geom class="collision" type="cylinder" pos="-0.14113602 -0.28817983 0.28478876" size="0.02351096272468567 0.006129719782620668" quat="0.7071068286895752 0.7071067690849304 -1.5700924318127872e-16 -5.9269340452702814e-24" density="0.001"/>
          <geom class="collision" type="box" pos="-0.14113601 -0.30182295 0.28478879" size="0.019020427018404007 0.00912207830697298 0.005404408555477858" quat="1.0 0.0 0.0 0.0" density="0.001"/>
        </body>
        <body name="Knob002">
          <joint axis="0.0 1.0 0.0" pos="-0.03605950 -0.29099901 0.28478876" limited="true" name="Knob002_joint" range="0.0 5.585053606381854" type="hinge" damping="0.05" frictionloss="0.1" armature="0.001"/>
          <geom mesh="Knob002_vis" type="mesh" solimp="0.998 0.998 0.001" solref="0.001 1" friction="0.95 0.3 0.1" class="visual" material="Knob002_material"/>
          <geom class="collision" type="cylinder" pos="-0.03594968 -0.28817983 0.28478876" size="0.02351096272468567 0.006129719782620668" quat="0.7071068286895752 0.7071067690849304 -1.5700924318127872e-16 -5.9269340452702814e-24" density="0.001"/>
          <geom class="collision" type="box" pos="-0.03594972 -0.30182295 0.28478879" size="0.005404462572187185 0.009122075513005257 0.0190203208476305" quat="1.0 0.0 0.0 0.0" density="0.001"/>
        </body>
        <body name="Shelf001">
          <joint axis="0.0 -1.0 0.0" pos="0.00138041 0.00555030 0.01520206" limited="true" name="Shelf001_joint" range="0.0 0.37" type="slide" damping="1" frictionloss="1" armature=".01" stiffness="0.05"/>
          <geom mesh="Shelf001_vis" type="mesh" solimp="0.998 0.998 0.001" solref="0.001 1" friction="0.95 0.3 0.1" class="visual" material="Shelf001_material"/>
          <geom class="collision" type="box" pos="0.00039798 0.00387518 0.01403446" size="0.4045194685459137 0.24533198773860931 0.005284389015287161" quat="1.0 0.0 0.0 0.0"/>
        </body>
        <geom class="region" name="reg_int" type="box" pos="0.000618980000000019 0.018655664999999988 -0.02560143999999999" size="0.40745096999999997 0.266249945 0.21653456"/>
        <site type="cylinder" rgba="0.3 0.4 1 0.5" size="0.045871008187532425 0.01818244904279709" pos="-0.28646415 0.14615773 0.38920701" name="burner_on_rear_left"/>
        <site type="cylinder" rgba="0.3 0.4 1 0.5" size="0.06383007019758224 0.01818244904279709" pos="-0.28671888 -0.11018697 0.38920701" name="burner_on_front_left"/>
        <site type="cylinder" rgba="0.3 0.4 1 0.5" size="0.035795263946056366 0.01818244904279709" pos="0.28386751 -0.11033539 0.38920701" name="burner_on_front_right"/>
        <site type="cylinder" rgba="0.3 0.4 1 0.5" size="0.052925318479537964 0.01818244904279709" pos="0.28460315 0.14619322 0.38920701" name="burner_on_rear_right"/>
        <site type="cylinder" rgba="0.3 0.4 1 0.5" size="0.07991979271173477 0.01818244904279709" pos="-0.00036363 -0.11020944 0.38920701" name="burner_on_front_center"/>
        <site type="cylinder" rgba="0.3 0.4 1 0.5" size="0.0651245266199112 0.01818244904279709" pos="-0.00022945 0.14635897 0.38920701" name="burner_on_rear_center"/>
        <site type="cylinder" rgba="0.5 0 0 0" size="0.045871008187532425 4.999999873689376e-05" pos="-0.28646415 0.14615773 0.41475266" name="burner_rear_left_place_site"/>
        <site type="cylinder" rgba="0.5 0 0 0" size="0.06383007019758224 4.999999873689376e-05" pos="-0.28671888 -0.11018697 0.41475266" name="burner_front_left_place_site"/>
        <site type="cylinder" rgba="0.5 0 0 0" size="0.035795263946056366 4.999999873689376e-05" pos="0.28386751 -0.11033539 0.41475266" name="burner_front_right_place_site"/>
        <site type="cylinder" rgba="0.5 0 0 0" size="0.052925318479537964 4.999999873689376e-05" pos="0.28460315 0.14619322 0.41475266" name="burner_rear_right_place_site"/>
        <site type="cylinder" rgba="0.5 0 0 0" size="0.07991979271173477 4.999999873689376e-05" pos="-0.00036363 -0.11020944 0.41475266" name="burner_front_center_place_site"/>
        <site type="cylinder" rgba="0.5 0 0 0" size="0.0651245266199112 4.999999873689376e-05" pos="-0.00022945 0.14635897 0.41475266" name="burner_rear_center_place_site"/>
        <geom class="region" name="reg_main" type="box" pos="-4.999999997368221e-09 0.032352165000000016 -0.03741317999999999" size="0.49383614499999995 0.331000015 0.43108351"/>
      </body>
    </body>
  </worldbody>
  <actuator>
    <motor name="knob_front_center_joint_actuator" joint="knob_front_center_joint" gear="10"/>
    <motor name="knob_front_left_joint_actuator" joint="knob_front_left_joint" gear="10"/>
    <motor name="knob_front_right_joint_actuator" joint="knob_front_right_joint" gear="10"/>
    <motor name="knob_rear_center_joint_actuator" joint="knob_rear_center_joint" gear="10"/>
    <motor name="knob_rear_left_joint_actuator" joint="knob_rear_left_joint" gear="10"/>
    <motor name="knob_rear_right_joint_actuator" joint="knob_rear_right_joint" gear="10"/>
    <motor name="Door001_joint_actuator" joint="Door001_joint" gear="50"/>
    <motor name="Knob001_joint_actuator" joint="Knob001_joint" gear="50"/>
    <motor name="Knob002_joint_actuator" joint="Knob002_joint" gear="50"/>
    <motor name="Shelf001_joint_actuator" joint="Shelf001_joint" gear="50"/>
  </actuator>
</mujoco>
