<?xml version='1.0' encoding='UTF-8'?>
<mujoco model="model">
  <option timestep="0.002" gravity="0.0 0.0 -9.81"/>
  <compiler angle="radian"/>
  <asset>
    <mesh file="visuals/Body001.obj" name="Body001_vis"/>
    <mesh file="visuals/Button001.obj" name="Button001_vis"/>
    <mesh file="visuals/Button002.obj" name="Button002_vis"/>
    <mesh file="visuals/Button003.obj" name="Button003_vis"/>
    <mesh file="visuals/Container001_Clear.obj" name="Container001_Clear_vis"/>
    <mesh file="visuals/Lever001.obj" name="Lever001_vis"/>
    <mesh file="visuals/Lid001.obj" name="Lid001_vis"/>
    <mesh file="visuals/Lid002.obj" name="Lid002_vis"/>
    <mesh file="visuals/Lid003.obj" name="Lid003_vis"/>
    <texture file="visuals/T_BC001.png" name="Body001_material" type="2d"/>
    <material name="Body001_material" rgba="1 1 1 1.0" texture="Body001_material" shininess="-0.1" specular="2"/>
    <texture file="visuals/T_BC001.png" name="Button001_material" type="2d"/>
    <material name="Button001_material" rgba="1 1 1 1.0" texture="Button001_material" shininess="-0.1" specular="2"/>
    <texture file="visuals/T_BC001.png" name="Button002_material" type="2d"/>
    <material name="Button002_material" rgba="1 1 1 1.0" texture="Button002_material" shininess="-0.1" specular="2"/>
    <texture file="visuals/T_BC001.png" name="Button003_material" type="2d"/>
    <material name="Button003_material" rgba="1 1 1 1.0" texture="Button003_material" shininess="-0.1" specular="2"/>
    <material name="Container001_Clear_material" rgba="0.5 0.5 0.5 0.10000000149011612" shininess="-0.1" specular="0.3103448502657381"/>
    <texture file="visuals/T_BC001.png" name="Lever001_material" type="2d"/>
    <material name="Lever001_material" rgba="1 1 1 1.0" texture="Lever001_material" shininess="-0.1" specular="2"/>
    <texture file="visuals/T_BC001.png" name="Lid001_material" type="2d"/>
    <material name="Lid001_material" rgba="1 1 1 1.0" texture="Lid001_material" shininess="-0.1" specular="2"/>
    <texture file="visuals/T_BC001.png" name="Lid002_material" type="2d"/>
    <material name="Lid002_material" rgba="1 1 1 1.0" texture="Lid002_material" shininess="-0.1" specular="2"/>
    <texture file="visuals/T_BC001.png" name="Lid003_material" type="2d"/>
    <material name="Lid003_material" rgba="1 1 1 1.0" texture="Lid003_material" shininess="-0.1" specular="2"/>
  </asset>
  <default>
    <default class="visual">
      <geom conaffinity="0" contype="0" group="1" type="mesh"/>
    </default>
    <default class="collision">
      <geom group="0" rgba="0.5 0 0 0.5"/>
    </default>
    <default class="spawn">
      <geom group="0" rgba="1 1 1 0.5" contype="0" conaffinity="0"/>
      <site group="0" rgba="1 1 1 0.5"/>
    </default>
    <default class="region">
      <geom group="1" conaffinity="0" contype="0" rgba="0 1 0 0"/>
    </default>
  </default>
  <worldbody>
    <body>
      <body name="object">
        <geom class="collision" type="box" pos="-0.00124559 -0.16493319 0.10540237" size="0.010432046838104725 0.010432046838104725 0.00023479762603528798" quat="0.7657781839370728 0.6431047916412354 0.0 0.0" name="start_button_1" rgba="0.0 0.5 0 0.5"/>
        <geom class="collision" type="box" pos="-0.03165734 -0.16878255 0.05037468" size="0.010432046838104725 0.00023871820303611457 0.010432046838104725" quat="1.0 0.0 0.0 0.0" name="start_button_2" rgba="0.0 0.5 0 0.5"/>
        <geom mesh="Body001_vis" type="mesh" solimp="0.998 0.998 0.001" solref="0.001 1" friction="0.95 0.3 0.1" class="visual" material="Body001_material"/>
        <geom class="collision" type="box" pos="-0.00000000 0.06312108 -0.15725248" size="0.11195165663957596 0.15366652607917786 0.020686009898781776" quat="1.0 0.0 0.0 0.0"/>
        <geom class="collision" type="box" pos="-0.00000000 -0.15732262 -0.16783005" size="0.11194931715726852 0.06829290091991425 0.010334211401641369" quat="1.0 0.0 0.0 0.0"/>
        <geom class="collision" type="box" pos="-0.00000000 -0.22556078 -0.14791322" size="0.11195165663957596 0.011879979632794857 0.0036422957200556993" quat="0.8053767085075378 -0.5927633047103882 -1.316199202782537e-16 -6.994547234390643e-24"/>
        <geom class="collision" type="box" pos="-0.00000000 0.20468479 -0.02874508" size="0.11195165663957596 0.012152980081737041 0.10867776721715927" quat="1.0 0.0 0.0 0.0"/>
        <geom class="collision" type="box" pos="0.00200903 0.08386704 -0.13102606" size="0.11396069079637527 0.10867775976657867 0.005318571347743273" quat="1.0 0.0 0.0 0.0"/>
        <geom class="collision" type="box" pos="0.00000000 0.05154718 0.06618332" size="0.11195165663957596 0.14099763333797455 0.013451976701617241" quat="1.0 0.0 0.0 0.0"/>
        <geom class="collision" type="box" pos="0.00000000 -0.07261194 0.02959609" size="0.11195165663957596 0.0183626189827919 0.023557720705866814" quat="1.0 0.0 0.0 0.0"/>
        <geom class="collision" type="box" pos="-0.00000000 -0.08129348 -0.01741900" size="0.11195165663957596 0.02345963940024376 0.007367161102592945" quat="0.7399609088897705 -0.6726498603820801 -1.4895644801217288e-16 4.444539141957276e-19"/>
        <geom class="collision" type="box" pos="0.00000000 -0.07434868 -0.06290860" size="0.11195165663957596 0.02345964126288891 0.007367161102592945" quat="0.7782642841339111 -0.627936840057373 -1.3905500343568453e-16 4.673307831080121e-19"/>
        <geom class="collision" type="box" pos="-0.00000000 -0.06076238 -0.11258774" size="0.11195165663957596 0.02864706702530384 0.007367161102592945" quat="0.8100221753120422 -0.586399257183075 -1.2985674178920506e-16 4.862973624696053e-19"/>
        <geom class="collision" type="box" pos="-0.00000000 -0.03955568 -0.12624059" size="0.11195165663957596 0.01639576442539692 0.010064381174743176" quat="0.812647819519043 -0.5827551484107971 -1.2904978408826773e-16 4.878807929571849e-19"/>
        <geom class="collision" type="box" pos="-0.03069810 0.08528562 -0.03427409" size="0.08770895004272461 0.13229043781757355 0.09314877539873123" quat="1.0 0.0 0.0 0.0"/>
        <geom class="collision" type="box" pos="-0.02647818 -0.06568921 -0.01656785" size="0.08547347784042358 0.02345963940024376 0.007367161102592945" quat="0.7399609088897705 -0.6726498603820801 -1.4895644801217288e-16 4.444539141957276e-19"/>
        <geom class="collision" type="box" pos="-0.02647818 -0.05874441 -0.06205746" size="0.08547347784042358 0.02345964126288891 0.007367161102592945" quat="0.7782642841339111 -0.627936840057373 -1.3905500343568453e-16 4.673307831080121e-19"/>
        <geom class="collision" type="box" pos="-0.02647818 -0.04948430 -0.10284135" size="0.08547347784042358 0.02345964126288891 0.007367161102592945" quat="0.7782642841339111 -0.627936840057373 -1.3905500343568453e-16 4.673307831080121e-19"/>
        <geom class="collision" type="box" pos="-0.02647818 -0.05150350 -0.01518869" size="0.08547347784042358 0.02345963940024376 0.007367161102592945" quat="0.7399609088897705 -0.6726498603820801 -1.4895644801217288e-16 4.444539141957276e-19"/>
        <geom class="collision" type="box" pos="-0.02647818 -0.04455870 -0.06067829" size="0.08547347784042358 0.02345964126288891 0.007367161102592945" quat="0.7782642841339111 -0.627936840057373 -1.3905500343568453e-16 4.673307831080121e-19"/>
        <geom class="collision" type="box" pos="-0.02647818 -0.05320579 0.03043254" size="0.08547347784042358 0.02345963940024376 0.007367160636931658" quat="0.7027764320373535 -0.7114107608795166 -1.3989560422649562e-16 1.6461407041785034e-17"/>
        <geom class="collision" type="box" pos="0.07145903 -0.00744638 0.11744830" size="0.040491294115781784 0.08122146129608154 0.052932869642972946" quat="1.0 0.0 0.0 0.0"/>
        <geom class="collision" type="box" pos="0.00000000 -0.09589675 0.17173259" size="0.05102944374084473 0.04928381368517876 0.0028701561968773603" quat="1.0 0.0 0.0 0.0"/>
        <geom class="collision" type="box" pos="-0.00035770 -0.11892272 0.14599654" size="0.051004067063331604 0.03275555744767189 0.02363540045917034" quat="1.0 0.0 0.0 0.0"/>
        <geom class="collision" type="box" pos="-0.00035770 -0.12323713 0.09538749" size="0.051004067063331604 0.032320212572813034 0.03457696735858917" quat="0.6663897633552551 -0.7456035614013672 -1.484139631141259e-16 1.7188495491496695e-17"/>
        <geom class="collision" type="box" pos="-0.00035770 -0.12688938 0.04737138" size="0.051004067063331604 0.01664959453046322 0.034529104828834534" quat="0.6930869817733765 -0.7208539843559265 -1.5432706041423877e-16 5.7490686254145216e-18"/>
        <geom class="collision" type="cylinder" pos="-0.00226319 -0.14478752 0.02306658" size="0.005195016972720623 0.0056921616196632385" quat="1.0 0.0 0.0 0.0"/>
        <geom class="collision" type="box" pos="-0.00000000 0.22612965 -0.06005920" size="0.11195118725299835 0.008782172575592995 0.11500222235918045" quat="1.0 0.0 0.0 0.0"/>
        <geom class="collision" type="box" pos="-0.07153250 -0.00744638 0.11744830" size="0.040340181440114975 0.0812220573425293 0.052933283150196075" quat="1.0 0.0 0.0 0.0"/>
        <geom class="collision" type="box" pos="0.00134664 0.05108090 0.11744830" size="0.040340203791856766 0.02157868817448616 0.05293331295251846" quat="1.0 0.0 0.0 0.0"/>
        <geom class="collision" type="box" pos="0.00134664 -0.04549785 0.11744830" size="0.04034022241830826 0.021578697487711906 0.05293333902955055" quat="1.0 0.0 0.0 0.0"/>
        <geom class="collision" type="box" pos="0.00000000 0.00300127 0.15243676" size="0.02961600571870804 0.02676309645175934 0.003558612195774913" quat="1.0 0.0 0.0 0.0"/>
        <geom class="collision" type="box" pos="-0.00012960 0.21829988 0.12446262" size="0.11182994395494461 0.0043168626725673676 0.04551542177796364" quat="1.0 0.0 0.0 0.0"/>
        <geom class="collision" type="box" pos="-0.10832668 0.14374593 0.12446262" size="0.005925577599555254 0.07020445168018341 0.04551549628376961" quat="0.9993990063667297 0.0 -0.0 -0.034664370119571686"/>
        <geom class="collision" type="box" pos="0.10840483 0.14053614 0.12446262" size="0.005043792072683573 0.07020445168018341 0.04551549628376961" quat="0.9993990063667297 0.0 0.0 0.03466436639428139"/>
        <geom class="collision" type="box" pos="-0.00012960 0.14104941 0.08196507" size="0.11183001101016998 0.0707031786441803 0.003017946146428585" quat="1.0 0.0 0.0 0.0"/>
        <body name="Button001">
          <joint axis="0.0 1.0 0.0" pos="0.03129099 -0.16479285 0.05037481" limited="true" name="Button001_joint" range="0.0 0.0025" type="slide" damping="1" frictionloss="1" armature=".01" stiffness="0.05" springref="-5"/>
          <geom mesh="Button001_vis" type="mesh" solimp="0.998 0.998 0.001" solref="0.001 1" friction="0.95 0.3 0.1" class="visual" material="Button001_material"/>
          <geom class="collision" type="cylinder" pos="0.03131602 -0.16681343 0.05037468" size="0.010432046838104725 0.0023561641573905945" quat="0.7071067094802856 0.7071068286895752 0.0 0.0"/>
        </body>
        <body name="Button002">
          <joint axis="0.0 1.0 0.0" pos="-0.03166272 -0.16467367 0.05027713" limited="true" name="Button002_joint" range="0.0 0.0025" type="slide" damping="1" frictionloss="1" armature=".01" stiffness="0.05" springref="-5"/>
          <geom mesh="Button002_vis" type="mesh" solimp="0.998 0.998 0.001" solref="0.001 1" friction="0.95 0.3 0.1" class="visual" material="Button002_material"/>
          <geom class="collision" type="cylinder" pos="-0.03165734 -0.16622196 0.05037468" size="0.010432046838104725 0.00196964293718338" quat="0.7071067094802856 0.7071068286895752 0.0 0.0"/>
        </body>
        <body name="Button003">
          <joint axis="0.0 0.9853023290634155 -0.17081961035728455" pos="-0.00100410 -0.16081756 0.10449706" limited="true" name="Button003_joint" range="0.0 0.0025" type="slide" damping="1" frictionloss="1" armature=".01" stiffness="0.05" springref="-5"/>
          <geom mesh="Button003_vis" type="mesh" solimp="0.998 0.998 0.001" solref="0.001 1" friction="0.95 0.3 0.1" class="visual" material="Button003_material"/>
          <geom class="collision" type="cylinder" pos="-0.00124559 -0.16244118 0.10496509" size="0.010432046838104725 0.0019674296490848064" quat="0.7657781839370728 0.6431047916412354 0.0 0.0"/>
        </body>
        <body name="Container001_Clear">
          <!-- <joint axis="1.0 0.0 0.0" pos="0.09206671 0.05837971 -0.03589656" limited="true" name="Container001_Clear_joint" range="0.0 0.1" type="slide" damping="1" frictionloss="1" armature=".01" stiffness="0.05"/> -->
          <geom mesh="Container001_Clear_vis" type="mesh" solimp="0.998 0.998 0.001" solref="0.001 1" friction="0.95 0.3 0.1" class="visual" material="Container001_Clear_material"/>
          <geom class="collision" type="box" pos="0.06747180 0.08172545 -0.03490606" size="0.0012893963139504194 0.10880737751722336 0.08657684922218323" quat="1.0 0.0 0.0 0.0"/>
          <geom class="collision" type="box" pos="0.11297145 0.08113438 -0.03610009" size="0.0012893963139504194 0.10880719125270844 0.08777087926864624" quat="1.0 0.0 0.0 0.0"/>
          <geom class="collision" type="box" pos="0.08838917 0.18962118 -0.03490606" size="0.021932460367679596 0.0012893973616883159 0.08657684922218323" quat="1.0 0.0 0.0 0.0"/>
          <geom class="collision" type="box" pos="0.11297145 -0.03566129 0.01097213" size="0.0012893963139504194 0.012768151238560677 0.040536943823099136" quat="1.0 0.0 0.0 0.0"/>
          <geom class="collision" type="box" pos="0.11297145 -0.02768000 -0.06522002" size="0.0012893963139504194 0.012768151238560677 0.040536943823099136" quat="0.9948450922966003 0.10140614956617355 2.2516686763028417e-17 9.573317164694347e-25"/>
          <geom class="collision" type="box" pos="0.06711939 -0.03566129 0.01197042" size="0.0012893963139504194 0.012768151238560677 0.040536943823099136" quat="1.0 0.0 0.0 0.0"/>
          <geom class="collision" type="box" pos="0.06711939 -0.02608761 -0.07294995" size="0.0012893963139504194 0.012768151238560677 0.04842919856309891" quat="0.9948450922966003 0.10140614956617355 2.2516686763028417e-17 9.573317164694347e-25"/>
          <geom class="collision" type="box" pos="0.11297145 -0.02621131 -0.07234945" size="0.0012893963139504194 0.012768151238560677 0.04781608283519745" quat="0.9948450922966003 0.10140614956617355 2.2516686763028417e-17 9.573317164694347e-25"/>
          <geom class="collision" type="box" pos="0.08838917 -0.05134052 0.02380571" size="0.021932460367679596 0.0010894195875152946 0.028150122612714767" quat="1.0 0.0 0.0 0.0"/>
          <geom class="collision" type="box" pos="0.08838917 -0.04631644 -0.03546367" size="0.0010894185397773981 0.021932460367679596 0.03273638337850571" quat="0.7053433060646057 0.04990704730153084 0.04990704357624054 -0.70534348487854"/>
          <geom class="collision" type="box" pos="0.08838917 -0.03537068 -0.08991884" size="0.0010894185397773981 0.021932460367679596 0.03273638337850571" quat="0.701687216758728 0.08737853169441223 0.08737853914499283 -0.7016872763633728"/>
          <geom class="collision" type="box" pos="0.08939569 0.08124294 -0.12197870" size="0.020589197054505348 0.1095348373055458 0.0003066382196266204" quat="1.0 0.0 0.0 0.0"/>
          <geom class="collision" type="box" pos="0.07804937 0.13068095 -0.07602878" size="0.0091010220348835 0.018342208117246628 0.04625656083226204" quat="1.0 0.0 0.0 0.0"/>
          <geom class="collision" type="box" pos="0.07766443 -0.05587247 -0.03966841" size="0.0012893963139504194 0.012768150307238102 0.03808744251728058" quat="0.9969019889831543 0.07865401357412338 1.7464712604724077e-17 -5.921095291280288e-24"/>
          <geom class="collision" type="box" pos="0.07766443 -0.06116562 -0.00001498" size="0.0012893963139504194 0.010859214700758457 0.003424856113269925" quat="0.9990853071212769 0.04276217520236969 9.495108644183923e-18 -1.11250742100867e-23"/>
          <geom class="collision" type="box" pos="0.07766443 -0.04779420 -0.08828053" size="0.0012893963139504194 0.010859215632081032 0.01135159656405449" quat="0.9964436888694763 0.08426135778427124 1.8709778245293994e-17 -1.156451154392278e-23"/>
          <geom class="collision" type="box" pos="0.07766443 -0.04173798 -0.10248831" size="0.0012893963139504194 0.010859215632081032 0.0034083090722560883" quat="0.9999037981033325 -0.01387268677353859 -3.080352979132399e-18 -6.412931921884769e-24"/>
          <geom class="collision" type="box" pos="0.07766443 -0.04173798 -0.09925515" size="0.0012893963139504194 0.010859215632081032 0.0034083090722560883" quat="0.9999037981033325 -0.01387268677353859 -3.080352979132399e-18 -6.412931921884769e-24"/>
          <geom class="collision" type="box" pos="0.09122528 -0.05941088 0.00293078" size="0.015479560010135174 0.007000826299190521 0.0013459947658702731" quat="1.0 0.0 0.0 0.0"/>
          <geom class="collision" type="box" pos="0.09122528 -0.05941088 0.00293078" size="0.015479560010135174 0.007000826299190521 0.0013459931360557675" quat="1.0 0.0 0.0 0.0"/>
          <geom class="collision" type="box" pos="0.09122528 -0.06944578 -0.00059747" size="0.0012893963139504194 0.005344013683497906 0.0154795590788126" quat="0.6386833190917969 0.3034527599811554 0.6386833786964417 0.3034527599811554"/>
          <geom class="collision" type="box" pos="0.09122528 -0.07155579 -0.02005999" size="0.0012893963139504194 0.015372076071798801 0.0154795590788126" quat="0.4742617607116699 0.5244766473770142 0.4742617905139923 0.5244766473770142"/>
          <geom class="collision" type="box" pos="0.09122528 -0.06693700 -0.05034611" size="0.0012893963139504194 0.015372076071798801 0.0154795590788126" quat="0.4516051411628723 0.5441073179244995 0.4516051709651947 0.5441073179244995"/>
          <geom class="collision" type="box" pos="0.09122528 -0.06072432 -0.08000612" size="0.0012893963139504194 0.015372078865766525 0.0154795590788126" quat="0.4372918903827667 0.5556758642196655 0.4372921884059906 0.5556758642196655"/>
          <geom class="collision" type="box" pos="0.09122528 -0.04059955 -0.10540951" size="0.015479445457458496 0.0096397390589118 0.0013706699246540666" quat="1.0 0.0 0.0 0.0"/>
          <geom class="collision" type="box" pos="0.09122529 -0.05487658 -0.09834196" size="0.001289396546781063 0.00748261995613575 0.0154795590788126" quat="0.37345433235168457 0.6004418730735779 0.3734580874443054 0.6004418730735779"/>
        </body>
        <body name="Lever001">
          <joint axis="0.0 0.0 1.0" pos="0.02511166 -0.13981327 0.03404039" limited="true" name="Lever001_joint" range="0.0 1.0471975511965976" type="hinge" damping="1" frictionloss="1" armature=".01" stiffness="0.01" springref="-0.01"/>
          <geom mesh="Lever001_vis" type="mesh" solimp="0.998 0.998 0.001" solref="0.001 1" friction="0.95 0.3 0.1" class="visual" material="Lever001_material"/>
          <geom class="collision" type="cylinder" pos="0.02848408 -0.14202023 0.02460318" size="0.003279789350926876 0.003593653440475464" quat="0.31129348278045654 -0.35401102900505066 0.0707671195268631 0.8790702819824219"/>
          <geom class="collision" type="cylinder" pos="0.03880131 -0.14789039 0.02248377" size="0.003279789350926876 0.008309883996844292" quat="0.42010000348091125 -0.7000372409820557 -0.05817507952451706 0.5745254755020142"/>
          <geom class="collision" type="cylinder" pos="0.05225787 -0.15593562 0.02242677" size="0.004313711076974869 0.008277508430182934" quat="0.42010000348091125 -0.7000372409820557 -0.05817507952451706 0.5745254755020142"/>
          <geom class="collision" type="cylinder" pos="0.06137380 -0.17102972 -0.01621588" size="0.0056446935050189495 0.04409264773130417" quat="0.5790894627571106 -0.07702662795782089 0.10727851092815399 0.8044958710670471"/>
          <geom class="collision" type="cylinder" pos="0.06138318 -0.16317971 0.01272061" size="0.007267702370882034 0.005794093478471041" quat="0.5790894627571106 -0.07702662795782089 0.10727851092815399 0.8044958710670471"/>
        </body>
        <body name="Lid001">
          <!-- <joint axis="0.0 0.0 1.0" pos="-0.00014347 -0.15945262 -0.14686940" limited="true" name="Lid001_joint" range="0.0 0.05" type="slide" damping="15" frictionloss="1" armature=".01" stiffness="0.05"/> -->
          <geom mesh="Lid001_vis" type="mesh" solimp="0.998 0.998 0.001" solref="0.001 1" friction="0.95 0.3 0.1" class="visual" material="Lid001_material"/>
          <geom class="collision" type="box" pos="-0.11014700 -0.15378317 -0.14743953" size="0.000713276385795325 0.06260634958744049 0.009638052433729172" quat="1.0 0.0 0.0 0.0"/>
          <geom class="collision" type="box" pos="0.10979776 -0.15378317 -0.14743953" size="0.0007132759201340377 0.0626063123345375 0.009638046845793724" quat="1.0 0.0 0.0 0.0"/>
          <geom class="collision" type="box" pos="0.00007139 -0.15643242 -0.13744508" size="0.1103711649775505 0.06525538861751556 0.0007132954779081047" quat="1.0 0.0 0.0 0.0"/>
          <geom class="collision" type="box" pos="-0.11014700 -0.21671472 -0.14609839" size="0.0007132748141884804 0.0024728174321353436 0.009638032875955105" quat="0.9899290204048157 0.14156463742256165 -3.1433663987848e-17 -5.754917402860503e-24"/>
          <geom class="collision" type="box" pos="0.10977748 -0.21671472 -0.14609839" size="0.0007132748141884804 0.0024728174321353436 0.009638032875955105" quat="0.9899290204048157 0.14156463742256165 -3.1433663987848e-17 -5.754917402860503e-24"/>
        </body>
        <body name="Lid002">
          <joint axis="-1.0 0.0 0.0" pos="0.00000000 0.03464422 0.17133443" limited="true" name="Lid002_joint" range="0.0 1.5707963267948966" type="hinge" damping="1" frictionloss="1" armature=".01" stiffness="0.05"/>
          <geom mesh="Lid002_vis" type="mesh" solimp="0.998 0.998 0.001" solref="0.001 1" friction="0.95 0.3 0.1" class="visual" material="Lid002_material"/>
          <geom class="collision" type="cylinder" pos="-0.00007254 -0.02065807 0.17296940" size="0.0028926830273121595 0.000971427361946553" quat="1.0 0.0 0.0 0.0"/>
          <geom class="collision" type="cylinder" pos="-0.00007254 -0.02065807 0.17462751" size="0.003775096731260419 0.0007055872702039778" quat="1.0 0.0 0.0 0.0"/>
          <geom class="collision" type="box" pos="0.00000000 0.00427841 0.17128793" size="0.030378278344869614 0.030378278344869614 0.0007464580121450126" quat="1.0 0.0 0.0 0.0"/>
        </body>
        <body name="Lid003">
          <joint axis="1.0 0.0 0.0" pos="0.00255463 0.07548355 0.17015095" limited="true" name="Lid003_joint" range="0.0 1.5707963267948966" type="hinge" damping="1" frictionloss="1" armature=".01" stiffness="0.05"/>
          <geom mesh="Lid003_vis" type="mesh" solimp="0.998 0.998 0.001" solref="0.001 1" friction="0.95 0.3 0.1" class="visual" material="Lid003_material"/>
          <geom class="collision" type="box" pos="0.00163938 0.14268361 0.17189818" size="0.09382521361112595 0.06474097818136215 0.002249283716082573" quat="1.0 0.0 0.0 0.0"/>
          <geom class="collision" type="cylinder" pos="-0.00007254 0.20651057 0.17596717" size="0.003775096731260419 0.0020452539902180433" quat="1.0 0.0 0.0 0.0"/>
        </body>
        <site rgba="0 0 0 0" size="0.009999999776482582 0.009999999776482582" pos="-0.00228661 -0.16514937 -0.13649668" name="receptacle_place_site"/>
        <site type="cylinder" rgba="0.8 0.5 0.25 1" size="0.0015930539229884744 0.08924613147974014" pos="-0.00213293 -0.14492139 -0.06885117" name="coffee_liquid"/>
        <geom class="region" name="reg_main" type="box" pos="0.0 0.0 -0.0012149999999999939" size="0.11916649 0.23422913 0.17763556"/>
      </body>
    </body>
  </worldbody>
  <actuator>
    <motor name="Button001_joint_actuator" joint="Button001_joint" gear="0.5"/>
    <motor name="Button002_joint_actuator" joint="Button002_joint" gear="0.5"/>
    <motor name="Button003_joint_actuator" joint="Button003_joint" gear="0.5"/>
    <!-- <motor name="Container001_Clear_joint_actuator" joint="Container001_Clear_joint" gear="10"/> -->
    <motor name="Lever001_joint_actuator" joint="Lever001_joint" gear="10"/>
    <!-- <motor name="Lid001_joint_actuator" joint="Lid001_joint" gear="10"/> -->
    <motor name="Lid002_joint_actuator" joint="Lid002_joint" gear="10"/>
    <motor name="Lid003_joint_actuator" joint="Lid003_joint" gear="10"/>
  </actuator>
</mujoco>
