<?xml version='1.0' encoding='UTF-8'?>
<mujoco model="model">
  <option timestep="0.002" gravity="0.0 0.0 -9.81"/>
  <compiler angle="radian"/>
  <asset>
    <mesh file="visuals/Body001.obj" name="Body001_vis"/>
    <mesh file="visuals/Button001.obj" name="Button001_vis"/>
    <mesh file="visuals/Button002.obj" name="Button002_vis"/>
    <mesh file="visuals/Container001_Clear.obj" name="Container001_Clear_vis"/>
    <mesh file="visuals/Lid001.obj" name="Lid001_vis"/>
    <mesh file="visuals/Lid002.obj" name="Lid002_vis"/>
    <mesh file="visuals/Lid003.obj" name="Lid003_vis"/>
    <texture file="visuals/T_BC001.png" name="Body001_material" type="2d"/>
    <material name="Body001_material" rgba="1 1 1 1.0" texture="Body001_material" shininess="0.2512328028678894" specular="2"/>
    <texture file="visuals/T_BC001.png" name="Button001_material" type="2d"/>
    <material name="Button001_material" rgba="1 1 1 1.0" texture="Button001_material" shininess="0.2512328028678894" specular="0.3103448502657381"/>
    <texture file="visuals/T_BC001.png" name="Button002_material" type="2d"/>
    <material name="Button002_material" rgba="1 1 1 1.0" texture="Button002_material" shininess="0.2512328028678894" specular="0.3103448502657381"/>
    <texture file="visuals/T_BC001.png" name="Container001_Clear_material" type="2d"/>
    <material name="Container001_Clear_material" rgba="1 1 1 0.13824884593486786" texture="Container001_Clear_material" shininess="0.2512328028678894" specular="0.3103448502657381"/>
    <texture file="visuals/T_BC001.png" name="Lid003_material" type="2d"/>
    <material name="Lid003_material" rgba="1 1 1 1.0" texture="Lid003_material" shininess="0.2512328028678894" specular="2"/>
    <texture file="visuals/T_BC001.png" name="Lid001_material" type="2d"/>
    <material name="Lid001_material" rgba="1 1 1 1.0" texture="Lid001_material" shininess="0.2512328028678894" specular="2"/>
    <texture file="visuals/T_BC001.png" name="Lid002_material" type="2d"/>
    <material name="Lid002_material" rgba="1 1 1 1.0" texture="Lid002_material" shininess="0.2512328028678894" specular="0.3"/>
  </asset>
  <default>
    <default class="visual">
      <geom conaffinity="0" contype="0" group="1" type="mesh"/>
    </default>
    <default class="collision">
      <geom group="0" rgba="0.5 0 0 0.5"/>
    </default>
    <default class="spawn">
      <geom group="0" rgba="1 1 1 0.5" contype="0" conaffinity="0"/>
      <site group="0" rgba="1 1 1 0.5"/>
    </default>
    <default class="region">
      <geom group="1" conaffinity="0" contype="0" rgba="0 1 0 0"/>
    </default>
  </default>
  <worldbody>
    <body>
      <body name="object">
        <geom class="collision" type="box" pos="0.02869567 -0.19397776 0.08382124" size="0.007607913576066494 0.007607907056808472 0.00020208954811096191" quat="0.7459015250205994 0.6660562753677368 0.0 0.0" name="start_button_2" rgba="0.0 0.5 0 0.5"/>
        <geom class="collision" type="box" pos="-0.02820123 -0.19410904 0.08383613" size="0.007607912644743919 0.007607907056808472 0.00020018592476844788" quat="0.7459015250205994 0.6660562753677368 0.0 0.0" name="start_button_1" rgba="0.0 0.5 0 0.5"/>
        <geom mesh="Body001_vis" type="mesh" solimp="0.998 0.998 0.001" solref="0.001 1" friction="0.95 0.3 0.1" class="visual" material="Body001_material"/>
        <geom class="collision" type="cylinder" pos="0.00000000 0.18168957 -0.14633475" size="0.03961363062262535 0.016524437814950943" quat="1.0 0.0 0.0 0.0"/>
        <geom class="collision" type="box" pos="-0.01432543 -0.00732752 -0.07597130" size="0.07095097750425339 0.12847651541233063 0.08733460307121277" quat="0.9993888735771179 0.0 -0.0 -0.03495505824685097"/>
        <geom class="collision" type="box" pos="0.00358002 0.06367003 0.07863120" size="0.0515001155436039 0.05674178525805473 0.06494974344968796" quat="1.0 0.0 0.0 0.0"/>
        <geom class="collision" type="box" pos="-0.00000008 -0.16074612 0.08130898" size="0.0393209308385849 0.023646311834454536 0.04621018096804619" quat="1.0 0.0 0.0 0.0"/>
        <geom class="collision" type="box" pos="-0.04835994 -0.16074612 0.07851361" size="0.013603509403765202 0.023646311834454536 0.03279045596718788" quat="1.0 0.0 0.0 0.0"/>
        <geom class="collision" type="box" pos="0.04947807 -0.16074612 0.07851361" size="0.013603509403765202 0.023646311834454536 0.03279045596718788" quat="1.0 0.0 0.0 0.0"/>
        <geom class="collision" type="box" pos="-0.00000000 -0.16293000 0.01670945" size="0.03066980466246605 0.013373971916735172 0.01796042174100876" quat="1.0 0.0 0.0 0.0"/>
        <geom class="collision" type="box" pos="0.00133234 -0.18583631 -0.14267632" size="0.06004676595330238 0.047027695924043655 0.02073153480887413" quat="1.0 0.0 0.0 0.0"/>
        <geom class="collision" type="box" pos="-0.06746832 -0.17187805 -0.14267632" size="0.025794075801968575 0.033069442957639694 0.02073153480887413" quat="1.0 0.0 0.0 0.0"/>
        <geom class="collision" type="box" pos="0.06682580 -0.17187805 -0.14267632" size="0.025794075801968575 0.033069442957639694 0.02073153480887413" quat="1.0 0.0 0.0 0.0"/>
        <geom class="collision" type="box" pos="-0.06120498 -0.01361217 0.07126802" size="0.015446631237864494 0.1343405395746231 0.05758656561374664" quat="0.9994908571243286 0.0 -0.0 -0.03190695121884346"/>
        <geom class="collision" type="box" pos="0.05448866 -0.01392873 0.07126802" size="0.017209811136126518 0.1343405395746231 0.05758656561374664" quat="1.0 0.0 0.0 0.0"/>
        <geom class="collision" type="box" pos="0.05220388 -0.07370593 0.09105101" size="0.009339816868305206 0.08286666870117188 0.05757973715662956" quat="1.0 0.0 0.0 0.0"/>
        <geom class="collision" type="box" pos="-0.05393906 -0.07370593 0.09105101" size="0.009339816868305206 0.08286666870117188 0.05757973715662956" quat="1.0 0.0 0.0 0.0"/>
        <geom class="collision" type="box" pos="0.01371926 -0.00648857 -0.07584269" size="0.07095097750425339 0.12511514127254486 0.08733459562063217" quat="0.998998761177063 0.0007554792682640254 -0.018539974465966225 0.04070787876844406"/>
        <body name="Button001">
          <joint axis="0.0 0.9961668848991394 -0.08747246116399765" pos="-0.02844916 -0.19306772 0.08361481" limited="true" name="Button001_joint" range="0.0 0.002" type="slide" damping="1" frictionloss="1" armature=".01" stiffness="0.2" springref="-0.1"/>
          <geom mesh="Button001_vis" type="mesh" solimp="0.998 0.998 0.001" solref="0.001 1" friction="0.95 0.3 0.1" class="visual" material="Button001_material"/>
          <geom class="collision" type="box" pos="-0.02833646 -0.19222710 0.08362260" size="0.007607913110405207 0.007607913110405207 0.0012142325285822153" quat="0.7459015250205994 0.6660562753677368 0.0 0.0"/>
        </body>
        <body name="Button002">
          <joint axis="0.0 0.9954521059989929 -0.09526348114013672" pos="0.02883963 -0.19306772 0.08361483" limited="true" name="Button002_joint" range="0.0 0.002" type="slide" damping="1" frictionloss="1" armature=".01" stiffness="0.2" springref="-0.1"/>
          <geom mesh="Button002_vis" type="mesh" solimp="0.998 0.998 0.001" solref="0.001 1" friction="0.95 0.3 0.1" class="visual" material="Button002_material"/>
          <geom class="collision" type="box" pos="0.02863881 -0.19230894 0.08363188" size="0.007607913110405207 0.007607913110405207 0.0012965851929038763" quat="0.7459015250205994 0.6660562753677368 0.0 0.0"/>
        </body>
        <body name="Container001_Clear">
          <!-- <joint axis="0.0 0.0 1.0" pos="-0.00007460 0.18167587 -0.04231491" limited="true" name="Container001_Clear_joint" range="0.0 0.05" type="slide" damping="1" frictionloss="1" armature=".01" stiffness="0.05"/> -->
          <geom mesh="Container001_Clear_vis" type="mesh" solimp="0.998 0.998 0.001" solref="0.001 1" friction="0.95 0.3 0.1" class="visual" material="Container001_Clear_material"/>
          <geom class="collision" type="cylinder" pos="0.00000000 0.18168957 -0.12482879" size="0.048823967576026917 0.002825837815180421" quat="1.0 0.0 0.0 0.0"/>
          <geom class="collision" type="box" pos="-0.00000000 0.13030651 -0.00235536" size="0.00850038044154644 0.0034357651602476835 0.12401857227087021" quat="1.0 0.0 0.0 0.0"/>
          <geom class="collision" type="box" pos="0.01535243 0.13267767 -0.00235536" size="0.00850038044154644 0.0034357651602476835 0.12401857227087021" quat="0.9885026812553406 0.0 0.0 0.15120349824428558"/>
          <geom class="collision" type="box" pos="0.02341253 0.13599030 -0.00235536" size="0.00850038044154644 0.0034357651602476835 0.12401857227087021" quat="0.9721153974533081 0.0 0.0 0.23450306057929993"/>
          <geom class="collision" type="box" pos="0.02874832 0.13915464 -0.00235536" size="0.00850038044154644 0.0034357651602476835 0.12401857227087021" quat="0.9561820030212402 0.0 0.0 0.29277297854423523"/>
          <geom class="collision" type="box" pos="0.03960427 0.14905068 -0.00235536" size="0.00850038044154644 0.0034357651602476835 0.12401857227087021" quat="0.9044972062110901 0.0 0.0 0.42647960782051086"/>
          <geom class="collision" type="box" pos="0.04754261 0.16240367 -0.00235536" size="0.00850038044154644 0.0034357651602476835 0.12401857227087021" quat="0.8296126127243042 0.0 0.0 0.5583394169807434"/>
          <geom class="collision" type="box" pos="0.05011499 0.17072962 -0.00235536" size="0.008500379510223866 0.00343576492741704 0.12401857227087021" quat="0.7792649269104004 0.0 0.0 0.6266946792602539"/>
          <geom class="collision" type="box" pos="0.05106851 0.17685942 -0.00235536" size="0.00850038044154644 0.0034357651602476835 0.12401857227087021" quat="0.7400022149085999 0.0 0.0 0.6726044416427612"/>
          <geom class="collision" type="box" pos="0.05024947 0.19198630 -0.00235536" size="0.00850038044154644 0.0034357651602476835 0.12401857227087021" quat="0.6327367424964905 0.0 0.0 0.7743669748306274"/>
          <geom class="collision" type="box" pos="0.04486630 0.20655824 -0.00235536" size="0.00850038044154644 0.0034357651602476835 0.12401857227087021" quat="0.5083749890327454 0.0 0.0 0.8611358404159546"/>
          <geom class="collision" type="box" pos="0.04001384 0.21379649 -0.00235536" size="0.00850038044154644 0.0034357651602476835 0.12401857227087021" quat="0.4335016906261444 0.0 0.0 0.9011527299880981"/>
          <geom class="collision" type="box" pos="0.03584963 0.21839463 -0.00235536" size="0.00850038044154644 0.0034357651602476835 0.12401857227087021" quat="0.37829774618148804 0.0 0.0 0.9256839752197266"/>
          <geom class="collision" type="box" pos="0.02398862 0.22706064 -0.00235536" size="0.00850038044154644 0.0034357651602476835 0.12401857227087021" quat="0.24205699563026428 0.0 0.0 0.9702620506286621"/>
          <geom class="collision" type="box" pos="0.00932146 0.23217865 -0.00235536" size="0.00850038044154644 0.0034357651602476835 0.12401857227087021" quat="0.09256701171398163 0.0 0.0 0.9957064390182495"/>
          <geom class="collision" type="box" pos="0.00064987 0.23304018 -0.00235536" size="0.00850038044154644 0.0034357651602476835 0.12401857227087021" quat="0.00777792651206255 0.0 0.0 0.9999697804450989"/>
          <geom class="collision" type="box" pos="-0.00554701 0.23275296 -0.00235536" size="0.008500379510223866 0.00343576492741704 0.12401857227087021" quat="0.05261608585715294 0.0 -0.0 -0.9986147880554199"/>
          <geom class="collision" type="box" pos="-0.02086051 0.22865207 -0.00235536" size="0.00850038044154644 0.0034357651602476835 0.12401857227087021" quat="0.2060772180557251 0.0 -0.0 -0.9785357117652893"/>
          <geom class="collision" type="box" pos="-0.03395268 0.22029054 -0.00235536" size="0.00850038044154644 0.0034357651602476835 0.12401857227087021" quat="0.3516659736633301 0.0 -0.0 -0.9361255764961243"/>
          <geom class="collision" type="box" pos="-0.03999216 0.21400858 -0.00235536" size="0.00850038044154644 0.0034357651602476835 0.12401857227087021" quat="0.42980024218559265 0.0 -0.0 -0.9029240012168884"/>
          <geom class="collision" type="box" pos="-0.04359856 0.20896103 -0.00235536" size="0.00850038044154644 0.0034357651602476835 0.12401857227087021" quat="0.4835362136363983 0.0 -0.0 -0.8753243684768677"/>
          <geom class="collision" type="box" pos="-0.04954130 0.19552723 -0.00235536" size="0.008500379510223866 0.00343576492741704 0.12401857227087021" quat="0.603721559047699 0.0 -0.0 -0.7971952557563782"/>
          <geom class="collision" type="box" pos="-0.05142002 0.18010680 -0.00235536" size="0.0036816170904785395 0.008596740663051605 0.12401857227087021" quat="1.0 0.0 0.0 0.0"/>
          <geom class="collision" type="box" pos="-0.05041600 0.17145055 -0.00235536" size="0.00850038044154644 0.0034357651602476835 0.12401857227087021" quat="0.7738319039344788 0.0 -0.0 -0.6333910226821899"/>
          <geom class="collision" type="box" pos="-0.04881633 0.16545681 -0.00235536" size="0.00850038044154644 0.0034357651602476835 0.12401857227087021" quat="0.8106650710105896 0.0 -0.0 -0.5855101346969604"/>
          <geom class="collision" type="box" pos="-0.05143508 0.18071903 -0.00235536" size="0.003581249387934804 0.00855813454836607 0.12401857227087021" quat="1.0 0.0 0.0 0.0"/>
          <geom class="collision" type="box" pos="-0.04880058 0.16540956 -0.00235536" size="0.008500379510223866 0.00343576492741704 0.12401857227087021" quat="0.8109488487243652 0.0 -0.0 -0.5851171016693115"/>
          <geom class="collision" type="box" pos="-0.04535002 0.15740758 -0.00235536" size="0.00850038044154644 0.0034357651602476835 0.12401857227087021" quat="0.8576557636260986 0.0 -0.0 -0.5142242312431335"/>
          <geom class="collision" type="box" pos="-0.04209450 0.15212690 -0.00235536" size="0.00850038044154644 0.0034357651602476835 0.12401857227087021" quat="0.8871405720710754 0.0 -0.0 -0.46149930357933044"/>
          <geom class="collision" type="box" pos="-0.03201347 0.14144253 -0.00235536" size="0.00850038044154644 0.0034357651602476835 0.12401857227087021" quat="0.9440107345581055 0.0 -0.0 -0.32991474866867065"/>
          <geom class="collision" type="box" pos="-0.01852611 0.13373470 -0.00235536" size="0.00850038044154644 0.0034357651602476835 0.12401857227087021" quat="0.9830413460731506 0.0 -0.0 -0.1833840012550354"/>
          <geom class="collision" type="box" pos="-0.01015719 0.13130569 -0.00235536" size="0.00850038044154644 0.0034357651602476835 0.12401857227087021" quat="0.9950533509254456 0.0 -0.0 -0.09934170544147491"/>
          <geom class="collision" type="box" pos="-0.00401190 0.13045760 -0.00235536" size="0.00850038044154644 0.0034357651602476835 0.12401857227087021" quat="0.9992361664772034 0.0 -0.0 -0.03907749429345131"/>
          <body name="Lid003">
            <!-- <joint axis="0.0 0.0 1.0" pos="-0.00007460 0.18167589 0.12289707" limited="true" name="Lid003_joint" range="0.0 0.05" type="slide" damping="1" frictionloss="1" armature=".01" stiffness="0.05"/> -->
            <geom mesh="Lid003_vis" type="mesh" solimp="0.998 0.998 0.001" solref="0.001 1" friction="0.95 0.3 0.1" class="visual" material="Lid003_material"/>
            <geom class="collision" type="cylinder" pos="0.00000000 0.18168957 0.12657201" size="0.0544167086482048 0.002825837815180421" quat="1.0 0.0 0.0 0.0"/>
          </body>
        </body>
        <body name="Lid001">
          <joint axis="-1.0 0.0 0.0" pos="-0.00168450 0.00204663 0.14778067" limited="true" name="Lid001_joint" range="0.0 1.5707963267948966" type="hinge" damping="1" frictionloss="1" armature=".01" stiffness="0.05"/>
          <geom mesh="Lid001_vis" type="mesh" solimp="0.998 0.998 0.001" solref="0.001 1" friction="0.95 0.3 0.1" class="visual" material="Lid001_material"/>
          <geom class="collision" type="box" pos="-0.00058151 -0.08484201 0.15097573" size="0.024652011692523956 0.07436910271644592 0.0048652286641299725" quat="0.9984737634658813 -0.05522807687520981 -0.0 0.0"/>
          <geom class="collision" type="box" pos="0.03039749 -0.08510069 0.14864452" size="0.009061611257493496 0.07436910271644592 0.004768600687384605" quat="0.9838422536849976 -0.05441880226135254 0.1703064739704132 -0.009420071728527546"/>
          <geom class="collision" type="box" pos="-0.03344478 -0.08508221 0.14881115" size="0.007928354665637016 0.07436910271644592 0.0032166189048439264" quat="0.9838421940803528 -0.05441881716251373 -0.17030689120292664 0.009420101530849934"/>
        </body>
        <body name="Lid002">
          <!-- <joint axis="0.0 0.0 1.0" pos="-0.00133493 -0.17526426 -0.11722137" limited="true" name="Lid002_joint" range="0.0 0.05" type="slide" damping="1" frictionloss="1" armature=".01" stiffness="0.05"/> -->
          <geom mesh="Lid002_vis" type="mesh" solimp="0.998 0.998 0.001" solref="0.001 1" friction="0.95 0.3 0.1" class="visual" material="Lid002_material"/>
          <geom class="collision" type="box" pos="0.00133234 -0.18085831 -0.11722140" size="0.06004676595330238 0.03832380846142769 0.0017765340162441134" quat="1.0 0.0 0.0 0.0"/>
          <geom class="collision" type="box" pos="-0.06233043 -0.17186133 -0.11722140" size="0.020656179636716843 0.02932683750987053 0.0017765340162441134" quat="1.0 0.0 0.0 0.0"/>
          <geom class="collision" type="box" pos="0.06168790 -0.17186131 -0.11722140" size="0.020656177774071693 0.02932683564722538 0.0017765340162441134" quat="1.0 0.0 0.0 0.0"/>
        </body>
        <site type="cylinder" rgba="0.8 0.5 0.25 1" size="0.0030428320169448853 0.06326339393854141" pos="-0.01858877 -0.16317043 -0.06470901" name="coffee_liquid_left"/>
        <site type="cylinder" rgba="0.8 0.5 0.25 1" size="0.0031466877553611994 0.06326339393854141" pos="0.01803329 -0.16317043 -0.06470901" name="coffee_liquid_right"/>
        <site rgba="0 0 0 0" size="0.019999999552965164 0.019999999552965164" pos="0.01 -0.19232263 -0.11787546" name="receptacle_place_site"/>
        <geom class="region" name="reg_main" type="box" pos="4.999999997368221e-09 3.999999999976245e-07 0.0" size="0.098357175 0.23743609999999998 0.1648411"/>
      </body>
    </body>
  </worldbody>
  <actuator>
    <motor name="Button001_joint_actuator" joint="Button001_joint" gear="0.5"/>
    <motor name="Button002_joint_actuator" joint="Button002_joint" gear="0.5"/>
    <!-- <motor name="Container001_Clear_joint_actuator" joint="Container001_Clear_joint" gear="10"/> -->
    <motor name="Lid001_joint_actuator" joint="Lid001_joint" gear="10"/>
    <!-- <motor name="Lid002_joint_actuator" joint="Lid002_joint" gear="10"/> -->
    <!-- <motor name="Lid003_joint_actuator" joint="Lid003_joint" gear="10"/> -->
  </actuator>
</mujoco>
