<?xml version='1.0' encoding='UTF-8'?>
<mujoco model="model">
  <option timestep="0.002" gravity="0.0 0.0 -9.81"/>
  <compiler angle="radian"/>
  <asset>
    <mesh file="visuals/door.obj" name="door_vis"/>
    <mesh file="visuals/door_Clear.obj" name="door_Clear_vis"/>
    <mesh file="visuals/knob_temp.obj" name="knob_temp_vis"/>
    <mesh file="visuals/knob_time.obj" name="knob_time_vis"/>
    <mesh file="visuals/Body001.obj" name="Body001_vis"/>
    <mesh file="visuals/rack0.obj" name="rack0_vis"/>
    <texture file="visuals/T_BC001.png" name="Body001_material" type="2d"/>
    <material name="Body001_material" rgba="1 1 1 1.0" texture="Body001_material" shininess="0.4472135901451111" specular="2"/>
    <texture file="visuals/T_BC001.png" name="door_material" type="2d"/>
    <material name="door_material" rgba="1 1 1 1.0" texture="door_material" shininess="0.4472135901451111" specular="2"/>
    <texture file="visuals/T_BC001.png" name="door_Clear_material" type="2d"/>
    <material name="door_Clear_material" rgba="1 1 1 0.7935505509376526" texture="door_Clear_material" shininess="0.4472135901451111" specular="0.3103448502657381"/>
    <texture file="visuals/T_BC001.png" name="knob_temp_material" type="2d"/>
    <material name="knob_temp_material" rgba="1 1 1 1.0" texture="knob_temp_material" shininess="0.4472135901451111" specular="2"/>
    <texture file="visuals/T_BC001.png" name="knob_time_material" type="2d"/>
    <material name="knob_time_material" rgba="1 1 1 1.0" texture="knob_time_material" shininess="0.4472135901451111" specular="2"/>
    <texture file="visuals/T_BC001.png" name="rack0_material" type="2d"/>
    <material name="rack0_material" rgba="1 1 1 1.0" texture="rack0_material" shininess="0.4472135901451111" specular="3"/>
  </asset>
  <default>
    <default class="visual">
      <geom conaffinity="0" contype="0" group="1" type="mesh"/>
    </default>
    <default class="collision">
      <geom group="0" rgba="0.5 0 0 0.5"/>
    </default>
    <default class="spawn">
      <geom group="0" rgba="1 1 1 0.5" contype="0" conaffinity="0"/>
      <site group="0" rgba="1 1 1 0.5"/>
    </default>
    <default class="region">
      <geom group="1" conaffinity="0" contype="0" rgba="0 1 0 0"/>
    </default>
  </default>
  <worldbody>
    <body>
      <body name="object">
        <geom mesh="Body001_vis" type="mesh" solimp="0.998 0.998 0.001" solref="0.001 1" friction="0.95 0.3 0.1" class="visual" material="Body001_material"/>
        <geom class="collision" type="box" pos="8.997171896396594e-09 0.03359567001461983 -0.23666268587112427" size="0.29789331555366516 0.28025561571121216 0.06047181040048599" quat="1.0 0.0 0.0 0.0"/>
        <geom class="collision" type="box" pos="8.997171896396594e-09 0.03359567001461983 0.152528315782547" size="0.297891765832901 0.28025561571121216 0.0229275394231081" quat="1.0 0.0 0.0 0.0"/>
        <geom class="collision" type="box" pos="8.997171896396594e-09 0.2713991701602936 -0.026509864255785942" size="0.2978918254375458 0.0424521267414093 0.16321706771850586" quat="1.0 0.0 0.0 0.0"/>
        <geom class="collision" type="box" pos="8.997171896396594e-09 -0.237870991230011 0.23620638251304626" size="0.29789188504219055 0.01453822199255228 0.06143416091799736" quat="1.0 0.0 0.0 0.0"/>
        <geom class="collision" type="box" pos="-0.26134997606277466 -0.006889544427394867 -0.02650986984372139" size="0.03654332831501961 0.23991259932518005 0.16321706771850586" quat="1.0 0.0 0.0 0.0"/>
        <geom class="collision" type="box" pos="0.2615256905555725 -0.006889544427394867 -0.02650986984372139" size="0.03636763244867325 0.23991259932518005 0.16321706771850586" quat="1.0 0.0 0.0 0.0"/>
        <geom class="collision" type="box" pos="0.20561546087265015 -0.008686602115631104 -0.08421019464731216" size="0.005245341453701258 0.1396121233701706 0.0022579608485102654" quat="1.0 0.0 0.0 0.0"/>
        <geom class="collision" type="box" pos="-0.2059779167175293 -0.008686602115631104 -0.0844443291425705" size="0.005245341453701258 0.1396121233701706 0.0022579608485102654" quat="1.0 0.0 0.0 0.0"/>
        <geom class="collision" type="box" pos="-0.25359785556793213 0.01937284506857395 -0.030206579715013504" size="0.04429559409618378 0.18684671819210052 0.08682307600975037" quat="1.0 0.0 0.0 0.0"/>
        <geom class="collision" type="box" pos="0.2535504698753357 0.019070351496338844 -0.030206579715013504" size="0.04434296488761902 0.18654409050941467 0.086823008954525" quat="1.0 0.0 0.0 0.0"/>
        <body name="door">
         <joint axis="1.0 0.0 0.0" pos="-4.103255923837423e-05 -0.26975842006504536 -0.2657351791858673" limited="true" name="door_joint" range="0.0 1.05" type="hinge" damping="1" frictionloss="1" armature="1" stiffness="2"/>
          <geom mesh="door_vis" type="mesh" solimp="0.998 0.998 0.001" solref="0.001 1" friction="0.95 0.3 0.1" class="visual" material="door_material"/>
          <geom class="collision" type="box" pos="-4.103255923837423e-05 -0.2616859972476959 -0.0484561026096344" size="0.29785436391830444 0.008072422817349434 0.2172790765762329" quat="1.0 0.0 0.0 0.0" name="door_main"/>
          <geom class="collision" type="cylinder" pos="-3.313751708336433e-17 -0.3022207021713257 0.14923810958862305" size="0.01154937595129013 0.27145805954933167" quat="0.7071068286895752 -4.750302551315144e-08 0.7071067094802856 4.7503014855010406e-08" name="door_handle_main"/>
          <body name="door_Clear">
            <geom mesh="door_Clear_vis" type="mesh" solimp="0.998 0.998 0.001" solref="0.001 1" friction="0.95 0.3 0.1" class="visual" material="door_Clear_material"/>
          </body>
        </body>
        <body name="knob_temp">
          <joint axis="0.0 1.0 0.0" pos="-0.23529845476150513 -0.27033066749572754 0.23625878989696503" limited="true" name="knob_temp_joint" range="0.0 5.585053606381854" type="hinge" damping="0.05" armature="1" frictionloss="0.75"/>
          <geom mesh="knob_temp_vis" type="mesh" solimp="0.998 0.998 0.001" solref="0.001 1" friction="0.95 0.3 0.1" class="visual" material="knob_temp_material"/>
          <geom class="collision" type="cylinder" pos="-0.23528419435024261 -0.2644576132297516 0.2362239807844162" size="0.02280486561357975 0.010639902204275131" quat="0.7071068286895752 0.7071067690849304 -1.5700924318127872e-16 -5.9269340452702814e-24" name="knob_temp_main" friction="100 0.5 0.01"/>
          <geom class="collision" type="box" pos="-0.23520402610301971 -0.28180527687072754 0.2357035130262375" size="0.005530590191483498 0.006051141303032637 0.016372092068195343" quat="1.0 0.0 0.0 0.0" friction="100 0.5 0.01"/>
        </body>
        <body name="knob_time">
          <joint axis="0.0 -1.0 0.0" pos="0.23303470015525818 -0.27033063769340515 0.23482543230056763" name="knob_time_joint" range="-1.0471975511965976 3.141592653589793" type="hinge" damping="0.05" armature="1" frictionloss="0.75"/>
          <geom mesh="knob_time_vis" type="mesh" solimp="0.998 0.998 0.001" solref="0.001 1" friction="0.95 0.3 0.1" class="visual" material="knob_time_material"/>
          <geom class="collision" type="cylinder" pos="0.23303470015525818 -0.26409900188446045 0.23482543230056763" size="0.02280486561357975 0.010685468092560768" quat="0.7071068286895752 0.7071067690849304 -1.5700924318127872e-16 -5.9269340452702814e-24" name="knob_time_main" friction="100 0.5 0.01"/>
          <geom class="collision" type="box" pos="0.23303470015525818 -0.28180527687072754 0.2357035130262375" size="0.005530590191483498 0.006051141303032637 0.016372092068195343" quat="1.0 0.0 0.0 0.0" friction="100 0.5 0.01"/>
        </body>
        <body name="rack0">
          <geom class="region" name="reg_rack0" type="box" pos="-0.0014535337686538696 0.015737280249595642 0.018328838050365448" size="0.18742711639404297 0.14561131393909454 0.10660755431652069"/>
          <joint axis="0.0 -1.0 0.0" pos="-1.658499240875244e-05 0.015904594212770462 -0.0878145769238472" limited="true" name="rack0_joint" range="0.0 0.30" type="slide" damping="1" frictionloss="1" armature=".01" stiffness="0.05"/>
          <geom mesh="rack0_vis" type="mesh" solimp="0.998 0.998 0.001" solref="0.001 1" friction="0.95 0.3 0.1" class="visual" material="rack0_material"/>
          <geom class="collision" type="box" pos="-1.658499240875244e-05 -0.13808530569076538 -0.0878145769238472" size="0.19845271110534668 0.003500240622088313 0.011858089827001095" quat="1.0 0.0 0.0 0.0"/>
          <geom class="collision" type="box" pos="-1.658499240875244e-05 0.1694319248199463 -0.0878145769238472" size="0.19845271110534668 0.003500240622088313 0.011858089827001095" quat="1.0 0.0 0.0 0.0"/>
          <geom class="collision" type="box" pos="-1.658499240875244e-05 0.015257209539413452 -0.09638398885726929" size="0.19845271110534668 0.1511310338973999 0.0032886744011193514" quat="1.0 0.0 0.0 0.0"/>
          <geom class="collision" type="box" pos="-0.2011500597000122 0.015257209539413452 -0.0787535309791565" size="0.005066304467618465 0.1511310338973999 0.0028946958482265472" quat="1.0 0.0 0.0 0.0"/>
          <geom class="collision" type="box" pos="0.20123517513275146 0.015257209539413452 -0.07868973165750504" size="0.005066304467618465 0.1511310338973999 0.0027903129812330008" quat="1.0 0.0 0.0 0.0"/>
          <geom class="collision" type="box" pos="0.19513991475105286 0.015257209539413452 -0.08776701241731644" size="0.0027219720650464296 0.1511310338973999 0.01186759490519762" quat="1.0 0.0 0.0 0.0"/>
          <geom class="collision" type="box" pos="-0.19634169340133667 0.015257209539413452 -0.08776701241731644" size="0.0027219720650464296 0.1511310338973999 0.01186759490519762" quat="1.0 0.0 0.0 0.0"/>
        </body>
        <geom class="region" name="reg_int" type="box" pos="-9.096413850784302e-05 -0.010981820523738861 -0.022656604647636414" size="0.21881735867261887 0.2343974912762642 0.14772255516052246"/>
        <geom class="region" name="reg_main" type="box" pos="-7.450580596923828e-09 0.030613943934440613 0.0" size="0.29889331555366516 0.284237487077713 0.2981334159374237"/>
      </body>
    </body>
  </worldbody>
  <actuator>
    <motor name="door_joint_actuator" joint="door_joint" gear="50"/>
    <motor name="knob_temp_joint_actuator" joint="knob_temp_joint" gear="10"/>
    <motor name="knob_time_joint_actuator" joint="knob_time_joint" gear="10"/>
    <motor name="rack0_joint_actuator" joint="rack0_joint" gear="50"/>
  </actuator>
</mujoco>