<?xml version='1.0' encoding='UTF-8'?>
<mujoco model="model">
  <option timestep="0.002" gravity="0.0 0.0 -9.81"/>
  <compiler angle="radian"/>
  <asset>
    <mesh file="visuals/blender.obj" name="blender_vis"/>
    <mesh file="visuals/bowl.obj" name="bowl_vis"/>
    <mesh file="visuals/button_head_lock.obj" name="button_head_lock_vis"/>
    <mesh file="visuals/head.obj" name="head_vis"/>
    <mesh file="visuals/knob_speed.obj" name="knob_speed_vis"/>
    <mesh file="visuals/Body001.obj" name="Body001_vis"/>
    <texture file="visuals/T_BC001.png" name="Body001_material" type="2d"/>
    <material name="Body001_material" rgba="1 1 1 1.0" texture="Body001_material" shininess="0.4472135901451111" specular="0.3103448502657381"/>
    <texture file="visuals/T_BC001.png" name="bowl_material" type="2d"/>
    <material name="bowl_material" rgba="1 1 1 1.0" texture="bowl_material" shininess="1" specular="1"/>
    <texture file="visuals/T_BC001.png" name="button_head_lock_material" type="2d"/>
    <material name="button_head_lock_material" rgba="1 1 1 1.0" texture="button_head_lock_material" shininess="0.4472135901451111" specular="0.3103448502657381"/>
    <texture file="visuals/T_BC001.png" name="head_material" type="2d"/>
    <material name="head_material" rgba="1 1 1 1.0" texture="head_material" shininess="0.4472135901451111" specular="0.3103448502657381"/>
    <texture file="visuals/T_BC001.png" name="blender_material" type="2d"/>
    <material name="blender_material" rgba="1 1 1 1.0" texture="blender_material" shininess="1" specular="1"/>
    <texture file="visuals/T_BC001.png" name="knob_speed_material" type="2d"/>
    <material name="knob_speed_material" rgba="1 1 1 1.0" texture="knob_speed_material" shininess="0.4472135901451111" specular="0.3103448502657381"/>
  </asset>
  <default>
    <default class="visual">
      <geom conaffinity="0" contype="0" group="1" type="mesh"/>
    </default>
    <default class="collision">
      <geom group="0" rgba="0.5 0 0 0.5"/>
    </default>
    <default class="spawn">
      <geom group="0" rgba="1 1 1 0.5" contype="0" conaffinity="0"/>
      <site group="0" rgba="1 1 1 0.5"/>
    </default>
    <default class="region">
      <geom group="1" conaffinity="0" contype="0" rgba="0 1 0 0"/>
    </default>
  </default>
  <worldbody>
    <body>
      <body name="object">
        <geom mesh="Body001_vis" type="mesh" solimp="0.998 0.998 0.001" solref="0.001 1" friction="0.95 0.3 0.1" class="visual" material="Body001_material"/>
        <geom type="box" pos="-0.0020150209311395884 0.10966469347476959 -0.011680183932185173" size="0.09030012786388397 0.0818587988615036 0.13259609043598175" quat="1.0 0.0 0.0 0.0" class="collision"/>
        <geom type="cylinder" pos="-0.09157982468605042 -0.12557129561901093 -0.21869555115699768" size="0.01601528935134411 0.011921694502234459" quat="1.0 0.0 0.0 0.0" class="collision"/>
        <geom type="cylinder" pos="-0.09157982468605042 0.13837343454360962 -0.21869555115699768" size="0.01601528935134411 0.011921694502234459" quat="1.0 0.0 0.0 0.0" class="collision"/>
        <geom type="cylinder" pos="0.0929291695356369 0.13837343454360962 -0.21869555115699768" size="0.01601528935134411 0.011921694502234459" quat="1.0 0.0 0.0 0.0" class="collision"/>
        <geom type="cylinder" pos="0.0929291695356369 -0.12557129561901093 -0.21869555115699768" size="0.01601528935134411 0.011921694502234459" quat="1.0 0.0 0.0 0.0" class="collision"/>
        <geom type="cylinder" pos="-0.09143412858247757 -0.12539009749889374 -0.1359458714723587" size="0.008488369174301624 0.009389183484017849" quat="1.0 0.0 0.0 0.0" class="collision"/>
        <geom type="cylinder" pos="0.09264079481363297 -0.12539009749889374 -0.1359458714723587" size="0.008488369174301624 0.009389183484017849" quat="1.0 0.0 0.0 0.0" class="collision"/>
        <geom type="cylinder" pos="-0.00843361858278513 -0.12539009749889374 -0.1359458714723587" size="0.008488369174301624 0.009389183484017849" quat="1.0 0.0 0.0 0.0" class="collision"/>
        <geom type="cylinder" pos="-0.001985041191801429 -0.11356186866760254 -0.14867164194583893" size="0.06737740337848663 0.02544773928821087" quat="1.0 0.0 0.0 0.0" class="collision"/>
        <geom type="box" pos="-0.0006400577840395272 0.04438207298517227 -0.178863063454628" size="0.1297663003206253 0.18647709488868713 0.03476670756936073" quat="1.0 0.0 0.0 0.0" class="collision"/>
        <geom type="cylinder" pos="0.0007358510629273951 -0.09750024229288101 -0.17969581484794617" size="0.13394969701766968 0.033853307366371155" quat="1.0 0.0 0.0 0.0" class="collision"/>
        <body name="bowl">
          <!-- <joint axis="0.0 0.0 1.0" pos="0.0 -0.10831348598003387 -0.04335395246744156" limited="true" name="bowl_joint" range="0.0 0.1" type="slide" damping="1" frictionloss="1" armature=".01" stiffness="0.05"/> -->
          <geom mesh="bowl_vis" type="mesh" solimp="0.998 0.998 0.001" solref="0.001 1" friction="0.95 0.3 0.1" class="visual" material="bowl_material"/>
          <geom type="box" pos="0.10189328342676163 -0.11322380602359772 -0.10233451426029205" size="0.013965840451419353 0.0066327000968158245 0.015045318752527237" quat="0.7120574712753296 0.12730690836906433 0.12152275443077087 0.6797053217887878" class="collision"/>
          <geom type="box" pos="0.09313759207725525 -0.1500387042760849 -0.10233451426029205" size="0.013965838588774204 0.00663269916549325 0.015045315958559513" quat="0.8260143995285034 0.14768095314502716 0.09573482722043991 0.5354674458503723" class="collision"/>
          <geom type="box" pos="0.09738185256719589 -0.1519366353750229 -0.028676670044660568" size="0.01396583765745163 0.006632702890783548 0.06229601800441742" quat="0.8391123414039612 0.0 0.0 0.5439581871032715" class="collision"/>
          <geom type="cylinder" pos="0.00023518240777775645 -0.11029031872749329 -0.11285266280174255" size="0.09875737875699997 0.00806751474738121" quat="1.0 0.0 0.0 0.0" class="collision"/>
          <geom type="box" pos="0.021402928978204727 -0.20803727209568024 -0.10233448445796967" size="0.013965836726129055 0.00663269916549325 0.015045316889882088" quat="0.9789935350418091 0.1750316321849823 0.018404554575681686 0.10294099152088165" class="collision"/>
          <geom type="box" pos="0.06026076897978783 -0.1963675171136856 -0.028676670044660568" size="0.01396583765745163 0.006632702890783548 0.06229601800441742" quat="0.9554409384727478 0.0 0.0 0.29518234729766846" class="collision"/>
          <geom type="box" pos="0.05763828754425049 -0.19252844154834747 -0.10233451426029205" size="0.013965838588774204 0.006632699631154537 0.015045318752527237" quat="0.9405272603034973 0.16815443336963654 0.05195111781358719 0.2905747592449188" class="collision"/>
          <geom type="box" pos="0.08464417606592178 -0.1653444468975067 -0.10233451426029205" size="0.013965838588774204 0.0066327000968158245 0.015045316889882088" quat="0.8690050840377808 0.15536712110042572 0.08267930895090103 0.4624449908733368" class="collision"/>
          <geom type="box" pos="0.08850041776895523 -0.1679416447877884 -0.028676670044660568" size="0.01396583765745163 0.006632702890783548 0.06229601800441742" quat="0.8827846646308899 0.0 0.0 0.469777911901474" class="collision"/>
          <geom type="box" pos="0.10429301112890244 -0.13077999651432037 -0.028676677495241165" size="0.013965839520096779 0.006632703822106123 0.06229601800441742" quat="0.7776281237602234 0.0 0.0 0.6287245154380798" class="collision"/>
          <geom type="box" pos="0.09974677860736847 -0.12980639934539795 -0.10233451426029205" size="0.01396583765745163 0.006632699631154537 0.015045315958559513" quat="0.765489935874939 0.1368599534034729 0.11065340042114258 0.6189106106758118" class="collision"/>
          <geom type="box" pos="0.10065349191427231 -0.09197548031806946 -0.10233451426029205" size="0.013965839520096779 0.006632699631154537 0.015045316889882088" quat="0.6370744109153748 0.11390084028244019 0.1341693252325058 0.750440776348114" class="collision"/>
          <geom type="box" pos="0.10524114221334457 -0.09122078120708466 -0.028676670044660568" size="0.013965841382741928 0.00663270428776741 0.06229601800441742" quat="0.6471763253211975 0.0 0.0 0.7623403668403625" class="collision"/>
          <geom type="box" pos="0.07420507073402405 -0.18500061333179474 -0.028676670044660568" size="0.013965839520096779 0.006632703822106123 0.06229601800441742" quat="0.9270707368850708 0.0 0.0 0.3748863935470581" class="collision"/>
          <geom type="box" pos="0.0904875099658966 -0.0521109402179718 -0.028676670044660568" size="0.013965836726129055 0.006632702425122261 0.06229601800441742" quat="0.4848506450653076 0.0 0.0 0.8745969533920288" class="collision"/>
          <geom type="box" pos="0.08654442429542542 -0.05457431823015213 -0.10233451426029205" size="0.01396583765745163 0.006632699631154537 0.015045316889882088" quat="0.4772825241088867 0.08533207327127457 0.15392613410949707 0.8609451651573181" class="collision"/>
          <geom type="box" pos="0.022369982674717903 -0.21258492767810822 -0.028676670044660568" size="0.013965839520096779 0.006632703822106123 0.06229601800441742" quat="0.9945171475410461 0.0 0.0 0.10457359999418259" class="collision"/>
          <geom type="box" pos="0.061737511307001114 -0.02741362899541855 -0.10233451426029205" size="0.013965836726129055 0.0066327000968158245 0.015045316889882088" quat="0.3138279318809509 0.056108467280864716 0.1668132245540619 0.9330258369445801" class="collision"/>
          <geom type="box" pos="0.06454727053642273 -0.023709386587142944 -0.028676677495241165" size="0.013965836726129055 0.006632702425122261 0.06229601800441742" quat="0.31880423426628113 0.0 0.0 0.9478206038475037" class="collision"/>
          <geom type="box" pos="0.026318933814764023 -0.005323871970176697 -0.028676670044660568" size="0.01396583765745163 0.006632702890783548 0.06229601800441742" quat="0.12349949777126312 0.0 0.0 0.9923446178436279" class="collision"/>
          <geom type="box" pos="0.025179345160722733 -0.009831339120864868 -0.10233451426029205" size="0.01396583765745163 0.006632698699831963 0.015045315958559513" quat="0.12157176434993744 0.02173551917076111 0.17464932799339294 0.9768549203872681" class="collision"/>
          <geom type="box" pos="-0.012225277721881866 -0.007492713630199432 -0.10233451426029205" size="0.013965840451419353 0.006632700562477112 0.015045315958559513" quat="0.06037798523902893 0.010794822126626968 -0.17566528916358948 -0.9825373888015747" class="collision"/>
          <geom type="box" pos="-0.012794534675776958 -0.0028783977031707764 -0.028676670044660568" size="0.013965840451419353 0.006632703822106123 0.06229601800441742" quat="0.061335381120443344 0.0 0.0 -0.998117208480835" class="collision"/>
          <geom type="box" pos="-0.05263176187872887 -0.0161384716629982 -0.028676677495241165" size="0.013965838588774204 0.006632703356444836 0.06229601800441742" quat="0.25702959299087524 0.0 0.0 -0.9664035439491272" class="collision"/>
          <geom type="box" pos="0.07097336649894714 -0.18165814876556396 -0.10233451426029205" size="0.013965836726129055 0.0066327000968158245 0.015045316889882088" quat="0.9125999212265015 0.16316133737564087 0.0659787505865097 0.36903467774391174" class="collision"/>
          <geom type="box" pos="-0.0503220334649086 -0.020173467695713043 -0.10233451426029205" size="0.013965840451419353 0.0066327000968158245 0.015045316889882088" quat="0.2530176639556885 0.04523634538054466 -0.17008377611637115 -0.9513186812400818" class="collision"/>
          <geom type="box" pos="-0.07794873416423798 -0.04334898293018341 -0.10233451426029205" size="0.013965839520096779 0.0066327000968158245 0.015045316889882088" quat="0.417558878660202 0.07465425878763199 -0.15937866270542145 -0.8914425373077393" class="collision"/>
          <geom type="box" pos="-0.08152057975530624 -0.04037274420261383 -0.028676670044660568" size="0.013965839520096779 0.006632703822106123 0.06229601800441742" quat="0.4241800010204315 0.0 0.0 -0.9055778980255127" class="collision"/>
          <geom type="box" pos="-0.10010028630495071 -0.07303456962108612 -0.028676670044660568" size="0.013965836726129055 0.006632702425122261 0.06229601800441742" quat="0.5773990154266357 0.0 0.0 -0.8164620995521545" class="collision"/>
          <geom type="box" pos="-0.095716692507267 -0.07458384335041046 -0.10233451426029205" size="0.013965836726129055 0.0066327000968158245 0.015045316889882088" quat="0.5683863162994385 0.10162027180194855 -0.14369459450244904 -0.8037177324295044" class="collision"/>
          <geom type="box" pos="-0.10152013599872589 -0.11010442674160004 -0.10233451426029205" size="0.013965838588774204 0.006632700562477112 0.015045316889882088" quat="0.7015516757965088 0.12542855739593506 -0.12346050143241882 -0.6905435919761658" class="collision"/>
          <geom type="box" pos="-0.10616885870695114 -0.11017793416976929 -0.028676670044660568" size="0.013965838588774204 0.006632703356444836 0.06229601800441742" quat="0.712675929069519 0.0 0.0 -0.7014934420585632" class="collision"/>
          <geom type="box" pos="-0.09911313652992249 -0.1466338187456131 -0.028676670044660568" size="0.013965840451419353 0.006632703822106123 0.06229601800441742" quat="0.8241325616836548 0.0 0.0 -0.5663970112800598" class="collision"/>
          <geom type="box" pos="-0.09477266669273376 -0.14496755599975586 -0.10233451426029205" size="0.013965836726129055 0.006632699631154537 0.015045318752527237" quat="0.8112683892250061 0.14504455029964447 -0.09968403726816177 -0.5575560927391052" class="collision"/>
          <geom type="box" pos="-0.074417345225811 -0.17765958607196808 -0.10233451426029205" size="0.013965839520096779 0.0066327000968158245 0.015045316889882088" quat="0.9021095633506775 0.16128577291965485 -0.0704394057393074 -0.39398422837257385" class="collision"/>
          <geom type="box" pos="0.03890387341380119 -0.202630415558815 -0.10233448445796967" size="0.013965840451419353 0.006632699631154537 0.015045318752527237" quat="0.965756893157959 0.17266513407230377 0.03408178314566612 0.19062745571136475" class="collision"/>
          <geom type="box" pos="-0.07782787829637527 -0.18081939220428467 -0.028676677495241165" size="0.013965838588774204 0.006632703356444836 0.06229601800441742" quat="0.9164140224456787 0.0 0.0 -0.40023157000541687" class="collision"/>
          <geom type="box" pos="-0.048105597496032715 -0.2032991498708725 -0.028676670044660568" size="0.01396583765745163 0.006632702890783548 0.06229601800441742" quat="0.9723350405693054 0.0 0.0 -0.23359063267707825" class="collision"/>
          <geom type="box" pos="-0.045993611216545105 -0.19915719330310822 -0.10233451426029205" size="0.013965839520096779 0.006632700562477112 0.015045318752527237" quat="0.9571576714515686 0.17112773656845093 -0.04111115261912346 -0.2299443483352661" class="collision"/>
          <geom type="box" pos="-0.014120768755674362 -0.20924539864063263 -0.10233451426029205" size="0.013965841382741928 0.006632700562477112 0.015045318752527237" quat="0.9819267988204956 0.17555609345436096 -0.012444666586816311 -0.06960588693618774" class="collision"/>
          <geom type="box" pos="-0.014776633121073246 -0.21384824812412262 -0.028676670044660568" size="0.01396583765745163 0.006632702890783548 0.06229601800441742" quat="0.9974969625473022 0.0 0.0 -0.07070967555046082" class="collision"/>
          <geom type="box" pos="-0.036361776292324066 -0.20842157304286957 -0.028676677495241165" size="0.013965838588774204 0.006632703356444836 0.06229601800441742" quat="0.9846334457397461 0.0 0.0 -0.1746336817741394" class="collision"/>
          <geom type="box" pos="-0.03476287052035332 -0.20405586063861847 -0.10233451426029205" size="0.013965836726129055 0.00663269916549325 0.015045317821204662" quat="0.9692639708518982 0.17329254746437073 -0.030735071748495102 -0.17190803587436676" class="collision"/>
          <geom type="box" pos="-0.06384027004241943 -0.18755872547626495 -0.10233451426029205" size="0.013965839520096779 0.0066327000968158245 0.015045320615172386" quat="0.927863597869873 0.16589036583900452 -0.05878116562962532 -0.3287770748138428" class="collision"/>
          <geom type="box" pos="-0.06676758825778961 -0.1911708265542984 -0.028676677495241165" size="0.01396583765745163 0.006632702890783548 0.06229601800441742" quat="0.9425765872001648 0.0 0.0 -0.3339901566505432" class="collision"/>
          <geom type="box" pos="-0.0911640077829361 -0.1630004495382309 -0.028676670044660568" size="0.013965839520096779 0.006632703822106123 0.06229601800441742" quat="0.8695359230041504 0.0 0.0 -0.49386975169181824" class="collision"/>
          <geom type="box" pos="0.04067046567797661 -0.206931009888649 -0.028676677495241165" size="0.013965839520096779 0.006632703822106123 0.06229601800441742" quat="0.9810706377029419 0.0 0.0 0.19365014135837555" class="collision"/>
          <geom type="box" pos="-0.08717083185911179 -0.16061915457248688 -0.10233451426029205" size="0.013965839520096779 0.006632699631154537 0.015045316889882088" quat="0.8559631109237671 0.15303540229797363 -0.08691941201686859 -0.4861608147621155" class="collision"/>
          <geom type="box" pos="-0.1002810150384903 -0.12440823018550873 -0.10233451426029205" size="0.013965836726129055 0.006632701028138399 0.015045316889882088" quat="0.7485148310661316 0.13382500410079956 -0.11430522799491882 -0.6393361687660217" class="collision"/>
          <geom type="box" pos="-0.10487311333417892 -0.12513522803783417 -0.028676670044660568" size="0.013965836726129055 0.006632702425122261 0.06229601800441742" quat="0.7603838443756104 0.0 0.0 -0.6494739651679993" class="collision"/>
          <geom type="box" pos="-0.10419172793626785 -0.08800908923149109 -0.028676670044660568" size="0.013965836726129055 0.006632702425122261 0.06229601800441742" quat="0.6354108452796936 0.0 0.0 -0.7721742391586304" class="collision"/>
          <geom type="box" pos="-0.09962937980890274 -0.08890409767627716 -0.10233451426029205" size="0.013965840451419353 0.006632699631154537 0.015045315958559513" quat="0.6254926919937134 0.11183018237352371 -0.13590008020401 -0.7601211071014404" class="collision"/>
          <geom type="box" pos="-0.08656459301710129 -0.05536751449108124 -0.10233451426029205" size="0.013965838588774204 0.0066327000968158245 0.015045316889882088" quat="0.4812224805355072 0.08603650331497192 -0.15353348851203918 -0.8587491512298584" class="collision"/>
          <geom type="box" pos="-0.09053006768226624 -0.05294034630060196 -0.028676670044660568" size="0.013965838588774204 0.006632703356444836 0.06229601800441742" quat="0.4888530969619751 0.0 0.0 -0.8723661303520203" class="collision"/>
          <geom type="box" pos="-0.06556304544210434 -0.02485746145248413 -0.028676670044660568" size="0.013965838588774204 0.006632703356444836 0.06229601800441742" quat="0.3271549344062805 0.0 0.0 -0.9449707269668579" class="collision"/>
          <geom type="box" pos="-0.06268836557865143 -0.028511539101600647 -0.10233451426029205" size="0.013965839520096779 0.006632700562477112 0.015045315958559513" quat="0.3220481872558594 0.05757814273238182 -0.16631169617176056 -0.9302204847335815" class="collision"/>
          <geom type="box" pos="-0.03084539622068405 -0.011589251458644867 -0.10233451426029205" size="0.013965841382741928 0.006632699631154537 0.015045318752527237" quat="0.15214776992797852 0.027202147990465164 -0.1738818734884262 -0.9725616574287415" class="collision"/>
          <geom type="box" pos="0.00023517990484833717 -0.21026302874088287 -0.10233448445796967" size="0.013965838588774204 0.006632700562477112 0.015045320615172386" quat="0.9843907356262207 0.17599669098854065 -3.907928115478584e-17 1.2584044844161278e-23" class="collision"/>
          <geom type="box" pos="-0.0322653166949749 -0.007162079215049744 -0.028676670044660568" size="0.013965841382741928 0.00663270428776741 0.06229601800441742" quat="0.15456034243106842 0.0 0.0 -0.9879833459854126" class="collision"/>
          <geom type="box" pos="0.00945871789008379 -0.002478167414665222 -0.028676670044660568" size="0.013965838588774204 0.006632703356444836 0.06229601800441742" quat="0.04337745159864426 0.0 0.0 0.9990587830543518" class="collision"/>
          <geom type="box" pos="0.009055743925273418 -0.007109969854354858 -0.10233451426029205" size="0.013965838588774204 0.00663269916549325 0.015045317821204662" quat="0.04270035773515701 0.00763430492952466 0.17583119869232178 0.9834641814231873" class="collision"/>
          <geom type="box" pos="0.0451558418571949 -0.01717764139175415 -0.10233451426029205" size="0.013965839520096779 0.00663269916549325 0.015045320615172386" quat="0.22305823862552643 0.039880018681287766 0.17141884565353394 0.9587857723236084" class="collision"/>
          <geom type="box" pos="0.047208067029714584 -0.013005778193473816 -0.028676670044660568" size="0.013965839520096779 0.006632703822106123 0.06229601800441742" quat="0.2265952229499817 0.0 0.0 0.9739890098571777" class="collision"/>
          <geom type="box" pos="0.08077610284090042 -0.0389406681060791 -0.028676670044660568" size="0.013965839520096779 0.006632703822106123 0.06229601800441742" quat="0.4161731004714966 0.0 0.0 0.9092854261398315" class="collision"/>
          <geom type="box" pos="0.07725732028484344 -0.041979461908340454 -0.10233451426029205" size="0.013965839520096779 0.0066327000968158245 0.015045316889882088" quat="0.40967684984207153 0.07324506342411041 0.16003122925758362 0.8950921893119812" class="collision"/>
          <geom type="box" pos="0.09587226063013077 -0.07370595633983612 -0.10233451426029205" size="0.013965836726129055 0.006632699631154537 0.015045318752527237" quat="0.5646975040435791 0.10096082091331482 0.144158735871315 0.8063137531280518" class="collision"/>
          <geom type="box" pos="0.10024146735668182 -0.07211661338806152 -0.028676670044660568" size="0.013965836726129055 0.006632702425122261 0.06229601800441742" quat="0.5736517310142517 0.0 0.0 0.8190993070602417" class="collision"/>
          <geom type="box" pos="0.10653755813837051 -0.11343982815742493 -0.028676670044660568" size="0.01396583765745163 0.006632702890783548 0.06229601800441742" quat="0.7233484387397766 0.0 0.0 0.6904832124710083" class="collision"/>
          <geom type="box" pos="0.00023517990484833717 -0.21491236984729767 -0.028676670044660568" size="0.013965838588774204 0.006632703356444836 0.06229601800441742" quat="1.0 0.0 0.0 0.0" class="collision"/>
          <geom name="reg_bowl" type="ellipsoid" pos="0.0002351822331547737 -0.109382763504982 0.034054793417453766" size="0.09605401754379272 0.097884401679039 0.1370994597673416" rgba="0 1 0 0.5" class="region"/>
        </body>
        <body name="button_head_lock">
          <joint axis="-1.0 0.0 0.0" pos="0.09190913289785385 0.10892479121685028 0.017827346920967102" limited="true" name="button_head_lock_joint" range="0.0 0.0015" type="slide" damping="1" frictionloss="1" armature=".01" stiffness="0.05"/>
          <geom mesh="button_head_lock_vis" type="mesh" solimp="0.998 0.998 0.001" solref="0.001 1" friction="0.95 0.3 0.1" class="visual" material="button_head_lock_material"/>
          <geom class="collision" type="box" pos="0.09451240301132202 0.10884135216474533 0.017717504873871803" size="0.0010479416232556105 0.01577267050743103 0.00806450191885233" quat="1.0 0.0 0.0 0.0" name="button_head_lock_main"/>
        </body>
        <body name="head">
          <joint axis="-1.0 0.0 0.0" pos="0.003621272509917617 0.18859846889972687 0.12621155381202698" limited="true" name="head_joint" range="0.0 1.5707963267948966" type="hinge" damping="1" frictionloss="1" armature=".01" stiffness="0.05"/>
          <geom mesh="head_vis" type="mesh" solimp="0.998 0.998 0.001" solref="0.001 1" friction="0.95 0.3 0.1" class="visual" material="head_material"/>
          <geom type="box" pos="-0.001328813610598445 0.026462554931640625 0.14599385857582092" size="0.09517229348421097 0.1636313945055008 0.022937024012207985" quat="1.0 0.0 0.0 0.0" class="collision"/>
          <geom type="box" pos="4.78647998534143e-05 -0.06080763041973114 0.18801355361938477" size="0.07387419044971466 0.013172413222491741 0.019035594537854195" quat="1.0 0.0 0.0 0.0" class="collision"/>
          <geom type="box" pos="4.78647998534143e-05 0.050475552678108215 0.2016994208097458" size="0.07387419044971466 0.1224902793765068 0.032721444964408875" quat="1.0 0.0 0.0 0.0" class="collision"/>
          <geom type="box" pos="4.78647998534143e-05 -0.06735362112522125 0.18801355361938477" size="0.07387419044971466 0.006761389318853617 0.019035594537854195" quat="1.0 0.0 0.0 0.0" class="collision"/>
          <geom type="box" pos="4.78647998534143e-05 -0.07674458622932434 0.17815126478672028" size="0.07387419044971466 0.006002186797559261 0.009173284284770489" quat="1.0 0.0 0.0 0.0" class="collision"/>
          <geom type="box" pos="4.78647998534143e-05 -0.066293865442276 0.18358752131462097" size="0.07387419044971466 0.010829201899468899 0.014609532430768013" quat="1.0 0.0 0.0 0.0" class="collision"/>
          <geom type="box" pos="0.09245838224887848 -0.01736270636320114 0.04113068804144859" size="0.0027169263921678066 0.03912002220749855 0.0037242791149765253" quat="1.0 0.0 0.0 0.0" class="collision"/>
          <geom type="box" pos="-0.001328813610598445 0.023036610335111618 0.08092157542705536" size="0.09517229348421097 0.002696755575016141 0.043424759060144424" quat="1.0 0.0 0.0 0.0" class="collision"/>
          <geom type="box" pos="-0.09378419071435928 -0.01736270636320114 0.04113068804144859" size="0.0027169263921678066 0.03912002220749855 0.0037242791149765253" quat="1.0 0.0 0.0 0.0" class="collision"/>
          <geom type="box" pos="-0.07319995760917664 -0.029625937342643738 0.04113068804144859" size="0.0027169263921678066 0.020795566961169243 0.0037242791149765253" quat="0.9227108955383301 0.0 0.0 -0.3854927122592926" class="collision"/>
          <geom type="box" pos="-0.04002855718135834 -0.007736615836620331 0.04113068804144859" size="0.002716926857829094 0.02079557068645954 0.0037242791149765253" quat="0.837822437286377 0.0 0.0 -0.5459427833557129" class="collision"/>
          <geom type="box" pos="-0.0006694255862385035 0.0018757320940494537 0.04113068804144859" size="0.002716926857829094 0.020795568823814392 0.0037242791149765253" quat="0.7352935671806335 0.0 0.0 -0.6777487397193909" class="collision"/>
          <geom type="box" pos="0.04049614444375038 -0.003307454288005829 0.04113068804144859" size="0.0027169263921678066 0.020795565098524094 0.0037242791149765253" quat="0.5781680941581726 0.0 0.0 -0.8159176707267761" class="collision"/>
          <geom type="box" pos="0.0754881277680397 -0.023771516978740692 0.04113068804144859" size="0.0027169263921678066 0.020795566961169243 0.0037242791149765253" quat="0.42034149169921875 0.0 0.0 -0.9073659777641296" class="collision"/>
          <geom type="box" pos="-0.002869380870833993 -0.17646372318267822 0.07941456139087677" size="0.03435741737484932 0.002696757670491934 0.05819800868630409" quat="0.9129106998443604 -0.40815937519073486 9.062957397578455e-17 9.815488587912014e-24" class="collision"/>
          <geom type="box" pos="-0.0573975145816803 -0.15529786050319672 0.08139331638813019" size="0.03435741737484932 0.0026967579033225775 0.054849106818437576" quat="0.8775176405906677 -0.345663458108902 0.12181935459375381 -0.3092564642429352" class="collision"/>
          <geom type="box" pos="-0.07870510220527649 -0.08780740201473236 0.08140534162521362" size="0.03435741737484932 0.002696757670491934 0.05192197486758232" quat="0.6705660820007324 -0.22436828911304474 0.22436831891536713 -0.6705660820007324" class="collision"/>
          <geom type="box" pos="-0.07558850944042206 -0.11878924071788788 0.08101095259189606" size="0.03435742110013962 0.002696758136153221 0.052268557250499725" quat="0.5672957897186279 0.2008899748325348 0.2665899991989136 0.752826988697052" class="collision"/>
          <geom type="box" pos="-0.02643406391143799 -0.17646372318267822 0.07941456139087677" size="0.034357424825429916 0.00269675743766129 0.05819801241159439" quat="0.9145876169204712 -0.3882196545600891 0.04423206299543381 -0.10420415550470352" class="collision"/>
          <geom type="box" pos="0.035575054585933685 -0.17646372318267822 0.07941456139087677" size="0.03435741737484932 0.00269675743766129 0.05819800868630409" quat="0.38821929693222046 0.9145877957344055 0.1042041927576065 0.04423203319311142" class="collision"/>
          <geom type="box" pos="0.085704505443573 -0.11906881630420685 0.07975839078426361" size="0.034357406198978424 0.002696758368983865 0.05388029292225838" quat="0.20089006423950195 -0.5672956705093384 0.752826988697052 -0.2665901482105255" class="collision"/>
          <geom type="box" pos="0.0885564312338829 -0.08780740201473236 0.08046267926692963" size="0.03435741737484932 0.0026967579033225775 0.05310233309864998" quat="0.22436833381652832 0.6705661416053772 0.6705660223960876 0.22436827421188354" class="collision"/>
          <geom type="box" pos="0.06728053838014603 -0.15621985495090485 0.0801241397857666" size="0.03435741737484932 0.002696757670491934 0.05658446252346039" quat="0.3456633985042572 0.8775177001953125 0.30925649404525757 0.12181936204433441" class="collision"/>
          <geom type="box" pos="0.01201037596911192 -0.17646372318267822 0.07941456139087677" size="0.03435741737484932 0.00269675743766129 0.058198004961013794" quat="0.40815937519073486 0.9129106998443604 -8.554915682639614e-24 9.062957397578455e-17" class="collision"/>
          <body name="blender">
            <joint axis="0.0 0.0 1.0" pos="0.002795243402943015 -0.11111302673816681 0.034960873425006866" limited="false" name="blender_joint" range="0 360" type="hinge" damping="1" frictionloss="1" armature=".01" stiffness="0.05"/>
            <geom mesh="blender_vis" type="mesh" solimp="0.998 0.998 0.001" solref="0.001 1" friction="0.95 0.3 0.1" class="visual" material="blender_material"/>
            <geom type="cylinder" pos="0.0027952438686043024 -0.11111300438642502 0.08938224613666534" size="0.005836151540279388 0.026723826304078102" quat="1.0 0.0 0.0 0.0" class="collision"/>
            <geom type="cylinder" pos="0.0027952438686043024 -0.11111301183700562 0.05263470858335495" size="0.04610991105437279 0.007561697158962488" quat="1.0 0.0 0.0 0.0" class="collision"/>
            <geom type="cylinder" pos="0.0027952438686043024 -0.11111301183700562 0.056176893413066864" size="0.013604322448372841 0.006940186023712158" quat="1.0 0.0 0.0 0.0" class="collision"/>
            <geom type="cylinder" pos="0.0027952438686043024 -0.11111301183700562 -0.008721573278307915" size="0.0449167937040329 0.009293390437960625" quat="1.0 0.0 0.0 0.0" class="collision"/>
            <geom type="cylinder" pos="0.0027952438686043024 -0.11111301183700562 0.022189287468791008" size="0.05491243302822113 0.02572678215801716" quat="1.0 0.0 0.0 0.0" class="collision"/>
            <geom type="cylinder" pos="0.0027952436357736588 -0.11111301183700562 -0.025776680558919907" size="0.04001713916659355 0.008279640227556229" quat="1.0 0.0 0.0 0.0" class="collision"/>
            <geom type="cylinder" pos="0.002795243402943015 -0.11111301183700562 -0.03797990083694458" size="0.02850527875125408 0.005897809285670519" quat="1.0 0.0 0.0 0.0" class="collision"/>
            <geom type="cylinder" pos="0.002795243402943015 -0.11111301183700562 -0.04878636822104454" size="0.01759735494852066 0.005184714682400227" quat="1.0 0.0 0.0 0.0" class="collision"/>
          </body>
        </body>
        <body name="knob_speed">
          <joint axis="-1.0 0.0 0.0" pos="0.10591834783554077 0.10892479121685028 -0.060967087745666504" limited="true" name="knob_speed_joint" range="0.0 4.974188368183839" type="hinge" damping="0.05" armature="0.001"/>
          <geom mesh="knob_speed_vis" type="mesh" solimp="0.998 0.998 0.001" solref="0.001 1" friction="0.95 0.3 0.1" class="visual" material="knob_speed_material"/>
          <geom type="cylinder" pos="0.09889586269855499 0.1084667518734932 -0.06107860431075096" size="0.024719323962926865 0.005838913843035698" quat="0.7071068286895752 -0.0 0.7071067690849304 0.0" class="collision"/>
          <geom class="collision" type="box" pos="0.11128564924001694 0.10930505394935608 -0.0606585294008255" size="0.007459341082721949 0.007930416613817215 0.022051239386200905" quat="0.8656713962554932 0.5006126761436462 1.1115833065988877e-16 6.5158573652021226e-24" name="knob_speed_main"/>
        </body>
        <geom class="region" name="reg_main" type="box" pos="2.806384902243053e-09 0.0 0.0" size="0.13000981307029724 0.23113272881507874 0.2312367091178894"/>
      </body>
    </body>
  </worldbody>
  <actuator>
    <!-- <motor name="bowl_joint_actuator" joint="bowl_joint" gear="10"/> -->
    <motor name="button_head_lock_joint_actuator" joint="button_head_lock_joint" gear="0.1"/>
    <motor name="head_joint_actuator" joint="head_joint" gear="10"/>
    <motor name="knob_speed_joint_actuator" joint="knob_speed_joint" gear="10"/>
    <motor name="blender_joint_actuator" joint="blender_joint" gear="10"/>
  </actuator>
</mujoco>
