<?xml version='1.0' encoding='UTF-8'?>
<mujoco model="model">
  <option timestep="0.002" gravity="0.0 0.0 -9.81"/>
  <compiler angle="radian"/>
  <asset>
    <mesh file="visuals/door.obj" name="door_vis"/>
    <mesh file="visuals/door_Clear.obj" name="door_Clear_vis"/>
    <mesh file="visuals/Body001.obj" name="Body001_vis"/>
    <mesh file="visuals/Disc001.obj" name="Disc001_vis"/>
    <texture file="visuals/T_BC001.png" name="Body001_material" type="2d"/>
    <material name="Body001_material" rgba="1 1 1 1.0" texture="Body001_material" shininess="0.4" specular="6"/>
    <texture file="visuals/T_BC001.png" name="door_material" type="2d"/>
    <material name="door_material" rgba="1 1 1 1.0" texture="door_material" shininess="0.5" specular="11"/>
    <material name="door_Clear_material" rgba="0.20077744126319885 0.20077744126319885 0.20077744126319885 0.800000011920929" shininess="0.5" specular="0.3103448502657381"/>
    <texture file="visuals/T_BC001.png" name="Disc001_material" type="2d"/>
    <material name="Disc001_material" rgba="1 1 1 1.0" texture="Disc001_material" shininess="0.05" specular="0.657381"/>
  </asset>
  <default>
    <default class="visual">
      <geom conaffinity="0" contype="0" group="1" type="mesh"/>
    </default>
    <default class="collision">
      <geom group="0" rgba="0.5 0 0 0.5"/>
    </default>
    <default class="spawn">
      <geom group="0" rgba="1 1 1 0.5" contype="0" conaffinity="0"/>
      <site group="0" rgba="1 1 1 0.5"/>
    </default>
    <default class="region">
      <geom group="1" conaffinity="0" contype="0" rgba="0 1 0 0"/>
    </default>
  </default>
  <worldbody>
    <body>
      <body name="object">
        <geom class="collision" type="cylinder" pos="-0.04455467 0.00746983 -0.12630755" size="0.17360438406467438 0.0012126457877457142" quat="1.0 0.0 0.0 0.0" name="tray" rgba="0 1 0 0.5"/>
        <geom class="collision" type="box" pos="0.21900322 -0.20385806 -0.09367545" size="0.011469731107354164 0.0006778106326237321 0.00612998753786087" quat="1.0 0.0 0.0 0.0" name="start_button" rgba="0.0 0.5 0 0.5"/>
        <geom class="collision" type="box" pos="0.19209343 -0.20391321 -0.09366934" size="0.011334268376231194 0.0006778127863071859 0.006057601887732744" quat="1.0 0.0 0.0 0.0" name="stop_button" rgba="0.0 0.5 0 0.5"/>
        <geom mesh="Body001_vis" type="mesh" solimp="0.998 0.998 0.001" solref="0.001 1" friction="0.95 0.3 0.1" class="visual" material="Body001_material"/>
        <geom class="collision" type="box" pos="0.00000002 0.02582202 0.16092953" size="0.2749999165534973 0.20708754658699036 0.007470408920198679" quat="1.0 0.0 0.0 0.0"/>
        <geom class="collision" type="box" pos="-0.26279849 0.02358145 -0.00283944" size="0.012201599776744843 0.20482203364372253 0.16503989696502686" quat="1.0 0.0 0.0 0.0"/>
        <geom class="collision" type="box" pos="-0.04900579 0.21668215 -0.00746386" size="0.22599411010742188 0.016229622066020966 0.16092294454574585" quat="1.0 0.0 0.0 0.0"/>
        <geom class="collision" type="box" pos="0.21677347 0.01607733 -0.00080173" size="0.05822645500302315 0.2168346345424652 0.1670721173286438" quat="1.0 0.0 0.0 0.0"/>
        <geom class="collision" type="box" pos="0.00000085 0.02358145 -0.15418187" size="0.2749978005886078 0.20549042522907257 0.01420481875538826" quat="1.0 0.0 0.0 0.0"/>
        <body name="door">
          <joint axis="0.0 0.0 1.0" pos="-0.26788872 -0.19784257 -0.00367214" limited="true" name="microjoint" range="-1.5707963267948966 0.0" type="hinge" damping="1" frictionloss="1" armature=".01" stiffness="0.05"/>
          <geom mesh="door_vis" type="mesh" solimp="0.998 0.998 0.001" solref="0.001 1" friction="0.95 0.3 0.1" class="visual" material="door_material"/>
          <geom class="collision" type="box" pos="-0.05909067 -0.19089340 -0.01438447" size="0.16923785209655762 0.00038382320781238377 0.0934218317270279" quat="1.0 0.0 0.0 0.0"/>
          <geom class="collision" type="box" pos="0.14097391 -0.21141426 -0.10636541" size="0.006189691834151745 0.00963758397847414 0.009602737613022327" quat="1.0 0.0 0.0 0.0"/>
          <geom class="collision" type="box" pos="0.14097391 -0.21141426 0.09305353" size="0.006189699750393629 0.009637625887989998 0.00846958253532648" quat="1.0 0.0 0.0 0.0"/>
          <geom class="collision" type="box" pos="0.14097391 -0.22706163 -0.08056697" size="0.009110740385949612 0.005179787054657936 0.01571737416088581" quat="1.0 0.0 0.0 0.0"/>
          <geom class="collision" type="box" pos="0.14097390 -0.22483857 -0.10123515" size="0.009110698476433754 0.005459960550069809 0.01576252654194832" quat="1.0 0.0 0.0 0.0"/>
          <geom class="collision" type="box" pos="0.14097390 -0.22471839 0.08667571" size="0.009110698476433754 0.0053551821038126945 0.0157462190836668" quat="1.0 0.0 0.0 0.0"/>
          <geom class="collision" type="box" pos="0.14097390 -0.22848554 0.00421343" size="0.00911069568246603 0.004860551096498966 0.0707850381731987" quat="1.0 0.0 0.0 0.0" name="door_handle_main"/>
          <geom class="collision" type="box" pos="-0.05072383 -0.19685031 0.00003493" size="0.20758512616157532 0.006730121094733477 0.16617514193058014" quat="1.0 0.0 0.0 0.0" name="door_main"/>
          <body name="door_Clear">
            <geom mesh="door_Clear_vis" type="mesh" solimp="0.998 0.998 0.001" solref="0.001 1" friction="0.95 0.3 0.1" class="visual" material="door_Clear_material"/>
            <geom class="collision" type="box" pos="-0.05909067 -0.19089340 -0.01438447" size="0.16923785209655762 0.00038382320781238377 0.0934218317270279" quat="1.0 0.0 0.0 0.0"/>
          </body>
        </body>
        <body name="Disc001">
          <joint axis="0.0 0.0 1.0" pos="-0.04455467 0.00746983 -0.13419536" limited="false" name="Disc001_joint" range="0 360" type="hinge" damping="1" frictionloss="1" armature=".01" stiffness="0.05"/>
          <geom mesh="Disc001_vis" type="mesh" solimp="0.998 0.998 0.001" solref="0.001 1" friction="0.95 0.3 0.1" class="visual" material="Disc001_material"/>
          <geom class="collision" type="cylinder" pos="-0.04455467 0.00746983 -0.13372723" size="0.17360438406467438 0.003919103182852268" quat="1.0 0.0 0.0 0.0"/>
        </body>
        <geom class="region" name="reg_int" type="box" pos="-0.04600364 0.0064275849999999995 0.011398745000000002" size="0.20028162 0.189856395 0.137493545"/>
        <geom class="region" name="reg_main" type="box" pos="2.9999999984209325e-08 0.014341470000000009 6.615000000001481e-06" size="0.27599992 0.21957052999999999 0.169393375"/>
      </body>
    </body>
  </worldbody>
  <actuator>
    <motor name="microjoint_actuator" joint="microjoint" gear="10"/>
    <motor name="Disc001_joint_actuator" joint="Disc001_joint" gear="10"/>
  </actuator>
</mujoco>
