<?xml version='1.0' encoding='UTF-8'?>
<mujoco model="model">
  <option timestep="0.002" gravity="0.0 0.0 -9.81"/>
  <compiler angle="radian"/>
  <asset>
    <mesh file="visuals/sideL_button_cancel.obj" name="sideL_button_cancel_vis"/>
    <mesh file="visuals/sideL_knob_doneness.obj" name="sideL_knob_doneness_vis"/>
    <mesh file="visuals/sideL_lever.obj" name="sideL_lever_vis"/>
    <mesh file="visuals/sideR_button_cancel.obj" name="sideR_button_cancel_vis"/>
    <mesh file="visuals/sideR_knob_doneness.obj" name="sideR_knob_doneness_vis"/>
    <mesh file="visuals/sideR_lever.obj" name="sideR_lever_vis"/>
    <mesh file="visuals/Body001.obj" name="Body001_vis"/>
    <mesh file="visuals/Body002.obj" name="Body002_vis"/>
    <texture file="visuals/T_BC001.png" name="Body001_material" type="2d"/>
    <material name="Body001_material" rgba="1 1 1 1.0" texture="Body001_material" shininess="0.5" specular="0.8"/>
    <texture file="visuals/T_BC001.png" name="sideL_button_cancel_material" type="2d"/>
    <material name="sideL_button_cancel_material" rgba="1 1 1 1.0" texture="sideL_button_cancel_material" shininess="0.5" specular="0.3103448502657381"/>
    <texture file="visuals/T_BC001.png" name="sideL_knob_doneness_material" type="2d"/>
    <material name="sideL_knob_doneness_material" rgba="1 1 1 1.0" texture="sideL_knob_doneness_material" shininess="0.5" specular="0.3103448502657381"/>
    <texture file="visuals/T_BC001.png" name="sideL_lever_material" type="2d"/>
    <material name="sideL_lever_material" rgba="1 1 1 1.0" texture="sideL_lever_material" shininess="0.5" specular="0.3103448502657381"/>
    <texture file="visuals/T_BC001.png" name="sideR_button_cancel_material" type="2d"/>
    <material name="sideR_button_cancel_material" rgba="1 1 1 1.0" texture="sideR_button_cancel_material" shininess="0.5" specular="0.3103448502657381"/>
    <texture file="visuals/T_BC001.png" name="sideR_knob_doneness_material" type="2d"/>
    <material name="sideR_knob_doneness_material" rgba="1 1 1 1.0" texture="sideR_knob_doneness_material" shininess="0.5" specular="0.3103448502657381"/>
    <texture file="visuals/T_BC001.png" name="sideR_lever_material" type="2d"/>
    <material name="sideR_lever_material" rgba="1 1 1 1.0" texture="sideR_lever_material" shininess="0.5" specular="0.3103448502657381"/>
    <texture file="visuals/T_BC001.png" name="Body002_material" type="2d"/>
    <material name="Body002_material" rgba="1 1 1 1.0" texture="Body002_material" shininess="0.5" specular="3"/>
  </asset>
  <default>
    <default class="visual">
      <geom conaffinity="0" contype="0" group="1" type="mesh"/>
    </default>
    <default class="collision_1">
      <geom group="0" rgba="0.5 0 0 0.5" solref="0.004 1" solimp="0.998 0.998 0.001"/>
    </default>
    <default class="collision_2">
      <geom group="0" rgba="0.5 0 0 0.5" solref="0.004 1" solimp="0.998 0.998 0.001"/>
    </default>
    <default class="collision_3">
      <geom group="0" rgba="0.5 0 0 0.5" solref="0.004 1" solimp="0.998 0.998 0.001"/>
    </default>
    <default class="collision_4">
      <geom group="0" rgba="0.5 0 0 0.5" solref="0.004 1" solimp="0.998 0.998 0.001"/>
    </default>
    <default class="collision_5">
      <geom group="0" rgba="0.5 0 0 0.5" solref="0.004 1" solimp="0.998 0.998 0.001"/>
    </default>
    <default class="collision_6">
      <geom group="0" rgba="0.5 0 0 0.5" solref="0.004 1" solimp="0.998 0.998 0.001"/>
    </default>
    <default class="collision_7">
      <geom group="0" rgba="0.5 0 0 0.5" solref="0.004 1" solimp="0.998 0.998 0.001"/>
    </default>
    <default class="collision_8">
      <geom group="0" rgba="0.5 0 0 0.5" solref="0.004 1" solimp="0.998 0.998 0.001"/>
    </default>
    <default class="spawn">
      <geom group="0" rgba="1 1 1 0.5" contype="0" conaffinity="0"/>
      <site group="0" rgba="1 1 1 0.5"/>
    </default>
    <default class="region">
      <geom group="1" conaffinity="0" contype="0" rgba="0 1 0 0" mass="0"/>
    </default>
  </default>
  <worldbody>
    <body>
      <body name="object">
        <geom mesh="Body001_vis" type="mesh" solimp="0.998 0.998 0.001" solref="0.001 1" friction="0.95 0.3 0.1" class="visual" material="Body001_material"/>
        <geom type="box" pos="-0.15742726624011993 0.012915825471282005 0.002451108768582344" size="0.028422826901078224 0.15073636174201965 0.10915911197662354" quat="1.0 0.0 0.0 0.0" class="collision_1"/>
        <geom type="box" pos="0.15744970738887787 0.012915825471282005 0.002451108768582344" size="0.025575680658221245 0.15073636174201965 0.10915911197662354" quat="1.0 0.0 0.0 0.0" class="collision_1"/>
        <geom type="box" pos="0.0019800602458417416 0.12985439598560333 0.002451108768582344" size="0.12950655817985535 0.03379778936505318 0.10915911197662354" quat="1.0 0.0 0.0 0.0" class="collision_1"/>
        <geom type="box" pos="-0.0792175829410553 0.011945940554141998 0.011153440922498703" size="0.022919220849871635 0.0839310958981514 0.10045678168535233" quat="1.0 0.0 0.0 0.0" class="collision_1"/>
        <geom type="box" pos="2.308376133441925e-05 0.011945940554141998 0.011153440922498703" size="0.02770495042204857 0.0839310958981514 0.10045678168535233" quat="1.0 0.0 0.0 0.0" class="collision_1"/>
        <geom type="box" pos="0.08044862747192383 0.011945940554141998 0.011153440922498703" size="0.02377796173095703 0.0839310958981514 0.10045678168535233" quat="1.0 0.0 0.0 0.0" class="collision_1"/>
        <geom type="box" pos="0.002134939655661583 -0.02025175467133522 -0.09706620126962662" size="0.13013973832130432 0.11612878739833832 0.009750613942742348" quat="1.0 0.0 0.0 0.0" class="collision_1"/>
        <geom type="box" pos="0.002134939655661583 -0.10463718324899673 -0.07667811959981918" size="0.13013973832130432 0.03244194760918617 0.010927493683993816" quat="1.0 0.0 0.0 0.0" class="collision_1"/>
        <geom type="box" pos="0.0015447498299181461 -0.10459443926811218 0.08488725125789642" size="0.1295495480298996 0.03248468041419983 0.025019899010658264" quat="1.0 0.0 0.0 0.0" class="collision_1"/>
        <geom type="box" pos="0.000752061780076474 -0.10406503081321716 0.0019107051193714142" size="0.07500772178173065 0.03195526450872421 0.05791382119059563" quat="1.0 0.0 0.0 0.0" class="collision_1"/>
        <geom type="box" pos="0.107742078602314 -0.10459443926811218 0.003130665048956871" size="0.023630762472748756 0.03248468041419983 0.05669386312365532" quat="1.0 0.0 0.0 0.0" class="collision_1"/>
        <geom type="box" pos="-0.10584954917430878 -0.10382004082202911 0.0019107051193714142" size="0.022509802132844925 0.03216703236103058 0.05791382119059563" quat="1.0 0.0 0.0 0.0" class="collision_1"/>
        <geom type="box" pos="-0.010623300448060036 -0.10435780137777328 -0.06052663177251816" size="0.04294619336724281 0.03224804624915123 0.004553386475890875" quat="1.0 0.0 0.0 0.0" class="collision_1"/>
        <geom type="box" pos="0.11870092898607254 -0.10459443926811218 -0.06011997535824776" size="0.013107260689139366 0.03248468041419983 0.006688314955681562" quat="1.0 0.0 0.0 0.0" class="collision_1"/>
        <geom type="box" pos="-0.07698499411344528 -0.10413768887519836 -0.046199340373277664" size="0.015368800610303879 0.03248468041419983 0.007363850716501474" quat="1.0 0.0 0.0 0.0" class="collision_1"/>
        <geom type="box" pos="0.08126544207334518 -0.10413768887519836 -0.046199340373277664" size="0.015312239527702332 0.03248468041419983 0.007363850716501474" quat="1.0 0.0 0.0 0.0" class="collision_1"/>
        <geom type="box" pos="0.08111836761236191 -0.10413768887519836 0.05556058883666992" size="0.015459313988685608 0.03248468041419983 0.004495400004088879" quat="1.0 0.0 0.0 0.0" class="collision_1"/>
        <geom type="box" pos="-0.07711538672447205 -0.10413768887519836 0.05556058883666992" size="0.015897255390882492 0.03248468041419983 0.004495400004088879" quat="1.0 0.0 0.0 0.0" class="collision_1"/>
        <geom type="cylinder" pos="-0.16226035356521606 -0.09640666097402573 -0.10892433673143387" size="0.004896887578070164 0.002551341662183404" quat="1.0 0.0 0.0 0.0" class="collision_1"/>
        <geom type="cylinder" pos="0.16216564178466797 -0.09640666097402573 -0.10892433673143387" size="0.004896887578070164 0.002551341662183404" quat="1.0 0.0 0.0 0.0" class="collision_1"/>
        <geom type="cylinder" pos="0.16216564178466797 0.1349889636039734 -0.10892433673143387" size="0.004896887578070164 0.002551341662183404" quat="1.0 0.0 0.0 0.0" class="collision_1"/>
        <geom type="cylinder" pos="-0.16226035356521606 0.1349889636039734 -0.10892433673143387" size="0.004896887578070164 0.002551341662183404" quat="1.0 0.0 0.0 0.0" class="collision_1"/>
        <body name="sideL_button_cancel">
          <joint axis="0.0 1.0 0.0" pos="-0.11641499400138855 -0.13784638047218323 -0.03743427246809006" limited="true" name="sideL_button_cancel_joint" range="0.0 0.001" type="slide" damping="1" frictionloss="1" armature=".01" stiffness="4" springref="-1"/>
          <geom mesh="sideL_button_cancel_vis" type="mesh" solimp="0.998 0.998 0.001" solref="0.001 1" friction="0.95 0.3 0.1" class="visual" material="sideL_button_cancel_material"/>
          <geom class="collision_2" type="box" pos="-0.11637920141220093 -0.13805429637432098 -0.03751402348279953" size="0.012049396522343159 0.0014285552315413952 0.004999059252440929" quat="1.0 0.0 0.0 0.0" name="sideL_button_cancel_main"/>
        </body>
        <body name="sideL_knob_doneness">
          <joint axis="1.0 0.0 0.0" pos="-0.11414897441864014 -0.12978218495845795 -0.05992436408996582" limited="true" name="sideL_knob_doneness_joint" range="0.0 0.05" type="slide" damping="0.05" armature="1" frictionloss="0.75"/>
          <geom mesh="sideL_knob_doneness_vis" type="mesh" solimp="0.998 0.998 0.001" solref="0.001 1" friction="0.95 0.3 0.1" class="visual" material="sideL_knob_doneness_material"/>
          <geom class="collision_3" type="box" pos="-0.11415667831897736 -0.13981583714485168 -0.05994628369808197" size="0.009560592472553253 0.002833350794389844 0.005086520686745644" quat="1.0 0.0 0.0 0.0" name="sideL_knob_doneness_main" friction="100 0.5 0.01"/>
          <geom type="cylinder" pos="-0.11352100968360901 -0.12739166617393494 -0.0600186251103878" size="0.0018894533859565854 0.009607632644474506" quat="0.7071067094802856 0.7071068286895752 0.0 0.0" class="collision_3" friction="100 0.5 0.01"/>
        </body>
        <body name="sideL_lever">
          <joint axis="0.0 0.0 -1.0" pos="-0.07934772968292236 -0.13922840356826782 0.036322835832834244" limited="true" name="sideL_lever_joint" range="0.0 0.045" type="slide" damping="1" frictionloss="1" armature=".1" stiffness="2" springref="-0.5"/>
          <geom class="region" name="reg_sideL_slotL" type="box" pos="-0.11568981409072876 0.013133928179740906 0.1108818631619215" size="0.010754985570907594 0.07866659557819367 0.07600007934868336"/>
          <geom class="region" name="reg_sideL_slotR" type="box" pos="-0.041929950937628746 0.013133928179740906 0.1108818631619215" size="0.010527752175927163 0.07866659557819367 0.07600007934868336"/>
          <geom mesh="sideL_lever_vis" type="mesh" solimp="0.998 0.998 0.001" solref="0.001 1" friction="0.95 0.3 0.1" class="visual" material="sideL_lever_material"/>
          <geom class="collision_4" type="box" pos="-0.07930850237607956 -0.15010011196136475 0.03633635863661766" size="0.016504444181919098 0.012149329297244549 0.004880914930254221" quat="1.0 0.0 0.0 0.0" name="sideL_lever_handle"/>
          <geom type="cylinder" pos="-0.07924050837755203 -0.12753355503082275 0.03628745675086975" size="0.002466813661158085 0.01055104285478592" quat="0.7071067094802856 0.7071068286895752 0.0 0.0" class="collision_4"/>
          <geom class="collision_4" type="box" pos="-0.11549612134695053 0.012951436452567577 0.03092200495302677" size="0.01249999925494194 0.08173847943544388 0.00047661259304732084" quat="1.0 0.0 0.0 0.0" name="sideL_slotL_floor"/>
          <geom class="collision_4" type="box" pos="-0.041988011449575424 0.012951436452567577 0.03092200495302677" size="0.01249999925494194 0.08173847943544388 0.00047661259304732084" quat="1.0 0.0 0.0 0.0" name="sideL_slotR_floor"/>
        </body>
        <body name="sideR_button_cancel">
          <joint axis="0.0 1.0 0.0" pos="0.04230264574289322 -0.13784638047218323 -0.03743429481983185" limited="true" name="sideR_button_cancel_joint" range="0.0 0.001" type="slide" damping="1" frictionloss="1" armature=".01" stiffness="4" springref="-1"/>
          <geom mesh="sideR_button_cancel_vis" type="mesh" solimp="0.998 0.998 0.001" solref="0.001 1" friction="0.95 0.3 0.1" class="visual" material="sideR_button_cancel_material"/>
          <geom class="collision_5" type="box" pos="0.04235977679491043 -0.13805429637432098 -0.03751402348279953" size="0.012049396522343159 0.0014285552315413952 0.004999059252440929" quat="1.0 0.0 0.0 0.0" name="sideR_button_cancel_main"/>
        </body>
        <body name="sideR_knob_doneness">
          <joint axis="1.0 0.0 0.0" pos="0.044298525899648666 -0.12978234887123108 -0.05992436408996582" limited="true" name="sideR_knob_doneness_joint" range="0.0 0.05" type="slide" damping="0.05" armature="1" frictionloss="0.75"/>
          <geom mesh="sideR_knob_doneness_vis" type="mesh" solimp="0.998 0.998 0.001" solref="0.001 1" friction="0.95 0.3 0.1" class="visual" material="sideR_knob_doneness_material"/>
          <geom class="collision_6" type="box" pos="0.044316455721855164 -0.13981583714485168 -0.05994628369808197" size="0.009560592472553253 0.002833350794389844 0.005086520686745644" quat="1.0 0.0 0.0 0.0" name="sideR_knob_doneness_main" friction="100 0.5 0.01"/>
          <geom type="cylinder" pos="0.044370438903570175 -0.12739166617393494 -0.0600186251103878" size="0.0018894533859565854 0.009607632644474506" quat="0.7071067094802856 0.7071068286895752 0.0 0.0" class="collision_6" friction="100 0.5 0.01"/>
        </body>
        <body name="sideR_lever">
          <joint axis="0.0 0.0 -1.0" pos="0.0801430493593216 -0.13923010230064392 0.03632010519504547" limited="true" name="sideR_lever_joint" range="0.0 0.045" type="slide" damping="1" frictionloss="1" armature=".1" stiffness="2" springref="-0.5"/>
          <geom class="region" name="reg_sideR_slotL" type="box" pos="0.04349844716489315 0.013133928179740906 0.1108818631619215" size="0.010703563526272775 0.07866659557819367 0.07600007934868336"/>
          <geom class="region" name="reg_sideR_slotR" type="box" pos="0.11673378199338913 0.013133928179740906 0.1108818631619215" size="0.010628109633922578 0.07866659557819367 0.07600007934868336"/>
          <geom mesh="sideR_lever_vis" type="mesh" solimp="0.998 0.998 0.001" solref="0.001 1" friction="0.95 0.3 0.1" class="visual" material="sideR_lever_material"/>
          <geom class="collision_7" type="box" pos="0.08009845018386841 -0.15010011196136475 0.03633635863661766" size="0.016504444181919098 0.012149329297244549 0.004880914930254221" quat="1.0 0.0 0.0 0.0" name="sideR_lever_handle"/>
          <geom type="cylinder" pos="0.08016644418239594 -0.12753355503082275 0.03628745675086975" size="0.002466813661158085 0.01055104285478592" quat="0.7071067094802856 0.7071068286895752 0.0 0.0" class="collision_7"/>
          <geom class="collision_7" type="box" pos="0.0427587665617466 0.012951436452567577 0.03092200495302677" size="0.01249999925494194 0.08173847943544388 0.00047661259304732084" quat="1.0 0.0 0.0 0.0" name="sideR_slotL_floor"/>
          <geom class="collision_7" type="box" pos="0.11821363121271133 0.012951436452567577 0.03092200495302677" size="0.01249999925494194 0.08173847943544388 0.00047661259304732084" quat="1.0 0.0 0.0 0.0" name="sideR_slotR_floor"/>
        </body>
        <body name="Body002">
          <geom mesh="Body002_vis" type="mesh" solimp="0.998 0.998 0.001" solref="0.001 1" friction="0.95 0.3 0.1" class="visual" material="Body002_material"/>
        </body>
        <geom class="region" name="reg_main" type="box" pos="3.725290298461914e-09 0.012827321887016296 0.0" size="0.1839766482114792 0.15034466779232025 0.11241440272331238"/>
      </body>
    </body>
  </worldbody>
  <actuator>
    <motor name="sideL_button_cancel_joint_actuator" joint="sideL_button_cancel_joint" gear="0.5"/>
    <motor name="sideL_knob_doneness_joint_actuator" joint="sideL_knob_doneness_joint" gear="1"/>
    <motor name="sideL_lever_joint_actuator" joint="sideL_lever_joint" gear="2"/>
    <motor name="sideR_button_cancel_joint_actuator" joint="sideR_button_cancel_joint" gear="0.5"/>
    <motor name="sideR_knob_doneness_joint_actuator" joint="sideR_knob_doneness_joint" gear="1"/>
    <motor name="sideR_lever_joint_actuator" joint="sideR_lever_joint" gear="2"/>
  </actuator>
</mujoco>