<?xml version='1.0' encoding='UTF-8'?>
<mujoco model="model">
  <option timestep="0.002" gravity="0.0 0.0 -9.81"/>
  <compiler angle="radian"/>
  <asset>
    <mesh file="visuals/freezer0.obj" name="freezer0_vis"/>
    <mesh file="visuals/fridge_door.obj" name="fridge_door_vis"/>
    <mesh file="visuals/fridge_door_Clear.obj" name="fridge_door_Clear_vis"/>
    <mesh file="visuals/fridge_drawer0.obj" name="fridge_drawer0_vis"/>
    <mesh file="visuals/Body001.obj" name="Body001_vis"/>
    <mesh file="visuals/Body001_Clear.obj" name="Body001_Clear_vis"/>
    <texture file="visuals/T_BC001.png" name="Body001_material" type="2d"/>
    <material name="Body001_material" rgba="1 1 1 1.0" texture="Body001_material" shininess="0.4472135901451111" specular="2"/>
    <texture file="visuals/T_BC001.png" name="freezer0_material" type="2d"/>
    <material name="freezer0_material" rgba="1 1 1 1.0" texture="freezer0_material" shininess="0.4472135901451111" specular="2"/>
    <texture file="visuals/T_BC001.png" name="fridge_door_material" type="2d"/>
    <material name="fridge_door_material" rgba="1 1 1 1.0" texture="fridge_door_material" shininess="0.4472135901451111" specular="2"/>
    <texture file="visuals/T_BC001.png" name="fridge_door_Clear_material" type="2d"/>
    <material name="fridge_door_Clear_material" rgba="1 1 1 0.4411303400993347" texture="fridge_door_Clear_material" shininess="0.5" specular="0.3103448502657381"/>
    <texture file="visuals/T_BC001.png" name="fridge_drawer0_material" type="2d"/>
    <material name="fridge_drawer0_material" rgba="1 1 1 1.0" texture="fridge_drawer0_material" shininess="0.4472135901451111" specular="0.3103448502657381"/>
    <texture file="visuals/T_BC001.png" name="Body001_Clear_material" type="2d"/>
    <material name="Body001_Clear_material" rgba="1 1 1 0.4411303400993347" texture="Body001_Clear_material" shininess="0.5" specular="0.3103448502657381"/>
  </asset>
  <default>
    <default class="visual">
      <geom conaffinity="0" contype="0" group="1" type="mesh"/>
    </default>
    <default class="collision">
      <geom group="0" rgba="0.5 0 0 0.5"/>
    </default>
    <default class="spawn">
      <geom group="0" rgba="1 1 1 0.5" contype="0" conaffinity="0"/>
      <site group="0" rgba="1 1 1 0.5"/>
    </default>
    <default class="region">
      <geom group="1" conaffinity="0" contype="0" rgba="0 1 0 0"/>
    </default>
  </default>
  <worldbody>
    <body>
      <body name="object">
        <geom mesh="Body001_vis" type="mesh" solimp="0.998 0.998 0.001" solref="0.001 1" friction="0.95 0.3 0.1" class="visual" material="Body001_material"/>
        <geom class="collision" type="box" pos="3.4691765904426575e-08 0.046065088361501694 -0.8849540948867798" size="0.4184049665927887 0.40577802062034607 0.048721954226493835" quat="1.0 0.0 0.0 0.0"/>
        <geom class="collision" type="box" pos="-0.38955575227737427 0.0463176891207695 0.04772455617785454" size="0.02884865179657936 0.40551820397377014 0.8859670162200928" quat="1.0 0.0 0.0 0.0"/>
        <geom class="collision" type="box" pos="-0.014195600524544716 0.04606311395764351 0.8900960087776184" size="0.34721803665161133 0.40577998757362366 0.0435805581510067" quat="1.0 0.0 0.0 0.0"/>
        <geom class="collision" type="box" pos="0.37585487961769104 0.04562413692474365 0.04772542417049408" size="0.04254920780658722 0.40621209144592285 0.8859654068946838" quat="1.0 0.0 0.0 0.0"/>
        <geom class="collision" type="box" pos="-0.009869547560811043 -0.0465119294822216 0.5256437063217163" size="0.34337595105171204 0.2574009597301483 0.002635375363752246" quat="1.0 0.0 0.0 0.0"/>
        <geom class="collision" type="box" pos="-0.009583763778209686 -0.04710531234741211 0.21403063833713531" size="0.34366172552108765 0.2551637291908264 0.0026230011135339737" quat="1.0 0.0 0.0 0.0"/>
        <geom class="collision" type="box" pos="-0.014991133473813534 0.32848867774009705 0.006801291834563017" size="0.34631630778312683 0.12335363030433655 0.8450122475624084" quat="1.0 0.0 0.0 0.0"/>
        <geom class="collision" type="box" pos="-0.014195600524544716 -0.02551545947790146 -0.22356769442558289" size="0.34721803665161133 0.32394760847091675 0.030765503644943237" quat="1.0 0.0 0.0 0.0"/>
        <body name="freezer0">
          <geom class="region" name="reg_freezer0" type="box" pos="-0.009489908814430237 -0.09901586174964905 -0.5897982716560364" size="0.2998690286874771 0.24857039546966553 0.19871569967269898"/>
          <joint axis="0.0 -1.0 0.0" pos="8.940696716308594e-08 -0.13862109184265137 -0.5760611891746521" limited="true" name="freezer0_door_joint" range="0.0 0.45" type="slide" damping="1" frictionloss="1" armature=".01" stiffness="0.05"/>
          <geom mesh="freezer0_vis" type="mesh" solimp="0.998 0.998 0.001" solref="0.001 1" friction="0.95 0.3 0.1" class="visual" material="freezer0_material"/>
          <geom class="collision" type="box" pos="6.955815479159355e-09 -0.3903758227825165 -0.5759356617927551" size="0.4184049367904663 0.01874351315200329 0.34442299604415894" quat="1.0 0.0 0.0 0.0" name="freezer0_door_main"/>
          <geom class="collision" type="box" pos="-0.3456881642341614 -0.42310863733291626 -0.2831193506717682" size="0.021169910207390785 0.013989350758492947 0.017770813778042793" quat="1.0 0.0 0.0 0.0" name="freezer0_door_handle_1"/>
          <geom class="collision" type="box" pos="0.011073564179241657 -0.44080981612205505 -0.2825925648212433" size="0.4073314368724823 0.01143124233931303 0.02148660458624363" quat="1.0 0.0 0.0 0.0" name="freezer0_door_handle_main"/>
          <geom class="collision" type="box" pos="0.3575775623321533 -0.42310863733291626 -0.2831193506717682" size="0.021169910207390785 0.01398931723088026 0.017770813778042793" quat="1.0 0.0 0.0 0.0" name="freezer0_door_handle_2"/>
          <geom class="collision" type="box" pos="0.3081456422805786 -0.08935493230819702 -0.6066580414772034" size="0.012117437086999416 0.26494473218917847 0.22165796160697937" quat="1.0 0.0 0.0 0.0"/>
          <geom class="collision" type="box" pos="-0.32881656289100647 -0.08935493230819702 -0.6066580414772034" size="0.012117435224354267 0.26494473218917847 0.22165796160697937" quat="1.0 0.0 0.0 0.0"/>
          <geom class="collision" type="box" pos="-0.009681074880063534 0.16568218171596527 -0.6066580414772034" size="0.306090384721756 0.009798376820981503 0.22165796160697937" quat="1.0 0.0 0.0 0.0"/>
          <geom class="collision" type="box" pos="-0.009681080467998981 -0.09938091784715652 -0.8112134337425232" size="0.306090384721756 0.2548059821128845 0.017102576792240143" quat="1.0 0.0 0.0 0.0"/>
          <geom class="collision" type="box" pos="-0.013841669075191021 -0.3630203902721405 -0.5440488457679749" size="0.34341034293174744 0.010004036128520966 0.28850358724594116" quat="1.0 0.0 0.0 0.0"/>
        </body>
        <body name="fridge_door">
          <joint axis="0.0 0.0 1.0" pos="0.398270845413208 -0.39148035645484924 0.357952356338501" limited="true" name="fridge_door_joint" range="0.0 1.5707963267948966" type="hinge" damping="1" frictionloss="1" armature=".01" stiffness="0.05"/>
          <geom mesh="fridge_door_vis" type="mesh" solimp="0.998 0.998 0.001" solref="0.001 1" friction="0.95 0.3 0.1" class="visual" material="fridge_door_material"/>
          <geom class="collision" type="box" pos="-0.3035118579864502 -0.3609536588191986 0.1288968026638031" size="0.003228553105145693 0.011789285577833652 0.059241604059934616" quat="1.0 0.0 0.0 0.0"/>
          <geom class="collision" type="box" pos="-0.0008189299842342734 -0.3415113389492035 0.13031218945980072" size="0.3010403513908386 0.003955512773245573 0.06320180743932724" quat="1.0 0.0 0.0 0.0"/>
          <geom class="collision" type="box" pos="0.30434656143188477 -0.35811498761177063 0.12843604385852814" size="0.0020166372414678335 0.020167620852589607 0.058914560824632645" quat="1.0 0.0 0.0 0.0"/>
          <geom class="collision" type="box" pos="-0.0010958004277199507 -0.3632794916629791 0.0617678165435791" size="0.301297664642334 0.014990507625043392 0.004100287798792124" quat="1.0 0.0 0.0 0.0"/>
          <geom class="collision" type="box" pos="0.0006768889725208282 -0.3464416563510895 0.3771534860134125" size="0.2995249629020691 0.014958427287638187 0.0021699205972254276" quat="1.0 0.0 0.0 0.0"/>
          <geom class="collision" type="box" pos="0.3041929602622986 -0.3431452214717865 0.41270139813423157" size="0.002170219086110592 0.012792040593922138 0.029203588142991066" quat="1.0 0.0 0.0 0.0"/>
          <geom class="collision" type="box" pos="0.00023628940107300878 -0.3249150812625885 0.4143744111061096" size="0.2999827563762665 0.00504776556044817 0.027853142470121384" quat="1.0 0.0 0.0 0.0"/>
          <geom class="collision" type="box" pos="-0.3053753972053528 -0.3468959629535675 0.41161346435546875" size="0.0013649907195940614 0.01509031094610691 0.028536992147564888" quat="1.0 0.0 0.0 0.0"/>
          <geom class="collision" type="box" pos="-0.3035118579864502 -0.34567341208457947 0.5358172655105591" size="0.0032285209745168686 0.014797506853938103 0.029959529638290405" quat="1.0 0.0 0.0 0.0"/>
          <geom class="collision" type="box" pos="0.0007004301296547055 -0.3274819552898407 0.5373093485832214" size="0.2995171844959259 0.003708739997819066 0.029826143756508827" quat="1.0 0.0 0.0 0.0"/>
          <geom class="collision" type="box" pos="0.30440574884414673 -0.3509902060031891 0.5287048816680908" size="0.0019574060570448637 0.011457794345915318 0.03615258261561394" quat="1.0 0.0 0.0 0.0"/>
          <geom class="collision" type="box" pos="0.0013456159504130483 -0.35078075528144836 0.5021404027938843" size="0.2988562285900116 0.014763807877898216 0.0041002850048244" quat="1.0 0.0 0.0 0.0"/>
          <geom class="collision" type="box" pos="-0.00013862716150470078 -0.33811357617378235 0.6366299390792847" size="0.300340473651886 0.022642824798822403 0.0015565496869385242" quat="1.0 0.0 0.0 0.0"/>
          <geom class="collision" type="box" pos="0.3044595718383789 -0.34080877900123596 0.6812611222267151" size="0.0019036070443689823 0.019667141139507294 0.041286613792181015" quat="1.0 0.0 0.0 0.0"/>
          <geom class="collision" type="box" pos="-0.0001229922636412084 -0.31280675530433655 0.6845166683197021" size="0.3003382086753845 0.004460331052541733 0.03835388273000717" quat="1.0 0.0 0.0 0.0"/>
          <geom class="collision" type="box" pos="-0.3035118579864502 -0.3385394513607025 0.6774614453315735" size="0.003228538203984499 0.017397744581103325 0.04565775394439697" quat="1.0 0.0 0.0 0.0"/>
          <geom class="collision" type="box" pos="6.984919309616089e-09 -0.39368265867233276 0.3577885627746582" size="0.4184049367904663 0.015436657704412937 0.5758880376815796" quat="1.0 0.0 0.0 0.0" name="fridge_door_main"/>
          <geom class="collision" type="box" pos="-0.3326978087425232 -0.4230325222015381 0.7210708856582642" size="0.017770813778042793 0.013913324102759361 0.021169910207390785" quat="1.0 0.0 0.0 0.0" name="fridge_door_handle_1"/>
          <geom class="collision" type="box" pos="-0.3332245945930481 -0.44065728783607483 0.2762830853462219" size="0.021486591547727585 0.01143124233931303 0.4793464243412018" quat="1.0 0.0 0.0 0.0" name="fridge_door_handle_main"/>
          <geom class="collision" type="box" pos="-0.3326978087425232 -0.42303237318992615 -0.1627090871334076" size="0.017770813778042793 0.013913124799728394 0.021169910207390785" quat="1.0 0.0 0.0 0.0" name="fridge_door_handle_2"/>
          <geom class="collision" type="box" pos="-0.01318422518670559 -0.35715028643608093 0.840620756149292" size="0.34219425916671753 0.023262569680809975 0.004276500083506107" quat="1.0 0.0 0.0 0.0"/>
          <geom class="collision" type="box" pos="0.3195115029811859 -0.35715028643608093 0.4454904794692993" size="0.009498503990471363 0.023262569680809975 0.39117616415023804" quat="1.0 0.0 0.0 0.0"/>
          <geom class="collision" type="box" pos="-0.3373781442642212 -0.35715028643608093 0.4454904794692993" size="0.016009612008929253 0.023262571543455124 0.39117616415023804" quat="1.0 0.0 0.0 0.0"/>
          <body name="fridge_door_Clear">
            <geom mesh="fridge_door_Clear_vis" type="mesh" solimp="0.998 0.998 0.001" solref="0.001 1" friction="0.95 0.3 0.1" class="visual" material="fridge_door_Clear_material"/>
            <geom class="collision" type="box" pos="-0.3035118579864502 -0.3609536588191986 0.1288968026638031" size="0.003228553105145693 0.011789285577833652 0.059241604059934616" quat="1.0 0.0 0.0 0.0"/>
            <geom class="collision" type="box" pos="-0.0008189299842342734 -0.3415113389492035 0.13031218945980072" size="0.3010403513908386 0.003955512773245573 0.06320180743932724" quat="1.0 0.0 0.0 0.0"/>
            <geom class="collision" type="box" pos="0.30434656143188477 -0.35811498761177063 0.12843604385852814" size="0.0020166372414678335 0.020167620852589607 0.058914560824632645" quat="1.0 0.0 0.0 0.0"/>
            <geom class="collision" type="box" pos="-0.0010958004277199507 -0.3632794916629791 0.0617678165435791" size="0.301297664642334 0.014990507625043392 0.004100287798792124" quat="1.0 0.0 0.0 0.0"/>
            <geom class="collision" type="box" pos="0.0006768889725208282 -0.3464416563510895 0.3771534860134125" size="0.2995249629020691 0.014958427287638187 0.0021699205972254276" quat="1.0 0.0 0.0 0.0"/>
            <geom class="collision" type="box" pos="0.3041929602622986 -0.3431452214717865 0.41270139813423157" size="0.002170219086110592 0.012792040593922138 0.029203588142991066" quat="1.0 0.0 0.0 0.0"/>
            <geom class="collision" type="box" pos="0.00023628940107300878 -0.3249150812625885 0.4143744111061096" size="0.2999827563762665 0.00504776556044817 0.027853142470121384" quat="1.0 0.0 0.0 0.0"/>
            <geom class="collision" type="box" pos="-0.3053753972053528 -0.3468959629535675 0.41161346435546875" size="0.0013649907195940614 0.01509031094610691 0.028536992147564888" quat="1.0 0.0 0.0 0.0"/>
            <geom class="collision" type="box" pos="-0.3035118579864502 -0.34567341208457947 0.5358172655105591" size="0.0032285209745168686 0.014797506853938103 0.029959529638290405" quat="1.0 0.0 0.0 0.0"/>
            <geom class="collision" type="box" pos="0.0007004301296547055 -0.3274819552898407 0.5373093485832214" size="0.2995171844959259 0.003708739997819066 0.029826143756508827" quat="1.0 0.0 0.0 0.0"/>
            <geom class="collision" type="box" pos="0.30440574884414673 -0.3509902060031891 0.5287048816680908" size="0.0019574060570448637 0.011457794345915318 0.03615258261561394" quat="1.0 0.0 0.0 0.0"/>
            <geom class="collision" type="box" pos="0.0013456159504130483 -0.35078075528144836 0.5021404027938843" size="0.2988562285900116 0.014763807877898216 0.0041002850048244" quat="1.0 0.0 0.0 0.0"/>
            <geom class="collision" type="box" pos="-0.00013862716150470078 -0.33811357617378235 0.6366299390792847" size="0.300340473651886 0.022642824798822403 0.0015565496869385242" quat="1.0 0.0 0.0 0.0"/>
            <geom class="collision" type="box" pos="0.3044595718383789 -0.34080877900123596 0.6812611222267151" size="0.0019036070443689823 0.019667141139507294 0.041286613792181015" quat="1.0 0.0 0.0 0.0"/>
            <geom class="collision" type="box" pos="-0.0001229922636412084 -0.31280675530433655 0.6845166683197021" size="0.3003382086753845 0.004460331052541733 0.03835388273000717" quat="1.0 0.0 0.0 0.0"/>
            <geom class="collision" type="box" pos="-0.3035118579864502 -0.3385394513607025 0.6774614453315735" size="0.003228538203984499 0.017397744581103325 0.04565775394439697" quat="1.0 0.0 0.0 0.0"/>
          </body>
        </body>
        <body name="fridge_drawer0">
          <geom class="region" name="reg_fridge_drawer0" type="box" pos="-0.01835612952709198 -0.044676944613456726 0.011936359107494354" size="0.29385116493701935 0.2101457098722458 0.1787130737900734"/>
          <joint axis="0.0 -1.0 0.0" pos="-0.01722750999033451 -0.09665685147047043 0.00561465322971344" limited="true" name="fridge_drawer0_joint" range="0.0 0.45" type="slide" damping="1" frictionloss="1" armature=".01" stiffness="0.05"/>
          <geom mesh="fridge_drawer0_vis" type="mesh" solimp="0.998 0.998 0.001" solref="0.001 1" friction="0.95 0.3 0.1" class="visual" material="fridge_drawer0_material"/>
          <geom class="collision" type="box" pos="-0.3300918936729431 -0.04381192475557327 0.010443203151226044" size="0.012271959334611893 0.21923433244228363 0.1853756457567215" quat="1.0 0.0 0.0 0.0"/>
          <geom class="collision" type="box" pos="0.2945006191730499 -0.045922257006168365 0.010281492955982685" size="0.012674178928136826 0.22219836711883545 0.18521392345428467" quat="1.0 0.0 0.0 0.0"/>
          <geom class="collision" type="box" pos="-0.016805533319711685 0.17360424995422363 0.011090479791164398" size="0.31907016038894653 0.002899477956816554 0.18602252006530762" quat="1.0 0.0 0.0 0.0"/>
          <geom class="collision" type="box" pos="-0.019166722893714905 -0.26728662848472595 0.010400258004665375" size="0.3196590542793274 0.0026238486170768738 0.18533270061016083" quat="1.0 0.0 0.0 0.0"/>
          <geom class="collision" type="box" pos="-0.016971122473478317 -0.04920931160449982 -0.17960180342197418" size="0.32334086298942566 0.22023600339889526 0.006715747062116861" quat="1.0 0.0 0.0 0.0"/>
          <geom class="collision" type="box" pos="0.1829824149608612 -0.29321175813674927 0.18143442273139954" size="0.11831755191087723 0.008652029559016228 0.014979681000113487" quat="0.9945970773696899 0.0 0.0 0.10381060838699341"/>
          <geom class="collision" type="box" pos="-0.22086118161678314 -0.2920616865158081 0.18143442273139954" size="0.11387142539024353 0.008652029559016228 0.014979681000113487" quat="0.99354088306427 0.0 -0.0 -0.11347480118274689"/>
          <geom class="collision" type="box" pos="-0.02271162159740925 -0.31760120391845703 0.18143442273139954" size="0.09203242510557175 0.008652030490338802 0.014979681000113487" quat="1.0 0.0 0.0 0.0"/>
        </body>
        <body name="Body001_Clear">
          <geom mesh="Body001_Clear_vis" type="mesh" solimp="0.998 0.998 0.001" solref="0.001 1" friction="0.95 0.3 0.1" class="visual" material="Body001_Clear_material"/>
          <geom class="collision" type="box" pos="-0.009869547560811043 -0.0465119294822216 0.5256437063217163" size="0.34337595105171204 0.2574009597301483 0.002635375363752246" quat="1.0 0.0 0.0 0.0"/>
          <geom class="collision" type="box" pos="-0.009583763778209686 -0.04710531234741211 0.21403063833713531" size="0.34366172552108765 0.2551637291908264 0.0026230011135339737" quat="1.0 0.0 0.0 0.0"/>
        </body>
        <geom class="region" name="reg_fridge_shelf0" type="box" pos="-0.013874515891075134 -0.047584161162376404 0.36608510464429855" size="0.34092867171764374 0.24736034667491913 0.14460583573579788"/>
        <geom class="region" name="reg_fridge_shelf1" type="box" pos="-0.013906046748161316 -0.047584161162376404 0.6868031024932861" size="0.3408779481649399 0.24736034667491913 0.15388007259368897"/>
        <geom class="region" name="reg_main" type="box" pos="1.4901161193847656e-08 0.02136211469769478 -5.960464477539063e-08" size="0.4194049665927887 0.4314814040660858 0.9346766600608826"/>
      </body>
    </body>
  </worldbody>
  <actuator>
    <motor name="freezer0_door_joint_actuator" joint="freezer0_door_joint" gear="50"/>
    <motor name="fridge_door_joint_actuator" joint="fridge_door_joint" gear="50"/>
    <motor name="fridge_drawer0_joint_actuator" joint="fridge_drawer0_joint" gear="50"/>
  </actuator>
</mujoco>
