<?xml version='1.0' encoding='UTF-8'?>
<mujoco model="model">
  <option timestep="0.002" gravity="0.0 0.0 -9.81"/>
  <compiler angle="radian"/>
  <asset>
    <mesh file="visuals/knob_center.obj" name="knob_center_vis"/>
    <mesh file="visuals/knob_front_left.obj" name="knob_front_left_vis"/>
    <mesh file="visuals/knob_front_right.obj" name="knob_front_right_vis"/>
    <mesh file="visuals/knob_rear_left.obj" name="knob_rear_left_vis"/>
    <mesh file="visuals/knob_rear_right.obj" name="knob_rear_right_vis"/>
    <mesh file="visuals/Body001.obj" name="Body001_vis"/>
    <mesh file="visuals/Body002.obj" name="Body002_vis"/>
    <texture file="visuals/T_BC001.png" name="Body001_material" type="2d"/>
    <material name="Body001_material" rgba="1 1 1 1.0" texture="Body001_material" shininess="0.4472135901451111" specular="1"/>
    <texture file="visuals/T_BC001.png" name="knob_center_material" type="2d"/>
    <material name="knob_center_material" rgba="1 1 1 1.0" texture="knob_center_material" shininess="0.4472135901451111" specular="0.3103448502657381"/>
    <texture file="visuals/T_BC001.png" name="knob_front_left_material" type="2d"/>
    <material name="knob_front_left_material" rgba="1 1 1 1.0" texture="knob_front_left_material" shininess="0.4472135901451111" specular="0.3103448502657381"/>
    <texture file="visuals/T_BC001.png" name="knob_front_right_material" type="2d"/>
    <material name="knob_front_right_material" rgba="1 1 1 1.0" texture="knob_front_right_material" shininess="0.4472135901451111" specular="0.3103448502657381"/>
    <texture file="visuals/T_BC001.png" name="knob_rear_left_material" type="2d"/>
    <material name="knob_rear_left_material" rgba="1 1 1 1.0" texture="knob_rear_left_material" shininess="0.4472135901451111" specular="0.3103448502657381"/>
    <texture file="visuals/T_BC001.png" name="knob_rear_right_material" type="2d"/>
    <material name="knob_rear_right_material" rgba="1 1 1 1.0" texture="knob_rear_right_material" shininess="0.4472135901451111" specular="0.3103448502657381"/>
    <texture file="visuals/T_BC001.png" name="Body002_material" type="2d"/>
    <material name="Body002_material" rgba="1 1 1 1.0" texture="Body002_material" shininess="0.4472135901451111" specular="5"/>
  </asset>
  <default>
    <default class="visual">
      <geom conaffinity="0" contype="0" group="1" type="mesh"/>
    </default>
    <default class="collision">
      <geom group="0" rgba="0.5 0 0 0.5"/>
    </default>
    <default class="spawn">
      <geom group="0" rgba="1 1 1 0.5" contype="0" conaffinity="0"/>
      <site group="0" rgba="1 1 1 0.5"/>
    </default>
    <default class="region">
      <geom group="1" conaffinity="0" contype="0" rgba="0 1 0 0"/>
    </default>
  </default>
  <worldbody>
    <body>
      <body name="object">
        <geom mesh="Body001_vis" type="mesh" solimp="0.998 0.998 0.001" solref="0.001 1" friction="0.95 0.3 0.1" class="visual" material="Body001_material"/>
        <geom class="collision" type="box" pos="-0.28813583 -0.16638283 0.00337146" size="0.0751245766878128 0.0444386787712574 0.0019045494263991714" quat="1.0 0.0 0.0 0.0"/>
        <geom class="collision" type="box" pos="0.28999156 -0.16747157 0.00333294" size="0.0732676312327385 0.04469894990324974 0.0019430917454883456" quat="1.0 0.0 0.0 0.0"/>
        <geom class="collision" type="box" pos="0.00106531 -0.00434250 -0.00706696" size="0.3523796498775482 0.20782798528671265 0.011730697937309742" quat="1.0 0.0 0.0 0.0"/>
        <geom class="collision" type="box" pos="0.14612123 -0.18761241 0.00366933" size="0.024549225345253944 0.024557655677199364 0.0016067030373960733" quat="1.0 0.0 0.0 0.0"/>
        <geom class="collision" type="box" pos="0.05225899 -0.18761241 0.00366930" size="0.024549225345253944 0.024557670578360558 0.0016066738171502948" quat="1.0 0.0 0.0 0.0"/>
        <geom class="collision" type="box" pos="-0.04284529 -0.18761241 0.00366930" size="0.02556147426366806 0.02455768547952175 0.0016066748648881912" quat="1.0 0.0 0.0 0.0"/>
        <geom class="collision" type="box" pos="-0.14043364 -0.18761241 0.00366933" size="0.027516139671206474 0.02455807849764824 0.0016067055985331535" quat="1.0 0.0 0.0 0.0"/>
        <geom class="collision" type="box" pos="-0.00054177 -0.14305633 0.00436129" size="0.21817095577716827 0.021450063213706017 0.0009147481177933514" quat="1.0 0.0 0.0 0.0"/>
        <body name="knob_center">
          <joint axis="0.0 0.0 1.0" pos="0.00411063 -0.18759118 0.01275586" limited="true" name="knob_center_joint" range="0.0 3.490658503988659" type="hinge" damping="0.05" armature="0.001"/>
          <geom mesh="knob_center_vis" type="mesh" solimp="0.998 0.998 0.001" solref="0.001 1" friction="0.95 0.3 0.1" class="visual" material="knob_center_material"/>
          <geom class="collision" type="cylinder" pos="0.00480273 -0.18758310 0.00727141" size="0.019496535882353783 0.0014805382816120982" quat="1.0 0.0 0.0 0.0"/>
          <geom class="collision" type="box" pos="0.00479777 -0.18707226 0.01400510" size="0.0055315857753157616 0.018967404961586 0.005083708558231592" quat="1.0 0.0 0.0 0.0" name="knob_center_main"/>
        </body>
        <body name="knob_front_left">
          <joint axis="0.0 0.0 1.0" pos="-0.18964076 -0.18762493 0.01276156" limited="true" name="knob_front_left_joint" range="0.0 3.490658503988659" type="hinge" damping="0.05" armature="0.001"/>
          <geom mesh="knob_front_left_vis" type="mesh" solimp="0.998 0.998 0.001" solref="0.001 1" friction="0.95 0.3 0.1" class="visual" material="knob_front_left_material"/>
          <geom class="collision" type="cylinder" pos="-0.19024011 -0.18773565 0.00710645" size="0.020140523090958595 0.001558757503516972" quat="1.0 0.0 0.0 0.0"/>
          <geom class="collision" type="box" pos="-0.19019648 -0.18750843 0.01417008" size="0.005714186001569033 0.019593531265854836 0.005329487845301628" quat="1.0 0.0 0.0 0.0" name="knob_front_left_main"/>
        </body>
        <body name="knob_front_right">
          <joint axis="0.0 0.0 1.0" pos="0.19270384 -0.18753318 0.01275206" limited="true" name="knob_front_right_joint" range="0.0 3.490658503988659" type="hinge" damping="0.05" armature="0.001"/>
          <geom mesh="knob_front_right_vis" type="mesh" solimp="0.998 0.998 0.001" solref="0.001 1" friction="0.95 0.3 0.1" class="visual" material="knob_front_right_material"/>
          <geom class="collision" type="cylinder" pos="0.19267158 -0.18742198 0.00726491" size="0.019521916285157204 0.0014836209593340755" quat="1.0 0.0 0.0 0.0"/>
          <geom class="collision" type="box" pos="0.19318451 -0.18749899 0.01401163" size="0.005538681522011757 0.018991736695170403 0.00509310606867075" quat="1.0 0.0 0.0 0.0" name="knob_front_right_main"/>
        </body>
        <body name="knob_rear_left">
          <joint axis="0.0 0.0 1.0" pos="-0.08995538 -0.18754975 0.01275357" limited="true" name="knob_rear_left_joint" range="0.0 3.490658503988659" type="hinge" damping="0.05" armature="0.001"/>
          <geom mesh="knob_rear_left_vis" type="mesh" solimp="0.998 0.998 0.001" solref="0.001 1" friction="0.95 0.3 0.1" class="visual" material="knob_rear_left_material"/>
          <geom class="collision" type="cylinder" pos="-0.08981052 -0.18720858 0.00719654" size="0.019788820296525955 0.0015160393668338656" quat="1.0 0.0 0.0 0.0"/>
          <geom class="collision" type="box" pos="-0.08985190 -0.18719451 0.01407999" size="0.005614409688860178 0.01925140619277954 0.005195101257413626" quat="1.0 0.0 0.0 0.0" name="knob_rear_left_main"/>
        </body>
        <body name="knob_rear_right">
          <joint axis="0.0 0.0 1.0" pos="0.09888817 -0.18750942 0.01275500" limited="true" name="knob_rear_right_joint" range="0.0 3.490658503988659" type="hinge" damping="0.05" armature="0.001"/>
          <geom mesh="knob_rear_right_vis" type="mesh" solimp="0.998 0.998 0.001" solref="0.001 1" friction="0.95 0.3 0.1" class="visual" material="knob_rear_right_material"/>
          <geom class="collision" type="cylinder" pos="0.09901419 -0.18728840 0.00727758" size="0.019472436979413033 0.0014776111347600818" quat="1.0 0.0 0.0 0.0"/>
          <geom class="collision" type="box" pos="0.09915873 -0.18744788 0.01399895" size="0.005524749401956797 0.01894395798444748 0.0050742062740027905" quat="1.0 0.0 0.0 0.0" name="knob_rear_right_main"/>
        </body>
        <body name="Body002">
          <geom mesh="Body002_vis" type="mesh" solimp="0.998 0.998 0.001" solref="0.001 1" friction="0.95 0.3 0.1" class="visual" material="Body002_material"/>
          <geom class="collision" type="box" pos="0.00069567 0.02321664 0.00143281" size="0.3594398498535156 0.1850607693195343 0.012610304169356823" quat="1.0 0.0 0.0 0.0"/>
        </body>
        <site type="cylinder" rgba="0.3 0.4 1 0.5" size="0.03745981678366661 0.002486850367859006" pos="0.00015866 0.05000529 0.00568537" name="burner_on_center"/>
        <site type="cylinder" rgba="0.3 0.4 1 0.5" size="0.02907802164554596 0.003863085061311722" pos="-0.22942518 -0.06691027 0.00486764" name="burner_on_front_left"/>
        <site type="cylinder" rgba="0.3 0.4 1 0.5" size="0.02907802164554596 0.0042644646018743515" pos="-0.22942518 0.08998244 0.00451344" name="burner_on_rear_left"/>
        <site type="cylinder" rgba="0.3 0.4 1 0.5" size="0.022008158266544342 0.0031790260691195726" pos="0.22896278 0.08977943 0.00039701" name="burner_on_rear_right"/>
        <site type="cylinder" rgba="0.3 0.4 1 0.5" size="0.03311452642083168 0.004783322103321552" pos="0.22916579 -0.06691027 0.00492176" name="burner_on_front_right"/>
        <site type="cylinder" rgba="0.5 0 0 0" size="0.03971847891807556 4.999998054699972e-05" pos="0.00028196 0.05062176 0.01404308" name="burner_center_place_site"/>
        <site type="cylinder" rgba="0.5 0 0 0" size="0.02907802164554596 4.9999951443169266e-05" pos="-0.22942518 -0.06691027 0.01404308" name="burner_front_left_place_site"/>
        <site type="cylinder" rgba="0.5 0 0 0" size="0.03311452642083168 4.999994416721165e-05" pos="0.22916579 -0.06691027 0.01404308" name="burner_front_right_place_site"/>
        <site type="cylinder" rgba="0.5 0 0 0" size="0.02907802164554596 5.0000013288808987e-05" pos="-0.22942518 0.08998244 0.01404308" name="burner_rear_left_place_site"/>
        <site type="cylinder" rgba="0.5 0 0 0" size="0.022008158266544342 4.999995871912688e-05" pos="0.22896278 0.08977943 0.01404308" name="burner_rear_right_place_site"/>
        <geom class="region" name="reg_main" type="box" pos="0.0 0.0 -0.006760839999999999" size="0.36426039 0.21317048 0.01303685"/>
      </body>
    </body>
  </worldbody>
  <actuator>
    <motor name="knob_center_joint_actuator" joint="knob_center_joint" gear="10"/>
    <motor name="knob_front_left_joint_actuator" joint="knob_front_left_joint" gear="10"/>
    <motor name="knob_front_right_joint_actuator" joint="knob_front_right_joint" gear="10"/>
    <motor name="knob_rear_left_joint_actuator" joint="knob_rear_left_joint" gear="10"/>
    <motor name="knob_rear_right_joint_actuator" joint="knob_rear_right_joint" gear="10"/>
  </actuator>
</mujoco>
