<?xml version='1.0' encoding='UTF-8'?>
<mujoco model="model">
  <option timestep="0.002" gravity="0.0 0.0 -9.81"/>
  <compiler angle="radian"/>
  <asset>
    <mesh file="visuals/button_lock.obj" name="button_lock_vis"/>
    <mesh file="visuals/button_power.obj" name="button_power_vis"/>
    <mesh file="visuals/Body001.obj" name="Body001_vis"/>
    <mesh file="visuals/door.obj" name="door_vis"/>
    <mesh file="visuals/rack0.obj" name="rack0_vis"/>
    <mesh file="visuals/rack1.obj" name="rack1_vis"/>
    <texture file="visuals/T_BC001.png" name="Body001_material" type="2d"/>
    <material name="Body001_material" rgba="1 1 1 1.0" texture="Body001_material" shininess="0.2512328028678894" specular="0.3103448502657381"/>
    <texture file="visuals/T_BC001.png" name="door_material" type="2d"/>
    <material name="door_material" rgba="1 1 1 1.0" texture="door_material" shininess="0.2512328028678894" specular="0.3103448502657381"/>
    <texture file="visuals/T_BC001.png" name="button_lock_material" type="2d"/>
    <material name="button_lock_material" rgba="1 1 1 1.0" texture="button_lock_material" shininess="0.2512328028678894" specular="0.3103448502657381"/>
    <texture file="visuals/T_BC001.png" name="button_power_material" type="2d"/>
    <material name="button_power_material" rgba="1 1 1 1.0" texture="button_power_material" shininess="0.2512328028678894" specular="0.3103448502657381"/>
    <texture file="visuals/T_BC001.png" name="rack0_material" type="2d"/>
    <material name="rack0_material" rgba="1 1 1 1.0" texture="rack0_material" shininess="0.2512328028678894" specular="0.81"/>
    <texture file="visuals/T_BC001.png" name="rack1_material" type="2d"/>
    <material name="rack1_material" rgba="1 1 1 1.0" texture="rack1_material" shininess="0.2512328028678894" specular="0.81"/>
  </asset>
  <default>
    <default class="visual">
      <geom conaffinity="0" contype="0" group="1" type="mesh"/>
    </default>
    <default class="collision">
      <geom group="0" rgba="0.5 0 0 0.5"/>
    </default>
    <default class="spawn">
      <geom group="0" rgba="1 1 1 0.5" contype="0" conaffinity="0"/>
      <site group="0" rgba="1 1 1 0.5"/>
    </default>
    <default class="region">
      <geom group="1" conaffinity="0" contype="0" rgba="0 1 0 0"/>
    </default>
  </default>
  <worldbody>
    <body>
      <body name="object">
        <geom mesh="Body001_vis" type="mesh" solimp="0.998 0.998 0.001" solref="0.001 1" friction="0.95 0.3 0.1" class="visual" material="Body001_material"/>
        <geom class="collision" type="box" pos="0.00029417 0.07328099 -0.39501620" size="0.3009321391582489 0.24403943121433258 0.05291081219911575" quat="1.0 0.0 0.0 0.0"/>
        <geom class="collision" type="box" pos="-0.00076243 0.05632151 0.42135128" size="0.30047422647476196 0.26099902391433716 0.012723494321107864" quat="1.0 0.0 0.0 0.0"/>
        <geom class="collision" type="box" pos="0.28546664 0.05578600 0.07878324" size="0.011960831470787525 0.26153454184532166 0.3489367961883545" quat="1.0 0.0 0.0 0.0"/>
        <geom class="collision" type="box" pos="-0.00000517 0.31023428 -0.00255796" size="0.3012315034866333 0.007086256518959999 0.430277943611145" quat="1.0 0.0 0.0 0.0"/>
        <geom class="collision" type="box" pos="-0.28707191 0.05578600 0.07878324" size="0.013566008768975735 0.26153454184532166 0.3489367961883545" quat="1.0 0.0 0.0 0.0"/>
        <geom class="collision" type="box" pos="0.00029417 0.08525718 -0.31731966" size="0.3009321391582489 0.23206323385238647 0.0508718378841877" quat="1.0 0.0 0.0 0.0"/>
        <geom class="collision" type="box" pos="-0.00000518 0.05632141 -0.26035485" size="0.3012315034866333 0.26099902391433716 0.009799429215490818" quat="1.0 0.0 0.0 0.0"/>
        <geom class="collision" type="box" pos="-0.27701229 0.04340295 0.34653520" size="0.013169663026928902 0.2292359173297882 0.005914244335144758" quat="1.0 0.0 0.0 0.0"/>
        <geom class="collision" type="box" pos="-0.27701229 0.04340295 0.31398350" size="0.013169663026928902 0.2292359173297882 0.005914244335144758" quat="1.0 0.0 0.0 0.0"/>
        <geom class="collision" type="box" pos="-0.27679080 0.26754209 0.33028286" size="0.013391165062785149 0.005096788052469492 0.011809350922703743" quat="1.0 0.0 0.0 0.0"/>
        <geom class="collision" type="box" pos="-0.27936542 0.25883684 0.33028286" size="0.010816534981131554 0.005096788052469492 0.011809350922703743" quat="1.0 0.0 0.0 0.0"/>
        <geom class="collision" type="box" pos="-0.27892971 0.25883684 0.16583746" size="0.010816534981131554 0.005096788052469492 0.016891485080122948" quat="1.0 0.0 0.0 0.0"/>
        <geom class="collision" type="box" pos="-0.27864802 0.26754209 0.16583746" size="0.011098233982920647 0.005096788052469492 0.016891485080122948" quat="1.0 0.0 0.0 0.0"/>
        <geom class="collision" type="box" pos="-0.27712440 0.04684454 0.14532323" size="0.009106027893722057 0.22579433023929596 0.005046974401921034" quat="1.0 0.0 0.0 0.0"/>
        <geom class="collision" type="box" pos="-0.27696317 0.04684454 0.18706336" size="0.009267290122807026 0.22579433023929596 0.0045092664659023285" quat="1.0 0.0 0.0 0.0"/>
        <geom class="collision" type="box" pos="0.27618822 0.04684454 0.18771903" size="0.005342652555555105 0.22579433023929596 0.0049775890074670315" quat="1.0 0.0 0.0 0.0"/>
        <geom class="collision" type="box" pos="0.27634948 0.04684454 0.14511335" size="0.005181390326470137 0.22579433023929596 0.004837093409150839" quat="1.0 0.0 0.0 0.0"/>
        <geom class="collision" type="box" pos="0.27954757 0.26754209 0.16572125" size="0.009056074544787407 0.005096788052469492 0.017195038497447968" quat="1.0 0.0 0.0 0.0"/>
        <geom class="collision" type="box" pos="0.28212219 0.25883684 0.16572125" size="0.006481444928795099 0.005096788052469492 0.017195038497447968" quat="1.0 0.0 0.0 0.0"/>
        <geom class="collision" type="box" pos="0.27822283 0.25883684 0.33028286" size="0.010816534981131554 0.005096788052469492 0.011809350922703743" quat="1.0 0.0 0.0 0.0"/>
        <geom class="collision" type="box" pos="0.27564821 0.26754209 0.33028286" size="0.013391165062785149 0.005096788052469492 0.011809350922703743" quat="1.0 0.0 0.0 0.0"/>
        <geom class="collision" type="box" pos="0.27586970 0.04340295 0.31398350" size="0.013169663026928902 0.2292359173297882 0.005914244335144758" quat="1.0 0.0 0.0 0.0"/>
        <geom class="collision" type="box" pos="0.27586970 0.04340295 0.34653520" size="0.013169663026928902 0.2292359173297882 0.005914244335144758" quat="1.0 0.0 0.0 0.0"/>
        <geom class="collision" type="box" pos="-0.27892971 0.26000974 -0.09731040" size="0.010816534981131554 0.003923878073692322 0.016891485080122948" quat="1.0 0.0 0.0 0.0"/>
        <geom class="collision" type="box" pos="-0.27864802 0.26754209 -0.09731040" size="0.011098233982920647 0.005096788052469492 0.016891485080122948" quat="1.0 0.0 0.0 0.0"/>
        <geom class="collision" type="box" pos="-0.27712440 0.04684454 -0.11782464" size="0.009106027893722057 0.22579433023929596 0.005046974401921034" quat="1.0 0.0 0.0 0.0"/>
        <geom class="collision" type="box" pos="-0.27696317 0.04684454 -0.07608451" size="0.009267290122807026 0.22579433023929596 0.0045092664659023285" quat="1.0 0.0 0.0 0.0"/>
        <geom class="collision" type="box" pos="0.27603841 0.04684454 -0.07522218" size="0.0054924688301980495 0.22579433023929596 0.0049775876104831696" quat="1.0 0.0 0.0 0.0"/>
        <geom class="collision" type="box" pos="0.27619967 0.04684454 -0.11782787" size="0.005331206601113081 0.22579433023929596 0.00483709154650569" quat="1.0 0.0 0.0 0.0"/>
        <geom class="collision" type="box" pos="0.27954757 0.26754209 -0.09721996" size="0.009056074544787407 0.005096788052469492 0.017195038497447968" quat="1.0 0.0 0.0 0.0"/>
        <geom class="collision" type="box" pos="0.28212219 0.25883684 -0.09721996" size="0.006481444928795099 0.005096788052469492 0.017195038497447968" quat="1.0 0.0 0.0 0.0"/>
        <geom class="collision" type="box" pos="0.00066126 0.28484437 -0.00255796" size="0.018991000950336456 0.0074838194996118546 0.430277943611145" quat="1.0 0.0 0.0 0.0"/>
        <body name="door">
          <joint axis="1.0 0.0 0.0" pos="0.00000003 -0.21591373 -0.28529650" limited="true" name="door_joint" range="0.0 0.65" type="hinge" damping="1" frictionloss="1" armature=".01" stiffness="0.2" springref="-50"/>
          <geom mesh="door_vis" type="mesh" solimp="0.998 0.998 0.001" solref="0.001 1" friction="0.95 0.3 0.1" class="visual" material="door_material"/>
          <geom class="collision" type="cylinder" pos="0.19631019 -0.29907158 0.39731550" size="0.01735132746398449 0.060629162937402725" quat="0.7062416076660156 -0.03496948629617691 0.7062415480613708 0.03496948257088661" name="door_handle_2"/>
          <geom class="collision" type="cylinder" pos="-0.19515961 -0.29866976 0.39731550" size="0.01735132746398449 0.059862907975912094" quat="0.7062416076660156 0.03496948629617691 0.7062415480613708 -0.03496948257088661" name="door_handle_1"/>
          <geom class="collision" type="box" pos="0.23335938 -0.27898762 0.39746287" size="0.026319457218050957 0.024345053359866142 0.012857450172305107" quat="1.0 0.0 0.0 0.0"/>
          <geom class="collision" type="box" pos="0.22132823 -0.28404731 0.39746287" size="0.024539422243833542 0.019285371527075768 0.012857450172305107" quat="1.0 0.0 0.0 0.0"/>
          <geom class="collision" type="box" pos="0.24247786 -0.26710165 0.39746287" size="0.026319457218050957 0.012459082528948784 0.012857450172305107" quat="1.0 0.0 0.0 0.0"/>
          <geom class="collision" type="box" pos="-0.00000002 -0.23670320 0.05462014" size="0.30156058073043823 0.016663767397403717 0.38467860221862793" quat="1.0 0.0 0.0 0.0" name="door_main"/>
          <geom class="collision" type="box" pos="-0.23421580 -0.27898762 0.39746287" size="0.026319457218050957 0.024345053359866142 0.012857450172305107" quat="1.0 0.0 0.0 0.0"/>
          <geom class="collision" type="box" pos="-0.22348009 -0.28404731 0.39746287" size="0.024539422243833542 0.019285371527075768 0.012857450172305107" quat="1.0 0.0 0.0 0.0"/>
          <geom class="collision" type="box" pos="-0.24415970 -0.26710165 0.39746287" size="0.026319457218050957 0.012459082528948784 0.012857450172305107" quat="1.0 0.0 0.0 0.0"/>
          <geom class="collision" type="cylinder" pos="-0.00026742 -0.30440718 0.39734283" size="0.016833096742630005 0.13011766970157623" quat="0.7071068286895752 0.0 -0.7071067690849304 0.0" name="door_handle_main"/>
          <body name="button_lock">
            <joint axis="0.0 0.0 -1.0" pos="0.18303400 -0.22955389 0.44712066" limited="true" name="button_lock_joint" range="0.0 0.0015" type="slide" damping="1" frictionloss="1" armature=".01" stiffness="0.5" springref="-1"/>
            <geom mesh="button_lock_vis" type="mesh" solimp="0.998 0.998 0.001" solref="0.001 1" friction="0.95 0.3 0.1" class="visual" material="button_lock_material"/>
            <geom class="collision" type="box" pos="0.18298596 -0.22957662 0.44871676" size="0.00852269772440195 0.00852269772440195 0.0017354871379211545" quat="1.0 0.0 0.0 0.0"/>
          </body>
          <body name="button_power">
            <joint axis="0.0 0.0 -1.0" pos="-0.18628043 -0.22955389 0.44712066" limited="true" name="button_power_joint" range="0.0 0.0015" type="slide" damping="1" frictionloss="1" armature=".01" stiffness="0.5" springref="-1"/>
            <geom mesh="button_power_vis" type="mesh" solimp="0.998 0.998 0.001" solref="0.001 1" friction="0.95 0.3 0.1" class="visual" material="button_power_material"/>
            <geom class="collision" type="box" pos="-0.18621622 -0.22957662 0.44871676" size="0.00852269772440195 0.00852269772440195 0.0017354871379211545" quat="1.0 0.0 0.0 0.0"/>
          </body>
        </body>
        <body name="rack0">
          <geom class="region" name="reg_rack0" type="box" pos="-0.00014389000000000762 0.03043224 -0.026006825000000004" size="0.24410039 0.19327739 0.103825535"/>
          <joint axis="0.0 -1.0 0.0" pos="0.00002422 0.03081315 -0.08415386" limited="true" name="rack0_joint" range="0.0 0.11" type="slide" damping="1" frictionloss="1" armature=".01" stiffness="0.05"/>
          <geom mesh="rack0_vis" type="mesh" solimp="0.998 0.998 0.001" solref="0.001 1" friction="0.95 0.3 0.1" class="visual" material="rack0_material"/>
          <geom class="collision" type="box" pos="-0.07983516 -0.03449736 -0.14929544" size="0.0009215290774591267 0.006419182289391756 0.002024671994149685" quat="1.0 0.0 0.0 0.0"/>
          <geom class="collision" type="box" pos="-0.08394356 -0.03449736 -0.14755120" size="0.004006793722510338 0.006419182755053043 0.0005324396188370883" quat="1.0 0.0 0.0 0.0"/>
          <geom class="collision" type="box" pos="-0.15429580 -0.05028968 -0.11694812" size="0.09347943216562271 0.002516882959753275 0.04563521966338158" quat="0.09089885652065277 0.7012399435043335 0.7012398838996887 0.09089892357587814"/>
          <geom class="collision" type="box" pos="-0.08175866 0.13373846 -0.09997887" size="0.09813521057367325 0.002516882959753275 0.04563521593809128" quat="0.09341192990541458 -0.7009094953536987 -0.7009096145629883 0.0934118703007698"/>
          <geom class="collision" type="box" pos="0.05957322 0.03249620 -0.10229826" size="0.17156313359737396 0.002516882261261344 0.04563521593809128" quat="0.09341192990541458 -0.7009094953536987 -0.7009096145629883 0.0934118703007698"/>
          <geom class="collision" type="box" pos="0.19291317 0.05567762 -0.12249402" size="0.1869610697031021 0.002516882959753275 0.04670282453298569" quat="0.1831398904323578 0.6829785704612732 0.682978630065918 0.18313990533351898"/>
          <geom class="collision" type="box" pos="0.23743968 0.04642402 -0.16426477" size="0.022970160469412804 0.21411961317062378 0.0026653041131794453" quat="1.0 0.0 0.0 0.0"/>
          <geom class="collision" type="box" pos="0.20247936 0.04642401 -0.15544653" size="0.21413519978523254 0.0025168831925839186 0.028035128489136696" quat="0.3555333912372589 0.6112250089645386 0.6112250089645386 0.3555334210395813"/>
          <geom class="collision" type="box" pos="0.15037882 0.04642402 -0.15534444" size="0.21413518488407135 0.0025168827269226313 0.021187733858823776" quat="0.6499353051185608 0.27853918075561523 0.2785392105579376 0.6499353051185608"/>
          <geom class="collision" type="box" pos="0.11886489 0.04642401 -0.15607500" size="0.21413519978523254 0.0025168831925839186 0.025858500972390175" quat="0.4052272140979767 0.579474687576294 0.579474687576294 0.4052272439002991"/>
          <geom class="collision" type="box" pos="0.00046990 0.04594428 -0.14755915" size="0.09508145600557327 0.21459941565990448 0.002690638415515423" quat="1.0 0.0 0.0 0.0"/>
          <geom class="collision" type="box" pos="-0.11756045 0.04642401 -0.15587850" size="0.21413519978523254 0.0025168831925839186 0.0251455157995224" quat="0.5795987844467163 0.4050496518611908 0.4050496816635132 0.5795987844467163"/>
          <geom class="collision" type="box" pos="-0.04980827 0.02324805 -0.15690895" size="0.013340570963919163 0.006175429560244083 0.006049413233995438" quat="1.0 0.0 0.0 0.0"/>
          <geom class="collision" type="box" pos="-0.14897253 0.04642402 -0.15609186" size="0.21413518488407135 0.0025168827269226313 0.02121863141655922" quat="0.279901921749115 0.649349570274353 0.6493496298789978 0.27990207076072693"/>
          <geom class="collision" type="box" pos="-0.20256023 0.04642401 -0.15631652" size="0.21413519978523254 0.0025168827269226313 0.026395291090011597" quat="0.6152599453926086 0.34850409626960754 0.3485041558742523 0.6152600646018982"/>
          <geom class="collision" type="box" pos="-0.23729941 0.04642401 -0.16366808" size="0.023139100521802902 0.21411985158920288 0.0025167774874716997" quat="1.0 0.0 0.0 0.0"/>
          <geom class="collision" type="box" pos="0.25844225 0.04642397 -0.07589085" size="0.00708431750535965 0.21411994099617004 0.08800740540027618" quat="1.0 0.0 0.0 0.0"/>
          <geom class="collision" type="box" pos="-0.00009505 -0.17338634 -0.07589085" size="0.263395220041275 0.004776543006300926 0.08800744265317917" quat="1.0 0.0 0.0 0.0"/>
          <geom class="collision" type="box" pos="-0.25975969 0.04642401 -0.07589085" size="0.005382630508393049 0.21412010490894318 0.08800748735666275" quat="1.0 0.0 0.0 0.0"/>
          <geom class="collision" type="box" pos="0.16230601 0.25682986 -0.07589085" size="0.09588821232318878 0.0052562495693564415 0.08800752460956573" quat="1.0 0.0 0.0 0.0"/>
          <geom class="collision" type="box" pos="0.05490205 0.24349350 -0.07092467" size="0.018606767058372498 0.005256484728306532 0.08341021835803986" quat="0.3173389434814453 0.0 -0.0 -0.9483121633529663"/>
          <geom class="collision" type="box" pos="-0.00184746 0.23558646 -0.07589085" size="0.04493517056107521 0.00420778663828969 0.08800756931304932" quat="1.0 0.0 0.0 0.0"/>
          <geom class="collision" type="box" pos="-0.05877124 0.24720354 -0.07092467" size="0.018606767058372498 0.005256484728306532 0.08341021835803986" quat="0.9204282760620117 0.0 -0.0 -0.3909115195274353"/>
          <geom class="collision" type="box" pos="-0.08829404 -0.03449736 -0.14398267" size="0.0006814482621848583 0.006419182289391756 0.004163840319961309" quat="1.0 0.0 0.0 0.0"/>
          <geom class="collision" type="box" pos="-0.16545722 0.25682986 -0.07589085" size="0.09588833153247833 0.00525625329464674 0.08800765126943588" quat="1.0 0.0 0.0 0.0"/>
          <geom class="collision" type="box" pos="-0.02890452 0.04324955 -0.15910273" size="0.009459958411753178 0.18434371054172516 0.009459900669753551" quat="1.0 0.0 0.0 0.0"/>
          <geom class="collision" type="box" pos="0.26040110 0.09256986 -0.08043865" size="0.0016526376130059361 0.1631735861301422 0.009929639287292957" quat="1.0 0.0 0.0 0.0"/>
          <geom class="collision" type="box" pos="0.26043624 -0.08031923 -0.10745059" size="0.0016174936899915338 0.010302397422492504 0.0369400829076767" quat="1.0 0.0 0.0 0.0"/>
          <geom class="collision" type="box" pos="0.26696804 -0.04438775 -0.08228123" size="0.0054283360950648785 0.005095592699944973 0.001464014989323914" quat="1.0 0.0 0.0 0.0"/>
          <geom class="collision" type="box" pos="0.26719877 -0.04438775 -0.11026179" size="0.005197575315833092 0.005095594096928835 0.001811028691008687" quat="1.0 0.0 0.0 0.0"/>
          <geom class="collision" type="box" pos="0.26719877 -0.04786528 -0.09581838" size="0.005197576712816954 0.0016182493418455124 0.013074900023639202" quat="1.0 0.0 0.0 0.0"/>
          <geom class="collision" type="box" pos="0.26726469 0.10136647 -0.08510555" size="0.004186698235571384 0.1479000300168991 0.0017828861018642783" quat="1.0 0.0 0.0 0.0"/>
          <geom class="collision" type="box" pos="0.26431802 0.08270192 -0.06860362" size="0.005861997604370117 0.17304180562496185 0.002146468497812748" quat="1.0 0.0 0.0 0.0"/>
          <geom class="collision" type="box" pos="0.26627210 0.10136647 -0.08902053" size="0.003194267163053155 0.14790011942386627 0.002412942936643958" quat="1.0 0.0 0.0 0.0"/>
          <geom class="collision" type="box" pos="-0.04980827 -0.03433228 -0.15690895" size="0.013340570963919163 0.006175429560244083 0.006049413233995438" quat="1.0 0.0 0.0 0.0"/>
          <geom class="collision" type="box" pos="0.26627210 0.10136647 -0.10696460" size="0.003194268560037017 0.14790022373199463 0.00241294433362782" quat="1.0 0.0 0.0 0.0"/>
          <geom class="collision" type="box" pos="0.26627210 -0.03862338 -0.09800271" size="0.003194269258528948 0.007917537353932858 0.007178285624831915" quat="1.0 0.0 0.0 0.0"/>
          <geom class="collision" type="box" pos="0.26627210 0.11469522 -0.09800271" size="0.003194269957020879 0.13459159433841705 0.007178287021815777" quat="1.0 0.0 0.0 0.0"/>
          <geom class="collision" type="box" pos="0.26381886 -0.02690836 -0.09800271" size="0.000741118798032403 0.007917542941868305 0.007178288418799639" quat="1.0 0.0 0.0 0.0"/>
          <geom class="collision" type="box" pos="0.26688278 0.10134265 -0.11018511" size="0.004881561268121004 0.14793668687343597 0.0018877162365242839" quat="1.0 0.0 0.0 0.0"/>
          <geom class="collision" type="box" pos="0.26283953 0.02140599 -0.10904942" size="0.004090850707143545 0.016424477100372314 0.01875297538936138" quat="1.0 0.0 0.0 0.0"/>
          <geom class="collision" type="box" pos="0.26283953 0.06417835 -0.10904942" size="0.004090852104127407 0.024293581023812294 0.01875298097729683" quat="1.0 0.0 0.0 0.0"/>
          <geom class="collision" type="box" pos="0.26283953 0.10974296 -0.10904942" size="0.004090853501111269 0.018582142889499664 0.018752986565232277" quat="1.0 0.0 0.0 0.0"/>
          <geom class="collision" type="box" pos="0.26283953 0.19360924 -0.10904942" size="0.004090854898095131 0.062086645513772964 0.018752992153167725" quat="1.0 0.0 0.0 0.0"/>
          <geom class="collision" type="box" pos="-0.26286417 0.19360924 -0.10904942" size="0.0040656449273228645 0.06208665668964386 0.018752997741103172" quat="1.0 0.0 0.0 0.0"/>
          <geom class="collision" type="box" pos="-0.08829404 0.02308297 -0.14398267" size="0.0006814482621848583 0.006419182289391756 0.004163840319961309" quat="1.0 0.0 0.0 0.0"/>
          <geom class="collision" type="box" pos="-0.26286417 0.10974296 -0.10904942" size="0.004065647721290588 0.018582165241241455 0.018753010779619217" quat="1.0 0.0 0.0 0.0"/>
          <geom class="collision" type="box" pos="-0.26286417 0.06417835 -0.10904942" size="0.00406564911827445 0.02429361455142498 0.018753016367554665" quat="1.0 0.0 0.0 0.0"/>
          <geom class="collision" type="box" pos="-0.26286417 0.02140599 -0.10904942" size="0.004065650515258312 0.016424521803855896 0.018753021955490112" quat="1.0 0.0 0.0 0.0"/>
          <geom class="collision" type="box" pos="-0.26670945 0.10134265 -0.11018511" size="0.004658401012420654 0.1479371339082718 0.0018877197289839387" quat="1.0 0.0 0.0 0.0"/>
          <geom class="collision" type="box" pos="-0.26386875 -0.02690836 -0.09800271" size="0.0007411208935081959 0.007917576469480991 0.007178305182605982" quat="1.0 0.0 0.0 0.0"/>
          <geom class="collision" type="box" pos="-0.26632199 0.11469522 -0.09800271" size="0.0031942797359079123 0.1345922350883484 0.007178306579589844" quat="1.0 0.0 0.0 0.0"/>
          <geom class="collision" type="box" pos="-0.26632199 -0.03862339 -0.09800271" size="0.003194280434399843 0.007917582057416439 0.007178307976573706" quat="1.0 0.0 0.0 0.0"/>
          <geom class="collision" type="box" pos="-0.26632199 0.10136647 -0.10696460" size="0.003194281132891774 0.1479010283946991 0.0024129569064825773" quat="1.0 0.0 0.0 0.0"/>
          <geom class="collision" type="box" pos="-0.26632199 0.10136647 -0.08902053" size="0.003194281831383705 0.14790107309818268 0.0024129576049745083" quat="1.0 0.0 0.0 0.0"/>
          <geom class="collision" type="box" pos="-0.26274502 0.08270192 -0.06885890" size="0.0042391689494252205 0.17304284870624542 0.0018912492087110877" quat="1.0 0.0 0.0 0.0"/>
          <geom class="collision" type="box" pos="-0.08394356 0.02308297 -0.14755120" size="0.004006793722510338 0.006419182755053043 0.0005324396188370883" quat="1.0 0.0 0.0 0.0"/>
          <geom class="collision" type="box" pos="-0.26731455 0.10136647 -0.08510555" size="0.004186734557151794 0.14790120720863342 0.0017828952986747026" quat="1.0 0.0 0.0 0.0"/>
          <geom class="collision" type="box" pos="-0.26724866 -0.04786528 -0.09581838" size="0.005197616294026375 0.0016182592371478677 0.013074979186058044" quat="1.0 0.0 0.0 0.0"/>
          <geom class="collision" type="box" pos="-0.26724866 -0.04438775 -0.11026179" size="0.005197617691010237 0.00509563647210598 0.0018110392848029733" quat="1.0 0.0 0.0 0.0"/>
          <geom class="collision" type="box" pos="-0.26701790 -0.04438775 -0.08228123" size="0.005428381264209747 0.005095637869089842 0.0014640262816101313" quat="1.0 0.0 0.0 0.0"/>
          <geom class="collision" type="box" pos="-0.26048613 -0.08031923 -0.10745059" size="0.001617505680769682 0.01030249334871769 0.03694046661257744" quat="1.0 0.0 0.0 0.0"/>
          <geom class="collision" type="box" pos="-0.26045099 0.09256986 -0.08043865" size="0.0016526503022760153 0.16317521035671234 0.00992974080145359" quat="1.0 0.0 0.0 0.0"/>
          <geom class="collision" type="box" pos="-0.00507184 -0.13846746 -0.15294902" size="0.03811417520046234 0.006508534774184227 0.004481990821659565" quat="1.0 0.0 0.0 0.0"/>
          <geom class="collision" type="box" pos="-0.00507184 -0.14310893 -0.15940380" size="0.03811417520046234 0.006508534774184227 0.010936778038740158" quat="1.0 0.0 0.0 0.0"/>
          <geom class="collision" type="box" pos="-0.02832828 0.07346234 -0.17542528" size="0.19184672832489014 0.012827771715819836 0.005360372830182314" quat="1.0 0.0 0.0 0.0"/>
          <geom class="collision" type="box" pos="-0.06689170 -0.11968148 -0.15288420" size="0.013266862370073795 0.006309157703071833 0.002024671994149685" quat="1.0 0.0 0.0 0.0"/>
          <geom class="collision" type="box" pos="-0.07983516 0.02308297 -0.14929544" size="0.0009215290774591267 0.006419182289391756 0.002024671994149685" quat="1.0 0.0 0.0 0.0"/>
          <geom class="collision" type="box" pos="-0.07983516 -0.11965042 -0.14929544" size="0.0009215290774591267 0.006419182289391756 0.002024671994149685" quat="1.0 0.0 0.0 0.0"/>
          <geom class="collision" type="box" pos="-0.08394356 -0.11965042 -0.14755120" size="0.004006793722510338 0.006419182755053043 0.0005324396188370883" quat="1.0 0.0 0.0 0.0"/>
          <geom class="collision" type="box" pos="-0.08829404 -0.11965042 -0.14398267" size="0.0006814482621848583 0.006419182289391756 0.004163840319961309" quat="1.0 0.0 0.0 0.0"/>
          <geom class="collision" type="box" pos="-0.04980827 -0.11948535 -0.15690895" size="0.013340570963919163 0.006175429094582796 0.006049413233995438" quat="1.0 0.0 0.0 0.0"/>
          <geom class="collision" type="box" pos="-0.04980827 -0.08592123 -0.15690895" size="0.013340570963919163 0.006175429560244083 0.006049413233995438" quat="1.0 0.0 0.0 0.0"/>
          <geom class="collision" type="box" pos="-0.08829404 -0.08608630 -0.14398267" size="0.0006814482621848583 0.006419182289391756 0.004163840319961309" quat="1.0 0.0 0.0 0.0"/>
          <geom class="collision" type="box" pos="-0.08394356 -0.08608630 -0.14755120" size="0.004006793722510338 0.006419182755053043 0.0005324396188370883" quat="1.0 0.0 0.0 0.0"/>
          <geom class="collision" type="box" pos="-0.07983516 -0.08608630 -0.14929544" size="0.0009215290774591267 0.006419182289391756 0.002024671994149685" quat="1.0 0.0 0.0 0.0"/>
          <geom class="collision" type="box" pos="-0.06689170 -0.08611735 -0.15288420" size="0.013266862370073795 0.006309157703071833 0.002024671994149685" quat="1.0 0.0 0.0 0.0"/>
          <geom class="collision" type="box" pos="-0.06689170 -0.03452841 -0.15288420" size="0.013266862370073795 0.006309156771749258 0.002024671994149685" quat="1.0 0.0 0.0 0.0"/>
          <geom class="collision" type="box" pos="-0.06689170 0.02305192 -0.15288420" size="0.013266862370073795 0.006309156771749258 0.002024671994149685" quat="1.0 0.0 0.0 0.0"/>
        </body>
        <body name="rack1">
          <geom class="region" name="reg_rack1" type="box" pos="0.00013159000000000087 0.03045771 0.268502315" size="0.2439689 0.193309 0.13629110500000002"/>
          <joint axis="0.0 -1.0 0.0" pos="0.00002422 0.03081315 0.17890155" limited="true" name="rack1_joint" range="0.0 0.285" type="slide" damping="1" frictionloss="1" armature=".01" stiffness="0.05"/>
          <geom mesh="rack1_vis" type="mesh" solimp="0.998 0.998 0.001" solref="0.001 1" friction="0.95 0.3 0.1" class="visual" material="rack1_material"/>
          <!-- <geom class="collision" type="box" pos="-0.07983516 -0.03449736 0.11359059" size="0.0009215290774591267 0.006419182289391756 0.002024671994149685" quat="1.0 0.0 0.0 0.0"/>
          <geom class="collision" type="box" pos="-0.08394356 -0.03449736 0.11533483" size="0.004006793722510338 0.006419182755053043 0.0005324396188370883" quat="1.0 0.0 0.0 0.0"/>
          <geom class="collision" type="box" pos="-0.15429580 -0.05028968 0.14593790" size="0.09347943216562271 0.002516882959753275 0.04563521966338158" quat="0.09089885652065277 0.7012399435043335 0.7012398838996887 0.09089892357587814"/>
          <geom class="collision" type="box" pos="-0.08175866 0.13373846 0.16290715" size="0.09813521057367325 0.002516882959753275 0.04563521593809128" quat="0.09341192990541458 -0.7009094953536987 -0.7009096145629883 0.0934118703007698"/>
          <geom class="collision" type="box" pos="0.05957322 0.03249620 0.16058777" size="0.17156313359737396 0.002516882261261344 0.04563521593809128" quat="0.09341192990541458 -0.7009094953536987 -0.7009096145629883 0.0934118703007698"/>  
          <geom class="collision" type="box" pos="0.19291317 0.05567762 0.14039200" size="0.1869610697031021 0.002516882959753275 0.04670282453298569" quat="0.1831398904323578 0.6829785704612732 0.682978630065918 0.18313990533351898"/>-->
          <geom class="collision" type="box" pos="0.23743968 0.04642402 0.09862126" size="0.02297084592282772 0.21412509679794312 0.0026653469540178776" quat="1.0 0.0 0.0 0.0"/>
          <geom class="collision" type="box" pos="0.20172393 0.04642401 0.10786916" size="0.21413519978523254 0.0025168831925839186 0.028035128489136696" quat="0.3555333912372589 0.6112250089645386 0.6112250089645386 0.3555334210395813"/>
          <geom class="collision" type="box" pos="0.15079363 0.04642402 0.10793665" size="0.21413518488407135 0.0025168827269226313 0.021187733858823776" quat="0.6499353051185608 0.27853918075561523 0.2785392105579376 0.6499353051185608"/>
          <geom class="collision" type="box" pos="0.11886489 0.04642401 0.10681103" size="0.21413519978523254 0.0025168831925839186 0.025858500972390175" quat="0.4052272140979767 0.579474687576294 0.579474687576294 0.4052272439002991"/>
          <geom class="collision" type="box" pos="0.00046990 0.04594428 0.11532688" size="0.09508420526981354 0.214604914188385 0.002690724330022931" quat="1.0 0.0 0.0 0.0"/>
          <geom class="collision" type="box" pos="-0.11756045 0.04642401 0.10700753" size="0.21413519978523254 0.0025168831925839186 0.0251455157995224" quat="0.5795987844467163 0.4050496518611908 0.4050496816635132 0.5795987844467163"/>
          <geom class="collision" type="box" pos="-0.04980827 0.02324805 0.10597709" size="0.013340570963919163 0.006175429560244083 0.006049413233995438" quat="1.0 0.0 0.0 0.0"/>
          <geom class="collision" type="box" pos="-0.15019727 0.04642402 0.10795085" size="0.21413518488407135 0.0025168827269226313 0.02121863141655922" quat="0.279901921749115 0.649349570274353 0.6493496298789978 0.27990207076072693"/>
          <geom class="collision" type="box" pos="-0.19848835 0.04642401 0.10901059" size="0.21413519978523254 0.0025168827269226313 0.026395291090011597" quat="0.6152599453926086 0.34850409626960754 0.3485041558742523 0.6152600646018982"/>
          <geom class="collision" type="box" pos="-0.23729941 0.04642401 0.09921794" size="0.02313978597521782 0.2141253501176834 0.0025168205611407757" quat="1.0 0.0 0.0 0.0"/>
          <geom class="collision" type="box" pos="0.25803608 0.04642397 0.18699518" size="0.006678314413875341 0.21412542462348938 0.08801014721393585" quat="1.0 0.0 0.0 0.0"/>
          <geom class="collision" type="box" pos="-0.00009505 -0.17338634 0.18699518" size="0.26340070366859436 0.004776628687977791 0.08801019191741943" quat="1.0 0.0 0.0 0.0"/>
          <geom class="collision" type="box" pos="-0.25970617 0.04642401 0.18699518" size="0.005329441279172897 0.2141255885362625 0.08801022917032242" quat="1.0 0.0 0.0 0.0"/>
          <geom class="collision" type="box" pos="0.16230601 0.25682986 0.18699518" size="0.09589095413684845 0.005256335251033306 0.088010273873806" quat="1.0 0.0 0.0 0.0"/>
          <geom class="collision" type="box" pos="0.05490205 0.24349350 0.19196136" size="0.018606767058372498 0.005256484728306532 0.08341021835803986" quat="0.3173389434814453 0.0 -0.0 -0.9483121633529663"/>
          <geom class="collision" type="box" pos="-0.00184746 0.23558646 0.18699518" size="0.044936541467905045 0.004207872319966555 0.08801031112670898" quat="1.0 0.0 0.0 0.0"/>
          <geom class="collision" type="box" pos="-0.05877124 0.24720354 0.19196136" size="0.018606767058372498 0.005256484728306532 0.08341021835803986" quat="0.9204282760620117 0.0 -0.0 -0.3909115195274353"/>
          <geom class="collision" type="box" pos="-0.08829404 -0.03449736 0.11890337" size="0.0006814482621848583 0.006419182289391756 0.004163840319961309" quat="1.0 0.0 0.0 0.0"/>
          <geom class="collision" type="box" pos="-0.16545722 0.25682986 0.18699518" size="0.0958910807967186 0.005256338976323605 0.08801039308309555" quat="1.0 0.0 0.0 0.0"/>
          <geom class="collision" type="box" pos="-0.02890452 0.04324955 0.10378331" size="0.009459958411753178 0.18434371054172516 0.009459900669753551" quat="1.0 0.0 0.0 0.0"/>
          <geom class="collision" type="box" pos="0.26040110 0.09256986 0.18244737" size="0.001652661245316267 0.16317661106586456 0.009929828345775604" quat="1.0 0.0 0.0 0.0"/>
          <geom class="collision" type="box" pos="0.26043624 -0.08031923 0.15543544" size="0.0016175173223018646 0.010302586480975151 0.036940839141607285" quat="1.0 0.0 0.0 0.0"/>
          <geom class="collision" type="box" pos="0.26696804 -0.04438775 0.18060480" size="0.005428431089967489 0.0050956872291862965 0.001464038621634245" quat="1.0 0.0 0.0 0.0"/>
          <geom class="collision" type="box" pos="0.26719877 -0.04438775 0.15262423" size="0.005197669845074415 0.005095688626170158 0.0018110523233190179" quat="1.0 0.0 0.0 0.0"/>
          <geom class="collision" type="box" pos="0.26719877 -0.04786528 0.16706764" size="0.005197671242058277 0.0016182729741558433 0.013075090013444424" quat="1.0 0.0 0.0 0.0"/>
          <geom class="collision" type="box" pos="0.26726469 0.10136647 0.17778048" size="0.004186792764812708 0.14790306985378265 0.0017829097341746092" quat="1.0 0.0 0.0 0.0"/>
          <geom class="collision" type="box" pos="0.26431802 0.08270192 0.19428241" size="0.005862092133611441 0.1730448305606842 0.0021465157624334097" quat="1.0 0.0 0.0 0.0"/>
          <geom class="collision" type="box" pos="0.26627210 0.10136647 0.17386549" size="0.0031943144276738167 0.14790315926074982 0.00241299020126462" quat="1.0 0.0 0.0 0.0"/>
          <geom class="collision" type="box" pos="-0.04980827 -0.03433228 0.10597709" size="0.013340570963919163 0.006175429560244083 0.006049413233995438" quat="1.0 0.0 0.0 0.0"/>
          <geom class="collision" type="box" pos="0.26627210 0.10136647 0.15592143" size="0.0031943158246576786 0.14790324866771698 0.0024129915982484818" quat="1.0 0.0 0.0 0.0"/>
          <geom class="collision" type="box" pos="0.26627210 -0.03862338 0.16488331" size="0.0031943165231496096 0.007917726412415504 0.007178380154073238" quat="1.0 0.0 0.0 0.0"/>
          <geom class="collision" type="box" pos="0.26627210 0.11469522 0.16488331" size="0.0031943172216415405 0.1345946341753006 0.0071783815510571" quat="1.0 0.0 0.0 0.0"/>
          <geom class="collision" type="box" pos="0.26381886 -0.02690836 0.16488331" size="0.0007411306141875684 0.007917732000350952 0.007178382948040962" quat="1.0 0.0 0.0 0.0"/>
          <geom class="collision" type="box" pos="0.26688278 0.10134265 0.15270091" size="0.004881655797362328 0.14793971180915833 0.0018877398688346148" quat="1.0 0.0 0.0 0.0"/>
          <geom class="collision" type="box" pos="0.26283953 0.02140599 0.15383660" size="0.004090945236384869 0.01642485521733761 0.018753355368971825" quat="1.0 0.0 0.0 0.0"/>
          <geom class="collision" type="box" pos="0.26283953 0.06417835 0.15383660" size="0.004090947099030018 0.024293959140777588 0.018753360956907272" quat="1.0 0.0 0.0 0.0"/>
          <geom class="collision" type="box" pos="0.26283953 0.10974296 0.15383660" size="0.00409094849601388 0.018582521006464958 0.01875336654484272" quat="1.0 0.0 0.0 0.0"/>
          <geom class="collision" type="box" pos="0.26283953 0.19360924 0.15383660" size="0.004090949892997742 0.06208740547299385 0.018753372132778168" quat="1.0 0.0 0.0 0.0"/>
          <geom class="collision" type="box" pos="-0.26286417 0.19360924 0.15383660" size="0.004065739456564188 0.062087416648864746 0.018753377720713615" quat="1.0 0.0 0.0 0.0"/>
          <geom class="collision" type="box" pos="-0.08829404 0.02308297 0.11890337" size="0.0006814482621848583 0.006419182289391756 0.004163840319961309" quat="1.0 0.0 0.0 0.0"/>
          <geom class="collision" type="box" pos="-0.26286417 0.10974296 0.15383660" size="0.004065742250531912 0.018582545220851898 0.01875338889658451" quat="1.0 0.0 0.0 0.0"/>
          <geom class="collision" type="box" pos="-0.26286417 0.06417835 0.15383660" size="0.004065743647515774 0.024293994531035423 0.01875339448451996" quat="1.0 0.0 0.0 0.0"/>
          <geom class="collision" type="box" pos="-0.26286417 0.02140599 0.15383660" size="0.004065745044499636 0.01642490178346634 0.018753400072455406" quat="1.0 0.0 0.0 0.0"/>
          <geom class="collision" type="box" pos="-0.26670945 0.10134265 0.15270091" size="0.004658495541661978 0.14794015884399414 0.0018877433612942696" quat="1.0 0.0 0.0 0.0"/>
          <geom class="collision" type="box" pos="-0.26386875 -0.02690836 0.16488331" size="0.0007411327096633613 0.007917765527963638 0.007178399711847305" quat="1.0 0.0 0.0 0.0"/>
          <geom class="collision" type="box" pos="-0.26632199 0.11469522 0.16488331" size="0.003194327000528574 0.13459526002407074 0.007178401108831167" quat="1.0 0.0 0.0 0.0"/>
          <geom class="collision" type="box" pos="-0.26632199 -0.03862339 0.16488331" size="0.003194327699020505 0.007917771115899086 0.007178402505815029" quat="1.0 0.0 0.0 0.0"/>
          <geom class="collision" type="box" pos="-0.26632199 0.10136647 0.15592143" size="0.0031943286303430796 0.14790405333042145 0.002413004171103239" quat="1.0 0.0 0.0 0.0"/>
          <geom class="collision" type="box" pos="-0.26632199 0.10136647 0.17386549" size="0.0031943293288350105 0.14790409803390503 0.00241300486959517" quat="1.0 0.0 0.0 0.0"/>
          <geom class="collision" type="box" pos="-0.26274502 0.08270192 0.19402712" size="0.004239263478666544 0.17304587364196777 0.0018912728410214186" quat="1.0 0.0 0.0 0.0"/>
          <geom class="collision" type="box" pos="-0.08394356 0.02308297 0.11533483" size="0.004006793722510338 0.006419182755053043 0.0005324396188370883" quat="1.0 0.0 0.0 0.0"/>
          <geom class="collision" type="box" pos="-0.26731455 0.10136647 0.17778048" size="0.004186829552054405 0.14790423214435577 0.0017829189309850335" quat="1.0 0.0 0.0 0.0"/>
          <geom class="collision" type="box" pos="-0.26724866 -0.04786528 0.16706764" size="0.005197710823267698 0.0016182828694581985 0.013075169175863266" quat="1.0 0.0 0.0 0.0"/>
          <geom class="collision" type="box" pos="-0.26724866 -0.04438775 0.15262423" size="0.00519771222025156 0.005095731001347303 0.0018110629171133041" quat="1.0 0.0 0.0 0.0"/>
          <geom class="collision" type="box" pos="-0.26701790 -0.04438775 0.18060480" size="0.005428476259112358 0.005095732398331165 0.0014640499139204621" quat="1.0 0.0 0.0 0.0"/>
          <geom class="collision" type="box" pos="-0.26048613 -0.08031923 0.15543544" size="0.0016175293130800128 0.010302682407200336 0.036941222846508026" quat="1.0 0.0 0.0 0.0"/>
          <geom class="collision" type="box" pos="-0.26045099 0.09256986 0.18244737" size="0.0016526739345863461 0.1631782352924347 0.009929929859936237" quat="1.0 0.0 0.0 0.0"/>
          <geom class="collision" type="box" pos="-0.00507184 -0.13846746 0.10993702" size="0.03811417520046234 0.006508534774184227 0.004481990821659565" quat="1.0 0.0 0.0 0.0"/>
          <geom class="collision" type="box" pos="-0.00507184 -0.14310893 0.10348223" size="0.03811417520046234 0.006508534774184227 0.010936778038740158" quat="1.0 0.0 0.0 0.0"/>
          <geom class="collision" type="box" pos="-0.02832828 0.07346234 0.08746075" size="0.19184672832489014 0.012827771715819836 0.005360372830182314" quat="1.0 0.0 0.0 0.0"/>
          <geom class="collision" type="box" pos="-0.06689170 -0.11968148 0.11000183" size="0.013266862370073795 0.006309157703071833 0.002024671994149685" quat="1.0 0.0 0.0 0.0"/>
          <geom class="collision" type="box" pos="-0.07983516 0.02308297 0.11359059" size="0.0009215290774591267 0.006419182289391756 0.002024671994149685" quat="1.0 0.0 0.0 0.0"/>
          <geom class="collision" type="box" pos="-0.07983516 -0.11965042 0.11359059" size="0.0009215290774591267 0.006419182289391756 0.002024671994149685" quat="1.0 0.0 0.0 0.0"/>
          <geom class="collision" type="box" pos="-0.08394356 -0.11965042 0.11533483" size="0.004006793722510338 0.006419182755053043 0.0005324396188370883" quat="1.0 0.0 0.0 0.0"/>
          <geom class="collision" type="box" pos="-0.08829404 -0.11965042 0.11890337" size="0.0006814482621848583 0.006419182289391756 0.004163840319961309" quat="1.0 0.0 0.0 0.0"/>
          <geom class="collision" type="box" pos="-0.04980827 -0.11948535 0.10597709" size="0.013340570963919163 0.006175429094582796 0.006049413233995438" quat="1.0 0.0 0.0 0.0"/>
          <geom class="collision" type="box" pos="-0.04980827 -0.08592123 0.10597709" size="0.013340570963919163 0.006175429560244083 0.006049413233995438" quat="1.0 0.0 0.0 0.0"/>
          <geom class="collision" type="box" pos="-0.08829404 -0.08608630 0.11890337" size="0.0006814482621848583 0.006419182289391756 0.004163840319961309" quat="1.0 0.0 0.0 0.0"/>
          <geom class="collision" type="box" pos="-0.08394356 -0.08608630 0.11533483" size="0.004006793722510338 0.006419182755053043 0.0005324396188370883" quat="1.0 0.0 0.0 0.0"/>
          <geom class="collision" type="box" pos="-0.07983516 -0.08608630 0.11359059" size="0.0009215290774591267 0.006419182289391756 0.002024671994149685" quat="1.0 0.0 0.0 0.0"/>
          <geom class="collision" type="box" pos="-0.06689170 -0.08611735 0.11000183" size="0.013266862370073795 0.006309157703071833 0.002024671994149685" quat="1.0 0.0 0.0 0.0"/>
          <geom class="collision" type="box" pos="-0.06689170 -0.03452841 0.11000183" size="0.013266862370073795 0.006309156771749258 0.002024671994149685" quat="1.0 0.0 0.0 0.0"/>
          <geom class="collision" type="box" pos="-0.06689170 0.02305192 0.11000183" size="0.013266862370073795 0.006309156771749258 0.002024671994149685" quat="1.0 0.0 0.0 0.0"/>
        </body>
        <geom class="region" name="reg_int" type="box" pos="-0.0006453999999999904 0.06174253499999999 0.079082785" size="0.25807358 0.236694925 0.324919775"/>
        <geom class="region" name="reg_main" type="box" pos="-4.999999997368221e-09 0.03326318 -0.002541155000000017" size="0.302625075 0.28879957 0.448911145"/>
      </body>
    </body>
  </worldbody>
  <actuator>
    <motor name="door_joint_actuator" joint="door_joint" gear="50"/>
    <motor name="rack0_joint_actuator" joint="rack0_joint" gear="50"/>
    <motor name="rack1_joint_actuator" joint="rack1_joint" gear="50"/>
    <motor name="button_lock_joint_actuator" joint="button_lock_joint" gear="0.5"/>
    <motor name="button_power_joint_actuator" joint="button_power_joint" gear="0.5"/>
  </actuator>
</mujoco>