<?xml version='1.0' encoding='UTF-8'?>
<mujoco model="model">
  <option timestep="0.002" gravity="0.0 0.0 -9.81"/>
  <compiler angle="radian"/>
  <asset>
    <mesh file="visuals/door.obj" name="door_vis"/>
    <mesh file="visuals/knob_function.obj" name="knob_function_vis"/>
    <mesh file="visuals/knob_temp.obj" name="knob_temp_vis"/>
    <mesh file="visuals/knob_time.obj" name="knob_time_vis"/>
    <mesh file="visuals/rack0.obj" name="rack0_vis"/>
    <mesh file="visuals/Body001.obj" name="Body001_vis"/>
    <mesh file="visuals/window.obj" name="window_vis"/>
    <texture file="visuals/T_BC001.png" name="Body001_material" type="2d"/>
    <material name="Body001_material" rgba="1 1 1 1.0" texture="Body001_material" shininess="0.4472135901451111" specular="1"/>
    <texture file="visuals/T_BC001.png" name="door_material" type="2d"/>
    <material name="door_material" rgba="1 1 1 1.0" texture="door_material" shininess="0.4472135901451111" specular="1"/>
    <texture file="visuals/T_BC001.png" name="window_material" type="2d"/>
    <material name="window_material" rgba="1 1 1 0.7874016165733337" texture="window_material" shininess="0.4472135901451111" specular="0.3103448502657381"/>
    <texture file="visuals/T_BC001.png" name="knob_function_material" type="2d"/>
    <material name="knob_function_material" rgba="1 1 1 1.0" texture="knob_function_material" shininess="0.4472135901451111" specular="0.3103448502657381"/>
    <texture file="visuals/T_BC001.png" name="knob_temp_material" type="2d"/>
    <material name="knob_temp_material" rgba="1 1 1 1.0" texture="knob_temp_material" shininess="0.4472135901451111" specular="0.3103448502657381"/>
    <texture file="visuals/T_BC001.png" name="knob_time_material" type="2d"/>
    <material name="knob_time_material" rgba="1 1 1 1.0" texture="knob_time_material" shininess="0.4472135901451111" specular="0.3103448502657381"/>
    <texture file="visuals/T_BC001.png" name="rack0_material" type="2d"/>
    <material name="rack0_material" rgba="1 1 1 1.0" texture="rack0_material" shininess="0.4472135901451111" specular="2"/>
  </asset>
  <default>
    <default class="visual">
      <geom conaffinity="0" contype="0" group="1" type="mesh"/>
    </default>
    <default class="collision">
      <geom group="0" rgba="0.5 0 0 0.5"/>
    </default>
    <default class="spawn">
      <geom group="0" rgba="1 1 1 0.5" contype="0" conaffinity="0"/>
      <site group="0" rgba="1 1 1 0.5"/>
    </default>
    <default class="region">
      <geom group="1" conaffinity="0" contype="0" rgba="0 1 0 0"/>
    </default>
  </default>
  <worldbody>
    <body>
      <body name="object">
        <geom mesh="Body001_vis" type="mesh" solimp="0.998 0.998 0.001" solref="0.001 1" friction="0.95 0.3 0.1" class="visual" material="Body001_material"/>
        <geom class="collision" type="box" pos="-0.15014806389808655 0.03225326165556908 0.007988776080310345" size="0.01095607504248619 0.12452957034111023 0.15582062304019928" quat="1.0 0.0 0.0 0.0"/>
        <geom class="collision" type="box" pos="0.15014807879924774 0.03225326165556908 0.007988776080310345" size="0.010956059210002422 0.12452957034111023 0.15582062304019928" quat="1.0 0.0 0.0 0.0"/>
        <geom class="collision" type="box" pos="0.00037354338564909995 0.03225326165556908 -0.14459064602851868" size="0.15582062304019928 0.12452957034111023 0.029636377468705177" quat="1.0 0.0 0.0 0.0"/>
        <geom class="collision" type="box" pos="0.0003735424834303558 0.02025252766907215 0.11629744619131088" size="0.15582062304019928 0.1365303099155426 0.05007728934288025" quat="1.0 0.0 0.0 0.0"/>
        <geom class="collision" type="box" pos="-0.003032587468624115 0.1421884149312973 0.007988776080310345" size="0.1524145007133484 0.014594434760510921 0.15582062304019928" quat="1.0 0.0 0.0 0.0"/>
        <geom class="collision" type="cylinder" pos="-0.1104695200920105 -0.04687829315662384 0.16864657402038574" size="0.015137218870222569 0.005071556195616722" quat="1.0 0.0 0.0 0.0"/>
        <geom class="collision" type="box" pos="0.00037354344385676086 0.03225326165556908 0.08603633940219879" size="0.15582062304019928 0.12452957034111023 0.02958161011338234" quat="1.0 0.0 0.0 0.0"/>
        <geom class="collision" type="box" pos="0.13413213193416595 0.030581790953874588 -0.034753818064928055" size="0.012300267815589905 0.0830044224858284 0.002318410435691476" quat="1.0 0.0 0.0 0.0"/>
        <geom class="collision" type="box" pos="-0.1335434913635254 0.030581790953874588 -0.034753818064928055" size="0.012300270609557629 0.08300444483757019 0.002318410901352763" quat="1.0 0.0 0.0 0.0"/>
        <body name="door">
          <joint axis="1.0 0.0 0.0" pos="-0.0002447452279739082 -0.09181776642799377 -0.14766952395439148" limited="true" name="door_joint" range="0.0 1.3707963267948966" type="hinge" damping="1" frictionloss="1" armature=".01" stiffness="1" springref="-2"/>
          <geom mesh="door_vis" type="mesh" solimp="0.998 0.998 0.001" solref="0.001 1" friction="0.95 0.3 0.1" class="visual" material="door_material"/>
          <geom class="collision" type="box" pos="-0.0002530446508899331 -0.10681606829166412 -0.04308674484491348" size="0.15938039124011993 0.007766919210553169 0.09968185424804688" quat="1.0 0.0 0.0 0.0" name="door_main"/>
          <geom class="collision" type="box" pos="-0.002028370974585414 -0.15088653564453125 0.0458734966814518" size="0.12011595070362091 0.005527830217033625 0.005527830217033625" quat="1.0 0.0 0.0 0.0" name="door_handle_main"/>
          <geom class="collision" type="box" pos="0.12467844784259796 -0.1301622986793518 0.0458734966814518" size="0.005527839530259371 0.01422300934791565 0.005527830217033625" quat="1.0 0.0 0.0 0.0"/>
          <geom class="collision" type="box" pos="-0.12602689862251282 -0.1301622986793518 0.0458734966814518" size="0.005527839530259371 0.01422300934791565 0.005527830217033625" quat="1.0 0.0 0.0 0.0"/>
          <body name="window">
            <geom mesh="window_vis" type="mesh" solimp="0.998 0.998 0.001" solref="0.001 1" friction="0.95 0.3 0.1" class="visual" material="window_material"/>
            <geom class="collision" type="box" pos="-6.950646638870239e-05 -0.10270194709300995 -0.03836246207356453" size="0.12502355873584747 0.0007287650369107723 0.06635313481092453" quat="1.0 0.0 0.0 0.0"/>
          </body>
        </body>
        <body name="knob_function">
          <joint axis="0.0 1.0 0.0" pos="0.09242938458919525 -0.1250920593738556 0.11093008518218994" limited="true" name="knob_function_joint" range="0.0 3.141592653589793" type="hinge" damping="0.05" armature="0.001"/>
          <geom mesh="knob_function_vis" type="mesh" solimp="0.998 0.998 0.001" solref="0.001 1" friction="0.95 0.3 0.1" class="visual" material="knob_function_material"/>
          <geom class="collision" type="cylinder" pos="0.09248964488506317 -0.1199907511472702 0.11097143590450287" size="0.01761051081120968 0.0027485794853419065" quat="0.7071067094802856 0.7071068286895752 0.0 0.0"/>
          <geom class="collision" type="box" pos="0.0924294963479042 -0.12741884589195251 0.11086548119783401" size="0.0030167505610734224 0.005303218029439449 0.00994835700839758" quat="0.6227676868438721 0.0 0.7824068069458008 0.0" name="knob_function_main"/>
        </body>
        <body name="knob_temp">
          <joint axis="0.0 1.0 0.0" pos="-0.0007955371984280646 -0.1250920593738556 0.11092999577522278" limited="true" name="knob_temp_joint" range="0.0 3.2288591161895095" type="hinge" damping="0.05" armature="0.001"/>
          <geom mesh="knob_temp_vis" type="mesh" solimp="0.998 0.998 0.001" solref="0.001 1" friction="0.95 0.3 0.1" class="visual" material="knob_temp_material"/>
          <geom class="collision" type="cylinder" pos="-0.0009866959881037474 -0.1199907511472702 0.11097143590450287" size="0.01761051081120968 0.0027485794853419065" quat="0.7071067094802856 0.7071068286895752 0.0 0.0"/>
          <geom class="collision" type="box" pos="-0.000777900218963623 -0.12741884589195251 0.11086548119783401" size="0.009948354214429855 0.005303217098116875 0.0030167503282427788" quat="1.0 0.0 0.0 0.0" name="knob_temp_main"/>
        </body>
        <body name="knob_time">
          <joint axis="0.0 1.0 0.0" pos="-0.091954305768013 -0.1250920593738556 0.11093045771121979" limited="true" name="knob_time_joint" range="0.0 4.014257279586958" type="hinge" damping="0.05" frictionloss="0.1" armature="0.001"/>
          <geom mesh="knob_time_vis" type="mesh" solimp="0.998 0.998 0.001" solref="0.001 1" friction="0.95 0.3 0.1" class="visual" material="knob_time_material"/>
          <geom class="collision" type="cylinder" pos="-0.09187865257263184 -0.1199907511472702 0.11097143590450287" size="0.01761051081120968 0.0027485794853419065" quat="0.7071067094802856 0.7071068286895752 0.0 0.0" density="0.001"/>
          <geom class="collision" type="box" pos="-0.09196415543556213 -0.12741884589195251 0.1105961799621582" size="0.003016749396920204 0.0053032161667943 0.009948352351784706" quat="1.0 0.0 0.0 0.0" name="knob_time_main" density="0.001"/>
        </body>
        <body name="rack0">
          <geom class="region" name="reg_rack0" type="box" pos="0.0007556155323982239 0.019857779145240784 0.010057561099529266" size="0.10514926707744598 0.09526365047693253 0.04629280960559845"/>
          <joint axis="0.0 -1.0 0.0" pos="0.007002250291407108 0.019703805446624756 -0.036553241312503815" limited="true" name="rack0_joint" range="0.0 0.15" type="slide" damping="1" frictionloss="1" armature=".01" stiffness="0.05"/>
          <geom mesh="rack0_vis" type="mesh" solimp="0.998 0.998 0.001" solref="0.001 1" friction="0.95 0.3 0.1" class="visual" material="rack0_material"/>
          <geom class="collision" type="box" pos="0.00039822518010623753 0.0192455742508173 -0.03828849270939827" size="0.10529593378305435 0.09590399265289307 0.002356566721573472" quat="1.0 0.0 0.0 0.0"/>
          <geom class="collision" type="box" pos="-0.11944076418876648 0.01918330043554306 -0.030751248821616173" size="0.006655312608927488 0.09602116793394089 0.0012939152074977756" quat="1.0 0.0 0.0 0.0"/>
          <geom class="collision" type="box" pos="-0.10865580290555954 0.019178202375769615 -0.03446810320019722" size="0.00665531400591135 0.09602617472410202 0.0012939026346430182" quat="0.9440328478813171 -2.0632491271044273e-08 0.3298514783382416 7.209132402152818e-09"/>
          <geom class="collision" type="box" pos="0.10940202325582504 0.019178202375769615 -0.03446810692548752" size="0.00665531400591135 0.09602617472410202 0.0012939037987962365" quat="7.127249546101666e-08 -0.9440328478813171 -2.4903092921135794e-08 -0.3298514783382416"/>
          <geom class="collision" type="box" pos="0.11957360059022903 0.01918330043554306 -0.030751248821616173" size="0.006655312608927488 0.09602116793394089 0.001293914276175201" quat="1.0 0.0 0.0 0.0"/>
        </body>
        <geom class="region" name="reg_main" type="box" pos="0.0 0.020252518355846405 -1.862645149230957e-08" size="0.16210414266586304 0.1375303248167038 0.1752270141839981"/>
      </body>
    </body>
  </worldbody>
  <actuator>
    <motor name="door_joint_actuator" joint="door_joint" gear="50"/>
    <motor name="knob_function_joint_actuator" joint="knob_function_joint" gear="50"/>
    <motor name="knob_temp_joint_actuator" joint="knob_temp_joint" gear="50"/>
    <motor name="knob_time_joint_actuator" joint="knob_time_joint" gear="50"/>
    <motor name="rack0_joint_actuator" joint="rack0_joint" gear="50"/>
  </actuator>
</mujoco>
