<?xml version='1.0' encoding='UTF-8'?>
<mujoco model="model">
  <option timestep="0.002" gravity="0.0 0.0 -9.81"/>
  <compiler angle="radian"/>
  <asset>
    <mesh file="visuals/door.obj" name="door_vis"/>
    <mesh file="visuals/door_Clear.obj" name="door_Clear_vis"/>
    <mesh file="visuals/Body001.obj" name="Body001_vis"/>
    <mesh file="visuals/Disc001.obj" name="Disc001_vis"/>
    <texture file="visuals/T_BC001.png" name="Body001_material" type="2d"/>
    <material name="Body001_material" rgba="1 1 1 1.0" texture="Body001_material" shininess="0.1" specular="5"/>
    <texture file="visuals/T_BC001.png" name="door_material" type="2d"/>
    <material name="door_material" rgba="1 1 1 1.0" texture="door_material" shininess="0.1" specular="5"/>
    <material name="door_Clear_material" rgba="0.09514838457107544 0.09514838457107544 0.09514838457107544 0.800000011920929" shininess="0.5" specular="0.3103448502657381"/>
    <texture file="visuals/T_BC001.png" name="Disc001_material" type="2d"/>
    <material name="Disc001_material" rgba="1 1 1 1.0" texture="Disc001_material" shininess="0.1" specular="5"/>
  </asset>
  <default>
    <default class="visual">
      <geom conaffinity="0" contype="0" group="1" type="mesh"/>
    </default>
    <default class="collision">
      <geom group="0" rgba="0.5 0 0 0.5"/>
    </default>
    <default class="spawn">
      <geom group="0" rgba="1 1 1 0.5" contype="0" conaffinity="0"/>
      <site group="0" rgba="1 1 1 0.5"/>
    </default>
    <default class="region">
      <geom group="1" conaffinity="0" contype="0" rgba="0 1 0 0"/>
    </default>
  </default>
  <worldbody>
    <body>
      <body name="object">
        <geom class="collision" type="cylinder" pos="-0.060759879648685455 0.021106692031025887 -0.1328725963830948" size="0.14255502820014954 0.0014981509884819388" quat="1.0 0.0 0.0 0.0" name="tray" rgba="0 1 0 0.5"/>
        <geom class="collision" type="box" pos="0.25932788848876953 -0.21656057238578796 -0.11676647514104843" size="0.015629081055521965 0.0010499833151698112 0.01617376133799553" quat="1.0 0.0 0.0 0.0" name="stop_button" rgba="0.0 0.5 0 0.5"/>
        <geom class="collision" type="box" pos="0.20051923394203186 -0.21656057238578796 -0.11640120297670364" size="0.016063643619418144 0.0010977096389979124 0.016673916950821877" quat="1.0 0.0 0.0 0.0" name="start_button" rgba="0.0 0.5 0 0.5"/>
        <geom mesh="Body001_vis" type="mesh" solimp="0.998 0.998 0.001" solref="0.001 1" friction="0.95 0.3 0.1" class="visual" material="Body001_material"/>
        <geom class="collision" type="box" pos="0.2377501279115677 0.018529720604419708 0.001223099185153842" size="0.05364568904042244 0.22963473200798035 0.16832594573497772" quat="1.0 0.0 0.0 0.0"/>
        <geom class="collision" type="box" pos="-8.701378828845918e-05 0.22681181132793427 0.000955226190853864" size="0.29336556792259216 0.03332466259598732 0.16824114322662354" quat="1.0 0.0 0.0 0.0"/>
        <geom class="collision" type="box" pos="0.2033662348985672 0.03149781748652458 0.004265929572284222" size="0.09008629620075226 0.2168685495853424 0.16528382897377014" quat="1.0 0.0 0.0 0.0"/>
        <geom class="collision" type="box" pos="-0.0008076358353719115 0.037123698741197586 -0.158383309841156" size="0.29264557361602783 0.22301435470581055 0.011166481301188469" quat="1.0 0.0 0.0 0.0"/>
        <geom class="collision" type="box" pos="-0.28042083978652954 0.037383731454610825 0.0005206208443269134" size="0.013030908070504665 0.2227540761232376 0.1688016802072525" quat="1.0 0.0 0.0 0.0"/>
        <geom class="collision" type="box" pos="-0.000807647651527077 0.037123698741197586 0.15857042372226715" size="0.29264408349990845 0.22301284968852997 0.010979358106851578" quat="1.0 0.0 0.0 0.0"/>
        <body name="door">
          <joint axis="0.0 0.0 1.0" pos="-0.27479857206344604 -0.20117312669754028 0.0027948173228651285" limited="true" name="microjoint" range="-1.5707963267948966 0.0" type="hinge" damping="1" frictionloss="1" armature=".01" stiffness="0.05"/>
          <geom mesh="door_vis" type="mesh" solimp="0.998 0.998 0.001" solref="0.001 1" friction="0.95 0.3 0.1" class="visual" material="door_material"/>
          <geom class="collision" type="box" pos="0.1460995078086853 -0.2519758641719818 0.0038811680860817432" size="0.016500357538461685 0.009066409431397915 0.06949946284294128" quat="1.0 0.0 0.0 0.0" name="door_handle_main"/>
          <geom class="collision" type="box" pos="0.1467444747686386 -0.23927158117294312 -0.10896866023540497" size="0.015760447829961777 0.018705299124121666 0.010145241394639015" quat="0.864357054233551 -0.5028786063194275 6.948561122044339e-07 7.785965294715425e-08"/>
          <geom class="collision" type="box" pos="-0.24951070547103882 -0.20567037165164948 -0.018414851278066635" size="0.02450057677924633 0.010938514955341816 0.1332176774740219" quat="1.0 0.0 0.0 0.0"/>
          <geom class="collision" type="box" pos="0.13522017002105713 -0.20567040145397186 0.005505544599145651" size="0.04553541541099548 0.010938532650470734 0.15713804960250854" quat="1.0 0.0 0.0 0.0"/>
          <geom class="collision" type="box" pos="-0.04459337145090103 -0.20567037165164948 -0.12936659157276154" size="0.2279670536518097 0.010938575491309166 0.028038175776600838" quat="1.0 0.0 0.0 0.0"/>
          <geom class="collision" type="box" pos="0.1467444747686386 -0.22427043318748474 -0.1308474987745285" size="0.015760447829961777 0.018705304712057114 0.01090038288384676" quat="0.8963797092437744 -0.44328704476356506 3.6028129102305684e-07 1.4993763386428327e-07"/>
          <geom class="collision" type="box" pos="0.1467444747686386 -0.24735455214977264 -0.09000664949417114" size="0.015760447829961777 0.018705302849411964 0.0093734385445714" quat="0.8013164401054382 -0.5982407331466675 6.814299808866053e-07 1.5665389696550847e-07"/>
          <geom class="collision" type="box" pos="-0.0489509254693985 -0.20567037165164948 0.13129369914531708" size="0.22841805219650269 0.01093857828527689 0.03351430594921112" quat="1.0 0.0 0.0 0.0" name="door_main"/>
          <geom class="collision" type="box" pos="-0.07153061032295227 -0.20096594095230103 -0.001199199352413416" size="0.15822134912014008 0.01202082633972168 0.11153775453567505" quat="1.0 0.0 0.0 0.0"/>
          <geom class="collision" type="box" pos="0.1467444747686386 -0.23927158117294312 0.11536557227373123" size="0.015760447829961777 0.018705299124121666 0.010145241394639015" quat="9.661798827664825e-08 -6.952240596547199e-07 -0.5028786063194275 0.864357054233551"/>
          <geom class="collision" type="box" pos="0.1467444747686386 -0.22427043318748474 0.13724441826343536" size="0.015760447829961777 0.018705304712057114 0.010900383815169334" quat="-2.159218439601318e-07 -6.069335540814791e-07 -0.4432871341705322 0.8963796496391296"/>
          <geom class="collision" type="box" pos="0.1467444747686386 -0.24857884645462036 0.09636051952838898" size="0.015760447829961777 0.018705304712057114 0.009373435750603676" quat="9.99178908500653e-08 -7.618554604960082e-07 -0.6223275065422058 0.7827569842338562"/>
          <body name="door_Clear">
            <geom mesh="door_Clear_vis" type="mesh" solimp="0.998 0.998 0.001" solref="0.001 1" friction="0.95 0.3 0.1" class="visual" material="door_Clear_material"/>
            <geom class="collision" type="box" pos="-0.07153061032295227 -0.20096594095230103 -0.001199199352413416" size="0.15822134912014008 0.01202082633972168 0.11153775453567505" quat="1.0 0.0 0.0 0.0"/>
          </body>
        </body>
        <body name="Disc001">
          <joint axis="0.0 0.0 1.0" pos="-0.0595463290810585 0.021286826580762863 -0.11701425909996033" limited="false" name="Disc001_joint" range="0 360" type="hinge" damping="1" frictionloss="1" armature=".01" stiffness="0.05"/>
          <geom mesh="Disc001_vis" type="mesh" solimp="0.998 0.998 0.001" solref="0.001 1" friction="0.95 0.3 0.1" class="visual" material="Disc001_material"/>
          <geom class="collision" type="cylinder" pos="-0.06075989454984665 0.020416980609297752 -0.1388215720653534" size="0.14195062220096588 0.004203101620078087" quat="1.9470718370939721e-07 -1.0 0.0 0.0"/>
        </body>
        <geom class="region" name="reg_int" type="box" pos="-0.07712024077773094 0.004163332283496857 0.003747284412384033" size="0.18249379268288612 0.18201555854082108 0.13612171804904938"/>
        <geom class="region" name="reg_main" type="box" pos="7.450580596923828e-09 0.021763700991868973 0.0" size="0.2944515178203583 0.23937260901927948 0.17054977810382843"/>
      </body>
    </body>
  </worldbody>
  <actuator>
    <motor name="microjoint_actuator" joint="microjoint" gear="10"/>
    <motor name="Disc001_joint_actuator" joint="Disc001_joint" gear="10"/>
  </actuator>
</mujoco>
