<?xml version='1.0' encoding='UTF-8'?>
<mujoco model="model">
  <option timestep="0.002" gravity="0.0 0.0 -9.81"/>
  <compiler angle="radian"/>
  <asset>
    <mesh file="visuals/door.obj" name="door_vis"/>
    <mesh file="visuals/knob_doneness.obj" name="knob_doneness_vis"/>
    <mesh file="visuals/knob_function.obj" name="knob_function_vis"/>
    <mesh file="visuals/knob_temp.obj" name="knob_temp_vis"/>
    <mesh file="visuals/knob_time.obj" name="knob_time_vis"/>
    <mesh file="visuals/rack0.obj" name="rack0_vis"/>
    <mesh file="visuals/Body001.obj" name="Body001_vis"/>
    <mesh file="visuals/window.obj" name="window_vis"/>
    <texture file="visuals/T_BC001.png" name="Body001_material" type="2d"/>
    <material name="Body001_material" rgba="1 1 1 1.0" texture="Body001_material" shininess="0.2512328028678894" specular="0.5"/>
    <texture file="visuals/T_BC001.png" name="door_material" type="2d"/>
    <material name="door_material" rgba="1 1 1 1.0" texture="door_material" shininess="0.2512328028678894" specular="0.5"/>
    <texture file="visuals/T_BC001.png" name="window_material" type="2d"/>
    <material name="window_material" rgba="1 1 1 0.800000011920929" texture="window_material" shininess="0.2512328028678894" specular="0.3103448502657381"/>
    <texture file="visuals/T_BC001.png" name="knob_doneness_material" type="2d"/>
    <material name="knob_doneness_material" rgba="1 1 1 1.0" texture="knob_doneness_material" shininess="0.2512328028678894" specular="0.3103448502657381"/>
    <texture file="visuals/T_BC001.png" name="knob_function_material" type="2d"/>
    <material name="knob_function_material" rgba="1 1 1 1.0" texture="knob_function_material" shininess="0.2512328028678894" specular="0.3103448502657381"/>
    <texture file="visuals/T_BC001.png" name="knob_temp_material" type="2d"/>
    <material name="knob_temp_material" rgba="1 1 1 1.0" texture="knob_temp_material" shininess="0.2512328028678894" specular="0.3103448502657381"/>
    <texture file="visuals/T_BC001.png" name="knob_time_material" type="2d"/>
    <material name="knob_time_material" rgba="1 1 1 1.0" texture="knob_time_material" shininess="0.2512328028678894" specular="0.3103448502657381"/>
    <texture file="visuals/T_BC001.png" name="rack0_material" type="2d"/>
    <material name="rack0_material" rgba="1 1 1 1.0" texture="rack0_material" shininess="0.141421377658844" specular="5"/>
  </asset>
  <default>
    <default class="visual">
      <geom conaffinity="0" contype="0" group="1" type="mesh"/>
    </default>
    <default class="collision">
      <geom group="0" rgba="0.5 0 0 0.5"/>
    </default>
    <default class="spawn">
      <geom group="0" rgba="1 1 1 0.5" contype="0" conaffinity="0"/>
      <site group="0" rgba="1 1 1 0.5"/>
    </default>
    <default class="region">
      <geom group="1" conaffinity="0" contype="0" rgba="0 1 0 0"/>
    </default>
  </default>
  <worldbody>
    <body>
      <body name="object">
        <geom mesh="Body001_vis" type="mesh" solimp="0.998 0.998 0.001" solref="0.001 1" friction="0.95 0.3 0.1" class="visual" material="Body001_material"/>
        <geom class="collision" type="box" pos="-0.14384970 0.01806410 0.00575145" size="0.021892467513680458 0.10961189866065979 0.13251899182796478" quat="1.0 0.0 0.0 0.0"/>
        <geom class="collision" type="box" pos="-0.00000005 0.01806403 -0.11228935" size="0.1657390296459198 0.10961207747459412 0.015027121640741825" quat="1.0 0.0 0.0 0.0"/>
        <geom class="collision" type="box" pos="0.14385003 0.01809291 0.00635892" size="0.021892113611102104 0.10958168655633926 0.13251946866512299" quat="1.0 0.0 0.0 0.0"/>
        <geom class="collision" type="box" pos="-0.00016390 0.01806313 0.08223901" size="0.16557534039020538 0.10961160063743591 0.060967203229665756" quat="1.0 0.0 0.0 0.0"/>
        <geom class="collision" type="box" pos="-0.00015167 -0.09759170 0.09214653" size="0.1517123579978943 0.0053787510842084885 0.040148694068193436" quat="1.0 0.0 0.0 0.0"/>
        <geom class="collision" type="cylinder" pos="0.12863237 -0.06223436 -0.13526306" size="0.009940076619386673 0.007945614866912365" quat="7.549790126404332e-08 -1.0 0.0 0.0"/>
        <geom class="collision" type="cylinder" pos="-0.12975863 -0.06223436 -0.13526306" size="0.009940076619386673 0.007945614866912365" quat="7.549790126404332e-08 -1.0 0.0 0.0"/>
        <geom class="collision" type="cylinder" pos="0.12863237 0.09466845 -0.13526306" size="0.009940076619386673 0.007945614866912365" quat="7.549790126404332e-08 -1.0 0.0 0.0"/>
        <geom class="collision" type="cylinder" pos="-0.12975863 0.09466845 -0.13526306" size="0.009940076619386673 0.007945614866912365" quat="7.549790126404332e-08 -1.0 0.0 0.0"/>
        <geom class="collision" type="box" pos="0.00120360 0.07685552 -0.03956271" size="0.1254693567752838 0.050822723656892776 0.06082941219210625" quat="1.0 0.0 0.0 0.0"/>
        <geom class="collision" type="box" pos="-0.12302516 -0.03077261 -0.04503537" size="0.004926081281155348 0.042049676179885864 0.01603158749639988" quat="1.0 0.0 0.0 0.0"/>
        <geom class="collision" type="box" pos="-0.12302516 -0.03077261 -0.07507122" size="0.004926081281155348 0.042049676179885864 0.007960397750139236" quat="1.0 0.0 0.0 0.0"/>
        <geom class="collision" type="box" pos="-0.12302516 -0.02339957 0.01227983" size="0.004926081281155348 0.049422718584537506 0.006165614817291498" quat="1.0 0.0 0.0 0.0"/>
        <geom class="collision" type="box" pos="-0.12302516 0.01951633 -0.00799675" size="0.004926078952848911 0.006506818812340498 0.016109801828861237" quat="1.0 0.0 0.0 0.0"/>
        <geom class="collision" type="box" pos="0.12390774 -0.01207612 -0.01267803" size="0.004926078952848911 0.012758263386785984 0.009307733736932278" quat="1.0 0.0 0.0 0.0"/>
        <geom class="collision" type="box" pos="0.12394489 0.01951633 -0.00799675" size="0.004926078952848911 0.006506823934614658 0.016109803691506386" quat="1.0 0.0 0.0 0.0"/>
        <geom class="collision" type="box" pos="0.12394489 -0.02339957 0.01227983" size="0.004926081281155348 0.049422718584537506 0.006165631115436554" quat="1.0 0.0 0.0 0.0"/>
        <geom class="collision" type="box" pos="0.12286151 -0.03077261 -0.07507122" size="0.004926081281155348 0.04204967990517616 0.007960411719977856" quat="1.0 0.0 0.0 0.0"/>
        <geom class="collision" type="box" pos="-0.12302516 -0.01207612 -0.01267803" size="0.004926078952848911 0.01275826059281826 0.00930773001164198" quat="1.0 0.0 0.0 0.0"/>
        <geom class="collision" type="box" pos="0.12301072 -0.03077261 -0.04503537" size="0.004926081281155348 0.04204967990517616 0.016031600534915924" quat="1.0 0.0 0.0 0.0"/>
        <geom class="collision" type="box" pos="-0.00052856 0.00686557 -0.11801764" size="0.16464251279830933 0.1096147745847702 0.00862452294677496" quat="1.0 0.0 0.0 0.0"/>
        <body name="door">
          <joint axis="1.0 0.0 0.0" pos="0.00000023 -0.10259805 -0.10788514" limited="true" name="door_joint" range="0.0 1.5707963267948966" type="hinge" damping="1" frictionloss="1" armature=".01" stiffness="0.05"/>
          <geom mesh="door_vis" type="mesh" solimp="0.998 0.998 0.001" solref="0.001 1" friction="0.95 0.3 0.1" class="visual" material="door_material"/>
          <geom class="collision" type="box" pos="-0.00160570 -0.09759170 0.03688635" size="0.1570468246936798 0.005378819070756435 0.010370129719376564" quat="1.0 0.0 0.0 0.0"/>
          <geom class="collision" type="box" pos="-0.14461967 -0.09759170 -0.03575443" size="0.014037130400538445 0.005378827918320894 0.06419248133897781" quat="1.0 0.0 0.0 0.0"/>
          <geom class="collision" type="box" pos="0.14100505 -0.09759170 -0.03575443" size="0.014037162065505981 0.005378835368901491 0.06419260054826736" quat="1.0 0.0 0.0 0.0"/>
          <geom class="collision" type="box" pos="0.14744768 -0.11557846 0.04020564" size="0.005300507415086031 0.012701136991381645 0.009724574163556099" quat="1.0 0.0 0.0 0.0"/>
          <geom class="collision" type="box" pos="-0.14778328 -0.11563839 0.04009482" size="0.005140730645507574 0.012761094607412815 0.009747170843183994" quat="1.0 0.0 0.0 0.0"/>
          <geom class="collision" type="box" pos="-0.00160570 -0.09759170 -0.09276982" size="0.1570497453212738 0.005378910340368748 0.010370312258601189" quat="1.0 0.0 0.0 0.0"/>
          <geom class="collision" type="box" pos="-0.00160570 -0.10123054 -0.02821571" size="0.15704865753650665 0.0017400409560650587 0.07547225803136826" quat="1.0 0.0 0.0 0.0" name="door_main"/>
          <geom class="collision" type="box" pos="0.00000385 -0.12317576 0.04020564" size="0.14150260388851166 0.005103878676891327 0.009724589064717293" quat="1.0 0.0 0.0 0.0" name="door_handle_main"/>
          <body name="window">
            <geom mesh="window_vis" type="mesh" solimp="0.998 0.998 0.001" solref="0.001 1" friction="0.95 0.3 0.1" class="visual" material="window_material"/>
            <geom class="collision" type="box" pos="-0.00053016 -0.09459904 -0.03132229" size="0.1300632357597351 0.0015163501957431436 0.059017691761255264" quat="1.0 0.0 0.0 0.0"/>
          </body>
        </body>
        <body name="knob_doneness">
          <joint axis="0.0 1.0 0.0" pos="0.08784427 -0.11321857 0.09276430" limited="true" name="knob_doneness_joint" range="0.0 4.71238898038469" type="hinge" damping="0.05" armature="0.001"/>
          <geom mesh="knob_doneness_vis" type="mesh" solimp="0.998 0.998 0.001" solref="0.001 1" friction="0.95 0.3 0.1" class="visual" material="knob_doneness_material"/>
          <geom class="collision" type="cylinder" pos="0.08783818 -0.11013374 0.09272636" size="0.015111498534679413 0.0016196591313928366" quat="0.7071067094802856 0.70710688829422 0.0 0.0"/>
          <geom class="collision" type="box" pos="0.08777113 -0.11526523 0.09214580" size="0.004297190345823765 0.003512029070407152 0.013432742096483707" quat="1.0 0.0 0.0 0.0" name="knob_doneness_main"/>
        </body>
        <body name="knob_function">
          <joint axis="0.0 1.0 0.0" pos="0.02852556 -0.11321857 0.09276430" limited="true" name="knob_function_joint" range="0.0 3.141592653589793" type="hinge" damping="0.05" armature="0.001"/>
          <geom mesh="knob_function_vis" type="mesh" solimp="0.998 0.998 0.001" solref="0.001 1" friction="0.95 0.3 0.1" class="visual" material="knob_function_material"/>
          <geom class="collision" type="cylinder" pos="0.02836811 -0.11013374 0.09272636" size="0.015111498534679413 0.0016196591313928366" quat="0.7071067094802856 0.70710688829422 0.0 0.0"/>
          <geom class="collision" type="box" pos="0.02884178 -0.11526523 0.09221374" size="0.004297186620533466 0.003512021852657199 0.013432711362838745" quat="1.0 0.0 0.0 0.0" name="knob_function_main"/>
        </body>
        <body name="knob_temp">
          <joint axis="0.0 1.0 0.0" pos="-0.03098843 -0.11321857 0.09276430" limited="true" name="knob_temp_joint" range="0.0 3.5779249665883754" type="hinge" damping="0.05" armature="0.001"/>
          <geom mesh="knob_temp_vis" type="mesh" solimp="0.998 0.998 0.001" solref="0.001 1" friction="0.95 0.3 0.1" class="visual" material="knob_temp_material"/>
          <geom class="collision" type="cylinder" pos="-0.03094646 -0.11013374 0.09254301" size="0.015111498534679413 0.0016196591313928366" quat="0.7071067094802856 0.70710688829422 0.0 0.0"/>
          <geom class="collision" type="box" pos="-0.03107433 -0.11526523 0.09218863" size="0.004297178704291582 0.003512013703584671 0.013432678766548634" quat="1.0 0.0 0.0 0.0" name="knob_temp_main"/>
        </body>
        <body name="knob_time">
          <joint axis="0.0 1.0 0.0" pos="-0.09053220 -0.11321857 0.09276430" limited="true" name="knob_time_joint" range="0.0 5.235987755982989" type="hinge" damping="0.05" armature="0.001"/>
          <geom mesh="knob_time_vis" type="mesh" solimp="0.998 0.998 0.001" solref="0.001 1" friction="0.95 0.3 0.1" class="visual" material="knob_time_material"/>
          <geom class="collision" type="cylinder" pos="-0.09055644 -0.11013374 0.09254301" size="0.015111498534679413 0.0016196591313928366" quat="0.7071067094802856 0.70710688829422 0.0 0.0"/>
          <geom class="collision" type="box" pos="-0.09062349 -0.11526523 0.09196245" size="0.004297166131436825 0.003512004856020212 0.013432645238935947" quat="1.0 0.0 0.0 0.0" name="knob_time_main"/>
        </body>
        <body name="rack0">
          <geom class="region" name="reg_rack0" type="box" pos="0.00048040499999999625 -0.025675709999999997 -0.007852079999999999" size="0.093428325 0.04437897 0.02674369"/>
          <joint axis="0.0 -1.0 0.0" pos="0.00030020 -0.00593611 -0.03185891" limited="true" name="rack0_joint" range="0.0 0.085" type="slide" damping="1" frictionloss="1" armature=".01" stiffness="0.05"/>
          <geom mesh="rack0_vis" type="mesh" solimp="0.998 0.998 0.001" solref="0.001 1" friction="0.95 0.3 0.1" class="visual" material="rack0_material"/>
          <geom class="collision" type="box" pos="0.00057734 -0.02559394 -0.03631821" size="0.09562108665704727 0.046136803925037384 0.001950536505319178" quat="1.0 0.0 0.0 0.0"/>
          <geom class="collision" type="box" pos="0.11378317 -0.02559394 -0.02692596" size="0.006737360265105963 0.046136803925037384 0.001950536505319178" quat="1.0 0.0 0.0 0.0"/>
          <geom class="collision" type="box" pos="0.10123889 -0.02559394 -0.03168534" size="0.008415200747549534 0.046136803925037384 0.001950536505319178" quat="0.9429240226745605 0.0 -0.33300796151161194 0.0"/>
          <geom class="collision" type="box" pos="-0.10104806 -0.02559394 -0.03168534" size="0.008415201678872108 0.046136803925037384 0.0019505366217345" quat="1.8359408215928852e-07 0.9429240226745605 6.48390425794787e-08 -0.33300793170928955"/>
          <geom class="collision" type="box" pos="-0.11359234 -0.02559394 -0.02692596" size="0.006737360265105963 0.046136803925037384 0.0019505515228956938" quat="1.0 0.0 0.0 0.0"/>
        </body>
        <geom class="region" name="reg_main" type="box" pos="-4.999999997368221e-09 0.009227715000000004 0.0" size="0.170784445 0.11945197500000002 0.1442087"/>
      </body>
    </body>
  </worldbody>
  <actuator>
    <motor name="door_joint_actuator" joint="door_joint" gear="50"/>
    <motor name="knob_doneness_joint_actuator" joint="knob_doneness_joint" gear="50"/>
    <motor name="knob_function_joint_actuator" joint="knob_function_joint" gear="50"/>
    <motor name="knob_temp_joint_actuator" joint="knob_temp_joint" gear="50"/>
    <motor name="knob_time_joint_actuator" joint="knob_time_joint" gear="50"/>
    <motor name="rack0_joint_actuator" joint="rack0_joint" gear="50"/>
  </actuator>
</mujoco>
