<?xml version='1.0' encoding='UTF-8'?>
<mujoco model="model">
  <option timestep="0.002" gravity="0.0 0.0 -9.81"/>
  <compiler angle="radian"/>
  <asset>
    <mesh file="visuals/freezer0.obj" name="freezer0_vis"/>
    <mesh file="visuals/fridge_drawer0.obj" name="fridge_drawer0_vis"/>
    <mesh file="visuals/fridge_left_door.obj" name="fridge_left_door_vis"/>
    <mesh file="visuals/fridge_right_door.obj" name="fridge_right_door_vis"/>
    <mesh file="visuals/Body001.obj" name="Body001_vis"/>
    <mesh file="visuals/Body001_Clear.obj" name="Body001_Clear_vis"/>
    <texture file="visuals/T_BC001.png" name="Body001_material" type="2d"/>
    <material name="Body001_material" rgba="1 1 1 1.0" texture="Body001_material" shininess="2" specular="2"/>
    <texture file="visuals/T_BC001.png" name="freezer0_material" type="2d"/>
    <material name="freezer0_material" rgba="1 1 1 1.0" texture="freezer0_material" shininess="2" specular="2"/>
    <texture file="visuals/T_BC001.png" name="fridge_drawer0_material" type="2d"/>
    <material name="fridge_drawer0_material" rgba="1 1 1 1.0" texture="fridge_drawer0_material" shininess="0.7577263116836548" specular="0.3103448502657381"/>
    <texture file="visuals/T_BC001.png" name="fridge_left_door_material" type="2d"/>
    <material name="fridge_left_door_material" rgba="1 1 1 1.0" texture="fridge_left_door_material" shininess="2" specular="2"/>
    <texture file="visuals/T_BC001.png" name="fridge_right_door_material" type="2d"/>
    <material name="fridge_right_door_material" rgba="1 1 1 1.0" texture="fridge_right_door_material" shininess="2" specular="2"/>
    <material name="Body001_Clear_material" rgba="0.6760485172271729 0.8000229597091675 0.7606381177902222 0.27272725105285645" shininess="0.5" specular="0.3103448502657381"/>
  </asset>
  <default>
    <default class="visual">
      <geom conaffinity="0" contype="0" group="1" type="mesh"/>
    </default>
    <default class="collision">
      <geom group="0" rgba="0.5 0 0 0.5"/>
    </default>
    <default class="spawn">
      <geom group="0" rgba="1 1 1 0.5" contype="0" conaffinity="0"/>
      <site group="0" rgba="1 1 1 0.5"/>
    </default>
    <default class="region">
      <geom group="1" conaffinity="0" contype="0" rgba="0 1 0 0"/>
    </default>
  </default>
  <worldbody>
    <body>
      <body name="object">
        <geom mesh="Body001_vis" type="mesh" solimp="0.998 0.998 0.001" solref="0.001 1" friction="0.95 0.3 0.1" class="visual" material="Body001_material"/>
        <geom class="collision" type="box" pos="0.00244130 0.04467770 0.47924063" size="0.40693676471710205 0.20570765435695648 0.008224813267588615" quat="1.0 0.0 0.0 0.0"/>
        <geom class="collision" type="box" pos="0.00244130 0.04467770 0.13264118" size="0.40693676471710205 0.20570765435695648 0.008224813267588615" quat="1.0 0.0 0.0 0.0"/>
        <geom class="collision" type="box" pos="-0.43643510 0.08550413 -0.00073579" size="0.01859312132000923 0.3094015419483185 0.8944895267486572" quat="1.0 0.0 0.0 0.0"/>
        <geom class="collision" type="box" pos="0.43642050 0.08548879 -0.00040731" size="0.018579570576548576 0.3093862235546112 0.8941609859466553" quat="1.0 0.0 0.0 0.0"/>
        <geom class="collision" type="box" pos="-0.00138975 0.33245702 -0.00071217" size="0.419253945350647 0.062493860721588135 0.894465982913971" quat="1.0 0.0 0.0 0.0"/>
        <geom class="collision" type="box" pos="-0.00091293 0.08548879 0.86302954" size="0.4200219213962555 0.3093862235546112 0.030724193900823593" quat="1.0 0.0 0.0 0.0"/>
        <geom class="collision" type="box" pos="-0.00091293 0.08550692 -0.24774715" size="0.4200219213962555 0.3094043433666229 0.04806247353553772" quat="1.0 0.0 0.0 0.0"/>
        <geom class="collision" type="box" pos="-0.00091293 0.08546695 -0.86918718" size="0.4200219213962555 0.309364378452301 0.026062777265906334" quat="1.0 0.0 0.0 0.0"/>
        <body name="freezer0">
          <geom class="region" name="reg_freezer0" type="box" pos="-0.0006033000000000011 0.018661540000000004 -0.57097927" size="0.39270638999999996 0.21382617 0.19819109000000001"/>
          <joint axis="0.0 -1.0 0.0" pos="0.00000003 -0.06583229 -0.56924975" limited="true" name="freezer0_door_joint" range="0.0 0.4" type="slide" damping="1" frictionloss="1" armature=".01" stiffness="0.05"/>
          <geom mesh="freezer0_vis" type="mesh" solimp="0.998 0.998 0.001" solref="0.001 1" friction="0.95 0.3 0.1" class="visual" material="freezer0_material"/>
          <geom class="collision" type="cylinder" pos="-0.20717679 -0.33731227 -0.30073348" size="0.00958966463804245 0.01981106400489807" quat="0.7071067094802856 0.7071068286895752 0.0 0.0" name="freezer0_door_handle_1"/>
          <geom class="collision" type="cylinder" pos="0.20889451 -0.33731227 -0.30073348" size="0.00958966463804245 0.01981106400489807" quat="0.7071067094802856 0.7071068286895752 0.0 0.0" name="freezer0_door_handle_2"/>
          <geom class="collision" type="cylinder" pos="0.00054136 -0.37616433 -0.30049491" size="0.01512225717306137 0.2832430899143219" quat="0.7071068286895752 -0.0 0.7071067690849304 0.0" name="freezer0_door_handle_main"/>
          <geom class="collision" type="box" pos="0.00031409 -0.31415440 -0.57057822" size="0.45428305864334106 0.010988916270434856 0.3240372836589813" quat="1.0 0.0 0.0 0.0" name="freezer0_door_main"/>
          <geom class="collision" type="box" pos="0.00000012 -0.28266658 -0.57089525" size="0.455000102519989 0.03940330445766449 0.3243543207645416" quat="1.0 0.0 0.0 0.0"/>
          <geom class="collision" type="box" pos="0.40209508 0.00605657 -0.57578731" size="0.0012200025375932455 0.23485112190246582 0.20430701971054077" quat="1.0 0.0 0.0 0.0"/>
          <geom class="collision" type="box" pos="-0.40607324 0.00605657 -0.57578731" size="0.003635436063632369 0.23485112190246582 0.20430701971054077" quat="1.0 0.0 0.0 0.0"/>
          <geom class="collision" type="box" pos="0.00479245 0.24995583 -0.57578731" size="0.3954424262046814 0.002310782438144088 0.20430701971054077" quat="1.0 0.0 0.0 0.0"/>
          <geom class="collision" type="box" pos="0.00479245 0.02202710 -0.78704077" size="0.3954424262046814 0.23100967705249786 0.012409958057105541" quat="1.0 0.0 0.0 0.0"/>
        </body>
        <body name="fridge_drawer0">
          <geom class="region" name="reg_fridge_drawer0" type="box" pos="0.004019439999999985 0.05347409499999999 -0.05750791" size="0.29088141 0.171442985 0.10435024000000001"/>
          <joint axis="0.0 -1.0 0.0" pos="0.00343926 0.02418251 -0.06103485" limited="true" name="fridge_drawer0_joint" range="0.0 0.4" type="slide" damping="1" frictionloss="1" armature=".01" stiffness="0.05"/>
          <geom mesh="fridge_drawer0_vis" type="mesh" solimp="0.998 0.998 0.001" solref="0.001 1" friction="0.95 0.3 0.1" class="visual" material="fridge_drawer0_material"/>
          <geom class="collision" type="box" pos="0.31745097 0.01149486 -0.05984484" size="0.01572214625775814 0.21937870979309082 0.11382616311311722" quat="1.0 0.0 0.0 0.0"/>
          <geom class="collision" type="box" pos="-0.30874649 0.01149486 -0.05984902" size="0.01572214625775814 0.21937870979309082 0.1138303354382515" quat="1.0 0.0 0.0 0.0"/>
          <geom class="collision" type="box" pos="0.00354372 0.01149486 -0.17100862" size="0.2995295226573944 0.21938344836235046 0.002856377512216568" quat="1.0 0.0 0.0 0.0"/>
          <geom class="collision" type="box" pos="0.00354372 -0.19068517 -0.08423010" size="0.2995370924472809 0.017198646441102028 0.08452503383159637" quat="1.0 0.0 0.0 0.0"/>
          <geom class="collision" type="box" pos="0.00441118 0.23865519 -0.06112564" size="0.3274199366569519 0.00832795724272728 0.11302142590284348" quat="1.0 0.0 0.0 0.0"/>
          <geom class="collision" type="box" pos="0.00320474 -0.15026397 0.04171962" size="0.3023030757904053 0.025498157367110252 0.011790852062404156" quat="1.0 0.0 0.0 0.0"/>
        </body>
        <body name="fridge_left_door">
          <joint axis="0.0 0.0 -1.0" pos="-0.40531173 -0.28519540 0.29310042" limited="true" name="fridge_left_door_joint" range="0.0 1.5707963267948966" type="hinge" damping="1" frictionloss="1" armature=".01" stiffness="0.05"/>
          <geom mesh="fridge_left_door_vis" type="mesh" solimp="0.998 0.998 0.001" solref="0.001 1" friction="0.95 0.3 0.1" class="visual" material="fridge_left_door_material"/>
          <geom class="collision" type="box" pos="-0.21050665 -0.31717561 0.33133805" size="0.204952210187912 0.00818533543497324 0.5639119744300842" quat="1.0 0.0 0.0 0.0" name="fridge_left_door_main"/>
          <geom class="collision" type="cylinder" pos="-0.06040616 -0.33731227 0.68688142" size="0.00958966463804245 0.01981106400489807" quat="0.7071067094802856 0.7071068286895752 0.0 0.0" name="fridge_left_door_handle_1"/>
          <geom class="collision" type="cylinder" pos="-0.06040616 -0.33731227 -0.10662180" size="0.00958966463804245 0.01981106400489807" quat="0.7071067094802856 0.7071068286895752 0.0 0.0" name="fridge_left_door_handle_2"/>
          <geom class="collision" type="cylinder" pos="-0.06059455 -0.38077806 0.29052567" size="0.015450036153197289 0.47307562828063965" quat="1.0 0.0 0.0 0.0" name="fridge_left_door_handle_main"/>
          <geom class="collision" type="box" pos="-0.21041995 -0.28401230 0.33133805" size="0.20486551523208618 0.03745518997311592 0.5639119744300842" quat="1.0 0.0 0.0 0.0"/>
        </body>
        <body name="fridge_right_door">
          <joint axis="0.0 0.0 1.0" pos="0.41055948 -0.28442077 0.29310042" limited="true" name="fridge_right_door_joint" range="0.0 1.5707963267948966" type="hinge" damping="1" frictionloss="1" armature=".01" stiffness="0.05"/>
          <geom mesh="fridge_right_door_vis" type="mesh" solimp="0.998 0.998 0.001" solref="0.001 1" friction="0.95 0.3 0.1" class="visual" material="fridge_right_door_material"/>
          <geom class="collision" type="box" pos="0.20889558 -0.31755991 0.33133805" size="0.1988135576248169 0.007898606359958649 0.5639119744300842" quat="1.0 0.0 0.0 0.0" name="fridge_right_door_main"/>
          <geom class="collision" type="cylinder" pos="0.07084915 -0.33731227 -0.10662180" size="0.00958966463804245 0.01981106400489807" quat="0.7071067094802856 0.7071068286895752 0.0 0.0" name="fridge_right_door_handle_1"/>
          <geom class="collision" type="cylinder" pos="0.07084915 -0.33731227 0.68688142" size="0.00958966463804245 0.01981106400489807" quat="0.7071067094802856 0.7071068286895752 0.0 0.0" name="fridge_right_door_handle_2"/>
          <geom class="collision" type="cylinder" pos="0.07070101 -0.38039930 0.29052567" size="0.015450036153197289 0.47307562828063965" quat="1.0 0.0 0.0 0.0" name="fridge_right_door_handle_main"/>
          <geom class="collision" type="box" pos="0.20880888 -0.28596659 0.33133805" size="0.1987268626689911 0.0355009026825428 0.5639119744300842" quat="1.0 0.0 0.0 0.0"/>
        </body>
        <body name="Body001_Clear">
          <geom mesh="Body001_Clear_vis" type="mesh" solimp="0.998 0.998 0.001" solref="0.001 1" friction="0.95 0.3 0.1" class="visual" material="Body001_Clear_material"/>
          <geom class="collision" type="box" pos="0.00244130 0.04467770 0.47924063" size="0.40693676471710205 0.20570765435695648 0.008224813267588615" quat="1.0 0.0 0.0 0.0"/>
          <geom class="collision" type="box" pos="0.00244130 0.04467770 0.13264118" size="0.40693676471710205 0.20570765435695648 0.008224813267588615" quat="1.0 0.0 0.0 0.0"/>
        </body>
        <geom class="region" name="reg_fridge_shelf0" type="box" pos="0.0025017999999999985 0.04465746000000001 0.30671411" size="0.40800929 0.20663348 0.15897628000000003"/>
        <geom class="region" name="reg_fridge_shelf1" type="box" pos="0.0025017999999999985 0.04465746000000001 0.6605898450000001" size="0.40800929 0.20663348 0.165372715"/>
        <geom class="region" name="reg_main" type="box" pos="7.850500000000649e-05 0.033385499999999985 0.0" size="0.456714555 0.36252576999999997 0.89624996"/>
      </body>
    </body>
  </worldbody>
  <actuator>
    <motor name="freezer0_door_joint_actuator" joint="freezer0_door_joint" gear="50"/>
    <motor name="fridge_drawer0_joint_actuator" joint="fridge_drawer0_joint" gear="50"/>
    <motor name="fridge_left_door_joint_actuator" joint="fridge_left_door_joint" gear="50"/>
    <motor name="fridge_right_door_joint_actuator" joint="fridge_right_door_joint" gear="50"/>
  </actuator>
</mujoco>
