<?xml version='1.0' encoding='UTF-8'?>
<mujoco model="model">
  <option timestep="0.002" gravity="0.0 0.0 -9.81"/>
  <compiler angle="radian"/>
  <asset>
    <mesh file="visuals/handle.obj" name="handle_vis"/>
    <mesh file="visuals/Body001.obj" name="Body001_vis"/>
    <mesh file="visuals/Funnel001.obj" name="Funnel001_vis"/>
    <mesh file="visuals/spout.obj" name="spout_vis"/>
    <texture file="visuals/T_BC001.png" name="Body001_material" type="2d"/>
    <material name="Body001_material" rgba="1 1 1 1.0" texture="Body001_material" shininess="0.35739320516586304" specular="0.5"/>
    <texture file="visuals/T_BC001.png" name="handle_material" type="2d"/>
    <material name="handle_material" rgba="1 1 1 1.0" texture="handle_material" shininess="0.35739320516586304" specular="0.5"/>
    <texture file="visuals/T_BC001.png" name="Funnel001_material" type="2d"/>
    <material name="Funnel001_material" rgba="1 1 1 1.0" texture="Funnel001_material" shininess="0.35739320516586304" specular="1"/>
    <texture file="visuals/T_BC001.png" name="spout_material" type="2d"/>
    <material name="spout_material" rgba="1 1 1 1.0" texture="spout_material" shininess="0.35739320516586304" specular="0.5"/>
  </asset>
  <default>
    <default class="visual">
      <geom conaffinity="0" contype="0" group="1" type="mesh"/>
    </default>
    <default class="collision">
      <geom group="0" rgba="0.5 0 0 0.5"/>
    </default>
    <default class="spawn">
      <geom group="0" rgba="1 1 1 0.5" contype="0" conaffinity="0"/>
      <site group="0" rgba="1 1 1 0.5"/>
    </default>
    <default class="region">
      <geom group="1" conaffinity="0" contype="0" rgba="0 1 0 0"/>
    </default>
  </default>
  <worldbody>
    <body>
      <body name="object">
        <geom mesh="Body001_vis" type="mesh" solimp="0.998 0.998 0.001" solref="0.001 1" friction="0.95 0.3 0.1" class="visual" material="Body001_material"/>
        <geom class="collision" type="box" pos="-0.2871226668357849 2.9685907065868378e-09 0.04207734763622284" size="0.2736888527870178 0.30101001262664795 0.00918702781200409" quat="1.0 0.0 0.0 0.0"/>
        <geom class="collision" type="box" pos="0.5286571979522705 2.939486876130104e-09 0.04212311655282974" size="0.032154303044080734 0.30101001262664795 0.009141258895397186" quat="1.0 0.0 0.0 0.0"/>
        <geom class="collision" type="box" pos="0.5109840631484985 -0.0005308240652084351 -0.07721409946680069" size="0.008321618661284447 0.21207192540168762 0.11421234905719757" quat="1.0 0.0 0.0 0.0"/>
        <geom class="collision" type="box" pos="-0.010453362949192524 0.026724064722657204 -0.07721409946680069" size="0.013463507406413555 0.21207192540168762 0.11421234905719757" quat="1.0 0.0 0.0 0.0"/>
        <geom class="collision" type="box" pos="0.2424127608537674 0.26563823223114014 0.04215243086218834" size="0.2546788454055786 0.03537175804376602 0.009111916646361351" quat="1.0 0.0 0.0 0.0"/>
        <geom class="collision" type="box" pos="0.24078743159770966 0.2454732209444046 -0.07589737325906754" size="0.2530535161495209 0.01516951248049736 0.1090444028377533" quat="1.0 0.0 0.0 0.0"/>
        <geom class="collision" type="box" pos="0.24078743159770966 -0.24943241477012634 -0.07589737325906754" size="0.2530535161495209 0.012662705965340137 0.1090444028377533" quat="1.0 0.0 0.0 0.0"/>
        <geom class="collision" type="box" pos="0.24213886260986328 -0.2654821276664734 0.04237736389040947" size="0.2552923560142517 0.035527847707271576 0.008886951021850109" quat="1.0 0.0 0.0 0.0"/>
        <geom class="collision" type="box" pos="0.25460320711135864 -0.10328363627195358 -0.18796999752521515" size="0.2530520260334015 0.13475719094276428 0.017098838463425636" quat="1.0 0.0 0.0 0.0"/>
        <geom class="collision" type="box" pos="0.40957146883010864 0.13129770755767822 -0.1879698932170868" size="0.0940568819642067 0.10557010024785995 0.01709897629916668" quat="1.0 0.0 0.0 0.0"/>
        <geom class="collision" type="box" pos="0.08970554918050766 0.13406549394130707 -0.1879698932170868" size="0.09498114138841629 0.10601967573165894 0.01709897629916668" quat="1.0 0.0 0.0 0.0"/>
        <geom class="collision" type="cylinder" pos="0.25292259454727173 0.09532701969146729 -0.24495285749435425" size="0.0708804577589035 0.046830661594867706" quat="1.0 0.0 0.0 0.0"/>
        <geom class="collision" type="cylinder" pos="-0.04991922900080681 0.2460225522518158 0.11299807578325272" size="0.024180535227060318 0.062119390815496445" quat="1.0 0.0 0.0 0.0"/>
        <geom class="collision" type="cylinder" pos="-0.020786724984645844 0.2478511780500412 0.14000830054283142" size="0.017893292009830475 0.016760164871811867" quat="0.7071068286895752 -0.0 0.7071067690849304 0.0"/>
        <geom class="collision" type="box" pos="0.4977240562438965 0.21953433752059937 -0.06518340855836868" size="0.018300360068678856 0.038068220019340515 0.11528453230857849" quat="0.9275355339050293 0.0 0.0 0.3737350404262543"/>
        <geom class="collision" type="box" pos="0.494344025850296 -0.22387133538722992 -0.06518340855836868" size="0.018300360068678856 0.038068220019340515 0.11528453230857849" quat="0.38563087582588196 0.0 0.0 0.9226531386375427"/>
        <geom class="collision" type="box" pos="4.952680319547653e-05 -0.22442252933979034 -0.06518340855836868" size="0.018300360068678856 0.038068220019340515 0.11528453230857849" quat="0.297259122133255 0.0 -0.0 -0.9547968506813049"/>
        <geom class="collision" type="box" pos="0.0017277644947171211 0.22711066901683807 -0.06518340855836868" size="0.018300360068678856 0.038068220019340515 0.11528453230857849" quat="0.9127280712127686 0.0 -0.0 -0.4085676074028015"/>
        <geom class="collision" type="box" pos="0.26680490374565125 0.2084677517414093 -0.18818596005439758" size="0.08813568949699402 0.05046704411506653 0.016630278900265694" quat="1.0 0.0 0.0 0.0"/>
        <geom class="collision" type="box" pos="0.25460320711135864 -0.23006552457809448 -0.18407657742500305" size="0.1979919672012329 0.017220091074705124 0.025875912979245186" quat="0.910473644733429 0.41356709599494934 0.0 0.0"/>
        <geom class="collision" type="box" pos="-0.005342260003089905 0.011147376149892807 -0.17567333579063416" size="0.1979919672012329 0.017220091074705124 0.025875912979245186" quat="0.20827989280223846 0.6757362484931946 0.6757362484931946 0.20827995240688324"/>
        <geom class="collision" type="box" pos="0.5005956292152405 0.008264077827334404 -0.18563374876976013" size="0.1979919672012329 0.017220089212059975 0.015161111950874329" quat="0.649133563041687 0.2804023027420044 0.2804023325443268 0.6491338014602661"/>
        <geom class="collision" type="box" pos="0.48651352524757385 0.21867622435092926 -0.18716545403003693" size="0.018300356343388557 0.05297768861055374 0.025608424097299576" quat="0.8635186553001404 -0.15017087757587433 0.3499581813812256 0.3306259214878082"/>
        <geom class="collision" type="box" pos="0.4807043671607971 -0.20080024003982544 -0.18500405550003052" size="0.018300356343388557 0.05297768861055374 0.025608424097299576" quat="0.8686248064041138 0.12839116156101227 0.2975769639015198 -0.37477269768714905"/>
        <geom class="collision" type="box" pos="0.019483037292957306 -0.21153709292411804 -0.1789291352033615" size="0.018300356343388557 0.05297768861055374 0.025608424097299576" quat="0.3267918527126312 0.3041425347328186 0.11195366084575653 -0.8877898454666138"/>
        <geom class="collision" type="box" pos="0.030434217303991318 0.2283417135477066 -0.1714058816432953" size="0.018300356343388557 0.05297768488526344 0.025608424097299576" quat="0.4189767837524414 -0.29057538509368896 0.14353470504283905 0.8481875658035278"/>
        <body name="handle">
          <joint axis="1.0 0.0 0.0" pos="0.014068372547626495 0.2480713427066803 0.13857950270175934" limited="true" name="handle_temp_joint" type="hinge" range="-0.7853981633974483 0.7853981633974483" damping="1" frictionloss="1" armature=".01"/>
          <joint axis="0.0 1.0 0.0" pos="0.014068372547626495 0.2480713427066803 0.13857950270175934" limited="true" name="handle_joint" type="hinge" range="0 0.5" damping="1" frictionloss="1" armature=".01"/>
          <geom mesh="handle_vis" type="mesh" solimp="0.998 0.998 0.001" solref="0.001 1" friction="0.95 0.3 0.1" class="visual" material="handle_material"/>
          <geom class="collision" type="cylinder" pos="0.01986480876803398 0.2478511780500412 0.13881364464759827" size="0.01828182302415371 0.009385824203491211" quat="0.7071068286895752 -0.0 0.7071067690849304 0.0" density="0.001"/>
          <geom class="collision" type="box" pos="0.02817542478442192 0.24869947135448456 0.16306659579277039" size="0.0016845897771418095 0.013875380158424377 0.03605586662888527" quat="1.0 0.0 0.0 0.0" density="0.001"/>
        </body>
        <body name="Funnel001">
          <joint axis="0.0 0.0 1.0" pos="0.2522986829280853 0.09536375105381012 -0.1954815685749054" limited="true" name="Funnel001_joint" range="0.0 0.05" type="slide" damping="1" frictionloss="1" armature=".01" stiffness="0.05"/>
          <geom mesh="Funnel001_vis" type="mesh" solimp="0.998 0.998 0.001" solref="0.001 1" friction="0.95 0.3 0.1" class="visual" material="Funnel001_material"/>
          <geom class="collision" type="cylinder" pos="0.25230440497398376 0.09596304595470428 -0.19668932259082794" size="0.05950119346380234 0.0009597260504961014" quat="1.0 0.0 0.0 0.0"/>
          <geom class="collision" type="cylinder" pos="0.2521103620529175 0.0955749899148941 -0.19136670231819153" size="0.024024147540330887 0.004455683287233114" quat="1.0 0.0 0.0 0.0"/>
        </body>
        <body name="spout">
          <joint axis="0.0 0.0 1.0" pos="-0.05127536505460739 0.2445916086435318 0.23410385847091675" limited="true" name="spout_joint" range="-0.7853981633974483 0.7853981633974483" type="hinge" damping="1" frictionloss="1" armature=".01" stiffness="0.05"/>
          <site type="cylinder" rgba="0.5 0.75 1 0.5" size="0.010150724090635777 0.22796685993671417" pos="0.0916941836476326 0.0978408008813858 0.036135561764240265" name="water"/>
          <geom mesh="spout_vis" type="mesh" solimp="0.998 0.998 0.001" solref="0.001 1" friction="0.95 0.3 0.1" class="visual" material="spout_material"/>
          <geom class="collision" type="cylinder" pos="0.02296653762459755 0.1644744873046875 0.2511208951473236" size="0.02158275619149208 0.080698661506176" quat="0.7809773683547974 0.4956744909286499 0.36428695917129517 0.10805641114711761" name="spout_main"/>
          <geom class="collision" type="box" pos="0.09023865312337875 0.09976723790168762 0.26791703701019287" size="0.02299872599542141 0.02299872599542141 0.02299872599542141" quat="1.0 0.0 0.0 0.0"/>
          <geom class="collision" type="cylinder" pos="-0.04888329282402992 0.24282993376255035 0.2002493292093277" size="0.021778030321002007 0.023167377337813377" quat="1.0 0.0 0.0 0.0"/>
          <geom class="collision" type="cylinder" pos="-0.04139203950762749 0.23307953774929047 0.2222091108560562" size="0.021778030321002007 0.023167377337813377" quat="0.904144823551178 0.32398682832717896 0.2762206494808197 0.03545193746685982"/>
        </body>
        <geom class="region" name="reg_basin" type="box" pos="0.250229237601161 0.0002999529242515564 -0.0622384175658226" size="0.21698130650818348 0.20572995191812515 0.09183358198404312"/>
        <geom class="region" name="reg_main" type="box" pos="0.0 0.0 -0.1202595978975296" size="0.5618115196228027 0.30201001262664795 0.17252397334575653"/>
      </body>
    </body>
  </worldbody>
  <actuator>
    <motor name="handle_joint_actuator" joint="handle_joint" gear="10"/>
    <motor name="handle_temp_joint_actuator" joint="handle_temp_joint" gear="10"/>
    <motor name="Funnel001_joint_actuator" joint="Funnel001_joint" gear="10"/>
    <motor name="spout_joint_actuator" joint="spout_joint" gear="10"/>
  </actuator>
</mujoco>
