<?xml version='1.0' encoding='UTF-8'?>
<mujoco model="model">
  <option timestep="0.002" gravity="0.0 0.0 -9.81"/>
  <compiler angle="radian"/>
  <asset>
    <mesh file="visuals/button_lid.obj" name="button_lid_vis"/>
    <mesh file="visuals/Body001.obj" name="Body001_vis"/>
    <mesh file="visuals/kettle_main.obj" name="kettle_main_vis"/>
    <mesh file="visuals/kettle_main_Clear.obj" name="kettle_main_Clear_vis"/>
    <mesh file="visuals/lid.obj" name="lid_vis"/>
    <mesh file="visuals/switch.obj" name="switch_vis"/>
    <texture file="visuals/T_BC001.png" name="Body001_material" type="2d"/>
    <material name="Body001_material" rgba="1 1 1 1.0" texture="Body001_material" shininess="0.5" specular="1"/>
    <texture file="visuals/T_BC001.png" name="kettle_main_material" type="2d"/>
    <material name="kettle_main_material" rgba="1 1 1 1.0" texture="kettle_main_material" shininess="0.5" specular="1"/>
    <texture file="visuals/T_BC001.png" name="button_lid_material" type="2d"/>
    <material name="button_lid_material" rgba="1 1 1 1.0" texture="button_lid_material" shininess="0.5" specular="1"/>
    <texture file="visuals/T_BC001.png" name="kettle_main_Clear_material" type="2d"/>
    <material name="kettle_main_Clear_material" rgba="1 1 1 0.699999988079071" texture="kettle_main_Clear_material" shininess="0.5" specular="1"/>
    <texture file="visuals/T_BC001.png" name="lid_material" type="2d"/>
    <material name="lid_material" rgba="1 1 1 1.0" texture="lid_material" shininess="0.5" specular="1"/>
    <texture file="visuals/T_BC001.png" name="switch_material" type="2d"/>
    <material name="switch_material" rgba="1 1 1 1.0" texture="switch_material" shininess="0.5" specular="1"/>
  </asset>
  <default>
    <default class="visual">
      <geom conaffinity="0" contype="0" group="1" type="mesh"/>
    </default>
    <default class="collision">
      <geom group="0" rgba="0.5 0 0 0.5"/>
    </default>
    <default class="spawn">
      <geom group="0" rgba="1 1 1 0.5" contype="0" conaffinity="0"/>
      <site group="0" rgba="1 1 1 0.5"/>
    </default>
    <default class="region">
      <geom group="1" conaffinity="0" contype="0" rgba="0 1 0 0" mass="0"/>
    </default>
  </default>
  <worldbody>
    <body>
      <body name="object">
        <geom mesh="Body001_vis" type="mesh" solimp="0.998 0.998 0.001" solref="0.001 1" friction="0.95 0.3 0.1" class="visual" material="Body001_material"/>
        <geom type="cylinder" pos="-0.03663462 0.00000002 -0.15673008" size="0.11323785781860352 0.012101196683943272" quat="1.0 0.0 0.0 0.0" class="collision"/>
        <body name="kettle_main">
          <!-- <joint axis="0.0 0.0 1.0" pos="0.00064059 -0.00006427 0.00892175" limited="true" name="kettle_main_joint" range="0.0 0.1" type="slide" damping="1" frictionloss="1" armature=".01" stiffness="0.05"></joint> -->
          <geom mesh="kettle_main_vis" type="mesh" solimp="0.998 0.998 0.001" solref="0.001 1" friction="0.95 0.3 0.1" class="visual" material="kettle_main_material"/>
          <geom type="box" pos="-0.13985163 -0.00032412 -0.11241894" size="0.0038029812276363373 0.017222760245203972 0.028604567050933838" quat="1.0 0.0 0.0 0.0" class="collision"/>
          <geom type="box" pos="-0.13365173 0.03483723 -0.11241894" size="0.0038029812276363373 0.017222760245203972 0.028604567050933838" quat="0.9848077297210693 0.0 -0.0 -0.17364826798439026" class="collision"/>
          <geom type="box" pos="-0.11579987 0.06575760 -0.11241894" size="0.0038029812276363373 0.017222760245203972 0.028604567050933838" quat="0.9396926164627075 0.0 -0.0 -0.3420201539993286" class="collision"/>
          <geom type="box" pos="-0.08844920 0.08870754 -0.11241894" size="0.003802981460466981 0.01722276210784912 0.028604567050933838" quat="0.866025447845459 0.0 -0.0 -0.4999999701976776" class="collision"/>
          <geom type="box" pos="-0.05489862 0.10091894 -0.11241894" size="0.0038029812276363373 0.01722276210784912 0.028604567050933838" quat="0.7660444378852844 0.0 -0.0 -0.6427876353263855" class="collision"/>
          <geom type="box" pos="-0.01919486 0.10091895 -0.11241894" size="0.0038029812276363373 0.017222760245203972 0.028604567050933838" quat="0.6427875757217407 0.0 -0.0 -0.7660444974899292" class="collision"/>
          <geom type="box" pos="0.01435571 0.08870755 -0.11241894" size="0.003802981460466981 0.017222760245203972 0.028604567050933838" quat="0.5000000596046448 0.0 -0.0 -0.8660253882408142" class="collision"/>
          <geom type="box" pos="0.04170640 0.06575760 -0.11241894" size="0.0038029812276363373 0.017222760245203972 0.028604567050933838" quat="0.3420201539993286 0.0 -0.0 -0.9396926164627075" class="collision"/>
          <geom type="box" pos="0.05955828 0.03483723 -0.11241894" size="0.0038029812276363373 0.01722276210784912 0.028604567050933838" quat="0.17364822328090668 0.0 -0.0 -0.9848077297210693" class="collision"/>
          <geom type="box" pos="0.06575818 -0.00032410 -0.12854474" size="0.0038030410651117563 0.017223019152879715 0.01309843361377716" quat="1.0 0.0 0.0 0.0" class="collision"/>
          <geom type="box" pos="0.05955828 -0.03548547 -0.11241894" size="0.0038029812276363373 0.01722276210784912 0.028604567050933838" quat="0.17364822328090668 0.0 0.0 0.9848077297210693" class="collision"/>
          <geom type="box" pos="0.04170638 -0.06640586 -0.11241894" size="0.0038029812276363373 0.017222760245203972 0.028604567050933838" quat="0.34202027320861816 0.0 0.0 0.9396925568580627" class="collision"/>
          <geom type="box" pos="0.01435572 -0.08935579 -0.11241894" size="0.003802981460466981 0.017222760245203972 0.028604567050933838" quat="0.5000000596046448 0.0 0.0 0.8660253882408142" class="collision"/>
          <geom type="box" pos="-0.00588152 -0.09987818 -0.11241894" size="0.0038029809948056936 0.01052257139235735 0.028604567050933838" quat="0.6427876353263855 0.0 0.0 0.7660444378852844" class="collision"/>
          <geom type="box" pos="-0.06731777 -0.09938142 -0.11241894" size="0.0038029816932976246 0.01019357517361641 0.028604567050933838" quat="0.7660444378852844 0.0 0.0 0.6427876353263855" class="collision"/>
          <geom type="box" pos="-0.08844922 -0.08935577 -0.11241894" size="0.003802981460466981 0.01722276210784912 0.028604567050933838" quat="0.8660255074501038 0.0 0.0 0.4999997913837433" class="collision"/>
          <geom type="box" pos="-0.11579988 -0.06640583 -0.11241894" size="0.0038029812276363373 0.017222760245203972 0.028604567050933838" quat="0.9396926164627075 0.0 0.0 0.3420201539993286" class="collision"/>
          <geom type="box" pos="-0.13365176 -0.03548540 -0.11241894" size="0.0038029812276363373 0.01722276210784912 0.028604567050933838" quat="0.9848077893257141 0.0 0.0 0.1736479252576828" class="collision"/>
          <geom type="box" pos="0.05936805 0.00000791 0.03026299" size="0.00857990700751543 0.03885626792907715 0.11858449876308441" quat="0.9996725916862488 -7.246983609625259e-16 -0.025587743148207664 -3.437939488648567e-09" class="collision"/>
          <geom type="box" pos="-0.12398712 0.00061809 0.13238326" size="0.0032161162234842777 0.014564995653927326 0.028536276891827583" quat="1.0 0.0 0.0 0.0" class="collision"/>
          <geom type="box" pos="-0.11874396 0.03035345 0.13238326" size="0.0032161164563149214 0.014564993791282177 0.028536276891827583" quat="0.9848077297210693 0.0 -0.0 -0.17364826798439026" class="collision"/>
          <geom type="box" pos="-0.10364693 0.05650230 0.13238326" size="0.003216115990653634 0.014564993791282177 0.028536276891827583" quat="0.9396926164627075 0.0 -0.0 -0.3420201539993286" class="collision"/>
          <geom type="box" pos="-0.08051693 0.07591065 0.13238326" size="0.0032161157578229904 0.014564994722604752 0.028536276891827583" quat="0.866025447845459 0.0 -0.0 -0.4999999701976776" class="collision"/>
          <geom type="box" pos="-0.05214375 0.08623762 0.13238326" size="0.003216118086129427 0.014564991928637028 0.028536276891827583" quat="0.7660444378852844 0.0 -0.0 -0.6427876353263855" class="collision"/>
          <geom type="box" pos="-0.02194970 0.08623765 0.13238326" size="0.0032161162234842777 0.014564993791282177 0.028536276891827583" quat="0.6427875757217407 0.0 -0.0 -0.7660444974899292" class="collision"/>
          <geom type="box" pos="0.00642345 0.07591067 0.13238326" size="0.0032161162234842777 0.014564992859959602 0.028536276891827583" quat="0.5000000596046448 0.0 -0.0 -0.8660253882408142" class="collision"/>
          <geom type="box" pos="0.02955346 0.05650228 0.13238326" size="0.0032161162234842777 0.014564995653927326 0.028536276891827583" quat="0.3420201539993286 0.0 -0.0 -0.9396926164627075" class="collision"/>
          <geom type="box" pos="0.04465048 0.03035344 0.13238326" size="0.0032161155249923468 0.01456499844789505 0.028536276891827583" quat="0.17364822328090668 0.0 -0.0 -0.9848077297210693" class="collision"/>
          <geom type="box" pos="0.04989364 0.00061811 0.13320265" size="0.003216096665710211 0.014564995653927326 0.026827065274119377" quat="1.0 0.0 0.0 0.0" class="collision"/>
          <geom type="box" pos="0.04465050 -0.02911726 0.13238326" size="0.003216116689145565 0.014564999379217625 0.028536276891827583" quat="0.17364822328090668 0.0 0.0 0.9848077297210693" class="collision"/>
          <geom type="box" pos="0.02955345 -0.05526611 0.13238326" size="0.0032161178532987833 0.014564999379217625 0.028536276891827583" quat="0.34202027320861816 0.0 0.0 0.9396925568580627" class="collision"/>
          <geom type="box" pos="0.00642345 -0.07467447 0.13238326" size="0.003216116689145565 0.014564994722604752 0.028536276891827583" quat="0.5000000596046448 0.0 0.0 0.8660253882408142" class="collision"/>
          <geom type="box" pos="-0.08051699 -0.07467446 0.13238326" size="0.003216116689145565 0.01456499844789505 0.028536276891827583" quat="0.8660255074501038 0.0 0.0 0.4999997913837433" class="collision"/>
          <geom type="box" pos="-0.10364693 -0.05526609 0.13238326" size="0.0032161178532987833 0.014564997516572475 0.028536276891827583" quat="0.9396926164627075 0.0 0.0 0.3420201539993286" class="collision"/>
          <geom type="box" pos="-0.11874402 -0.02911720 0.13238326" size="0.003216116689145565 0.01456499844789505 0.028536276891827583" quat="0.9848077893257141 0.0 0.0 0.1736479252576828" class="collision"/>
          <geom type="box" pos="-0.02211409 -0.08505347 0.13238326" size="0.0032161164563149214 0.014564997516572475 0.028536276891827583" quat="0.6365191340446472 0.0 0.0 0.7712609171867371" class="collision"/>
          <geom type="box" pos="-0.05230412 -0.08554589 0.13238326" size="0.0032161178532987833 0.014564997516572475 0.028536276891827583" quat="0.7607770562171936 0.0 0.0 0.649013340473175" class="collision"/>
          <geom class="collision" type="box" pos="0.06318591 -0.00077526 0.12052153" size="0.023810403421521187 0.021033577620983124 0.024949699640274048" quat="6.761706572433468e-08 -0.18729208409786224 2.01860661519504e-08 -0.9823042750358582" name="handle_1"/>
          <geom class="collision" type="box" pos="0.09693900 -0.00077526 0.10052650" size="0.02381039783358574 0.021033577620983124 0.020623112097382545" quat="1.4059237685160042e-07 -0.4023577868938446 7.342559893430689e-09 -0.9154825210571289" name="handle_2"/>
          <geom class="collision" type="box" pos="0.13060802 -0.00077525 0.02952776" size="0.020921437069773674 0.021033460274338722 0.0654262974858284" quat="1.0 0.0 0.0 0.0" name="handle_main"/>
          <geom class="collision" type="box" pos="0.10794544 -0.00077524 -0.04494194" size="0.023810401558876038 0.021033577620983124 0.016938816756010056" quat="1.8325357586945756e-07 0.9143844246864319 -2.8854032052549883e-07 0.40484702587127686" name="handle_3"/>
          <geom class="collision" type="box" pos="0.07896181 -0.00077524 -0.06567073" size="0.02381039969623089 0.021033577620983124 0.019156059250235558" quat="1.304392043266489e-07 0.9797647595405579 -2.915321033469809e-07 0.20015253126621246" name="handle_4"/>
          <geom type="box" pos="0.02318280 -0.00000002 0.15415818" size="0.023765312507748604 0.0646960437297821 0.005883368197828531" quat="1.0 0.0 0.0 0.0" class="collision"/>
          <geom type="box" pos="-0.13665007 0.00061809 0.13768404" size="0.0032161162234842777 0.014564995653927326 0.020097581669688225" quat="0.9665632843971252 2.1661724131549938e-15 -0.25642818212509155 -3.4453400132861134e-08" class="collision"/>
          <geom type="box" pos="-0.12268750 0.03013106 0.13768404" size="0.0032161162234842777 0.025760723277926445 0.020097581669688225" quat="0.906714141368866 -0.08883118629455566 -0.24055026471614838 -0.33483436703681946" class="collision"/>
          <geom type="box" pos="-0.12614256 -0.02718220 0.13768404" size="0.0032161162234842777 0.025760723277926445 0.020097581669688225" quat="0.912358820438385 0.0846657082438469 -0.24204778671264648 0.3191332519054413" class="collision"/>
          <geom type="box" pos="-0.02694730 -0.10359265 -0.11241894" size="0.0038029809948056936 0.01052257139235735 0.028604567050933838" quat="0.6427876353263855 0.0 0.0 0.7660444378852844" class="collision"/>
          <geom type="box" pos="-0.04599904 -0.10423942 -0.11241894" size="0.0038029812276363373 0.010522570461034775 0.028604567050933838" quat="0.7489557266235352 0.0 0.0 0.6626200675964355" class="collision"/>
          <body name="button_lid">
            <joint axis="0.0 8.881784197001252e-15 -1.0" pos="0.02660317 0.00014485 0.16432958" limited="true" name="button_lid_joint" range="0.0 0.003" type="slide" damping="1" frictionloss="1" armature=".01" stiffness="0.5" springref="-0.5"/>
            <geom mesh="button_lid_vis" type="mesh" solimp="0.998 0.998 0.001" solref="0.001 1" friction="0.95 0.3 0.1" class="visual" material="button_lid_material"/>
            <geom class="collision" type="cylinder" pos="0.02671923 0.00014473 0.16725603" size="0.017381543293595314 0.002769363345578313" quat="1.0 0.0 0.0 0.0" name="button_lid_main"/>
          </body>
          <body name="kettle_main_Clear">
            <geom mesh="kettle_main_Clear_vis" type="mesh" solimp="0.998 0.998 0.001" solref="0.001 1" friction="0.95 0.3 0.1" class="visual" material="kettle_main_Clear_material"/>
            <geom type="box" pos="-0.13348833 0.00064784 0.00799294" size="0.0035675864201039076 0.016156639903783798 0.0879131481051445" quat="1.0 0.0 0.0 0.0" class="collision"/>
            <geom type="box" pos="-0.12767217 0.03363280 0.00799294" size="0.003567586885765195 0.016156714409589767 0.08791357278823853" quat="0.9848077297210693 0.0 -0.0 -0.17364826798439026" class="collision"/>
            <geom type="box" pos="-0.11092526 0.06263930 0.00799294" size="0.0035675859544426203 0.016156716272234917 0.08791357278823853" quat="0.9396926164627075 0.0 -0.0 -0.3420201539993286" class="collision"/>
            <geom type="box" pos="-0.08526752 0.08416868 0.00799294" size="0.0035675859544426203 0.016156714409589767 0.08791357278823853" quat="0.866025447845459 0.0 -0.0 -0.4999999701976776" class="collision"/>
            <geom type="box" pos="-0.05379362 0.09562422 0.00799294" size="0.003567588049918413 0.016156714409589767 0.08791357278823853" quat="0.7660444378852844 0.0 -0.0 -0.6427876353263855" class="collision"/>
            <geom type="box" pos="-0.02029984 0.09562425 0.00799294" size="0.0035675866529345512 0.016156714409589767 0.08791357278823853" quat="0.6427875757217407 0.0 -0.0 -0.7660444974899292" class="collision"/>
            <geom type="box" pos="0.01117405 0.08416870 0.00799294" size="0.003567586885765195 0.016156714409589767 0.08791357278823853" quat="0.5000000596046448 0.0 -0.0 -0.8660253882408142" class="collision"/>
            <geom type="box" pos="0.03683180 0.06263928 0.00799294" size="0.0035675859544426203 0.016156718134880066 0.08791357278823853" quat="0.3420201539993286 0.0 -0.0 -0.9396926164627075" class="collision"/>
            <geom type="box" pos="0.05357869 0.03363279 0.00799294" size="0.003567585488781333 0.016156718134880066 0.08791357278823853" quat="0.17364822328090668 0.0 -0.0 -0.9848077297210693" class="collision"/>
            <geom type="box" pos="0.05939484 0.00064786 0.01051727" size="0.0035676194820553064 0.016156718134880066 0.08264859765768051" quat="1.0 0.0 0.0 0.0" class="collision"/>
            <geom type="box" pos="0.05357870 -0.03233711 0.00799294" size="0.003567586885765195 0.016156723722815514 0.08791357278823853" quat="0.17364822328090668 0.0 0.0 0.9848077297210693" class="collision"/>
            <geom type="box" pos="0.03683178 -0.06134361 0.00799294" size="0.003567588049918413 0.016156723722815514 0.08791357278823853" quat="0.34202027320861816 0.0 0.0 0.9396925568580627" class="collision"/>
            <geom type="box" pos="0.01117405 -0.08287300 0.00799294" size="0.003567586885765195 0.016156714409589767 0.08791357278823853" quat="0.5000000596046448 0.0 0.0 0.8660253882408142" class="collision"/>
            <geom type="box" pos="-0.08526759 -0.08287300 0.00799294" size="0.0035675864201039076 0.016156719997525215 0.08791357278823853" quat="0.8660255074501038 0.0 0.0 0.4999997913837433" class="collision"/>
            <geom type="box" pos="-0.11092527 -0.06134359 0.00799294" size="0.003567588049918413 0.016156719997525215 0.08791357278823853" quat="0.9396926164627075 0.0 0.0 0.3420201539993286" class="collision"/>
            <geom type="box" pos="-0.12767223 -0.03233705 0.00799294" size="0.003567587351426482 0.016156718134880066 0.08791357278823853" quat="0.9848077893257141 0.0 0.0 0.1736479252576828" class="collision"/>
            <geom type="box" pos="-0.02048220 -0.09438625 0.00799294" size="0.003567586187273264 0.016156716272234917 0.08791357278823853" quat="0.6365191340446472 0.0 0.0 0.7712609171867371" class="collision"/>
            <geom type="box" pos="-0.05397150 -0.09493250 0.00799294" size="0.003567588049918413 0.016156718134880066 0.08791357278823853" quat="0.7607770562171936 0.0 0.0 0.649013340473175" class="collision"/>
            <geom type="cylinder" pos="-0.03663462 0.00000002 -0.08399986" size="0.08498886227607727 0.00908235926181078" quat="1.0 0.0 0.0 0.0" class="collision"/>
          </body>
          <body name="lid">
            <joint axis="0.0 1.0 0.0" pos="-0.00450826 -0.00000389 0.16267686" limited="true" name="lid_joint" range="0.0 1.5707963267948966" type="hinge" damping="1" frictionloss="0.1" armature=".01" stiffness="0.05" springref="-6"/>
            <geom mesh="lid_vis" type="mesh" solimp="0.998 0.998 0.001" solref="0.001 1" friction="0.95 0.3 0.1" class="visual" material="lid_material"/>
            <geom class="collision" type="box" pos="-0.02614610 0.00000000 0.15675875" size="0.022182608023285866 0.06655722856521606 0.008596892468631268" quat="1.0 0.0 0.0 0.0" name="lid_main"/>
            <geom class="collision" type="box" pos="-0.07589929 0.00003862 0.15675875" size="0.029840057715773582 0.025471679866313934 0.008596925064921379" quat="1.0 0.0 0.0 0.0" name="lid_1"/>
            <geom class="collision" type="box" pos="-0.06403767 0.04109196 0.15675875" size="0.01466391235589981 0.019164545461535454 0.008596925064921379" quat="1.0 0.0 0.0 0.0" name="lid_2"/>
            <geom class="collision" type="box" pos="-0.06403767 -0.04052017 0.15675875" size="0.01466391235589981 0.01916455663740635 0.008596925064921379" quat="1.0 0.0 0.0 0.0" name="lid_3"/>
            <geom class="collision" type="box" pos="-0.08555321 0.03196098 0.15675875" size="0.00975166168063879 0.012744667008519173 0.008596925064921379" quat="1.0 0.0 0.0 0.0" name="lid_4"/>
            <geom class="collision" type="box" pos="-0.08513340 -0.03185096 0.15675875" size="0.00975166168063879 0.012744667008519173 0.008596925064921379" quat="1.0 0.0 0.0 0.0" name="lid_5"/>
          </body>
          <body name="switch">
            <joint axis="0.0 0.0 -1.0" pos="0.07244617 -0.00010131 -0.10419340" limited="true" name="switch_joint" range="0.0 0.003" type="slide" damping="1" frictionloss="1" armature=".01" stiffness="0.05" springref="-2.0"/>
            <geom mesh="switch_vis" type="mesh" solimp="0.998 0.998 0.001" solref="0.001 1" friction="0.95 0.3 0.1" class="visual" material="switch_material"/>
            <geom class="collision" type="cylinder" pos="0.11713517 -0.00007841 -0.10388936" size="0.01972413808107376 0.003606347134336829" quat="1.0 0.0 0.0 0.0" name="switch_main"/>
            <geom type="box" pos="0.08062357 0.00000000 -0.10457336" size="0.018911199644207954 0.010567450895905495 0.003926997538655996" quat="1.0 0.0 0.0 0.0" class="collision"/>
          </body>
        </body>
        <geom class="region" name="reg_main" type="box" pos="0.0 -2.999999999808711e-08 2.7499999999403e-07" size="0.15051372 0.11393177 0.170677095"/>
      </body>
    </body>
  </worldbody>
  <actuator>
    <!-- <motor name="kettle_main_joint_actuator" joint="kettle_main_joint" gear="10"/> -->
    <motor name="button_lid_joint_actuator" joint="button_lid_joint" gear="0.5"/>
    <motor name="lid_joint_actuator" joint="lid_joint" gear="0.5"/>
    <motor name="switch_joint_actuator" joint="switch_joint" gear="0.3"/>
  </actuator>
</mujoco>