<?xml version='1.0' encoding='UTF-8'?>
<mujoco model="model">
  <option timestep="0.002" gravity="0.0 0.0 -9.81"/>
  <compiler angle="radian"/>
  <asset>
    <mesh file="visuals/door.obj" name="door_vis"/>
    <mesh file="visuals/knob_temp.obj" name="knob_temp_vis"/>
    <mesh file="visuals/knob_time.obj" name="knob_time_vis"/>
    <mesh file="visuals/rack0.obj" name="rack0_vis"/>
    <mesh file="visuals/Body001.obj" name="Body001_vis"/>
    <mesh file="visuals/window.obj" name="window_vis"/>
    <texture file="visuals/T_BC001.png" name="Body001_material" type="2d"/>
    <material name="Body001_material" rgba="1 1 1 1.0" texture="Body001_material" shininess="0.141421377658844" specular="2"/>
    <texture file="visuals/T_BC001.png" name="door_material" type="2d"/>
    <material name="door_material" rgba="1 1 1 1.0" texture="door_material" shininess="0.241421377658844" specular="1"/>
    <texture file="visuals/T_BC001.png" name="window_material" type="2d"/>
    <material name="window_material" rgba="1 1 1 0.7896907329559326" texture="window_material" shininess="0.141421377658844" specular="0.3103448502657381"/>
    <texture file="visuals/T_BC001.png" name="knob_temp_material" type="2d"/>
    <material name="knob_temp_material" rgba="1 1 1 1.0" texture="knob_temp_material" shininess="0.141421377658844" specular="0.3103448502657381"/>
    <texture file="visuals/T_BC001.png" name="knob_time_material" type="2d"/>
    <material name="knob_time_material" rgba="1 1 1 1.0" texture="knob_time_material" shininess="0.141421377658844" specular="0.3103448502657381"/>
    <texture file="visuals/T_BC001.png" name="rack0_material" type="2d"/>
    <material name="rack0_material" rgba="1 1 1 1.0" texture="rack0_material" shininess="0.141421377658844" specular="2"/>
  </asset>
  <default>
    <default class="visual">
      <geom conaffinity="0" contype="0" group="1" type="mesh"/>
    </default>
    <default class="collision">
      <geom group="0" rgba="0.5 0 0 0.5"/>
    </default>
    <default class="spawn">
      <geom group="0" rgba="1 1 1 0.5" contype="0" conaffinity="0"/>
      <site group="0" rgba="1 1 1 0.5"/>
    </default>
    <default class="region">
      <geom group="1" conaffinity="0" contype="0" rgba="0 1 0 0"/>
    </default>
  </default>
  <worldbody>
    <body>
      <body name="object">
        <geom mesh="Body001_vis" type="mesh" solimp="0.998 0.998 0.001" solref="0.001 1" friction="0.95 0.3 0.1" class="visual" material="Body001_material"/>
        <geom class="collision" type="box" pos="-0.23984715 0.03170668 0.00923254" size="0.016103293746709824 0.16864113509655 0.1361086219549179" quat="1.0 0.0 0.0 0.0"/>
        <geom class="collision" type="box" pos="-0.04529931 0.01482415 -0.14198300" size="0.2106505185365677 0.18552252650260925 0.01835312321782112" quat="1.0 0.0 0.0 0.0"/>
        <geom class="collision" type="box" pos="-0.04692912 0.18550963 0.01382422" size="0.20902132987976074 0.014838124625384808 0.14651153981685638" quat="1.0 0.0 0.0 0.0"/>
        <geom class="collision" type="box" pos="0.20139016 0.01482457 0.00000001" size="0.05456048622727394 0.18552327156066895 0.16033624112606049" quat="1.0 0.0 0.0 0.0"/>
        <geom class="collision" type="box" pos="-0.04485186 0.01482443 0.15161811" size="0.2110985964536667 0.18552300333976746 0.008718099445104599" quat="1.0 0.0 0.0 0.0"/>
        <geom class="collision" type="box" pos="-0.22304827 0.03042528 -0.00378089" size="0.008748199790716171 0.14672890305519104 0.016295943409204483" quat="1.0 0.0 0.0 0.0"/>
        <geom class="collision" type="box" pos="-0.22304827 0.03042528 -0.04195267" size="0.008748199790716171 0.14672890305519104 0.016295943409204483" quat="1.0 0.0 0.0 0.0"/>
        <geom class="collision" type="box" pos="0.14577189 0.03042528 -0.00440377" size="0.008748222142457962 0.1467292159795761 0.01597226783633232" quat="1.0 0.0 0.0 0.0"/>
        <geom class="collision" type="box" pos="0.14577189 0.03042528 -0.04197511" size="0.008748199790716171 0.14672890305519104 0.016295943409204483" quat="1.0 0.0 0.0 0.0"/>
        <geom class="collision" type="box" pos="-0.24124980 -0.15325397 0.00923254" size="0.014700651168823242 0.01744471862912178 0.13610891997814178" quat="1.0 0.0 0.0 0.0"/>
        <body name="door">
          <joint axis="1.0 0.0 0.0" pos="-0.03938596 -0.16686032 -0.12208751" limited="true" name="door_joint" range="0.0 1.5707963267948966" type="hinge" damping="1" frictionloss="1" armature=".01" stiffness="0.5" springref="-0.4"/>
          <geom mesh="door_vis" type="mesh" solimp="0.998 0.998 0.001" solref="0.001 1" friction="0.95 0.3 0.1" class="visual" material="door_material"/>
          <geom class="collision" type="box" pos="-0.03934085 -0.16711044 0.01127480" size="0.18538400530815125 0.0035882568918168545 0.12862595915794373" quat="1.0 0.0 0.0 0.0" name="door_main"/>
          <geom class="collision" type="box" pos="0.11659695 -0.18369199 0.11418281" size="0.019696667790412903 0.005493865814059973 0.013131000101566315" quat="1.814838412883546e-07 0.9320859909057617 0.36223703622817993 7.053017014868601e-08"/>
          <geom class="collision" type="box" pos="-0.04008418 -0.19370061 0.11387166" size="0.1399654597043991 0.005172303412109613 0.01313098892569542" quat="1.0 0.0 0.0 0.0" name="door_handle_main"/>
          <geom class="collision" type="box" pos="-0.19830747 -0.18340960 0.11418281" size="0.020143670961260796 0.005374647676944733 0.013131000101566315" quat="0.9129475355148315 0.0 -0.0 -0.4080769717693329"/>
          <body name="window">
            <geom mesh="window_vis" type="mesh" solimp="0.998 0.998 0.001" solref="0.001 1" friction="0.95 0.3 0.1" class="visual" material="window_material"/>
            <geom class="collision" type="box" pos="-0.04120736 -0.16582557 0.00830135" size="0.1293821483850479 0.001589049817994237 0.07643870264291763" quat="1.0 0.0 0.0 0.0"/>
          </body>
        </body>
        <body name="knob_temp">
          <joint axis="0.0 1.0 0.0" pos="0.20182766 -0.18567112 0.07832259" limited="true" name="knob_temp_joint" range="0.0 4.39822971502571" type="hinge" damping="0.05" frictionloss="0.1" armature="0.001"/>
          <geom mesh="knob_temp_vis" type="mesh" solimp="0.998 0.998 0.001" solref="0.001 1" friction="0.95 0.3 0.1" class="visual" material="knob_temp_material"/>
          <geom class="collision" type="box" pos="0.20195419 -0.19133181 0.07804938" size="0.009441480040550232 0.009057309478521347 0.024213304743170738" quat="0.894934356212616 0.0 0.44619786739349365 0.0" name="knob_temp_main" density="0.001"/>
          <geom class="collision" type="cylinder" pos="0.20174049 -0.18061746 0.07826789" size="0.024659136310219765 0.007099910639226437" quat="0.7071067094802856 0.7071068286895752 0.0 0.0" density="0.001"/>
        </body>
        <body name="knob_time">
          <joint axis="0.0 1.0 0.0" pos="0.20206685 -0.18269534 -0.07867224" limited="true" name="knob_time_joint" range="0.0 3.9269908169872414" type="hinge" damping="0.05" armature="0.001"/>
          <geom mesh="knob_time_vis" type="mesh" solimp="0.998 0.998 0.001" solref="0.001 1" friction="0.95 0.3 0.1" class="visual" material="knob_time_material"/>
          <geom class="collision" type="box" pos="0.20159622 -0.18934749 -0.07830635" size="0.009441480040550232 0.009057312272489071 0.024213304743170738" quat="1.0 0.0 0.0 0.0" name="knob_time_main"/>
          <geom class="collision" type="cylinder" pos="0.20227078 -0.17881140 -0.07853217" size="0.024659136310219765 0.0063616069965064526" quat="0.7071067094802856 0.7071068286895752 0.0 0.0"/>
        </body>
        <body name="rack0">
          <geom class="region" name="reg_rack0" type="box" pos="-0.038268575000000006 0.011495109999999996 0.05530337" size="0.15086523500000001 0.11990045999999999 0.08626231"/>
          <joint axis="0.0 -1.0 0.0" pos="-0.03900466 0.01150059 -0.02509472" limited="true" name="rack0_joint" range="0.0 0.22" type="slide" damping="1" frictionloss="1" armature=".01" stiffness="0.05"/>
          <geom mesh="rack0_vis" type="mesh" solimp="0.998 0.998 0.001" solref="0.001 1" friction="0.95 0.3 0.1" class="visual" material="rack0_material"/>
          <geom class="collision" type="box" pos="-0.03834916 0.01171809 -0.03312175" size="0.1529725193977356 0.12284987419843674 0.0030371074099093676" quat="1.0 0.0 0.0 0.0"/>
          <geom class="collision" type="box" pos="-0.21134125 0.01163783 -0.02340786" size="0.009668748825788498 0.12300089001655579 0.001667578355409205" quat="1.0 0.0 0.0 0.0"/>
          <geom class="collision" type="box" pos="-0.19678137 0.01163126 -0.02819809" size="0.009363675490021706 0.12300733476877213 0.0017728143138810992" quat="0.9440328478813171 -2.0632493047401113e-08 0.3298514187335968 7.209131958063608e-09"/>
          <geom class="collision" type="box" pos="0.12001006 0.01163126 -0.02819809" size="0.009363675490021706 0.12300733476877213 0.001772815827280283" quat="7.127249546101666e-08 -0.9440328478813171 -2.4903089368422116e-08 -0.3298514187335968"/>
          <geom class="collision" type="box" pos="0.13322128 0.01163783 -0.02340786" size="0.009668748825788498 0.12300089001655579 0.0016675770748406649" quat="1.0 0.0 0.0 0.0"/>
        </body>
        <geom class="region" name="reg_main" type="box" pos="0.0 0.014824564999999998 0.0" size="0.25695045 0.186523275 0.16133623"/>
      </body>
    </body>
  </worldbody>
  <actuator>
    <motor name="door_joint_actuator" joint="door_joint" gear="20"/>
    <motor name="knob_temp_joint_actuator" joint="knob_temp_joint" gear="10"/>
    <motor name="knob_time_joint_actuator" joint="knob_time_joint" gear="10"/>
    <motor name="rack0_joint_actuator" joint="rack0_joint" gear="30"/>
  </actuator>
</mujoco>
