<?xml version='1.0' encoding='UTF-8'?>
<mujoco model="model">
  <option timestep="0.002" gravity="0.0 0.0 -9.81"/>
  <compiler angle="radian"/>
  <asset>
    <mesh file="visuals/handle.obj" name="handle_vis"/>
    <mesh file="visuals/Body001.obj" name="Body001_vis"/>
    <mesh file="visuals/spout.obj" name="spout_vis"/>
    <texture file="visuals/T_BC001.png" name="Body001_material" type="2d"/>
    <material name="Body001_material" rgba="1 1 1 1.0" texture="Body001_material" shininess="0.1" specular="4"/>
    <texture file="visuals/T_BC001.png" name="handle_material" type="2d"/>
    <material name="handle_material" rgba="1 1 1 1.0" texture="handle_material" shininess="0.1" specular="4"/>
    <texture file="visuals/T_BC001.png" name="spout_material" type="2d"/>
    <material name="spout_material" rgba="1 1 1 1.0" texture="spout_material" shininess="0.1" specular="4"/>
  </asset>
  <default>
    <default class="visual">
      <geom conaffinity="0" contype="0" group="1" type="mesh"/>
    </default>
    <default class="collision">
      <geom group="0" rgba="0.5 0 0 0.5"/>
    </default>
    <default class="spawn">
      <geom group="0" rgba="1 1 1 0.5" contype="0" conaffinity="0"/>
      <site group="0" rgba="1 1 1 0.5"/>
    </default>
    <default class="region">
      <geom group="1" conaffinity="0" contype="0" rgba="0 1 0 0"/>
    </default>
  </default>
  <worldbody>
    <body>
      <body name="object">
        <geom mesh="Body001_vis" type="mesh" solimp="0.998 0.998 0.001" solref="0.001 1" friction="0.95 0.3 0.1" class="visual" material="Body001_material"/>
        <geom class="collision" type="box" pos="-0.46494564414024353 -3.725290298461914e-08 -0.15274174511432648" size="0.00526255089789629 0.22168999910354614 0.1083621233701706" quat="1.0 0.0 0.0 0.0"/>
        <geom class="collision" type="box" pos="0.2809807062149048 0.0 -0.05791960656642914" size="0.21534903347492218 0.2463299036026001 0.013540014624595642" quat="1.0 0.0 0.0 0.0"/>
        <geom class="collision" type="box" pos="-0.22511747479438782 0.21577562391757965 -0.15274173021316528" size="0.23433896899223328 0.005914333276450634 0.10836213827133179" quat="1.0 0.0 0.0 0.0"/>
        <geom class="collision" type="box" pos="-0.22511747479438782 -0.21584121882915497 -0.15274174511432648" size="0.23433896899223328 0.005848739296197891 0.1083620935678482" quat="1.0 0.0 0.0 0.0"/>
        <geom class="collision" type="box" pos="0.004479175433516502 -0.0001220703125 -0.1622358113527298" size="0.004742255434393883 0.20761872828006744 0.09886802732944489" quat="1.0 0.0 0.0 0.0"/>
        <geom class="collision" type="box" pos="-0.22905099391937256 -0.0001220703125 -0.24504411220550537" size="0.23025718331336975 0.20973381400108337 0.0160597562789917" quat="1.0 0.0 0.0 0.0"/>
        <geom class="collision" type="box" pos="-0.2297610491514206 -0.00018372759222984314 -0.25355565547943115" size="0.029758846387267113 0.0289392601698637 0.007548192515969276" quat="1.0 0.0 0.0 0.0"/>
        <geom class="collision" type="box" pos="0.03253858536481857 -0.19159090518951416 -0.05399749055504799" size="0.03280166536569595 0.018068870529532433 0.009617896750569344" quat="1.0 0.0 0.0 0.0"/>
        <geom class="collision" type="box" pos="0.03253858536481857 0.1905437558889389 -0.05399752035737038" size="0.03280166536569595 0.018068870529532433 0.009617866948246956" quat="1.0 0.0 0.0 0.0"/>
        <geom class="collision" type="cylinder" pos="0.06282471120357513 0.21369335055351257 0.011515638791024685" size="0.01693006418645382 0.010373175144195557" quat="0.7071068286895752 -0.0 0.7071067690849304 0.0"/>
        <geom class="collision" type="cylinder" pos="0.032461803406476974 0.21311423182487488 0.001127038151025772" size="0.023737186565995216 0.044803354889154434" quat="1.0 0.0 0.0 0.0"/>
        <geom class="collision" type="box" pos="-0.4779931306838989 -4.3213367462158203e-07 -0.05791971832513809" size="0.0183100588619709 0.2463027536869049 0.013540113344788551" quat="1.0 0.0 0.0 0.0"/>
        <geom class="collision" type="box" pos="-0.19333596527576447 0.228084996342659 -0.05791974067687988" size="0.2661204934120178 0.018223706632852554 0.013540130108594894" quat="1.0 0.0 0.0 0.0"/>
        <geom class="collision" type="box" pos="-0.19583700597286224 -0.22815737128257751 -0.05791956186294556" size="0.26361942291259766 0.01816488616168499 0.013540089130401611" quat="1.0 0.0 0.0 0.0"/>
        <geom class="collision" type="box" pos="0.03317368030548096 -0.0001220703125 -0.06791914254426956" size="0.033436767756938934 0.20761872828006744 0.003540582722052932" quat="1.0 0.0 0.0 0.0"/>
        <body name="handle">
          <joint axis="1.0 0.0 0.0" pos="0.08706565946340561 0.213865727186203 0.011550354771316051" limited="true" name="handle_temp_joint" type="hinge" range="-0.7853981633974483 0.7853981633974483" damping="1" frictionloss="1" armature=".01" stiffness="0.01" springref="-0.01"/>
          <joint axis="0.0 1.0 0.0" pos="0.08706565946340561 0.213865727186203 0.011550354771316051" limited="true" name="handle_joint" type="hinge" range="0 0.5" damping="1" frictionloss="1" armature=".01" stiffness="0.01" springref="-0.01"/>
          <geom mesh="handle_vis" type="mesh" solimp="0.998 0.998 0.001" solref="0.001 1" friction="0.95 0.3 0.1" class="visual" material="handle_material"/>
          <geom class="collision" type="cylinder" pos="0.09450801461935043 0.21369335055351257 0.011515636928379536" size="0.01685892790555954 0.006536256521940231" quat="0.7071068286895752 -0.0 0.7071067690849304 0.0"/>
          <geom class="collision" type="cylinder" pos="0.09118786454200745 0.21369335055351257 0.0617612823843956" size="0.004467882215976715 0.03439529985189438" quat="1.0 6.71794140316706e-08 6.145066907718233e-15 -6.717942113709796e-08"/>
        </body>
        <body name="spout">
          <joint axis="0.0 0.0 1.0" pos="0.032499492168426514 0.21374382078647614 0.15128037333488464" limited="true" name="spout_joint" range="-1.0471975511965976 1.0471975511965976" type="hinge" damping="1" frictionloss="1" armature=".01" stiffness="0.01" springref="-0.01"/>
          <site type="cylinder" rgba="0.5 0.75 1 0.5" size="0.007500000298023224 0.2263500690460205" pos="0.03237338364124298 -0.010179027915000916 -0.0039896368980407715" name="water"/>
          <geom mesh="spout_vis" type="mesh" solimp="0.998 0.998 0.001" solref="0.001 1" friction="0.95 0.3 0.1" class="visual" material="spout_material"/>
          <geom class="collision" type="cylinder" pos="0.032461799681186676 0.21370676159858704 0.11349726468324661" size="0.0151570038869977 0.06713789701461792" quat="1.0 0.0 0.0 0.0"/>
          <geom class="collision" type="cylinder" pos="0.032461803406476974 0.05527316778898239 0.24607573449611664" size="0.015157007612287998 0.09822708368301392" quat="0.7071067094802856 0.70710688829422 0.0 0.0" name="spout_main"/>
          <geom class="collision" type="cylinder" pos="0.032461803406476974 0.1671609878540039 0.24007338285446167" size="0.016099071130156517 0.021583354100584984" quat="0.8109226226806641 0.5851534008979797 0.0 0.0"/>
          <geom class="collision" type="cylinder" pos="0.032461803406476974 0.19277259707450867 0.22381256520748138" size="0.016146332025527954 0.018798397853970528" quat="0.9223295450210571 0.38640424609184265 0.0 0.0"/>
          <geom class="collision" type="cylinder" pos="0.032461803406476974 0.2090616375207901 0.19464395940303802" size="0.016237551346421242 0.022440042346715927" quat="0.9891262054443359 0.14706917107105255 0.0 0.0"/>
          <geom class="collision" type="cylinder" pos="0.032461803406476974 -0.009760892949998379 0.23331312835216522" size="0.011198245920240879 0.01170522440224886" quat="7.549790126404332e-08 1.0 0.0 0.0"/>
        </body>
        <geom class="region" name="reg_basin" type="box" pos="-0.22999398224055767 -0.00014901906251907349 -0.13642670214176178" size="0.22314923985302448 0.2047745639681816 0.08804669773578644"/>
        <geom class="region" name="reg_main" type="box" pos="7.450580596923828e-09 0.0 -0.15274173021316528" size="0.49732975459098816 0.2473299185037613 0.1093621084690094"/>
      </body>
    </body>
  </worldbody>
  <actuator>
    <motor name="handle_joint_actuator" joint="handle_joint" gear="10"/>
    <motor name="handle_temp_joint_actuator" joint="handle_temp_joint" gear="10"/>
    <motor name="spout_joint_actuator" joint="spout_joint" gear="10"/>
  </actuator>
</mujoco>
