<?xml version='1.0' encoding='UTF-8'?>
<mujoco model="model">
  <compiler angle="radian"/>
  <asset>
    <mesh file="visuals/Body001.obj" name="Body001_vis"/>
    <mesh file="visuals/Button001.obj" name="Button001_vis"/>
    <mesh file="visuals/Button002.obj" name="Button002_vis"/>
    <mesh file="visuals/Container001_Clear.obj" name="Container001_Clear_vis"/>
    <mesh file="visuals/Lever001.obj" name="Lever001_vis"/>
    <mesh file="visuals/Lid001.obj" name="Lid001_vis"/>
    <mesh file="visuals/Lid002.obj" name="Lid002_vis"/>
    <mesh file="visuals/Lid003.obj" name="Lid003_vis"/>
    <texture file="visuals/T_BC001.png" name="Body001_material" type="2d"/>
    <material name="Body001_material" rgba="1 1 1 1.0" texture="Body001_material" shininess="0.5" specular="0.3103448502657381"/>
    <texture file="visuals/T_BC001.png" name="Button001_material" type="2d"/>
    <material name="Button001_material" rgba="1 1 1 1.0" texture="Button001_material" shininess="0.5" specular="0.3103448502657381"/>
    <texture file="visuals/T_BC001.png" name="Button002_material" type="2d"/>
    <material name="Button002_material" rgba="1 1 1 1.0" texture="Button002_material" shininess="0.5" specular="0.3103448502657381"/>
    <texture file="visuals/T_BC001.png" name="Container001_Clear_material" type="2d"/>
    <material name="Container001_Clear_material" rgba="1 1 1 0.30000001192092896" texture="Container001_Clear_material" shininess="0.5" specular="0.3103448502657381"/>
    <texture file="visuals/T_BC001.png" name="Lid003_material" type="2d"/>
    <material name="Lid003_material" rgba="1 1 1 1.0" texture="Lid003_material" shininess="0.5" specular="0.3103448502657381"/>
    <texture file="visuals/T_BC001.png" name="Lever001_material" type="2d"/>
    <material name="Lever001_material" rgba="1 1 1 1.0" texture="Lever001_material" shininess="0.5" specular="0.3103448502657381"/>
    <texture file="visuals/T_BC001.png" name="Lid001_material" type="2d"/>
    <material name="Lid001_material" rgba="1 1 1 1.0" texture="Lid001_material" shininess="0.5" specular="0.3103448502657381"/>
    <texture file="visuals/T_BC001.png" name="Lid002_material" type="2d"/>
    <material name="Lid002_material" rgba="1 1 1 1.0" texture="Lid002_material" shininess="0.5" specular="0.3103448502657381"/>
  </asset>
  <default>
    <default class="visual">
      <geom conaffinity="0" contype="0" group="1" type="mesh"/>
    </default>
    <default class="collision">
      <geom group="0" rgba="0.5 0 0 0.5"/>
    </default>
    <default class="spawn">
      <geom group="0" rgba="1 1 1 0.5" contype="0" conaffinity="0"/>
      <site group="0" rgba="1 1 1 0.5"/>
    </default>
    <default class="region">
      <geom group="1" conaffinity="0" contype="0" rgba="0 1 0 0"/>
    </default>
  </default>
  <worldbody>
    <body>
      <body name="object">
        <geom class="collision" type="box" pos="0.03713391 -0.16052744 0.09030780" size="0.010415244847536087 0.010415244847536087 0.0008930626208893955" quat="0.7933533191680908 0.6087614297866821 -1.3517219117058102e-16 -2.6126816801125714e-24" name="start_button" rgba="0.0 0.5 0 0.5"/>
        <site type="cylinder" rgba="0.8 0.5 0.25 1" size="0.0027536980342119932 0.07233459502458572" pos="-0.00057711 -0.14727188 -0.06497024" name="coffee_liquid"/>
        <site rgba="0 0 0 0" size="0.009999999776482582 0.009999999776482582" pos="-0.00057711 -0.14727188 -0.11741403" name="receptacle_place_site"/>
        <geom mesh="Body001_vis" type="mesh" solimp="0.998 0.998 0.001" solref="0.001 1" density="100" friction="0.95 0.3 0.1" class="visual" material="Body001_material"/>
        <geom class="collision" type="box" pos="-0.00000000 0.03307621 -0.02438879" size="0.10385061055421829 0.13536663353443146 0.1417696475982666" quat="1.0 0.0 0.0 0.0"/>
        <geom class="collision" type="box" pos="0.00000000 0.16407360 0.12916711" size="0.10385061055421829 0.004345276392996311 0.013829709030687809" quat="1.0 0.0 0.0 0.0"/>
        <geom class="collision" type="box" pos="-0.09430110 0.10376639 0.12916711" size="0.05989970266819 0.007561163976788521 0.01382970716804266" quat="0.7071068286895752 0.0 -0.0 -0.7071067690849304"/>
        <geom class="collision" type="box" pos="0.09464195 0.10376639 0.12916711" size="0.05989970266819 0.007561163976788521 0.01382970716804266" quat="0.7071068286895752 0.0 -0.0 -0.7071067690849304"/>
        <geom class="collision" type="box" pos="0.00000000 -0.04454631 0.13065294" size="0.10385061055421829 0.08900878578424454 0.015315547585487366" quat="1.0 0.0 0.0 0.0"/>
        <geom class="collision" type="box" pos="0.00000000 0.04777525 0.13065294" size="0.04721876606345177 0.0055664400570094585 0.015315547585487366" quat="1.0 0.0 0.0 0.0"/>
        <geom class="collision" type="box" pos="0.00000000 0.05528834 0.13065294" size="0.03188616409897804 0.0018839340191334486 0.015315547585487366" quat="1.0 0.0 0.0 0.0"/>
        <geom class="collision" type="box" pos="-0.05927647 0.04657879 0.13065294" size="0.028971705585718155 0.004871274344623089 0.015315547585487366" quat="0.9953288435935974 0.0 0.0 0.09654258191585541"/>
        <geom class="collision" type="box" pos="0.05889073 0.04666360 0.13065294" size="0.028971707448363304 0.005043487995862961 0.015315547585487366" quat="9.394273803309261e-08 0.09654244780540466 0.9953288435935974 1.8650882793735946e-07"/>
        <geom class="collision" type="box" pos="0.00000000 -0.15991845 -0.14789786" size="0.10385061055421829 0.057872675359249115 0.017408352345228195" quat="1.0 0.0 0.0 0.0"/>
        <geom class="collision" type="box" pos="-0.05905307 -0.22045124 -0.14789786" size="0.030084267258644104 0.007930274121463299 0.017408352345228195" quat="0.9896388053894043 0.0 -0.0 -0.143579363822937"/>
        <geom class="collision" type="box" pos="0.05786028 -0.21949779 -0.14789786" size="0.030084259808063507 0.008903853595256805 0.017408352345228195" quat="5.1323603145192465e-08 -0.14357930421829224 0.9896388053894043 1.720726459097932e-07"/>
        <geom class="collision" type="box" pos="-0.02077106 -0.21924437 -0.14789786" size="0.01983846351504326 0.010606835596263409 0.017408352345228195" quat="0.9831233620643616 0.0 0.0 0.1829438954591751"/>
        <geom class="collision" type="box" pos="0.02036264 -0.21924437 -0.14789786" size="0.01983846351504326 0.010606835596263409 0.017408352345228195" quat="1.0984424392290748e-07 0.1829439103603363 0.9831233620643616 1.7760930859367363e-07"/>
        <geom class="collision" type="box" pos="0.00000000 -0.10145076 -0.11139267" size="0.10385061055421829 0.01613113470375538 0.010602785274386406" quat="0.5825121402740479 0.8128219842910767 -1.8048270990651252e-16 9.235185939952428e-24"/>
        <geom class="collision" type="box" pos="0.00000000 -0.10874397 -0.08185517" size="0.10385061055421829 0.01613113470375538 0.011195383034646511" quat="0.6141020655632019 0.7892266511917114 -1.7524350672527925e-16 -2.0004558034709542e-24"/>
        <geom class="collision" type="box" pos="0.00000000 -0.11056727 -0.05025125" size="0.10385061055421829 0.016131136566400528 0.015758054330945015" quat="0.6442039012908936 0.7648537755012512 -1.6983164117170412e-16 -1.4513890496866805e-23"/>
        <geom class="collision" type="box" pos="-0.00000000 -0.11421387 -0.01937666" size="0.10385061055421829 0.016131136566400528 0.015758054330945015" quat="0.6718460917472839 0.7406907677650452 -1.6446637566511777e-16 -1.333264544422343e-23"/>
        <geom class="collision" type="box" pos="-0.00000000 -0.11615872 0.01186259" size="0.10385061055421829 0.01613113470375538 0.015758052468299866" quat="0.6962460279464722 0.7178032398223877 -1.5938432356537978e-16 5.027924886283712e-24"/>
        <geom class="collision" type="box" pos="-0.00000000 -0.11640183 0.04492514" size="0.10385061055421829 0.017620937898755074 0.015758058056235313" quat="0.707630455493927 0.7065827250480652 -1.5689288203014966e-16 -2.733011761581816e-23"/>
        <geom class="collision" type="box" pos="0.00000000 -0.12866344 0.06937477" size="0.10385061055421829 0.026443947106599808 0.008293532766401768" quat="1.0 0.0 0.0 0.0"/>
        <geom class="collision" type="box" pos="0.00000000 -0.12572590 0.10741251" size="0.10385061055421829 0.023252753540873528 0.009452405385673046" quat="1.0 0.0 0.0 0.0"/>
        <geom class="collision" type="box" pos="0.00000000 -0.13281651 0.13091287" size="0.10385061055421829 0.005140719469636679 0.013905131258070469" quat="1.0 0.0 0.0 0.0"/>
        <geom class="collision" type="box" pos="0.00000000 -0.13933759 0.12856534" size="0.10385061055421829 0.005140719469636679 0.013905131258070469" quat="0.9797577261924744 -0.20018696784973145 4.4450442804778463e-17 2.0013975061765618e-24"/>
        <geom class="collision" type="box" pos="0.00000000 -0.14689518 0.10824386" size="0.10385061055421829 0.005140719469636679 0.007589207962155342" quat="0.9886624813079834 -0.15015475451946259 3.334105645361158e-17 -1.2039743046902811e-24"/>
        <geom class="collision" type="box" pos="0.00000000 -0.15790842 0.06995996" size="0.10385061055421829 0.005140719469636679 0.007705593015998602" quat="0.9922476410865784 -0.12427633255720139 2.7594894127279263e-17 5.797133688633858e-25"/>
        <geom class="collision" type="box" pos="0.00000000 -0.14624157 0.05254321" size="0.048668261617422104 0.01614558883011341 0.01374830026179552" quat="1.0 0.0 0.0 0.0"/>
        <geom class="collision" type="box" pos="0.00000000 -0.14713841 0.02989793" size="0.03141579404473305 0.010052923113107681 0.008940882049500942" quat="1.0 0.0 0.0 0.0"/>
        <geom class="collision" type="box" pos="0.00000000 -0.16510961 0.02290991" size="0.015898415818810463 0.008515176363289356 0.0010712944203987718" quat="1.0 0.0 0.0 0.0"/>
        <geom class="collision" type="cylinder" pos="-0.00084294 -0.14687551 0.01285360" size="0.007553964853286743 0.008512386120855808" quat="1.0 0.0 0.0 0.0"/>
        <geom class="collision" type="box" pos="0.00000000 -0.12620712 0.08785514" size="0.10385061055421829 0.02403733879327774 0.010288608260452747" quat="1.0 0.0 0.0 0.0"/>
        <geom class="collision" type="box" pos="-0.00045072 0.20370200 -0.14720555" size="0.0985279455780983 0.03189034387469292 0.017388582229614258" quat="1.0 0.0 0.0 0.0"/>
        <geom class="collision" type="box" pos="-0.07587539 -0.15268194 0.09005382" size="0.027956640347838402 0.005140719469636679 0.01253354363143444" quat="0.9922476410865784 -0.12427633255720139 2.7594894127279263e-17 5.797133688633858e-25"/>
        <geom class="collision" type="box" pos="0.07631868 -0.15279364 0.08961491" size="0.027513351291418076 0.005140719469636679 0.01208063866943121" quat="0.9922476410865784 -0.12427633255720139 2.7594894127279263e-17 5.797133688633858e-25"/>
        <geom class="collision" type="box" pos="0.00064848 -0.15279364 0.08961491" size="0.0239991694688797 0.005140719469636679 0.01208063866943121" quat="0.9922476410865784 -0.12427633255720139 2.7594894127279263e-17 5.797133688633858e-25"/>
        <body name="Button001">
          <joint axis="-1.4874174832110107e-17 0.9659257531166077 -0.2588190734386444" pos="-0.03626514 -0.15954406 0.08954591" limited="true" name="Button001_joint" range="0.0 0.003" type="slide" damping="1" frictionloss="1" armature=".01" stiffness="0.05" springref="-0.1"/>
          <geom mesh="Button001_vis" type="mesh" solimp="0.998 0.998 0.001" solref="0.001 1" density="100" friction="0.95 0.3 0.1" class="visual" material="Button001_material"/>
          <geom class="collision" type="cylinder" pos="-0.03626514 -0.15932435 0.09051259" size="0.010931293480098248 0.0022768608760088682" quat="0.7933533191680908 0.6087614297866821 -1.3517219117058102e-16 -2.6126816801125714e-24"/>
        </body>
        <body name="Button002">
          <joint axis="-1.4874174832110107e-17 0.9659257531166077 -0.2588190734386444" pos="0.03713391 -0.15929333 0.08997713" limited="true" name="Button002_joint" range="0.0 0.003" type="slide" damping="1" frictionloss="1" armature=".01" stiffness="0.05" springref="-0.1"/>
          <geom mesh="Button002_vis" type="mesh" solimp="0.998 0.998 0.001" solref="0.001 1" density="100" friction="0.95 0.3 0.1" class="visual" material="Button002_material"/>
          <geom class="collision" type="cylinder" pos="0.03713391 -0.15839385 0.08973610" size="0.010415244847536087 0.0008834953187033534" quat="0.7933533191680908 0.6087614297866821 -1.3517219117058102e-16 -2.6126816801125714e-24"/>
        </body>
        <body name="Container001_Clear">
          <joint axis="0.0 0.0 1.0" pos="-0.00059708 0.20353132 -0.01179617" limited="true" name="Container001_Clear_joint" range="0.0 0.1" type="slide" damping="1" frictionloss="1" armature=".01" stiffness="0.05"/>
          <geom mesh="Container001_Clear_vis" type="mesh" solimp="0.998 0.998 0.001" solref="0.001 1" density="100" friction="0.95 0.3 0.1" class="visual" material="Container001_Clear_material"/>
          <geom class="collision" type="box" pos="-0.00000000 0.23502151 0.00166822" size="0.08326917141675949 0.0012448341585695744 0.1288316249847412" quat="1.0 0.0 0.0 0.0"/>
          <geom class="collision" type="box" pos="-0.00000000 0.17230692 0.00166822" size="0.08326917141675949 0.0012448341585695744 0.1288316249847412" quat="1.0 0.0 0.0 0.0"/>
          <geom class="collision" type="box" pos="-0.09843681 0.20323775 0.00166822" size="0.02020031400024891 0.0012448341585695744 0.1288316249847412" quat="0.7071068286895752 0.0 -0.0 -0.7071067690849304"/>
          <geom class="collision" type="box" pos="0.09730802 0.20323775 0.00166822" size="0.02020031400024891 0.0012448341585695744 0.1288316249847412" quat="0.7071068286895752 0.0 -0.0 -0.7071067690849304"/>
          <geom class="collision" type="box" pos="-0.09664870 0.22643583 0.00166822" size="0.004168647341430187 0.0012448341585695744 0.1288316249847412" quat="0.529154360294342 0.0 -0.0 -0.8485255837440491"/>
          <geom class="collision" type="box" pos="-0.08710741 0.23427550 0.00166822" size="0.004168647341430187 0.0012448341585695744 0.1288316249847412" quat="0.1368826925754547 0.0 -0.0 -0.9905872344970703"/>
          <geom class="collision" type="box" pos="-0.09285042 0.23157112 0.00166822" size="0.002946387743577361 0.001244834391400218 0.1288316249847412" quat="0.3439255654811859 0.0 -0.0 -0.9389969110488892"/>
          <geom class="collision" type="box" pos="0.09575572 0.22643583 0.00166822" size="0.004168651532381773 0.0012448378838598728 0.1288316249847412" quat="1.1032908986408074e-07 -0.8485255837440491 0.529154360294342 3.424172589916452e-08"/>
          <geom class="collision" type="box" pos="0.08621443 0.23427550 0.00166822" size="0.0041686492040753365 0.0012448434717953205 0.1288316249847412" quat="1.879148925354457e-07 -0.9905872344970703 0.13688282668590546 -6.254319373510953e-08"/>
          <geom class="collision" type="box" pos="0.09195744 0.23157112 0.00166822" size="0.002946389140561223 0.0012448435882106423 0.1288316249847412" quat="1.928527098016275e-07 -0.9389968514442444 0.34392574429512024 -3.959896588412448e-08"/>
          <geom class="collision" type="box" pos="-0.09664870 0.18104782 0.00166822" size="0.004168651532381773 0.0012448378838598728 0.1288316249847412" quat="2.4111839636020704e-08 0.5291544795036316 0.8485255241394043 -1.0401195282838671e-07"/>
          <geom class="collision" type="box" pos="-0.08710741 0.17320816 0.00166822" size="0.004168650135397911 0.0012448378838598728 0.1288316249847412" quat="6.445291234058459e-08 0.13688266277313232 0.9905872941017151 -8.512154181516962e-08"/>
          <geom class="collision" type="box" pos="-0.09285042 0.17591254 0.00166822" size="0.002946391236037016 0.0012448380002751946 0.1288316249847412" quat="4.492661886956739e-08 0.34392574429512024 0.9389968514442444 -9.68579598747965e-08"/>
          <geom class="collision" type="box" pos="0.09575572 0.18104782 0.00166822" size="0.004168648272752762 0.0012448362540453672 0.1288316249847412" quat="0.8485255837440491 4.6267196296412294e-08 5.708320038877446e-09 0.529154360294342"/>
          <geom class="collision" type="box" pos="0.08621443 0.17320816 0.00166822" size="0.004168650135397911 0.0012448400957509875 0.1288316249847412" quat="0.9905872344970703 1.1312776848626527e-07 7.287757597396194e-08 0.13688282668590546"/>
          <geom class="collision" type="box" pos="0.09195744 0.17591254 0.00166822" size="0.002946388442069292 0.0012448407942429185 0.1288316249847412" quat="0.9389968514442444 1.2196042575851607e-07 6.556465592666427e-08 0.34392574429512024"/>
          <geom class="collision" type="box" pos="-0.00045072 0.20342095 -0.12290930" size="0.09727999567985535 0.030171487480401993 0.004045017994940281" quat="1.0 0.0 0.0 0.0"/>
          <body name="Lid003">
            <joint axis="0.0 0.0 1.0" pos="-0.00059706 0.20353132 0.13784590" limited="true" name="Lid003_joint" range="0.0 0.1" type="slide" damping="1" frictionloss="1" armature=".01" stiffness="0.05"/>
            <geom mesh="Lid003_vis" type="mesh" solimp="0.998 0.998 0.001" solref="0.001 1" density="100" friction="0.95 0.3 0.1" class="visual" material="Lid003_material"/>
            <geom class="collision" type="box" pos="-0.00045072 0.20342095 0.13810679" size="0.09930843114852905 0.03241795301437378 0.006119163706898689" quat="1.0 0.0 0.0 0.0"/>
            <geom class="collision" type="box" pos="0.00070895 0.20284503 0.16296745" size="0.03243435546755791 0.0029803814832121134 0.003190913936123252" quat="1.0 0.0 0.0 0.0"/>
            <geom class="collision" type="box" pos="0.02887899 0.20285269 0.15209257" size="0.0034317008685320616 0.0024682353250682354 0.007980492897331715" quat="1.0 0.0 0.0 0.0"/>
            <geom class="collision" type="box" pos="-0.02716607 0.20285269 0.15209257" size="0.0034317008685320616 0.0024682353250682354 0.007980492897331715" quat="1.0 0.0 0.0 0.0"/>
          </body>
        </body>
        <body name="Lever001">
          <joint axis="0.0 0.0 1.0" pos="-0.08446693 -0.14075716 0.06214121" limited="true" name="Lever001_joint" range="-0.7853981633974483 0.7853981633974483" type="hinge" damping="1" frictionloss="1" armature=".01" stiffness="0.01" springref="-0.1"/>
          <geom mesh="Lever001_vis" type="mesh" solimp="0.998 0.998 0.001" solref="0.001 1" density="100" friction="0.95 0.3 0.1" class="visual" material="Lever001_material"/>
          <geom class="collision" type="box" pos="-0.08446693 -0.20381953 0.02653662" size="0.0014831729931756854 0.011660904623568058 0.014016982167959213" quat="1.0 0.0 0.0 0.0"/>
          <geom class="collision" type="cylinder" pos="-0.08446693 -0.18326015 -0.01747613" size="0.00998516846448183 0.037780001759529114" quat="1.0 0.0 0.0 0.0"/>
          <geom class="collision" type="cylinder" pos="-0.08446693 -0.18326015 0.03036968" size="0.009125753305852413 0.010445179417729378" quat="1.0 0.0 0.0 0.0"/>
          <geom class="collision" type="cylinder" pos="-0.08446693 -0.16228027 0.05116348" size="0.0034377879928797483 0.011636033654212952" quat="0.7071068286895752 0.7071067690849304 -1.5700924318127872e-16 -5.9269340452702814e-24"/>
          <geom class="collision" type="cylinder" pos="-0.08446693 -0.17591803 0.05080828" size="0.0038652813527733088 0.0031983964145183563" quat="0.5620652437210083 0.8270928859710693 -1.8365151310175006e-16 1.6991271093250847e-24"/>
          <geom class="collision" type="cylinder" pos="-0.08446693 -0.17984394 0.04822840" size="0.0038652813527733088 0.0031983964145183563" quat="0.3725944757461548 0.9279942512512207 -2.0605611689177754e-16 1.6253715334722694e-23"/>
          <geom class="collision" type="cylinder" pos="-0.08446693 -0.18221817 0.04428381" size="0.0038652813527733088 0.0031983964145183563" quat="0.1722848266363144 0.9850471615791321 -2.1872468575804768e-16 1.99480882156702e-23"/>
          <geom class="collision" type="cylinder" pos="-0.08446693 -0.18289118 0.04022704" size="0.0038652813527733088 0.0031983964145183563" quat="0.008437251672148705 0.9999644160270691 -2.220367036958202e-16 9.246119552098791e-24"/>
          <geom class="collision" type="cylinder" pos="-0.08446693 -0.14861273 0.05176919" size="0.004256662912666798 0.0031790086068212986" quat="0.6109145283699036 0.7916965484619141 -1.7579197379351621e-16 5.969173996870793e-24"/>
          <geom class="collision" type="cylinder" pos="-0.08446693 -0.14427211 0.05341349" size="0.00401742197573185 0.0030003355350345373" quat="0.4699932634830475 0.882669985294342 -1.9599210816386537e-16 -1.6739328641645887e-24"/>
          <geom class="collision" type="cylinder" pos="-0.08446693 -0.14116474 0.05838943" size="0.004228831268846989 0.002063020132482052" quat="0.0038151212502270937 0.9999927282333374 -2.220429902684756e-16 1.1298587321633682e-23"/>
          <geom class="collision" type="cylinder" pos="-0.08446693 -0.14194426 0.05620464" size="0.004228831268846989 0.002535817679017782" quat="0.26043400168418884 0.9654916524887085 -2.143822125352709e-16 5.2777918448470365e-24"/>
        </body>
        <body name="Lid001">
          <joint axis="0.0 0.0 1.0" pos="0.00055729 -0.17087764 -0.12768974" limited="true" name="Lid001_joint" range="0.0 0.03" type="slide" damping="1" frictionloss="1" armature=".01" stiffness="0.05" springref="-15"/>
          <geom mesh="Lid001_vis" type="mesh" solimp="0.998 0.998 0.001" solref="0.001 1" density="100" friction="0.95 0.3 0.1" class="visual" material="Lid001_material"/>
          <geom class="collision" type="box" pos="0.00057311 -0.16393889 -0.12751197" size="0.09955251961946487 0.048658475279808044 0.0014220435405150056" quat="1.0 0.0 0.0 0.0"/>
          <geom class="collision" type="box" pos="0.00057311 -0.22185515 -0.12751197" size="0.025284498929977417 0.01186862587928772 0.0014220435405150056" quat="1.0 0.0 0.0 0.0"/>
          <geom class="collision" type="box" pos="-0.05701764 -0.21261220 -0.12751197" size="0.038862444460392 0.011868624947965145 0.0014220435405150056" quat="0.9915341734886169 0.0 -0.0 -0.12984591722488403"/>
          <geom class="collision" type="box" pos="0.05708201 -0.21261220 -0.12751197" size="0.038862444460392 0.011868624947965145 0.0014220435405150056" quat="5.3704201974369425e-08 -0.1298457533121109 0.9915342330932617 1.713444248707674e-07"/>
        </body>
        <body name="Lid002">
          <joint axis="-1.0 0.0 0.0" pos="0.00011047 0.16052873 0.14580327" limited="true" name="Lid002_joint" range="0.0 1.5707963267948966" type="hinge" damping="1" frictionloss="1" armature=".01" stiffness="0.05"/>
          <geom mesh="Lid002_vis" type="mesh" solimp="0.998 0.998 0.001" solref="0.001 1" density="100" friction="0.95 0.3 0.1" class="visual" material="Lid002_material"/>
          <geom class="collision" type="box" pos="-0.00045072 0.11174090 0.14615348" size="0.08798467367887497 0.049731526523828506 0.0021538978908210993" quat="1.0 0.0 0.0 0.0"/>
          <geom class="collision" type="box" pos="-0.02716607 0.06515391 0.15209257" size="0.0034317008685320616 0.0024682353250682354 0.007980492897331715" quat="1.0 0.0 0.0 0.0"/>
          <geom class="collision" type="box" pos="0.02887899 0.06515392 0.15209257" size="0.0034317008685320616 0.0024682353250682354 0.007980492897331715" quat="1.0 0.0 0.0 0.0"/>
          <geom class="collision" type="box" pos="0.00070895 0.06514626 0.16296745" size="0.03243435546755791 0.0029803814832121134 0.003190913936123252" quat="1.0 0.0 0.0 0.0"/>
        </body>
        <geom class="region" name="reg_main" type="box" pos="0.0 0.0006029999999999924 -0.008068000000000006" size="0.1027821 0.23622915 0.15700571000000002"/>
      </body>
    </body>
  </worldbody>
  <actuator>
    <motor name="Button001_joint_actuator" joint="Button001_joint" gear="0.5"/>
    <motor name="Button002_joint_actuator" joint="Button002_joint" gear="0.5"/>
    <motor name="Container001_Clear_joint_actuator" joint="Container001_Clear_joint" gear="10"/>
    <motor name="Lever001_joint_actuator" joint="Lever001_joint" gear="10"/>
    <motor name="Lid001_joint_actuator" joint="Lid001_joint" gear="10"/>
    <motor name="Lid002_joint_actuator" joint="Lid002_joint" gear="10"/>
    <motor name="Lid003_joint_actuator" joint="Lid003_joint" gear="10"/>
  </actuator>
</mujoco>
