<?xml version='1.0' encoding='UTF-8'?>
<mujoco model="model">
  <option timestep="0.002" gravity="0.0 0.0 -9.81"/>
  <compiler angle="radian"/>
  <asset>
    <mesh file="visuals/sideL_button_cancel.obj" name="sideL_button_cancel_vis"/>
    <mesh file="visuals/sideL_knob_doneness.obj" name="sideL_knob_doneness_vis"/>
    <mesh file="visuals/sideL_lever.obj" name="sideL_lever_vis"/>
    <mesh file="visuals/sideR_button_cancel.obj" name="sideR_button_cancel_vis"/>
    <mesh file="visuals/sideR_knob_doneness.obj" name="sideR_knob_doneness_vis"/>
    <mesh file="visuals/sideR_lever.obj" name="sideR_lever_vis"/>
    <mesh file="visuals/Body001.obj" name="Body001_vis"/>
    <mesh file="visuals/Body002.obj" name="Body002_vis"/>
    <texture file="visuals/T_BC001.png" name="Body001_material" type="2d"/>
    <material name="Body001_material" rgba="1 1 1 1.0" texture="Body001_material" shininess="0.5" specular="0.6"/>
    <texture file="visuals/T_BC001.png" name="sideL_button_cancel_material" type="2d"/>
    <material name="sideL_button_cancel_material" rgba="1 1 1 1.0" texture="sideL_button_cancel_material" shininess="0.5" specular="0.8"/>
    <texture file="visuals/T_BC001.png" name="sideL_knob_doneness_material" type="2d"/>
    <material name="sideL_knob_doneness_material" rgba="1 1 1 1.0" texture="sideL_knob_doneness_material" shininess="0.5" specular="0.8"/>
    <texture file="visuals/T_BC001.png" name="sideL_lever_material" type="2d"/>
    <material name="sideL_lever_material" rgba="1 1 1 1.0" texture="sideL_lever_material" shininess="0.5" specular="0.8"/>
    <texture file="visuals/T_BC001.png" name="sideR_button_cancel_material" type="2d"/>
    <material name="sideR_button_cancel_material" rgba="1 1 1 1.0" texture="sideR_button_cancel_material" shininess="0.5" specular="0.8"/>
    <texture file="visuals/T_BC001.png" name="sideR_knob_doneness_material" type="2d"/>
    <material name="sideR_knob_doneness_material" rgba="1 1 1 1.0" texture="sideR_knob_doneness_material" shininess="0.5" specular="0.8"/>
    <texture file="visuals/T_BC001.png" name="sideR_lever_material" type="2d"/>
    <material name="sideR_lever_material" rgba="1 1 1 1.0" texture="sideR_lever_material" shininess="0.5" specular="0.8"/>
    <texture file="visuals/T_BC001.png" name="Body002_material" type="2d"/>
    <material name="Body002_material" rgba="1 1 1 1.0" texture="Body002_material" shininess="0.5" specular="3"/>
  </asset>
  <default>
    <default class="visual">
      <geom conaffinity="0" contype="0" group="1" type="mesh"/>
    </default>
    <default class="collision_1">
      <geom group="0" rgba="0.5 0 0 0.5" solref="0.004 1" solimp="0.998 0.998 0.001"/>
    </default>
    <default class="collision_2">
      <geom group="0" rgba="0.5 0 0 0.5" solref="0.004 1" solimp="0.998 0.998 0.001"/>
    </default>
    <default class="collision_3">
      <geom group="0" rgba="0.5 0 0 0.5" solref="0.004 1" solimp="0.998 0.998 0.001"/>
    </default>
    <default class="collision_4">
      <geom group="0" rgba="0.5 0 0 0.5" solref="0.004 1" solimp="0.998 0.998 0.001"/>
    </default>
    <default class="collision_5">
      <geom group="0" rgba="0.5 0 0 0.5" solref="0.004 1" solimp="0.998 0.998 0.001"/>
    </default>
    <default class="collision_6">
      <geom group="0" rgba="0.5 0 0 0.5" solref="0.004 1" solimp="0.998 0.998 0.001"/>
    </default>
    <default class="collision_7">
      <geom group="0" rgba="0.5 0 0 0.5" solref="0.004 1" solimp="0.998 0.998 0.001"/>
    </default>
    <default class="collision_8">
      <geom group="0" rgba="0.5 0 0 0.5" solref="0.004 1" solimp="0.998 0.998 0.001"/>
    </default>
    <default class="spawn">
      <geom group="0" rgba="1 1 1 0.5" contype="0" conaffinity="0"/>
      <site group="0" rgba="1 1 1 0.5"/>
    </default>
    <default class="region">
      <geom group="1" conaffinity="0" contype="0" rgba="0 1 0 0" mass="0"/>
    </default>
  </default>
  <worldbody>
    <body>
      <body name="object">
        <geom mesh="Body001_vis" type="mesh" solimp="0.998 0.998 0.001" solref="0.001 1" friction="0.95 0.3 0.1" class="visual" material="Body001_material"/>
        <geom type="box" pos="0.0 0.1307358741760254 0.007763848640024662" size="0.18278317153453827 0.030968448147177696 0.11197870224714279" quat="1.0 0.0 0.0 0.0" class="collision_1"/>
        <geom type="box" pos="0.0 -0.10518806427717209 0.007763848640024662" size="0.18278315663337708 0.028775308281183243 0.11197870224714279" quat="1.0 0.0 0.0 0.0" class="collision_1"/>
        <geom type="box" pos="0.162806898355484 0.012079990468919277 0.007763849571347237" size="0.01963685266673565 0.08824531733989716 0.11198690533638" quat="1.0 0.0 0.0 0.0" class="collision_1"/>
        <geom type="box" pos="-0.16372668743133545 0.012079990468919277 0.007763851433992386" size="0.01963685266673565 0.08824531733989716 0.11198662966489792" quat="1.0 0.0 0.0 0.0" class="collision_1"/>
        <geom type="box" pos="-0.08492938429117203 0.012079990468919277 0.007763849571347237" size="0.013056380674242973 0.08824266493320465 0.11197104305028915" quat="1.0 0.0 0.0 0.0" class="collision_1"/>
        <geom type="box" pos="0.0003066202625632286 0.012079990468919277 0.007763851433992386" size="0.02036367356777191 0.08824531733989716 0.11197501420974731" quat="1.0 0.0 0.0 0.0" class="collision_1"/>
        <geom type="box" pos="0.08334530889987946 0.012079990468919277 0.007763848640024662" size="0.014646485447883606 0.08824531733989716 0.11197870224714279" quat="1.0 0.0 0.0 0.0" class="collision_1"/>
        <geom type="cylinder" pos="-0.15894222259521484 -0.11052775382995605 -0.11220764368772507" size="0.009821919724345207 0.007714869454503059" quat="1.0 0.0 0.0 0.0" class="collision_1"/>
        <geom type="cylinder" pos="-0.15894222259521484 0.14165472984313965 -0.11220764368772507" size="0.009821919724345207 0.007714869454503059" quat="1.0 0.0 0.0 0.0" class="collision_1"/>
        <geom type="cylinder" pos="0.16593624651432037 -0.11052775382995605 -0.11220764368772507" size="0.009821919724345207 0.007714869454503059" quat="1.0 0.0 0.0 0.0" class="collision_1"/>
        <geom type="cylinder" pos="0.16593624651432037 0.14165472984313965 -0.11220764368772507" size="0.009821919724345207 0.007714869454503059" quat="1.0 0.0 0.0 0.0" class="collision_1"/>
        <geom type="box" pos="-0.0664513036608696 0.012079990468919277 0.007763851433992386" size="0.004780661314725876 0.0850042849779129 0.11198554188013077" quat="1.0 0.0 0.0 0.0" class="collision_1"/>
        <geom type="box" pos="-0.02547631412744522 0.012079990468919277 0.007763849571347237" size="0.005699888337403536 0.08500410616397858 0.11198526620864868" quat="1.0 0.0 0.0 0.0" class="collision_1"/>
        <geom type="box" pos="0.02359612286090851 0.012079990468919277 0.007763851433992386" size="0.004780661314725876 0.08500391989946365 0.1119849905371666" quat="1.0 0.0 0.0 0.0" class="collision_1"/>
        <geom type="box" pos="0.06495026499032974 0.012079990468919277 0.007763849571347237" size="0.004849208518862724 0.08500374108552933 0.11198471486568451" quat="1.0 0.0 0.0 0.0" class="collision_1"/>
        <geom type="box" pos="0.10086341202259064 0.012079990468919277 0.007763849571347237" size="0.00365849444642663 0.08499972522258759 0.11197584122419357" quat="1.0 0.0 0.0 0.0" class="collision_1"/>
        <geom type="box" pos="0.14052079617977142 0.012079990468919277 0.007763849571347237" size="0.006151702255010605 0.08500337600708008 0.11198417097330093" quat="1.0 0.0 0.0 0.0" class="collision_1"/>
        <geom type="box" pos="-0.14139775931835175 0.012079990468919277 0.007763851433992386" size="0.004780661314725876 0.08500318974256516 0.11198389530181885" quat="1.0 0.0 0.0 0.0" class="collision_1"/>
        <geom type="box" pos="-0.10245190560817719 0.012079990468919277 0.007763848640024662" size="0.00560641149058938 0.08500301092863083 0.11197870224714279" quat="1.0 0.0 0.0 0.0" class="collision_1"/>
        <geom type="box" pos="0.0 0.017169732600450516 -0.09214702248573303" size="0.1800077259540558 0.14913173019886017 0.012762213125824928" quat="1.0 0.0 0.0 0.0" class="collision_1"/>
        <body name="sideL_button_cancel">
          <joint axis="0.0 1.0 0.0" pos="-0.12382468581199646 -0.13341757655143738 -0.05799706652760506" limited="true" name="sideL_button_cancel_joint" range="0.0 0.003" type="slide" damping="1" frictionloss="1" armature=".01" stiffness="0.05"/>
          <geom mesh="sideL_button_cancel_vis" type="mesh" solimp="0.998 0.998 0.001" solref="0.001 1" friction="0.95 0.3 0.1" class="visual" material="sideL_button_cancel_material"/>
          <geom class="collision_2" type="cylinder" pos="-0.12393656373023987 -0.13629214465618134 -0.05785689502954483" size="0.007437814027070999 0.0013412082334980369" quat="0.7071068286895752 0.7071067690849304 0.0 0.0" name="sideL_button_cancel_main"/>
        </body>
        <body name="sideL_knob_doneness">
          <joint axis="0.0 1.0 0.0" pos="-0.0457763709127903 -0.14416104555130005 -0.05669567361474037" limited="true" name="sideL_knob_doneness_joint" range="0.0 5.235987755982989" type="hinge" damping="0.05" frictionloss="0.1" armature="0.001"/>
          <geom mesh="sideL_knob_doneness_vis" type="mesh" solimp="0.998 0.998 0.001" solref="0.001 1" friction="0.95 0.3 0.1" class="visual" material="sideL_knob_doneness_material"/>
          <geom type="cylinder" pos="-0.045753952115774155 -0.14257530868053436 -0.05660383403301239" size="0.014604751951992512 0.0049477447755634785" quat="0.7071068286895752 0.7071067690849304 0.0 0.0" class="collision_3" density="0.001"/>
          <geom class="collision_3" type="box" pos="-0.045708123594522476 -0.14622710645198822 -0.05956811457872391" size="0.0027107419446110725 0.011635971255600452 0.015003010630607605" quat="1.0 0.0 0.0 0.0" name="sideL_knob_doneness_main" density="0.001"/>
        </body>
        <body name="sideL_lever">
          <joint axis="0.0 0.0 -1.0" pos="-0.08562967926263809 -0.12279382348060608 0.06072010099887848" limited="true" name="sideL_lever_joint" range="0.0 0.06" type="slide" damping="1" frictionloss="1" armature=".01" stiffness="3" springref="-0.5"/>
          <geom class="region" name="reg_sideL_slotL" type="box" pos="-0.12213747575879097 0.012564100325107574 0.12046733684837818" size="0.014860519975423814 0.07920514589548111 0.07600007562339306"/>
          <geom class="region" name="reg_sideL_slotR" type="box" pos="-0.04648022539913654 0.012564100325107574 0.12046733684837818" size="0.014927871361374856 0.07920514589548111 0.07600007562339306"/>
          <geom mesh="sideL_lever_vis" type="mesh" solimp="0.998 0.998 0.001" solref="0.001 1" friction="0.95 0.3 0.1" class="visual" material="sideL_lever_material"/>
          <geom class="collision_4" type="box" pos="-0.08537087589502335 -0.1507624089717865 0.06096380203962326" size="0.01433886680752039 0.004464126192033291 0.0023683267645537853" quat="1.0 0.0 0.0 0.0" name="sideL_lever_handle"/>
          <geom type="box" pos="-0.08537087589502335 -0.14317749440670013 0.06096380203962326" size="0.019358130171895027 0.003041111631318927 0.009927273727953434" quat="1.0 0.0 0.0 0.0" class="collision_4"/>
          <geom class="collision_4" type="box" pos="-0.12215737253427505 0.013026301749050617 0.039405837655067444" size="0.013749999925494194 0.08113616704940796 0.001352261402644217" quat="1.0 0.0 0.0 0.0" name="sideL_slotL_floor"/>
          <geom class="collision_4" type="box" pos="-0.046521954238414764 0.013026301749050617 0.039405837655067444" size="0.013749999925494194 0.08113612234592438 0.0013522593071684241" quat="1.0 0.0 0.0 0.0" name="sideL_slotR_floor"/>
        </body>
        <body name="sideR_button_cancel">
          <joint axis="0.0 1.0 0.0" pos="0.12132418155670166 -0.13341757655143738 -0.05799706652760506" limited="true" name="sideR_button_cancel_joint" range="0.0 0.003" type="slide" damping="1" frictionloss="1" armature=".01" stiffness="0.05"/>
          <geom mesh="sideR_button_cancel_vis" type="mesh" solimp="0.998 0.998 0.001" solref="0.001 1" friction="0.95 0.3 0.1" class="visual" material="sideR_button_cancel_material"/>
          <geom class="collision_5" type="cylinder" pos="0.12145990878343582 -0.13603216409683228 -0.05785689502954483" size="0.007437814027070999 0.0013412082334980369" quat="0.7071068286895752 0.7071067690849304 0.0 0.0" name="sideR_button_cancel_main"/>
        </body>
        <body name="sideR_knob_doneness">
          <joint axis="0.0 1.0 0.0" pos="0.04678315296769142 -0.14416104555130005 -0.05626770108938217" limited="true" name="sideR_knob_doneness_joint" range="0.0 5.235987755982989" type="hinge" damping="0.05" frictionloss="0.1" armature="0.001"/>
          <geom mesh="sideR_knob_doneness_vis" type="mesh" solimp="0.998 0.998 0.001" solref="0.001 1" friction="0.95 0.3 0.1" class="visual" material="sideR_knob_doneness_material"/>
          <geom type="cylinder" pos="0.046773139387369156 -0.1424776166677475 -0.056292127817869186" size="0.014244599267840385 0.005085412412881851" quat="0.7071068286895752 0.7071067690849304 0.0 0.0" class="collision_6" density="0.001"/>
          <geom class="collision_6" type="box" pos="0.04683396592736244 -0.14622710645198822 -0.05956811457872391" size="0.0027107419446110725 0.011635971255600452 0.015003010630607605" quat="1.0 0.0 0.0 0.0" name="sideR_knob_doneness_main" density="0.001"/>
        </body>
        <body name="sideR_lever">
          <joint axis="0.0 0.0 -1.0" pos="0.08349090814590454 -0.12279382348060608 0.06072010099887848" limited="true" name="sideR_lever_joint" range="0.0 0.06" type="slide" damping="1" frictionloss="1" armature=".01" stiffness="3" springref="-0.5"/>
          <geom class="region" name="reg_sideR_slotL" type="box" pos="0.044490463100373745 0.012564100325107574 0.12046733684837818" size="0.014943967409431935 0.07920514589548111 0.07600007562339306"/>
          <geom class="region" name="reg_sideR_slotR" type="box" pos="0.1198720932006836 0.012564100325107574 0.12046733684837818" size="0.014918712735176087 0.07920514589548111 0.07600007562339306"/>
          <geom mesh="sideR_lever_vis" type="mesh" solimp="0.998 0.998 0.001" solref="0.001 1" friction="0.95 0.3 0.1" class="visual" material="sideR_lever_material"/>
          <geom type="box" pos="0.0834248885512352 -0.14317749440670013 0.06096380203962326" size="0.019358130171895027 0.003041111631318927 0.00992730911821127" quat="1.0 0.0 0.0 0.0" class="collision_7"/>
          <geom class="collision_7" type="box" pos="0.0834248885512352 -0.1507624089717865 0.06096380203962326" size="0.014338712207973003 0.004464126192033291 0.0023683267645537853" quat="1.0 0.0 0.0 0.0" name="sideR_lever_handle"/>
          <geom class="collision_7" type="box" pos="0.04452598839998245 0.013026301749050617 0.039405837655067444" size="0.013749999925494194 0.08113597333431244 0.0013522531371563673" quat="1.0 0.0 0.0 0.0" name="sideR_slotL_floor"/>
          <geom class="collision_7" type="box" pos="0.11979889869689941 0.013026301749050617 0.039405837655067444" size="0.013749999925494194 0.08113592863082886 0.0013522510416805744" quat="1.0 0.0 0.0 0.0" name="sideR_slotR_floor"/>
        </body>
        <body name="Body002">
          <geom mesh="Body002_vis" type="mesh" solimp="0.998 0.998 0.001" solref="0.001 1" friction="0.95 0.3 0.1" class="visual" material="Body002_material"/>
        </body>
        <geom class="region" name="reg_main" type="box" pos="3.725290298461914e-09 0.011982321739196777 0.0" size="0.18304496800899506 0.14696709609031677 0.12031507289409638"/>
      </body>
    </body>
  </worldbody>
  <actuator>
    <motor name="sideL_button_cancel_joint_actuator" joint="sideL_button_cancel_joint" gear="0.5"/>
    <motor name="sideL_knob_doneness_joint_actuator" joint="sideL_knob_doneness_joint" gear="10"/>
    <motor name="sideL_lever_joint_actuator" joint="sideL_lever_joint" gear="2"/>
    <motor name="sideR_button_cancel_joint_actuator" joint="sideR_button_cancel_joint" gear="0.5"/>
    <motor name="sideR_knob_doneness_joint_actuator" joint="sideR_knob_doneness_joint" gear="10"/>
    <motor name="sideR_lever_joint_actuator" joint="sideR_lever_joint" gear="2"/>
  </actuator>
</mujoco>
