<?xml version='1.0' encoding='UTF-8'?>
<mujoco model="model">
  <option timestep="0.002" gravity="0.0 0.0 -9.81"/>
  <compiler angle="radian"/>
  <asset>
    <mesh file="visuals/knob_front_left.obj" name="knob_front_left_vis"/>
    <mesh file="visuals/knob_front_right.obj" name="knob_front_right_vis"/>
    <mesh file="visuals/knob_rear_left.obj" name="knob_rear_left_vis"/>
    <mesh file="visuals/knob_rear_right.obj" name="knob_rear_right_vis"/>
    <mesh file="visuals/rack0.obj" name="rack0_vis"/>
    <mesh file="visuals/Body001.obj" name="Body001_vis"/>
    <mesh file="visuals/Door001.obj" name="Door001_vis"/>
    <mesh file="visuals/Door001_Clear.obj" name="Door001_Clear_vis"/>
    <mesh file="visuals/Knob001.obj" name="Knob001_vis"/>
    <mesh file="visuals/Knob002.obj" name="Knob002_vis"/>
    <texture file="visuals/T_BC001.png" name="Body001_material" type="2d"/>
    <material name="Body001_material" rgba="1 1 1 1.0" texture="Body001_material" shininess="0.5" specular="2"/>
    <texture file="visuals/T_BC001.png" name="knob_front_left_material" type="2d"/>
    <material name="knob_front_left_material" rgba="1 1 1 1.0" texture="knob_front_left_material" shininess="0.5" specular="0.3103448502657381"/>
    <texture file="visuals/T_BC001.png" name="knob_front_right_material" type="2d"/>
    <material name="knob_front_right_material" rgba="1 1 1 1.0" texture="knob_front_right_material" shininess="0.5" specular="0.3103448502657381"/>
    <texture file="visuals/T_BC001.png" name="knob_rear_left_material" type="2d"/>
    <material name="knob_rear_left_material" rgba="1 1 1 1.0" texture="knob_rear_left_material" shininess="0.5" specular="0.3103448502657381"/>
    <texture file="visuals/T_BC001.png" name="knob_rear_right_material" type="2d"/>
    <material name="knob_rear_right_material" rgba="1 1 1 1.0" texture="knob_rear_right_material" shininess="0.5" specular="0.3103448502657381"/>
    <texture file="visuals/T_BC001.png" name="rack0_material" type="2d"/>
    <material name="rack0_material" rgba="1 1 1 1.0" texture="rack0_material" shininess="0.5" specular="2"/>
    <texture file="visuals/T_BC001.png" name="Door001_material" type="2d"/>
    <material name="Door001_material" rgba="1 1 1 1.0" texture="Door001_material" shininess="0.5" specular="2"/>
    <texture file="visuals/T_BC001.png" name="Door001_Clear_material" type="2d"/>
    <material name="Door001_Clear_material" rgba="1 1 1 0.5" texture="Door001_Clear_material" shininess="0.5" specular="0.3103448502657381"/>
    <texture file="visuals/T_BC001.png" name="Knob001_material" type="2d"/>
    <material name="Knob001_material" rgba="1 1 1 1.0" texture="Knob001_material" shininess="0.5" specular="0.3103448502657381"/>
    <texture file="visuals/T_BC001.png" name="Knob002_material" type="2d"/>
    <material name="Knob002_material" rgba="1 1 1 1.0" texture="Knob002_material" shininess="0.5" specular="0.3103448502657381"/>
  </asset>
  <default>
    <default class="visual">
      <geom conaffinity="0" contype="0" group="1" type="mesh"/>
    </default>
    <default class="collision">
      <geom group="0" rgba="0.5 0 0 0.5"/>
    </default>
    <default class="spawn">
      <geom group="0" rgba="1 1 1 0.5" contype="0" conaffinity="0"/>
      <site group="0" rgba="1 1 1 0.5"/>
    </default>
    <default class="region">
      <geom group="1" conaffinity="0" contype="0" rgba="0 1 0 0"/>
    </default>
  </default>
  <worldbody>
    <body>
      <body name="object">
        <geom mesh="Body001_vis" type="mesh" solimp="0.998 0.998 0.001" solref="0.001 1" friction="0.95 0.3 0.1" class="visual" material="Body001_material"/>
        <geom class="collision" type="box" pos="-0.30546206 0.04095108 0.40979198" size="0.03157045692205429 0.3458944261074066 0.019299974665045738" quat="1.0 0.0 0.0 0.0"/>
        <geom class="collision" type="box" pos="0.31874925 0.03742482 0.40995559" size="0.019163703545928 0.3494206964969635 0.01913635991513729" quat="1.0 0.0 0.0 0.0"/>
        <geom class="collision" type="box" pos="-0.00232367 -0.27769148 0.40788490" size="0.32577696442604065 0.027789197862148285 0.021897345781326294" quat="1.0 0.0 0.0 0.0"/>
        <geom class="collision" type="box" pos="-0.00232367 0.35195252 0.40788490" size="0.32577696442604065 0.03511851653456688 0.02189701981842518" quat="1.0 0.0 0.0 0.0"/>
        <geom class="collision" type="box" pos="-0.00232367 0.03898244 0.39388674" size="0.32577696442604065 0.34452980756759644 0.007899037562310696" quat="1.0 0.0 0.0 0.0"/>
        <geom class="collision" type="box" pos="-0.00232365 0.05351739 0.32429916" size="0.3257769048213959 0.30906498432159424 0.06580030918121338" quat="1.0 0.0 0.0 0.0"/>
        <geom class="collision" type="box" pos="0.00066019 0.03535568 0.32449546" size="0.33674007654190063 0.32959872484207153 0.06599660217761993" quat="1.0 0.0 0.0 0.0"/>
        <geom class="collision" type="box" pos="-0.30717543 0.04433045 0.01439470" size="0.030927466228604317 0.34163305163383484 0.37609729170799255" quat="1.0 0.0 0.0 0.0"/>
        <geom class="collision" type="box" pos="0.31118414 0.04297619 0.01419863" size="0.02935098670423031 0.3429873585700989 0.3759011924266815" quat="1.0 0.0 0.0 0.0"/>
        <geom class="collision" type="box" pos="-0.00320623 0.35573965 0.00177801" size="0.32665953040122986 0.009213967248797417 0.26213300228118896" quat="1.0 0.0 0.0 0.0"/>
        <geom class="collision" type="box" pos="-0.00232367 0.04256850 -0.30832461" size="0.32577696442604065 0.32221418619155884 0.06112684682011604" quat="1.0 0.0 0.0 0.0"/>
        <geom class="collision" type="box" pos="-0.00165172 -0.29387802 -0.31239748" size="0.3337043821811676 0.016561346128582954 0.05705389380455017" quat="1.0 0.0 0.0 0.0"/>
        <geom class="collision" type="box" pos="0.00121366 0.05351739 -0.40136060" size="0.3393222391605377 0.33244603872299194 0.03992301598191261" quat="1.0 0.0 0.0 0.0"/>
        <geom class="collision" type="box" pos="-0.27467409 0.08413249 -0.00041802" size="0.0062475260347127914 0.23480769991874695 0.007247717119753361" quat="1.0 0.0 0.0 0.0"/>
        <geom class="collision" type="box" pos="0.27983472 0.08413249 -0.00041802" size="0.008244672790169716 0.23480767011642456 0.0072477166540920734" quat="1.0 0.0 0.0 0.0"/>
        <geom class="collision" type="box" pos="0.00280371 0.03326523 0.41868404" size="0.3267553448677063 0.30354809761047363 0.02259973995387554" quat="1.0 0.0 0.0 0.0"/>
        <body name="knob_front_left">
          <joint axis="0.0 -1.0 0.0" pos="-0.27671891 -0.31603825 0.32971612" limited="true" name="knob_front_left_joint" range="0.0 3.141592653589793" type="hinge" damping="0.05" frictionloss="0.1" armature="0.001"/>
          <geom mesh="knob_front_left_vis" type="mesh" solimp="0.998 0.998 0.001" solref="0.001 1" friction="0.95 0.3 0.1" class="visual" material="knob_front_left_material"/>
          <geom class="collision" type="cylinder" pos="-0.27706653 -0.31139922 0.32951266" size="0.02695857733488083 0.008445155806839466" quat="0.70710688829422 0.7071066498756409 0.0 0.0" density="0.001"/>
          <geom class="collision" type="box" pos="-0.27708113 -0.32426155 0.32848740" size="0.00596280675381422 0.007199874613434076 0.02400292083621025" quat="1.0 0.0 0.0 0.0" name="knob_front_left_main" density="0.001"/>
        </body>
        <body name="knob_front_right">
          <joint axis="0.0 -1.0 0.0" pos="0.27471930 -0.31603825 0.32971612" limited="true" name="knob_front_right_joint" range="0.0 3.141592653589793" type="hinge" damping="0.05" frictionloss="0.1" armature="0.001"/>
          <geom mesh="knob_front_right_vis" type="mesh" solimp="0.998 0.998 0.001" solref="0.001 1" friction="0.95 0.3 0.1" class="visual" material="knob_front_right_material"/>
          <geom class="collision" type="cylinder" pos="0.27464855 -0.31176448 0.32958555" size="0.026809222996234894 0.00839253980666399" quat="0.7071068286895752 0.7071067690849304 0.0 0.0" density="0.001"/>
          <geom class="collision" type="box" pos="0.27463403 -0.32454967 0.32856596" size="0.005929763428866863 0.007159987930208445 0.023869896307587624" quat="1.0 0.0 0.0 0.0" name="knob_front_right_main" density="0.001"/>
        </body>
        <body name="knob_rear_left">
          <joint axis="0.0 -1.0 0.0" pos="-0.16156253 -0.31603825 0.32971612" limited="true" name="knob_rear_left_joint" range="0.0 3.141592653589793" type="hinge" damping="0.05" armature="0.001"/>
          <geom mesh="knob_rear_left_vis" type="mesh" solimp="0.998 0.998 0.001" solref="0.001 1" friction="0.95 0.3 0.1" class="visual" material="knob_rear_left_material"/>
          <geom class="collision" type="cylinder" pos="-0.16142583 -0.31238443 0.32950911" size="0.026647401973605156 0.009387573227286339" quat="0.7071068286895752 0.7071067690849304 0.0 0.0"/>
          <geom class="collision" type="box" pos="-0.16144031 -0.32613820 0.32940227" size="0.0058941105380654335 0.007117106579244137 0.023726284503936768" quat="1.0 0.0 0.0 0.0" name="knob_rear_left_main"/>
        </body>
        <body name="knob_rear_right">
          <joint axis="0.0 -1.0 0.0" pos="0.17054012 -0.31603825 0.32971612" limited="true" name="knob_rear_right_joint" range="0.0 3.141592653589793" type="hinge" damping="0.05" armature="0.001"/>
          <geom mesh="knob_rear_right_vis" type="mesh" solimp="0.998 0.998 0.001" solref="0.001 1" friction="0.95 0.3 0.1" class="visual" material="knob_rear_right_material"/>
          <geom class="collision" type="cylinder" pos="0.17065348 -0.31172848 0.32952958" size="0.02718520164489746 0.008524991571903229" quat="0.7071068286895752 0.7071067690849304 0.0 0.0"/>
          <geom class="collision" type="box" pos="0.17063871 -0.32470775 0.32849571" size="0.006013091653585434 0.007260401267558336 0.02420542575418949" quat="1.0 0.0 0.0 0.0" name="knob_rear_right_main"/>
        </body>
        <body name="rack0">
          <geom class="region" name="reg_rack0" type="box" pos="0.005235865000000006 0.08223359 0.135870755" size="0.271251285 0.25672799 0.11954863500000001"/>
          <joint axis="0.0 -1.0 0.0" pos="0.00300857 0.09261624 0.01319867" limited="true" name="rack0_joint" range="0.0 0.45" type="slide" damping="1" frictionloss="1" armature=".01" stiffness="0.05"/>
          <geom mesh="rack0_vis" type="mesh" solimp="0.998 0.998 0.001" solref="0.001 1" friction="0.95 0.3 0.1" class="visual" material="rack0_material"/>
          <geom class="collision" type="box" pos="0.00271789 0.08102890 0.01154228" size="0.27813947200775146 0.2619660496711731 0.003577019087970257" quat="1.0 0.0 0.0 0.0"/>
        </body>
        <body name="Door001">
          <joint axis="1.0 0.0 0.0" pos="0.00072970 -0.32296717 -0.25242454" limited="true" name="Door001_joint" range="0.0 1.5707963267948966" type="hinge" damping="1" frictionloss="1" armature=".01" stiffness="0.05"/>
          <geom mesh="Door001_vis" type="mesh" solimp="0.998 0.998 0.001" solref="0.001 1" friction="0.95 0.3 0.1" class="visual" material="Door001_material"/>
          <geom class="collision" type="box" pos="0.00044730 -0.31061691 0.00674204" size="0.3348972797393799 0.009196015074849129 0.2565017342567444" quat="1.0 0.0 0.0 0.0"/>
          <geom class="collision" type="box" pos="-0.26167098 -0.35420477 0.22209807" size="0.013943732716143131 0.035224854946136475 0.018639419227838516" quat="1.0 0.0 0.0 0.0"/>
          <geom class="collision" type="box" pos="0.00219752 -0.37681973 0.22209807" size="0.2778121829032898 0.012609956786036491 0.018639421090483665" quat="1.0 0.0 0.0 0.0"/>
          <geom class="collision" type="box" pos="0.26728436 -0.35420477 0.22209807" size="0.01394373457878828 0.03522485867142677 0.018639421090483665" quat="1.0 0.0 0.0 0.0"/>
          <geom class="collision" type="box" pos="0.00612022 -0.31020314 0.00804880" size="0.23763589560985565 0.008296974003314972 0.18880362808704376" quat="1.0 0.0 0.0 0.0"/>
          <body name="Door001_Clear">
            <geom mesh="Door001_Clear_vis" type="mesh" solimp="0.998 0.998 0.001" solref="0.001 1" friction="0.95 0.3 0.1" class="visual" material="Door001_Clear_material"/>
            <geom class="collision" type="box" pos="0.00612022 -0.31020314 0.00804880" size="0.23763589560985565 0.008296974003314972 0.18880362808704376" quat="1.0 0.0 0.0 0.0"/>
          </body>
        </body>
        <body name="Knob001">
          <joint axis="0.0 1.0 0.0" pos="-0.05176498 -0.31603825 0.33131796" limited="true" name="Knob001_joint" range="0.0 5.585053606381854" type="hinge" damping="0.05" frictionloss="0.1" armature="0.001"/>
          <geom mesh="Knob001_vis" type="mesh" solimp="0.998 0.998 0.001" solref="0.001 1" friction="0.95 0.3 0.1" class="visual" material="Knob001_material"/>
          <geom class="collision" type="cylinder" pos="-0.05164183 -0.31222963 0.33117071" size="0.02685207687318325 0.009459678083658218" quat="0.7071068286895752 0.7071067690849304 0.0 0.0" density="0.001"/>
          <geom class="collision" type="box" pos="-0.05165643 -0.32608896 0.33083758" size="0.005939232651144266 0.007171344012022018 0.023907819762825966" quat="1.0 0.0 0.0 0.0" density="0.001"/>
        </body>
        <body name="Knob002">
          <joint axis="0.0 1.0 0.0" pos="0.05930292 -0.31603825 0.32888177" limited="true" name="Knob002_joint" range="0.0 5.235987755982989" type="hinge" damping="1" frictionloss="0.1" armature="0.001"/>
          <geom mesh="Knob002_vis" type="mesh" solimp="0.998 0.998 0.001" solref="0.001 1" friction="0.95 0.3 0.1" class="visual" material="Knob002_material"/>
          <geom class="collision" type="cylinder" pos="0.05940415 -0.31135696 0.32875010" size="0.026502354070544243 0.008284438401460648" quat="0.5 0.5 -0.4999999701976776 0.5" density="0.00001"/>
          <geom class="collision" type="box" pos="0.06001235 -0.32398379 0.32843736" size="0.023597078397870064 0.007077804300934076 0.005862010642886162" quat="1.0 0.0 0.0 0.0" density="0.00001"/>
        </body>
        <geom class="region" name="reg_int" type="box" pos="0.0018044550000000104 0.033228965 0.006977705000000015" size="0.271961095 0.307726935 0.24631343500000002"/>
        <site type="cylinder" rgba="0.3 0.4 1 0.5" size="0.04184328764677048 0.014999999664723873" pos="-0.14577645 0.19499782 0.41748473" name="burner_on_rear_left"/>
        <site type="cylinder" rgba="0.3 0.4 1 0.5" size="0.0424492284655571 0.014999999664723873" pos="-0.14590652 -0.10903773 0.41713873" name="burner_on_front_left"/>
        <site type="cylinder" rgba="0.3 0.4 1 0.5" size="0.060189858078956604 0.014999999664723873" pos="0.14681518 -0.10913062 0.41594177" name="burner_on_front_right"/>
        <site type="cylinder" rgba="0.3 0.4 1 0.5" size="0.038490861654281616 0.014999999664723873" pos="0.14627458 0.19499749 0.41698748" name="burner_on_rear_right"/>
        <site type="cylinder" rgba="0.5 0 0 0" size="0.04184328764677048 5.0000002374872565e-05" pos="-0.14577645 0.19499782 0.44133380" name="burner_rear_left_place_site"/>
        <site type="cylinder" rgba="0.5 0 0 0" size="0.0424492284655571 4.999999873689376e-05" pos="-0.14590652 -0.10903773 0.44133377" name="burner_front_left_place_site"/>
        <site type="cylinder" rgba="0.5 0 0 0" size="0.060189858078956604 4.999999873689376e-05" pos="0.14681518 -0.10913062 0.44133380" name="burner_front_right_place_site"/>
        <site type="cylinder" rgba="0.5 0 0 0" size="0.038490861654281616 4.999999873689376e-05" pos="0.14627458 0.19499749 0.44133380" name="burner_rear_right_place_site"/>
        <geom class="region" name="reg_main" type="box" pos="1.650000000241736e-07 0.03274911999999999 -0.02220216" size="0.34279830499999997 0.35722716 0.42008151000000005"/>
      </body>
    </body>
  </worldbody>
  <actuator>
    <motor name="knob_front_left_joint_actuator" joint="knob_front_left_joint" gear="10"/>
    <motor name="knob_front_right_joint_actuator" joint="knob_front_right_joint" gear="10"/>
    <motor name="knob_rear_left_joint_actuator" joint="knob_rear_left_joint" gear="10"/>
    <motor name="knob_rear_right_joint_actuator" joint="knob_rear_right_joint" gear="10"/>
    <motor name="rack0_joint_actuator" joint="rack0_joint" gear="10"/>
    <motor name="Door001_joint_actuator" joint="Door001_joint" gear="100"/>
    <motor name="Knob001_joint_actuator" joint="Knob001_joint" gear="10"/>
    <motor name="Knob002_joint_actuator" joint="Knob002_joint" gear="10"/>
  </actuator>
</mujoco>
