<?xml version='1.0' encoding='UTF-8'?>
<mujoco model="model">
  <option timestep="0.002" gravity="0.0 0.0 -9.81"/>
  <compiler angle="radian"/>
  <asset>
    <mesh file="visuals/door.obj" name="door_vis"/>
    <mesh file="visuals/door_Clear.obj" name="door_Clear_vis"/>
    <mesh file="visuals/Body001.obj" name="Body001_vis"/>
    <mesh file="visuals/Disc001.obj" name="Disc001_vis"/>
    <texture file="visuals/T_BC001.png" name="Body001_material" type="2d"/>
    <material name="Body001_material" rgba="1 1 1 1.0" texture="Body001_material" shininess="0.141421377658844" specular="1"/>
    <texture file="visuals/T_BC001.png" name="door_material" type="2d"/>
    <material name="door_material" rgba="1 1 1 1.0" texture="door_material" shininess="0.141421377658844" specular="1"/>
    <material name="door_Clear_material" rgba="0.01037973165512085 0.01037973165512085 0.01037973165512085 0.8029197454452515" shininess="0.5" specular="0.3103448502657381"/>
    <texture file="visuals/T_BC001.png" name="Disc001_material" type="2d"/>
    <material name="Disc001_material" rgba="1 1 1 1.0" texture="Disc001_material" shininess="0.141421377658844" specular="0.5"/>
  </asset>
  <default>
    <default class="visual">
      <geom conaffinity="0" contype="0" group="1" type="mesh"/>
    </default>
    <default class="collision">
      <geom group="0" rgba="0.5 0 0 0.5"/>
    </default>
    <default class="spawn">
      <geom group="0" rgba="1 1 1 0.5" contype="0" conaffinity="0"/>
      <site group="0" rgba="1 1 1 0.5"/>
    </default>
    <default class="region">
      <geom group="1" conaffinity="0" contype="0" rgba="0 1 0 0"/>
    </default>
  </default>
  <worldbody>
    <body>
      <body name="object">
        <geom class="collision" type="box" pos="0.17568564 -0.18728293 -0.09789214" size="0.009654606692492962 0.0006261059897951782 0.006593481637537479" quat="1.0 0.0 0.0 0.0" name="stop_button" rgba="0.0 0.5 0 0.5"/>
        <geom class="collision" type="box" pos="0.22910032 -0.18707716 -0.09760179" size="0.009654614143073559 0.0006261059897951782 0.006593488622456789" quat="1.0 0.0 0.0 0.0" name="start_button" rgba="0.0 0.5 0 0.5"/>
        <geom class="collision" type="cylinder" pos="-0.05689941 0.01663616 -0.13820649" size="0.15419769287109375 0.0011919435346499085" quat="7.549790126404332e-08 0.0 0.0 1.0" name="tray" rgba="0 1 0 0.5"/>
        <geom mesh="Body001_vis" type="mesh" solimp="0.998 0.998 0.001" solref="0.001 1" friction="0.95 0.3 0.1" class="visual" material="Body001_material"/>
        <geom class="collision" type="box" pos="-0.00000003 0.20141830 0.00093462" size="0.2667255699634552 0.011984211392700672 0.16359718143939972" quat="1.0 0.0 0.0 0.0"/>
        <geom class="collision" type="box" pos="-0.25403982 0.02114284 0.00093459" size="0.012686800211668015 0.17804817855358124 0.1635972559452057" quat="1.0 0.0 0.0 0.0"/>
        <geom class="collision" type="box" pos="0.19802403 0.02114284 0.00091655" size="0.06870240718126297 0.17804838716983795 0.1635793149471283" quat="1.0 0.0 0.0 0.0"/>
        <geom class="collision" type="box" pos="-0.05283179 0.02114284 0.15184873" size="0.1950417459011078 0.17804861068725586 0.01268356665968895" quat="1.0 0.0 0.0 0.0"/>
        <geom class="collision" type="box" pos="-0.00015752 0.02814339 -0.15695258" size="0.2665683925151825 0.185049369931221 0.007873866707086563" quat="1.0 0.0 0.0 0.0"/>
        <geom class="collision" type="box" pos="0.20986769 -0.16919050 0.00093448" size="0.05685887113213539 0.01701016165316105 0.16359752416610718" quat="1.0 0.0 0.0 0.0"/>
        <body name="door">
          <joint axis="0.0 0.0 1.0" pos="-0.25064364 -0.17070249 0.00006511" limited="true" name="microjoint" range="-1.5707963267948966 0.0" type="hinge" damping="1" frictionloss="1" armature=".01" stiffness="0.05"/>
          <geom mesh="door_vis" type="mesh" solimp="0.998 0.998 0.001" solref="0.001 1" friction="0.95 0.3 0.1" class="visual" material="door_material"/>
          <geom class="collision" type="box" pos="-0.04740505 -0.17941912 0.00093445" size="0.19814977049827576 0.006781565025448799 0.16359759867191315" quat="1.0 0.0 0.0 0.0"/>
          <geom class="collision" type="box" pos="0.13449171 -0.20839845 0.00060428" size="0.009654595516622066 0.005131038837134838 0.10738371312618256" quat="1.0 0.0 0.0 0.0" name="door_handle_main"/>
          <geom class="collision" type="box" pos="0.13449171 -0.19495520 0.10352590" size="0.009654602035880089 0.0075681512244045734 0.00530577078461647" quat="1.0 0.0 0.0 0.0"/>
          <geom class="collision" type="box" pos="0.13449171 -0.19495520 -0.10168201" size="0.009654609486460686 0.00756815867498517 0.005305777303874493" quat="1.0 0.0 0.0 0.0"/>
          <geom class="collision" type="box" pos="-0.05644451 -0.17082328 -0.00081223" size="0.15925107896327972 0.01537742093205452 0.09145861864089966" quat="1.0 0.0 0.0 0.0"/>
          <geom class="collision" type="box" pos="-0.04740505 -0.18272437 0.00093445" size="0.19815032184123993 0.003476313780993223 0.16359786689281464" quat="1.0 0.0 0.0 0.0" name="door_main"/>
          <body name="door_Clear">
            <geom mesh="door_Clear_vis" type="mesh" solimp="0.998 0.998 0.001" solref="0.001 1" friction="0.95 0.3 0.1" class="visual" material="door_Clear_material"/>
            <geom class="collision" type="box" pos="-0.05644451 -0.17082328 -0.00081223" size="0.15925107896327972 0.01537742093205452 0.09145861864089966" quat="1.0 0.0 0.0 0.0"/>
          </body>
        </body>
        <body name="Disc001">
          <joint axis="0.0 0.0 1.0" pos="-0.05689946 0.01663616 -0.13303021" limited="false" name="Disc001_joint" range="0 360" type="hinge" damping="1" frictionloss="1" armature=".01" stiffness="0.05"/>
          <geom mesh="Disc001_vis" type="mesh" solimp="0.998 0.998 0.001" solref="0.001 1" friction="0.95 0.3 0.1" class="visual" material="Disc001_material"/>
          <geom class="collision" type="cylinder" pos="-0.05689942 0.01663615 -0.14421462" size="0.15419769287109375 0.0033758704084903" quat="7.549790126404332e-08 0.0 0.0 1.0"/>
        </body>
        <geom class="region" name="reg_int" type="box" pos="-0.05540862 0.022228474999999998 -0.003973730000000009" size="0.17685032 0.159290455 0.13404073"/>
        <geom class="region" name="reg_main" type="box" pos="4.999999997368221e-09 0.01360095 -2.3000000000383825e-07" size="0.26772670499999995 0.20080164 0.16553275"/>
      </body>
    </body>
  </worldbody>
  <actuator>
    <motor name="microjoint_actuator" joint="microjoint" gear="10"/>
    <motor name="Disc001_joint_actuator" joint="Disc001_joint" gear="10"/>
  </actuator>
</mujoco>
