<?xml version='1.0' encoding='UTF-8'?>
<mujoco model="model">
  <option timestep="0.002" gravity="0.0 0.0 -9.81"/>
  <compiler angle="radian"/>
  <asset>
    <mesh file="visuals/button_lid.obj" name="button_lid_vis"/>
    <mesh file="visuals/Body001.obj" name="Body001_vis"/>
    <mesh file="visuals/kettle_main.obj" name="kettle_main_vis"/>
    <mesh file="visuals/lid.obj" name="lid_vis"/>
    <mesh file="visuals/switch.obj" name="switch_vis"/>
    <texture file="visuals/T_BC001.png" name="Body001_material" type="2d"/>
    <material name="Body001_material" rgba="1 1 1 1.0" texture="Body001_material" shininess="0.2512328028678894" specular="0.3103448502657381"/>
    <texture file="visuals/T_BC001.png" name="kettle_main_material" type="2d"/>
    <material name="kettle_main_material" rgba="1 1 1 1.0" texture="kettle_main_material" shininess="0.2512328028678894" specular="0.3103448502657381"/>
    <texture file="visuals/T_BC001.png" name="button_lid_material" type="2d"/>
    <material name="button_lid_material" rgba="1 1 1 1.0" texture="button_lid_material" shininess="0.2512328028678894" specular="0.3103448502657381"/>
    <texture file="visuals/T_BC001.png" name="lid_material" type="2d"/>
    <material name="lid_material" rgba="1 1 1 1.0" texture="lid_material" shininess="0.2512328028678894" specular="0.3103448502657381"/>
    <texture file="visuals/T_BC001.png" name="switch_material" type="2d"/>
    <material name="switch_material" rgba="1 1 1 1.0" texture="switch_material" shininess="0.2512328028678894" specular="0.3103448502657381"/>
  </asset>
  <default>
    <default class="visual">
      <geom conaffinity="0" contype="0" group="1" type="mesh"/>
    </default>
    <default class="collision">
      <geom group="0" rgba="0.5 0 0 0.5"/>
    </default>
    <default class="spawn">
      <geom group="0" rgba="1 1 1 0.5" contype="0" conaffinity="0"/>
      <site group="0" rgba="1 1 1 0.5"/>
    </default>
    <default class="region">
      <geom group="1" conaffinity="0" contype="0" rgba="0 1 0 0" mass="0"/>
    </default>
  </default>
  <worldbody>
    <body>
      <body name="object">
        <geom mesh="Body001_vis" type="mesh" solimp="0.998 0.998 0.001" solref="0.001 1" friction="0.95 0.3 0.1" class="visual" material="Body001_material"/>
        <geom type="cylinder" pos="-0.04088974 0.00000970 -0.17252803" size="0.11124438792467117 0.015558336861431599" quat="0.7071068286895752 0.0 0.0 0.7071067690849304" class="collision"/>
        <body name="kettle_main">
          <!-- <joint axis="0.0 0.0 1.0" pos="0.00000001 0.00007419 -0.00080466" limited="true" name="kettle_main_joint" range="0.0 0.07" type="slide" damping="1" frictionloss="1" armature=".01" stiffness="0.05"></joint> -->
          <geom mesh="kettle_main_vis" type="mesh" solimp="0.998 0.998 0.001" solref="0.001 1" friction="0.95 0.3 0.1" class="visual" material="kettle_main_material"/>
          <geom type="box" pos="-0.04088973 0.10701322 -0.05156071" size="0.020732257515192032 0.0035313626285642385 0.10418971627950668" quat="1.0 0.0 0.0 0.0" class="collision"/>
          <geom type="box" pos="-0.04088973 0.10701322 -0.05156071" size="0.020732257515192032 0.0035313626285642385 0.10418971627950668" quat="1.0 0.0 0.0 0.0" class="collision"/>
          <geom type="box" pos="0.00153995 0.09824144 -0.05156071" size="0.0035313607659190893 0.020732255652546883 0.10418971627950668" quat="0.8356213569641113 0.0 0.0 0.5493058562278748" class="collision"/>
          <geom type="box" pos="0.03703261 0.07334362 -0.05156071" size="0.003531360998749733 0.020732257515192032 0.10418971627950668" quat="0.9295758008956909 0.0 0.0 0.368630975484848" class="collision"/>
          <geom type="box" pos="0.05973274 0.03705873 -0.05156070" size="0.003531360998749733 0.020732255652546883 0.10418973118066788" quat="0.9783125519752502 0.0 0.0 0.20713411271572113" class="collision"/>
          <geom type="box" pos="0.06635232 -0.00776355 -0.14284416" size="0.003531360998749733 0.020732257515192032 0.01290628407150507" quat="0.999381422996521 0.0 0.0 -0.03516842797398567" class="collision"/>
          <geom type="box" pos="0.05371923 -0.05032695 -0.05156071" size="0.003531360998749733 0.020732257515192032 0.10418971627950668" quat="0.9701465368270874 0.0 0.0 -0.2425195872783661" class="collision"/>
          <geom type="box" pos="0.02601363 -0.08363794 -0.05156071" size="0.003531360998749733 0.020732257515192032 0.10418971627950668" quat="0.9009568095207214 0.0 0.0 -0.4339088201522827" class="collision"/>
          <geom type="box" pos="-0.01265681 -0.10323965 -0.05156071" size="0.003531360998749733 0.020732257515192032 0.10418971627950668" quat="0.7943715453147888 0.0 0.0 -0.6074321866035461" class="collision"/>
          <geom type="box" pos="-0.05680384 -0.10575987 -0.05156071" size="0.003531360998749733 0.020732257515192032 0.10418971627950668" quat="0.6517195105552673 0.0 -0.0 -0.7584600448608398" class="collision"/>
          <geom type="box" pos="-0.09801992 -0.09094475 -0.05156071" size="0.003531360998749733 0.020732257515192032 0.10418971627950668" quat="0.48403555154800415 0.0 -0.0 -0.8750483393669128" class="collision"/>
          <geom type="box" pos="-0.12943818 -0.06005627 -0.05156071" size="0.003531360998749733 0.020732257515192032 0.10418971627950668" quat="0.29274100065231323 0.0 -0.0 -0.9561917781829834" class="collision"/>
          <geom type="box" pos="-0.14592336 -0.01998806 -0.05156071" size="0.0035313612315803766 0.02073225937783718 0.10418971627950668" quat="0.09309259057044983 0.0 -0.0 -0.9956574440002441" class="collision"/>
          <geom type="box" pos="-0.14516284 0.02336000 -0.05156071" size="0.003531360998749733 0.020732257515192032 0.10418971627950668" quat="0.11054379492998123 0.0 0.0 0.99387127161026" class="collision"/>
          <geom type="box" pos="-0.12674281 0.06355965 -0.05156071" size="0.0035313612315803766 0.02073225937783718 0.10418971627950668" quat="0.31351524591445923 0.0 0.0 0.9495831727981567" class="collision"/>
          <geom type="box" pos="-0.09437106 0.09306093 -0.05156071" size="0.0035313607659190893 0.020732255652546883 0.10418971627950668" quat="0.4998989999294281 0.0 0.0 0.8660836815834045" class="collision"/>
          <geom type="box" pos="-0.07454212 0.10196567 -0.05156071" size="0.003531360998749733 0.020732257515192032 0.10418971627950668" quat="0.585281491279602 0.0 0.0 0.8108301758766174" class="collision"/>
          <geom type="box" pos="0.06635233 -0.00776355 -0.00671871" size="0.003531360998749733 0.020732257515192032 0.05934770777821541" quat="0.999381422996521 0.0 0.0 -0.03516842797398567" class="collision"/>
          <geom class="collision" type="box" pos="0.11620237 0.00000969 0.09483030" size="0.04474826902151108 0.02653958648443222 0.00876293983310461" quat="1.0 0.0 0.0 0.0" name="handle_1"/>
          <geom class="collision" type="box" pos="0.14671671 0.00000969 0.00441366" size="0.026539616286754608 0.02080962248146534 0.07887310534715652" quat="0.7067153453826904 -0.02352476492524147 -0.02352476678788662 0.7067153453826904" name="handle_main"/>
          <geom type="box" pos="-0.05687099 -0.09396544 0.10908151" size="0.003977437969297171 0.020732255652546883 0.05129411444067955" quat="0.6439078450202942 -0.10060315579175949 -0.11708022654056549 -0.7493690252304077" class="collision"/>
          <geom type="box" pos="-0.09193143 -0.08049785 0.10908145" size="0.003977437969297171 0.020732253789901733 0.05129411071538925" quat="0.48366251587867737 -0.12169675529003143 -0.09496693313121796 -0.8615345358848572" class="collision"/>
          <geom type="box" pos="-0.11965933 -0.05367526 0.10908145" size="0.003977437969297171 0.020732251927256584 0.05129410699009895" quat="0.29932263493537903 -0.13839606940746307 -0.06837660819292068 -0.9415822625160217" class="collision"/>
          <geom type="box" pos="-0.13399474 -0.02043977 0.10908151" size="0.003977437969297171 0.020732257515192032 0.05129411444067955" quat="0.1151157096028328 -0.14886033535003662 -0.04085797071456909 -0.9812846779823303" class="collision"/>
          <geom type="box" pos="-0.13466726 0.01711230 0.10908145" size="0.003977437969297171 0.020732248201966286 0.05129410699009895" quat="0.08045467734336853 0.1539924293756485 0.010731582529842854 0.9847325682640076" class="collision"/>
          <geom type="box" pos="-0.12020913 0.05287893 0.10908145" size="0.003977437969297171 0.020732250064611435 0.051294099539518356" quat="0.2780543267726898 0.1529783308506012 -0.020651372149586678 0.9480806589126587" class="collision"/>
          <geom type="box" pos="-0.09507081 0.07843887 0.10908151" size="0.003977437969297171 0.020732255652546883 0.05129411444067955" quat="0.45137497782707214 0.14636589586734772 -0.04904959723353386 0.8788809776306152" class="collision"/>
          <geom type="box" pos="-0.06056952 0.09328042 0.10908145" size="0.003977437969297171 0.020732251927256584 0.05129410699009895" quat="0.615670382976532 0.13383470475673676 -0.0769226998090744 0.772736132144928" class="collision"/>
          <geom type="box" pos="-0.02199152 0.09344192 0.10908145" size="0.003977437969297171 0.020732253789901733 0.05129410699009895" quat="0.7592993974685669 0.11550059914588928 -0.10241339355707169 0.6321672797203064" class="collision"/>
          <geom type="box" pos="0.01238178 0.07905948 0.10908151" size="0.003977437969297171 0.020732255652546883 0.05129411444067955" quat="0.8682090640068054 0.09325709939002991 -0.12301197648048401 0.4715763032436371" class="collision"/>
          <geom type="box" pos="0.03878241 0.05234586 0.10908145" size="0.003977437969297171 0.020732250064611435 0.05129410699009895" quat="0.9440962076187134 0.06719603389501572 -0.13897311687469482 0.2912962734699249" class="collision"/>
          <geom type="box" pos="0.05300035 0.01648310 0.10908145" size="0.003977438434958458 0.020732251927256584 0.05129410699009895" quat="0.9835100173950195 0.03768429160118103 -0.14969566464424133 0.09422940760850906" class="collision"/>
          <geom type="box" pos="0.05207895 -0.02105089 0.10908151" size="0.003977437969297171 0.020732253789901733 0.05129411444067955" quat="0.9828066229820251 0.00746604148298502 -0.1541852504014969 -0.1013031005859375" class="collision"/>
          <geom type="box" pos="0.03672742 -0.05532835 0.10908145" size="0.003977438434958458 0.020732250064611435 0.051294099539518356" quat="0.9435896873474121 -0.02305513620376587 -0.15263450145721436 -0.29293292760849" class="collision"/>
          <geom type="box" pos="0.00843872 -0.08155882 0.10908145" size="0.003977437969297171 0.020732251927256584 0.05129410699009895" quat="0.864793598651886 -0.05346410349011421 -0.14481158554553986 -0.47781088948249817" class="collision"/>
          <geom type="box" pos="-0.02433717 -0.09386650 0.10908145" size="0.003977437503635883 0.020732250064611435 0.05129410699009895" quat="0.7623418569564819 -0.07914788275957108 -0.13253068923950195 -0.6284950971603394" class="collision"/>
          <geom type="box" pos="-0.14139876 0.00000970 0.11245653" size="0.023766638711094856 0.02080962248146534 0.024814028292894363" quat="0.6947651505470276 -0.1315348893404007 -0.1315348744392395 0.6947650909423828" class="collision"/>
          <geom class="collision" type="box" pos="0.09339941 0.00000969 0.11490469" size="0.026539601385593414 0.04474828392267227 0.008762944489717484" quat="0.7051696181297302 0.052305132150650024 0.05230513587594032 0.7051695585250854" name="handle_2"/>
          <geom type="cylinder" pos="-0.04088974 0.00000970 -0.15097396" size="0.11124438792467117 0.0036440379917621613" quat="0.7071068286895752 0.0 0.0 0.7071067690849304" class="collision"/>
          <body name="button_lid">
            <joint axis="0.0 0.0 -1.0" pos="0.10462500 0.00000279 0.13733089" limited="true" name="button_lid_joint" range="0.0 0.004" type="slide" damping="100" frictionloss="1" armature=".01" stiffness="1" springref="-0.5"/>
            <geom mesh="button_lid_vis" type="mesh" solimp="0.998 0.998 0.001" solref="0.001 1" friction="0.95 0.3 0.1" class="visual" material="button_lid_material"/>
            <geom class="collision" type="box" pos="0.09766245 0.00048437 0.13435811" size="0.016185544431209564 0.031404461711645126 0.006680401507765055" quat="0.7043230533599854 0.06268153339624405 0.06268154829740524 0.7043231725692749" name="button_lid_main"/>
          </body>
          <body name="lid">
            <joint axis="0.0 1.0 0.0" pos="0.03631870 0.00000038 0.15721738" limited="true" name="lid_joint" range="0.0 1.5707963267948966" type="hinge" damping="1" frictionloss="1" armature=".01" stiffness="0.05"/>
            <geom mesh="lid_vis" type="mesh" solimp="0.998 0.998 0.001" solref="0.001 1" friction="0.95 0.3 0.1" class="visual" material="lid_material"/>
            <geom class="collision" type="cylinder" pos="-0.04088974 0.00000970 0.16603878" size="0.0638863667845726 0.005286297760903835" quat="1.0 0.0 0.0 0.0" name="lid_main"/>
            <geom class="collision" type="cylinder" pos="-0.04088974 0.00000970 0.17554356" size="0.04869084432721138 0.004028938245028257" quat="1.0 0.0 0.0 0.0" name="lid_1"/>
            <geom class="collision" type="cylinder" pos="-0.04088974 0.00000970 0.18516879" size="0.027325695380568504 0.0022610723972320557" quat="1.0 0.0 0.0 0.0" name="lid_2"/>
          </body>
          <body name="switch">
            <joint axis="0.0 1.0 0.0" pos="0.07133611 0.00000034 -0.09759223" limited="true" name="switch_joint" range="0.0 0.22689280275926282" type="hinge" damping="1" frictionloss="1" armature=".01" stiffness="0.05"/>
            <geom mesh="switch_vis" type="mesh" solimp="0.998 0.998 0.001" solref="0.001 1" friction="0.95 0.3 0.1" class="visual" material="switch_material"/>
            <geom class="collision" type="box" pos="0.07073595 0.00000969 -0.09779774" size="0.018760845065116882 0.0036192922852933407 0.02099692076444626" quat="0.705668032169342 -0.045084889978170395 -0.04508490115404129 0.705668032169342" name="switch_main"/>
          </body>
        </body>
        <geom class="region" name="reg_main" type="box" pos="0.0 2.3000000000002185e-05 9.999999994736442e-09" size="0.17513573 0.11251412 0.19039951"/>
      </body>
    </body>
  </worldbody>
  <actuator>
    <!-- <motor name="kettle_main_joint_actuator" joint="kettle_main_joint" gear="10"/> -->
    <motor name="button_lid_joint_actuator" joint="button_lid_joint" gear="50"/>
    <motor name="lid_joint_actuator" joint="lid_joint" gear="0.5"/>
    <motor name="switch_joint_actuator" joint="switch_joint" gear="50"/>
  </actuator>
</mujoco>