<?xml version='1.0' encoding='UTF-8'?>
<mujoco model="model">
  <option timestep="0.002" gravity="0.0 0.0 -9.81"/>
  <compiler angle="radian"/>
  <asset>
    <mesh file="visuals/handle.obj" name="handle_vis"/>
    <mesh file="visuals/Body001.obj" name="Body001_vis"/>
    <mesh file="visuals/spout.obj" name="spout_vis"/>
    <texture file="visuals/T_BC001.png" name="Body001_material" type="2d"/>
    <material name="Body001_material" rgba="1 1 1 1.0" texture="Body001_material" shininess="0.1" specular="0.9"/>
    <texture file="visuals/T_BC001.png" name="handle_material" type="2d"/>
    <material name="handle_material" rgba="1 1 1 1.0" texture="handle_material" shininess="0.1" specular="0.9"/>
    <texture file="visuals/T_BC001.png" name="spout_material" type="2d"/>
    <material name="spout_material" rgba="1 1 1 1.0" texture="spout_material" shininess="0.1" specular="0.9"/>
  </asset>
  <default>
    <default class="visual">
      <geom conaffinity="0" contype="0" group="1" type="mesh"/>
    </default>
    <default class="collision">
      <geom group="0" rgba="0.5 0 0 0.5"/>
    </default>
    <default class="spawn">
      <geom group="0" rgba="1 1 1 0.5" contype="0" conaffinity="0"/>
      <site group="0" rgba="1 1 1 0.5"/>
    </default>
    <default class="region">
      <geom group="1" conaffinity="0" contype="0" rgba="0 1 0 0"/>
    </default>
  </default>
  <worldbody>
    <body>
      <body name="object">
        <geom mesh="Body001_vis" type="mesh" solimp="0.998 0.998 0.001" solref="0.001 1" friction="0.95 0.3 0.1" class="visual" material="Body001_material"/>
        <geom class="collision" type="box" pos="0.00000010 -0.02723934 -0.24971938" size="0.21356330811977386 0.2224341630935669 0.027828527614474297" quat="1.0 0.0 0.0 0.0"/>
        <geom class="collision" type="box" pos="0.00000008 -0.22821340 -0.15838618" size="0.21356332302093506 0.021460069343447685 0.08808031678199768" quat="1.0 0.0 0.0 0.0"/>
        <geom class="collision" type="box" pos="0.00000005 0.17633932 -0.15838618" size="0.21356338262557983 0.018855499103665352 0.08808031678199768" quat="1.0 0.0 0.0 0.0"/>
        <geom class="collision" type="box" pos="0.19384086 -0.02623338 -0.15838618" size="0.019722601398825645 0.21366256475448608 0.08808031678199768" quat="1.0 0.0 0.0 0.0"/>
        <geom class="collision" type="box" pos="-0.19070537 -0.02623338 -0.15838618" size="0.02285793609917164 0.21366256475448608 0.08808031678199768" quat="1.0 0.0 0.0 0.0"/>
        <geom class="collision" type="box" pos="0.01479127 0.23080759 -0.06365855" size="0.037191566079854965 0.019080042839050293 0.006647302769124508" quat="1.0 0.0 0.0 0.0"/>
        <geom class="collision" type="cylinder" pos="-0.00117334 0.23184376 -0.01816747" size="0.014722767286002636 0.035603467375040054" quat="1.0 0.0 0.0 0.0"/>
        <geom class="collision" type="cylinder" pos="0.01772805 0.23094559 -0.01612609" size="0.01090774405747652 0.009847342036664486" quat="0.7071068286895752 -0.0 0.7071067690849304 0.0"/>
        <body name="handle">
          <joint axis="1.0 0.0 0.0" pos="0.03685264 0.23096340 -0.01635845" limited="true" name="handle_temp_joint" type="hinge" range="-0.7853981633974483 0.7853981633974483" damping="1" frictionloss="1" armature=".01" stiffness="0.05"/>
          <joint axis="0.0 1.0 0.0" pos="0.03685264 0.23096340 -0.01635845" limited="true" name="handle_joint" type="hinge" range="0 0.5" damping="1" frictionloss="1" armature=".01" stiffness="0.05"/>
          <geom mesh="handle_vis" type="mesh" solimp="0.998 0.998 0.001" solref="0.001 1" friction="0.95 0.3 0.1" class="visual" material="handle_material"/>
          <geom name="handle_main" class="collision" type="cylinder" pos="0.04065097 0.23094559 0.01637959" size="0.0021245551761239767 0.021682260558009148" quat="1.0 0.0 0.0 0.0"/>
          <geom class="collision" type="cylinder" pos="0.04046332 0.23094559 -0.01612609" size="0.011749033816158772 0.004021472297608852" quat="0.7071068286895752 -0.0 0.7071067690849304 0.0"/>
        </body>
        <body name="spout">
          <joint axis="0.0 0.0 1.0" pos="-0.00125000 0.23182844 0.16170767" limited="true" name="spout_joint" range="-0.7853981633974483 0.7853981633974483" type="hinge" damping="1" frictionloss="1" armature=".01" stiffness="0.05"/>
          <site type="cylinder" rgba="0.5 0.75 1 0.5" size="0.008400022983551025 0.1558043658733368" pos="-0.00121276 0.05851951 -0.10721771" name="water"/>
          <geom mesh="spout_vis" type="mesh" solimp="0.998 0.998 0.001" solref="0.001 1" friction="0.95 0.3 0.1" class="visual" material="spout_material"/>
          <geom class="collision" type="cylinder" pos="-0.00117334 0.23171637 0.06826868" size="0.010490449145436287 0.051460057497024536" quat="1.0 0.0 0.0 0.0" name="spout_main"/>
          <geom class="collision" type="cylinder" pos="-0.00155641 0.23216756 0.15987796" size="0.00506379920989275 0.041539017111063004" quat="1.0 0.0 0.0 0.0"/>
          <geom class="collision" type="cylinder" pos="-0.00155642 0.22384206 0.22274806" size="0.00506379920989275 0.024297237396240234" quat="0.9829229712486267 0.1840173751115799 0.0 0.0"/>
          <geom class="collision" type="cylinder" pos="-0.00155642 0.19497781 0.25728132" size="0.00506379920989275 0.024297237396240234" quat="0.8916955590248108 0.4526357054710388 0.0 0.0"/>
          <geom class="collision" type="cylinder" pos="-0.00155642 0.14936345 0.27180085" size="0.00506379920989275 0.024297237396240234" quat="0.7119148969650269 0.702265739440918 1.9894496097094492e-18 -2.1740198673544782e-18"/>
          <geom class="collision" type="cylinder" pos="-0.00155642 0.10434016 0.26193269" size="0.00506379920989275 0.024297237396240234" quat="0.5284743905067444 0.8489492535591125 2.441664287508514e-18 -1.6500137706016298e-18"/>
          <geom class="collision" type="cylinder" pos="-0.00155642 0.06893397 0.22529845" size="0.00506379920989275 0.029924193397164345" quat="0.21848298609256744 0.9758407473564148 2.8496198394523167e-18 -7.511655576927601e-19"/>
          <geom class="collision" type="cylinder" pos="-0.00155641 0.05851950 0.15921471" size="0.00506379920989275 0.0355721190571785" quat="1.0 0.0 0.0 0.0"/>
          <geom class="collision" type="cylinder" pos="-0.00121276 0.05851950 0.08494469" size="0.010660765692591667 0.03866029903292656" quat="1.0 0.0 0.0 0.0"/>
          <geom class="collision" type="box" pos="-0.00141570 0.14590306 0.11163712" size="0.0014512402703985572 0.07775963097810745 0.005529983434826136" quat="1.0 0.0 0.0 0.0"/>
          <geom class="collision" type="box" pos="-0.00109286 0.04718370 0.07634044" size="0.004602022003382444 0.0018451862270012498 0.01818827912211418" quat="1.0 0.0 0.0 0.0"/>
        </body>
        <geom class="region" name="reg_basin" type="box" pos="0.0009517599999999959 -0.027191284999999996 -0.143973695" size="0.16202133 0.171441785 0.074948635"/>
        <geom class="region" name="reg_main" type="box" pos="-4.999999997368221e-09 -0.027239324999999995 -0.17417639000000001" size="0.214563235 0.22343416500000002 0.10487054000000001"/>
      </body>
    </body>
  </worldbody>
  <actuator>
    <motor name="handle_joint_actuator" joint="handle_joint" gear="10"/>
    <motor name="handle_temp_joint_actuator" joint="handle_temp_joint" gear="10"/>
    <motor name="spout_joint_actuator" joint="spout_joint" gear="10"/>
  </actuator>
</mujoco>
