<?xml version='1.0' encoding='UTF-8'?>
<mujoco model="model">
  <option timestep="0.002" gravity="0.0 0.0 -9.81"/>
  <compiler angle="radian"/>
  <asset>
    <mesh file="visuals/sideL_button_cancel.obj" name="sideL_button_cancel_vis"/>
    <mesh file="visuals/sideL_knob_doneness.obj" name="sideL_knob_doneness_vis"/>
    <mesh file="visuals/sideL_lever.obj" name="sideL_lever_vis"/>
    <mesh file="visuals/sideR_button_cancel.obj" name="sideR_button_cancel_vis"/>
    <mesh file="visuals/sideR_knob_doneness.obj" name="sideR_knob_doneness_vis"/>
    <mesh file="visuals/sideR_lever.obj" name="sideR_lever_vis"/>
    <mesh file="visuals/Body001.obj" name="Body001_vis"/>
    <texture file="visuals/T_BC001.png" name="Body001_material" type="2d"/>
    <material name="Body001_material" rgba="1 1 1 1.0" texture="Body001_material" shininess="0.1" specular="5"/>
    <texture file="visuals/T_BC001.png" name="sideL_button_cancel_material" type="2d"/>
    <material name="sideL_button_cancel_material" rgba="1 1 1 1.0" texture="sideL_button_cancel_material" shininess="0.1" specular="5"/>
    <texture file="visuals/T_BC001.png" name="sideL_knob_doneness_material" type="2d"/>
    <material name="sideL_knob_doneness_material" rgba="1 1 1 1.0" texture="sideL_knob_doneness_material" shininess="0.1" specular="5"/>
    <texture file="visuals/T_BC001.png" name="sideL_lever_material" type="2d"/>
    <material name="sideL_lever_material" rgba="1 1 1 1.0" texture="sideL_lever_material" shininess="0.1" specular="5"/>
    <texture file="visuals/T_BC001.png" name="sideR_button_cancel_material" type="2d"/>
    <material name="sideR_button_cancel_material" rgba="1 1 1 1.0" texture="sideR_button_cancel_material" shininess="0.1" specular="5"/>
    <texture file="visuals/T_BC001.png" name="sideR_knob_doneness_material" type="2d"/>
    <material name="sideR_knob_doneness_material" rgba="1 1 1 1.0" texture="sideR_knob_doneness_material" shininess="0.1" specular="5"/>
    <texture file="visuals/T_BC001.png" name="sideR_lever_material" type="2d"/>
    <material name="sideR_lever_material" rgba="1 1 1 1.0" texture="sideR_lever_material" shininess="0.1" specular="5"/>
  </asset>
  <default>
    <default class="visual">
      <geom conaffinity="0" contype="0" group="1" type="mesh"/>
    </default>
    <default class="collision_1">
      <geom group="0" rgba="0.5 0 0 0.5" solref="0.004 1" solimp="0.998 0.998 0.001"/>
    </default>
    <default class="collision_2">
      <geom group="0" rgba="0.5 0 0 0.5" solref="0.004 1" solimp="0.998 0.998 0.001"/>
    </default>
    <default class="collision_3">
      <geom group="0" rgba="0.5 0 0 0.5" solref="0.004 1" solimp="0.998 0.998 0.001"/>
    </default>
    <default class="collision_4">
      <geom group="0" rgba="0.5 0 0 0.5" solref="0.004 1" solimp="0.998 0.998 0.001"/>
    </default>
    <default class="collision_5">
      <geom group="0" rgba="0.5 0 0 0.5" solref="0.004 1" solimp="0.998 0.998 0.001"/>
    </default>
    <default class="collision_6">
      <geom group="0" rgba="0.5 0 0 0.5" solref="0.004 1" solimp="0.998 0.998 0.001"/>
    </default>
    <default class="collision_7">
      <geom group="0" rgba="0.5 0 0 0.5" solref="0.004 1" solimp="0.998 0.998 0.001"/>
    </default>
    <default class="spawn">
      <geom group="0" rgba="1 1 1 0.5" contype="0" conaffinity="0"/>
      <site group="0" rgba="1 1 1 0.5"/>
    </default>
    <default class="region">
      <geom group="1" conaffinity="0" contype="0" rgba="0 1 0 0" mass="0"/>
    </default>
  </default>
  <worldbody>
    <body>
      <body name="object">
        <geom mesh="Body001_vis" type="mesh" solimp="0.998 0.998 0.001" solref="0.001 1" friction="0.95 0.3 0.1" class="visual" material="Body001_material"/>
        <geom type="box" pos="-0.0012560514733195305 0.12971682846546173 -0.0017426153644919395" size="0.16246019303798676 0.03374330326914787 0.09306848794221878" quat="1.0 0.0 0.0 0.0" class="collision_1"/>
        <geom type="box" pos="-0.0006148911779746413 -0.11116699874401093 -0.0015051248483359814" size="0.16264528036117554 0.03222201019525528 0.0927574634552002" quat="1.0 0.0 0.0 0.0" class="collision_1"/>
        <geom type="box" pos="0.13630668818950653 0.009045934304594994 0.0010561231756582856" size="0.025313517078757286 0.08799093216657639 0.09395420551300049" quat="1.0 0.0 0.0 0.0" class="collision_1"/>
        <geom type="box" pos="-0.13585346937179565 0.009045934304594994 0.0007388443918898702" size="0.0253834817558527 0.08799093216657639 0.09363691508769989" quat="1.0 0.0 0.0 0.0" class="collision_1"/>
        <geom type="box" pos="-0.0678049698472023 0.009045934304594994 0.0010561231756582856" size="0.016553794965147972 0.08799093216657639 0.09395420551300049" quat="1.0 0.0 0.0 0.0" class="collision_1"/>
        <geom type="box" pos="8.098941179923713e-05 0.009045934304594994 0.0010561231756582856" size="0.024907933548092842 0.08799093216657639 0.09395420551300049" quat="1.0 0.0 0.0 0.0" class="collision_1"/>
        <geom type="box" pos="0.06841133534908295 0.009045934304594994 0.0010561231756582856" size="0.016349172219634056 0.08799093216657639 0.09395420551300049" quat="1.0 0.0 0.0 0.0" class="collision_1"/>
        <geom type="box" pos="-5.163844980415888e-05 0.013782797381281853 -0.06903751939535141" size="0.160116046667099 0.1482686698436737 0.025194332003593445" quat="1.0 0.0 0.0 0.0" class="collision_1"/>
        <body name="sideL_button_cancel">
          <joint axis="0.0 1.0 0.0" pos="-0.11383563280105591 -0.14538095891475677 -0.05240114778280258" limited="true" name="sideL_button_cancel_joint" range="0.0 0.0025" type="slide" damping="1" frictionloss="1" armature=".01" stiffness="4" springref="-1"/>
          <geom mesh="sideL_button_cancel_vis" type="mesh" solimp="0.998 0.998 0.001" solref="0.001 1" friction="0.95 0.3 0.1" class="visual" material="sideL_button_cancel_material"/>
          <geom class="collision_2" type="box" pos="-0.11383930593729019 -0.1463705152273178 -0.052384551614522934" size="0.015842219814658165 0.0013096303446218371 0.005820271093398333" quat="1.0 0.0 0.0 0.0" name="sideL_button_cancel_main"/>
        </body>
        <body name="sideL_knob_doneness">
          <joint axis="0.0 1.0 0.0" pos="-0.07382764667272568 -0.14924290776252747 -0.052457500249147415" limited="true" name="sideL_knob_doneness_joint" range="0.0 4.6774823953448035" type="hinge" damping="0.05" armature="1" frictionloss="0.75"/>
          <geom mesh="sideL_knob_doneness_vis" type="mesh" solimp="0.998 0.998 0.001" solref="0.001 1" friction="0.95 0.3 0.1" class="visual" material="sideL_knob_doneness_material"/>
          <geom type="cylinder" pos="-0.07373664528131485 -0.146297425031662 -0.05240565538406372" size="0.018016349524259567 0.002148986328393221" quat="0.7071067094802856 0.7071068286895752 0.0 0.0" class="collision_3" friction="100 0.5 0.01"/>
          <geom class="collision_3" type="box" pos="-0.0743117481470108 -0.15460531413555145 -0.052469756454229355" size="0.006345165893435478 0.00603867881000042 0.014894815161824226" quat="0.9238795042037964 0.0 0.3826834559440613 0.0" name="sideL_knob_doneness_main" friction="100 0.5 0.01"/>
        </body>
        <body name="sideL_lever">
          <joint axis="0.0 0.0 -1.0" pos="-0.07383695244789124 -0.15048380196094513 0.06355318427085876" limited="true" name="sideL_lever_joint" range="0.0 0.057999999999999996" type="slide" damping="1" frictionloss="1" armature=".1" stiffness="3.2" springref="-0.5"/>
          <geom class="region" name="reg_sideL_slotL" type="box" pos="-0.09734488651156425 0.008882109075784683 0.09173226542770863" size="0.012949364095926286 0.08735127916932106 0.07600000111758709"/>
          <geom class="region" name="reg_sideL_slotR" type="box" pos="-0.03838101960718632 0.008882109075784683 0.09173226542770863" size="0.013353362515568734 0.08735127916932106 0.07600000111758709"/>
          <geom mesh="sideL_lever_vis" type="mesh" solimp="0.998 0.998 0.001" solref="0.001 1" friction="0.95 0.3 0.1" class="visual" material="sideL_lever_material"/>
          <geom class="collision_4" type="box" pos="-0.07362759113311768 -0.1536025106906891 0.0610208697617054" size="0.017076076939702034 0.008703199215233326 0.0042862179689109325" quat="1.0 0.0 0.0 0.0" name="sideL_lever_handle"/>
          <geom class="collision_4" type="box" pos="-0.037956517189741135 0.009057892486453056 0.014988172799348831" size="0.012499943375587463 0.08546552807092667 0.0013593488838523626" quat="1.0 0.0 0.0 0.0" name="sideL_slotR_floor"/>
          <geom class="collision_4" type="box" pos="-0.09746018797159195 0.009057892486453056 0.014988172799348831" size="0.012499960139393806 0.08546552807092667 0.0013593488838523626" quat="1.0 0.0 0.0 0.0" name="sideL_slotL_floor"/>
        </body>
        <body name="sideR_button_cancel">
          <joint axis="0.0 1.0 0.0" pos="0.11383558809757233 -0.14538095891475677 -0.05240114778280258" limited="true" name="sideR_button_cancel_joint" range="0.0 0.0025" type="slide" damping="1" frictionloss="1" armature=".01" stiffness="4" springref="-1"/>
          <geom mesh="sideR_button_cancel_vis" type="mesh" solimp="0.998 0.998 0.001" solref="0.001 1" friction="0.95 0.3 0.1" class="visual" material="sideR_button_cancel_material"/>
          <geom class="collision_5" type="box" pos="0.1138099655508995 -0.14624431729316711 -0.05224185809493065" size="0.0158662311732769 0.0013519369531422853 0.006011961027979851" quat="1.0 0.0 0.0 0.0" name="sideR_button_cancel_main"/>
        </body>
        <body name="sideR_knob_doneness">
          <joint axis="0.0 1.0 0.0" pos="0.07377184182405472 -0.14924290776252747 -0.052457500249147415" limited="true" name="sideR_knob_doneness_joint" range="0.0 4.6774823953448035" type="hinge" damping="0.05" armature="1" frictionloss="0.75"/>
          <geom mesh="sideR_knob_doneness_vis" type="mesh" solimp="0.998 0.998 0.001" solref="0.001 1" friction="0.95 0.3 0.1" class="visual" material="sideR_knob_doneness_material"/>
          <geom type="cylinder" pos="0.07379748672246933 -0.14628790318965912 -0.0523960217833519" size="0.0178628321737051 0.0022610612213611603" quat="0.7071067094802856 0.7071068286895752 0.0 0.0" class="collision_6" friction="100 0.5 0.01"/>
          <geom class="collision_6" type="box" pos="0.07394041121006012 -0.15460531413555145 -0.052469756454229355" size="0.006345165893435478 0.00603867881000042 0.014894815161824226" quat="0.9238795042037964 0.0 0.3826834559440613 0.0" name="sideR_knob_doneness_main" friction="100 0.5 0.01"/>
        </body>
        <body name="sideR_lever">
          <joint axis="0.0 0.0 -1.0" pos="0.07383693754673004 -0.15048380196094513 0.06355318427085876" limited="true" name="sideR_lever_joint" range="0.0 0.057999999999999996" type="slide" damping="1" frictionloss="1" armature=".1" stiffness="3.2" springref="-0.5"/>
          <geom class="region" name="reg_sideR_slotL" type="box" pos="0.038619017228484154 0.008882109075784683 0.09173226542770863" size="0.013686735019087792 0.08735127916932106 0.07600000111758709"/>
          <geom class="region" name="reg_sideR_slotR" type="box" pos="0.09797613322734833 0.008882109075784683 0.09173226542770863" size="0.013448891997337342 0.08735127916932106 0.07600000111758709"/>
          <geom mesh="sideR_lever_vis" type="mesh" solimp="0.998 0.998 0.001" solref="0.001 1" friction="0.95 0.3 0.1" class="visual" material="sideR_lever_material"/>
          <geom class="collision_7" type="box" pos="0.074133962392807 -0.1536025106906891 0.0610208697617054" size="0.01707603968679905 0.008703179657459259 0.004286210518330336" quat="1.0 0.0 0.0 0.0" name="sideR_lever_handle"/>
          <geom class="collision_7" type="box" pos="0.09799081832170486 0.009057892486453056 0.014988172799348831" size="0.01249999925494194 0.08546552807092667 0.0013593488838523626" quat="1.0 0.0 0.0 0.0" name="sideR_slotR_floor"/>
          <geom class="collision_7" type="box" pos="0.03848715126514435 0.009057892486453056 0.014988172799348831" size="0.01249999925494194 0.08546552807092667 0.0013593488838523626" quat="1.0 0.0 0.0 0.0" name="sideR_slotL_floor"/>
        </body>
        <geom class="region" name="reg_main" type="box" pos="3.725290298461914e-09 0.009046092629432678 0.0" size="0.16220414435863495 0.15400731360912323 0.09523209726810455"/>
      </body>
    </body>
  </worldbody>
  <actuator>
    <motor name="sideL_button_cancel_joint_actuator" joint="sideL_button_cancel_joint" gear="0.5"/>
    <motor name="sideL_knob_doneness_joint_actuator" joint="sideL_knob_doneness_joint" gear="0.5"/>
    <motor name="sideL_lever_joint_actuator" joint="sideL_lever_joint" gear="0.5"/>
    <motor name="sideR_button_cancel_joint_actuator" joint="sideR_button_cancel_joint" gear="0.5"/>
    <motor name="sideR_knob_doneness_joint_actuator" joint="sideR_knob_doneness_joint" gear="0.5"/>
    <motor name="sideR_lever_joint_actuator" joint="sideR_lever_joint" gear="0.5"/>
  </actuator>
</mujoco>