<?xml version='1.0' encoding='UTF-8'?>
<mujoco model="model">
  <option timestep="0.002" gravity="0.0 0.0 -9.81"/>
  <compiler angle="radian"/>
  <asset>
    <mesh file="visuals/door.obj" name="door_vis"/>
    <mesh file="visuals/door_Clear.obj" name="door_Clear_vis"/>
    <mesh file="visuals/knob_front_center.obj" name="knob_front_center_vis"/>
    <mesh file="visuals/knob_front_left.obj" name="knob_front_left_vis"/>
    <mesh file="visuals/knob_front_right.obj" name="knob_front_right_vis"/>
    <mesh file="visuals/knob_rear_center.obj" name="knob_rear_center_vis"/>
    <mesh file="visuals/knob_rear_left.obj" name="knob_rear_left_vis"/>
    <mesh file="visuals/knob_rear_right.obj" name="knob_rear_right_vis"/>
    <mesh file="visuals/knob_temp.obj" name="knob_temp_vis"/>
    <mesh file="visuals/knob_time.obj" name="knob_time_vis"/>
    <mesh file="visuals/rack0.obj" name="rack0_vis"/>
    <mesh file="visuals/rack1.obj" name="rack1_vis"/>
    <mesh file="visuals/Body001.obj" name="Body001_vis"/>
    <texture file="visuals/T_BC001.png" name="Body001_material" type="2d"/>
    <material name="Body001_material" rgba="1 1 1 1.0" texture="Body001_material" shininess="0.4472135901451111" specular="2"/>
    <texture file="visuals/T_BC001.png" name="door_material" type="2d"/>
    <material name="door_material" rgba="1 1 1 1.0" texture="door_material" shininess="0.4472135901451111" specular="0.3103448502657381"/>
    <texture file="visuals/T_BC001.png" name="door_Clear_material" type="2d"/>
    <material name="door_Clear_material" rgba="1 1 1 0.8" texture="door_Clear_material" shininess="0.5" specular="2"/>
    <texture file="visuals/T_BC001.png" name="knob_front_center_material" type="2d"/>
    <material name="knob_front_center_material" rgba="1 1 1 1.0" texture="knob_front_center_material" shininess="0.4472135901451111" specular="0.3103448502657381"/>
    <texture file="visuals/T_BC001.png" name="knob_front_left_material" type="2d"/>
    <material name="knob_front_left_material" rgba="1 1 1 1.0" texture="knob_front_left_material" shininess="0.4472135901451111" specular="0.3103448502657381"/>
    <texture file="visuals/T_BC001.png" name="knob_front_right_material" type="2d"/>
    <material name="knob_front_right_material" rgba="1 1 1 1.0" texture="knob_front_right_material" shininess="0.4472135901451111" specular="0.3103448502657381"/>
    <texture file="visuals/T_BC001.png" name="knob_rear_center_material" type="2d"/>
    <material name="knob_rear_center_material" rgba="1 1 1 1.0" texture="knob_rear_center_material" shininess="0.4472135901451111" specular="0.3103448502657381"/>
    <texture file="visuals/T_BC001.png" name="knob_rear_left_material" type="2d"/>
    <material name="knob_rear_left_material" rgba="1 1 1 1.0" texture="knob_rear_left_material" shininess="0.4472135901451111" specular="0.3103448502657381"/>
    <texture file="visuals/T_BC001.png" name="knob_rear_right_material" type="2d"/>
    <material name="knob_rear_right_material" rgba="1 1 1 1.0" texture="knob_rear_right_material" shininess="0.4472135901451111" specular="0.3103448502657381"/>
    <texture file="visuals/T_BC001.png" name="knob_temp_material" type="2d"/>
    <material name="knob_temp_material" rgba="1 1 1 1.0" texture="knob_temp_material" shininess="0.4472135901451111" specular="0.3103448502657381"/>
    <texture file="visuals/T_BC001.png" name="knob_time_material" type="2d"/>
    <material name="knob_time_material" rgba="1 1 1 1.0" texture="knob_time_material" shininess="0.4472135901451111" specular="0.3103448502657381"/>
    <texture file="visuals/T_BC001.png" name="rack0_material" type="2d"/>
    <material name="rack0_material" rgba="1 1 1 1.0" texture="rack0_material" shininess="0.4472135901451111" specular="2"/>
    <texture file="visuals/T_BC001.png" name="rack1_material" type="2d"/>
    <material name="rack1_material" rgba="1 1 1 1.0" texture="rack1_material" shininess="0.4472135901451111" specular="2"/>
  </asset>
  <default>
    <default class="visual">
      <geom conaffinity="0" contype="0" group="1" type="mesh"/>
    </default>
    <default class="collision">
      <geom group="0" rgba="0.5 0 0 0.5"/>
    </default>
    <default class="spawn">
      <geom group="0" rgba="1 1 1 0.5" contype="0" conaffinity="0"/>
      <site group="0" rgba="1 1 1 0.5"/>
    </default>
    <default class="region">
      <geom group="1" conaffinity="0" contype="0" rgba="0 1 0 0"/>
    </default>
  </default>
  <worldbody>
    <body>
      <body name="object">
        <geom mesh="Body001_vis" type="mesh" solimp="0.998 0.998 0.001" solref="0.001 1" friction="0.95 0.3 0.1" class="visual" material="Body001_material"/>
        <geom class="collision" type="box" pos="0.36442062 -0.07107395 0.11972211" size="0.018662435933947563 0.18144045770168304 0.0023834460880607367" quat="1.0 0.0 0.0 0.0"/>
        <geom class="collision" type="box" pos="0.36442062 -0.07107395 0.08483463" size="0.018662435933947563 0.18144045770168304 0.0023834460880607367" quat="1.0 0.0 0.0 0.0"/>
        <geom class="collision" type="box" pos="0.36442062 -0.07107395 0.01778460" size="0.018662435933947563 0.18144045770168304 0.0023834460880607367" quat="1.0 0.0 0.0 0.0"/>
        <geom class="collision" type="box" pos="0.36442062 -0.07107395 -0.04949691" size="0.018662435933947563 0.18144045770168304 0.0023834460880607367" quat="1.0 0.0 0.0 0.0"/>
        <geom class="collision" type="box" pos="-0.36823025 -0.07107395 0.11972211" size="0.018662435933947563 0.18144045770168304 0.0023834460880607367" quat="1.0 0.0 0.0 0.0"/>
        <geom class="collision" type="box" pos="-0.36823025 -0.07107395 0.01778460" size="0.018662435933947563 0.18144045770168304 0.0023834460880607367" quat="1.0 0.0 0.0 0.0"/>
        <geom class="collision" type="box" pos="-0.36823025 -0.07107395 -0.04949691" size="0.018662435933947563 0.18144045770168304 0.0023834460880607367" quat="1.0 0.0 0.0 0.0"/>
        <geom class="collision" type="box" pos="-0.36697626 -0.07107395 0.08483463" size="0.018662435933947563 0.18144045770168304 0.0023834460880607367" quat="1.0 0.0 0.0 0.0"/>
        <geom class="collision" type="box" pos="-0.40745792 0.04048937 -0.02279192" size="0.016274921596050262 0.34789374470710754 0.4722433090209961" quat="1.0 0.0 0.0 0.0"/>
        <geom class="collision" type="box" pos="0.40668231 0.04017869 -0.02267685" size="0.016654742881655693 0.3475830554962158 0.47212931513786316" quat="1.0 0.0 0.0 0.0"/>
        <geom class="collision" type="box" pos="-0.00049931 0.01948482 0.37617436" size="0.42072170972824097 0.35166284441947937 0.07339657098054886" quat="1.0 0.0 0.0 0.0"/>
        <geom class="collision" type="box" pos="0.00127596 0.37787163 0.00133083" size="0.42017021775245667 0.010949005372822285 0.4954916536808014" quat="1.0 0.0 0.0 0.0"/>
        <geom class="collision" type="box" pos="-0.00002117 0.01890159 -0.37255797" size="0.42352452874183655 0.3522559106349945 0.1225961297750473" quat="1.0 0.0 0.0 0.0"/>
        <geom class="collision" type="box" pos="-0.00002117 0.01924868 -0.35098603" size="0.42352452874183655 0.3277283012866974 0.14400139451026917" quat="1.0 0.0 0.0 0.0"/>
        <geom class="collision" type="box" pos="0.00127596 0.33902419 -0.02691193" size="0.420156329870224 0.028379196301102638 0.467974990606308" quat="1.0 0.0 0.0 0.0"/>
        <geom class="collision" type="box" pos="-0.38963971 -0.07148314 0.03456661" size="0.004897887818515301 0.18065761029720306 0.14356626570224762" quat="1.0 0.0 0.0 0.0"/>
        <geom class="collision" type="box" pos="0.38668123 -0.07148314 0.03456710" size="0.004897890146821737 0.18065761029720306 0.1435663253068924" quat="1.0 0.0 0.0 0.0"/>
        <geom class="collision" type="box" pos="-0.00049931 0.01948482 0.31828767" size="0.3940332233905792 0.3293551504611969 0.04628801345825195" quat="1.0 0.0 0.0 0.0"/>
        <geom class="collision" type="box" pos="-0.00000024 0.04557000 0.46096796" size="0.33345237374305725 0.29586857557296753 0.011515788733959198" quat="1.0 0.0 0.0 0.0"/>
        <geom class="collision" type="box" pos="0.00000004 0.35967815 0.45040563" size="0.41833364963531494 0.00724449660629034 0.001000917167402804" quat="1.0 0.0 0.0 0.0"/>
        <body name="door">
          <joint axis="1.0 0.0 0.0" pos="-0.00000008 -0.32220954 -0.22697541" limited="true" name="door_joint" range="0.0 1.5707963267948966" type="hinge" damping="1" frictionloss="1" armature=".01" stiffness="1" springref="-4"/>
          <geom mesh="door_vis" type="mesh" solimp="0.998 0.998 0.001" solref="0.001 1" friction="0.95 0.3 0.1" class="visual" material="door_material"/>
          <geom class="collision" type="box" pos="-0.00000000 -0.32338038 0.03300362" size="0.42301270365715027 0.010427734814584255 0.265535831451416" quat="1.0 0.0 0.0 0.0" name="door_main"/>
          <geom class="collision" type="box" pos="-0.38080359 -0.34805244 0.26990244" size="0.013406136073172092 0.012864393182098866 0.021215109154582024" quat="1.0 0.0 0.0 0.0"/>
          <geom class="collision" type="box" pos="0.37891248 -0.34805244 0.26990244" size="0.013406136073172092 0.012864393182098866 0.021215109154582024" quat="1.0 0.0 0.0 0.0"/>
          <geom class="collision" type="box" pos="-0.00094554 -0.37582538 0.26990244" size="0.39326414465904236 0.013490837998688221 0.021215109154582024" quat="1.0 0.0 0.0 0.0" name="door_handle_main"/>
          <geom class="collision" type="box" pos="-0.00000002 -0.32257232 0.09607217" size="0.41250625252723694 0.006797316949814558 0.19522199034690857" quat="1.0 0.0 0.0 0.0"/>
          <body name="door_Clear">
            <geom mesh="door_Clear_vis" type="mesh" solimp="0.998 0.998 0.001" solref="0.001 1" friction="0.95 0.3 0.1" class="visual" material="door_Clear_material"/>
            <geom class="collision" type="box" pos="-0.00000002 -0.32257232 0.09607217" size="0.41250625252723694 0.006797316949814558 0.19522199034690857" quat="1.0 0.0 0.0 0.0"/>
          </body>
        </body>
        <body name="knob_front_center">
          <joint axis="0.0 -1.0 0.0" pos="0.05981584 -0.34303910 0.37707967" limited="true" name="knob_front_center_joint" range="0.0 3.141592653589793" type="hinge" damping="0.05" frictionloss="0.75" armature="1"/>
          <geom mesh="knob_front_center_vis" type="mesh" solimp="0.998 0.998 0.001" solref="0.001 1" friction="0.95 0.3 0.1" class="visual" material="knob_front_center_material"/>
          <geom class="collision" type="cylinder" pos="0.05974300 -0.34062976 0.37687969" size="0.02347167767584324 0.006403839215636253" quat="0.7071067094802856 0.70710688829422 -1.5700929612083792e-16 2.2148514736588345e-23" friction="100 0.5 0.01"/>
          <geom class="collision" type="box" pos="0.05910010 -0.35056436 0.37643027" size="0.005083238240331411 0.007866290397942066 0.018166102468967438" quat="1.0 0.0 0.0 0.0" name="knob_front_center_main" friction="100 0.5 0.01"/>
        </body>
        <body name="knob_front_left">
          <joint axis="0.0 -1.0 0.0" pos="-0.33796531 -0.34303898 0.37707955" limited="true" name="knob_front_left_joint" range="0.0 3.141592653589793" type="hinge" damping="0.05" frictionloss="0.75" armature="1"/>
          <geom mesh="knob_front_left_vis" type="mesh" solimp="0.998 0.998 0.001" solref="0.001 1" friction="0.95 0.3 0.1" class="visual" material="knob_front_left_material"/>
          <geom class="collision" type="cylinder" pos="-0.33822209 -0.34062976 0.37680575" size="0.02347167767584324 0.006403839215636253" quat="0.7071067094802856 0.70710688829422 -1.5700929612083792e-16 2.2148514736588345e-23" friction="100 0.5 0.01"/>
          <geom class="collision" type="box" pos="-0.33886498 -0.35056436 0.37635633" size="0.005083238240331411 0.007866299711167812 0.018166111782193184" quat="1.0 0.0 0.0 0.0" name="knob_front_left_main" friction="100 0.5 0.01"/>
        </body>
        <body name="knob_front_right">
          <joint axis="0.0 -1.0 0.0" pos="0.35715580 -0.34303907 0.37707967" limited="true" name="knob_front_right_joint" range="0.0 3.141592653589793" type="hinge" damping="0.05" armature="1" frictionloss="0.75"/>
          <geom mesh="knob_front_right_vis" type="mesh" solimp="0.998 0.998 0.001" solref="0.001 1" friction="0.95 0.3 0.1" class="visual" material="knob_front_right_material"/>
          <geom class="collision" type="cylinder" pos="0.35743338 -0.34062976 0.37707686" size="0.02347167767584324 0.006403839215636253" quat="0.7071067094802856 0.70710688829422 -1.5700929612083792e-16 2.2148514736588345e-23" friction="100 0.5 0.01"/>
          <geom class="collision" type="box" pos="0.35679036 -0.35056436 0.37662745" size="0.005083238240331411 0.00786630716174841 0.01816612109541893" quat="1.0 0.0 0.0 0.0" name="knob_front_right_main" friction="100 0.5 0.01"/>
        </body>
        <body name="knob_rear_center">
          <joint axis="0.0 -1.0 0.0" pos="0.15863809 -0.34303910 0.37707967" limited="true" name="knob_rear_center_joint" range="0.0 3.141592653589793" type="hinge" damping="0.05" frictionloss="0.75" armature="1"/>
          <geom mesh="knob_rear_center_vis" type="mesh" solimp="0.998 0.998 0.001" solref="0.001 1" friction="0.95 0.3 0.1" class="visual" material="knob_rear_center_material"/>
          <geom class="collision" type="cylinder" pos="0.15876567 -0.34062976 0.37673771" size="0.02347167767584324 0.006403839215636253" quat="0.7071067094802856 0.70710688829422 -1.5700929612083792e-16 2.2148514736588345e-23" friction="100 0.5 0.01"/>
          <geom class="collision" type="box" pos="0.15812278 -0.35056436 0.37628829" size="0.005083238240331411 0.007866575382649899 0.018166430294513702" quat="1.0 0.0 0.0 0.0" name="knob_rear_center_main" friction="100 0.5 0.01"/>
        </body>
        <body name="knob_rear_left">
          <joint axis="0.0 -1.0 0.0" pos="-0.23807894 -0.34303898 0.37707955" limited="true" name="knob_rear_left_joint" range="0.0 3.141592653589793" type="hinge" damping="0.05" frictionloss="0.75" armature="1"/>
          <geom mesh="knob_rear_left_vis" type="mesh" solimp="0.998 0.998 0.001" solref="0.001 1" friction="0.95 0.3 0.1" class="visual" material="knob_rear_left_material"/>
          <geom class="collision" type="cylinder" pos="-0.23820667 -0.34062976 0.37707686" size="0.02347167767584324 0.006403839215636253" quat="0.7071067094802856 0.70710688829422 -1.5700929612083792e-16 2.2148514736588345e-23" friction="100 0.5 0.01"/>
          <geom class="collision" type="box" pos="-0.23884957 -0.35056436 0.37662745" size="0.005083238240331411 0.00786627922207117 0.018166089430451393" quat="1.0 0.0 0.0 0.0" name="knob_rear_left_main" friction="100 0.5 0.01"/>
        </body>
        <body name="knob_rear_right">
          <joint axis="0.0 -1.0 0.0" pos="0.25762111 -0.34303915 0.37707967" limited="true" name="knob_rear_right_joint" range="0.0 3.141592653589793" type="hinge" damping="0.05" frictionloss="0.75" armature="1"/>
          <geom mesh="knob_rear_right_vis" type="mesh" solimp="0.998 0.998 0.001" solref="0.001 1" friction="0.95 0.3 0.1" class="visual" material="knob_rear_right_material"/>
          <geom class="collision" type="cylinder" pos="0.25769719 -0.34062976 0.37678111" size="0.02347167767584324 0.006403839215636253" quat="0.7071067094802856 0.70710688829422 -1.5700929612083792e-16 2.2148514736588345e-23" friction="100 0.5 0.01"/>
          <geom class="collision" type="box" pos="0.25705418 -0.35056436 0.37633169" size="0.005083238240331411 0.007866299711167812 0.018166111782193184" quat="1.0 0.0 0.0 0.0" name="knob_rear_right_main" friction="100 0.5 0.01"/>
        </body>
        <body name="knob_temp">
          <joint axis="0.0 1.0 0.0" pos="-0.13864596 -0.34303907 0.37707967" limited="true" name="knob_temp_joint" range="0.0 3.2288591161895095" type="hinge" damping="0.05" frictionloss="0.75" armature="1"/>
          <geom mesh="knob_temp_vis" type="mesh" solimp="0.998 0.998 0.001" solref="0.001 1" friction="0.95 0.3 0.1" class="visual" material="knob_temp_material"/>
          <geom class="collision" type="cylinder" pos="-0.13827902 -0.34062976 0.37697828" size="0.02347167767584324 0.006403839215636253" quat="0.7071067094802856 0.70710688829422 -1.5700929612083792e-16 2.2148514736588345e-23" friction="100 0.5 0.01"/>
          <geom class="collision" type="box" pos="-0.13892192 -0.35056436 0.37652886" size="0.005083238240331411 0.00786630716174841 0.01816612109541893" quat="1.0 0.0 0.0 0.0" name="knob_temp_main" friction="100 0.5 0.01"/>
        </body>
        <body name="knob_time">
          <joint axis="0.0 1.0 0.0" pos="-0.03929348 -0.34303910 0.37707967" limited="true" name="knob_time_joint" range="0.0 3.979350694547071" type="hinge" damping="0.05" armature="1" frictionloss="0.75"/>
          <geom mesh="knob_time_vis" type="mesh" solimp="0.998 0.998 0.001" solref="0.001 1" friction="0.95 0.3 0.1" class="visual" material="knob_time_material"/>
          <geom class="collision" type="cylinder" pos="-0.03930022 -0.34062976 0.37717548" size="0.02347167767584324 0.006403839215636253" quat="0.7071067094802856 0.70710688829422 -1.5700929612083792e-16 2.2148514736588345e-23" friction="100 0.5 0.01"/>
          <geom class="collision" type="box" pos="-0.03994312 -0.35056436 0.37672606" size="0.005083238240331411 0.007866312749683857 0.018166128545999527" quat="1.0 0.0 0.0 0.0" name="knob_time_main" friction="100 0.5 0.01"/>
        </body>
        <body name="rack0">
          <geom class="region" name="reg_rack0" type="box" pos="-0.0009109050000000174 -0.07106946000000001 0.027675835000000003" size="0.341970575 0.20676559 0.058923885"/>
          <joint axis="0.0 -1.0 0.0" pos="0.00067105 -0.07070274 -0.04004359" limited="true" name="rack0_joint" range="0.0 0.34" type="slide" damping="1" frictionloss="1" armature=".01" stiffness="0.05"/>
          <geom mesh="rack0_vis" type="mesh" solimp="0.998 0.998 0.001" solref="0.001 1" friction="0.95 0.3 0.1" class="visual" material="rack0_material"/>
          <geom class="collision" type="box" pos="0.00000000 -0.07070269 -0.03966287" size="0.3694811463356018 0.21092276275157928 0.006707852240651846" quat="1.0 0.0 0.0 0.0"/>
        </body>
        <body name="rack1">
          <geom class="region" name="reg_rack1" type="box" pos="-0.0005254450000000133 -0.07104399500000001 0.186935515" size="0.342461595 0.206797195 0.08293781500000001"/>
          <joint axis="0.0 -1.0 0.0" pos="0.00052660 -0.07070275 0.09464755" limited="true" name="rack1_joint" range="0.0 0.34" type="slide" damping="1" frictionloss="1" armature=".01" stiffness="0.05"/>
          <geom mesh="rack1_vis" type="mesh" solimp="0.998 0.998 0.001" solref="0.001 1" friction="0.95 0.3 0.1" class="visual" material="rack1_material"/>
          <geom class="collision" type="box" pos="0.00000000 -0.07070240 0.09494178" size="0.3687414228916168 0.2109231799840927 0.00684721302241087" quat="1.0 0.0 0.0 0.0"/>
        </body>
        <site type="cylinder" rgba="0.3 0.4 1 0.5" size="0.0381271168589592 0.014030364342033863" pos="-0.22235025 0.21393515 0.44946471" name="burner_on_rear_left"/>
        <site type="cylinder" rgba="0.3 0.4 1 0.5" size="0.03225818648934364 0.014232753776013851" pos="0.22242302 0.21431790 0.44925427" name="burner_on_rear_right"/>
        <site type="cylinder" rgba="0.3 0.4 1 0.5" size="0.0357445552945137 0.014081882312893867" pos="-0.22205293 -0.12382008 0.44997364" name="burner_on_front_left"/>
        <site type="cylinder" rgba="0.3 0.4 1 0.5" size="0.05448267608880997 0.014307087287306786" pos="-0.00075421 -0.12175559 0.44951719" name="burner_on_front_center"/>
        <site type="cylinder" rgba="0.3 0.4 1 0.5" size="0.02403990738093853 0.013180036097764969" pos="0.22217818 -0.12353557 0.45021281" name="burner_on_front_right"/>
        <geom class="region" name="reg_int" type="box" pos="-0.0011198350000000135 2.5180000000013525e-05 0.03339354500000001" size="0.342318505 0.30635233 0.236213595"/>
        <site type="cylinder" rgba="0.3 0.4 1 0.5" size="0.04445645958185196 0.01621667668223381" pos="-0.00063508 0.21320999 0.44752738" name="burner_on_rear_center"/>
        <site type="cylinder" rgba="0.5 0 0 0" size="0.0381271168589592 5.0009035476250574e-05" pos="-0.22235025 0.21393515 0.47253746" name="burner_rear_left_place_site"/>
        <site type="cylinder" rgba="0.5 0 0 0" size="0.03225818648934364 4.9993210268439725e-05" pos="0.22242302 0.21431790 0.47253734" name="burner_rear_right_place_site"/>
        <site type="cylinder" rgba="0.5 0 0 0" size="0.0357445552945137 5.002266698284075e-05" pos="-0.22205293 -0.12382008 0.47253746" name="burner_front_left_place_site"/>
        <site type="cylinder" rgba="0.5 0 0 0" size="0.05448267608880997 5.000790042686276e-05" pos="-0.00075421 -0.12175559 0.47253731" name="burner_front_center_place_site"/>
        <site type="cylinder" rgba="0.5 0 0 0" size="0.02403990738093853 5.001014142180793e-05" pos="0.22217818 -0.12353557 0.47253808" name="burner_front_right_place_site"/>
        <site type="cylinder" rgba="0.5 0 0 0" size="0.04445645958185196 5.0020829803543165e-05" pos="-0.00063508 0.21320997 0.47253621" name="burner_rear_center_place_site"/>
        <geom class="region" name="reg_main" type="box" pos="0.0 0.027295525000000015 -0.02282063000000001" size="0.42487855 0.362577095 0.47342549"/>
      </body>
    </body>
  </worldbody>
  <actuator>
    <motor name="door_joint_actuator" joint="door_joint" gear="50"/>
    <motor name="knob_front_center_joint_actuator" joint="knob_front_center_joint" gear="50"/>
    <motor name="knob_front_left_joint_actuator" joint="knob_front_left_joint" gear="50"/>
    <motor name="knob_front_right_joint_actuator" joint="knob_front_right_joint" gear="50"/>
    <motor name="knob_rear_center_joint_actuator" joint="knob_rear_center_joint" gear="50"/>
    <motor name="knob_rear_left_joint_actuator" joint="knob_rear_left_joint" gear="50"/>
    <motor name="knob_rear_right_joint_actuator" joint="knob_rear_right_joint" gear="50"/>
    <motor name="knob_temp_joint_actuator" joint="knob_temp_joint" gear="50"/>
    <motor name="knob_time_joint_actuator" joint="knob_time_joint" gear="50"/>
    <motor name="rack0_joint_actuator" joint="rack0_joint" gear="50"/>
    <motor name="rack1_joint_actuator" joint="rack1_joint" gear="50"/>
  </actuator>
</mujoco>