<?xml version='1.0' encoding='UTF-8'?>
<mujoco model="model">
  <option timestep="0.002" gravity="0.0 0.0 -9.81"/>
  <compiler angle="radian"/>
  <asset>
    <mesh file="visuals/door.obj" name="door_vis"/>
    <mesh file="visuals/door_Clear.obj" name="door_Clear_vis"/>
    <mesh file="visuals/knob_center.obj" name="knob_center_vis"/>
    <mesh file="visuals/knob_front_left.obj" name="knob_front_left_vis"/>
    <mesh file="visuals/knob_front_right.obj" name="knob_front_right_vis"/>
    <mesh file="visuals/knob_rear_left.obj" name="knob_rear_left_vis"/>
    <mesh file="visuals/knob_rear_right.obj" name="knob_rear_right_vis"/>
    <mesh file="visuals/knob_temp.obj" name="knob_temp_vis"/>
    <mesh file="visuals/knob_time.obj" name="knob_time_vis"/>
    <mesh file="visuals/rack0.obj" name="rack0_vis"/>
    <mesh file="visuals/Body001.obj" name="Body001_vis"/>
    <texture file="visuals/T_BC001.png" name="Body001_material" type="2d"/>
    <material name="Body001_material" rgba="1 1 1 1.0" texture="Body001_material" shininess="0.1" specular="6"/>
    <texture file="visuals/T_BC001.png" name="door_material" type="2d"/>
    <material name="door_material" rgba="1 1 1 1.0" texture="door_material" shininess="0.1" specular="6"/>
    <texture file="visuals/T_BC001.png" name="door_Clear_material" type="2d"/>
    <material name="door_Clear_material" rgba="1 1 1 0.5" texture="door_Clear_material" shininess="0.1" specular="0.3103448502657381"/>
    <texture file="visuals/T_BC001.png" name="knob_center_material" type="2d"/>
    <material name="knob_center_material" rgba="1 1 1 1.0" texture="knob_center_material" shininess="0.1" specular="5"/>
    <texture file="visuals/T_BC001.png" name="knob_front_left_material" type="2d"/>
    <material name="knob_front_left_material" rgba="1 1 1 1.0" texture="knob_front_left_material" shininess="0.1" specular="5"/>
    <texture file="visuals/T_BC001.png" name="knob_front_right_material" type="2d"/>
    <material name="knob_front_right_material" rgba="1 1 1 1.0" texture="knob_front_right_material" shininess="0.1" specular="5"/>
    <texture file="visuals/T_BC001.png" name="knob_rear_left_material" type="2d"/>
    <material name="knob_rear_left_material" rgba="1 1 1 1.0" texture="knob_rear_left_material" shininess="0.1" specular="5"/>
    <texture file="visuals/T_BC001.png" name="knob_rear_right_material" type="2d"/>
    <material name="knob_rear_right_material" rgba="1 1 1 1.0" texture="knob_rear_right_material" shininess="0.1" specular="5"/>
    <texture file="visuals/T_BC001.png" name="knob_temp_material" type="2d"/>
    <material name="knob_temp_material" rgba="1 1 1 1.0" texture="knob_temp_material" shininess="0.1" specular="5"/>
    <texture file="visuals/T_BC001.png" name="knob_time_material" type="2d"/>
    <material name="knob_time_material" rgba="1 1 1 1.0" texture="knob_time_material" shininess="0.1" specular="5"/>
    <texture file="visuals/T_BC001.png" name="rack0_material" type="2d"/>
    <material name="rack0_material" rgba="1 1 1 1.0" texture="rack0_material" shininess="0.1" specular="3"/>
  </asset>
  <default>
    <default class="visual">
      <geom conaffinity="0" contype="0" group="1" type="mesh"/>
    </default>
    <default class="collision">
      <geom group="0" rgba="0.5 0 0 0.5"/>
    </default>
    <default class="spawn">
      <geom group="0" rgba="1 1 1 0.5" contype="0" conaffinity="0"/>
      <site group="0" rgba="1 1 1 0.5"/>
    </default>
    <default class="region">
      <geom group="1" conaffinity="0" contype="0" rgba="0 1 0 0"/>
    </default>
  </default>
  <worldbody>
    <body>
      <body name="object">
        <geom mesh="Body001_vis" type="mesh" solimp="0.998 0.998 0.001" solref="0.001 1" friction="0.95 0.3 0.1" class="visual" material="Body001_material"/>
        <geom class="collision" type="box" pos="6.490154191851616e-07 0.30399298667907715 -0.0001319174189120531" size="0.37950000166893005 0.03063351660966873 0.4929412603378296" quat="1.0 0.0 0.0 0.0"/>
        <geom class="collision" type="box" pos="9.247881962437532e-07 0.01607316918671131 0.38297146558761597" size="0.37950047850608826 0.3185533583164215 0.016051707789301872" quat="1.0 0.0 0.0 0.0"/>
        <geom class="collision" type="box" pos="-0.3719644546508789 0.005501424893736839 -0.09880691766738892" size="0.007534903474152088 0.26959389448165894 0.39427047967910767" quat="1.0 0.0 0.0 0.0"/>
        <geom class="collision" type="box" pos="0.3719663619995117 0.005501288454979658 -0.0988069400191307" size="0.007534792181104422 0.269593745470047 0.3942703604698181" quat="1.0 0.0 0.0 0.0"/>
        <geom class="collision" type="box" pos="-0.0003282291581854224 0.002114064060151577 0.28348594903945923" size="0.37917107343673706 0.2660934329032898 0.009091421961784363" quat="1.0 0.0 0.0 0.0"/>
        <geom class="collision" type="box" pos="-0.0003283511323388666 0.0025597289204597473 -0.2571186423301697" size="0.3791711926460266 0.26564764976501465 0.01277067605406046" quat="1.0 0.0 0.0 0.0"/>
        <geom class="collision" type="box" pos="-0.00032822907087393105 -0.017137626186013222 -0.38388580083847046" size="0.37917107343673706 0.28534483909606934 0.10918741673231125" quat="1.0 0.0 0.0 0.0"/>
        <geom class="collision" type="box" pos="9.200302883982658e-07 0.2244304120540619 -0.02571159601211548" size="0.37950021028518677 0.042242083698511124 0.3127388656139374" quat="1.0 0.0 0.0 0.0"/>
        <geom class="collision" type="box" pos="5.369074642658234e-07 0.016116617247462273 -0.39065417647361755" size="0.3794998526573181 0.318509578704834 0.10241939127445221" quat="1.0 0.0 0.0 0.0"/>
        <geom class="collision" type="box" pos="0.0002088821493089199 0.002356607234105468 0.4074528217315674" size="0.3397592306137085 0.2768365144729614 0.008890204131603241" quat="1.0 0.0 0.0 0.0"/>
        <geom class="collision" type="box" pos="0.35568249225616455 -0.04684135317802429 0.024103298783302307" size="0.009308365173637867 0.2168421894311905 0.0055905114859342575" quat="1.0 0.0 0.0 0.0"/>
        <geom class="collision" type="box" pos="-0.35767704248428345 -0.04684135317802429 0.024103298783302307" size="0.009308365173637867 0.2168421894311905 0.005590509623289108" quat="1.0 0.0 0.0 0.0"/>
        <geom class="collision" type="box" pos="9.133765388469328e-07 0.01607316918671131 0.33178508281707764" size="0.37950047850608826 0.3185533583164215 0.035134848207235336" quat="1.0 0.0 0.0 0.0"/>
        <body name="door">
          <joint axis="1.0 0.0 0.0" pos="6.915070116519928e-07 -0.2990294098854065 -0.2656201124191284" limited="true" name="door_joint" range="0.0 1.5707963267948966" type="hinge" damping="1" frictionloss="1" armature=".01" stiffness="0.05"/>
          <geom mesh="door_vis" type="mesh" solimp="0.998 0.998 0.001" solref="0.001 1" friction="0.95 0.3 0.1" class="visual" material="door_material"/>
          <geom class="collision" type="box" pos="-0.0003282262769062072 -0.28507494926452637 0.009530797600746155" size="0.37917107343673706 0.01666591875255108 0.2750031352043152" quat="1.0 0.0 0.0 0.0" name="door_main"/>
          <geom class="collision" type="box" pos="-0.3148961663246155 -0.30137747526168823 0.2613299787044525" size="0.02222270332276821 0.0024574706330895424 0.019035419449210167" quat="1.0 0.0 0.0 0.0"/>
          <geom class="collision" type="box" pos="-0.270940363407135 -0.30515754222869873 0.26056957244873047" size="0.0024574636481702328 0.022222571074962616 0.0205561351031065" quat="0.6362748742103577 0.0 0.0 -0.7714624404907227"/>
          <geom class="collision" type="box" pos="-0.22743520140647888 -0.3138009309768677 0.26056957244873047" size="0.0024574636481702328 0.022222571074962616 0.0205561351031065" quat="0.6362748742103577 0.0 0.0 -0.7714624404907227"/>
          <geom class="collision" type="box" pos="-0.1837860643863678 -0.32179611921310425 0.26056957244873047" size="0.0024574636481702328 0.022222576662898064 0.0205561351031065" quat="0.6439476609230042 0.0 0.0 -0.7650695443153381"/>
          <geom class="collision" type="box" pos="-0.13977670669555664 -0.3284947872161865 0.26056957244873047" size="0.0024574636481702328 0.022222567349672318 0.0205561351031065" quat="0.6602786183357239 0.0 0.0 -0.7510207295417786"/>
          <geom class="collision" type="box" pos="-0.09539932012557983 -0.33354467153549194 0.26056957244873047" size="0.0024574636481702328 0.022222572937607765 0.0205561351031065" quat="0.678578794002533 0.0 0.0 -0.7345276474952698"/>
          <geom class="collision" type="box" pos="-0.05112898722290993 -0.3366588354110718 0.26056957244873047" size="0.0024574636481702328 0.022222572937607765 0.0205561351031065" quat="0.6858806014060974 0.0 0.0 -0.7277140617370605"/>
          <geom class="collision" type="box" pos="-0.0066461567766964436 -0.3383820056915283 0.26056957244873047" size="0.0024574636481702328 0.022222572937607765 0.0205561351031065" quat="0.7013971209526062 0.0 0.0 -0.7127707004547119" name="door_handle_main"/>
          <geom class="collision" type="box" pos="0.03728786110877991 -0.33745628595352173 0.26056957244873047" size="0.022292759269475937 0.003204898675903678 0.0205561351031065" quat="1.0 0.0 0.0 0.0"/>
          <geom class="collision" type="box" pos="0.08173882961273193 -0.335046648979187 0.26056957244873047" size="0.0024574636481702328 0.022222574800252914 0.0205561351031065" quat="0.7337282299995422 0.0 0.0 -0.6794430613517761"/>
          <geom class="collision" type="box" pos="0.1260986328125 -0.3303929567337036 0.26056957244873047" size="0.0024574636481702328 0.022222571074962616 0.0205561351031065" quat="0.7502427101135254 0.0 0.0 -0.6611624956130981"/>
          <geom class="collision" type="box" pos="0.17006200551986694 -0.32435983419418335 0.26056957244873047" size="0.0024574636481702328 0.022222578525543213 0.0205561351031065" quat="0.7568084001541138 0.0 0.0 -0.6536368131637573"/>
          <geom class="collision" type="box" pos="0.21386264264583588 -0.3166324496269226 0.26056957244873047" size="0.0024574636481702328 0.022222574800252914 0.0205561351031065" quat="0.7731620073318481 0.0 0.0 -0.6342085599899292"/>
          <geom class="collision" type="box" pos="0.25716614723205566 -0.30790263414382935 0.26056957244873047" size="0.0024574636481702328 0.022222574800252914 0.0205561351031065" quat="0.7731620073318481 0.0 0.0 -0.6342085599899292"/>
          <geom class="collision" type="box" pos="0.3008153438568115 -0.300037145614624 0.26056957244873047" size="0.0024574636481702328 0.022222571074962616 0.0205561351031065" quat="0.7578297257423401 0.0 0.0 -0.6524524092674255"/>
          <geom class="collision" type="box" pos="0.3170894980430603 -0.3001844882965088 0.2613299787044525" size="0.022301524877548218 0.0033225587103515863 0.01903529278934002" quat="1.0 0.0 0.0 0.0"/>
          <geom class="collision" type="box" pos="-0.0018881545402109623 -0.2838437557220459 0.02219078131020069" size="0.3464679718017578 0.010744373314082623 0.21997284889221191" quat="1.0 0.0 0.0 0.0"/>
          <body name="door_Clear">
            <geom mesh="door_Clear_vis" type="mesh" solimp="0.998 0.998 0.001" solref="0.001 1" friction="0.95 0.3 0.1" class="visual" material="door_Clear_material"/>
            <geom class="collision" type="box" pos="-0.0018881545402109623 -0.2838437557220459 0.02219078131020069" size="0.3464679718017578 0.010744373314082623 0.21997284889221191" quat="1.0 0.0 0.0 0.0"/>
          </body>
        </body>
        <body name="knob_center">
          <joint axis="0.0 -1.0 0.0" pos="0.11236615478992462 -0.3173580765724182 0.3298296332359314" limited="true" name="knob_center_joint" range="0.0 3.141592653589793" type="hinge" damping="0.05" frictionloss="0.1" armature="0.001"/>
          <geom mesh="knob_center_vis" type="mesh" solimp="0.998 0.998 0.001" solref="0.001 1" friction="0.95 0.3 0.1" class="visual" material="knob_center_material"/>
          <geom class="collision" type="cylinder" pos="0.11202891170978546 -0.30954474210739136 0.3293464183807373" size="0.021778227761387825 0.005089934915304184" quat="0.5 0.5 0.4999999701976776 -0.5" density="0.001"/>
          <geom class="collision" type="box" pos="0.11229107528924942 -0.32348543405532837 0.3294242024421692" size="0.008317047730088234 0.008900513872504234 0.021573344245553017" quat="1.0 0.0 0.0 0.0" name="knob_center_main" density="0.001"/>
        </body>
        <body name="knob_front_left">
          <joint axis="0.0 -1.0 0.0" pos="-0.10567551106214523 -0.3173580765724182 0.32953786849975586" limited="true" name="knob_front_left_joint" range="0.0 3.141592653589793" type="hinge" damping="0.05" frictionloss="0.1" armature="0.001"/>
          <geom mesh="knob_front_left_vis" type="mesh" solimp="0.998 0.998 0.001" solref="0.001 1" friction="0.95 0.3 0.1" class="visual" material="knob_front_left_material"/>
          <geom class="collision" type="cylinder" pos="-0.10575403273105621 -0.30954474210739136 0.3293464183807373" size="0.021778227761387825 0.005089934915304184" quat="0.5 0.5 0.4999999701976776 -0.5" density="0.001"/>
          <geom class="collision" type="box" pos="-0.10549186915159225 -0.32348543405532837 0.3294242024421692" size="0.008317025378346443 0.008900513872504234 0.021573254838585854" quat="1.0 0.0 0.0 0.0" name="knob_front_left_main" density="0.001"/>
        </body>
        <body name="knob_front_right">
          <joint axis="0.0 -1.0 0.0" pos="0.3330467939376831 -0.3173580765724182 0.32981473207473755" limited="true" name="knob_front_right_joint" range="0.0 3.141592653589793" type="hinge" damping="0.05" frictionloss="0.1" armature="0.001"/>
          <geom mesh="knob_front_right_vis" type="mesh" solimp="0.998 0.998 0.001" solref="0.001 1" friction="0.95 0.3 0.1" class="visual" material="knob_front_right_material"/>
          <geom class="collision" type="cylinder" pos="0.3326355814933777 -0.30954474210739136 0.3293464183807373" size="0.021778227761387825 0.005089934915304184" quat="0.5 0.5 0.4999999701976776 -0.5" density="0.001"/>
          <geom class="collision" type="box" pos="0.33289772272109985 -0.32348543405532837 0.3294242024421692" size="0.008317049592733383 0.008900513872504234 0.021573353558778763" quat="1.0 0.0 0.0 0.0" name="knob_front_right_main" density="0.001"/>
        </body>
        <body name="knob_rear_left">
          <joint axis="0.0 -1.0 0.0" pos="0.0019752737134695053 -0.3173580765724182 0.32953786849975586" limited="true" name="knob_rear_left_joint" range="0.0 3.141592653589793" type="hinge" damping="0.05" frictionloss="0.1" armature="0.001"/>
          <geom mesh="knob_rear_left_vis" type="mesh" solimp="0.998 0.998 0.001" solref="0.001 1" friction="0.95 0.3 0.1" class="visual" material="knob_rear_left_material"/>
          <geom class="collision" type="cylinder" pos="0.0017690521199256182 -0.30954474210739136 0.3293464183807373" size="0.021778227761387825 0.005089934915304184" quat="0.5 0.5 0.4999999701976776 -0.5" density="0.001"/>
          <geom class="collision" type="box" pos="0.002031215699389577 -0.32348543405532837 0.3294242024421692" size="0.008317051455378532 0.008900513872504234 0.02157336100935936" quat="1.0 0.0 0.0 0.0" name="knob_rear_left_main" density="0.001"/>
        </body>
        <body name="knob_rear_right">
          <joint axis="0.0 -1.0 0.0" pos="0.22260557115077972 -0.3173580765724182 0.33012378215789795" limited="true" name="knob_rear_right_joint" range="0.0 3.141592653589793" type="hinge" damping="0.05" frictionloss="0.1" armature="0.001"/>
          <geom mesh="knob_rear_right_vis" type="mesh" solimp="0.998 0.998 0.001" solref="0.001 1" friction="0.95 0.3 0.1" class="visual" material="knob_rear_right_material"/>
          <geom class="collision" type="cylinder" pos="0.2225378006696701 -0.30954474210739136 0.3296049237251282" size="0.021778227761387825 0.005089934915304184" quat="0.5 0.5 0.4999999701976776 -0.5" density="0.001"/>
          <geom class="collision" type="box" pos="0.22279995679855347 -0.32348543405532837 0.32968267798423767" size="0.008317053318023682 0.008900513872504234 0.021573368459939957" quat="1.0 0.0 0.0 0.0" name="knob_rear_right_main" density="0.001"/>
        </body>
        <body name="knob_temp">
          <joint axis="0.0 1.0 0.0" pos="-0.3297589421272278 -0.3173580765724182 0.32753875851631165" limited="true" name="knob_temp_joint" range="0.0 4.363323129985823" type="hinge" damping="0.05" frictionloss="0.1" armature="0.001"/>
          <geom mesh="knob_temp_vis" type="mesh" solimp="0.998 0.998 0.001" solref="0.001 1" friction="0.95 0.3 0.1" class="visual" material="knob_temp_material"/>
          <geom class="collision" type="cylinder" pos="-0.32981687784194946 -0.3096262216567993 0.3276185989379883" size="0.017223043367266655 0.004585263319313526" quat="0.21008674800395966 0.21008668839931488 0.675176739692688 -0.6751766800880432" density="0.001"/>
          <geom class="collision" type="box" pos="-0.3298744559288025 -0.3233341574668884 0.3275153636932373" size="0.009020081721246243 0.006863096263259649 0.01700630784034729" quat="0.6268596053123474 -0.3271808326244354 0.3271809220314026 -0.6268591284751892" name="knob_temp_main" density="0.001"/>
        </body>
        <body name="knob_time">
          <joint axis="0.0 1.0 0.0" pos="-0.21431638300418854 -0.31687605381011963 0.3258565068244934" limited="true" name="knob_time_joint" range="0.0 4.014257279586958" type="hinge" damping="0.05" frictionloss="0.1" armature="0.001"/>
          <geom mesh="knob_time_vis" type="mesh" solimp="0.998 0.998 0.001" solref="0.001 1" friction="0.95 0.3 0.1" class="visual" material="knob_time_material"/>
          <geom class="collision" type="cylinder" pos="-0.21430985629558563 -0.308935284614563 0.325877845287323" size="0.019157784059643745 0.005100345704704523" quat="0.5018579959869385 0.5019054412841797 -0.4980877637863159 0.498134583234787" density="0.001"/>
          <geom class="collision" type="box" pos="-0.21436633169651031 -0.3239622116088867 0.32633745670318604" size="0.007558888290077448 0.009881828911602497 0.018647173419594765" quat="1.0 0.0 0.0 0.0" name="knob_time_main" density="0.001"/>
        </body>
        <body name="rack0">
          <geom class="region" name="reg_rack0" type="box" pos="-0.001135304570198059 -0.04560874402523041 0.154441449791193" size="0.3418627361059189 0.2033354321718216 0.11046699604392052"/>
          <joint axis="0.0 -1.0 0.0" pos="-0.0014163809828460217 -0.045786283910274506 0.03486105799674988" limited="true" name="rack0_joint" range="0.0 0.35" type="slide" damping="1" frictionloss="1" armature=".01" stiffness="0.05"/>
          <geom mesh="rack0_vis" type="mesh" solimp="0.998 0.998 0.001" solref="0.001 1" friction="0.95 0.3 0.1" class="visual" material="rack0_material"/>
          <geom class="collision" type="box" pos="-0.001008454943075776 -0.04573242366313934 0.034881461411714554" size="0.3534024655818939 0.20836016535758972 0.004014792386442423" quat="1.0 0.0 0.0 0.0"/>
        </body>
        <geom class="region" name="reg_int" type="box" pos="-0.001135304570198059 -0.040598347783088684 0.01787400245666504" size="0.3418627361059189 0.21815886890888214 0.2517888078689575"/>
        <site type="cylinder" rgba="0.3 0.4 1 0.5" size="0.04910412058234215 0.009300893172621727" pos="-0.1791195273399353 0.08587392419576645 0.402950257062912" name="burner_on_rear_left"/>
        <site type="cylinder" rgba="0.3 0.4 1 0.5" size="0.04910412058234215 0.009300893172621727" pos="0.17771181464195251 0.08587392419576645 0.402950257062912" name="burner_on_rear_right"/>
        <site type="cylinder" rgba="0.3 0.4 1 0.5" size="0.04910412058234215 0.009300893172621727" pos="0.1781647503376007 -0.11547911912202835 0.402950257062912" name="burner_on_front_right"/>
        <site type="cylinder" rgba="0.3 0.4 1 0.5" size="0.03738318011164665 0.009300893172621727" pos="0.0014605133328586817 -0.017544277012348175 0.40311214327812195" name="burner_on_center"/>
        <site type="cylinder" rgba="0.3 0.4 1 0.5" size="0.04910412058234215 0.009300893172621727" pos="-0.17922016978263855 -0.11620382219552994 0.402950257062912" name="burner_on_front_left"/>
        <site type="cylinder" rgba="0.5 0 0 0" size="0.04910412058234215 5.000006785849109e-05" pos="-0.17922018468379974 -0.11620383709669113 0.41639259457588196" name="burner_front_left_place_site"/>
        <site type="cylinder" rgba="0.5 0 0 0" size="0.04910413175821304 5.000006785849109e-05" pos="0.1777118295431137 0.08587393909692764 0.41639259457588196" name="burner_rear_right_place_site"/>
        <site type="cylinder" rgba="0.5 0 0 0" size="0.04910412058234215 5.000006785849109e-05" pos="-0.1791195422410965 0.08587393909692764 0.41639259457588196" name="burner_rear_left_place_site"/>
        <site type="cylinder" rgba="0.5 0 0 0" size="0.04910412058234215 5.000002420274541e-05" pos="0.1781647503376007 -0.11547911912202835 0.41639256477355957" name="burner_front_right_place_site"/>
        <site type="cylinder" rgba="0.5 0 0 0" size="0.03738318011164665 4.998933945898898e-05" pos="0.0014605133328586817 -0.017544277012348175 0.41639259457588196" name="burner_center_place_site"/>
        <geom class="region" name="reg_main" type="box" pos="7.003545761108398e-07 0.016073167324066162 -0.06307661533355713" size="0.38050003147125244 0.31955309009552 0.4309965500831604"/>
      </body>
    </body>
  </worldbody>
  <actuator>
    <motor name="door_joint_actuator" joint="door_joint" gear="50"/>
    <motor name="knob_center_joint_actuator" joint="knob_center_joint" gear="50"/>
    <motor name="knob_front_left_joint_actuator" joint="knob_front_left_joint" gear="50"/>
    <motor name="knob_front_right_joint_actuator" joint="knob_front_right_joint" gear="50"/>
    <motor name="knob_rear_left_joint_actuator" joint="knob_rear_left_joint" gear="50"/>
    <motor name="knob_rear_right_joint_actuator" joint="knob_rear_right_joint" gear="50"/>
    <motor name="knob_temp_joint_actuator" joint="knob_temp_joint" gear="50"/>
    <motor name="knob_time_joint_actuator" joint="knob_time_joint" gear="50"/>
    <motor name="rack0_joint_actuator" joint="rack0_joint" gear="50"/>
  </actuator>
</mujoco>
