<?xml version='1.0' encoding='UTF-8'?>
<mujoco model="model">
  <option timestep="0.002" gravity="0.0 0.0 -9.81"/>
  <compiler angle="radian"/>
  <asset>
    <mesh file="visuals/door.obj" name="door_vis"/>
    <mesh file="visuals/door_Clear.obj" name="door_Clear_vis"/>
    <mesh file="visuals/Body001.obj" name="Body001_vis"/>
    <mesh file="visuals/Disc001.obj" name="Disc001_vis"/>
    <texture file="visuals/T_BC001.png" name="Body001_material" type="2d"/>
    <material name="Body001_material" rgba="1 1 1 1.0" texture="Body001_material" shininess="0.4472135901451111" specular="0.5"/>
    <texture file="visuals/T_BC001.png" name="door_material" type="2d"/>
    <material name="door_material" rgba="1 1 1 1.0" texture="door_material" shininess="0.4472135901451111" specular="0.5"/>
    <texture file="visuals/T_BC001.png" name="door_Clear_material" type="2d"/>
    <material name="door_Clear_material" rgba="1 1 1 0.8469945192337036" texture="door_Clear_material" shininess="0.4472135901451111" specular="0.3103448502657381"/>
    <texture file="visuals/T_BC001.png" name="Disc001_material" type="2d"/>
    <material name="Disc001_material" rgba="1 1 1 1.0" texture="Disc001_material" shininess="0.4472135901451111" specular="0.5"/>
  </asset>
  <default>
    <default class="visual">
      <geom conaffinity="0" contype="0" group="1" type="mesh"/>
    </default>
    <default class="collision">
      <geom group="0" rgba="0.5 0 0 0.5"/>
    </default>
    <default class="spawn">
      <geom group="0" rgba="1 1 1 0.5" contype="0" conaffinity="0"/>
      <site group="0" rgba="1 1 1 0.5"/>
    </default>
    <default class="region">
      <geom group="1" conaffinity="0" contype="0" rgba="0 1 0 0"/>
    </default>
  </default>
  <worldbody>
    <body>
      <body name="object">
        <geom class="collision" type="box" pos="0.20688511 -0.20140959 -0.08837923" size="0.011203333735466003 0.0005456866347230971 0.006529494654387236" quat="1.0 0.0 0.0 0.0" name="start_button" rgba="0.0 0.5 0 0.5"/>
        <geom class="collision" type="box" pos="0.24758175 -0.20140959 -0.08837923" size="0.011203338392078876 0.0005456869257614017 0.006529499311000109" quat="1.0 0.0 0.0 0.0" name="stop_button" rgba="0.0 0.5 0 0.5"/>
        <geom class="collision" type="cylinder" pos="-0.04088518 -0.00769267 -0.12107181" size="0.16101673245429993 0.0022666649892926216" quat="1.0 0.0 0.0 0.0" name="tray" rgba="0 1 0 0.5"/>
        <geom mesh="Body001_vis" type="mesh" solimp="0.998 0.998 0.001" solref="0.001 1" friction="0.95 0.3 0.1" class="visual" material="Body001_material"/>
        <geom class="collision" type="box" pos="0.00000000 0.20615921 0.00486070" size="0.26994314789772034 0.026556527242064476 0.1437952220439911" quat="1.0 0.0 0.0 0.0"/>
        <geom class="collision" type="box" pos="-0.25133833 -0.00762603 0.00486070" size="0.018604833632707596 0.19010990858078003 0.1437952220439911" quat="1.0 0.0 0.0 0.0"/>
        <geom class="collision" type="box" pos="0.17348723 -0.00762603 0.00486070" size="0.026006774976849556 0.19010990858078003 0.1437952220439911" quat="1.0 0.0 0.0 0.0"/>
        <geom class="collision" type="box" pos="-0.01726867 -0.00762603 0.14332044" size="0.2167627066373825 0.19010990858078003 0.005335479509085417" quat="1.0 0.0 0.0 0.0"/>
        <geom class="collision" type="box" pos="-0.01726867 -0.00762603 -0.13509087" size="0.2167627066373825 0.19010990858078003 0.004102307837456465" quat="1.0 0.0 0.0 0.0"/>
        <geom class="collision" type="box" pos="0.22731711 -0.00846768 0.00486070" size="0.0426260307431221 0.19095154106616974 0.1437952220439911" quat="1.0 0.0 0.0 0.0"/>
        <geom class="collision" type="cylinder" pos="-0.18516758 0.17306202 -0.14190505" size="0.01037526410073042 0.006750664208084345" quat="1.0 0.0 0.0 0.0"/>
        <geom class="collision" type="cylinder" pos="0.16264436 0.17306202 -0.14190505" size="0.01037526410073042 0.006750664208084345" quat="1.0 0.0 0.0 0.0"/>
        <geom class="collision" type="cylinder" pos="0.16264436 -0.14608803 -0.14190505" size="0.01037526410073042 0.006750664208084345" quat="1.0 0.0 0.0 0.0"/>
        <geom class="collision" type="cylinder" pos="-0.18516758 -0.14608803 -0.14190505" size="0.01037526410073042 0.006750664208084345" quat="1.0 0.0 0.0 0.0"/>
        <body name="door">
          <joint axis="0.0 0.0 1.0" pos="-0.26554516 -0.20252347 0.00535504" limited="true" name="microjoint" range="-1.5707963267948966 0.0" type="hinge" damping="1" frictionloss="1" armature=".01" stiffness="0.05"/>
          <geom mesh="door_vis" type="mesh" solimp="0.998 0.998 0.001" solref="0.001 1" friction="0.95 0.3 0.1" class="visual" material="door_material"/>
          <geom class="collision" type="box" pos="-0.03756569 -0.20244173 0.00530048" size="0.22089003026485443 0.004169816616922617 0.14335528016090393" quat="1.0 0.0 0.0 0.0"/>
          <geom class="collision" type="box" pos="0.16431227 -0.22701576 0.00435505" size="0.011955862864851952 0.005856535397469997 0.07246973365545273" quat="1.0 0.0 0.0 0.0" name="door_handle_main"/>
          <geom class="collision" type="box" pos="0.16493176 -0.21124035 0.12515020" size="0.011907381936907768 0.010255555622279644 0.006392296869307756" quat="7.978625831128738e-07 4.85545058381831e-07 0.21992571651935577 -0.9755166172981262"/>
          <geom class="collision" type="box" pos="0.16460048 -0.22296725 0.11235357" size="0.0116716418415308 0.011197931133210659 0.006073447875678539" quat="9.661798827664825e-08 -6.952240596547199e-07 -0.5028786063194275 0.864357054233551"/>
          <geom class="collision" type="box" pos="0.16452757 -0.22717453 0.09143840" size="0.011830589734017849 0.006787508260458708 0.01344011165201664" quat="1.0 0.0 0.0 0.0"/>
          <geom class="collision" type="box" pos="0.16482906 -0.21124035 -0.11763681" size="0.012010076083242893 0.010255555622279644 0.006392296869307756" quat="0.9755166172981262 -0.21992571651935577 4.951577352585446e-07 7.552212082373444e-07"/>
          <geom class="collision" type="box" pos="0.16478385 -0.22296725 -0.10484018" size="0.011752326041460037 0.011197932064533234 0.006073447875678539" quat="0.864357054233551 -0.5028786063194275 7.707887448304973e-07 -5.265471969551072e-08"/>
          <geom class="collision" type="box" pos="0.16445422 -0.22717453 -0.08392499" size="0.012344039976596832 0.006787517108023167 0.013440113514661789" quat="1.0 0.0 0.0 0.0"/>
          <geom class="collision" type="box" pos="-0.04085507 -0.20431067 0.00567954" size="0.15795336663722992 0.0014338067267090082 0.09186302870512009" quat="1.0 0.0 0.0 0.0"/>
          <geom class="collision" type="box" pos="-0.03756569 -0.20500612 0.00530047" size="0.2208903431892395 0.0016054679872468114 0.14335541427135468" quat="1.0 0.0 0.0 0.0" name="door_main"/>
          <body name="door_Clear">
            <geom mesh="door_Clear_vis" type="mesh" solimp="0.998 0.998 0.001" solref="0.001 1" friction="0.95 0.3 0.1" class="visual" material="door_Clear_material"/>
            <geom class="collision" type="box" pos="-0.04085507 -0.20431067 0.00567954" size="0.15795336663722992 0.0014338067267090082 0.09186302870512009" quat="1.0 0.0 0.0 0.0"/>
          </body>
        </body>
        <body name="Disc001">
          <joint axis="0.0 0.0 1.0" pos="-0.04088516 -0.00769264 -0.12149373" limited="false" name="Disc001_joint" range="0 360" type="hinge" damping="1" frictionloss="1" armature=".01" stiffness="0.05"/>
          <geom mesh="Disc001_vis" type="mesh" solimp="0.998 0.998 0.001" solref="0.001 1" friction="0.95 0.3 0.1" class="visual" material="Disc001_material"/>
          <geom class="collision" type="cylinder" pos="-0.04088516 -0.00769267 -0.12742083" size="0.16115526854991913 0.001962974201887846" quat="1.0 0.0 0.0 0.0"/>
        </body>
        <geom class="region" name="reg_int" type="box" pos="-0.04202080500000001 -0.009418289999999996 0.006555034999999994" size="0.182046885 0.1812779 0.126330245"/>
        <geom class="region" name="reg_main" type="box" pos="-7.999999998564711e-08 0.013052089999999988 -2.3000000000383825e-07" size="0.27094312 0.22066368 0.14965615999999998"/>
      </body>
    </body>
  </worldbody>
  <actuator>
    <motor name="microjoint_actuator" joint="microjoint" gear="10"/>
    <motor name="Disc001_joint_actuator" joint="Disc001_joint" gear="10"/>
  </actuator>
</mujoco>
