<?xml version='1.0' encoding='UTF-8'?>
<mujoco model="model">
  <option timestep="0.002" gravity="0.0 0.0 -9.81"/>
  <compiler angle="radian"/>
  <asset>
    <mesh file="visuals/handle.obj" name="handle_vis"/>
    <mesh file="visuals/Body001.obj" name="Body001_vis"/>
    <mesh file="visuals/spout.obj" name="spout_vis"/>
    <texture file="visuals/T_BC001.png" name="Body001_material" type="2d"/>
    <material name="Body001_material" rgba="1 1 1 1.0" texture="Body001_material" shininess="0.4472135901451111" specular="1"/>
    <texture file="visuals/T_BC001.png" name="handle_material" type="2d"/>
    <material name="handle_material" rgba="1 1 1 1.0" texture="handle_material" shininess="0.4472135901451111" specular="1"/>
    <texture file="visuals/T_BC001.png" name="spout_material" type="2d"/>
    <material name="spout_material" rgba="1 1 1 1.0" texture="spout_material" shininess="0.4472135901451111" specular="1"/>
  </asset>
  <default>
    <default class="visual">
      <geom conaffinity="0" contype="0" group="1" type="mesh"/>
    </default>
    <default class="collision">
      <geom group="0" rgba="0.5 0 0 0.5"/>
    </default>
    <default class="spawn">
      <geom group="0" rgba="1 1 1 0.5" contype="0" conaffinity="0"/>
      <site group="0" rgba="1 1 1 0.5"/>
    </default>
    <default class="region">
      <geom group="1" conaffinity="0" contype="0" rgba="0 1 0 0"/>
    </default>
  </default>
  <worldbody>
    <body>
      <body name="object">
        <geom mesh="Body001_vis" type="mesh" solimp="0.998 0.998 0.001" solref="0.001 1" friction="0.95 0.3 0.1" class="visual" material="Body001_material"/>
        <geom class="collision" type="cylinder" pos="0.00013274 0.22498367 -0.00581795" size="0.016698651015758514 0.0544344037771225" quat="0.7071067094802856 0.0 0.0 -0.7071068286895752"/>
        <geom class="collision" type="cylinder" pos="0.00022893 0.22498367 -0.06293694" size="0.025238705798983574 0.002348281443119049" quat="0.7071067094802856 0.0 0.0 -0.7071068286895752"/>
        <geom class="collision" type="cylinder" pos="0.02158878 0.22498367 -0.00602341" size="0.015174861997365952 0.020444747060537338" quat="0.7071068286895752 1.2101623703131281e-08 0.7071067690849304 -1.2101622814952862e-08"/>
        <geom class="collision" type="box" pos="-0.22326328 0.00000023 -0.12871663" size="0.011260617524385452 0.2513779401779175 0.06668765842914581" quat="1.0 0.0 0.0 0.0"/>
        <geom class="collision" type="box" pos="0.22334352 0.00000028 -0.12871663" size="0.011180365458130836 0.2513778507709503 0.06668762862682343" quat="1.0 0.0 0.0 0.0"/>
        <geom class="collision" type="box" pos="-0.00872150 -0.23940448 -0.12871663" size="0.22522450983524323 0.011973206885159016 0.06668765097856522" quat="1.0 0.0 0.0 0.0"/>
        <geom class="collision" type="box" pos="0.00000001 0.00042350 -0.18852685" size="0.2345239818096161 0.23745904862880707 0.006877499632537365" quat="1.0 0.0 0.0 0.0"/>
        <geom class="collision" type="box" pos="-0.00872148 0.22295270 -0.12871662" size="0.22522716224193573 0.028425544500350952 0.06668765097856522" quat="1.0 0.0 0.0 0.0"/>
        <geom class="collision" type="box" pos="0.21455719 -0.22357739 -0.12871663" size="0.011599640361964703 0.009580041281878948 0.06668764352798462" quat="0.43918120861053467 -3.5775858719944154e-08 7.318384831478397e-08 -0.8983985185623169"/>
        <geom class="collision" type="box" pos="-0.21049516 -0.22902475 -0.12871663" size="0.011599640361964703 0.009580040350556374 0.06668765842914581" quat="0.338575154542923 -2.7580441042118764e-08 -7.664925050221427e-08 0.9409393668174744"/>
        <geom class="collision" type="box" pos="-0.21331194 0.19395523 -0.12871662" size="0.011599640361964703 0.009580041281878948 0.06668766587972641" quat="0.9065268039703369 -7.38459888793841e-08 -3.4388353498115976e-08 0.422148197889328"/>
        <geom class="collision" type="box" pos="0.21394131 0.19671448 -0.12871663" size="0.011599640361964703 0.009580041281878948 0.06668765097856522" quat="0.9206199645996094 -7.49940269884064e-08 3.180697660809528e-08 -0.3904598355293274"/>
        <body name="handle">
          <joint axis="1.0 0.0 0.0" pos="0.05916828 0.22499300 -0.00593547" limited="true" name="handle_temp_joint" type="hinge" range="-0.7853981633974483 0.7853981633974483" damping="1" frictionloss="1" armature=".01" stiffness="0.05"/>
          <joint axis="0.0 1.0 0.0" pos="0.05916828 0.22499300 -0.00593547" limited="true" name="handle_joint" type="hinge" range="0 0.5" damping="1" frictionloss="1" armature=".01" stiffness="0.05"/>
          <geom mesh="handle_vis" type="mesh" solimp="0.998 0.998 0.001" solref="0.001 1" friction="0.95 0.3 0.1" class="visual" material="handle_material"/>
          <geom class="collision" type="box" pos="0.05939483 0.22498367 0.03646419" size="0.012284770607948303 0.002811816055327654 0.028053397312760353" quat="1.0 0.0 0.0 0.0"/>
          <geom class="collision" type="cylinder" pos="0.06279292 0.22498367 -0.00666502" size="0.015174861997365952 0.009489334188401699" quat="0.7071068286895752 1.2101623703131281e-08 0.7071067690849304 -1.2101622814952862e-08"/>
        </body>
        <body name="spout">
          <joint axis="0.0 0.0 1.0" pos="0.00020842 0.22513611 0.11921735" limited="true" name="spout_joint" range="-0.7853981633974483 0.7853981633974483" type="hinge" damping="1" frictionloss="1" armature=".01" stiffness="0.05"/>
          <site type="cylinder" rgba="0.5 0.75 1 0.5" size="0.007300759665668011 0.18885229527950287" pos="-0.00017486 0.01323098 0.00154263" name="water"/>
          <geom mesh="spout_vis" type="mesh" solimp="0.998 0.998 0.001" solref="0.001 1" friction="0.95 0.3 0.1" class="visual" material="spout_material"/>
          <geom class="collision" type="box" pos="0.00014477 0.22505694 0.10058191" size="0.014651925303041935 0.004856440704315901 0.052547164261341095" quat="1.0 0.0 0.0 0.0"/>
          <geom class="collision" type="box" pos="0.00014475 0.09077517 0.18721798" size="0.004856437910348177 0.014651536010205746 0.09460997581481934" quat="0.49069836735725403 -0.5091310739517212 -0.509148120880127 -0.4906820058822632" name="spout_main"/>
          <geom class="collision" type="box" pos="0.00014476 0.22406494 0.15945125" size="0.004856437910348177 0.014651536010205746 0.008405144326388836" quat="0.7054564952850342 0.04828108102083206 0.04828107729554176 -0.7054566144943237"/>
          <geom class="collision" type="box" pos="0.00014476 0.22029979 0.16952396" size="0.00485643744468689 0.014651536010205746 0.008405144326388836" quat="0.6765242218971252 0.20570605993270874 0.20570604503154755 -0.6765242218971252"/>
          <geom class="collision" type="box" pos="0.00014476 0.21058436 0.17898455" size="0.00485643744468689 0.014651536010205746 0.008405151776969433" quat="0.6162596344947815 0.3467335104942322 0.3467335104942322 -0.6162595748901367"/>
          <geom class="collision" type="box" pos="0.00014476 0.19785782 0.18318692" size="0.004856438841670752 0.014651536010205746 0.008405154570937157" quat="0.5158505439758301 0.48362910747528076 0.48361703753471375 -0.5158639550209045"/>
          <geom class="collision" type="box" pos="0.00014476 0.18699070 0.18380766" size="0.004856437910348177 0.014651536010205746 0.008405153639614582" quat="0.5070911049842834 0.4928070306777954 0.49281197786331177 -0.5070859789848328"/>
          <geom class="collision" type="cylinder" pos="0.00000761 0.01287481 0.18148445" size="0.012532871216535568 0.004810836631804705" quat="0.7071067094802856 0.0 0.0 -0.7071068286895752"/>
        </body>
        <geom class="region" name="reg_basin" type="box" pos="0.00027484500000000966 -0.01626723999999999 -0.121532255" size="0.20059934499999998 0.2032273 0.054858415"/>
        <geom class="region" name="reg_main" type="box" pos="1.500000000598245e-08 2.699999999966618e-07 -0.12871663" size="0.23552389499999998 0.25237796999999995 0.06768765000000002"/>
      </body>
    </body>
  </worldbody>
  <actuator>
    <motor name="handle_joint_actuator" joint="handle_joint" gear="10"/>
    <motor name="handle_temp_joint_actuator" joint="handle_temp_joint" gear="10"/>
    <motor name="spout_joint_actuator" joint="spout_joint" gear="10"/>
  </actuator>
</mujoco>
