<?xml version='1.0' encoding='UTF-8'?>
<mujoco model="model">
  <option timestep="0.002" gravity="0.0 0.0 -9.81"/>
  <compiler angle="radian"/>
  <asset>
    <mesh file="visuals/door.obj" name="door_vis"/>
    <mesh file="visuals/door_Clear.obj" name="door_Clear_vis"/>
    <mesh file="visuals/Body001.obj" name="Body001_vis"/>
    <mesh file="visuals/Button001.obj" name="Button001_vis"/>
    <mesh file="visuals/Button002.obj" name="Button002_vis"/>
    <mesh file="visuals/Disc001.obj" name="Disc001_vis"/>
    <texture file="visuals/T_BC001.png" name="Body001_material" type="2d"/>
    <material name="Body001_material" rgba="1 1 1 1.0" texture="Body001_material" shininess="0.1" specular="2"/>
    <texture file="visuals/T_BC001.png" name="door_material" type="2d"/>
    <material name="door_material" rgba="1 1 1 1.0" texture="door_material" shininess="0.1" specular="0.99"/>
    <material name="door_Clear_material" rgba="0.012270155362784863 0.012270155362784863 0.012270155362784863 0.8397825360298157" shininess="0.1" specular="0.99"/>
    <texture file="visuals/T_BC001.png" name="Button001_material" type="2d"/>
    <material name="Button001_material" rgba="1 1 1 1.0" texture="Button001_material" shininess="0.1" specular="0.99"/>
    <texture file="visuals/T_BC001.png" name="Button002_material" type="2d"/>
    <material name="Button002_material" rgba="1 1 1 1.0" texture="Button002_material" shininess="0.1" specular="0.99"/>
    <texture file="visuals/T_BC001.png" name="Disc001_material" type="2d"/>
    <material name="Disc001_material" rgba="1 1 1 1.0" texture="Disc001_material" shininess="0.1" specular="0.99"/>
  </asset>
  <default>
    <default class="visual">
      <geom conaffinity="0" contype="0" group="1" type="mesh"/>
    </default>
    <default class="collision">
      <geom group="0" rgba="0.5 0 0 0.5"/>
    </default>
    <default class="spawn">
      <geom group="0" rgba="1 1 1 0.5" contype="0" conaffinity="0"/>
      <site group="0" rgba="1 1 1 0.5"/>
    </default>
    <default class="region">
      <geom group="1" conaffinity="0" contype="0" rgba="0 1 0 0"/>
    </default>
  </default>
  <worldbody>
    <body>
      <body name="object">
        <geom class="collision" type="cylinder" pos="-0.053948815912008286 0.00721850385889411 -0.12552699446678162" size="0.13166728615760803 0.0006402618018910289" quat="1.0 0.0 0.0 0.0" name="tray" rgba="0 1 0 0.5"/>
        <geom class="collision" type="box" pos="0.23246632516384125 -0.19946980476379395 -0.05689051374793053" size="0.010617456398904324 0.0002798598143272102 0.007955159060657024" quat="1.0 0.0 0.0 0.0" name="start_button" rgba="0.0 0.5 0 0.5"/>
        <geom class="collision" type="box" pos="0.1815623790025711 -0.19946980476379395 -0.05655767768621445" size="0.01157171931117773 0.0002798600180540234 0.007955159060657024" quat="1.0 0.0 0.0 0.0" name="stop_button" rgba="0.0 0.5 0 0.5"/>
        <geom mesh="Body001_vis" type="mesh" solimp="0.998 0.998 0.001" solref="0.001 1" friction="0.95 0.3 0.1" class="visual" material="Body001_material"/>
        <geom class="collision" type="box" pos="3.026798367500305e-09 0.028110068291425705 0.14922992885112762" size="0.27094560861587524 0.1948748379945755 0.010673843324184418" quat="1.0 0.0 0.0 0.0"/>
        <geom class="collision" type="box" pos="-0.2460903376340866 0.028110038489103317 -0.009832211770117283" size="0.02485777996480465 0.19487500190734863 0.14944371581077576" quat="1.0 0.0 0.0 0.0"/>
        <geom class="collision" type="box" pos="0.19384488463401794 0.028110068291425705 -0.009643904864788055" size="0.077102892100811 0.19487519562244415 0.14963211119174957" quat="1.0 0.0 0.0 0.0"/>
        <geom class="collision" type="box" pos="-6.868503987789154e-09 0.028110068291425705 -0.14492705464363098" size="0.2709459662437439 0.19487540423870087 0.014358572661876678" quat="1.0 0.0 0.0 0.0"/>
        <geom class="collision" type="box" pos="-6.868503987789154e-09 0.19042719900608063 -0.006353685632348061" size="0.27094608545303345 0.032561030238866806 0.14558152854442596" quat="1.0 0.0 0.0 0.0"/>
        <geom class="collision" type="box" pos="0.21813222765922546 -0.17393672466278076 0.0036033657379448414" size="0.05281565710902214 0.018024057149887085 0.15629954636096954" quat="1.0 0.0 0.0 0.0"/>
        <body name="door">
          <joint axis="0.0 0.0 1.0" pos="-0.2574526071548462 -0.1819857656955719 0.004441767930984497" limited="true" name="microjoint" range="-1.5707963267948966 0.0" type="hinge" damping="1" frictionloss="1" armature=".01" stiffness="0.05"/>
          <geom mesh="door_vis" type="mesh" solimp="0.998 0.998 0.001" solref="0.001 1" friction="0.95 0.3 0.1" class="visual" material="door_material"/>
          <geom class="collision" type="box" pos="-0.05269811302423477 -0.18954874575138092 0.020522303879261017" size="0.16385461390018463 0.0018168184906244278 0.08685800433158875" quat="1.0 0.0 0.0 0.0"/>
          <geom class="collision" type="box" pos="-0.045881107449531555 -0.1879672259092331 0.004750963766127825" size="0.20303361117839813 0.006920710206031799 0.1551530659198761" quat="1.0 0.0 0.0 0.0" name="door_main"/>
          <geom class="collision" type="box" pos="0.14146743714809418 -0.21701546013355255 0.014288303442299366" size="0.014644913375377655 0.0065969196148216724 0.06216118857264519" quat="1.0 0.0 0.0 0.0" name="door_handle_main"/>
          <geom class="collision" type="box" pos="0.14146743714809418 -0.20233699679374695 0.10259798169136047" size="0.014644913375377655 0.022717298939824104 0.022829050198197365" quat="1.0 0.0 0.0 0.0"/>
          <geom class="collision" type="box" pos="0.14146743714809418 -0.20149850845336914 -0.07135457545518875" size="0.014644913375377655 0.02280215173959732 0.02274521067738533" quat="1.0 0.0 0.0 0.0"/>
          <body name="door_Clear">
            <geom mesh="door_Clear_vis" type="mesh" solimp="0.998 0.998 0.001" solref="0.001 1" friction="0.95 0.3 0.1" class="visual" material="door_Clear_material"/>
            <geom class="collision" type="box" pos="-0.05269811302423477 -0.18954874575138092 0.020522303879261017" size="0.16385461390018463 0.0018168184906244278 0.08685800433158875" quat="1.0 0.0 0.0 0.0"/>
          </body>
        </body>
        <body name="Button001">
          <joint axis="0.0 1.0 0.0" pos="0.18114350736141205 -0.1946958601474762 -0.05697348341345787" limited="true" name="Button001_joint" range="0.0 0.003" type="slide" damping="1" frictionloss="1" armature=".01" stiffness="0.05"/>
          <geom mesh="Button001_vis" type="mesh" solimp="0.998 0.998 0.001" solref="0.001 1" friction="0.95 0.3 0.1" class="visual" material="Button001_material"/>
          <geom class="collision" type="box" pos="0.1815623790025711 -0.19658896327018738 -0.05655767768621445" size="0.01157171931117773 0.001951877260580659 0.007955159060657024" quat="1.0 0.0 0.0 0.0"/>
        </body>
        <body name="Button002">
          <joint axis="0.0 1.0 0.0" pos="0.23229819536209106 -0.19503822922706604 -0.05696532875299454" limited="true" name="Button002_joint" range="0.0 0.003" type="slide" damping="1" frictionloss="1" armature=".01" stiffness="0.05"/>
          <geom mesh="Button002_vis" type="mesh" solimp="0.998 0.998 0.001" solref="0.001 1" friction="0.95 0.3 0.1" class="visual" material="Button002_material"/>
          <geom class="collision" type="box" pos="0.23246632516384125 -0.19658896327018738 -0.05689051374793053" size="0.010617456398904324 0.001951877260580659 0.007955159060657024" quat="1.0 0.0 0.0 0.0"/>
        </body>
        <body name="Disc001">
          <joint axis="0.0 0.0 -1.0" pos="-0.05321287363767624 0.00750887393951416 -0.09866394102573395" limited="false" name="Disc001_joint" range="0 360" type="hinge" damping="1" frictionloss="1" armature=".01" stiffness="0.05"/>
          <geom mesh="Disc001_vis" type="mesh" solimp="0.998 0.998 0.001" solref="0.001 1" friction="0.95 0.3 0.1" class="visual" material="Disc001_material"/>
          <geom class="collision" type="cylinder" pos="-0.053948815912008286 0.00721850385889411 -0.12761902809143066" size="0.13166752457618713 0.0010193423368036747" quat="1.0 0.0 0.0 0.0"/>
        </body>
        <geom class="region" name="reg_int" type="box" pos="-0.052042338997125626 -0.005843058228492737 0.004312507808208466" size="0.16355803033709526 0.15909829533100128 0.12901984697580338"/>
        <geom class="region" name="reg_main" type="box" pos="-7.450580596923828e-09 0.01356690376996994 0.0" size="0.2719484398365021 0.2104208598136902 0.16090403294563294"/>
      <geom class="region" name="reg_tray" type="cylinder" pos="-0.053948815912008286 0.00721850385889411 0.004222811059560627" size="0.13166728615760803 0.1281095437244512"/></body>
    </body>
  </worldbody>
  <actuator>
    <motor name="microjoint_actuator" joint="microjoint" gear="10"/>
    <motor name="Button001_joint_actuator" joint="Button001_joint" gear="0.5"/>
    <motor name="Button002_joint_actuator" joint="Button002_joint" gear="0.5"/>
    <motor name="Disc001_joint_actuator" joint="Disc001_joint" gear="0.5"/>
  </actuator>
</mujoco>
