<?xml version='1.0' encoding='UTF-8'?>
<mujoco model="model">
  <compiler angle="radian"/>
  <asset>
    <mesh file="visuals/Body001.obj" name="Body001_vis"/>
    <mesh file="visuals/Button001.obj" name="Button001_vis"/>
    <mesh file="visuals/Button002.obj" name="Button002_vis"/>
    <mesh file="visuals/Container001_Clear.obj" name="Container001_Clear_vis"/>
    <mesh file="visuals/Lid001.obj" name="Lid001_vis"/>
    <mesh file="visuals/Lid002.obj" name="Lid002_vis"/>
    <mesh file="visuals/Lid003.obj" name="Lid003_vis"/>
    <texture file="visuals/T_BC001.png" name="Body001_material" type="2d"/>
    <material name="Body001_material" rgba="1 1 1 1.0" texture="Body001_material" shininess="1" specular="1"/>
    <texture file="visuals/T_BC001.png" name="Button001_material" type="2d"/>
    <material name="Button001_material" rgba="1 1 1 1.0" texture="Button001_material" shininess="1" specular="1"/>
    <texture file="visuals/T_BC001.png" name="Button002_material" type="2d"/>
    <material name="Button002_material" rgba="1 1 1 1.0" texture="Button002_material" shininess="1" specular="1"/>
    <material name="Container001_Clear_material" rgba="0.800000011920929 0.800000011920929 0.800000011920929 0.060773469507694244" shininess="0.5" specular="0.3103448502657381"/>
    <texture file="visuals/T_BC001.png" name="Lid002_material" type="2d"/>
    <material name="Lid002_material" rgba="1 1 1 1.0" texture="Lid002_material" shininess="1" specular="1"/>
    <texture file="visuals/T_BC001.png" name="Lid001_material" type="2d"/>
    <material name="Lid001_material" rgba="1 1 1 1.0" texture="Lid001_material" shininess="1" specular="1"/>
    <texture file="visuals/T_BC001.png" name="Lid003_material" type="2d"/>
    <material name="Lid003_material" rgba="1 1 1 1.0" texture="Lid003_material" shininess="1" specular="1"/>
  </asset>
  <default>
    <default class="visual">
      <geom conaffinity="0" contype="0" group="1" type="mesh"/>
    </default>
    <default class="collision">
      <geom group="0" rgba="0.5 0 0 0.5"/>
    </default>
    <default class="spawn">
      <geom group="0" rgba="1 1 1 0.5" contype="0" conaffinity="0"/>
      <site group="0" rgba="1 1 1 0.5"/>
    </default>
    <default class="region">
      <geom group="1" conaffinity="0" contype="0" rgba="0 1 0 0"/>
    </default>
  </default>
  <worldbody>
    <body>
      <body name="object">
        <geom class="collision" type="box" pos="0.03337689 -0.12339199 0.12275045" size="0.008107754401862621 0.00810775626450777 0.0003749088500626385" quat="0.6850370168685913 -0.6850365996360779 -0.1752842217683792 0.17528419196605682" name="start_button_2" rgba="0.0 0.5 0 0.5"/>
        <geom class="collision" type="box" pos="-0.03153019 -0.12517217 0.12317976" size="0.008123134262859821 0.008123135194182396 0.00028663300327025354" quat="0.6893278956413269 -0.6893275380134583 0.15756691992282867 -0.15756681561470032" name="start_button_1" rgba="0.0 0.5 0 0.5"/>
        <site type="cylinder" rgba="0.8 0.5 0.25 1" size="0.0026102596893906593 0.06480149179697037" pos="-0.00006197 -0.17132880 -0.06067202" name="coffee_liquid"/>
        <site rgba="0 0 0 0" size="0.009999999776482582 0.009999999776482582" pos="0.00000000 -0.19099816 -0.12221063" name="receptacle_place_site"/>
        <geom mesh="Body001_vis" type="mesh" solimp="0.998 0.998 0.001" solref="0.001 1" density="100" friction="0.95 0.3 0.1" class="visual" material="Body001_material"/>
        <geom class="collision" type="cylinder" pos="-0.00008455 0.08543447 -0.00515004" size="0.05943594127893448 0.1380547285079956" quat="1.0 0.0 0.0 0.0"/>
        <geom class="collision" type="cylinder" pos="-0.00007092 -0.06774569 -0.02548748" size="0.06067289412021637 0.12002754956483841" quat="1.0 0.0 0.0 0.0"/>
        <geom class="collision" type="box" pos="0.04128961 0.01788845 0.11391169" size="0.019130084663629532 0.10068270564079285 0.01811387576162815" quat="1.0 0.0 0.0 0.0"/>
        <geom class="collision" type="box" pos="-0.00013092 0.02647686 -0.02269416" size="0.06055061146616936 0.0920943021774292 0.12082803249359131" quat="1.0 0.0 0.0 0.0"/>
        <geom class="collision" type="box" pos="-0.04330639 -0.08254817 0.11391169" size="0.013925363309681416 0.02177164889872074 0.01811387576162815" quat="0.9832549095153809 0.0 0.0 0.18223552405834198"/>
        <geom class="collision" type="box" pos="0.01800953 -0.12805091 0.04159516" size="0.00665710773319006 0.01646968349814415 0.008929953910410404" quat="1.0 0.0 0.0 0.0"/>
        <geom class="collision" type="box" pos="0.00302718 0.04895331 0.11383241" size="0.0400843545794487 0.03352620452642441 0.01803458295762539" quat="1.0 0.0 0.0 0.0"/>
        <geom class="collision" type="box" pos="0.00302718 -0.06283143 0.11151087" size="0.0400843545794487 0.039562687277793884 0.01571306213736534" quat="1.0 0.0 0.0 0.0"/>
        <geom class="collision" type="box" pos="-0.02219565 -0.10621590 0.11391169" size="0.013004411943256855 0.02177165262401104 0.01811387576162815" quat="0.8338857889175415 0.0 0.0 0.5519370436668396"/>
        <geom class="collision" type="box" pos="0.01092671 -0.10893441 0.11391169" size="0.011537442915141582 0.02177164889872074 0.01811387576162815" quat="0.6293203830718994 0.0 0.0 0.7771459817886353"/>
        <geom class="collision" type="box" pos="0.03913068 -0.09159508 0.11456246" size="0.01358610950410366 0.01903485134243965 0.018764644861221313" quat="0.2923716604709625 0.0 0.0 0.9563047885894775"/>
        <geom class="collision" type="cylinder" pos="-0.00095569 0.16287312 -0.11012395" size="0.06066026911139488 0.03334907069802284" quat="1.0 0.0 0.0 0.0"/>
        <geom class="collision" type="cylinder" pos="-0.00007033 -0.17143413 0.00815923" size="0.003892710665240884 0.006618843879550695" quat="1.0 0.0 0.0 0.0"/>
        <geom class="collision" type="box" pos="-0.01776849 -0.12805091 0.04159516" size="0.00665710773319006 0.01646968349814415 0.008929953910410404" quat="1.0 0.0 0.0 0.0"/>
        <geom class="collision" type="cylinder" pos="0.00005912 -0.16393071 -0.13212496" size="0.05953378975391388 0.009571795351803303" quat="1.0 0.0 0.0 0.0"/>
        <geom class="collision" type="box" pos="-0.04159667 0.02647686 0.11391169" size="0.01939186081290245 0.0920943021774292 0.01811387576162815" quat="1.0 0.0 0.0 0.0"/>
        <geom class="collision" type="cylinder" pos="-0.00007092 -0.16139901 0.05917697" size="0.038454651832580566 0.04464395344257355" quat="1.0 0.0 0.0 0.0"/>
        <body name="Button001">
          <joint axis="0.34288111329078674 0.9393788576126099 0.0" pos="-0.02824625 -0.11885668 0.12313449" limited="true" name="Button001_joint" range="0.0 0.003" type="slide" damping="1" frictionloss="1" armature=".01" stiffness="0.05"/>
          <geom mesh="Button001_vis" type="mesh" solimp="0.998 0.998 0.001" solref="0.001 1" density="100" friction="0.95 0.3 0.1" class="visual" material="Button001_material"/>
          <geom class="collision" type="cylinder" pos="-0.02996448 -0.12195992 0.12317976" size="0.008123134262859821 0.002947181696072221" quat="0.6893278956413269 -0.6893275380134583 0.15756691992282867 -0.15756681561470032"/>
        </body>
        <body name="Button002">
          <joint axis="-0.48307958245277405 0.8755765557289124 0.0" pos="0.03026902 -0.11796041 0.12273838" limited="true" name="Button002_joint" range="0.0 0.003" type="slide" damping="1" frictionloss="1" armature=".01" stiffness="0.05"/>
          <geom mesh="Button002_vis" type="mesh" solimp="0.998 0.998 0.001" solref="0.001 1" density="100" friction="0.95 0.3 0.1" class="visual" material="Button002_material"/>
          <geom class="collision" type="cylinder" pos="0.03172706 -0.12077847 0.12275045" size="0.008107754401862621 0.0022811703383922577" quat="0.6850370168685913 -0.6850365996360779 -0.1752842217683792 0.17528419196605682"/>
        </body>
        <body name="Container001_Clear">
          <joint axis="0.0 0.0 1.0" pos="0.00002819 0.17531276 0.02608194" limited="true" name="Container001_Clear_joint" range="0.0 0.1" type="slide" damping="1" frictionloss="1" armature=".01" stiffness="0.05"/>
          <geom mesh="Container001_Clear_vis" type="mesh" solimp="0.998 0.998 0.001" solref="0.001 1" density="100" friction="0.95 0.3 0.1" class="visual" material="Container001_Clear_material"/>
          <geom class="collision" type="box" pos="0.04845482 0.13288920 0.02458543" size="0.0012182785430923104 0.005222825799137354 0.09964721649885178" quat="0.9588197469711304 0.0 0.0 -0.28401538729667664"/>
          <geom class="collision" type="box" pos="0.05306359 0.14209267 0.02478163" size="0.0012182783102616668 0.005222824867814779 0.09945102035999298" quat="0.9816271662712097 0.0 0.0 -0.19080907106399536"/>
          <geom class="collision" type="box" pos="0.05592886 0.15187202 0.02478163" size="0.0012182785430923104 0.005222825799137354 0.09945101290941238" quat="0.9945219159126282 0.0 0.0 -0.10452854633331299"/>
          <geom class="collision" type="box" pos="0.05723620 0.16188884 0.02478163" size="0.0012182785430923104 0.005222825799137354 0.09945101290941238" quat="0.9998477101325989 0.0 0.0 -0.017452441155910492"/>
          <geom class="collision" type="box" pos="0.04172120 0.13322775 0.02478163" size="0.0012182785430923104 0.005222825799137354 0.09945102035999298" quat="0.9099612236022949 0.0 0.0 0.41469329595565796"/>
          <geom class="collision" type="box" pos="0.05425595 0.18234187 0.02478163" size="0.0012182786595076323 0.0052228267304599285 0.09945101290941238" quat="0.9862855672836304 0.0 0.0 0.16504766047000885"/>
          <geom class="collision" type="box" pos="0.04998215 0.19187807 0.02478163" size="0.0012182786595076323 0.005222826264798641 0.09945102035999298" quat="0.9681476354598999 0.0 0.0 0.2503799796104431"/>
          <geom class="collision" type="box" pos="0.04403534 0.20057775 0.02478163" size="0.0012182785430923104 0.005222825799137354 0.09945102035999298" quat="0.9396926164627075 0.0 0.0 0.3420201539993286"/>
          <geom class="collision" type="box" pos="0.03658281 0.20799986 0.02478163" size="0.0012182785430923104 0.005222825799137354 0.09945102035999298" quat="0.9063077569007874 0.0 0.0 0.4226183295249939"/>
          <geom class="collision" type="box" pos="0.02797438 0.21390106 0.02478163" size="0.001218278775922954 0.005222827196121216 0.09945101290941238" quat="0.866025447845459 0.0 0.0 0.4999999701976776"/>
          <geom class="collision" type="box" pos="0.01847246 0.21819700 0.02478163" size="0.0012182785430923104 0.005222825799137354 0.09945101290941238" quat="0.8191520571708679 0.0 0.0 0.5735764503479004"/>
          <geom class="collision" type="box" pos="0.00863306 0.22059539 0.02478163" size="0.0012182786595076323 0.005222826264798641 0.09945102035999298" quat="0.7660444378852844 0.0 0.0 0.6427876353263855"/>
          <geom class="collision" type="box" pos="-0.00157234 0.22126459 0.02478163" size="0.0012182785430923104 0.005222825799137354 0.09945101290941238" quat="0.70710688829422 0.0 0.0 0.7071066498756409"/>
          <geom class="collision" type="box" pos="-0.01104770 0.22023036 0.02478163" size="0.0012182785430923104 0.005222825799137354 0.09945102035999298" quat="0.6427876353263855 0.0 0.0 0.7660444378852844"/>
          <geom class="collision" type="box" pos="-0.02034055 0.21752311 0.02478163" size="0.0012182785430923104 0.005222825799137354 0.09945101290941238" quat="0.5735764503479004 0.0 0.0 0.8191520571708679"/>
          <geom class="collision" type="box" pos="-0.02918805 0.21312650 0.02478163" size="0.0012182786595076323 0.0052228267304599285 0.09945101290941238" quat="0.4999999701976776 0.0 0.0 0.866025447845459"/>
          <geom class="collision" type="box" pos="-0.03706644 0.20752949 0.02478163" size="0.0012182785430923104 0.005222825799137354 0.09945102035999298" quat="0.42261824011802673 0.0 0.0 0.9063078165054321"/>
          <geom class="collision" type="box" pos="-0.04387258 0.20080699 0.02478163" size="0.0012182785430923104 0.005222825799137354 0.09945102035999298" quat="0.3420201539993286 0.0 0.0 0.9396926164627075"/>
          <geom class="collision" type="box" pos="-0.04957604 0.19264469 0.02478163" size="0.0012182786595076323 0.0052228267304599285 0.09945101290941238" quat="0.2588190734386444 0.0 0.0 0.9659258127212524"/>
          <geom class="collision" type="box" pos="-0.05378393 0.18358251 0.02478163" size="0.0012182786595076323 0.005222826264798641 0.09945101290941238" quat="0.17364822328090668 0.0 0.0 0.9848077297210693"/>
          <geom class="collision" type="box" pos="-0.05640753 0.17359512 0.02478163" size="0.0012182785430923104 0.005222825799137354 0.09945101290941238" quat="0.08715580403804779 0.0 0.0 0.9961947202682495"/>
          <geom class="collision" type="box" pos="-0.05719334 0.16354434 0.02478163" size="0.0012182785430923104 0.005222825799137354 0.09945101290941238" quat="5.52335052361741e-07 0.0 -0.0 -1.0"/>
          <geom class="collision" type="box" pos="-0.05628079 0.15341751 0.02478163" size="0.0012182784266769886 0.005222825799137354 0.09945102035999298" quat="0.0871562734246254 0.0 -0.0 -0.9961946606636047"/>
          <geom class="collision" type="box" pos="-0.05359128 0.14354216 0.02478163" size="0.0012182786595076323 0.005222826264798641 0.09945101290941238" quat="0.17364822328090668 0.0 -0.0 -0.9848077297210693"/>
          <geom class="collision" type="box" pos="-0.04924083 0.13413250 0.02478163" size="0.0012182785430923104 0.005222825799137354 0.09945102035999298" quat="0.2588194012641907 0.0 -0.0 -0.9659257531166077"/>
          <geom class="collision" type="box" pos="-0.04331223 0.13204098 0.02458543" size="0.0012182785430923104 0.005222825799137354 0.09964721649885178" quat="0.41469326615333557 0.0 0.0 0.9099612832069397"/>
          <geom class="collision" type="box" pos="-0.03491673 0.13832241 0.02478163" size="0.0012182785430923104 0.005222825799137354 0.09945102035999298" quat="0.4848094582557678 0.0 0.0 0.8746197819709778"/>
          <geom class="collision" type="box" pos="-0.02581272 0.14325643 0.02478163" size="0.0012182785430923104 0.005222825799137354 0.09945101290941238" quat="0.544638991355896 0.0 0.0 0.8386706113815308"/>
          <geom class="collision" type="box" pos="-0.01621614 0.14677891 0.02478163" size="0.001218278193846345 0.005222824867814779 0.09945102035999298" quat="0.6018149852752686 0.0 0.0 0.7986355423927307"/>
          <geom class="collision" type="box" pos="-0.00620894 0.14870724 0.02478163" size="0.0012182785430923104 0.005222825799137354 0.09945101290941238" quat="0.6691306233406067 0.0 0.0 0.7431448101997375"/>
          <geom class="collision" type="box" pos="0.00402248 0.14889218 0.02478163" size="0.0012182786595076323 0.005222826264798641 0.09945101290941238" quat="0.7313539385795593 0.0 0.0 0.6819981336593628"/>
          <geom class="collision" type="box" pos="0.01436501 0.14731090 0.02478163" size="0.0012182785430923104 0.005222825799137354 0.09945102035999298" quat="0.7880106568336487 0.0 0.0 0.61566162109375"/>
          <geom class="collision" type="box" pos="0.02421232 0.14405064 0.02478163" size="0.0012182786595076323 0.0052228267304599285 0.09945101290941238" quat="0.8338857889175415 0.0 0.0 0.5519370436668396"/>
          <geom class="collision" type="box" pos="0.03348996 0.13921410 0.02478163" size="0.0012182786595076323 0.005222826264798641 0.09945102035999298" quat="0.8746196627616882 0.0 0.0 0.4848097264766693"/>
          <geom class="collision" type="box" pos="0.05668517 0.17218083 0.02478163" size="0.0012182785430923104 0.005222825799137354 0.09945101290941238" quat="0.9975640773773193 0.0 0.0 0.06975650042295456"/>
          <geom class="collision" type="box" pos="-0.04115665 0.18673016 -0.05745629" size="0.017046144232153893 0.008846818469464779 0.0021462563890963793" quat="0.5224984884262085 0.0 0.0 -0.8526402115821838"/>
          <geom class="collision" type="box" pos="0.02648988 0.20149383 -0.05745629" size="0.017046144232153893 0.008846817538142204 0.0021462563890963793" quat="0.9563047289848328 0.0 0.0 -0.29237180948257446"/>
          <geom class="collision" type="box" pos="0.03521128 0.14842322 -0.05745629" size="0.017046144232153893 0.008846818469464779 0.0021462563890963793" quat="0.9681476354598999 0.0 0.0 -0.2503799796104431"/>
          <geom class="collision" type="box" pos="-0.03601020 0.14788014 -0.05745629" size="0.017046144232153893 0.008846817538142204 0.0021462563890963793" quat="0.9659258127212524 0.0 0.0 0.2588191032409668"/>
          <geom class="collision" type="box" pos="-0.00120454 0.21229294 -0.05745629" size="0.017046144232153893 0.008846817538142204 0.0021462563890963793" quat="1.0 0.0 0.0 0.0"/>
          <geom class="collision" type="box" pos="-0.00125861 0.20378080 -0.05745629" size="0.029769079759716988 0.008846817538142204 0.0021462563890963793" quat="1.0 0.0 0.0 0.0"/>
          <geom class="collision" type="box" pos="-0.00076098 0.18708317 -0.05745629" size="0.04784898832440376 0.01339284423738718 0.0021462563890963793" quat="1.0 0.0 0.0 0.0"/>
          <geom class="collision" type="box" pos="-0.00019299 0.16198520 -0.05745629" size="0.05572507157921791 0.0125335194170475 0.0021462563890963793" quat="1.0 0.0 0.0 0.0"/>
          <geom class="collision" type="box" pos="-0.02435222 0.20482343 -0.05745629" size="0.017046144232153893 0.008846817538142204 0.0021462563890963793" quat="0.2840152382850647 0.0 0.0 -0.9588197469711304"/>
          <geom class="collision" type="box" pos="0.04332466 0.18046603 -0.05745629" size="0.017046146094799042 0.008846819400787354 0.0021462563890963793" quat="0.824126124382019 0.0 0.0 -0.5664063692092896"/>
          <body name="Lid002">
            <joint axis="0.0 0.0 1.0" pos="0.00000001 0.17537001 0.13381352" limited="true" name="Lid002_joint" range="0.0 0.05" type="slide" damping="1" frictionloss="1" armature=".01" stiffness="0.05" springref="-10"/>
            <geom mesh="Lid002_vis" type="mesh" solimp="0.998 0.998 0.001" solref="0.001 1" density="100" friction="0.95 0.3 0.1" class="visual" material="Lid002_material"/>
            <geom class="collision" type="box" pos="-0.02435222 0.20587437 0.12826881" size="0.017046144232153893 0.008846817538142204 0.0037567391991615295" quat="0.2840152382850647 0.0 0.0 -0.9588197469711304"/>
            <geom class="collision" type="box" pos="-0.00019299 0.16303614 0.12826881" size="0.05572507157921791 0.0125335194170475 0.0037567391991615295" quat="1.0 0.0 0.0 0.0"/>
            <geom class="collision" type="box" pos="-0.00076098 0.18813410 0.12826881" size="0.04784898832440376 0.01339284423738718 0.0037567391991615295" quat="1.0 0.0 0.0 0.0"/>
            <geom class="collision" type="box" pos="-0.00125861 0.20483173 0.12826881" size="0.029769079759716988 0.008846817538142204 0.0037567391991615295" quat="1.0 0.0 0.0 0.0"/>
            <geom class="collision" type="box" pos="-0.00120454 0.21334387 0.12826881" size="0.017046144232153893 0.008846817538142204 0.0037567391991615295" quat="1.0 0.0 0.0 0.0"/>
            <geom class="collision" type="box" pos="-0.03601020 0.14893107 0.12826881" size="0.017046144232153893 0.008846817538142204 0.003756739431992173" quat="0.9659258127212524 0.0 0.0 0.2588191032409668"/>
            <geom class="collision" type="box" pos="0.03521128 0.14947416 0.12826881" size="0.017046144232153893 0.008846818469464779 0.003756739431992173" quat="0.9681476354598999 0.0 0.0 -0.2503799796104431"/>
            <geom class="collision" type="box" pos="0.04332466 0.18151696 0.12826881" size="0.017046146094799042 0.008846819400787354 0.003756739431992173" quat="0.824126124382019 0.0 0.0 -0.5664063692092896"/>
            <geom class="collision" type="box" pos="0.02648988 0.20254476 0.12826881" size="0.017046144232153893 0.008846817538142204 0.003756739431992173" quat="0.9563047289848328 0.0 0.0 -0.29237180948257446"/>
            <geom class="collision" type="box" pos="-0.04115665 0.18778110 0.12826881" size="0.017046144232153893 0.008846818469464779 0.003756739431992173" quat="0.5224984884262085 0.0 0.0 -0.8526402115821838"/>
            <geom class="collision" type="box" pos="0.01886155 0.17849764 0.13587479" size="0.00119127391371876 0.0013586157001554966 0.004306853283196688" quat="1.0 0.0 0.0 0.0"/>
            <geom class="collision" type="box" pos="-0.01874880 0.17849764 0.13587479" size="0.00119127391371876 0.0013586157001554966 0.004306853283196688" quat="1.0 0.0 0.0 0.0"/>
            <geom class="collision" type="box" pos="0.00011367 0.17849764 0.14152364" size="0.020163578912615776 0.0014171447837725282 0.001490486436523497" quat="1.0 0.0 0.0 0.0"/>
          </body>
        </body>
        <body name="Lid001">
          <joint axis="-1.0 0.0 0.0" pos="-0.00000000 0.01223237 0.13202617" limited="true" name="Lid001_joint" range="0.0 1.5707963267948966" type="hinge" damping="1" frictionloss="1" armature=".01" stiffness="0.05"/>
          <geom mesh="Lid001_vis" type="mesh" solimp="0.998 0.998 0.001" solref="0.001 1" density="100" friction="0.95 0.3 0.1" class="visual" material="Lid001_material"/>
          <geom class="collision" type="box" pos="0.00000766 -0.07590801 0.13561028" size="0.020570728927850723 0.011319028213620186 0.0018015123205259442" quat="0.9848077893257141 -0.17364810407161713 0.0 0.0"/>
          <geom class="collision" type="box" pos="0.00000766 -0.02653229 0.13072474" size="0.020570728927850723 0.03908515349030495 0.0023022110108286142" quat="1.0 0.0 0.0 0.0"/>
        </body>
        <body name="Lid003">
          <joint axis="0.0 0.0 1.0" pos="0.00000000 -0.17033783 -0.11972327" limited="true" name="Lid003_joint" range="0.0 0.05" type="slide" damping="1" frictionloss="1" armature=".01" stiffness="0.05" springref="-20"/>
          <geom mesh="Lid003_vis" type="mesh" solimp="0.998 0.998 0.001" solref="0.001 1" density="100" friction="0.95 0.3 0.1" class="visual" material="Lid003_material"/>
          <geom class="collision" type="box" pos="0.04048457 -0.18513753 -0.11934864" size="0.017046144232153893 0.008846818469464779 0.0018110563978552818" quat="0.8526402115821838 0.0 0.0 0.5224984884262085"/>
          <geom class="collision" type="box" pos="-0.02716196 -0.19990121 -0.11934864" size="0.017046144232153893 0.008846817538142204 0.0018110565142706037" quat="0.2923717796802521 0.0 0.0 0.9563047289848328"/>
          <geom class="collision" type="box" pos="-0.04399674 -0.17887339 -0.11934864" size="0.01704614795744419 0.008846819400787354 0.0018110565142706037" quat="0.5664061307907104 0.0 0.0 0.8241262435913086"/>
          <geom class="collision" type="box" pos="-0.03233996 -0.14043817 -0.11934864" size="0.017046144232153893 0.01615563966333866 0.0018110566306859255" quat="0.2503805458545685 0.0 0.0 0.9681475162506104"/>
          <geom class="collision" type="box" pos="0.03196092 -0.14043801 -0.11934864" size="0.017046144232153893 0.01560122985392809 0.0018110563978552818" quat="0.25881895422935486 0.0 0.0 -0.9659258723258972"/>
          <geom class="collision" type="box" pos="0.00053246 -0.21070032 -0.11934864" size="0.017046144232153893 0.008846817538142204 0.0018110565142706037" quat="6.715443419125222e-07 0.0 0.0 1.0"/>
          <geom class="collision" type="box" pos="0.00058653 -0.20218818 -0.11934864" size="0.029769079759716988 0.008846817538142204 0.0018110565142706037" quat="6.715443419125222e-07 0.0 0.0 1.0"/>
          <geom class="collision" type="box" pos="0.00008891 -0.18549055 -0.11934864" size="0.04784898832440376 0.01339284423738718 0.0018110565142706037" quat="6.715443419125222e-07 0.0 0.0 1.0"/>
          <geom class="collision" type="box" pos="0.00093446 -0.14459391 -0.11934864" size="0.03661051392555237 0.013927038758993149 0.0018110565142706037" quat="6.715443419125222e-07 0.0 0.0 1.0"/>
          <geom class="collision" type="box" pos="-0.00047909 -0.16039258 -0.11934864" size="0.05572507157921791 0.0125335194170475 0.0018110565142706037" quat="6.715443419125222e-07 0.0 0.0 1.0"/>
        </body>
        <geom class="region" name="reg_main" type="box" pos="5.000000000837668e-09 1.500000000598245e-08 -0.0010559849999999954" size="0.061192075 0.22370256500000002 0.14295807500000002"/>
      </body>
    </body>
  </worldbody>
  <actuator>
    <motor name="Button001_joint_actuator" joint="Button001_joint" gear="0.5"/>
    <motor name="Button002_joint_actuator" joint="Button002_joint" gear="0.5"/>
    <motor name="Container001_Clear_joint_actuator" joint="Container001_Clear_joint" gear="10"/>
    <motor name="Lid001_joint_actuator" joint="Lid001_joint" gear="10"/>
    <motor name="Lid003_joint_actuator" joint="Lid003_joint" gear="10"/>
    <motor name="Lid002_joint_actuator" joint="Lid002_joint" gear="10"/>
  </actuator>
</mujoco>
