<?xml version='1.0' encoding='UTF-8'?>
<mujoco model="model">
  <option timestep="0.002" gravity="0.0 0.0 -9.81"/>
  <compiler angle="radian"/>
  <asset>
    <mesh file="visuals/door.obj" name="door_vis"/>
    <mesh file="visuals/door_Clear.obj" name="door_Clear_vis"/>
    <mesh file="visuals/Body001.obj" name="Body001_vis"/>
    <mesh file="visuals/Disc001.obj" name="Disc001_vis"/>
    <texture file="visuals/T_BC001.png" name="Body001_material" type="2d"/>
    <material name="Body001_material" rgba="1 1 1 1.0" texture="Body001_material" shininess="1" specular="1"/>
    <texture file="visuals/T_BC001.png" name="door_material" type="2d"/>
    <material name="door_material" rgba="1 1 1 1.0" texture="door_material" shininess="1" specular="1"/>
    <texture file="visuals/T_BC001.png" name="door_Clear_material" type="2d"/>
    <material name="door_Clear_material" rgba="1 1 1 0.75" texture="door_Clear_material" shininess="0.2512328028678894" specular="0.3103448502657381"/>
    <texture file="visuals/T_BC001.png" name="Disc001_material" type="2d"/>
    <material name="Disc001_material" rgba="1 1 1 1.0" texture="Disc001_material" shininess="0.5" specular="0.5"/>
  </asset>
  <default>
    <default class="visual">
      <geom conaffinity="0" contype="0" group="1" type="mesh"/>
    </default>
    <default class="collision">
      <geom group="0" rgba="0.5 0 0 0.5"/>
    </default>
    <default class="spawn">
      <geom group="0" rgba="1 1 1 0.5" contype="0" conaffinity="0"/>
      <site group="0" rgba="1 1 1 0.5"/>
    </default>
    <default class="region">
      <geom group="1" conaffinity="0" contype="0" rgba="0 1 0 0"/>
    </default>
  </default>
  <worldbody>
    <body>
      <body name="object">
        <geom class="collision" type="box" pos="0.26886290 -0.22100414 -0.09540475" size="0.010876283049583435 0.0004979527438990772 0.010797453112900257" quat="1.0 0.0 0.0 0.0" name="start_button" rgba="0.0 0.5 0 0.5"/>
        <geom class="collision" type="box" pos="0.23078033 -0.22100414 -0.09497277" size="0.010778550058603287 0.0004949670983478427 0.010775938630104065" quat="1.0 0.0 0.0 0.0" name="stop_button" rgba="0.0 0.5 0 0.5"/>
        <geom class="collision" type="cylinder" pos="-0.04945516 0.01560051 -0.13233270" size="0.1811605840921402 0.0011734063737094402" quat="1.0 0.0 0.0 0.0" name="tray" rgba="0 1 0 0.5"/>
        <geom mesh="Body001_vis" type="mesh" solimp="0.998 0.998 0.001" solref="0.001 1" friction="0.95 0.3 0.1" class="visual" material="Body001_material"/>
        <geom class="collision" type="box" pos="-0.28583077 0.03089763 -0.00228121" size="0.016901511698961258 0.2250843644142151 0.16554179787635803" quat="1.0 0.0 0.0 0.0"/>
        <geom class="collision" type="box" pos="0.23694518 0.03089764 -0.00061248" size="0.06578709930181503 0.2250843644142151 0.16721045970916748" quat="1.0 0.0 0.0 0.0"/>
        <geom class="collision" type="box" pos="0.00030022 0.03089763 0.15500790" size="0.3024320602416992 0.2250843644142151 0.012815229594707489" quat="1.0 0.0 0.0 0.0"/>
        <geom class="collision" type="box" pos="0.00030022 0.03089763 -0.15489802" size="0.3024320602416992 0.2250843644142151 0.012924929149448872" quat="1.0 0.0 0.0 0.0"/>
        <geom class="collision" type="box" pos="0.24769089 -0.19889010 0.00000003" size="0.055041395127773285 0.02009808085858822 0.16782304644584656" quat="1.0 0.0 0.0 0.0"/>
        <geom class="collision" type="box" pos="-0.06188840 0.23836537 -0.00228122" size="0.016901511698961258 0.2250843644142151 0.16554179787635803" quat="0.7071068286895752 0.0 0.0 -0.7071067094802856"/>
        <body name="door">
          <joint axis="0.0 0.0 1.0" pos="-0.28924674 -0.20665190 -0.00025728" limited="true" name="microjoint" range="-1.5707963267948966 0.0" type="hinge" damping="1" frictionloss="1" armature=".01" stiffness="0.05"/>
          <geom mesh="door_vis" type="mesh" solimp="0.998 0.998 0.001" solref="0.001 1" friction="0.95 0.3 0.1" class="visual" material="door_material"/>
          <geom class="collision" type="box" pos="-0.05539873 -0.21148932 0.00030119" size="0.20943863689899445 0.0022145546972751617 0.13125666975975037" quat="1.0 0.0 0.0 0.0"/>
          <geom class="collision" type="box" pos="-0.05670168 -0.20927480 0.15091729" size="0.23352432250976562 0.00971329864114523 0.016166234388947487" quat="1.0 0.0 0.0 0.0"/>
          <geom class="collision" type="box" pos="-0.05670168 -0.20927480 -0.15110295" size="0.23352432250976562 0.00971329864114523 0.01549109909683466" quat="1.0 0.0 0.0 0.0"/>
          <geom class="collision" type="box" pos="0.16707136 -0.20927480 -0.00343810" size="0.00981630478054285 0.00971329864114523 0.14392904937267303" quat="1.0 0.0 0.0 0.0"/>
          <geom class="collision" type="box" pos="-0.27970296 -0.20927480 -0.00137535" size="0.010523008182644844 0.00971329864114523 0.14233620464801788" quat="1.0 0.0 0.0 0.0"/>
          <geom class="collision" type="box" pos="0.13395572 -0.25117895 -0.14798586" size="0.01917259767651558 0.004803053569048643 0.009773798286914825" quat="1.0 0.0 0.0 0.0"/>
          <geom class="collision" type="box" pos="0.13395570 -0.25151581 0.12639284" size="0.01917259767651558 0.00446621747687459 0.023682648316025734" quat="1.0 0.0 0.0 0.0"/>
          <geom class="collision" type="box" pos="0.13395566 -0.23338032 0.15202446" size="0.01917262002825737 0.017437011003494263 0.004819198045879602" quat="1.0 0.0 0.0 0.0"/>
          <geom class="collision" type="box" pos="0.13423698 -0.23224500 -0.15573693" size="0.01895139180123806 0.016301777213811874 0.00469950819388032" quat="1.0 0.0 0.0 0.0"/>
          <geom class="collision" type="box" pos="0.13395572 -0.25151506 -0.01817428" size="0.01917264796793461 0.0044672382064163685 0.11811789125204086" quat="1.0 0.0 0.0 0.0" name="door_handle_main"/>
          <geom class="collision" type="box" pos="-0.05539873 -0.21561125 0.00030119" size="0.22794562578201294 0.0022145546972751617 0.1607520580291748" quat="1.0 0.0 0.0 0.0" name="door_main"/>
          <body name="door_Clear">
            <geom mesh="door_Clear_vis" type="mesh" solimp="0.998 0.998 0.001" solref="0.001 1" friction="0.95 0.3 0.1" class="visual" material="door_Clear_material"/>
            <geom class="collision" type="box" pos="-0.05539873 -0.21148932 0.00030119" size="0.20943863689899445 0.0022145546972751617 0.13125666975975037" quat="1.0 0.0 0.0 0.0"/>
          </body>
        </body>
        <body name="Disc001">
          <joint axis="0.0 0.0 1.0" pos="-0.04863029 0.01558806 -0.13602901" limited="false" name="Disc001_joint" range="0 360" type="hinge" damping="1" frictionloss="1" armature=".01" stiffness="0.05"/>
          <geom mesh="Disc001_vis" type="mesh" solimp="0.998 0.998 0.001" solref="0.001 1" friction="0.95 0.3 0.1" class="visual" material="Disc001_material"/>
          <geom class="collision" type="cylinder" pos="-0.04688514 0.01612883 -0.13734661" size="0.18033765256404877 0.0026822981890290976" quat="1.0 0.0 0.0 0.0"/>
        </body>
        <geom class="region" name="reg_int" type="box" pos="-0.04836992 0.013671780000000008 0.001949270000000003" size="0.21390253999999997 0.20144119 0.1341085"/>
        <geom class="region" name="reg_main" type="box" pos="0.0 0.018496974999999985 7.500000000215667e-08" size="0.30373229 0.238485035 0.168823045"/>
      <geom class="region" name="reg_tray" type="cylinder" pos="-0.04945516 0.01560051 0.0024492381868547186" size="0.1811605840921402 0.13260853181314528"/></body>
    </body>
  </worldbody>
  <actuator>
    <motor name="microjoint_actuator" joint="microjoint" gear="10"/>
    <motor name="Disc001_joint_actuator" joint="Disc001_joint" gear="10"/>
  </actuator>
</mujoco>
