<?xml version='1.0' encoding='UTF-8'?>
<mujoco model="model">
  <option timestep="0.002" gravity="0.0 0.0 -9.81"/>
  <compiler angle="radian"/>
  <asset>
    <mesh file="visuals/freezer0.obj" name="freezer0_vis"/>
    <mesh file="visuals/freezer1.obj" name="freezer1_vis"/>
    <mesh file="visuals/fridge_drawer0.obj" name="fridge_drawer0_vis"/>
    <mesh file="visuals/fridge_left_door.obj" name="fridge_left_door_vis"/>
    <mesh file="visuals/fridge_right_door.obj" name="fridge_right_door_vis"/>
    <mesh file="visuals/fridge_right_door_Clear.obj" name="fridge_right_door_Clear_vis"/>
    <mesh file="visuals/Body001.obj" name="Body001_vis"/>
    <mesh file="visuals/Body001_Clear.obj" name="Body001_Clear_vis"/>
    <texture file="visuals/T_BC001.png" name="Body001_material" type="2d"/>
    <material name="Body001_material" rgba="1 1 1 1.0" texture="Body001_material" shininess="0.1" specular="5"/>
    <texture file="visuals/T_BC001.png" name="freezer0_material" type="2d"/>
    <material name="freezer0_material" rgba="1 1 1 1.0" texture="freezer0_material" shininess="0.1" specular="5"/>
    <texture file="visuals/T_BC001.png" name="freezer1_material" type="2d"/>
    <material name="freezer1_material" rgba="1 1 1 1.0" texture="freezer1_material" shininess="0.1" specular="5"/>
    <texture file="visuals/T_BC001.png" name="fridge_drawer0_material" type="2d"/>
    <material name="fridge_drawer0_material" rgba="1 1 1 1.0" texture="fridge_drawer0_material" shininess="0.1" specular="5"/>
    <texture file="visuals/T_BC001.png" name="fridge_left_door_material" type="2d"/>
    <material name="fridge_left_door_material" rgba="1 1 1 1.0" texture="fridge_left_door_material" shininess="0.1" specular="5"/>
    <texture file="visuals/T_BC001.png" name="fridge_right_door_material" type="2d"/>
    <material name="fridge_right_door_material" rgba="1 1 1 1.0" texture="fridge_right_door_material" shininess="0.1" specular="5"/>
    <material name="fridge_right_door_Clear_material" rgba="0.7829207181930542 0.7829207181930542 0.7829207181930542 0.699999988079071" shininess="0.2512328028678894" specular="0.3103448502657381"/>
    <material name="Body001_Clear_material" rgba="0.7829207181930542 0.7829207181930542 0.7829207181930542 0.699999988079071" shininess="0.2512328028678894" specular="0.3103448502657381"/>
  </asset>
  <default>
    <default class="visual">
      <geom conaffinity="0" contype="0" group="1" type="mesh"/>
    </default>
    <default class="collision">
      <geom group="0" rgba="0.5 0 0 0.5"/>
    </default>
    <default class="spawn">
      <geom group="0" rgba="1 1 1 0.5" contype="0" conaffinity="0"/>
      <site group="0" rgba="1 1 1 0.5"/>
    </default>
    <default class="region">
      <geom group="1" conaffinity="0" contype="0" rgba="0 1 0 0"/>
    </default>
  </default>
  <worldbody>
    <body>
      <body name="object">
        <geom mesh="Body001_vis" type="mesh" solimp="0.998 0.998 0.001" solref="0.001 1" friction="0.95 0.3 0.1" class="visual" material="Body001_material"/>
        <geom class="collision" type="box" pos="0.0006654927274212241 0.05615266412496567 0.5888007879257202" size="0.40937232971191406 0.19231247901916504 0.005514178425073624" quat="1.0 0.0 0.0 0.0"/>
        <geom class="collision" type="box" pos="0.0006654927274212241 0.05615266412496567 0.20450350642204285" size="0.40937232971191406 0.19231247901916504 0.005514178425073624" quat="1.0 0.0 0.0 0.0"/>
        <geom class="collision" type="box" pos="-0.43239063024520874 0.0789387971162796 2.281851152474701e-09" size="0.025050994008779526 0.37569648027420044 0.9743537306785583" quat="1.0 0.0 0.0 0.0"/>
        <geom class="collision" type="box" pos="0.43343523144721985 0.0789387971162796 2.281851152474701e-09" size="0.024006403982639313 0.37569648027420044 0.9743537306785583" quat="1.0 0.0 0.0 0.0"/>
        <geom class="collision" type="box" pos="0.002809131983667612 0.35418015718460083 2.281851152474701e-09" size="0.4140954911708832 0.10045510530471802 0.9743537306785583" quat="1.0 0.0 0.0 0.0"/>
        <geom class="collision" type="box" pos="0.0028091389685869217 0.0789387971162796 0.9467322826385498" size="0.4140954911708832 0.37569648027420044 0.027621673420071602" quat="1.0 0.0 0.0 0.0"/>
        <geom class="collision" type="box" pos="0.002809138037264347 0.0789387971162796 -0.21230341494083405" size="0.4140954911708832 0.37569648027420044 0.038041457533836365" quat="1.0 0.0 0.0 0.0"/>
        <geom class="collision" type="box" pos="0.002809138037264347 0.0789387971162796 -0.5444928407669067" size="0.4140954911708832 0.37569648027420044 0.026665542274713516" quat="1.0 0.0 0.0 0.0"/>
        <geom class="collision" type="box" pos="0.0028091371059417725 0.0789387971162796 -0.9559710025787354" size="0.4140954911708832 0.37569648027420044 0.018382761627435684" quat="1.0 0.0 0.0 0.0"/>
        <geom class="collision" type="box" pos="-0.3977801501750946 0.03480931371450424 0.5585342645645142" size="0.0075620138086378574 0.22568455338478088 0.027275606989860535" quat="1.0 0.0 0.0 0.0"/>
        <geom class="collision" type="box" pos="-0.3977801501750946 0.02478325366973877 0.3838809132575989" size="0.0075620138086378574 0.23571060597896576 0.027275606989860535" quat="1.0 0.0 0.0 0.0"/>
        <geom class="collision" type="box" pos="-0.3977801501750946 0.02478325366973877 -0.0023946017026901245" size="0.0075620138086378574 0.23571060597896576 0.027275606989860535" quat="1.0 0.0 0.0 0.0"/>
        <geom class="collision" type="box" pos="-0.3977801501750946 0.02478324994444847 0.17225873470306396" size="0.0075620138086378574 0.23571060597896576 0.027275606989860535" quat="1.0 0.0 0.0 0.0"/>
        <geom class="collision" type="box" pos="0.39763379096984863 0.02478324994444847 0.17225873470306396" size="0.0075620138086378574 0.23571060597896576 0.027275606989860535" quat="1.0 0.0 0.0 0.0"/>
        <geom class="collision" type="box" pos="0.39763379096984863 0.02478325366973877 -0.0023946017026901245" size="0.0075620138086378574 0.23571060597896576 0.027275606989860535" quat="1.0 0.0 0.0 0.0"/>
        <geom class="collision" type="box" pos="0.39763379096984863 0.02478325366973877 0.3838809132575989" size="0.0075620138086378574 0.23571060597896576 0.027275606989860535" quat="1.0 0.0 0.0 0.0"/>
        <geom class="collision" type="box" pos="0.39763379096984863 0.03480931371450424 0.5585342645645142" size="0.0075620138086378574 0.22568455338478088 0.027275606989860535" quat="1.0 0.0 0.0 0.0"/>
        <geom class="collision" type="box" pos="0.0028091389685869217 -0.0073231663554906845 0.9188090562820435" size="0.1594373732805252 0.16066031157970428 0.00796419195830822" quat="1.0 0.0 0.0 0.0"/>
        <body name="freezer0">
          <geom class="region" name="reg_freezer0" type="box" pos="-0.0013597309589385986 -0.09237458184361458 -0.7517581582069397" size="0.34636629915237427 0.19313483855128288 0.16022856330871582"/>
          <joint axis="0.0 -1.0 0.0" pos="-5.4772979041217695e-08 -0.11758746206760406 -0.7575267553329468" limited="true" name="freezer0_door_joint" range="0.0 0.4" type="slide" damping="1" frictionloss="1" armature=".01" stiffness="0.05"/>
          <geom mesh="freezer0_vis" type="mesh" solimp="0.998 0.998 0.001" solref="0.001 1" friction="0.95 0.3 0.1" class="visual" material="freezer0_material"/>
          <geom class="collision" type="box" pos="0.0006083666230551898 -0.09320656955242157 -0.9239939451217651" size="0.35936403274536133 0.20855751633644104 0.0044151670299470425" quat="1.0 0.0 0.0 0.0"/>
          <geom class="collision" type="box" pos="0.3686133325099945 -0.06713901460170746 -0.7525335550308228" size="0.008640914224088192 0.2404424399137497 0.16708417236804962" quat="1.0 0.0 0.0 0.0"/>
          <geom class="collision" type="box" pos="-0.00023537719971500337 -0.3052603602409363 -0.7556809782981873" size="0.18085241317749023 0.3740488588809967 0.0035023794043809175" quat="0.4905640780925751 0.5092608332633972 -0.4905611574649811 0.5092642307281494"/>
          <geom class="collision" type="box" pos="-0.00023408143897540867 0.16065528988838196 -0.8216227889060974" size="0.11349354684352875 0.3740488588809967 0.003861266653984785" quat="0.37202736735343933 -0.6013256907463074 0.6013337969779968 0.37202250957489014"/>
          <geom class="collision" type="box" pos="-1.3189855962991714e-07 -0.34826090931892395 -0.7575268745422363" size="0.45744144916534424 0.04144240915775299 0.19901543855667114" quat="1.0 0.0 0.0 0.0" name="freezer0_door_main"/>
          <geom class="collision" type="box" pos="-0.0030822562985122204 -0.4421125054359436 -0.6056478023529053" size="0.18589089810848236 0.01306017767637968 0.02261965163052082" quat="1.0 0.0 0.0 0.0" name="freezer0_door_handle_main"/>
          <geom class="collision" type="box" pos="-0.30894798040390015 -0.39824309945106506 -0.6059889793395996" size="0.14072267711162567 0.014652024023234844 0.02227095142006874" quat="0.9923864603042603 0.0 0.0 -0.12316303700208664" name="freezer0_door_handle_1"/>
          <geom class="collision" type="box" pos="0.30305591225624084 -0.3985201418399811 -0.6056209802627563" size="0.14072267711162567 0.01493772678077221 0.022638944908976555" quat="0.9923864006996155 0.0 0.0 0.12316328287124634" name="freezer0_door_handle_2"/>
          <geom class="collision" type="box" pos="-0.3673965632915497 -0.06713901460170746 -0.7525335550308228" size="0.008640915155410767 0.24046066403388977 0.1672159731388092" quat="1.0 0.0 0.0 0.0"/>
          <geom class="collision" type="box" pos="0.0005800336366519332 0.21518729627132416 -0.6614482998847961" size="0.3721744120121002 0.005317181348800659 0.07658029347658157" quat="1.0 0.0 0.0 0.0"/>
        </body>
        <body name="freezer1">
          <geom class="region" name="reg_freezer1" type="box" pos="-0.0013597309589385986 -0.09237458184361458 -0.3810538202524185" size="0.34636629915237427 0.19313483855128288 0.1171111444234848"/>
          <joint axis="0.0 -1.0 0.0" pos="-2.463909076766413e-08 -0.1173470988869667 -0.38834065198898315" limited="true" name="freezer1_door_joint" range="0.0 0.4" type="slide" damping="1" frictionloss="1" armature=".01" stiffness="0.05"/>
          <geom mesh="freezer1_vis" type="mesh" solimp="0.998 0.998 0.001" solref="0.001 1" friction="0.95 0.3 0.1" class="visual" material="freezer1_material"/>
          <geom class="collision" type="box" pos="0.0 -0.34782081842422485 -0.388280987739563" size="0.45744162797927856 0.04100235179066658 0.1508244276046753" quat="1.0 0.0 0.0 0.0" name="freezer1_door_main"/>
          <geom class="collision" type="box" pos="-0.0030822562985122204 -0.4416618049144745 -0.28972965478897095" size="0.18589089810848236 0.012609447352588177 0.021864306181669235" quat="1.0 0.0 0.0 0.0" name="freezer1_door_handle_main"/>
          <geom class="collision" type="box" pos="-0.30886685848236084 -0.3979213237762451 -0.28972965478897095" size="0.14072267711162567 0.01432017795741558 0.021856945008039474" quat="0.9923864603042603 0.0 0.0 -0.12316303700208664" name="freezer1_door_handle_1"/>
          <geom class="collision" type="box" pos="0.30295634269714355 -0.39812520146369934 -0.28972965478897095" size="0.14072267711162567 0.014530442655086517 0.021856945008039474" quat="0.9923864006996155 0.0 0.0 0.12316328287124634" name="freezer1_door_handle_2"/>
          <geom class="collision" type="box" pos="-0.00023407801927533 0.1679583042860031 -0.4062451422214508" size="0.11459759622812271 0.3740488886833191 0.006074460688978434" quat="0.37202736735343933 -0.6013256907463074 0.6013337969779968 0.37202250957489014"/>
          <geom class="collision" type="box" pos="-0.00023537360539194196 -0.3052603602409363 -0.381129652261734" size="0.12921546399593353 0.3740488588809967 0.0035026802215725183" quat="0.4905640780925751 0.5092608332633972 -0.4905611574649811 0.5092642307281494"/>
          <geom class="collision" type="box" pos="0.0005800426006317139 0.21518729627132416 -0.2900519073009491" size="0.3721744418144226 0.005317189730703831 0.032599397003650665" quat="1.0 0.0 0.0 0.0"/>
          <geom class="collision" type="box" pos="0.3686133325099945 -0.06713901460170746 -0.3809087872505188" size="0.008640914224088192 0.24046143889427185 0.12334893643856049" quat="1.0 0.0 0.0 0.0"/>
          <geom class="collision" type="box" pos="-0.3673965632915497 -0.06713901460170746 -0.3809087872505188" size="0.008640915155410767 0.24046170711517334 0.12346427142620087" quat="1.0 0.0 0.0 0.0"/>
          <geom class="collision" type="box" pos="0.0006083666230551898 -0.09320656955242157 -0.5086162090301514" size="0.35936403274536133 0.20855751633644104 0.004415780305862427" quat="1.0 0.0 0.0 0.0"/>
        </body>
        <body name="fridge_drawer0">
          <geom class="region" name="reg_fridge_drawer0" type="box" pos="0.002443835139274597 0.011486493051052094 0.0035110078752040863" size="0.28600117361545563 0.20450006967782974 0.12949386408925057"/>
          <joint axis="0.0 -1.0 0.0" pos="-0.0028584750834852457 0.0022408217191696167 0.008335612714290619" limited="true" name="fridge_drawer0_joint" range="0.0 0.4" type="slide" damping="1" frictionloss="1" armature=".01" stiffness="0.05"/>
          <geom mesh="fridge_drawer0_vis" type="mesh" solimp="0.998 0.998 0.001" solref="0.001 1" friction="0.95 0.3 0.1" class="visual" material="fridge_drawer0_material"/>
          <geom class="collision" type="box" pos="-0.0018615599256008863 -0.21263664960861206 0.11792048811912537" size="0.30760201811790466 0.014628909528255463 0.05263250321149826" quat="1.0 0.0 0.0 0.0"/>
          <geom class="collision" type="box" pos="-0.002474024659022689 0.013149255886673927 -0.13450539112091064" size="0.2902950942516327 0.2111547440290451 0.00416182354092598" quat="1.0 0.0 0.0 0.0"/>
          <geom class="collision" type="box" pos="0.00050507509149611 0.22799749672412872 0.0011797472834587097" size="0.2904875874519348 0.005564833991229534 0.1347522735595703" quat="1.0 0.0 0.0 0.0"/>
          <geom class="collision" type="box" pos="-0.29894906282424927 0.015612324699759483 0.002210605889558792" size="0.006310629658401012 0.21361808478832245 0.13578325510025024" quat="1.0 0.0 0.0 0.0"/>
          <geom class="collision" type="box" pos="0.29438215494155884 0.02131838910281658 0.0022106077522039413" size="0.006310643628239632 0.2193242758512497 0.1357833743095398" quat="1.0 0.0 0.0 0.0"/>
          <geom class="collision" type="box" pos="-0.0018615599256008863 -0.2126377820968628 -0.0828283280134201" size="0.30764204263687134 0.014630107209086418 0.07450395077466965" quat="1.0 0.0 0.0 0.0"/>
          <geom class="collision" type="box" pos="-0.1794939488172531 -0.212637796998024 0.026925262063741684" size="0.1300179660320282 0.01463015004992485 0.03786812722682953" quat="1.0 0.0 0.0 0.0"/>
          <geom class="collision" type="box" pos="0.2017325609922409 -0.21263782680034637 0.026925262063741684" size="0.1028108075261116 0.014630201272666454 0.03786814957857132" quat="1.0 0.0 0.0 0.0"/>
          <geom class="collision" type="box" pos="0.026203811168670654 -0.22475449740886688 0.052468083798885345" size="0.07455941289663315 0.0025141423102468252 0.01256746519356966" quat="1.0 0.0 0.0 0.0"/>
          <geom class="collision" type="box" pos="0.026203811168670654 -0.19889093935489655 0.027250539511442184" size="0.0745597779750824 0.000883451197296381 0.03660789132118225" quat="1.0 0.0 0.0 0.0"/>
        </body>
        <body name="fridge_left_door">
          <joint axis="0.0 0.0 -1.0" pos="-0.40305250883102417 -0.34666505455970764 0.37841489911079407" limited="true" name="fridge_left_door_joint" range="0.0 1.5707963267948966" type="hinge" damping="1" frictionloss="1" armature=".01" stiffness="0.05"/>
          <geom mesh="fridge_left_door_vis" type="mesh" solimp="0.998 0.998 0.001" solref="0.001 1" friction="0.95 0.3 0.1" class="visual" material="fridge_left_door_material"/>
          <geom class="collision" type="box" pos="-0.22949627041816711 -0.3516943156719208 0.6658487319946289" size="0.20845761895179749 0.03155607730150223 0.3085051476955414" quat="1.0 0.0 0.0 0.0" name="fridge_left_door_main"/>
          <geom class="collision" type="box" pos="-0.043255966156721115 -0.4387055039405823 0.39825060963630676" size="0.020025629550218582 0.012182285077869892 0.20292799174785614" quat="1.0 0.0 0.0 0.0" name="fridge_left_door_handle_main"/>
          <geom class="collision" type="box" pos="-0.04368552938103676 -0.4142951965332031 0.6992678642272949" size="0.15277734398841858 0.012184272520244122 0.020025623962283134" quat="0.7036940455436707 -0.06938757747411728 0.7036941051483154 -0.06938757747411728" name="fridge_left_door_handle_1"/>
          <geom class="collision" type="box" pos="-0.04342835023999214 -0.4153255522251129 0.08840882033109665" size="0.15271838009357452 0.012182695791125298 0.020025666803121567" quat="0.705168604850769 0.05231887102127075 0.7051685452461243 0.05231887102127075" name="fridge_left_door_handle_2"/>
          <geom class="collision" type="box" pos="-0.22737178206443787 -0.2903779447078705 0.37775924801826477" size="0.14489077031612396 0.020536476746201515 0.5126291513442993" quat="1.0 0.0 0.0 0.0"/>
          <geom class="collision" type="box" pos="-0.22983205318450928 -0.2701058089733124 0.6600713729858398" size="0.16895322501659393 0.046253252774477005 0.24985185265541077" quat="1.0 0.0 0.0 0.0"/>
          <geom class="collision" type="box" pos="-0.22984567284584045 -0.35054901242256165 -0.13871297240257263" size="0.20880651473999023 0.030410680919885635 0.08287671208381653" quat="1.0 0.0 0.0 0.0"/>
          <geom class="collision" type="box" pos="-0.3748109042644501 -0.35059499740600586 0.14636197686195374" size="0.0626794621348381 0.03045680746436119 0.2097291201353073" quat="1.0 0.0 0.0 0.0"/>
          <geom class="collision" type="box" pos="-0.052935484796762466 -0.35635867714881897 0.14636196196079254" size="0.04649600014090538 0.03622039034962654 0.20972852408885956" quat="1.0 0.0 0.0 0.0"/>
          <geom class="collision" type="box" pos="-0.2095235139131546 -0.33079081773757935 0.3130360245704651" size="0.054677631705999374 0.035663824528455734 0.07370862364768982" quat="1.0 0.0 0.0 0.0"/>
          <geom class="collision" type="box" pos="-0.20344950258731842 -0.3709101676940918 -0.026633242145180702" size="0.10819727182388306 0.06406967341899872 0.012450749054551125" quat="1.0 0.0 0.0 0.0"/>
          <geom class="collision" type="box" pos="-0.2095235139131546 -0.3115566074848175 0.21992382407188416" size="0.02860577218234539 0.014527716673910618 0.03002556413412094" quat="1.0 0.0 0.0 0.0"/>
          <geom class="collision" type="box" pos="-0.23664847016334534 -0.23723644018173218 0.2317027449607849" size="0.14483046531677246 0.0038390583358705044 0.0443267822265625" quat="1.0 0.0 0.0 0.0"/>
          <geom class="collision" type="box" pos="-0.23664847016334534 -0.25695809721946716 0.1932295262813568" size="0.14483046531677246 0.016660405322909355 0.005856577306985855" quat="1.0 0.0 0.0 0.0"/>
          <geom class="collision" type="box" pos="-0.37607118487358093 -0.2550935447216034 0.23429983854293823" size="0.005407749209553003 0.021083654835820198 0.046924151480197906" quat="1.0 0.0 0.0 0.0"/>
          <geom class="collision" type="box" pos="-0.09749902784824371 -0.2550935447216034 0.23429983854293823" size="0.005407749209553003 0.021083654835820198 0.04692428559064865" quat="1.0 0.0 0.0 0.0"/>
        </body>
        <body name="fridge_right_door">
          <joint axis="0.0 0.0 1.0" pos="0.41050735116004944 -0.3474642038345337 0.3784147799015045" limited="true" name="fridge_right_door_joint" range="0.0 1.5707963267948966" type="hinge" damping="1" frictionloss="1" armature=".01" stiffness="0.05"/>
          <geom mesh="fridge_right_door_vis" type="mesh" solimp="0.998 0.998 0.001" solref="0.001 1" friction="0.95 0.3 0.1" class="visual" material="fridge_right_door_material"/>
          <geom class="collision" type="box" pos="0.23141421377658844 -0.30522629618644714 0.25686919689178467" size="0.15337137877941132 0.001518690842203796 0.037437066435813904" quat="1.0 0.0 0.0 0.0"/>
          <geom class="collision" type="box" pos="0.23141421377658844 -0.20369039475917816 0.25157129764556885" size="0.14881138503551483 0.001518699456937611 0.03213917091488838" quat="1.0 0.0 0.0 0.0"/>
          <geom class="collision" type="box" pos="0.08318133652210236 -0.25338324904441833 0.2540512681007385" size="0.0035103464033454657 0.053215499967336655 0.034619156271219254" quat="1.0 0.0 0.0 0.0"/>
          <geom class="collision" type="box" pos="0.38055282831192017 -0.25338324904441833 0.2540512681007385" size="0.0035103464033454657 0.05321575328707695 0.034619156271219254" quat="1.0 0.0 0.0 0.0"/>
          <geom class="collision" type="box" pos="0.23141421377658844 -0.30522629618644714 0.5099889039993286" size="0.15337137877941132 0.0015187225071713328 0.037437066435813904" quat="1.0 0.0 0.0 0.0"/>
          <geom class="collision" type="box" pos="0.23141421377658844 -0.20369039475917816 0.5046910047531128" size="0.14881138503551483 0.001518729724921286 0.03213917091488838" quat="1.0 0.0 0.0 0.0"/>
          <geom class="collision" type="box" pos="0.08318133652210236 -0.25338324904441833 0.5071709156036377" size="0.0035103464033454657 0.053216513246297836 0.034619156271219254" quat="1.0 0.0 0.0 0.0"/>
          <geom class="collision" type="box" pos="0.38055282831192017 -0.25338324904441833 0.5071709156036377" size="0.0035103464033454657 0.05321676656603813 0.034619156271219254" quat="1.0 0.0 0.0 0.0"/>
          <geom class="collision" type="box" pos="0.23141421377658844 -0.17485778033733368 0.8018209934234619" size="0.14881138503551483 0.0015187541721388698 0.03213917091488838" quat="1.0 0.0 0.0 0.0"/>
          <geom class="collision" type="box" pos="0.08312533795833588 -0.23516219854354858 0.8043009042739868" size="0.004710578825324774 0.06697990745306015 0.034619156271219254" quat="1.0 0.0 0.0 0.0"/>
          <geom class="collision" type="box" pos="0.38220059871673584 -0.23708322644233704 0.8043009042739868" size="0.0042063514702022076 0.06575009971857071 0.034619156271219254" quat="1.0 0.0 0.0 0.0"/>
          <geom class="collision" type="box" pos="0.08312533795833588 -0.2414541393518448 0.8673205375671387" size="0.004710578825324774 0.060688458383083344 0.034619156271219254" quat="1.0 0.0 0.0 0.0"/>
          <geom class="collision" type="box" pos="0.38215941190719604 -0.23516219854354858 0.8043009042739868" size="0.004710578825324774 0.06698066741228104 0.034619156271219254" quat="1.0 0.0 0.0 0.0"/>
          <geom class="collision" type="box" pos="0.38215941190719604 -0.2414541393518448 0.8673205375671387" size="0.004710578825324774 0.060688965022563934 0.034619156271219254" quat="1.0 0.0 0.0 0.0"/>
          <geom class="collision" type="box" pos="0.23264236748218536 -0.23411042988300323 0.7765291929244995" size="0.14480642974376678 0.06803295016288757 0.006220254581421614" quat="1.0 0.0 0.0 0.0"/>
          <geom class="collision" type="box" pos="0.23248694837093353 -0.25190040469169617 0.8969229459762573" size="0.14462853968143463 0.0502481646835804 0.003077739616855979" quat="1.0 0.0 0.0 0.0"/>
          <geom class="collision" type="box" pos="0.23248694837093353 -0.1919376254081726 0.8594681024551392" size="0.05016378313302994 0.0031052634585648775 0.14465102553367615" quat="0.6771653890609741 0.2035851776599884 0.6771655678749084 0.20358510315418243"/>
          <geom class="collision" type="box" pos="0.23233634233474731 -0.17049956321716309 0.7953920364379883" size="0.14462900161743164 0.0031011635437607765 0.025584066286683083" quat="1.0 0.0 0.0 0.0"/>
          <geom class="collision" type="box" pos="0.2233191877603531 -0.3516943156719208 0.37861859798431396" size="0.20651549100875854 0.03155607730150223 0.5957353115081787" quat="1.0 0.0 0.0 0.0" name="fridge_right_door_main"/>
          <geom class="collision" type="box" pos="0.04022764414548874 -0.4387055039405823 0.39825060963630676" size="0.020025629550218582 0.012182312086224556 0.20292851328849792" quat="1.0 0.0 0.0 0.0" name="fridge_right_door_handle_main"/>
          <geom class="collision" type="box" pos="0.0397980622947216 -0.4142951965332031 0.6992678642272949" size="0.15277734398841858 0.012184272520244122 0.020025623962283134" quat="0.7036940455436707 -0.06938757747411728 0.7036941051483154 -0.06938757747411728" name="fridge_right_door_handle_1"/>
          <geom class="collision" type="box" pos="0.04005524143576622 -0.4153255522251129 0.08840882033109665" size="0.15271838009357452 0.012182695791125298 0.020025666803121567" quat="0.705168604850769 0.05231887102127075 0.7051685452461243 0.05231887102127075" name="fridge_right_door_handle_2"/>
          <geom class="collision" type="box" pos="0.23107843101024628 -0.28338780999183655 0.9090375900268555" size="0.16718634963035583 0.03298664465546608 0.00502949021756649" quat="1.0 0.0 0.0 0.0"/>
          <geom class="collision" type="box" pos="0.23107843101024628 -0.2828749418258667 -0.12705786526203156" size="0.16718634963035583 0.03298664465546608 0.010212471708655357" quat="1.0 0.0 0.0 0.0"/>
          <geom class="collision" type="box" pos="0.07154716551303864 -0.2828749418258667 0.3933747708797455" size="0.007655085995793343 0.03298664465546608 0.5100640654563904" quat="1.0 0.0 0.0 0.0"/>
          <geom class="collision" type="box" pos="0.3910381495952606 -0.2828749418258667 0.3933747708797455" size="0.007655085995793343 0.03298664465546608 0.5100640654563904" quat="1.0 0.0 0.0 0.0"/>
          <body name="fridge_right_door_Clear">
            <geom mesh="fridge_right_door_Clear_vis" type="mesh" solimp="0.998 0.998 0.001" solref="0.001 1" friction="0.95 0.3 0.1" class="visual" material="fridge_right_door_Clear_material"/>
            <geom class="collision" type="box" pos="0.23141421377658844 -0.30522629618644714 0.25686919689178467" size="0.15337137877941132 0.001518690842203796 0.037437066435813904" quat="1.0 0.0 0.0 0.0"/>
            <geom class="collision" type="box" pos="0.23141421377658844 -0.20369039475917816 0.25157129764556885" size="0.14881138503551483 0.001518699456937611 0.03213917091488838" quat="1.0 0.0 0.0 0.0"/>
            <geom class="collision" type="box" pos="0.08318133652210236 -0.25338324904441833 0.2540512681007385" size="0.0035103464033454657 0.053215499967336655 0.034619156271219254" quat="1.0 0.0 0.0 0.0"/>
            <geom class="collision" type="box" pos="0.38055282831192017 -0.25338324904441833 0.2540512681007385" size="0.0035103464033454657 0.05321575328707695 0.034619156271219254" quat="1.0 0.0 0.0 0.0"/>
            <geom class="collision" type="box" pos="0.23141421377658844 -0.30522629618644714 0.5099889039993286" size="0.15337137877941132 0.0015187225071713328 0.037437066435813904" quat="1.0 0.0 0.0 0.0"/>
            <geom class="collision" type="box" pos="0.23141421377658844 -0.20369039475917816 0.5046910047531128" size="0.14881138503551483 0.001518729724921286 0.03213917091488838" quat="1.0 0.0 0.0 0.0"/>
            <geom class="collision" type="box" pos="0.08318133652210236 -0.25338324904441833 0.5071709156036377" size="0.0035103464033454657 0.053216513246297836 0.034619156271219254" quat="1.0 0.0 0.0 0.0"/>
            <geom class="collision" type="box" pos="0.38055282831192017 -0.25338324904441833 0.5071709156036377" size="0.0035103464033454657 0.05321676656603813 0.034619156271219254" quat="1.0 0.0 0.0 0.0"/>
            <geom class="collision" type="box" pos="0.23141421377658844 -0.17485778033733368 0.8018209934234619" size="0.14881138503551483 0.0015187541721388698 0.03213917091488838" quat="1.0 0.0 0.0 0.0"/>
            <geom class="collision" type="box" pos="0.08312533795833588 -0.23516219854354858 0.8043009042739868" size="0.004710578825324774 0.06697990745306015 0.034619156271219254" quat="1.0 0.0 0.0 0.0"/>
            <geom class="collision" type="box" pos="0.38220059871673584 -0.23708322644233704 0.8043009042739868" size="0.0042063514702022076 0.06575009971857071 0.034619156271219254" quat="1.0 0.0 0.0 0.0"/>
            <geom class="collision" type="box" pos="0.08312533795833588 -0.2414541393518448 0.8673205375671387" size="0.004710578825324774 0.060688458383083344 0.034619156271219254" quat="1.0 0.0 0.0 0.0"/>
            <geom class="collision" type="box" pos="0.38215941190719604 -0.23516219854354858 0.8043009042739868" size="0.004710578825324774 0.06698066741228104 0.034619156271219254" quat="1.0 0.0 0.0 0.0"/>
            <geom class="collision" type="box" pos="0.38215941190719604 -0.2414541393518448 0.8673205375671387" size="0.004710578825324774 0.060688965022563934 0.034619156271219254" quat="1.0 0.0 0.0 0.0"/>
            <geom class="collision" type="box" pos="0.23264236748218536 -0.23411042988300323 0.7765291929244995" size="0.14480642974376678 0.06803295016288757 0.006220254581421614" quat="1.0 0.0 0.0 0.0"/>
            <geom class="collision" type="box" pos="0.23248694837093353 -0.25190040469169617 0.8969229459762573" size="0.14462853968143463 0.0502481646835804 0.003077739616855979" quat="1.0 0.0 0.0 0.0"/>
            <geom class="collision" type="box" pos="0.23248694837093353 -0.1919376254081726 0.8594681024551392" size="0.05016378313302994 0.0031052634585648775 0.14465102553367615" quat="0.6771653890609741 0.2035851776599884 0.6771655678749084 0.20358510315418243"/>
            <geom class="collision" type="box" pos="0.23233634233474731 -0.17049956321716309 0.7953920364379883" size="0.14462900161743164 0.0031011635437607765 0.025584066286683083" quat="1.0 0.0 0.0 0.0"/>
          </body>
        </body>
        <body name="Body001_Clear">
          <geom mesh="Body001_Clear_vis" type="mesh" solimp="0.998 0.998 0.001" solref="0.001 1" friction="0.95 0.3 0.1" class="visual" material="Body001_Clear_material"/>
          <geom class="collision" type="box" pos="0.0006654927274212241 0.05615266412496567 0.5888007879257202" size="0.40937232971191406 0.19231247901916504 0.005514178425073624" quat="1.0 0.0 0.0 0.0"/>
          <geom class="collision" type="box" pos="0.0006654927274212241 0.05615266412496567 0.20450350642204285" size="0.40937232971191406 0.19231247901916504 0.005514178425073624" quat="1.0 0.0 0.0 0.0"/>
        </body>
        <geom class="region" name="reg_fridge_shelf0" type="box" pos="-0.00019602477550506592 0.05837142467498779 0.39673303067684174" size="0.38571172749996185 0.18862744963169098 0.18221738731861115"/>
        <geom class="region" name="reg_fridge_shelf1" type="box" pos="0.0012401789426803589 0.05837142467498779 0.7527535259723663" size="0.40360373055934906 0.18862744963169098 0.1537470052242279"/>
        <geom class="region" name="reg_main" type="box" pos="-7.450580596923828e-09 0.03246614336967468 0.0" size="0.45844162797927857 0.42316944694519043 0.9753539094924927"/>
      </body>
    </body>
  </worldbody>
  <actuator>
    <motor name="freezer0_door_joint_actuator" joint="freezer0_door_joint" gear="50"/>
    <motor name="freezer1_door_joint_actuator" joint="freezer1_door_joint" gear="50"/>
    <motor name="fridge_drawer0_joint_actuator" joint="fridge_drawer0_joint" gear="50"/>
    <motor name="fridge_left_door_joint_actuator" joint="fridge_left_door_joint" gear="50"/>
    <motor name="fridge_right_door_joint_actuator" joint="fridge_right_door_joint" gear="50"/>
  </actuator>
</mujoco>
