<?xml version='1.0' encoding='UTF-8'?>
<mujoco model="model">
  <option timestep="0.002" gravity="0.0 0.0 -9.81"/>
  <compiler angle="radian"/>
  <asset>
    <mesh file="visuals/handle.obj" name="handle_vis"/>
    <mesh file="visuals/Body001.obj" name="Body001_vis"/>
    <mesh file="visuals/Funnel001.obj" name="Funnel001_vis"/>
    <mesh file="visuals/spout.obj" name="spout_vis"/>
    <texture file="visuals/T_BC001.png" name="Body001_material" type="2d"/>
    <material name="Body001_material" rgba="1 1 1 1.0" texture="Body001_material" shininess=".05" specular="0.5"/>
    <texture file="visuals/T_BC001.png" name="handle_material" type="2d"/>
    <material name="handle_material" rgba="1 1 1 1.0" texture="handle_material" shininess="1" specular="1"/>
    <texture file="visuals/T_BC001.png" name="Funnel001_material" type="2d"/>
    <material name="Funnel001_material" rgba="1 1 1 1.0" texture="Funnel001_material" shininess="5" specular="5"/>
    <texture file="visuals/T_BC001.png" name="spout_material" type="2d"/>
    <material name="spout_material" rgba="1 1 1 1.0" texture="spout_material" shininess="1" specular="1"/>
  </asset>
  <default>
    <default class="visual">
      <geom conaffinity="0" contype="0" group="1" type="mesh"/>
    </default>
    <default class="collision">
      <geom group="0" rgba="0.5 0 0 0.5"/>
    </default>
    <default class="spawn">
      <geom group="0" rgba="1 1 1 0.5" contype="0" conaffinity="0"/>
      <site group="0" rgba="1 1 1 0.5"/>
    </default>
    <default class="region">
      <geom group="1" conaffinity="0" contype="0" rgba="0 1 0 0"/>
    </default>
  </default>
  <worldbody>
    <body>
      <body name="object">
        <geom mesh="Body001_vis" type="mesh" solimp="0.998 0.998 0.001" solref="0.001 1" friction="0.95 0.3 0.1" class="visual" material="Body001_material"/>
        <geom class="collision" type="box" pos="0.3659437298774719 -0.045784320682287216 -0.2152286320924759" size="0.020667994394898415 0.1631319373846054 0.13056601583957672" quat="7.549790126404332e-08 1.0 0.0 0.0"/>
        <geom class="collision" type="box" pos="-7.401220500469208e-06 -0.23192250728607178 -0.21515221893787384" size="0.3867374658584595 0.02325321175158024 0.1306402087211609" quat="7.549790126404332e-08 1.0 0.0 0.0"/>
        <geom class="collision" type="box" pos="-0.0001415652222931385 0.18975692987442017 -0.22068609297275543" size="0.38660332560539246 0.06541886925697327 0.1251053363084793" quat="7.549790126404332e-08 1.0 0.0 0.0"/>
        <geom class="collision" type="box" pos="0.1922358274459839 -0.04122324287891388 -0.29634279012680054" size="0.14259092509746552 0.15329819917678833 0.001300971838645637" quat="7.549790126404332e-08 1.0 0.0 0.0"/>
        <geom class="collision" type="box" pos="-0.1997900903224945 -0.04122324287891388 -0.29633498191833496" size="0.14259092509746552 0.15329819917678833 0.0013088188134133816" quat="7.549790126404332e-08 1.0 0.0 0.0"/>
        <geom class="collision" type="box" pos="-0.0033979848958551884 -0.12159993499517441 -0.2963346838951111" size="0.05315235257148743 0.07167477905750275 0.001309097744524479" quat="7.549790126404332e-08 1.0 0.0 0.0"/>
        <geom class="collision" type="box" pos="-0.0033979848958551884 0.08844104409217834 -0.2961500287055969" size="0.05315235257148743 0.02131601981818676 0.00149372941814363" quat="7.549790126404332e-08 1.0 0.0 0.0"/>
        <geom class="collision" type="box" pos="-0.0037646014243364334 0.00151534890756011 -0.3488848805427551" size="0.3874240517616272 0.25513944029808044 0.001757606165483594" quat="7.549790126404332e-08 1.0 0.0 0.0"/>
        <geom class="collision" type="cylinder" pos="-0.0020324583165347576 0.20041361451148987 -0.07855933159589767" size="0.027052659541368484 0.01135980524122715" quat="7.549790126404332e-08 1.0 0.0 0.0"/>
        <geom class="collision" type="cylinder" pos="-0.0020324583165347576 0.2000289261341095 0.018618857488036156" size="0.018673621118068695 0.08345291018486023" quat="7.549790126404332e-08 1.0 0.0 0.0"/>
        <geom class="collision" type="cylinder" pos="0.029449384659528732 0.20142251253128052 -0.031200909987092018" size="0.018711162731051445 0.011754904873669147" quat="1.3767879636361613e-07 0.70710688829422 -1.3767875373105198e-07 0.7071066498756409"/>
        <geom class="collision" type="box" pos="-0.36740797758102417 -0.047580596059560776 -0.21550484001636505" size="0.01933678425848484 0.16192060708999634 0.130289226770401" quat="7.549790126404332e-08 1.0 0.0 0.0"/>
        <body name="handle">
          <joint axis="1.0 0.0 0.0" pos="0.061209846287965775 0.20164522528648376 -0.031078986823558807" limited="true" name="handle_temp_joint" type="hinge" range="-0.7853981633974483 0.7853981633974483" damping="1" frictionloss="1" armature=".01" stiffness="0.05"/>
          <joint axis="0.0 1.0 0.0" pos="0.061209846287965775 0.20164522528648376 -0.031078986823558807" limited="true" name="handle_joint" type="hinge" range="0 0.5" damping="1" frictionloss="1" armature=".01" stiffness="0.05"/>
          <geom mesh="handle_vis" type="mesh" solimp="0.998 0.998 0.001" solref="0.001 1" friction="0.95 0.3 0.1" class="visual" material="handle_material"/>
          <geom class="collision" type="cylinder" pos="0.07241512835025787 0.20142251253128052 -0.031200909987092018" size="0.018711162731051445 0.008169170469045639" quat="1.3767879636361613e-07 0.70710688829422 -1.3767875373105198e-07 0.7071066498756409"/>
          <geom class="collision" type="cylinder" pos="0.06925530731678009 0.20142251253128052 0.017891744151711464" size="0.004444473888725042 0.031614042818546295" quat="7.549792968575275e-08 1.9470718370939721e-07 -1.6292069915380125e-07 1.0"/>
        </body>
        <body name="Funnel001">
          <joint axis="0.0 0.0 1.0" pos="8.225912461057305e-05 0.015119235962629318 -0.2924407720565796" limited="true" name="Funnel001_joint" range="0.0 0.15" type="slide" damping="0" frictionloss="0" armature="0" stiffness="0"/>
          <geom mesh="Funnel001_vis" type="mesh" solimp="0.998 0.998 0.001" solref="0.001 1" friction="0.95 0.3 0.1" class="visual" material="Funnel001_material"/>
          <geom class="collision" type="cylinder" pos="-0.001333288848400116 0.015713248401880264 -0.2985572814941406" size="0.041678279638290405 0.00451189000159502" quat="7.549790126404332e-08 1.0 0.0 0.0"/>
          <geom class="collision" type="cylinder" pos="-7.641974661964923e-06 0.015157032757997513 -0.2878127694129944" size="0.005436237435787916 0.005571270361542702" quat="7.549790126404332e-08 1.0 0.0 0.0"/>
        </body>
        <body name="spout">
          <joint axis="0.0 0.0 1.0" pos="-0.001766621950082481 0.20071300864219666 0.12077276408672333" limited="true" name="spout_joint" range="-1.0471975511965976 1.0471975511965976" type="hinge" damping="1" frictionloss="1" armature=".01" stiffness="0.05"/>
          <site type="cylinder" rgba="0.5 0.75 1 0.5" size="0.008671263232827187 0.21570436656475067" pos="-0.007581573911011219 -0.08707257360219955 -0.0869072824716568" name="water"/>
          <geom mesh="spout_vis" type="mesh" solimp="0.998 0.998 0.001" solref="0.001 1" friction="0.95 0.3 0.1" class="visual" material="spout_material"/>
          <geom class="collision" type="cylinder" pos="-0.0029121674597263336 0.20041361451148987 0.1425645649433136" size="0.014769676141440868 0.03290451318025589" quat="7.549790126404332e-08 1.0 0.0 0.0"/>
          <geom class="collision" type="cylinder" pos="-0.003160582622513175 0.1962512880563736 0.20318324863910675" size="0.014407367445528507 0.031245440244674683" quat="0.08006643503904343 -0.9967895150184631 4.419963493088107e-25 -1.7778314972916406e-17"/>
          <geom class="collision" type="cylinder" pos="-0.003998042084276676 0.1784127652645111 0.2602664828300476" size="0.014407367445528507 0.031245442107319832" quat="0.2368866354227066 -0.9715372920036316 -4.249221748508779e-24 -5.2599402683177265e-17"/>
          <geom class="collision" type="cylinder" pos="-0.004012579098343849 0.14290089905261993 0.30610156059265137" size="0.014407367445528507 0.031245442107319832" quat="0.396618515253067 -0.9179835319519043 -2.5472146657909133e-23 -8.806699490787487e-17"/>
          <geom class="collision" type="cylinder" pos="-0.004784042481333017 0.09500117599964142 0.33376777172088623" size="0.014407367445528507 0.031245442107319832" quat="0.5982699990272522 -0.8012945652008057 -1.6289830964685523e-23 -1.3284262557250508e-16"/>
          <geom class="collision" type="cylinder" pos="-0.004784042481333017 0.04008166491985321 0.3370712399482727" size="0.014407367445528507 0.031245442107319832" quat="0.7701568007469177 -0.6378546357154846 -4.144347029894624e-23 -1.710091625521754e-16"/>
          <geom class="collision" type="cylinder" pos="-0.004784042481333017 -0.01607663184404373 0.3184894323348999" size="0.014407367445528507 0.031245442107319832" quat="0.8541174530982971 -0.5200801491737366 -1.0566246722549945e-23 -1.8965213272811594e-16"/>
          <geom class="collision" type="cylinder" pos="-0.004784042481333017 -0.057369496673345566 0.28049999475479126" size="0.014407367445528507 0.031245442107319832" quat="0.9544209837913513 -0.29846376180648804 -2.687483443297891e-23 -2.1192403027811031e-16" name="spout_main"/>
          <geom class="collision" type="cylinder" pos="-0.004784042481333017 -0.08214521408081055 0.22847096621990204" size="0.014407367445528507 0.031245442107319832" quat="0.9939773082733154 -0.10958591848611832 -5.337752846708524e-23 -2.2070735165955358e-16"/>
          <geom class="collision" type="cylinder" pos="-0.004784042481333017 -0.08873169124126434 0.16193772852420807" size="0.016685059294104576 0.034328892827034" quat="0.999932587146759 0.011608731001615524 -5.0782094047373963e-23 -2.2203099945831604e-16"/>
        </body>
        <geom class="region" name="reg_basin" type="box" pos="0.00014956295490264893 -0.044332943856716156 -0.18819940835237503" size="0.3260722438097 0.15081403201818466 0.09863660281896591"/>
        <geom class="region" name="reg_main" type="box" pos="0.0 0.0 -0.21757721900939941" size="0.3877448568344116 0.25617570972442627 0.13406522369384766"/>
      </body>
    </body>
  </worldbody>
  <actuator>
    <motor name="handle_joint_actuator" joint="handle_joint" gear="10"/>
    <motor name="handle_temp_joint_actuator" joint="handle_temp_joint" gear="10"/>
    <motor name="Funnel001_joint_actuator" joint="Funnel001_joint" gear="10"/>
    <motor name="spout_joint_actuator" joint="spout_joint" gear="10"/>
  </actuator>
</mujoco>
