<?xml version='1.0' encoding='UTF-8'?>
<mujoco model="model">
  <option timestep="0.002" gravity="0.0 0.0 -9.81"/>
  <compiler angle="radian"/>
  <asset>
    <mesh file="visuals/freezer0.obj" name="freezer0_vis"/>
    <mesh file="visuals/fridge_drawer0.obj" name="fridge_drawer0_vis"/>
    <mesh file="visuals/fridge_left_door.obj" name="fridge_left_door_vis"/>
    <mesh file="visuals/fridge_left_door_Clear.obj" name="fridge_left_door_Clear_vis"/>
    <mesh file="visuals/fridge_right_door.obj" name="fridge_right_door_vis"/>
    <mesh file="visuals/fridge_right_door_Clear.obj" name="fridge_right_door_Clear_vis"/>
    <mesh file="visuals/Body001.obj" name="Body001_vis"/>
    <mesh file="visuals/Body001_Clear.obj" name="Body001_Clear_vis"/>
    <texture file="visuals/T_BC001.png" name="Body001_material" type="2d"/>
    <material name="Body001_material" rgba="1 1 1 1.0" texture="Body001_material" shininess="0.5651465654373169" specular="2"/>
    <texture file="visuals/T_BC001.png" name="freezer0_material" type="2d"/>
    <material name="freezer0_material" rgba="1 1 1 1.0" texture="freezer0_material" shininess="0.5651465654373169" specular="2"/>
    <texture file="visuals/T_BC001.png" name="fridge_drawer0_material" type="2d"/>
    <material name="fridge_drawer0_material" rgba="1 1 1 1.0" texture="fridge_drawer0_material" shininess="0.5651465654373169" specular="0.3103448502657381"/>
    <texture file="visuals/T_BC001.png" name="fridge_left_door_material" type="2d"/>
    <material name="fridge_left_door_material" rgba="1 1 1 1.0" texture="fridge_left_door_material" shininess="0.5651465654373169" specular="2"/>
    <texture file="visuals/T_BC001.png" name="fridge_left_door_Clear_material" type="2d"/>
    <material name="fridge_left_door_Clear_material" rgba="1 1 1 0.7185935378074646" texture="fridge_left_door_Clear_material" shininess="0.5" specular="0.3103448502657381"/>
    <texture file="visuals/T_BC001.png" name="fridge_right_door_material" type="2d"/>
    <material name="fridge_right_door_material" rgba="1 1 1 1.0" texture="fridge_right_door_material" shininess="0.5651465654373169" specular="2"/>
    <texture file="visuals/T_BC001.png" name="fridge_right_door_Clear_material" type="2d"/>
    <material name="fridge_right_door_Clear_material" rgba="1 1 1 0.7185935378074646" texture="fridge_right_door_Clear_material" shininess="0.5" specular="0.3103448502657381"/>
    <texture file="visuals/T_BC001.png" name="Body001_Clear_material" type="2d"/>
    <material name="Body001_Clear_material" rgba="1 1 1 0.7185935378074646" texture="Body001_Clear_material" shininess="0.5" specular="0.3103448502657381"/>
  </asset>
  <default>
    <default class="visual">
      <geom conaffinity="0" contype="0" group="1" type="mesh"/>
    </default>
    <default class="collision">
      <geom group="0" rgba="0.5 0 0 0.5"/>
    </default>
    <default class="spawn">
      <geom group="0" rgba="1 1 1 0.5" contype="0" conaffinity="0"/>
      <site group="0" rgba="1 1 1 0.5"/>
    </default>
    <default class="region">
      <geom group="1" conaffinity="0" contype="0" rgba="0 1 0 0"/>
    </default>
  </default>
  <worldbody>
    <body>
      <body name="object">
        <geom mesh="Body001_vis" type="mesh" solimp="0.998 0.998 0.001" solref="0.001 1" friction="0.95 0.3 0.1" class="visual" material="Body001_material"/>
        <geom class="collision" type="box" pos="-0.39227133989334106 0.05474406108260155 -0.0004710908397100866" size="0.022729117423295975 0.3394109904766083 0.950001060962677" quat="1.0 0.0 0.0 0.0"/>
        <geom class="collision" type="box" pos="0.3911631107330322 0.05474404990673065 -0.0004710908397100866" size="0.023837359622120857 0.3394109904766083 0.950001060962677" quat="1.0 0.0 0.0 0.0"/>
        <geom class="collision" type="box" pos="1.280568540096283e-08 0.05474915727972984 -0.20703259110450745" size="0.415000319480896 0.3394036293029785 0.03042835369706154" quat="1.0 0.0 0.0 0.0"/>
        <geom class="collision" type="box" pos="1.3969838619232178e-08 0.05474656820297241 -0.9224189519882202" size="0.41500338912010193 0.33940625190734863 0.028052954003214836" quat="1.0 0.0 0.0 0.0"/>
        <geom class="collision" type="box" pos="1.3969838619232178e-08 0.05474652349948883 0.9286476373672485" size="0.41500332951545715 0.3394063115119934 0.02088218554854393" quat="1.0 0.0 0.0 0.0"/>
        <geom class="collision" type="box" pos="-2.2584572434425354e-08 0.2999446392059326 -0.0004710378125309944" size="0.4149978458881378 0.09421038627624512 0.9500010013580322" quat="1.0 0.0 0.0 0.0"/>
        <geom class="collision" type="box" pos="1.907348590179936e-08 -0.011328396387398243 0.5301669836044312" size="0.3689470589160919 0.1993916630744934 0.00500008137896657" quat="1.0 0.0 0.0 0.0"/>
        <geom class="collision" type="box" pos="1.907348590179936e-08 -0.011328366585075855 0.1502426266670227" size="0.3689470589160919 0.1993916630744934 0.00500008137896657" quat="1.0 0.0 0.0 0.0"/>
        <geom class="collision" type="box" pos="0.35758131742477417 -0.04185579717159271 -0.7834590673446655" size="0.01360534131526947 0.2527852952480316 0.008317296393215656" quat="1.0 0.0 0.0 0.0"/>
        <geom class="collision" type="box" pos="-0.3576083779335022 -0.04185579717159271 -0.7834590673446655" size="0.01360534131526947 0.2527852952480316 0.008317297324538231" quat="1.0 0.0 0.0 0.0"/>
        <body name="freezer0">
          <geom class="region" name="reg_freezer0" type="box" pos="-0.00047992169857025146 -0.05982649326324463 -0.5627147853374481" size="0.3359756747484207 0.24532584643363953 0.1957723925113678"/>
          <joint axis="0.0 -1.0 0.0" pos="-0.0012154579162597656 -0.09398239850997925 -0.5798619985580444" limited="true" name="freezer0_door_joint" range="0.0 0.4" type="slide" damping="1" frictionloss="1" armature=".01" stiffness="0.05"/>
          <geom mesh="freezer0_vis" type="mesh" solimp="0.998 0.998 0.001" solref="0.001 1" friction="0.95 0.3 0.1" class="visual" material="freezer0_material"/>
          <geom class="collision" type="box" pos="-0.0008891969919204712 -0.32981547713279724 -0.5935872793197632" size="0.4141390919685364 0.019321383908391 0.3568846583366394" quat="1.0 0.0 0.0 0.0" name="freezer0_door_main"/>
          <geom class="collision" type="box" pos="-0.001215711236000061 -0.32507675886154175 -0.224431112408638" size="0.409322589635849 0.009542668238282204 0.0153754698112607" quat="1.0 0.0 0.0 0.0"/>
          <geom class="collision" type="box" pos="-0.0012157055316492915 -0.3390405774116516 -0.2314324975013733" size="0.409322589635849 0.006139228120446205 0.008009843528270721" quat="1.0 0.0 0.0 0.0"/>
          <geom class="collision" type="box" pos="-0.0012156275333836675 -0.333525687456131 -0.23534998297691345" size="0.40932416915893555 0.0005191449890844524 0.004614440258592367" quat="1.0 0.0 0.0 0.0"/>
          <geom class="collision" type="box" pos="0.0009714923799037933 -0.3698027729988098 -0.2932438850402832" size="0.33625397086143494 0.009555828757584095 0.005156020168215036" quat="1.0 0.0 0.0 0.0" name="freezer0_door_handle_1"/>
          <geom class="collision" type="box" pos="0.0009714514017105103 -0.38610073924064636 -0.29762113094329834" size="0.33625471591949463 0.006859722081571817 0.008949918672442436" quat="1.0 0.0 0.0 0.0" name="freezer0_door_handle_main"/>
          <geom class="collision" type="box" pos="0.0009714625775814056 -0.35022643208503723 -0.3054441809654236" size="0.33625471591949463 0.010662556625902653 0.01717992126941681" quat="1.0 0.0 0.0 0.0" name="freezer0_door_handle_2"/>
          <geom class="collision" type="box" pos="0.0024366192519664764 0.20238611102104187 -0.5663059949874878" size="0.3459130525588989 0.0033920349087566137 0.20452946424484253" quat="1.0 0.0 0.0 0.0"/>
          <geom class="collision" type="box" pos="-0.3462103009223938 -0.061954278498888016 -0.5663059949874878" size="0.004088173154741526 0.26058658957481384 0.20452925562858582" quat="1.0 0.0 0.0 0.0"/>
          <geom class="collision" type="box" pos="0.34475740790367126 -0.061954278498888016 -0.5663059949874878" size="0.0037448182702064514 0.2605862021446228 0.20452894270420074" quat="1.0 0.0 0.0 0.0"/>
          <geom class="collision" type="box" pos="-0.0009996322914958 -0.06195427104830742 -0.7673805952072144" size="0.3459119200706482 0.26058581471443176 0.003200327744707465" quat="1.0 0.0 0.0 0.0"/>
        </body>
        <body name="fridge_drawer0">
          <geom class="region" name="reg_fridge_drawer0" type="box" pos="-0.00048075616359710693 -0.01052907109260559 -0.019546829164028168" size="0.33597650921344757 0.18407726085186005 0.12966052240133286"/>
          <joint axis="0.0 -1.0 0.0" pos="-0.001167207956314087 -0.02784685418009758 -0.01833232492208481" limited="true" name="fridge_drawer0_joint" range="0.0 0.4" type="slide" damping="1" frictionloss="1" armature=".01" stiffness="0.05"/>
          <geom mesh="fridge_drawer0_vis" type="mesh" solimp="0.998 0.998 0.001" solref="0.001 1" friction="0.95 0.3 0.1" class="visual" material="fridge_drawer0_material"/>
          <geom class="collision" type="box" pos="0.20843300223350525 -0.21116550266742706 -0.016208797693252563" size="0.14094378054141998 0.010428237728774548 0.15302202105522156" quat="1.0 0.0 0.0 0.0"/>
          <geom class="collision" type="box" pos="-0.004416878800839186 -0.21116550266742706 0.03877970948815346" size="0.07190641760826111 0.010428213514387608 0.09803342074155807" quat="1.0 0.0 0.0 0.0"/>
          <geom class="collision" type="box" pos="-0.004416878800839186 -0.21116550266742706 -0.11041654646396637" size="0.0719064250588417 0.010428208857774734 0.05860121548175812" quat="1.0 0.0 0.0 0.0"/>
          <geom class="collision" type="box" pos="-0.21222737431526184 -0.21116550266742706 -0.016208797693252563" size="0.13590455055236816 0.01042824238538742 0.15302208065986633" quat="1.0 0.0 0.0 0.0"/>
          <geom class="collision" type="box" pos="-0.004416897892951965 -0.2110261768102646 -0.015276762656867504" size="0.07190626859664917 0.005427331663668156 0.033017951995134354" quat="0.9871617555618286 -0.15972371399402618 0.0 0.0"/>
          <geom class="collision" type="box" pos="-0.0009996322914958 -0.009495828300714493 -0.15835800766944885" size="0.3459117114543915 0.19932322204113007 0.0032003202941268682" quat="1.0 0.0 0.0 0.0"/>
          <geom class="collision" type="box" pos="0.34475740790367126 -0.009495824575424194 -0.023135758936405182" size="0.0037448136135935783 0.19932356476783752 0.1386764943599701" quat="1.0 0.0 0.0 0.0"/>
          <geom class="collision" type="box" pos="-0.3462103009223938 -0.009495824575424194 -0.023135758936405182" size="0.004088167566806078 0.1993238478899002 0.13867676258087158" quat="1.0 0.0 0.0 0.0"/>
          <geom class="collision" type="box" pos="-0.004416897892951965 -0.2025282233953476 -0.016591282561421394" size="0.07190626859664917 0.0022927967365831137 0.033525124192237854" quat="1.0 0.0 0.0 0.0"/>
          <geom class="collision" type="box" pos="0.0024366192519664764 0.193582221865654 -0.023135755211114883" size="0.3459126055240631 0.0033920290879905224 0.1386769562959671" quat="1.0 0.0 0.0 0.0"/>
          <geom class="collision" type="box" pos="-0.0009487569332122803 -0.24762417376041412 0.11647733300924301" size="0.34894639253616333 0.005588192492723465 0.0061883386224508286" quat="1.0 0.0 0.0 0.0"/>
          <geom class="collision" type="box" pos="-0.0009487569332122803 -0.23418964445590973 0.12933951616287231" size="0.34894639253616333 0.01889035291969776 0.0072239357978105545" quat="1.0 0.0 0.0 0.0"/>
        </body>
        <body name="fridge_left_door">
          <joint axis="0.0 0.0 -1.0" pos="-0.3918018043041229 -0.3276289999485016 0.345002681016922" limited="true" name="fridge_left_door_joint" range="0.0 1.5707963267948966" type="hinge" damping="1" frictionloss="1" armature=".01" stiffness="0.05"/>
          <geom mesh="fridge_left_door_vis" type="mesh" solimp="0.998 0.998 0.001" solref="0.001 1" friction="0.95 0.3 0.1" class="visual" material="fridge_left_door_material"/>
          <geom class="collision" type="box" pos="-0.20516915619373322 -0.2345476895570755 0.7477937936782837" size="0.14340534806251526 0.002978686476126313 0.04913042113184929" quat="1.0 0.0 0.0 0.0"/>
          <geom class="collision" type="box" pos="-0.20516915619373322 -0.272113174200058 0.6978591680526733" size="0.14340530335903168 0.04048322141170502 0.0018282029777765274" quat="1.0 0.0 0.0 0.0"/>
          <geom class="collision" type="box" pos="-0.06690992414951324 -0.272113174200058 0.7471681833267212" size="0.0023787938989698887 0.04048225283622742 0.04967685416340828" quat="1.0 0.0 0.0 0.0"/>
          <geom class="collision" type="box" pos="-0.3497503995895386 -0.272113174200058 0.7471681833267212" size="0.0023787938989698887 0.04048225283622742 0.04967685416340828" quat="1.0 0.0 0.0 0.0"/>
          <geom class="collision" type="box" pos="-0.20516915619373322 -0.30993375182151794 0.7477937936782837" size="0.14340534806251526 0.0029786808881908655 0.04913032799959183" quat="1.0 0.0 0.0 0.0"/>
          <geom class="collision" type="box" pos="-0.20516915619373322 -0.2359030693769455 0.5688835382461548" size="0.14340534806251526 0.0029786790255457163 0.04913030564785004" quat="1.0 0.0 0.0 0.0"/>
          <geom class="collision" type="box" pos="-0.20516915619373322 -0.273468554019928 0.518949031829834" size="0.14340530335903168 0.040483150631189346 0.001828206004574895" quat="1.0 0.0 0.0 0.0"/>
          <geom class="collision" type="box" pos="-0.06690992414951324 -0.273468554019928 0.5682579278945923" size="0.0023787938989698887 0.04048225283622742 0.04967685416340828" quat="1.0 0.0 0.0 0.0"/>
          <geom class="collision" type="box" pos="-0.3497503995895386 -0.273468554019928 0.5682579278945923" size="0.0023787938989698887 0.04048225283622742 0.04967685416340828" quat="1.0 0.0 0.0 0.0"/>
          <geom class="collision" type="box" pos="-0.20516915619373322 -0.31128913164138794 0.5688835382461548" size="0.14340534806251526 0.0029786734376102686 0.049130212515592575" quat="1.0 0.0 0.0 0.0"/>
          <geom class="collision" type="box" pos="-0.2051691710948944 -0.33751267194747925 0.38122427463531494" size="0.19552117586135864 0.01162412203848362 0.5683032870292664" quat="1.0 0.0 0.0 0.0" name="fridge_left_door_main"/>
          <geom class="collision" type="box" pos="-0.05077379569411278 -0.35022643208503723 0.18183356523513794" size="0.01717997156083584 0.010662556625902653 0.2320089340209961" quat="1.0 0.0 0.0 0.0" name="fridge_left_door_handle_1"/>
          <geom class="collision" type="box" pos="-0.04295074939727783 -0.38610073924064636 0.18183359503746033" size="0.00894989725202322 0.006859723012894392 0.23200887441635132" quat="1.0 0.0 0.0 0.0" name="fridge_left_door_handle_main"/>
          <geom class="collision" type="box" pos="-0.03857354819774628 -0.3698027729988098 0.18183358013629913" size="0.005156084895133972 0.009555828757584095 0.2320074588060379" quat="1.0 0.0 0.0 0.0" name="fridge_left_door_handle_2"/>
          <geom class="collision" type="box" pos="-0.2051691710948944 -0.3229532241821289 0.38122427463531494" size="0.19552117586135864 0.01162412203848362 0.5683032870292664" quat="1.0 0.0 0.0 0.0"/>
          <body name="fridge_left_door_Clear">
            <geom mesh="fridge_left_door_Clear_vis" type="mesh" solimp="0.998 0.998 0.001" solref="0.001 1" friction="0.95 0.3 0.1" class="visual" material="fridge_left_door_Clear_material"/>
            <geom class="collision" type="box" pos="-0.20516915619373322 -0.2345476895570755 0.7477937936782837" size="0.14340534806251526 0.002978686476126313 0.04913042113184929" quat="1.0 0.0 0.0 0.0"/>
            <geom class="collision" type="box" pos="-0.20516915619373322 -0.272113174200058 0.6978591680526733" size="0.14340530335903168 0.04048322141170502 0.0018282029777765274" quat="1.0 0.0 0.0 0.0"/>
            <geom class="collision" type="box" pos="-0.06690992414951324 -0.272113174200058 0.7471681833267212" size="0.0023787938989698887 0.04048225283622742 0.04967685416340828" quat="1.0 0.0 0.0 0.0"/>
            <geom class="collision" type="box" pos="-0.3497503995895386 -0.272113174200058 0.7471681833267212" size="0.0023787938989698887 0.04048225283622742 0.04967685416340828" quat="1.0 0.0 0.0 0.0"/>
            <geom class="collision" type="box" pos="-0.20516915619373322 -0.30993375182151794 0.7477937936782837" size="0.14340534806251526 0.0029786808881908655 0.04913032799959183" quat="1.0 0.0 0.0 0.0"/>
            <geom class="collision" type="box" pos="-0.20516915619373322 -0.2359030693769455 0.5688835382461548" size="0.14340534806251526 0.0029786790255457163 0.04913030564785004" quat="1.0 0.0 0.0 0.0"/>
            <geom class="collision" type="box" pos="-0.20516915619373322 -0.273468554019928 0.518949031829834" size="0.14340530335903168 0.040483150631189346 0.001828206004574895" quat="1.0 0.0 0.0 0.0"/>
            <geom class="collision" type="box" pos="-0.06690992414951324 -0.273468554019928 0.5682579278945923" size="0.0023787938989698887 0.04048225283622742 0.04967685416340828" quat="1.0 0.0 0.0 0.0"/>
            <geom class="collision" type="box" pos="-0.3497503995895386 -0.273468554019928 0.5682579278945923" size="0.0023787938989698887 0.04048225283622742 0.04967685416340828" quat="1.0 0.0 0.0 0.0"/>
            <geom class="collision" type="box" pos="-0.20516915619373322 -0.31128913164138794 0.5688835382461548" size="0.14340534806251526 0.0029786734376102686 0.049130212515592575" quat="1.0 0.0 0.0 0.0"/>
          </body>
        </body>
        <body name="fridge_right_door">
          <joint axis="0.0 0.0 1.0" pos="0.3914358615875244 -0.328512966632843 0.3450026214122772" limited="true" name="fridge_right_door_joint" range="0.0 1.5707963267948966" type="hinge" damping="1" frictionloss="1" armature=".01" stiffness="0.05"/>
          <geom mesh="fridge_right_door_vis" type="mesh" solimp="0.998 0.998 0.001" solref="0.001 1" friction="0.95 0.3 0.1" class="visual" material="fridge_right_door_material"/>
          <geom class="collision" type="box" pos="0.20989829301834106 -0.2345476895570755 0.7477937936782837" size="0.14340534806251526 0.00297866971231997 0.049130164086818695" quat="1.0 0.0 0.0 0.0"/>
          <geom class="collision" type="box" pos="0.20989829301834106 -0.2721131443977356 0.6978591680526733" size="0.14340530335903168 0.04048306494951248 0.0018282096134498715" quat="1.0 0.0 0.0 0.0"/>
          <geom class="collision" type="box" pos="0.34815752506256104 -0.272113174200058 0.7471681833267212" size="0.0023787938989698887 0.04048225283622742 0.04967685416340828" quat="1.0 0.0 0.0 0.0"/>
          <geom class="collision" type="box" pos="0.0653170496225357 -0.272113174200058 0.7471681833267212" size="0.0023787938989698887 0.04048225283622742 0.04967685416340828" quat="1.0 0.0 0.0 0.0"/>
          <geom class="collision" type="box" pos="0.20989829301834106 -0.30993375182151794 0.7477937936782837" size="0.14340534806251526 0.0029786655213683844 0.049130070954561234" quat="1.0 0.0 0.0 0.0"/>
          <geom class="collision" type="box" pos="0.20989829301834106 -0.2359030693769455 0.5688835382461548" size="0.14340534806251526 0.002978663658723235 0.04913004860281944" quat="1.0 0.0 0.0 0.0"/>
          <geom class="collision" type="box" pos="0.20989829301834106 -0.273468554019928 0.518949031829834" size="0.14340530335903168 0.04048299789428711 0.001828212640248239" quat="1.0 0.0 0.0 0.0"/>
          <geom class="collision" type="box" pos="0.34815752506256104 -0.273468554019928 0.5682579278945923" size="0.0023787938989698887 0.04048225283622742 0.04967685416340828" quat="1.0 0.0 0.0 0.0"/>
          <geom class="collision" type="box" pos="0.0653170496225357 -0.273468554019928 0.5682579278945923" size="0.0023787938989698887 0.04048225283622742 0.04967685416340828" quat="1.0 0.0 0.0 0.0"/>
          <geom class="collision" type="box" pos="0.20989829301834106 -0.31128913164138794 0.5688835382461548" size="0.14340534806251526 0.0029786580707877874 0.04912995174527168" quat="1.0 0.0 0.0 0.0"/>
          <geom class="collision" type="box" pos="0.20989829301834106 -0.33751243352890015 0.3812237083911896" size="0.19552117586135864 0.011623946018517017 0.5683045387268066" quat="1.0 0.0 0.0 0.0" name="fridge_right_door_main"/>
          <geom class="collision" type="box" pos="0.0507730208337307 -0.35022637248039246 0.18183356523513794" size="0.01717989705502987 0.010662556625902653 0.2320088893175125" quat="1.0 0.0 0.0 0.0" name="fridge_right_door_handle_1"/>
          <geom class="collision" type="box" pos="0.04294997453689575 -0.3861006796360016 0.18183359503746033" size="0.008949832990765572 0.006859723012894392 0.23200887441635132" quat="1.0 0.0 0.0 0.0" name="fridge_right_door_handle_main"/>
          <geom class="collision" type="box" pos="0.0385727733373642 -0.36980271339416504 0.18183355033397675" size="0.0051560113206505775 0.009555828757584095 0.2320077121257782" quat="1.0 0.0 0.0 0.0" name="fridge_right_door_handle_2"/>
          <geom class="collision" type="box" pos="0.20989829301834106 -0.3229529857635498 0.3812237083911896" size="0.19552117586135864 0.011623946018517017 0.5683045387268066" quat="1.0 0.0 0.0 0.0"/>
          <body name="fridge_right_door_Clear">
            <geom mesh="fridge_right_door_Clear_vis" type="mesh" solimp="0.998 0.998 0.001" solref="0.001 1" friction="0.95 0.3 0.1" class="visual" material="fridge_right_door_Clear_material"/>
            <geom class="collision" type="box" pos="0.20989829301834106 -0.2345476895570755 0.7477937936782837" size="0.14340534806251526 0.00297866971231997 0.049130164086818695" quat="1.0 0.0 0.0 0.0"/>
            <geom class="collision" type="box" pos="0.20989829301834106 -0.2721131443977356 0.6978591680526733" size="0.14340530335903168 0.04048306494951248 0.0018282096134498715" quat="1.0 0.0 0.0 0.0"/>
            <geom class="collision" type="box" pos="0.34815752506256104 -0.272113174200058 0.7471681833267212" size="0.0023787938989698887 0.04048225283622742 0.04967685416340828" quat="1.0 0.0 0.0 0.0"/>
            <geom class="collision" type="box" pos="0.0653170496225357 -0.272113174200058 0.7471681833267212" size="0.0023787938989698887 0.04048225283622742 0.04967685416340828" quat="1.0 0.0 0.0 0.0"/>
            <geom class="collision" type="box" pos="0.20989829301834106 -0.30993375182151794 0.7477937936782837" size="0.14340534806251526 0.0029786655213683844 0.049130070954561234" quat="1.0 0.0 0.0 0.0"/>
            <geom class="collision" type="box" pos="0.20989829301834106 -0.2359030693769455 0.5688835382461548" size="0.14340534806251526 0.002978663658723235 0.04913004860281944" quat="1.0 0.0 0.0 0.0"/>
            <geom class="collision" type="box" pos="0.20989829301834106 -0.273468554019928 0.518949031829834" size="0.14340530335903168 0.04048299789428711 0.001828212640248239" quat="1.0 0.0 0.0 0.0"/>
            <geom class="collision" type="box" pos="0.34815752506256104 -0.273468554019928 0.5682579278945923" size="0.0023787938989698887 0.04048225283622742 0.04967685416340828" quat="1.0 0.0 0.0 0.0"/>
            <geom class="collision" type="box" pos="0.0653170496225357 -0.273468554019928 0.5682579278945923" size="0.0023787938989698887 0.04048225283622742 0.04967685416340828" quat="1.0 0.0 0.0 0.0"/>
            <geom class="collision" type="box" pos="0.20989829301834106 -0.31128913164138794 0.5688835382461548" size="0.14340534806251526 0.0029786580707877874 0.04912995174527168" quat="1.0 0.0 0.0 0.0"/>
          </body>
        </body>
        <body name="Body001_Clear">
          <geom mesh="Body001_Clear_vis" type="mesh" solimp="0.998 0.998 0.001" solref="0.001 1" friction="0.95 0.3 0.1" class="visual" material="Body001_Clear_material"/>
          <geom class="collision" type="box" pos="1.907348590179936e-08 -0.011328396387398243 0.5301669836044312" size="0.3689470589160919 0.1993916630744934 0.00500008137896657" quat="1.0 0.0 0.0 0.0"/>
          <geom class="collision" type="box" pos="1.907348590179936e-08 -0.011328366585075855 0.1502426266670227" size="0.3689470589160919 0.1993916630744934 0.00500008137896657" quat="1.0 0.0 0.0 0.0"/>
        </body>
        <geom class="region" name="reg_fridge_shelf0" type="box" pos="-0.00047872960567474365 -0.011815585196018219 0.3404042720794678" size="0.36053621566295624 0.19365516847372055 0.17964763736724854"/>
        <geom class="region" name="reg_fridge_shelf1" type="box" pos="-0.0005102306604385376 -0.011815585196018219 0.7201476097106934" size="0.36048552191257477 0.19365516847372055 0.1794449815750122"/>
        <geom class="region" name="reg_main" type="box" pos="0.0 0.022509068250656128 0.0" size="0.416000319480896 0.3726459572315216 0.951472354888916"/>
      </body>
    </body>
  </worldbody>
  <actuator>
    <motor name="freezer0_door_joint_actuator" joint="freezer0_door_joint" gear="50"/>
    <motor name="fridge_drawer0_joint_actuator" joint="fridge_drawer0_joint" gear="50"/>
    <motor name="fridge_left_door_joint_actuator" joint="fridge_left_door_joint" gear="50"/>
    <motor name="fridge_right_door_joint_actuator" joint="fridge_right_door_joint" gear="50"/>
  </actuator>
</mujoco>
