<?xml version='1.0' encoding='UTF-8'?>
<mujoco model="model">
  <option timestep="0.002" gravity="0.0 0.0 -9.81"/>
  <compiler angle="radian"/>
  <asset>
    <mesh file="visuals/blender.obj" name="blender_vis"/>
    <mesh file="visuals/bowl.obj" name="bowl_vis"/>
    <mesh file="visuals/button_head_lock.obj" name="button_head_lock_vis"/>
    <mesh file="visuals/head.obj" name="head_vis"/>
    <mesh file="visuals/knob_speed.obj" name="knob_speed_vis"/>
    <mesh file="visuals/Body001.obj" name="Body001_vis"/>
    <texture file="visuals/T_BC001.png" name="Body001_material" type="2d"/>
    <material name="Body001_material" rgba="1 1 1 1.0" texture="Body001_material" shininess="0.4472135901451111" specular="1"/>
    <texture file="visuals/T_BC001.png" name="bowl_material" type="2d"/>
    <material name="bowl_material" rgba="1 1 1 1.0" texture="bowl_material" shininess="0.4472135901451111" specular="2"/>
    <texture file="visuals/T_BC001.png" name="button_head_lock_material" type="2d"/>
    <material name="button_head_lock_material" rgba="1 1 1 1.0" texture="button_head_lock_material" shininess="0.4472135901451111" specular="0.3103448502657381"/>
    <texture file="visuals/T_BC001.png" name="head_material" type="2d"/>
    <material name="head_material" rgba="1 1 1 1.0" texture="head_material" shininess="0.4472135901451111" specular="1"/>
    <texture file="visuals/T_BC001.png" name="blender_material" type="2d"/>
    <material name="blender_material" rgba="1 1 1 1.0" texture="blender_material" shininess="0.4472135901451111" specular="2"/>
    <texture file="visuals/T_BC001.png" name="knob_speed_material" type="2d"/>
    <material name="knob_speed_material" rgba="1 1 1 1.0" texture="knob_speed_material" shininess="0.4472135901451111" specular="0.3103448502657381"/>
  </asset>
  <default>
    <default class="visual">
      <geom conaffinity="0" contype="0" group="1" type="mesh"/>
    </default>
    <default class="collision">
      <geom group="0" rgba="0.5 0 0 0.5"/>
    </default>
    <default class="spawn">
      <geom group="0" rgba="1 1 1 0.5" contype="0" conaffinity="0"/>
      <site group="0" rgba="1 1 1 0.5"/>
    </default>
    <default class="region">
      <geom group="1" conaffinity="0" contype="0" rgba="0 1 0 0"/>
    </default>
  </default>
  <worldbody>
    <body>
      <body name="object">
        <geom mesh="Body001_vis" type="mesh" solimp="0.998 0.998 0.001" solref="0.001 1" friction="0.95 0.3 0.1" class="visual" material="Body001_material"/>
        <geom type="box" pos="5.073845386505127e-06 0.013375680893659592 -0.13134357333183289" size="0.07056957483291626 0.16979755461215973 0.01855016127228737" quat="1.0 0.0 0.0 0.0" class="collision"/>
        <geom type="box" pos="-0.005887225735932589 0.09084387868642807 -0.06559009104967117" size="0.04578365013003349 0.07607658207416534 0.04703680798411369" quat="1.0 0.0 0.0 0.0" class="collision"/>
        <geom type="box" pos="-0.005887224804610014 0.09195831418037415 -0.00040517188608646393" size="0.037225399166345596 0.06769412755966187 0.019153527915477753" quat="1.0 0.0 0.0 0.0" class="collision"/>
        <body name="bowl">
          <!-- <joint axis="0.0 0.0 1.0" pos="5.066394805908203e-06 -0.08725181967020035 -0.039084047079086304" limited="true" name="bowl_joint" range="0.0 0.08" type="slide" damping="1" frictionloss="1" armature=".01" stiffness="0.05"/> -->
          <geom mesh="bowl_vis" type="mesh" solimp="0.998 0.998 0.001" solref="0.001 1" friction="0.95 0.3 0.1" class="visual" material="bowl_material"/>
          <geom type="cylinder" pos="5.066394805908203e-06 -0.08725181967020035 -0.10524020344018936" size="0.0464482381939888 0.004687561187893152" quat="7.549790126404332e-08 0.0 0.0 1.0" class="collision"/>
          <geom type="box" pos="5.073733063909458e-06 -0.15343552827835083 -0.0882730558514595" size="0.027358751744031906 0.0020164165180176497 0.027878670021891594" quat="6.998173773808958e-08 -2.8328244638942124e-08 -0.9269362092018127 -0.3752189874649048" class="collision"/>
          <geom type="box" pos="5.073733063909458e-06 -0.17774909734725952 -0.018456988036632538" size="0.027358751744031906 0.002016416285187006 0.04990223050117493" quat="7.536473134450716e-08 -4.482207494049817e-09 -0.9982361197471619 -0.05936863273382187" class="collision"/>
          <geom type="box" pos="-0.03308677673339844 -0.14456859230995178 -0.0882730558514595" size="0.027358751744031906 0.002016416285187006 0.027878668159246445" quat="0.09711387753486633 0.23990875482559204 0.8953516483306885 0.36243361234664917" class="collision"/>
          <geom type="box" pos="-0.04524356871843338 -0.16562476754188538 -0.018456988036632538" size="0.027358751744031906 0.002016416285187006 0.04990223050117493" quat="-0.015365572646260262 -0.2583625316619873 -0.9642220735549927 -0.05734538659453392" class="collision"/>
          <geom type="box" pos="-0.05731169134378433 -0.12034367024898529 -0.0882730558514595" size="0.027358751744031906 0.002016416285187006 0.027878666296601295" quat="0.18760931491851807 0.46346813440322876 0.8027503490447998 0.3249490261077881" class="collision"/>
          <geom type="box" pos="-0.07836788147687912 -0.13250046968460083 -0.018456995487213135" size="0.027358751744031906 0.002016416285187006 0.04990223050117493" quat="-0.02968408912420273 -0.4991180896759033 -0.8644978404045105 -0.05141449719667435" class="collision"/>
          <geom type="box" pos="-0.06617863476276398 -0.08725183457136154 -0.0882730558514595" size="0.027358751744031906 0.002016416285187006 0.027878666296601295" quat="0.2653197944164276 0.6554428935050964 0.6554428935050964 0.2653198540210724" class="collision"/>
          <geom type="box" pos="-0.09049221873283386 -0.08725183457136154 -0.018456988036632538" size="0.027358751744031906 0.0020164165180176497 0.04990223050117493" quat="0.041979771107435226 0.7058594822883606 0.7058596014976501 0.04197971895337105" class="collision"/>
          <geom type="box" pos="-0.057311706244945526 -0.0541599877178669 -0.0882730558514595" size="0.027358751744031906 0.002016416285187006 0.027878666296601295" quat="0.32494908571243286 0.8027502298355103 0.4634682834148407 0.1876094490289688" class="collision"/>
          <geom type="box" pos="-0.07836788892745972 -0.04200320318341255 -0.018456988036632538" size="0.027358751744031906 0.002016416285187006 0.04990223050117493" quat="0.05141449719667435 0.8644978404045105 0.4991181492805481 0.02968413010239601" class="collision"/>
          <geom type="box" pos="-0.03308679163455963 -0.029935061931610107 -0.0882730558514595" size="0.027358751744031906 0.0020164165180176497 0.027878668159246445" quat="0.3624334931373596 0.8953517079353333 0.23990881443023682 0.09711382538080215" class="collision"/>
          <geom type="box" pos="-0.04524358734488487 -0.00887887179851532 -0.018456995487213135" size="0.027358751744031906 0.002016416285187006 0.04990223050117493" quat="0.05734540894627571 0.9642220735549927 0.2583625614643097 0.01536561455577612" class="collision"/>
          <geom type="box" pos="5.049063020123867e-06 -0.021068118512630463 -0.0882730558514595" size="0.027358751744031906 0.002016416285187006 0.027878666296601295" quat="0.37521877884864807 0.9269362688064575 5.358042187708634e-08 6.884591385869498e-08" class="collision"/>
          <geom type="box" pos="5.045391844760161e-06 0.0032454654574394226 -0.018456988036632538" size="0.027358751744031906 0.002016416285187006 0.04990223050117493" quat="0.05936868488788605 0.9982361197471619 7.276963742697262e-08 4.8116497453065676e-08" class="collision"/>
          <geom type="box" pos="0.033096909523010254 -0.029935050755739212 -0.0882730558514595" size="0.027358751744031906 0.002016416285187006 0.027878668159246445" quat="0.3624334931373596 0.8953517079353333 -0.23990881443023682 -0.09711382538080215" class="collision"/>
          <geom type="box" pos="0.0452537015080452 -0.008878879249095917 -0.018456988036632538" size="0.027358751744031906 0.002016416285187006 0.04990223050117493" quat="0.05734540894627571 0.9642220735549927 -0.2583625614643097 -0.015365615487098694" class="collision"/>
          <geom type="box" pos="0.057321831583976746 -0.054159972816705704 -0.0882730558514595" size="0.027358751744031906 0.002016416285187006 0.027878668159246445" quat="0.3249489367008209 0.8027502298355103 -0.46346840262413025 -0.18760946393013" class="collision"/>
          <geom type="box" pos="0.07837801426649094 -0.04200318083167076 -0.018456995487213135" size="0.027358751744031906 0.002016416285187006 0.04990223050117493" quat="0.05141449719667435 0.8644978404045105 -0.4991181492805481 -0.02968413010239601" class="collision"/>
          <geom type="box" pos="0.0661887675523758 -0.08725181221961975 -0.0882730558514595" size="0.027358751744031906 0.002016416285187006 0.027878666296601295" quat="0.2653197944164276 0.6554428935050964 -0.6554428935050964 -0.2653198540210724" class="collision"/>
          <geom type="box" pos="0.09050235152244568 -0.08725181221961975 -0.018456988036632538" size="0.027358751744031906 0.0020164165180176497 0.04990223050117493" quat="0.041979771107435226 0.7058594822883606 -0.7058596014976501 -0.04197971895337105" class="collision"/>
          <geom type="box" pos="0.057321835309267044 -0.1203436553478241 -0.0882730558514595" size="0.027358751744031906 0.002016416285187006 0.027878666296601295" quat="0.18760941922664642 0.4634682238101959 -0.802750289440155 -0.32494911551475525" class="collision"/>
          <geom type="box" pos="0.07837801426649094 -0.13250043988227844 -0.018456995487213135" size="0.027358751744031906 0.002016416285187006 0.04990223050117493" quat="-0.02968408353626728 -0.4991181492805481 0.8644978404045105 0.05141448602080345" class="collision"/>
          <geom type="box" pos="0.033096905797719955 -0.14456859230995178 -0.0882730558514595" size="0.027358755469322205 0.0020164165180176497 0.027878668159246445" quat="0.09711378812789917 0.2399086058139801 -0.8953517079353333 -0.3624335527420044" class="collision"/>
          <geom type="box" pos="0.0452536940574646 -0.16562476754188538 -0.018456995487213135" size="0.027358753606677055 0.002016416285187006 0.04990223050117493" quat="0.01536570955067873 0.258362352848053 -0.9642221331596375 -0.05734535679221153" class="collision"/>
          <geom name="reg_bowl" type="ellipsoid" pos="-0.00032674369867891073 -0.08714649826288223 0.03208763897418976" size="0.08353977650403976 0.0851316973567009 0.131158709526062" rgba="0 1 0 0.5" class="region"/>
        </body>
        <body name="button_head_lock">
          <joint axis="-0.9848235845565796 0.0 -0.17355889081954956" pos="0.06283474713563919 0.04864196851849556 0.0029252218082547188" limited="true" name="button_head_lock_joint" range="0.0 0.9599310885968813" type="hinge" damping="1" frictionloss="1" armature=".01" stiffness="0.05"/>
          <geom mesh="button_head_lock_vis" type="mesh" solimp="0.998 0.998 0.001" solref="0.001 1" friction="0.95 0.3 0.1" class="visual" material="button_head_lock_material"/>
          <geom type="cylinder" pos="0.04379193112254143 0.04874860495328903 -0.0006280594971030951" size="0.012832711450755596 0.0065756323747336864" quat="0.7654592394828796 -5.1422556879288095e-08 0.6434844136238098 4.322845725823754e-08" class="collision"/>
          <geom type="cylinder" pos="0.0562073178589344 0.048545051366090775 0.0018812189809978008" size="0.011901753023266792 0.0049078515730798244" quat="0.5284447073936462 -0.4458100497722626 -0.6163422465324402 0.37699049711227417" class="collision"/>
          <geom class="collision" type="box" pos="0.05370982363820076 0.07828723639249802 0.012396917678415775" size="0.004682561848312616 0.022244270890951157 0.004682561848312616" quat="0.9826816916465759 0.16859455406665802 -0.07516278326511383 0.016221465542912483" name="button_head_lock_main"/>
        </body>
        <body name="head">
          <joint axis="-1.0 0.0 0.0" pos="5.645250894303899e-06 0.15499162673950195 0.02600679360330105" limited="true" name="head_joint" range="0.0 1.5707963267948966" type="hinge" damping="1" frictionloss="1" armature=".01" stiffness="0.05"/>
          <geom mesh="head_vis" type="mesh" solimp="0.998 0.998 0.001" solref="0.001 1" friction="0.95 0.3 0.1" class="visual" material="head_material"/>
          <geom type="box" pos="5.073845386505127e-06 0.09217700362205505 0.10592108964920044" size="0.04311765730381012 0.06769410520792007 0.046253502368927" quat="1.0 0.0 0.0 0.0" class="collision"/>
          <geom type="box" pos="5.073845386505127e-06 0.014708846807479858 0.12418593466281891" size="0.05965360626578331 0.15832160413265228 0.027248049154877663" quat="1.0 0.0 0.0 0.0" class="collision"/>
          <geom type="box" pos="5.073845386505127e-06 0.09217700362205505 0.0479249432682991" size="0.04311765730381012 0.06769412755966187 0.01956850104033947" quat="1.0 0.0 0.0 0.0" class="collision"/>
          <geom type="cylinder" pos="5.073845386505127e-06 -0.08695147931575775 0.08893030136823654" size="0.054843828082084656 0.011555799283087254" quat="1.0 0.0 0.0 0.0" class="collision"/>
          <body name="blender">
            <joint axis="0.0 0.0 1.0" pos="6.427988409996033e-06 -0.08725085854530334 0.009146001189947128" limited="false" name="blender_joint" range="0 360" type="hinge" damping="1" frictionloss="1" armature=".01" stiffness="0.05"/>
            <geom mesh="blender_vis" type="mesh" solimp="0.998 0.998 0.001" solref="0.001 1" friction="0.95 0.3 0.1" class="visual" material="blender_material"/>
            <geom type="cylinder" pos="6.427988409996033e-06 -0.08725085854530334 0.009146001189947128" size="0.04660256952047348 0.024174952879548073" quat="1.0 0.0 0.0 0.0" class="collision"/>
            <geom type="cylinder" pos="6.427988409996033e-06 -0.08725085854530334 -0.035879235714673996" size="0.03096526861190796 0.021607886999845505" quat="1.0 0.0 0.0 0.0" class="collision"/>
            <geom type="cylinder" pos="6.427988409996033e-06 -0.08725085854530334 0.04285428673028946" size="0.024344278499484062 0.009810916148126125" quat="1.0 0.0 0.0 0.0" class="collision"/>
            <geom type="cylinder" pos="6.427988409996033e-06 -0.08725085854530334 0.06494736671447754" size="0.006610231939703226 0.011693627573549747" quat="1.0 0.0 0.0 0.0" class="collision"/>
            <geom type="cylinder" pos="6.427988409996033e-06 -0.08725085854530334 0.06630212068557739" size="0.018412040546536446 0.0013846845831722021" quat="1.0 0.0 0.0 0.0" class="collision"/>
          </body>
        </body>
        <body name="knob_speed">
          <joint axis="-0.9862949848175049 0.0 -0.16499117016792297" pos="0.05769357457756996 0.07274851202964783 -0.06667506694793701" limited="true" name="knob_speed_joint" range="0.0 3.141592653589793" type="hinge" damping="0.05" armature="0.001"/>
          <geom mesh="knob_speed_vis" type="mesh" solimp="0.998 0.998 0.001" solref="0.001 1" friction="0.95 0.3 0.1" class="visual" material="knob_speed_material"/>
          <geom type="cylinder" pos="0.05795777589082718 0.07274851202964783 -0.06654687225818634" size="0.026588069275021553 0.010307710617780685" quat="0.7660444378852844 -4.318225421684474e-08 0.6427876353263855 3.490197286737384e-08" class="collision"/>
          <geom class="collision" type="box" pos="0.07732999324798584 0.07274755835533142 -0.06316711008548737" size="0.00778769887983799 0.009430400095880032 0.02553301304578781" quat="0.9379123449325562 0.33283326029777527 -0.09194265305995941 0.03300035372376442" name="knob_speed_main"/>
        </body>
        <geom class="region" name="reg_main" type="box" pos="5.62518835067749e-06 0.01275847852230072 0.0" size="0.07100000774860382 0.17087170279026032 0.15059827065467835"/>
      </body>
    </body>
  </worldbody>
  <actuator>
    <!-- <motor name="bowl_joint_actuator" joint="bowl_joint" gear="10"/> -->
    <motor name="button_head_lock_joint_actuator" joint="button_head_lock_joint" gear="0.5"/>
    <motor name="head_joint_actuator" joint="head_joint" gear="0.5"/>
    <motor name="knob_speed_joint_actuator" joint="knob_speed_joint" gear="0.5"/>
    <motor name="blender_joint_actuator" joint="blender_joint" gear="10"/>
  </actuator>
</mujoco>
