<?xml version='1.0' encoding='UTF-8'?>
<mujoco model="model">
  <option timestep="0.002" gravity="0.0 0.0 -9.81"/>
  <compiler angle="radian"/>
  <asset>
    <mesh file="visuals/blender.obj" name="blender_vis"/>
    <mesh file="visuals/bowl.obj" name="bowl_vis"/>
    <mesh file="visuals/button_head_lock.obj" name="button_head_lock_vis"/>
    <mesh file="visuals/head.obj" name="head_vis"/>
    <mesh file="visuals/knob_speed.obj" name="knob_speed_vis"/>
    <mesh file="visuals/Body001.obj" name="Body001_vis"/>
    <texture file="visuals/T_BC001.png" name="Body001_material" type="2d"/>
    <material name="Body001_material" rgba="1 1 1 1.0" texture="Body001_material" shininess="0.4472135901451111" specular="1"/>
    <texture file="visuals/T_BC001.png" name="bowl_material" type="2d"/>
    <material name="bowl_material" rgba="1 1 1 1.0" texture="bowl_material" shininess="0.4472135901451111" specular="3"/>
    <texture file="visuals/T_BC001.png" name="button_head_lock_material" type="2d"/>
    <material name="button_head_lock_material" rgba="1 1 1 1.0" texture="button_head_lock_material" shininess="0.4472135901451111" specular="0.3103448502657381"/>
    <texture file="visuals/T_BC001.png" name="head_material" type="2d"/>
    <material name="head_material" rgba="1 1 1 1.0" texture="head_material" shininess="0.4472135901451111" specular="1"/>
    <texture file="visuals/T_BC001.png" name="blender_material" type="2d"/>
    <material name="blender_material" rgba="1 1 1 1.0" texture="blender_material" shininess="0.4472135901451111" specular="3"/>
    <texture file="visuals/T_BC001.png" name="knob_speed_material" type="2d"/>
    <material name="knob_speed_material" rgba="1 1 1 1.0" texture="knob_speed_material" shininess="0.4472135901451111" specular="0.3103448502657381"/>
  </asset>
  <default>
    <default class="visual">
      <geom conaffinity="0" contype="0" group="1" type="mesh"/>
    </default>
    <default class="collision">
      <geom group="0" rgba="0.5 0 0 0.5"/>
    </default>
    <default class="spawn">
      <geom group="0" rgba="1 1 1 0.5" contype="0" conaffinity="0"/>
      <site group="0" rgba="1 1 1 0.5"/>
    </default>
    <default class="region">
      <geom group="1" conaffinity="0" contype="0" rgba="0 1 0 0"/>
    </default>
  </default>
  <worldbody>
    <body>
      <body name="object">
        <geom mesh="Body001_vis" type="mesh" solimp="0.998 0.998 0.001" solref="0.001 1" friction="0.95 0.3 0.1" class="visual" material="Body001_material"/>
        <geom type="box" pos="0.00000000 -0.09774345 -0.19773351" size="0.12444791197776794 0.06564841419458389 0.019715720787644386" quat="1.0 0.0 0.0 0.0" class="collision"/>
        <geom type="box" pos="0.00000000 0.03692806 -0.19773351" size="0.11274799704551697 0.06673045456409454 0.019715720787644386" quat="1.0 0.0 0.0 0.0" class="collision"/>
        <geom type="box" pos="0.00000000 0.13221318 -0.19773351" size="0.08129703253507614 0.02755354344844818 0.019715720787644386" quat="1.0 0.0 0.0 0.0" class="collision"/>
        <geom type="box" pos="0.00000000 0.09626705 -0.15816690" size="0.0607515387237072 0.0507378876209259 0.019715720787644386" quat="1.0 0.0 0.0 0.0" class="collision"/>
        <geom type="box" pos="0.00000000 0.08876749 -0.04101869" size="0.047403931617736816 0.028754515573382378 0.09607848525047302" quat="1.0 0.0 0.0 0.0" class="collision"/>
        <geom type="box" pos="0.00000000 0.05066630 -0.05084569" size="0.05001681298017502 0.008843242190778255 0.05589098483324051" quat="1.0 0.0 0.0 0.0" class="collision"/>
        <geom type="box" pos="-0.07887462 0.02933136 -0.05926344" size="0.037609051913022995 0.008843464776873589 0.018383823335170746" quat="0.9097738265991211 0.0 0.0 0.41510432958602905" class="collision"/>
        <geom type="box" pos="-0.10710569 -0.03338044 -0.06289373" size="0.037609051913022995 0.008843463845551014 0.018383823335170746" quat="0.7446263432502747 0.0 0.0 0.667481541633606" class="collision"/>
        <geom type="box" pos="0.07755138 0.02982495 -0.05926344" size="0.037609051913022995 0.008843464776873589 0.018383823335170746" quat="0.3897849917411804 0.0 0.0 0.9209058880805969" class="collision"/>
        <geom type="box" pos="0.10614390 -0.03214647 -0.06289373" size="0.037609051913022995 0.008843464776873589 0.018383823335170746" quat="0.6137421727180481 0.0 0.0 0.7895064949989319" class="collision"/>
        <body name="bowl">
          <!-- <joint axis="0.0 0.0 1.0" pos="-0.00006433 -0.07026622 -0.09382065" limited="true" name="bowl_joint" range="0.0 0.05" type="slide" damping="1" frictionloss="1" armature=".01" stiffness="0.05"/> -->
          <geom mesh="bowl_vis" type="mesh" solimp="0.998 0.998 0.001" solref="0.001 1" friction="0.95 0.3 0.1" class="visual" material="bowl_material"/>
          <geom type="cylinder" pos="-0.00006433 -0.05599070 -0.16455388" size="0.054665472358465195 0.009494337253272533" quat="1.0 0.0 0.0 0.0" class="collision"/>
          <geom type="box" pos="0.00000489 0.03485604 -0.06516086" size="0.022890442982316017 0.0032224664464592934 0.05258779600262642" quat="1.0 0.0 0.0 0.0" class="collision"/>
          <geom type="box" pos="0.00000803 0.01756145 -0.13884102" size="0.023930231109261513 0.0030119305010885 0.03303047642111778" quat="0.9473550915718079 -0.3201848864555359 7.109532661598547e-17 -3.926967335560564e-24" class="collision"/>
          <geom type="box" pos="0.04619871 0.02400079 -0.06516086" size="0.022890442982316017 0.003222322789952159 0.05258544534444809" quat="0.9659258127212524 0.0 -0.0 -0.2588191032409668" class="collision"/>
          <geom type="box" pos="0.03677442 0.00767115 -0.13884102" size="0.023930231109261513 0.0030119302682578564 0.03303048014640808" quat="0.9150747060775757 -0.3092748820781708 0.08286997675895691 -0.24519360065460205" class="collision"/>
          <geom type="box" pos="0.07999639 -0.00984756 -0.06516086" size="0.022890442982316017 0.003222322789952159 0.05258544534444809" quat="0.8660253882408142 0.0 -0.0 -0.5" class="collision"/>
          <geom type="box" pos="0.06366990 -0.01927729 -0.13884102" size="0.023930231109261513 0.0030119309667497873 0.03303048387169838" quat="0.820433497428894 -0.2772882580757141 0.16009250283241272 -0.4736776351928711" class="collision"/>
          <geom type="box" pos="0.09234187 -0.05605993 -0.06516086" size="0.0032223265152424574 0.02289145067334175 0.05258750170469284" quat="1.0 0.0 0.0 0.0" class="collision"/>
          <geom type="box" pos="0.07348783 -0.05606307 -0.13884103" size="0.023930231109261513 0.0030119300354272127 0.033030468970537186" quat="0.6698811650276184 -0.22640492022037506 0.22640492022037506 -0.6698812246322632" class="collision"/>
          <geom type="box" pos="0.07992716 -0.10225375 -0.06516086" size="0.022890441119670868 0.003222322789952159 0.05258544534444809" quat="0.4999999701976776 0.0 -0.0 -0.866025447845459" class="collision"/>
          <geom type="box" pos="0.06359753 -0.09282945 -0.13884102" size="0.023930231109261513 0.0030119307339191437 0.033030468970537186" quat="0.4736774265766144 -0.16009239852428436 0.2772882878780365 -0.8204336166381836" class="collision"/>
          <geom type="box" pos="0.04607883 -0.13605141 -0.06516086" size="0.022890441119670868 0.003222322789952159 0.05258544534444809" quat="0.2588190734386444 0.0 -0.0 -0.9659258127212524" class="collision"/>
          <geom type="box" pos="0.03664909 -0.11972493 -0.13884102" size="0.023930232971906662 0.0030119300354272127 0.033030468970537186" quat="0.24519355595111847 -0.08286994695663452 0.309274822473526 -0.9150747656822205" class="collision"/>
          <geom type="box" pos="-0.00013358 -0.14839689 -0.06516086" size="0.022890442982316017 0.003222439903765917 0.05258721858263016" quat="1.0 0.0 0.0 0.0" class="collision"/>
          <geom type="box" pos="-0.00013671 -0.12954287 -0.13884102" size="0.023930231109261513 0.0030119307339191437 0.033030468970537186" quat="1.8445685157075786e-07 -6.234228777657336e-08 -0.3201848566532135 0.9473550915718079" class="collision"/>
          <geom type="box" pos="-0.04632739 -0.13598220 -0.06516086" size="0.022890442982316017 0.003222322789952159 0.05258544534444809" quat="0.25881919264793396 0.0 0.0 0.9659258127212524" class="collision"/>
          <geom type="box" pos="-0.03690309 -0.11965256 -0.13884102" size="0.023930231109261513 0.0030119307339191437 0.033030468970537186" quat="0.24519367516040802 -0.0828699842095375 -0.3092748522758484 0.9150747060775757" class="collision"/>
          <geom type="box" pos="-0.08012505 -0.10213384 -0.06516086" size="0.022890441119670868 0.0032223230227828026 0.05258544534444809" quat="0.5000000596046448 0.0 0.0 0.8660253882408142" class="collision"/>
          <geom type="box" pos="-0.06379855 -0.09270410 -0.13884102" size="0.023930231109261513 0.0030119305010885 0.033030468970537186" quat="0.4736776053905487 -0.16009245812892914 -0.27728819847106934 0.8204335570335388" class="collision"/>
          <geom type="box" pos="-0.09247051 -0.05592148 -0.06516086" size="0.0032223265152424574 0.022891167551279068 0.05258692428469658" quat="1.0 0.0 0.0 0.0" class="collision"/>
          <geom type="box" pos="-0.07361648 -0.05591833 -0.13884102" size="0.023930231109261513 0.0030119305010885 0.03303047642111778" quat="0.6698812246322632 -0.22640486061573029 -0.22640486061573029 0.6698812246322632" class="collision"/>
          <geom type="box" pos="-0.08005579 -0.00972759 -0.06516086" size="0.022890442982316017 0.003222322789952159 0.05258544534444809" quat="0.8660256266593933 0.0 0.0 0.49999961256980896" class="collision"/>
          <geom type="box" pos="-0.06372614 -0.01915190 -0.13884102" size="0.023930231109261513 0.0030119305010885 0.03303047642111778" quat="0.8204337954521179 -0.2772882580757141 -0.160092294216156 0.4736771583557129" class="collision"/>
          <geom type="box" pos="-0.04620745 0.02407004 -0.06516086" size="0.022890442982316017 0.003222322789952159 0.05258544534444809" quat="0.9659258723258972 0.0 0.0 0.25881892442703247" class="collision"/>
          <geom type="box" pos="-0.03677772 0.00774353 -0.13884102" size="0.023930232971906662 0.0030119300354272127 0.03303048014640808" quat="0.9150746464729309 -0.3092750012874603 -0.0828700140118599 0.24519355595111847" class="collision"/>
          <geom type="box" pos="-0.00012130 -0.17930090 -0.09281836" size="0.018832150846719742 0.0029947555158287287 0.06414459645748138" quat="1.0 0.0 0.0 0.0" class="collision"/>
          <geom type="box" pos="-0.00012130 -0.16068920 -0.03169235" size="0.018832193687558174 0.003601614385843277 0.01608855649828911" quat="1.0881876733037643e-07 1.7037454824730958e-07 -0.7451668381690979 0.6668781042098999" class="collision"/>
          <geom name="reg_bowl" type="ellipsoid" pos="-0.00006433 -0.05599070 -0.01347624" size="0.08483942598104477 0.08645611256361008 0.13056087493896484" rgba="0 1 0 0.5" class="region"/>
        </body>
        <body name="button_head_lock">
          <joint axis="-0.9986295700073242 0.0 -0.0523359589278698" pos="0.05559264 0.08777523 -0.04744010" limited="true" name="button_head_lock_joint" range="0.0 0.004" type="slide" damping="1" frictionloss="1" armature=".01" stiffness="0.5" springref="-0.5"/>
          <geom mesh="button_head_lock_vis" type="mesh" solimp="0.998 0.998 0.001" solref="0.001 1" friction="0.95 0.3 0.1" class="visual" material="button_head_lock_material"/>
          <geom class="collision" type="cylinder" pos="0.05610775 0.08775933 -0.04716124" size="0.010569674894213676 0.003992168232798576" quat="0.7321696281433105 -1.0106510490688961e-13 0.681122362613678 9.151521140893237e-08" name="button_head_lock_main"/>
        </body>
        <body name="head">
          <joint axis="-1.0 0.0 0.0" pos="-0.00011057 0.12739091 0.05992162" limited="true" name="head_joint" range="0.0 1.5707963267948966" type="hinge" damping="1" frictionloss="1" armature=".01" stiffness="0.05"/>
          <geom mesh="head_vis" type="mesh" solimp="0.998 0.998 0.001" solref="0.001 1" friction="0.95 0.3 0.1" class="visual" material="head_material"/>
          <geom type="box" pos="0.00000000 0.08666642 0.07792768" size="0.06253496557474136 0.0404474101960659 0.01676778867840767" quat="1.0 0.0 0.0 0.0" class="collision"/>
          <geom type="cylinder" pos="-0.00000000 -0.05154477 0.09178909" size="0.05965748801827431 0.014811050146818161" quat="1.0 0.0 0.0 0.0" class="collision"/>
          <geom type="cylinder" pos="0.00000000 0.03623885 0.16105494" size="0.05463188886642456 0.12900060415267944" quat="0.7071068286895752 -0.7071067690849304 -1.5700924318127872e-16 5.9269340452702814e-24" class="collision"/>
          <geom type="box" pos="0.00000000 0.08666642 0.09807473" size="0.0610172301530838 0.05543158948421478 0.009290141053497791" quat="1.0 0.0 0.0 0.0" class="collision"/>
          <geom type="cylinder" pos="0.00000000 -0.11484159 0.16816461" size="0.020197732374072075 0.02965622767806053" quat="0.7071068286895752 -0.7071067690849304 -1.5700924318127872e-16 5.9269340452702814e-24" class="collision"/>
          <body name="blender">
            <joint axis="0.0 0.0 1.0" pos="0.00021186 -0.05126611 -0.02648417" limited="false" name="blender_joint" range="0 360" type="hinge" damping="1" frictionloss="1" armature=".01" stiffness="0.05"/>
            <geom mesh="blender_vis" type="mesh" solimp="0.998 0.998 0.001" solref="0.001 1" friction="0.95 0.3 0.1" class="visual" material="blender_material"/>
            <geom type="cylinder" pos="0.00021186 -0.05126611 -0.02522224" size="0.04076942801475525 0.05489890277385712" quat="1.0 0.0 0.0 0.0" class="collision"/>
            <geom type="cylinder" pos="0.00021186 -0.05126611 0.05080776" size="0.006365129258483648 0.018637439236044884" quat="1.0 0.0 0.0 0.0" class="collision"/>
            <geom type="cylinder" pos="0.00021186 -0.05126611 0.04634096" size="0.01876448094844818 0.004426607862114906" quat="1.0 0.0 0.0 0.0" class="collision"/>
          </body>
        </body>
        <body name="knob_speed">
          <joint axis="-1.0 0.0 0.0" pos="0.05353300 0.08421250 0.02017800" limited="true" name="knob_speed_joint" range="0.0 3.6651914291880923" type="hinge" damping="0.05" armature="0.001"/>
          <geom mesh="knob_speed_vis" type="mesh" solimp="0.998 0.998 0.001" solref="0.001 1" friction="0.95 0.3 0.1" class="visual" material="knob_speed_material"/>
          <geom class="collision" type="box" pos="0.05780981 0.08425831 0.02016454" size="0.0056040058843791485 0.0023768404498696327 0.008633320219814777" quat="1.0 0.0 0.0 0.0" name="knob_speed_main"/>
          <geom type="cylinder" pos="0.05060749 0.08421450 0.02014453" size="0.012157334946095943 0.0018173756543546915" quat="0.7071068286895752 -4.750302551315144e-08 0.7071067094802856 4.7503014855010406e-08" class="collision"/>
        </body>
        <geom class="region" name="reg_main" type="box" pos="0.0 0.008716349999999998 0.0" size="0.12621651 0.1737535 0.21826479000000001"/>
      </body>
    </body>
  </worldbody>
  <actuator>
    <!-- <motor name="bowl_joint_actuator" joint="bowl_joint" gear="100"/> -->
    <motor name="button_head_lock_joint_actuator" joint="button_head_lock_joint" gear="0.5"/>
    <motor name="head_joint_actuator" joint="head_joint" gear="50"/>
    <motor name="knob_speed_joint_actuator" joint="knob_speed_joint" gear="10"/>
    <motor name="blender_joint_actuator" joint="blender_joint" gear="10"/>
  </actuator>
</mujoco>
