<?xml version='1.0' encoding='UTF-8'?>
<mujoco model="model">
  <option timestep="0.002" gravity="0.0 0.0 -9.81"/>
  <compiler angle="radian"/>
  <asset>
    <mesh file="visuals/button_lid.obj" name="button_lid_vis"/>
    <mesh file="visuals/Body001.obj" name="Body001_vis"/>
    <mesh file="visuals/kettle_main.obj" name="kettle_main_vis"/>
    <mesh file="visuals/kettle_main_Clear.obj" name="kettle_main_Clear_vis"/>
    <mesh file="visuals/lid.obj" name="lid_vis"/>
    <mesh file="visuals/switch.obj" name="switch_vis"/>
    <texture file="visuals/T_BC001.png" name="Body001_material" type="2d"/>
    <material name="Body001_material" rgba="1 1 1 1.0" texture="Body001_material" shininess="0.5" specular="0.3103448502657381"/>
    <texture file="visuals/T_BC001.png" name="kettle_main_material" type="2d"/>
    <material name="kettle_main_material" rgba="1 1 1 1.0" texture="kettle_main_material" shininess="0.5" specular="0.3103448502657381"/>
    <texture file="visuals/T_BC001.png" name="button_lid_material" type="2d"/>
    <material name="button_lid_material" rgba="1 1 1 1.0" texture="button_lid_material" shininess="0.5" specular="0.3103448502657381"/>
    <texture file="visuals/T_BC001.png" name="kettle_main_Clear_material" type="2d"/>
    <material name="kettle_main_Clear_material" rgba="1 1 1 0.2881355881690979" texture="kettle_main_Clear_material" shininess="0.5" specular="0.3103448502657381"/>
    <texture file="visuals/T_BC001.png" name="lid_material" type="2d"/>
    <material name="lid_material" rgba="1 1 1 1.0" texture="lid_material" shininess="0.5" specular="0.3103448502657381"/>
    <texture file="visuals/T_BC001.png" name="switch_material" type="2d"/>
    <material name="switch_material" rgba="1 1 1 1.0" texture="switch_material" shininess="0.5" specular="0.3103448502657381"/>
  </asset>
  <default>
    <default class="visual">
      <geom conaffinity="0" contype="0" group="1" type="mesh"/>
    </default>
    <default class="collision">
      <geom group="0" rgba="0.5 0 0 0.5"/>
    </default>
    <default class="spawn">
      <geom group="0" rgba="1 1 1 0.5" contype="0" conaffinity="0"/>
      <site group="0" rgba="1 1 1 0.5"/>
    </default>
    <default class="region">
      <geom group="1" conaffinity="0" contype="0" rgba="0 1 0 0" mass="0"/>
    </default>
  </default>
  <worldbody>
    <body>
      <body name="object">
        <geom mesh="Body001_vis" type="mesh" solimp="0.998 0.998 0.001" solref="0.001 1" friction="0.95 0.3 0.1" class="visual" material="Body001_material"/>
        <geom type="cylinder" pos="-0.03538152202963829 0.0010952461743727326 -0.1637687385082245" size="0.08254653215408325 0.009571613743901253" quat="1.0 0.0 0.0 0.0" class="collision"/>
        <body name="kettle_main">
          <!-- <joint axis="0.0 0.0 1.0" pos="-3.725290298461914e-09 0.0 -0.0032227039337158203" limited="true" name="kettle_main_joint" range="0.0 0.07" type="slide" damping="1" frictionloss="1" armature=".01" stiffness="0.05"></joint> -->
          <geom mesh="kettle_main_vis" type="mesh" solimp="0.998 0.998 0.001" solref="0.001 1" friction="0.95 0.3 0.1" class="visual" material="kettle_main_material"/>
          <geom type="cylinder" pos="-0.03547241538763046 -0.000652501592412591 -0.1391078531742096" size="0.08874797821044922 0.014229065738618374" quat="1.0 0.0 0.0 0.0" class="collision"/>
          <geom type="box" pos="-0.03471153974533081 -0.08220654726028442 -0.10265162587165833" size="0.02977779135107994 0.005581058096140623 0.026802511885762215" quat="1.0 0.0 0.0 0.0" class="collision"/>
          <geom type="box" pos="-0.03471154719591141 -0.06748807430267334 0.11778312921524048" size="0.02977782115340233 0.00558107253164053 0.03503568843007088" quat="0.9659258127212524 -0.2588191032409668 -0.0 0.0" class="collision"/>
          <geom type="box" pos="-0.07724742591381073 -0.053342461585998535 0.11778312921524048" size="0.02977782115340233 0.00558107253164053 0.03503568843007088" quat="0.9112226366996765 -0.2441614419221878 0.0858633741736412 -0.3204464316368103" class="collision"/>
          <geom type="box" pos="-0.08646006882190704 -0.06482115387916565 -0.10265162587165833" size="0.02977781742811203 0.005581064615398645 0.026802511885762215" quat="0.9433671832084656 0.0 -0.0 -0.33175045251846313" class="collision"/>
          <geom type="box" pos="-0.11624616384506226 -0.017508337274193764 -0.10265162587165833" size="0.02977781742811203 0.005581064615398645 0.026802511885762215" quat="0.7745359539985657 0.0 -0.0 -0.6325298547744751" class="collision"/>
          <geom type="box" pos="-0.10182451456785202 -0.014567404985427856 0.11778312921524048" size="0.02977782115340233 0.00558107253164053 0.03503568843007088" quat="0.748144268989563 -0.20046466588974 0.16371077299118042 -0.6109769344329834" class="collision"/>
          <geom type="box" pos="-0.09615639597177505 0.03055177628993988 0.11778312921524048" size="0.02977782115340233 0.00558107253164053 0.03503568843007088" quat="0.49888408184051514 -0.13367560505867004 0.2216261476278305 -0.8271199464797974" class="collision"/>
          <geom type="box" pos="-0.10917527973651886 0.037417806684970856 -0.10265162587165833" size="0.02977781742811203 0.005581064615398645 0.026802511885762215" quat="0.5164828300476074 0.0 -0.0 -0.8562975525856018" class="collision"/>
          <geom type="box" pos="-0.0681149959564209 0.07575635612010956 -0.10265162587165833" size="0.02977781742811203 0.005581064615398645 0.026802511885762215" quat="0.19312620162963867 0.0 -0.0 -0.9811739325523376" class="collision"/>
          <geom type="box" pos="-0.06253695487976074 0.06213580071926117 0.11778312921524048" size="0.02977782115340233 0.00558107253164053 0.03503568843007088" quat="0.18654558062553406 -0.04998474940657616 0.25394657254219055 -0.9477412104606628" class="collision"/>
          <geom type="box" pos="-0.015080209821462631 0.06434522569179535 0.11778312921524048" size="0.02977782115340233 0.00558107253164053 0.03503568843007088" quat="0.15858937799930573 -0.04249390959739685 -0.2553068697452545 0.952817976474762" class="collision"/>
          <geom type="box" pos="-0.010312728583812714 0.07827021181583405 -0.10265162587165833" size="0.02977781742811203 0.005581064615398645 0.026802511885762215" quat="0.1641838103532791 0.0 0.0 0.986429750919342" class="collision"/>
          <geom type="box" pos="0.03392260521650314 0.04363854229450226 -0.10265162587165833" size="0.02977781742811203 0.005581064615398645 0.026802511885762215" quat="0.4910895526409149 0.0 0.0 0.8711090683937073" class="collision"/>
          <geom type="box" pos="0.021329693496227264 0.036019328981637955 0.11778312921524048" size="0.02977782115340233 0.00558107253164053 0.03503568843007088" quat="0.47435635328292847 -0.12710344791412354 -0.22545963525772095 0.8414266109466553" class="collision"/>
          <geom type="box" pos="0.03706934303045273 -0.005954106338322163 0.11778312921524048" size="0.02977782115340233 0.00558107253164053 0.03503568843007088" quat="0.7183259129524231 -0.19247493147850037 -0.1730339527130127 0.6457712650299072" class="collision"/>
          <geom type="box" pos="0.05170482397079468 -0.007515400182455778 -0.10265162587165833" size="0.02977781742811203 0.005581064615398645 0.026802511885762215" quat="0.7436657547950745 0.0 0.0 0.6685516238212585" class="collision"/>
          <geom type="box" pos="0.019679777324199677 -0.06063393875956535 -0.10265162587165833" size="0.02977781742811203 0.005581064615398645 0.026802511885762215" quat="0.9346433877944946 0.0 0.0 0.355586439371109" class="collision"/>
          <geom type="box" pos="0.00989646464586258 -0.04963749647140503 0.11778312921524048" size="0.02977782115340233 0.00558107253164053 0.03503568843007088" quat="0.9027961492538452 -0.24190358817577362 -0.09203260391950607 0.3434702157974243" class="collision"/>
          <geom class="collision" type="box" pos="0.0663488358259201 -0.000382203608751297 0.12102849036455154" size="0.02952895313501358 0.01757529005408287 0.00980944000184536" quat="1.0 0.0 0.0 0.0" name="handle_2"/>
          <geom class="collision" type="box" pos="0.10790809243917465 -0.000382203608751297 0.04569841921329498" size="0.016733692958950996 0.01757529005408287 0.049610935151576996" quat="1.0 0.0 0.0 0.0" name="handle_main"/>
          <geom class="collision" type="box" pos="0.09872564673423767 -0.000382203608751297 0.11302942037582397" size="0.02952895313501358 0.01757529005408287 0.016728650778532028" quat="0.8562593460083008 0.0 0.5165461897850037 0.0" name="handle_1"/>
          <body name="button_lid">
            <joint axis="0.0 0.0 -1.0" pos="0.05610485374927521 0.00011815689504146576 0.14201116561889648" limited="true" name="button_lid_joint" range="0.0 0.003" type="slide" damping="1" frictionloss="1" armature=".01" stiffness="1" springref="-0.5"/>
            <geom mesh="button_lid_vis" type="mesh" solimp="0.998 0.998 0.001" solref="0.001 1" friction="0.95 0.3 0.1" class="visual" material="button_lid_material"/>
            <geom class="collision" type="box" pos="0.056178849190473557 0.0005087144672870636 0.14188969135284424" size="0.0048311809077858925 0.008083097636699677 0.0046598599292337894" quat="1.0 0.0 0.0 0.0" name="button_lid_main"/>
          </body>
          <body name="kettle_main_Clear">
            <geom mesh="kettle_main_Clear_vis" type="mesh" solimp="0.998 0.998 0.001" solref="0.001 1" friction="0.95 0.3 0.1" class="visual" material="kettle_main_Clear_material"/>
            <geom type="box" pos="-0.03471153974533081 -0.08220654726028442 0.0014674090780317783" size="0.02977781742811203 0.005581064615398645 0.08027462661266327" quat="1.0 0.0 0.0 0.0" class="collision"/>
            <geom type="box" pos="-0.08646006882190704 -0.06482115387916565 0.0014674090780317783" size="0.02977781742811203 0.005581064615398645 0.08027459681034088" quat="0.9433671832084656 0.0 -0.0 -0.33175045251846313" class="collision"/>
            <geom type="box" pos="-0.11624616384506226 -0.017508337274193764 0.0014674090780317783" size="0.02977781742811203 0.005581064615398645 0.08027459681034088" quat="0.7745359539985657 0.0 -0.0 -0.6325298547744751" class="collision"/>
            <geom type="box" pos="-0.10917527973651886 0.037417806684970856 0.0014674090780317783" size="0.02977781742811203 0.005581064615398645 0.08027459681034088" quat="0.5164828300476074 0.0 -0.0 -0.8562975525856018" class="collision"/>
            <geom type="box" pos="-0.0681149959564209 0.07575635612010956 0.0014674090780317783" size="0.02977781742811203 0.005581064615398645 0.08027459681034088" quat="0.19312620162963867 0.0 -0.0 -0.9811739325523376" class="collision"/>
            <geom type="box" pos="-0.010312728583812714 0.07827021181583405 0.0014674090780317783" size="0.02977781742811203 0.005581064615398645 0.08027459681034088" quat="0.1641838103532791 0.0 0.0 0.986429750919342" class="collision"/>
            <geom type="box" pos="0.03392260521650314 0.04363854229450226 0.0014674090780317783" size="0.02977781742811203 0.005581064615398645 0.08027459681034088" quat="0.4910895526409149 0.0 0.0 0.8711090683937073" class="collision"/>
            <geom type="box" pos="0.05170482397079468 -0.007515400182455778 0.0014674090780317783" size="0.02977781742811203 0.005581064615398645 0.08027459681034088" quat="0.7436657547950745 0.0 0.0 0.6685516238212585" class="collision"/>
            <geom type="box" pos="0.019679777324199677 -0.06063393875956535 0.0014674090780317783" size="0.02977781742811203 0.005581064615398645 0.08027459681034088" quat="0.9346433877944946 0.0 0.0 0.355586439371109" class="collision"/>
          </body>
          <body name="lid">
            <joint axis="0.0 1.0 0.0" pos="0.026003453880548477 -5.4329633712768555e-05 0.1463363915681839" limited="true" name="lid_joint" range="0.0 1.5707963267948966" type="hinge" damping="1" frictionloss="1" armature=".01" stiffness="0.05"/>
            <geom mesh="lid_vis" type="mesh" solimp="0.998 0.998 0.001" solref="0.001 1" friction="0.95 0.3 0.1" class="visual" material="lid_material"/>
            <geom class="collision" type="cylinder" pos="-0.035547804087400436 0.0003185271052643657 0.15125049650669098" size="0.047698937356472015 0.002917469246312976" quat="1.0 0.0 0.0 0.0" name="lid_main"/>
            <geom class="collision" type="cylinder" pos="-0.035547804087400436 0.0003185271052643657 0.16044364869594574" size="0.0346982479095459 0.002122292062267661" quat="1.0 0.0 0.0 0.0" name="lid_1"/>
            <geom class="collision" type="cylinder" pos="-0.035547804087400436 0.0003185271052643657 0.166156604886055" size="0.022068731486797333 0.0013498172629624605" quat="1.0 0.0 0.0 0.0" name="lid_2"/>
          </body>
          <body name="switch">
            <joint axis="0.0 0.0 -1.0" pos="0.08839569240808487 8.405954577028751e-05 -0.10657630115747452" limited="true" name="switch_joint" range="0.0 0.01" type="slide" damping="50" frictionloss="1" armature=".01" stiffness="1" springref="-0.25"/>
            <geom mesh="switch_vis" type="mesh" solimp="0.998 0.998 0.001" solref="0.001 1" friction="0.95 0.3 0.1" class="visual" material="switch_material"/>
            <geom class="collision" type="box" pos="0.09348791092634201 0.00018739677034318447 -0.10674447566270828" size="0.02226397953927517 0.01842275820672512 0.0038377416785806417" quat="1.0 0.0 0.0 0.0" name="switch_main"/>
          </body>
        </body>
        <geom class="region" name="reg_main" type="box" pos="0.0 -4.163336342344337e-16 -9.53674295089968e-09" size="0.12377255952358246 0.08694655990600586 0.1736222187280655"/>
      </body>
    </body>
  </worldbody>
  <actuator>
    <!-- <motor name="kettle_main_joint_actuator" joint="kettle_main_joint" gear="10"/> -->
    <motor name="button_lid_joint_actuator" joint="button_lid_joint" gear="50"/>
    <motor name="lid_joint_actuator" joint="lid_joint" gear="0.5"/>
    <motor name="switch_joint_actuator" joint="switch_joint" gear="50"/>
  </actuator>
</mujoco>