<?xml version='1.0' encoding='UTF-8'?>
<mujoco model="model">
  <option timestep="0.002" gravity="0.0 0.0 -9.81"/>
  <compiler angle="radian"/>
  <asset>
    <mesh file="visuals/knob_front_left.obj" name="knob_front_left_vis"/>
    <mesh file="visuals/knob_front_right.obj" name="knob_front_right_vis"/>
    <mesh file="visuals/knob_rear_left.obj" name="knob_rear_left_vis"/>
    <mesh file="visuals/knob_rear_right.obj" name="knob_rear_right_vis"/>
    <mesh file="visuals/Body001.obj" name="Body001_vis"/>
    <texture file="visuals/T_BC001.png" name="Body001_material" type="2d"/>
    <material name="Body001_material" rgba="1 1 1 1.0" texture="Body001_material" shininess="0.1" specular="2"/>
    <texture file="visuals/T_BC001.png" name="knob_front_right_material" type="2d"/>
    <material name="knob_front_right_material" rgba="1 1 1 1.0" texture="knob_front_right_material" shininess="0.30000001192092896" specular="0.3103448502657381"/>
    <texture file="visuals/T_BC001.png" name="knob_front_left_material" type="2d"/>
    <material name="knob_front_left_material" rgba="1 1 1 1.0" texture="knob_front_left_material" shininess="0.30000001192092896" specular="0.3103448502657381"/>
    <texture file="visuals/T_BC001.png" name="knob_rear_left_material" type="2d"/>
    <material name="knob_rear_left_material" rgba="1 1 1 1.0" texture="knob_rear_left_material" shininess="0.30000001192092896" specular="0.3103448502657381"/>
    <texture file="visuals/T_BC001.png" name="knob_rear_right_material" type="2d"/>
    <material name="knob_rear_right_material" rgba="1 1 1 1.0" texture="knob_rear_right_material" shininess="0.30000001192092896" specular="0.3103448502657381"/>
  </asset>
  <default>
    <default class="visual">
      <geom conaffinity="0" contype="0" group="1" type="mesh"/>
    </default>
    <default class="collision">
      <geom group="0" rgba="0.5 0 0 0.5"/>
    </default>
    <default class="spawn">
      <geom group="0" rgba="1 1 1 0.5" contype="0" conaffinity="0"/>
      <site group="0" rgba="1 1 1 0.5"/>
    </default>
    <default class="region">
      <geom group="1" conaffinity="0" contype="0" rgba="0 1 0 0"/>
    </default>
  </default>
  <worldbody>
    <body>
      <body name="object">
        <geom mesh="Body001_vis" type="mesh" solimp="0.998 0.998 0.001" solref="0.001 1" friction="0.95 0.3 0.1" class="visual" material="Body001_material"/>
        <geom class="collision" type="box" pos="0.00027156 0.00091843 -0.01647027" size="0.2963346540927887 0.2565191984176636 0.003129084361717105" quat="1.0 0.0 0.0 0.0"/>
        <geom class="collision" type="box" pos="-0.00095969 0.02750808 0.00226995" size="0.2897818386554718 0.18692438304424286 0.017222028225660324" quat="1.0 0.0 0.0 0.0"/>
        <body name="knob_front_right">
          <joint axis="0.0 0.0 1.0" pos="0.14623035 -0.21961883 -0.00133696" limited="true" name="knob_front_right_joint" range="0.0 3.6651914291880923" type="hinge" damping="0.2" armature="0.01" frictionloss="1"/>
          <geom mesh="knob_front_right_vis" type="mesh" solimp="0.998 0.998 0.001" solref="0.001 1" friction="0.95 0.3 0.1" class="visual" material="knob_front_right_material"/>
          <geom class="collision" type="cylinder" pos="0.14608303 -0.21942134 -0.00728045" size="0.019426897168159485 0.005733807105571032" quat="1.0 0.0 0.0 0.0" friction="100 0.5 0.01"/>
          <geom class="collision" type="box" pos="0.14544936 -0.21942134 0.00367980" size="0.005467358510941267 0.018467804417014122 0.005191871430724859" quat="1.0 0.0 0.0 0.0" name="knob_front_right_main" friction="100 0.5 0.01"/>
        </body>
        <body name="knob_front_left">
          <joint axis="0.0 0.0 1.0" pos="-0.14951883 -0.21961883 -0.00133696" limited="true" name="knob_front_left_joint" range="0.0 3.6651914291880923" type="hinge" damping="0.2" armature="0.01" frictionloss="1"/>
          <geom mesh="knob_front_left_vis" type="mesh" solimp="0.998 0.998 0.001" solref="0.001 1" friction="0.95 0.3 0.1" class="visual" material="knob_front_left_material"/>
          <geom class="collision" type="cylinder" pos="-0.14953047 -0.21942134 -0.00728045" size="0.019426897168159485 0.005733807105571032" quat="1.0 0.0 0.0 0.0" friction="100 0.5 0.01"/>
          <geom class="collision" type="box" pos="-0.14953047 -0.21942134 0.00367980" size="0.0054673561826348305 0.018467804417014122 0.00519186956807971" quat="1.0 0.0 0.0 0.0" name="knob_front_left_main" friction="100 0.5 0.01"/>
        </body>
        <body name="knob_rear_left">
          <joint axis="0.0 0.0 1.0" pos="-0.04911526 -0.21961883 -0.00133696" limited="true" name="knob_rear_left_joint" range="0.0 3.6651914291880923" type="hinge" damping="0.2" armature="0.01" frictionloss="1"/>
          <geom mesh="knob_rear_left_vis" type="mesh" solimp="0.998 0.998 0.001" solref="0.001 1" friction="0.95 0.3 0.1" class="visual" material="knob_rear_left_material"/>
          <geom class="collision" type="cylinder" pos="-0.04930050 -0.21942134 -0.00728045" size="0.019426897168159485 0.005733807105571032" quat="1.0 0.0 0.0 0.0" friction="100 0.5 0.01"/>
          <geom class="collision" type="box" pos="-0.04969703 -0.21942134 0.00367980" size="0.005467357113957405 0.018467804417014122 0.005191870033740997" quat="1.0 0.0 0.0 0.0" name="knob_rear_left_main" friction="100 0.5 0.01"/>
        </body>
        <body name="knob_rear_right">
          <joint axis="0.0 0.0 1.0" pos="0.04901238 -0.21961883 -0.00133696" limited="true" name="knob_rear_right_joint" range="0.0 3.6651914291880923" type="hinge" damping="0.2" armature="0.01" frictionloss="1"/>
          <geom mesh="knob_rear_right_vis" type="mesh" solimp="0.998 0.998 0.001" solref="0.001 1" friction="0.95 0.3 0.1" class="visual" material="knob_rear_right_material"/>
          <geom class="collision" type="cylinder" pos="0.04864764 -0.21942134 -0.00728045" size="0.019426897168159485 0.005733807105571032" quat="1.0 0.0 0.0 0.0" friction="100 0.5 0.01"/>
          <geom class="collision" type="box" pos="0.04817016 -0.21942134 0.00367980" size="0.005467357579618692 0.018467804417014122 0.005191870499402285" quat="1.0 0.0 0.0 0.0" name="knob_rear_right_main" friction="100 0.5 0.01"/>
        </body>
        <site type="cylinder" rgba="0.3 0.4 1 0.5" size="0.028610823675990105 0.004620049148797989" pos="-0.14501911 -0.07171194 0.00966110" name="burner_on_front_left"/>
        <site type="cylinder" rgba="0.3 0.4 1 0.5" size="0.04941902682185173 0.004620048217475414" pos="-0.14461172 0.12555607 0.00966110" name="burner_on_rear_left"/>
        <site type="cylinder" rgba="0.3 0.4 1 0.5" size="0.03761683404445648 0.0046200500801205635" pos="0.14493778 0.12546320 0.00966110" name="burner_on_rear_right"/>
        <site type="cylinder" rgba="0.3 0.4 1 0.5" size="0.03773178905248642 0.0046200500801205635" pos="0.14499480 -0.07214969 0.00966110" name="burner_on_front_right"/>
        <site type="cylinder" rgba="0.5 0 0 0" size="0.028610823675990105 4.999999873689376e-05" pos="-0.14501911 -0.07171194 0.01927962" name="burner_front_left_place_site"/>
        <site type="cylinder" rgba="0.5 0 0 0" size="0.04941902682185173 4.999999509891495e-05" pos="-0.14461172 0.12555607 0.01927962" name="burner_rear_left_place_site"/>
        <site type="cylinder" rgba="0.5 0 0 0" size="0.03761683404445648 5.0000002374872565e-05" pos="0.14493778 0.12546320 0.01927962" name="burner_rear_right_place_site"/>
        <site type="cylinder" rgba="0.5 0 0 0" size="0.03773178905248642 4.999999509891495e-05" pos="0.14499480 -0.07214969 0.01927962" name="burner_front_right_place_site"/>
        <geom class="region" name="reg_main" type="box" pos="9.999999994736442e-09 0.0 -0.01545067" size="0.29668419 0.2564118 0.00505115"/>
      </body>
    </body>
  </worldbody>
  <actuator>
    <motor name="knob_front_right_joint_actuator" joint="knob_front_right_joint" gear="10"/>
    <motor name="knob_front_left_joint_actuator" joint="knob_front_left_joint" gear="10"/>
    <motor name="knob_rear_left_joint_actuator" joint="knob_rear_left_joint" gear="10"/>
    <motor name="knob_rear_right_joint_actuator" joint="knob_rear_right_joint" gear="10"/>
  </actuator>
</mujoco>