<?xml version='1.0' encoding='UTF-8'?>
<mujoco model="model">
  <compiler angle="radian"/>
  <asset>
    <mesh file="visuals/Body001.obj" name="Body001_vis"/>
    <mesh file="visuals/Button001.obj" name="Button001_vis"/>
    <mesh file="visuals/Button002.obj" name="Button002_vis"/>
    <mesh file="visuals/Button003.obj" name="Button003_vis"/>
    <mesh file="visuals/Button004.obj" name="Button004_vis"/>
    <mesh file="visuals/Button005.obj" name="Button005_vis"/>
    <texture file="visuals/T_BC001.png" name="Body001_material" type="2d"/>
    <material name="Body001_material" rgba="1 1 1 1.0" texture="Body001_material" shininess="0.4472135901451111" specular="0.3103448502657381"/>
    <texture file="visuals/T_BC001.png" name="Button001_material" type="2d"/>
    <material name="Button001_material" rgba="1 1 1 1.0" texture="Button001_material" shininess="0.4472135901451111" specular="0.3103448502657381"/>
    <texture file="visuals/T_BC001.png" name="Button002_material" type="2d"/>
    <material name="Button002_material" rgba="1 1 1 1.0" texture="Button002_material" shininess="0.4472135901451111" specular="0.3103448502657381"/>
    <texture file="visuals/T_BC001.png" name="Button003_material" type="2d"/>
    <material name="Button003_material" rgba="1 1 1 1.0" texture="Button003_material" shininess="0.4472135901451111" specular="0.3103448502657381"/>
    <texture file="visuals/T_BC001.png" name="Button004_material" type="2d"/>
    <material name="Button004_material" rgba="1 1 1 1.0" texture="Button004_material" shininess="0.4472135901451111" specular="0.3103448502657381"/>
    <texture file="visuals/T_BC001.png" name="Button005_material" type="2d"/>
    <material name="Button005_material" rgba="1 1 1 1.0" texture="Button005_material" shininess="0.4472135901451111" specular="0.3103448502657381"/>
  </asset>
  <default>
    <default class="visual">
      <geom conaffinity="0" contype="0" group="1" type="mesh"/>
    </default>
    <default class="collision">
      <geom group="0" rgba="0.5 0 0 0.5"/>
    </default>
    <default class="spawn">
      <geom group="0" rgba="1 1 1 0.5" contype="0" conaffinity="0"/>
      <site group="0" rgba="1 1 1 0.5"/>
    </default>
    <default class="region">
      <geom group="1" conaffinity="0" contype="0" rgba="0 1 0 0"/>
    </default>
  </default>
  <worldbody>
    <body>
      <body name="object">
        <geom mesh="Body001_vis" type="mesh" solimp="0.998 0.998 0.001" solref="0.001 1" density="100" friction="0.95 0.3 0.1" class="visual" material="Body001_material"/>
        <geom class="collision" type="box" pos="0.00064009 0.02580616 -0.42287130" size="0.5037598013877869 0.26696163415908813 0.03394800052046776" quat="1.0 0.0 0.0 0.0"/>
        <geom class="collision" type="box" pos="-0.31719437 -0.26831469 -0.42287130" size="0.1857481598854065 0.02729858085513115 0.03394797071814537" quat="1.0 0.0 0.0 0.0"/>
        <geom class="collision" type="box" pos="0.31570554 -0.26697045 -0.42287130" size="0.19056837260723114 0.025034017860889435 0.03394797071814537" quat="1.0 0.0 0.0 0.0"/>
        <geom class="collision" type="box" pos="0.31266347 0.11266351 -0.37030990" size="0.15896327793598175 0.17897813022136688 0.032223429530858994" quat="0.987186074256897 0.0 0.15957336127758026 0.0"/>
        <geom class="collision" type="box" pos="-0.33161058 0.11266351 -0.37030990" size="0.15896327793598175 0.17897813022136688 0.032223429530858994" quat="0.14466482400894165 0.0 0.98948073387146 0.0"/>
        <geom class="collision" type="box" pos="-0.01238798 -0.11606847 -0.33617727" size="0.15896327793598175 0.1456536054611206 0.032223429530858994" quat="0.008614168502390385 -0.0006598452455364168 -0.9682444334030151 -0.24985621869564056"/>
        <geom class="collision" type="box" pos="-0.20751574 -0.14893661 -0.34842603" size="0.04558514803647995 0.11402983963489532 0.03025333397090435" quat="0.008614168502390385 -0.0006598452455364168 -0.9682444334030151 -0.24985621869564056"/>
        <geom class="collision" type="box" pos="-0.29803544 -0.19088629 -0.36894731" size="0.04558497667312622 0.06938584893941879 0.02718590945005417" quat="0.008614168502390385 -0.0006598452455364168 -0.9682444334030151 -0.24985621869564056"/>
        <geom class="collision" type="box" pos="-0.38909295 -0.21680780 -0.37989436" size="0.045580461621284485 0.042890068143606186 0.017412422224879265" quat="0.008614168502390385 -0.0006598452455364168 -0.9682444334030151 -0.24985621869564056"/>
        <geom class="collision" type="box" pos="-0.43163591 -0.11301628 -0.37875216" size="0.04558432102203369 0.04558131843805313 0.012735934928059578" quat="0.08819101750850677 0.703055739402771 0.700617253780365 0.08408591896295547"/>
        <geom class="collision" type="box" pos="-0.30200266 -0.11301628 -0.34952704" size="0.04558432102203369 0.04558131843805313 0.012735934928059578" quat="0.08819101750850677 0.703055739402771 0.700617253780365 0.08408591896295547"/>
        <geom class="collision" type="box" pos="0.31599716 -0.22037947 -0.37510599" size="0.04799279943108559 0.18398497998714447 0.01356036402285099" quat="0.16573308408260345 -0.6903117895126343 0.6758056879043579 0.19821415841579437"/>
        <geom class="collision" type="box" pos="0.34363080 -0.20567158 -0.40357907" size="0.04558431729674339 0.04558131843805313 0.012735934928059578" quat="0.10011235624551773 -0.6985071301460266 0.6562744379043579 0.2671501040458679"/>
        <geom class="collision" type="box" pos="0.35153974 -0.11522005 -0.37389175" size="0.1342732012271881 0.04291483759880066 0.024106070399284363" quat="0.008804059587419033 -0.9924291968345642 0.004050715360790491 0.1224353238940239"/>
        <geom class="collision" type="box" pos="0.19155692 -0.13033630 -0.32707976" size="0.04558156430721283 0.06852714717388153 0.016237616539001465" quat="0.09637093544006348 -0.995307981967926 0.003566374769434333 -0.007869507186114788"/>
        <geom class="collision" type="box" pos="-0.00510436 0.11143268 0.04978125" size="0.19184544682502747 0.18133512139320374 0.44018131494522095" quat="1.0 0.0 0.0 0.0"/>
        <geom class="collision" type="box" pos="-0.00064488 0.03036357 -0.47955949" size="0.06174424663186073 0.0338268056511879 0.02607591450214386" quat="1.0 0.0 0.0 0.0"/>
        <geom class="collision" type="box" pos="-0.00255465 -0.26584899 -0.44955705" size="0.12739261984825134 0.02198578417301178 0.007262250408530235" quat="1.0 0.0 0.0 0.0"/>
        <geom class="collision" type="box" pos="-0.00255465 -0.26584899 -0.40243329" size="0.12739261984825134 0.02198578417301178 0.012835061177611351" quat="1.0 0.0 0.0 0.0"/>
        <geom class="collision" type="box" pos="-0.36666274 -0.11301628 -0.36465354" size="0.04558432102203369 0.04558131843805313 0.012735934928059578" quat="0.08819101750850677 0.703055739402771 0.700617253780365 0.08408591896295547"/>
        <geom class="collision" type="box" pos="-0.36666274 -0.16779558 -0.36465354" size="0.04558432102203369 0.04558131843805313 0.012735934928059578" quat="0.08819101750850677 0.703055739402771 0.700617253780365 0.08408591896295547"/>
        <geom class="collision" type="box" pos="-0.44082224 -0.16779558 -0.38866429" size="0.04558432102203369 0.04558131843805313 0.012735934928059578" quat="0.08819101750850677 0.703055739402771 0.700617253780365 0.08408591896295547"/>
        <geom class="collision" type="box" pos="-0.44082224 -0.21837109 -0.39354901" size="0.04558432102203369 0.04558131843805313 0.012735934928059578" quat="0.08819101750850677 0.703055739402771 0.700617253780365 0.08408591896295547"/>
        <body name="Button001">
          <joint axis="0.0 0.9999999403953552 0.0" pos="-0.08777314 -0.28983393 -0.42941339" limited="true" name="Button001_joint" range="0.0 0.003" type="slide" damping="1" frictionloss="1" armature=".01" stiffness="0.05"/>
          <geom mesh="Button001_vis" type="mesh" solimp="0.998 0.998 0.001" solref="0.001 1" density="100" friction="0.95 0.3 0.1" class="visual" material="Button001_material"/>
          <geom class="collision" type="box" pos="-0.08789238 -0.28775412 -0.43009843" size="0.019130781292915344 0.004477586131542921 0.005090134683996439" quat="1.0 0.0 0.0 0.0"/>
        </body>
        <body name="Button002">
          <joint axis="0.0 0.9999999403953552 0.0" pos="-0.04429620 -0.28983384 -0.42941339" limited="true" name="Button002_joint" range="0.0 0.003" type="slide" damping="1" frictionloss="1" armature=".01" stiffness="0.05"/>
          <geom mesh="Button002_vis" type="mesh" solimp="0.998 0.998 0.001" solref="0.001 1" density="100" friction="0.95 0.3 0.1" class="visual" material="Button002_material"/>
          <geom class="collision" type="box" pos="-0.04534010 -0.28775412 -0.43009843" size="0.019130809232592583 0.004477586131542921 0.005090134683996439" quat="1.0 0.0 0.0 0.0"/>
        </body>
        <body name="Button003">
          <joint axis="0.0 0.9999999403953552 0.0" pos="-0.00095392 -0.28983384 -0.42941339" limited="true" name="Button003_joint" range="0.0 0.003" type="slide" damping="1" frictionloss="1" armature=".01" stiffness="0.05"/>
          <geom mesh="Button003_vis" type="mesh" solimp="0.998 0.998 0.001" solref="0.001 1" density="100" friction="0.95 0.3 0.1" class="visual" material="Button003_material"/>
          <geom class="collision" type="box" pos="-0.00164125 -0.28775412 -0.43009843" size="0.01913083903491497 0.004477586131542921 0.005090134683996439" quat="1.0 0.0 0.0 0.0"/>
        </body>
        <body name="Button004">
          <joint axis="0.0 0.9999999403953552 0.0" pos="0.04431940 -0.28983396 -0.42941339" limited="true" name="Button004_joint" range="0.0 0.003" type="slide" damping="1" frictionloss="1" armature=".01" stiffness="0.05"/>
          <geom mesh="Button004_vis" type="mesh" solimp="0.998 0.998 0.001" solref="0.001 1" density="100" friction="0.95 0.3 0.1" class="visual" material="Button004_material"/>
          <geom class="collision" type="box" pos="0.04350705 -0.28775412 -0.43009843" size="0.019130868837237358 0.004477586131542921 0.005090134683996439" quat="1.0 0.0 0.0 0.0"/>
        </body>
        <body name="Button005">
          <joint axis="0.0 1.0 0.0" pos="0.08904840 -0.28983393 -0.42941339" limited="true" name="Button005_joint" range="0.0 0.003" type="slide" damping="1" frictionloss="1" armature=".01" stiffness="0.05"/>
          <geom mesh="Button005_vis" type="mesh" solimp="0.998 0.998 0.001" solref="0.001 1" density="100" friction="0.95 0.3 0.1" class="visual" material="Button005_material"/>
          <geom class="collision" type="box" pos="0.08968077 -0.28775412 -0.43009843" size="0.019130896776914597 0.004477586131542921 0.005090134683996439" quat="1.0 0.0 0.0 0.0"/>
        </body>
        <geom class="region" name="reg_main" type="box" pos="-0.0002617749999999919 0.0024479550000000017 -2.1999999999522402e-07" size="0.504001695 0.489424065 0.29084618"/>
      </body>
    </body>
  </worldbody>
  <actuator>
    <motor name="Button001_joint_actuator" joint="Button001_joint" gear="0.5"/>
    <motor name="Button002_joint_actuator" joint="Button002_joint" gear="0.5"/>
    <motor name="Button003_joint_actuator" joint="Button003_joint" gear="0.5"/>
    <motor name="Button004_joint_actuator" joint="Button004_joint" gear="0.5"/>
    <motor name="Button005_joint_actuator" joint="Button005_joint" gear="0.5"/>
  </actuator>
</mujoco>
