<?xml version='1.0' encoding='UTF-8'?>
<mujoco model="model">
  <option timestep="0.002" gravity="0.0 0.0 -9.81"/>
  <compiler angle="radian"/>
  <asset>
    <mesh file="visuals/button_lock.obj" name="button_lock_vis"/>
    <mesh file="visuals/button_power.obj" name="button_power_vis"/>
    <mesh file="visuals/Body001.obj" name="Body001_vis"/>
    <mesh file="visuals/door.obj" name="door_vis"/>
    <mesh file="visuals/rack0.obj" name="rack0_vis"/>
    <mesh file="visuals/rack1.obj" name="rack1_vis"/>
    <texture file="visuals/T_BC001.png" name="Body001_material" type="2d"/>
    <material name="Body001_material" rgba="1 1 1 1.0" texture="Body001_material" shininess="0.1" specular="6"/>
    <texture file="visuals/T_BC001.png" name="door_material" type="2d"/>
    <material name="door_material" rgba="1 1 1 1.0" texture="door_material" shininess="0.1" specular="6"/>
    <texture file="visuals/T_BC001.png" name="button_lock_material" type="2d"/>
    <material name="button_lock_material" rgba="1 1 1 1.0" texture="button_lock_material" shininess="0.1" specular="6"/>
    <texture file="visuals/T_BC001.png" name="button_power_material" type="2d"/>
    <material name="button_power_material" rgba="1 1 1 1.0" texture="button_power_material" shininess="0.1" specular="6"/>
    <texture file="visuals/T_BC001.png" name="rack0_material" type="2d"/>
    <material name="rack0_material" rgba="1 1 1 1.0" texture="rack0_material" shininess="0.1" specular="6"/>
    <texture file="visuals/T_BC001.png" name="rack1_material" type="2d"/>
    <material name="rack1_material" rgba="1 1 1 1.0" texture="rack1_material" shininess="0.1" specular="6"/>
  </asset>
  <default>
    <default class="visual">
      <geom conaffinity="0" contype="0" group="1" type="mesh"/>
    </default>
    <default class="collision">
      <geom group="0" rgba="0.5 0 0 0.5"/>
    </default>
    <default class="spawn">
      <geom group="0" rgba="1 1 1 0.5" contype="0" conaffinity="0"/>
      <site group="0" rgba="1 1 1 0.5"/>
    </default>
    <default class="region">
      <geom group="1" conaffinity="0" contype="0" rgba="0 1 0 0"/>
    </default>
  </default>
  <worldbody>
    <body>
      <body name="object">
        <geom mesh="Body001_vis" type="mesh" solimp="0.998 0.998 0.001" solref="0.001 1" friction="0.95 0.3 0.1" class="visual" material="Body001_material"/>
        <geom class="collision" type="box" pos="0.0015593958087265491 0.03263065218925476 0.46358102560043335" size="0.29325568675994873 0.2784905433654785 0.01083672046661377" quat="1.0 0.0 0.0 0.0"/>
        <geom class="collision" type="box" pos="0.3084561228752136 0.04954814165830612 0.006293192505836487" size="0.013749126344919205 0.2954080104827881 0.46812450885772705" quat="1.0 0.0 0.0 0.0"/>
        <geom class="collision" type="box" pos="-0.3065454959869385 0.04954812675714493 0.006293192505836487" size="0.015659794211387634 0.2954079508781433 0.46812450885772705" quat="1.0 0.0 0.0 0.0"/>
        <geom class="collision" type="box" pos="0.00155941816046834 0.32865333557128906 0.006293192505836487" size="0.29325568675994873 0.016302794218063354 0.46812450885772705" quat="1.0 0.0 0.0 0.0"/>
        <geom class="collision" type="box" pos="-0.0003859625430777669 0.04952313005924225 -0.4698579013347626" size="0.31707763671875 0.295432984828949 0.00802655890583992" quat="1.0 0.0 0.0 0.0"/>
        <geom class="collision" type="box" pos="0.2874239683151245 0.048035819083452225 0.19780318439006805" size="0.007391098886728287 0.2839532494544983 0.0018048726487904787" quat="1.0 0.0 0.0 0.0"/>
        <geom class="collision" type="box" pos="-0.28673526644706726 0.048035819083452225 0.19780318439006805" size="0.004961001221090555 0.2839532494544983 0.0018048726487904787" quat="1.0 0.0 0.0 0.0"/>
        <geom class="collision" type="box" pos="-0.28673526644706726 0.048035819083452225 -0.09955725073814392" size="0.004961001221090555 0.2839532494544983 0.0018048763740807772" quat="1.0 0.0 0.0 0.0"/>
        <geom class="collision" type="box" pos="0.2874239683151245 0.048035819083452225 -0.09955725073814392" size="0.007391098886728287 0.2839532494544983 0.0018048763740807772" quat="1.0 0.0 0.0 0.0"/>
        <body name="door">
          <joint axis="1.0 0.0 0.0" pos="-0.00024969506193883717 -0.29217201471328735 -0.47744888067245483" limited="true" name="door_joint" range="0.0 0.5235987755982988" type="hinge" damping="1" frictionloss="1" armature=".01" stiffness="0.05"/>
          <geom mesh="door_vis" type="mesh" solimp="0.998 0.998 0.001" solref="0.001 1" friction="0.95 0.3 0.1" class="visual" material="door_material"/>
          <geom class="collision" type="box" pos="-0.001718308194540441 -0.27046892046928406 0.01473449170589447" size="0.31452664732933044 0.02164296619594097 0.4582974910736084" quat="1.0 0.0 0.0 0.0" name="door_main"/>
          <geom class="collision" type="box" pos="0.24632082879543304 -0.3101164698600769 0.398721843957901" size="0.012813650071620941 0.019381284713745117 0.0163764376193285" quat="0.7309410572052002 0.0 0.6824405789375305 0.0"/>
          <geom class="collision" type="box" pos="-0.2380959391593933 -0.3101164698600769 0.3988521695137024" size="0.012395946308970451 0.019381269812583923 0.01675279811024666" quat="0.7309410572052002 0.0 0.6824405789375305 0.0"/>
          <geom class="collision" type="cylinder" pos="0.003888395382091403 -0.33332085609436035 0.3999674916267395" size="0.012235971167683601 0.2582305371761322" quat="0.7071068286895752 1.2101618374060763e-08 0.7071067690849304 -1.2101617485882343e-08" name="door_handle_main"/>
          <body name="button_lock">
            <joint axis="0.0 0.0 -1.0" pos="-0.18298566341400146 -0.266629695892334 0.47530895471572876" limited="true" name="button_lock_joint" range="0.0 0.002" type="slide" damping="1" frictionloss="1" armature=".01" stiffness="0.05" springref="-5"/>
            <geom mesh="button_lock_vis" type="mesh" solimp="0.998 0.998 0.001" solref="0.001 1" friction="0.95 0.3 0.1" class="visual" material="button_lock_material"/>
            <geom class="collision" type="cylinder" pos="-0.18283316493034363 -0.2666301429271698 0.4759465456008911" size="0.009277576580643654 0.002105482155457139" quat="0.7071067094802856 0.0 -0.0 -0.7071068286895752"/>
          </body>
          <body name="button_power">
            <joint axis="0.0 0.0 -1.0" pos="0.18145567178726196 -0.26662978529930115 0.47530892491340637" limited="true" name="button_power_joint" range="0.0 0.002" type="slide" damping="1" frictionloss="1" armature=".01" stiffness="0.05" springref="-5"/>
            <geom mesh="button_power_vis" type="mesh" solimp="0.998 0.998 0.001" solref="0.001 1" friction="0.95 0.3 0.1" class="visual" material="button_power_material"/>
            <geom class="collision" type="cylinder" pos="0.18147970736026764 -0.2666301429271698 0.4759465456008911" size="0.009277576580643654 0.002105482155457139" quat="0.7071067094802856 0.0 -0.0 -0.7071068286895752"/>
          </body>
        </body>
        <body name="rack0">
          <geom class="region" name="reg_rack0" type="box" pos="-0.003179393708705902 0.05233059823513031 -0.0552699901163578" size="0.25211372023820877 0.24420031702518463 0.12110277435183525"/>
          <joint axis="0.0 -1.0 0.0" pos="-0.0016351775266230106 0.05106532201170921 -0.15279370546340942" limited="true" name="rack0_joint" range="0.0 0.2" type="slide" damping="1" frictionloss="1" armature=".01" stiffness="0.05"/>
          <geom mesh="rack0_vis" type="mesh" solimp="0.998 0.998 0.001" solref="0.001 1" friction="0.95 0.3 0.1" class="visual" material="rack0_material"/>
          <geom class="collision" type="box" pos="0.05465549975633621 0.05172783136367798 -0.15919500589370728" size="0.0019640550017356873 0.20299112796783447 0.026353538036346436" quat="1.0 0.0 0.0 0.0"/>
          <geom class="collision" type="box" pos="-0.04838342219591141 0.05172783136367798 -0.15919500589370728" size="0.0019640550017356873 0.20299112796783447 0.026353538036346436" quat="1.0 0.0 0.0 0.0"/>
          <geom class="collision" type="box" pos="-0.1368914544582367 0.05172783136367798 -0.15919500589370728" size="0.0019640550017356873 0.20299112796783447 0.026353538036346436" quat="1.0 0.0 0.0 0.0"/>
          <geom class="collision" type="box" pos="-0.2237427532672882 0.05172783136367798 -0.15919500589370728" size="0.0019640550017356873 0.20299112796783447 0.026353538036346436" quat="1.0 0.0 0.0 0.0"/>
          <geom class="collision" type="box" pos="-0.003178747370839119 0.050885796546936035 -0.20264820754528046" size="0.2567950189113617 0.2505642771720886 0.021035809069871902" quat="1.0 0.0 0.0 0.0"/>
          <geom class="collision" type="box" pos="-0.27093368768692017 0.052033431828022 -0.1449436992406845" size="0.010546132922172546 0.24883143603801727 0.05987343564629555" quat="1.0 0.0 0.0 0.0"/>
          <geom class="collision" type="box" pos="0.2640065550804138 0.052033431828022 -0.1449436992406845" size="0.010546132922172546 0.24883143603801727 0.05987343564629555" quat="1.0 0.0 0.0 0.0"/>
          <geom class="collision" type="box" pos="-0.00012752600014209747 -0.2029542475938797 -0.15362104773521423" size="0.27703744173049927 0.005895007401704788 0.07006293535232544" quat="1.0 0.0 0.0 0.0"/>
          <geom class="collision" type="box" pos="0.21544146537780762 0.05172783136367798 -0.15919500589370728" size="0.0019640550017356873 0.20299112796783447 0.026353538036346436" quat="1.0 0.0 0.0 0.0"/>
          <geom class="collision" type="box" pos="-0.00012752600014209747 0.3066815435886383 -0.15362104773521423" size="0.27703744173049927 0.005895007401704788 0.07006293535232544" quat="1.0 0.0 0.0 0.0"/>
        </body>
        <body name="rack1">
          <geom class="region" name="reg_rack1" type="box" pos="-0.003179393708705902 0.05233059823513031 0.28276923298835754" size="0.25211372023820877 0.24420031702518463 0.16516877508163452"/>
          <joint axis="0.0 -1.0 0.0" pos="-0.001635176595300436 0.05106532573699951 0.14311833679676056" limited="true" name="rack1_joint" range="0.0 0.33" type="slide" damping="1" frictionloss="1" armature=".01" stiffness="0.05"/>
          <geom mesh="rack1_vis" type="mesh" solimp="0.998 0.998 0.001" solref="0.001 1" friction="0.95 0.3 0.1" class="visual" material="rack1_material"/>
          <geom class="collision" type="box" pos="-0.00012752600014209747 0.3066815435886383 0.14050063490867615" size="0.27703744173049927 0.005895007401704788 0.07006293535232544" quat="1.0 0.0 0.0 0.0"/>
          <geom class="collision" type="box" pos="-0.00012752600014209747 -0.2029542475938797 0.14050063490867615" size="0.27703744173049927 0.005895007401704788 0.07006293535232544" quat="1.0 0.0 0.0 0.0"/>
          <geom class="collision" type="box" pos="0.2640065550804138 0.052033431828022 0.14917798340320587" size="0.010546132922172546 0.24883143603801727 0.05987343564629555" quat="1.0 0.0 0.0 0.0"/>
          <geom class="collision" type="box" pos="-0.27093368768692017 0.052033431828022 0.14917798340320587" size="0.010546132922172546 0.24883143603801727 0.05987343564629555" quat="1.0 0.0 0.0 0.0"/>
          <geom class="collision" type="box" pos="-0.003178747370839119 0.050885796546936035 0.09147347509860992" size="0.2567950189113617 0.2505642771720886 0.021035809069871902" quat="1.0 0.0 0.0 0.0"/>
          <geom class="collision" type="box" pos="-0.2237427532672882 0.05172783136367798 0.1349266767501831" size="0.0019640550017356873 0.20299112796783447 0.026353538036346436" quat="1.0 0.0 0.0 0.0"/>
          <geom class="collision" type="box" pos="-0.1368914544582367 0.05172783136367798 0.1349266767501831" size="0.0019640550017356873 0.20299112796783447 0.026353538036346436" quat="1.0 0.0 0.0 0.0"/>
          <geom class="collision" type="box" pos="-0.04838342219591141 0.05172783136367798 0.1349266767501831" size="0.0019640550017356873 0.20299112796783447 0.026353538036346436" quat="1.0 0.0 0.0 0.0"/>
          <geom class="collision" type="box" pos="0.05465549975633621 0.05172783136367798 0.1349266767501831" size="0.0019640550017356873 0.20299112796783447 0.026353538036346436" quat="1.0 0.0 0.0 0.0"/>
          <geom class="collision" type="box" pos="0.21544146537780762 0.05172783136367798 0.1349266767501831" size="0.0019640550017356873 0.20299112796783447 0.026353538036346436" quat="1.0 0.0 0.0 0.0"/>
        </body>
        <geom class="region" name="reg_int" type="box" pos="-0.0010293275117874146 0.044862449169158936 -0.0045640915632247925" size="0.27594703233242035 0.26291994547843933 0.45250209963321686"/>
        <geom class="region" name="reg_main" type="box" pos="0.0 0.02642211690545082 -0.00173337257001549" size="0.32320524549484253 0.3195340464115143 0.47715107893943787"/>
      </body>
    </body>
  </worldbody>
  <actuator>
    <motor name="door_joint_actuator" joint="door_joint" gear="50"/>
    <motor name="rack0_joint_actuator" joint="rack0_joint" gear="50"/>
    <motor name="rack1_joint_actuator" joint="rack1_joint" gear="50"/>
    <motor name="button_lock_joint_actuator" joint="button_lock_joint" gear="0.5"/>
    <motor name="button_power_joint_actuator" joint="button_power_joint" gear="0.5"/>
  </actuator>
</mujoco>
