<?xml version='1.0' encoding='UTF-8'?>
<mujoco model="model">
  <option timestep="0.002" gravity="0.0 0.0 -9.81"/>
  <compiler angle="radian"/>
  <asset>
    <mesh file="visuals/button_lock.obj" name="button_lock_vis"/>
    <mesh file="visuals/button_power.obj" name="button_power_vis"/>
    <mesh file="visuals/Body001.obj" name="Body001_vis"/>
    <mesh file="visuals/Handle001.obj" name="Handle001_vis"/>
    <mesh file="visuals/door.obj" name="door_vis"/>
    <mesh file="visuals/rack0.obj" name="rack0_vis"/>
    <mesh file="visuals/rack1.obj" name="rack1_vis"/>
    <texture file="visuals/T_BC001.png" name="Body001_material" type="2d"/>
    <material name="Body001_material" rgba="1 1 1 1.0" texture="Body001_material" shininess="0.4472135901451111" specular="2"/>
    <texture file="visuals/T_BC001.png" name="door_material" type="2d"/>
    <material name="door_material" rgba="1 1 1 1.0" texture="door_material" shininess="0.4472135901451111" specular="2"/>
    <texture file="visuals/T_BC001.png" name="button_lock_material" type="2d"/>
    <material name="button_lock_material" rgba="1 1 1 1.0" texture="button_lock_material" shininess="0.4472135901451111" specular="0.3103448502657381"/>
    <texture file="visuals/T_BC001.png" name="button_power_material" type="2d"/>
    <material name="button_power_material" rgba="1 1 1 1.0" texture="button_power_material" shininess="0.4472135901451111" specular="0.3103448502657381"/>
    <texture file="visuals/T_BC001.png" name="Handle001_material" type="2d"/>
    <material name="Handle001_material" rgba="1 1 1 1.0" texture="Handle001_material" shininess="0.4472135901451111" specular="2"/>
    <texture file="visuals/T_BC001.png" name="rack0_material" type="2d"/>
    <material name="rack0_material" rgba="1 1 1 1.0" texture="rack0_material" shininess="0.4472135901451111" specular="3"/>
    <texture file="visuals/T_BC001.png" name="rack1_material" type="2d"/>
    <material name="rack1_material" rgba="1 1 1 1.0" texture="rack1_material" shininess="0.4472135901451111" specular="3"/>
  </asset>
  <default>
    <default class="visual">
      <geom conaffinity="0" contype="0" group="1" type="mesh"/>
    </default>
    <default class="collision">
      <geom group="0" rgba="0.5 0 0 0.5"/>
    </default>
    <default class="spawn">
      <geom group="0" rgba="1 1 1 0.5" contype="0" conaffinity="0"/>
      <site group="0" rgba="1 1 1 0.5"/>
    </default>
    <default class="region">
      <geom group="1" conaffinity="0" contype="0" rgba="0 1 0 0"/>
    </default>
  </default>
  <worldbody>
    <body>
      <body name="object">
        <geom mesh="Body001_vis" type="mesh" solimp="0.998 0.998 0.001" solref="0.001 1" friction="0.95 0.3 0.1" class="visual" material="Body001_material"/>
        <geom class="collision" type="box" pos="-0.0007308664498850703 0.04895145446062088 0.4154976010322571" size="0.2864617109298706 0.24833838641643524 0.006697902921587229" quat="1.0 0.0 0.0 0.0"/>
        <geom class="collision" type="box" pos="-0.0007308664498850703 0.29252055287361145 0.044159505516290665" size="0.2864617109298706 0.004769292660057545 0.3780360221862793" quat="1.0 0.0 0.0 0.0"/>
        <geom class="collision" type="box" pos="-0.0007308664498850703 0.08336932212114334 -0.3714729845523834" size="0.2864617109298706 0.21392053365707397 0.05072249844670296" quat="1.0 0.0 0.0 0.0"/>
        <geom class="collision" type="box" pos="-0.27702757716178894 0.050713278353214264 0.042341411113739014" size="0.010165002197027206 0.24657657742500305 0.3788338303565979" quat="1.0 0.0 0.0 0.0"/>
        <geom class="collision" type="box" pos="-0.0007308664498850703 0.05071329325437546 -0.32871487736701965" size="0.2864617109298706 0.24657657742500305 0.007777574937790632" quat="1.0 0.0 0.0 0.0"/>
        <geom class="collision" type="box" pos="0.276434987783432 0.05082811415195465 0.042341411113739014" size="0.009608753956854343 0.24646174907684326 0.3788338303565979" quat="1.0 0.0 0.0 0.0"/>
        <geom class="collision" type="box" pos="-0.2538895308971405 0.047974489629268646 0.13629180192947388" size="0.01698312535881996 0.1966976374387741 0.00530070997774601" quat="1.0 0.0 0.0 0.0"/>
        <geom class="collision" type="box" pos="-0.2538900375366211 0.047974489629268646 -0.1410522311925888" size="0.016982611268758774 0.1966976374387741 0.0054292804561555386" quat="1.0 0.0 0.0 0.0"/>
        <geom class="collision" type="box" pos="0.25260430574417114 0.047974489629268646 -0.14113499224185944" size="0.01738894172012806 0.1966976374387741 0.005433524027466774" quat="1.0 0.0 0.0 0.0"/>
        <geom class="collision" type="box" pos="0.2525676190853119 0.047974489629268646 0.1362708956003189" size="0.017425650730729103 0.1966976374387741 0.005538972094655037" quat="1.0 0.0 0.0 0.0"/>
        <body name="door">
          <joint axis="1.0 0.0 0.0" pos="-7.450580596923828e-09 -0.19827471673488617 -0.33413323760032654" limited="true" name="door_joint" range="0.0 0.5235987755982988" type="hinge" damping="1" frictionloss="1" armature=".01" stiffness="0.2" springref="-100"/>
          <geom mesh="door_vis" type="mesh" solimp="0.998 0.998 0.001" solref="0.001 1" friction="0.95 0.3 0.1" class="visual" material="door_material"/>
          <geom class="collision" type="box" pos="0.004816306754946709 -0.28483542799949646 0.38173919916152954" size="0.1246873065829277 0.009063882753252983 0.019917838275432587" quat="1.0 0.0 0.0 0.0" name="door_handle_main"/>
          <geom class="collision" type="box" pos="0.0010703494772315025 -0.1895136833190918 0.039994124323129654" size="0.25574666261672974 0.03456544503569603 0.3404856324195862" quat="1.0 0.0 0.0 0.0"/>
          <geom class="collision" type="box" pos="-0.0004612865159288049 -0.22557859122753143 0.037790607661008835" size="0.29725509881973267 0.02568775601685047 0.37400493025779724" quat="1.0 0.0 0.0 0.0" name="door_main"/>
          <body name="button_lock">
            <joint axis="0.0 0.0 -1.0" pos="0.09270655363798141 -0.2257876992225647 0.41416501998901367" limited="true" name="button_lock_joint" range="0.0 0.002" type="slide" damping="1" frictionloss="1" armature=".01" stiffness="0.2" springref="-1"/>
            <geom mesh="button_lock_vis" type="mesh" solimp="0.998 0.998 0.001" solref="0.001 1" friction="0.95 0.3 0.1" class="visual" material="button_lock_material"/>
            <geom class="collision" type="cylinder" pos="0.09289846569299698 -0.22610458731651306 0.41483697295188904" size="0.008599499240517616 0.0025725311134010553" quat="1.0 0.0 0.0 0.0"/>
          </body>
          <body name="button_power">
            <joint axis="0.0 0.0 -1.0" pos="-0.15545640885829926 -0.2257876992225647 0.41416501998901367" limited="true" name="button_power_joint" range="0.0 0.002" type="slide" damping="1" frictionloss="1" armature=".01" stiffness="0.2" springref="-1"/>
            <geom mesh="button_power_vis" type="mesh" solimp="0.998 0.998 0.001" solref="0.001 1" friction="0.95 0.3 0.1" class="visual" material="button_power_material"/>
            <geom class="collision" type="cylinder" pos="-0.15556800365447998 -0.22610458731651306 0.41483697295188904" size="0.008599499240517616 0.0025725311134010553" quat="1.0 0.0 0.0 0.0"/>
          </body>
          <body name="Handle001">
            <geom mesh="Handle001_vis" type="mesh" solimp="0.998 0.998 0.001" solref="0.001 1" friction="0.95 0.3 0.1" class="visual" material="Handle001_material"/>
            <geom class="collision" type="box" pos="-0.1918780654668808 -0.2753402292728424 0.38173919916152954" size="0.06897824257612228 0.008954321034252644 0.019917838275432587" quat="7.537573765148409e-08 0.9983819723129272 -0.05686357989907265 -4.2930836663401806e-09"/>
            <geom class="collision" type="box" pos="-0.25305619835853577 -0.2562609612941742 0.38173919916152954" size="0.03264765068888664 0.015286944806575775 0.019917840138077736" quat="1.0 0.0 0.0 0.0"/>
            <geom class="collision" type="box" pos="0.19730180501937866 -0.27565431594848633 0.38173919916152954" size="0.06720057874917984 0.009000045247375965 0.019917838275432587" quat="0.9983651638031006 0.0 0.0 0.05715736001729965"/>
            <geom class="collision" type="box" pos="0.25259682536125183 -0.2562609612941742 0.38173919916152954" size="0.03264765068888664 0.015286942012608051 0.019917838275432587" quat="1.0 0.0 0.0 0.0"/>
          </body>
        </body>
        <body name="rack0">
          <geom class="region" name="reg_rack0" type="box" pos="-0.0010978206992149353 0.044897567480802536 -0.016848962754011154" size="0.2135975862145424 0.16527851095795631 0.11713335087895393"/>
          <joint axis="0.0 -1.0 0.0" pos="-0.0005671530961990356 0.053624846041202545 -0.08571070432662964" limited="true" name="rack0_joint" range="0.0 0.15" type="slide" damping="1" frictionloss="1" armature=".01" stiffness="0.05"/>
          <geom mesh="rack0_vis" type="mesh" solimp="0.998 0.998 0.001" solref="0.001 1" friction="0.95 0.3 0.1" class="visual" material="rack0_material"/>
          <geom class="collision" type="box" pos="0.09176896512508392 0.13317346572875977 -0.10503849387168884" size="0.10970109701156616 0.04568517208099365 0.0021208375692367554" quat="0.8271735906600952 0.5619465112686157 0.0 0.0"/>
          <geom class="collision" type="box" pos="-0.09200833737850189 0.09679260849952698 -0.10503849387168884" size="0.10970109701156616 0.04568517208099365 0.0021208375692367554" quat="0.8196538686752319 -0.5728591084480286 -0.0 0.0"/>
          <geom class="collision" type="box" pos="6.531881081173196e-05 0.050771839916706085 -0.1435907781124115" size="0.21681302785873413 0.15988022089004517 0.006917460821568966" quat="1.0 0.0 0.0 0.0"/>
          <geom class="collision" type="box" pos="-0.09200833737850189 0.19232936203479767 -0.10503849387168884" size="0.10970109701156616 0.04568517208099365 0.0021208375692367554" quat="0.8269923329353333 -0.5622132420539856 -0.0 0.0"/>
          <geom class="collision" type="box" pos="-0.22672180831432343 0.053505830466747284 -0.13750335574150085" size="0.006607782561331987 0.1802425980567932 0.025888554751873016" quat="1.0 0.0 0.0 0.0"/>
          <geom class="collision" type="box" pos="0.09176896512508392 0.22809265553951263 -0.10503849387168884" size="0.10970109701156616 0.045685168355703354 0.0021208375692367554" quat="0.8360558748245239 0.5486443042755127 0.0 0.0"/>
          <geom class="collision" type="box" pos="0.09176896512508392 0.04704730957746506 -0.10503849387168884" size="0.10970109701156616 0.04568517208099365 0.0021208375692367554" quat="0.8247002959251404 0.5655699968338013 0.0 0.0"/>
          <geom class="collision" type="box" pos="0.2251373827457428 0.053505830466747284 -0.13750335574150085" size="0.008000245317816734 0.1802425980567932 0.025888554751873016" quat="1.0 0.0 0.0 0.0"/>
          <geom class="collision" type="box" pos="-0.09200833737850189 0.010133296251296997 -0.10503849387168884" size="0.10970109701156616 0.04568517208099365 0.0021208375692367554" quat="0.8239781260490417 -0.5666216015815735 -0.0 0.0"/>
          <geom class="collision" type="box" pos="0.000461384654045105 0.2441696971654892 -0.06156189739704132" size="0.25434809923171997 0.010039759799838066 0.05720686912536621" quat="1.0 0.0 0.0 0.0"/>
          <geom class="collision" type="box" pos="0.000461384654045105 -0.13955336809158325 -0.06156190484762192" size="0.25434809923171997 0.010039759799838066 0.05720686912536621" quat="1.0 0.0 0.0 0.0"/>
          <geom class="collision" type="box" pos="-0.09200833737850189 -0.0854034572839737 -0.10503849387168884" size="0.10970109701156616 0.04568517208099365 0.0021208375692367554" quat="0.8237256407737732 -0.5669885873794556 -0.0 0.0"/>
          <geom class="collision" type="box" pos="-0.24917161464691162 0.053505830466747284 -0.06156190484762192" size="0.007331531494855881 0.1802425980567932 0.05720686912536621" quat="1.0 0.0 0.0 0.0"/>
          <geom class="collision" type="box" pos="0.09176896512508392 -0.048489440232515335 -0.10503849387168884" size="0.10970109701156616 0.04568517208099365 0.0021208375692367554" quat="0.8262253999710083 0.5633396506309509 0.0 0.0"/>
          <geom class="collision" type="box" pos="6.531881081173196e-05 0.2314874827861786 -0.1437162458896637" size="0.21681302785873413 0.023353757336735725 0.005816212855279446" quat="0.8835728764533997 0.4682937264442444 0.0 0.0"/>
          <geom class="collision" type="box" pos="6.531881081173196e-05 0.20617595314979553 -0.16044867038726807" size="0.21681302785873413 0.014112870208919048 0.00483235577121377" quat="1.0 0.0 0.0 0.0"/>
          <geom class="collision" type="box" pos="6.531881081173196e-05 -0.09492834657430649 -0.16044867038726807" size="0.21681302785873413 0.014112870208919048 0.00483235577121377" quat="1.0 0.0 0.0 0.0"/>
          <geom class="collision" type="box" pos="6.531881081173196e-05 -0.12206308543682098 -0.14495313167572021" size="0.21681302785873413 0.023353757336735725 0.0036130030639469624" quat="0.8835728764533997 -0.4682937264442444 -0.0 0.0"/>
          <geom class="collision" type="box" pos="0.24833625555038452 0.053505830466747284 -0.06156190484762192" size="0.007331531494855881 0.1802425980567932 0.05720686912536621" quat="1.0 0.0 0.0 0.0"/>
        </body>
        <body name="rack1">
          <geom class="region" name="reg_rack1" type="box" pos="-0.0010978206992149353 0.044897567480802536 0.2701593115925789" size="0.2135975862145424 0.16527851095795631 0.13321292942762375"/>
          <joint axis="0.0 -1.0 0.0" pos="-0.0005671530961990356 0.053624846041202545 0.18605315685272217" limited="true" name="rack1_joint" range="0.0 0.31" type="slide" damping="1" frictionloss="1" armature=".01" stiffness="0.05"/>
          <geom mesh="rack1_vis" type="mesh" solimp="0.998 0.998 0.001" solref="0.001 1" friction="0.95 0.3 0.1" class="visual" material="rack1_material"/>
          <geom class="collision" type="box" pos="0.24833625555038452 0.053505830466747284 0.21020197868347168" size="0.007331531494855881 0.1802425980567932 0.05720686912536621" quat="1.0 0.0 0.0 0.0"/>
          <geom class="collision" type="box" pos="-0.24917161464691162 0.053505830466747284 0.21020197868347168" size="0.007331531494855881 0.1802425980567932 0.05720686912536621" quat="1.0 0.0 0.0 0.0"/>
          <geom class="collision" type="box" pos="0.000461384654045105 -0.13955336809158325 0.21020197868347168" size="0.25434809923171997 0.010039759799838066 0.05720686912536621" quat="1.0 0.0 0.0 0.0"/>
          <geom class="collision" type="box" pos="0.000461384654045105 0.2441696971654892 0.21020197868347168" size="0.25434809923171997 0.010039759799838066 0.05720686912536621" quat="1.0 0.0 0.0 0.0"/>
          <geom class="collision" type="box" pos="0.22445058822631836 0.053505830466747284 0.13426053524017334" size="0.008687043562531471 0.1802425980567932 0.025888554751873016" quat="1.0 0.0 0.0 0.0"/>
          <geom class="collision" type="box" pos="-0.22542807459831238 0.053505830466747284 0.13426053524017334" size="0.00790152233093977 0.1802425980567932 0.025888554751873016" quat="1.0 0.0 0.0 0.0"/>
          <geom class="collision" type="box" pos="6.531881081173196e-05 0.05021416395902634 0.1281730979681015" size="0.21681302785873413 0.16043789684772491 0.006917460821568966" quat="1.0 0.0 0.0 0.0"/>
          <geom class="collision" type="box" pos="6.531881081173196e-05 -0.12214559316635132 0.1267547607421875" size="0.21681302785873413 0.023353757336735725 0.0035132935736328363" quat="0.8835728764533997 -0.4682937264442444 -0.0 0.0"/>
          <geom class="collision" type="box" pos="6.531881081173196e-05 -0.09492834657430649 0.11131522059440613" size="0.21681302785873413 0.014112870208919048 0.00483235577121377" quat="1.0 0.0 0.0 0.0"/>
          <geom class="collision" type="box" pos="6.531881081173196e-05 0.20617595314979553 0.11131522059440613" size="0.21681302785873413 0.014112870208919048 0.00483235577121377" quat="1.0 0.0 0.0 0.0"/>
          <geom class="collision" type="box" pos="6.531881081173196e-05 0.2314874827861786 0.1280476301908493" size="0.21681302785873413 0.023353757336735725 0.005816212855279446" quat="0.8835728764533997 0.4682937264442444 0.0 0.0"/>
          <geom class="collision" type="box" pos="0.09349654614925385 -0.049028024077415466 0.16672536730766296" size="0.10797350108623505 0.04568517208099365 0.0021208375692367554" quat="0.822824239730835 0.5682958960533142 0.0 0.0"/>
          <geom class="collision" type="box" pos="-0.09113943576812744 -0.0854034572839737 0.16672536730766296" size="0.10883218795061111 0.04568517208099365 0.0021208375692367554" quat="0.8247640132904053 -0.5654770731925964 -0.0 0.0"/>
          <geom class="collision" type="box" pos="-0.09113943576812744 0.010133296251296997 0.16672536730766296" size="0.10883218795061111 0.04568517208099365 0.0021208375692367554" quat="0.8231655359268188 -0.5678014755249023 -0.0 0.0"/>
          <geom class="collision" type="box" pos="0.09349654614925385 0.046508725732564926 0.16672536730766296" size="0.10797350108623505 0.04568517208099365 0.0021208375692367554" quat="0.8247389197349548 0.5655136704444885 0.0 0.0"/>
          <geom class="collision" type="box" pos="0.09349654614925385 0.22809265553951263 0.16672536730766296" size="0.10797350108623505 0.045685168355703354 0.0021208375692367554" quat="0.8360558748245239 0.5486443042755127 0.0 0.0"/>
          <geom class="collision" type="box" pos="-0.09113943576812744 0.19232936203479767 0.16672536730766296" size="0.10883218795061111 0.04568517208099365 0.0021208375692367554" quat="0.8203443288803101 -0.5718699097633362 -0.0 0.0"/>
          <geom class="collision" type="box" pos="-0.09113943576812744 0.09679260849952698 0.16672536730766296" size="0.10883218795061111 0.04568517208099365 0.0021208373364061117" quat="0.8235960006713867 -0.567176878452301 -0.0 0.0"/>
          <geom class="collision" type="box" pos="0.09349654614925385 0.1319337636232376 0.16672536730766296" size="0.10797350108623505 0.04568517208099365 0.0021208375692367554" quat="0.8203369975090027 0.5718804597854614 0.0 0.0"/>
        </body>
        <geom class="region" name="reg_int" type="box" pos="1.0967254638671875e-05 0.04609351605176926 0.04435986280441284" size="0.2632523605823517 0.23780821806192398 0.36143983697891235"/>
        <geom class="region" name="reg_main" type="box" pos="-2.2351741790771484e-08 0.022889956831932068 0.0" size="0.298716349363327 0.27539990639686585 0.4231954941749573"/>
      </body>
    </body>
  </worldbody>
  <actuator>
    <motor name="door_joint_actuator" joint="door_joint" gear="200"/>
    <motor name="rack0_joint_actuator" joint="rack0_joint" gear="50"/>
    <motor name="rack1_joint_actuator" joint="rack1_joint" gear="50"/>
    <motor name="button_lock_joint_actuator" joint="button_lock_joint" gear="0.5"/>
    <motor name="button_power_joint_actuator" joint="button_power_joint" gear="0.5"/>
  </actuator>
</mujoco>
