<?xml version='1.0' encoding='UTF-8'?>
<mujoco model="model">
  <option timestep="0.002" gravity="0.0 0.0 -9.81"/>
  <compiler angle="radian"/>
  <asset>
    <mesh file="visuals/sideL_button_cancel.obj" name="sideL_button_cancel_vis"/>
    <mesh file="visuals/sideL_knob_doneness.obj" name="sideL_knob_doneness_vis"/>
    <mesh file="visuals/sideL_lever.obj" name="sideL_lever_vis"/>
    <mesh file="visuals/sideR_button_cancel.obj" name="sideR_button_cancel_vis"/>
    <mesh file="visuals/sideR_knob_doneness.obj" name="sideR_knob_doneness_vis"/>
    <mesh file="visuals/sideR_lever.obj" name="sideR_lever_vis"/>
    <mesh file="visuals/Body001.obj" name="Body001_vis"/>
    <mesh file="visuals/Body002.obj" name="Body002_vis"/>
    <texture file="visuals/T_BC001.png" name="Body001_material" type="2d"/>
    <material name="Body001_material" rgba="1 1 1 1.0" texture="Body001_material" shininess="0.141421377658844" specular="0.3103448502657381"/>
    <texture file="visuals/T_BC001.png" name="sideL_button_cancel_material" type="2d"/>
    <material name="sideL_button_cancel_material" rgba="1 1 1 1.0" texture="sideL_button_cancel_material" shininess="0.141421377658844" specular="0.3103448502657381"/>
    <texture file="visuals/T_BC001.png" name="sideL_knob_doneness_material" type="2d"/>
    <material name="sideL_knob_doneness_material" rgba="1 1 1 1.0" texture="sideL_knob_doneness_material" shininess="0.141421377658844" specular="0.3103448502657381"/>
    <texture file="visuals/T_BC001.png" name="sideL_lever_material" type="2d"/>
    <material name="sideL_lever_material" rgba="1 1 1 1.0" texture="sideL_lever_material" shininess="0.141421377658844" specular="0.3103448502657381"/>
    <texture file="visuals/T_BC001.png" name="sideR_button_cancel_material" type="2d"/>
    <material name="sideR_button_cancel_material" rgba="1 1 1 1.0" texture="sideR_button_cancel_material" shininess="0.141421377658844" specular="0.3103448502657381"/>
    <texture file="visuals/T_BC001.png" name="sideR_knob_doneness_material" type="2d"/>
    <material name="sideR_knob_doneness_material" rgba="1 1 1 1.0" texture="sideR_knob_doneness_material" shininess="0.141421377658844" specular="0.3103448502657381"/>
    <texture file="visuals/T_BC001.png" name="sideR_lever_material" type="2d"/>
    <material name="sideR_lever_material" rgba="1 1 1 1.0" texture="sideR_lever_material" shininess="0.141421377658844" specular="0.3103448502657381"/>
    <texture file="visuals/T_BC001.png" name="Body002_material" type="2d"/>
    <material name="Body002_material" rgba="1 1 1 1.0" texture="Body002_material" shininess="1" specular="1"/>
  </asset>
  <default>
    <default class="visual">
      <geom conaffinity="0" contype="0" group="1" type="mesh"/>
    </default>
    <default class="collision_1">
      <geom group="0" rgba="0.5 0 0 0.5" solref="0.004 1" solimp="0.998 0.998 0.001"/>
    </default>
    <default class="collision_2">
      <geom group="0" rgba="0.5 0 0 0.5" solref="0.004 1" solimp="0.998 0.998 0.001"/>
    </default>
    <default class="collision_3">
      <geom group="0" rgba="0.5 0 0 0.5" solref="0.004 1" solimp="0.998 0.998 0.001"/>
    </default>
    <default class="collision_4">
      <geom group="0" rgba="0.5 0 0 0.5" solref="0.004 1" solimp="0.998 0.998 0.001"/>
    </default>
    <default class="collision_5">
      <geom group="0" rgba="0.5 0 0 0.5" solref="0.004 1" solimp="0.998 0.998 0.001"/>
    </default>
    <default class="collision_6">
      <geom group="0" rgba="0.5 0 0 0.5" solref="0.004 1" solimp="0.998 0.998 0.001"/>
    </default>
    <default class="collision_7">
      <geom group="0" rgba="0.5 0 0 0.5" solref="0.004 1" solimp="0.998 0.998 0.001"/>
    </default>
    <default class="collision_8">
      <geom group="0" rgba="0.5 0 0 0.5" solref="0.004 1" solimp="0.998 0.998 0.001"/>
    </default>
    <default class="spawn">
      <geom group="0" rgba="1 1 1 0.5" contype="0" conaffinity="0"/>
      <site group="0" rgba="1 1 1 0.5"/>
    </default>
    <default class="region">
      <geom group="1" conaffinity="0" contype="0" rgba="0 1 0 0" mass="0"/>
    </default>
  </default>
  <worldbody>
    <body>
      <body name="object">
        <geom mesh="Body001_vis" type="mesh" solimp="0.998 0.998 0.001" solref="0.001 1" friction="0.95 0.3 0.1" class="visual" material="Body001_material"/>
        <geom type="box" pos="-0.18932417 0.01250107 0.00000243" size="0.03158983215689659 0.1725785881280899 0.17859821021556854" quat="1.0 0.0 0.0 0.0" class="collision_1"/>
        <geom type="box" pos="0.00039823 0.16524635 0.00000243" size="0.17537757754325867 0.02102925442159176 0.1785985380411148" quat="1.0 0.0 0.0 0.0" class="collision_1"/>
        <geom type="box" pos="0.19104531 0.01250107 0.00000243" size="0.031911276280879974 0.17257925868034363 0.17859886586666107" quat="1.0 0.0 0.0 0.0" class="collision_1"/>
        <geom type="box" pos="-0.00055580 0.00909294 -0.00080684" size="0.05268297344446182 0.13771720230579376 0.17778992652893066" quat="1.0 0.0 0.0 0.0" class="collision_1"/>
        <geom type="box" pos="-0.10481458 0.00909294 -0.00116855" size="0.02332262322306633 0.13771754503250122 0.17742854356765747" quat="1.0 0.0 0.0 0.0" class="collision_1"/>
        <geom type="box" pos="0.10399563 0.00909294 -0.00116855" size="0.023167718201875687 0.13771787285804749 0.17742887139320374" quat="1.0 0.0 0.0 0.0" class="collision_1"/>
        <geom type="box" pos="0.00039823 -0.00087709 -0.15278208" size="0.17537923157215118 0.1582469642162323 0.02581915445625782" quat="1.0 0.0 0.0 0.0" class="collision_1"/>
        <geom type="box" pos="0.00039823 -0.14369716 0.16627187" size="0.175379678606987 0.01644795574247837 0.012329429388046265" quat="1.0 0.0 0.0 0.0" class="collision_1"/>
        <geom type="box" pos="0.00039823 -0.12429425 0.00000138" size="0.17538000643253326 0.0030128464568406343 0.17859992384910583" quat="1.0 0.0 0.0 0.0" class="collision_1"/>
        <geom type="box" pos="0.00122331 0.01250107 -0.15476450" size="0.221732959151268 0.17257922887802124 0.01895752362906933" quat="1.0 0.0 0.0 0.0" class="collision_1"/>
        <body name="sideL_button_cancel">
          <joint axis="0.0 1.0 0.0" pos="-0.17933874 -0.16643359 -0.03394211" limited="true" name="sideL_button_cancel_joint" range="0.0 0.005" type="slide" damping="1" frictionloss="1" armature=".01" stiffness="0.05"/>
          <geom mesh="sideL_button_cancel_vis" type="mesh" solimp="0.998 0.998 0.001" solref="0.001 1" friction="0.95 0.3 0.1" class="visual" material="sideL_button_cancel_material"/>
          <geom class="collision_2" type="box" pos="-0.17871365 -0.17120714 -0.03401089" size="0.01871049962937832 0.001530831097625196 0.008147835731506348" quat="1.0 0.0 0.0 0.0" name="sideL_button_cancel_main"/>
        </body>
        <body name="sideL_knob_doneness">
          <joint axis="0.0 1.0 0.0" pos="-0.17535233 -0.17695977 -0.09803502" limited="true" name="sideL_knob_doneness_joint" range="0.0 4.014257279586958" type="hinge" damping="0.05" armature="0.001"/>
          <geom mesh="sideL_knob_doneness_vis" type="mesh" solimp="0.998 0.998 0.001" solref="0.001 1" friction="0.95 0.3 0.1" class="visual" material="sideL_knob_doneness_material"/>
          <geom type="cylinder" pos="-0.17533594 -0.16817342 -0.09785897" size="0.021930573508143425 0.0035403200890868902" quat="5.338508657359853e-08 5.3385068810030134e-08 0.7071067690849304 0.7071068286895752" class="collision_3"/>
          <geom type="cylinder" pos="-0.17533594 -0.17162256 -0.09785897" size="0.017241286113858223 0.0035403200890868902" quat="5.338508657359853e-08 5.3385068810030134e-08 0.7071067690849304 0.7071068286895752" class="collision_3"/>
          <geom class="collision_3" type="box" pos="-0.17533402 -0.18237252 -0.09807735" size="0.005339017137885094 0.007695164065808058 0.017060521990060806" quat="0.9304175972938538 0.0 0.36650121212005615 0.0" name="sideL_knob_doneness_main"/>
        </body>
        <body name="sideL_lever">
          <joint axis="0.0 0.0 -1.0" pos="-0.09302386 -0.16574703 0.05609411" limited="true" name="sideL_lever_joint" range="0.0 0.06" type="slide" damping="1" frictionloss="1" armature=".01" stiffness="1" springref="-1"/>
          <geom class="region" name="reg_sideL_slotR" type="box" pos="-0.067484685 0.006018045 0.177053995" size="0.014695555000000003 0.10176592500000001 0.07600021500000001"/>
          <geom class="region" name="reg_sideL_slotL" type="box" pos="-0.142814105 0.006018045 0.17705376" size="0.014646684999999993 0.10176592500000001 0.07599998000000002"/>
          <geom mesh="sideL_lever_vis" type="mesh" solimp="0.998 0.998 0.001" solref="0.001 1" friction="0.95 0.3 0.1" class="visual" material="sideL_lever_material"/>
          <geom type="cylinder" pos="-0.09398884 -0.15793563 0.05649833" size="0.0047609698958694935 0.010114865377545357" quat="0.7071068286895752 0.7071067690849304 0.0 0.0" class="collision_4"/>
          <geom class="collision_4" type="cylinder" pos="-0.09372807 -0.17331789 0.05653100" size="0.007768087554723024 0.024166671559214592" quat="0.5000000596046448 0.5 0.4999999701976776 0.5" name="sideL_lever_handle"/>
          <geom class="collision_4" type="box" pos="-0.14302953 0.00613214 0.09664291" size="0.012878425419330597 0.09971249103546143 0.0030473258811980486" quat="1.0 0.0 0.0 0.0" name="sideL_slotL_floor"/>
          <geom class="collision_4" type="box" pos="-0.06715986 0.00613214 0.09664290" size="0.012580218724906445 0.09971249103546143 0.003047341015189886" quat="1.0 0.0 0.0 0.0" name="sideL_slotR_floor"/>
        </body>
        <body name="sideR_button_cancel">
          <joint axis="0.0 1.0 0.0" pos="0.18064249 -0.16643359 -0.03394211" limited="true" name="sideR_button_cancel_joint" range="0.0 0.005" type="slide" damping="1" frictionloss="1" armature=".01" stiffness="0.05"/>
          <geom mesh="sideR_button_cancel_vis" type="mesh" solimp="0.998 0.998 0.001" solref="0.001 1" friction="0.95 0.3 0.1" class="visual" material="sideR_button_cancel_material"/>
          <geom class="collision_5" type="box" pos="0.18157801 -0.17120714 -0.03401089" size="0.01871052198112011 0.001530832378193736 0.008147841319441795" quat="1.0 0.0 0.0 0.0" name="sideR_button_cancel_main"/>
        </body>
        <body name="sideR_knob_doneness">
          <joint axis="0.0 1.0 0.0" pos="0.17522788 -0.17695990 -0.09803502" limited="true" name="sideR_knob_doneness_joint" range="0.0 4.014257279586958" type="hinge" damping="0.05" armature="0.001"/>
          <geom mesh="sideR_knob_doneness_vis" type="mesh" solimp="0.998 0.998 0.001" solref="0.001 1" friction="0.95 0.3 0.1" class="visual" material="sideR_knob_doneness_material"/>
          <geom type="cylinder" pos="0.17526875 -0.16817342 -0.09785897" size="0.021930573508143425 0.0035403200890868902" quat="5.338508657359853e-08 5.3385068810030134e-08 0.7071067690849304 0.7071068286895752" class="collision_6"/>
          <geom type="cylinder" pos="0.17526875 -0.17162256 -0.09785897" size="0.017241286113858223 0.0035403200890868902" quat="5.338508657359853e-08 5.3385068810030134e-08 0.7071067690849304 0.7071068286895752" class="collision_6"/>
          <geom class="collision_6" type="box" pos="0.17527068 -0.18237252 -0.09807735" size="0.005339016206562519 0.0076951622031629086 0.017060521990060806" quat="0.9304175972938538 0.0 0.36650121212005615 0.0" name="sideR_knob_doneness_main"/>
        </body>
        <body name="sideR_lever">
          <joint axis="0.0 0.0 -1.0" pos="0.09305535 -0.16574706 0.05609411" limited="true" name="sideR_lever_joint" range="0.0 0.06" type="slide" damping="1" frictionloss="1" armature=".01" stiffness="1" springref="-1"/>
          <geom class="region" name="reg_sideR_slotR" type="box" pos="0.142822645 0.006018045 0.177053995" size="0.016334715 0.10176592500000001 0.07600021500000001"/>
          <geom class="region" name="reg_sideR_slotL" type="box" pos="0.066102935 0.006018045 0.177053995" size="0.014630425000000002 0.10176592500000001 0.07600021500000001"/>
          <geom mesh="sideR_lever_vis" type="mesh" solimp="0.998 0.998 0.001" solref="0.001 1" friction="0.95 0.3 0.1" class="visual" material="sideR_lever_material"/>
          <geom class="collision_7" type="cylinder" pos="0.09270387 -0.17331789 0.05653100" size="0.007768087554723024 0.024166665971279144" quat="0.5000000596046448 0.5 0.4999999701976776 0.5" name="sideR_lever_handle"/>
          <geom type="cylinder" pos="0.09244310 -0.15793563 0.05649833" size="0.0047609698958694935 0.010114865377545357" quat="0.7071068286895752 0.7071067690849304 0.0 0.0" class="collision_7"/>
          <geom class="collision_7" type="box" pos="0.06643827 0.00613214 0.09664291" size="0.0126280402764678 0.09971301257610321 0.0030473258811980486" quat="1.0 0.0 0.0 0.0" name="sideR_slotL_floor"/>
          <geom class="collision_7" type="box" pos="0.14306442 0.00613214 0.09664290" size="0.013967897742986679 0.09971226751804352 0.0030473305378109217" quat="1.0 0.0 0.0 0.0" name="sideR_slotR_floor"/>
        </body>
        <body name="Body002">
          <geom mesh="Body002_vis" type="mesh" solimp="0.998 0.998 0.001" solref="0.001 1" friction="0.95 0.3 0.1" class="visual" material="Body002_material"/>
        </body>
        <geom class="region" name="reg_main" type="box" pos="-4.999999997368221e-09 0.009207175000000012 0.0" size="0.227280125 0.181724625 0.17960129"/>
      </body>
    </body>
  </worldbody>
  <actuator>
    <motor name="sideL_button_cancel_joint_actuator" joint="sideL_button_cancel_joint" gear="0.1"/>
    <motor name="sideL_knob_doneness_joint_actuator" joint="sideL_knob_doneness_joint" gear="10"/>
    <motor name="sideL_lever_joint_actuator" joint="sideL_lever_joint" gear="5"/>
    <motor name="sideR_button_cancel_joint_actuator" joint="sideR_button_cancel_joint" gear="0.1"/>
    <motor name="sideR_knob_doneness_joint_actuator" joint="sideR_knob_doneness_joint" gear="10"/>
    <motor name="sideR_lever_joint_actuator" joint="sideR_lever_joint" gear="5"/>
  </actuator>
</mujoco>
