<?xml version='1.0' encoding='UTF-8'?>
<mujoco model="model">
  <option timestep="0.002" gravity="0.0 0.0 -9.81"/>
  <compiler angle="radian"/>
  <asset>
    <mesh file="visuals/sideL_button_cancel.obj" name="sideL_button_cancel_vis"/>
    <mesh file="visuals/sideL_knob_doneness.obj" name="sideL_knob_doneness_vis"/>
    <mesh file="visuals/sideL_lever.obj" name="sideL_lever_vis"/>
    <mesh file="visuals/sideR_button_cancel.obj" name="sideR_button_cancel_vis"/>
    <mesh file="visuals/sideR_knob_doneness.obj" name="sideR_knob_doneness_vis"/>
    <mesh file="visuals/sideR_lever.obj" name="sideR_lever_vis"/>
    <mesh file="visuals/Body001.obj" name="Body001_vis"/>
    <mesh file="visuals/Body002.obj" name="Body002_vis"/>
    <texture file="visuals/T_BC001.png" name="Body001_material" type="2d"/>
    <material name="Body001_material" rgba="1 1 1 1.0" texture="Body001_material" shininess="0.141421377658844" specular="0.3103448502657381"/>
    <texture file="visuals/T_BC001.png" name="sideL_button_cancel_material" type="2d"/>
    <material name="sideL_button_cancel_material" rgba="1 1 1 1.0" texture="sideL_button_cancel_material" shininess="0.141421377658844" specular="0.3103448502657381"/>
    <texture file="visuals/T_BC001.png" name="sideL_knob_doneness_material" type="2d"/>
    <material name="sideL_knob_doneness_material" rgba="1 1 1 1.0" texture="sideL_knob_doneness_material" shininess="0.141421377658844" specular="0.3103448502657381"/>
    <texture file="visuals/T_BC001.png" name="sideL_lever_material" type="2d"/>
    <material name="sideL_lever_material" rgba="1 1 1 1.0" texture="sideL_lever_material" shininess="0.141421377658844" specular="0.3103448502657381"/>
    <texture file="visuals/T_BC001.png" name="sideR_button_cancel_material" type="2d"/>
    <material name="sideR_button_cancel_material" rgba="1 1 1 1.0" texture="sideR_button_cancel_material" shininess="0.141421377658844" specular="0.3103448502657381"/>
    <texture file="visuals/T_BC001.png" name="sideR_knob_doneness_material" type="2d"/>
    <material name="sideR_knob_doneness_material" rgba="1 1 1 1.0" texture="sideR_knob_doneness_material" shininess="0.141421377658844" specular="0.3103448502657381"/>
    <texture file="visuals/T_BC001.png" name="sideR_lever_material" type="2d"/>
    <material name="sideR_lever_material" rgba="1 1 1 1.0" texture="sideR_lever_material" shininess="0.141421377658844" specular="0.3103448502657381"/>
    <texture file="visuals/T_BC001.png" name="Body002_material" type="2d"/>
    <material name="Body002_material" rgba="1 1 1 1.0" texture="Body002_material" shininess="1" specular="1"/>
  </asset>
  <default>
    <default class="visual">
      <geom conaffinity="0" contype="0" group="1" type="mesh"/>
    </default>
    <default class="collision_1">
      <geom group="0" rgba="0.5 0 0 0.5" solref="0.004 1" solimp="0.998 0.998 0.001"/>
    </default>
    <default class="collision_2">
      <geom group="0" rgba="0.5 0 0 0.5" solref="0.004 1" solimp="0.998 0.998 0.001"/>
    </default>
    <default class="collision_3">
      <geom group="0" rgba="0.5 0 0 0.5" solref="0.004 1" solimp="0.998 0.998 0.001"/>
    </default>
    <default class="collision_4">
      <geom group="0" rgba="0.5 0 0 0.5" solref="0.004 1" solimp="0.998 0.998 0.001"/>
    </default>
    <default class="collision_5">
      <geom group="0" rgba="0.5 0 0 0.5" solref="0.004 1" solimp="0.998 0.998 0.001"/>
    </default>
    <default class="collision_6">
      <geom group="0" rgba="0.5 0 0 0.5" solref="0.004 1" solimp="0.998 0.998 0.001"/>
    </default>
    <default class="collision_7">
      <geom group="0" rgba="0.5 0 0 0.5" solref="0.004 1" solimp="0.998 0.998 0.001"/>
    </default>
    <default class="collision_8">
      <geom group="0" rgba="0.5 0 0 0.5" solref="0.004 1" solimp="0.998 0.998 0.001"/>
    </default>
    <default class="spawn">
      <geom group="0" rgba="1 1 1 0.5" contype="0" conaffinity="0"/>
      <site group="0" rgba="1 1 1 0.5"/>
    </default>
    <default class="region">
      <geom group="1" conaffinity="0" contype="0" rgba="0 1 0 0" mass="0"/>
    </default>
  </default>
  <worldbody>
    <body>
      <body name="object">
        <geom mesh="Body001_vis" type="mesh" solimp="0.998 0.998 0.001" solref="0.001 1" friction="0.95 0.3 0.1" class="visual" material="Body001_material"/>
        <geom type="box" pos="-0.00311136 0.03029262 0.00501753" size="0.014889737591147423 0.11575660854578018 0.20856213569641113" quat="1.0 0.0 0.0 0.0" class="collision_1"/>
        <geom type="box" pos="0.08471326 0.03029262 0.00501753" size="0.014889653772115707 0.11575660109519958 0.2085607796907425" quat="1.0 0.0 0.0 0.0" class="collision_1"/>
        <geom type="box" pos="-0.09069987 0.03029262 0.00501753" size="0.014889569021761417 0.11575658619403839 0.20855943858623505" quat="1.0 0.0 0.0 0.0" class="collision_1"/>
        <geom type="box" pos="-0.24871520 0.02977030 0.00501753" size="0.09614712744951248 0.18473170697689056 0.2085580825805664" quat="1.0 0.0 0.0 0.0" class="collision_1"/>
        <geom type="box" pos="0.24842461 0.03022499 0.00501753" size="0.09672149270772934 0.1842769831418991 0.20855674147605896" quat="1.0 0.0 0.0 0.0" class="collision_1"/>
        <geom type="box" pos="0.03145607 -0.12205667 -0.00042886" size="0.18335102498531342 0.03561268746852875 0.203109011054039" quat="1.0 0.0 0.0 0.0" class="collision_1"/>
        <geom type="box" pos="0.03145607 0.17622766 -0.00078182" size="0.1833503544330597 0.03615760803222656 0.20275470614433289" quat="1.0 0.0 0.0 0.0" class="collision_1"/>
        <geom type="box" pos="0.03145607 0.02705383 -0.19898682" size="0.18334901332855225 0.11420955508947372 0.004544232971966267" quat="1.0 0.0 0.0 0.0" class="collision_1"/>
        <geom type="box" pos="-0.11019821 0.02736013 0.09401608" size="0.005456375423818827 0.09906361997127533 0.10445033758878708" quat="1.0 0.0 0.0 0.0" class="collision_1"/>
        <geom type="box" pos="-0.15050521 0.02736013 0.09401608" size="0.005456375423818827 0.09906360507011414 0.10445032268762589" quat="1.0 0.0 0.0 0.0" class="collision_1"/>
        <geom type="box" pos="-0.06772556 0.02736013 0.09401608" size="0.006852762307971716 0.09906349331140518 0.1044505387544632" quat="1.0 0.0 0.0 0.0" class="collision_1"/>
        <geom type="box" pos="-0.02536068 0.02736013 0.09401608" size="0.006852760445326567 0.09906349331140518 0.10445049405097961" quat="1.0 0.0 0.0 0.0" class="collision_1"/>
        <geom type="box" pos="0.01955391 0.02736013 0.09401608" size="0.0068527585826814175 0.09906349331140518 0.10445044934749603" quat="1.0 0.0 0.0 0.0" class="collision_1"/>
        <geom type="box" pos="0.06300827 0.02736013 0.09401608" size="0.006852756254374981 0.09906349331140518 0.10445040464401245" quat="1.0 0.0 0.0 0.0" class="collision_1"/>
        <geom type="box" pos="0.10404756 0.02736013 0.09401608" size="0.006852754391729832 0.09906349331140518 0.10445035994052887" quat="1.0 0.0 0.0 0.0" class="collision_1"/>
        <geom type="box" pos="0.14597888 0.02736013 0.09401608" size="0.006852752063423395 0.09906349331140518 0.10445031523704529" quat="1.0 0.0 0.0 0.0" class="collision_1"/>
        <geom type="cylinder" pos="0.22213344 -0.12507828 -0.21236209" size="0.018061628565192223 0.009052393957972527" quat="1.0 0.0 0.0 0.0" class="collision_1"/>
        <geom type="cylinder" pos="-0.23178133 -0.12507828 -0.21236209" size="0.018061628565192223 0.009052393957972527" quat="1.0 0.0 0.0 0.0" class="collision_1"/>
        <geom type="cylinder" pos="0.22213344 0.17294766 -0.21236209" size="0.018061628565192223 0.009052393957972527" quat="1.0 0.0 0.0 0.0" class="collision_1"/>
        <geom type="cylinder" pos="-0.23178133 0.17294766 -0.21236209" size="0.018061628565192223 0.009052393957972527" quat="1.0 0.0 0.0 0.0" class="collision_1"/>
        <body name="sideL_button_cancel">
          <joint axis="0.0 1.0 0.0" pos="-0.26410026 -0.15811472 -0.03015144" limited="true" name="sideL_button_cancel_joint" range="0.0 0.0075" type="slide" damping="1" frictionloss="1" armature=".01" stiffness="4" springref="-1"/>
          <geom mesh="sideL_button_cancel_vis" type="mesh" solimp="0.998 0.998 0.001" solref="0.001 1" friction="0.95 0.3 0.1" class="visual" material="sideL_button_cancel_material"/>
          <geom class="collision_2" type="box" pos="-0.26274700 -0.16370949 -0.03004264" size="0.02201722376048565 0.0021441825665533543 0.008669777773320675" quat="1.0 0.0 0.0 0.0" name="sideL_button_cancel_main"/>
        </body>
        <body name="sideL_knob_doneness">
          <joint axis="0.0 1.0 0.0" pos="-0.26555405 -0.17773810 -0.11421408" limited="true" name="sideL_knob_doneness_joint" range="0.0 4.625122517784973" type="hinge" damping="0.05" armature="1" frictionloss="0.75"/>
          <geom mesh="sideL_knob_doneness_vis" type="mesh" solimp="0.998 0.998 0.001" solref="0.001 1" friction="0.95 0.3 0.1" class="visual" material="sideL_knob_doneness_material"/>
          <geom class="collision_3" type="box" pos="-0.26554779 -0.17829334 -0.11350775" size="0.010949773713946342 0.016079390421509743 0.026809614151716232" quat="0.9189994931221008 0.0 0.3942587375640869 0.0" name="sideL_knob_doneness_main" friction="100 0.5 0.01"/>
          <geom type="cylinder" pos="-0.26645110 -0.16477439 -0.11456795" size="0.03140706568956375 0.005081482231616974" quat="0.7071067094802856 0.7071068286895752 0.0 0.0" class="collision_3" friction="100 0.5 0.01"/>
        </body>
        <body name="sideL_lever">
          <joint axis="0.0 0.0 -1.0" pos="-0.09055852 -0.19679202 0.00746036" limited="true" name="sideL_lever_joint" range="0.0 0.06" type="slide" damping="1" frictionloss="1" armature=".1" stiffness="2" springref="-0.5"/>
          <geom class="region" name="reg_sideL_slotR" type="box" pos="-0.04697168 0.027472965000000002 0.21842737" size="0.014398170000000002 0.100630545 0.07600023"/>
          <geom class="region" name="reg_sideL_slotL" type="box" pos="-0.13057355999999998 0.027472965000000002 0.21842713" size="0.013958289999999998 0.100630545 0.07599998999999999"/>
          <geom mesh="sideL_lever_vis" type="mesh" solimp="0.998 0.998 0.001" solref="0.001 1" friction="0.95 0.3 0.1" class="visual" material="sideL_lever_material"/>
          <geom type="cylinder" pos="-0.08918158 -0.17378079 0.00625992" size="0.00671454519033432 0.011980821378529072" quat="0.7071067094802856 0.7071068286895752 0.0 0.0" class="collision_4"/>
          <geom class="collision_4" type="box" pos="-0.09058586 -0.19973794 0.00768548" size="0.02013464830815792 0.014288297854363918 0.021342195570468903" quat="1.0 0.0 0.0 0.0" name="sideL_lever_handle"/>
          <geom class="collision_4" type="box" pos="-0.13056605 0.02736013 0.14509968" size="0.012583889998495579 0.09906349331140518 0.0011100867995992303" quat="1.0 0.0 0.0 0.0" name="sideL_slotL_floor"/>
          <geom class="collision_4" type="box" pos="-0.04686966 0.02736013 0.14509968" size="0.012716329656541348 0.09906391054391861 0.001110078883357346" quat="1.0 0.0 0.0 0.0" name="sideL_slotR_floor"/>
        </body>
        <body name="sideR_button_cancel">
          <joint axis="0.0 1.0 0.0" pos="0.26924878 -0.15811472 -0.03015144" limited="true" name="sideR_button_cancel_joint" range="0.0 0.0075" type="slide" damping="1" frictionloss="1" armature=".01" stiffness="4" springref="-1"/>
          <geom mesh="sideR_button_cancel_vis" type="mesh" solimp="0.998 0.998 0.001" solref="0.001 1" friction="0.95 0.3 0.1" class="visual" material="sideR_button_cancel_material"/>
          <geom class="collision_5" type="box" pos="0.26923769 -0.16370949 -0.03004264" size="0.02201722376048565 0.0021441823337227106 0.008669777773320675" quat="1.0 0.0 0.0 0.0" name="sideR_button_cancel_main"/>
        </body>
        <body name="sideR_knob_doneness">
          <joint axis="0.0 1.0 0.0" pos="0.26920929 -0.17773810 -0.11537564" limited="true" name="sideR_knob_doneness_joint" range="0.0 4.625122517784973" type="hinge" damping="0.05" armature="1" frictionloss="0.75"/>
          <geom mesh="sideR_knob_doneness_vis" type="mesh" solimp="0.998 0.998 0.001" solref="0.001 1" friction="0.95 0.3 0.1" class="visual" material="sideR_knob_doneness_material"/>
          <geom class="collision_6" type="box" pos="0.27025004 -0.17859397 -0.11346306" size="0.011468051932752132 0.01638001762330532 0.02847914583981037" quat="0.9130614995956421 0.0 0.407821923494339 0.0" name="sideR_knob_doneness_main" friction="100 0.5 0.01"/>
          <geom type="cylinder" pos="0.26911097 -0.16477439 -0.11525305" size="0.03140706568956375 0.005081482231616974" quat="0.7071067094802856 0.7071068286895752 0.0 0.0" class="collision_6" friction="100 0.5 0.01"/>
        </body>
        <body name="sideR_lever">
          <joint axis="0.0 0.0 -1.0" pos="0.08501331 -0.19679202 0.00746036" limited="true" name="sideR_lever_joint" range="0.0 0.06" type="slide" damping="1" frictionloss="1" armature=".1" stiffness="2" springref="-0.5"/>
          <geom class="region" name="reg_sideR_slotR" type="box" pos="0.12516096 0.027472965000000002 0.21842737" size="0.013968359999999999 0.100630545 0.07600023"/>
          <geom class="region" name="reg_sideR_slotL" type="box" pos="0.041577585 0.027472965000000002 0.21842737" size="0.014200175000000002 0.100630545 0.07600023"/>
          <geom mesh="sideR_lever_vis" type="mesh" solimp="0.998 0.998 0.001" solref="0.001 1" friction="0.95 0.3 0.1" class="visual" material="sideR_lever_material"/>
          <geom class="collision_7" type="box" pos="0.08453678 -0.19973794 0.00768548" size="0.020134495571255684 0.01428829412907362 0.021342042833566666" quat="1.0 0.0 0.0 0.0" name="sideR_lever_handle"/>
          <geom type="cylinder" pos="0.08594107 -0.17378079 0.00625992" size="0.00671454519033432 0.011980821378529072" quat="0.7071067094802856 0.7071068286895752 0.0 0.0" class="collision_7"/>
          <geom class="collision_7" type="box" pos="0.04153157 0.02736013 0.14509968" size="0.012675471603870392 0.09906449168920517 0.0011100867995992303" quat="1.0 0.0 0.0 0.0" name="sideR_slotL_floor"/>
          <geom class="collision_7" type="box" pos="0.12517587 0.02736013 0.14509968" size="0.012559778988361359 0.09906499087810516 0.0011100867995992303" quat="1.0 0.0 0.0 0.0" name="sideR_slotR_floor"/>
        </body>
        <body name="Body002">
          <geom mesh="Body002_vis" type="mesh" solimp="0.998 0.998 0.001" solref="0.001 1" friction="0.95 0.3 0.1" class="visual" material="Body002_material"/>
        </body>
        <geom class="region" name="reg_main" type="box" pos="0.00014190499999999773 0.02543774 -7.500000000215667e-08" size="0.346004085 0.19006367000000002 0.223660335"/>
      </body>
    </body>
  </worldbody>
  <actuator>
    <motor name="sideL_button_cancel_joint_actuator" joint="sideL_button_cancel_joint" gear="0.1"/>
    <motor name="sideL_knob_doneness_joint_actuator" joint="sideL_knob_doneness_joint" gear="10"/>
    <motor name="sideL_lever_joint_actuator" joint="sideL_lever_joint" gear="2"/>
    <motor name="sideR_button_cancel_joint_actuator" joint="sideR_button_cancel_joint" gear="0.1"/>
    <motor name="sideR_knob_doneness_joint_actuator" joint="sideR_knob_doneness_joint" gear="10"/>
    <motor name="sideR_lever_joint_actuator" joint="sideR_lever_joint" gear="2"/>
  </actuator>
</mujoco>