<?xml version='1.0' encoding='UTF-8'?>
<mujoco model="model">
  <option timestep="0.002" gravity="0.0 0.0 -9.81"/>
  <compiler angle="radian"/>
  <asset>
    <mesh file="visuals/door.obj" name="door_vis"/>
    <mesh file="visuals/knob_temp.obj" name="knob_temp_vis"/>
    <mesh file="visuals/knob_time.obj" name="knob_time_vis"/>
    <mesh file="visuals/rack0.obj" name="rack0_vis"/>
    <mesh file="visuals/Body001.obj" name="Body001_vis"/>
    <mesh file="visuals/window.obj" name="window_vis"/>
    <texture file="visuals/T_BC001.png" name="Body001_material" type="2d"/>
    <material name="Body001_material" rgba="1 1 1 1.0" texture="Body001_material" shininess="0.141421377658844" specular="1"/>
    <texture file="visuals/T_BC001.png" name="door_material" type="2d"/>
    <material name="door_material" rgba="1 1 1 1.0" texture="door_material" shininess="0.141421377658844" specular="1"/>
    <texture file="visuals/T_BC001.png" name="window_material" type="2d"/>
    <material name="window_material" rgba="1 1 1 0.75" texture="window_material" shininess="0.141421377658844" specular="0.1"/>
    <texture file="visuals/T_BC001.png" name="knob_temp_material" type="2d"/>
    <material name="knob_temp_material" rgba="1 1 1 1.0" texture="knob_temp_material" shininess="0.141421377658844" specular="1"/>
    <texture file="visuals/T_BC001.png" name="knob_time_material" type="2d"/>
    <material name="knob_time_material" rgba="1 1 1 1.0" texture="knob_time_material" shininess="0.141421377658844" specular="1"/>
    <texture file="visuals/T_BC001.png" name="rack0_material" type="2d"/>
    <material name="rack0_material" rgba="1 1 1 1.0" texture="rack0_material" shininess="0.141421377658844" specular="1"/>
  </asset>
  <default>
    <default class="visual">
      <geom conaffinity="0" contype="0" group="1" type="mesh"/>
    </default>
    <default class="collision">
      <geom group="0" rgba="0.5 0 0 0.5"/>
    </default>
    <default class="spawn">
      <geom group="0" rgba="1 1 1 0.5" contype="0" conaffinity="0"/>
      <site group="0" rgba="1 1 1 0.5"/>
    </default>
    <default class="region">
      <geom group="1" conaffinity="0" contype="0" rgba="0 1 0 0"/>
    </default>
  </default>
  <worldbody>
    <body>
      <body name="object">
        <geom mesh="Body001_vis" type="mesh" solimp="0.998 0.998 0.001" solref="0.001 1" friction="0.95 0.3 0.1" class="visual" material="Body001_material"/>
        <geom class="collision" type="box" pos="-0.04491190 0.15224161 0.01282259" size="0.2140880972146988 0.011358464136719704 0.13912859559059143" quat="1.0 0.0 0.0 0.0"/>
        <geom class="collision" type="box" pos="-0.04373375 0.00569444 0.15229528" size="0.21526534855365753 0.15740522742271423 0.012799685820937157" quat="1.0 0.0 0.0 0.0"/>
        <geom class="collision" type="box" pos="-0.24348645 0.00569444 0.00812054" size="0.01551310159265995 0.15740546584129333 0.13517946004867554" quat="1.0 0.0 0.0 0.0"/>
        <geom class="collision" type="box" pos="-0.04373369 0.00569444 -0.13176702" size="0.2152654230594635 0.1574053019285202 0.00688356626778841" quat="1.0 0.0 0.0 0.0"/>
        <geom class="collision" type="box" pos="0.21329430 0.00278296 0.01322218" size="0.04570510983467102 0.1603168249130249 0.15187261998653412" quat="1.0 0.0 0.0 0.0"/>
        <geom class="collision" type="box" pos="0.20621932 -0.16207626 0.12853372" size="0.03439680486917496 0.010685496963560581 0.01701904833316803" quat="0.9960876107215881 0.0 0.0 0.08837131410837173"/>
        <geom class="collision" type="box" pos="0.17326455 -0.16761263 0.12853372" size="0.005682479124516249 0.010685497894883156 0.01701904833316803" quat="1.0 0.0 0.0 0.0"/>
        <geom class="collision" type="box" pos="-0.03256284 0.17163591 0.01751526" size="0.17744673788547516 0.010239753872156143 0.10587236285209656" quat="1.0 0.0 0.0 0.0"/>
        <geom class="collision" type="box" pos="-0.22239554 0.00153404 0.06460548" size="0.004804165568202734 0.1254395842552185 0.007929136976599693" quat="1.0 0.0 0.0 0.0"/>
        <geom class="collision" type="box" pos="-0.22364412 0.00153404 0.02954123" size="0.004804165568202734 0.1254395842552185 0.013520335778594017" quat="1.0 0.0 0.0 0.0"/>
        <geom class="collision" type="box" pos="-0.22239554 0.00153404 -0.01711983" size="0.005446018185466528 0.1254395842552185 0.02287634275853634" quat="1.0 0.0 0.0 0.0"/>
        <geom class="collision" type="box" pos="-0.22154871 0.00153404 -0.05700907" size="0.004804163705557585 0.1254395842552185 0.007625168655067682" quat="1.0 0.0 0.0 0.0"/>
        <geom class="collision" type="box" pos="0.14603738 0.00153404 0.06460548" size="0.004804184660315514 0.1254395842552185 0.007929136976599693" quat="1.0 0.0 0.0 0.0"/>
        <geom class="collision" type="box" pos="0.14581195 0.00153404 0.03032159" size="0.004804184660315514 0.1254395842552185 0.013520327396690845" quat="1.0 0.0 0.0 0.0"/>
        <geom class="collision" type="box" pos="0.14603738 0.00153404 -0.01711983" size="0.0054460372775793076 0.1254395842552185 0.02287634275853634" quat="1.0 0.0 0.0 0.0"/>
        <geom class="collision" type="box" pos="0.14519055 0.00153404 -0.05700907" size="0.004804184194654226 0.1254395842552185 0.007625168655067682" quat="1.0 0.0 0.0 0.0"/>
        <geom class="collision" type="cylinder" pos="0.23406057 -0.11655891 -0.15113163" size="0.014817764982581139 0.013552319258451462" quat="7.549790126404332e-08 1.0 -1.1102230246251565e-16 1.1102229584507075e-16"/>
        <geom class="collision" type="cylinder" pos="0.23406057 0.11377754 -0.15113163" size="0.014817764982581139 0.013552319258451462" quat="7.549790126404332e-08 1.0 -1.1102230246251565e-16 1.1102229584507075e-16"/>
        <geom class="collision" type="cylinder" pos="-0.23203816 -0.11655891 -0.15113163" size="0.014817764982581139 0.013552319258451462" quat="7.549790126404332e-08 1.0 -1.1102230246251565e-16 1.1102229584507075e-16"/>
        <geom class="collision" type="cylinder" pos="-0.23203816 0.11377754 -0.15113163" size="0.014817764982581139 0.013552319258451462" quat="7.549790126404332e-08 1.0 -1.1102230246251565e-16 1.1102229584507075e-16"/>
        <geom class="collision" type="box" pos="-0.24170592 0.02102234 0.00812054" size="0.017293626442551613 0.14207758009433746 0.13517946004867554" quat="1.0 0.0 0.0 0.0"/>
        <geom class="collision" type="box" pos="0.16682625 0.02102234 0.00812054" size="0.017293626442551613 0.14207758009433746 0.13517946004867554" quat="1.0 0.0 0.0 0.0"/>
        <body name="door">
          <joint axis="1.0 0.0 0.0" pos="-0.03951699 -0.16112190 -0.12027641" limited="true" name="door_joint" range="0.0 1.5707963267948966" type="hinge" damping="1" frictionloss="1" armature=".01" stiffness="0.05"/>
          <geom mesh="door_vis" type="mesh" solimp="0.998 0.998 0.001" solref="0.001 1" friction="0.95 0.3 0.1" class="visual" material="door_material"/>
          <geom class="collision" type="box" pos="-0.03282071 -0.14801726 0.00753098" size="0.1943037509918213 0.013378138653934002 0.1289387196302414" quat="1.0 0.0 0.0 0.0" name="door_main"/>
          <geom class="collision" type="box" pos="-0.03753169 -0.17528993 0.12853372" size="0.1759776920080185 0.004100143909454346 0.017019083723425865" quat="1.0 0.0 0.0 0.0" name="door_handle_main"/>
          <geom class="collision" type="box" pos="-0.22575647 -0.16848550 0.12853372" size="0.01420120894908905 0.011237244121730328 0.017019076272845268" quat="1.0 0.0 0.0 0.0"/>
          <geom class="collision" type="box" pos="0.14575523 -0.16793375 0.12853372" size="0.01632223092019558 0.0106855109333992 0.01701907068490982" quat="1.0 0.0 0.0 0.0"/>
          <body name="window">
            <geom mesh="window_vis" type="mesh" solimp="0.998 0.998 0.001" solref="0.001 1" friction="0.95 0.3 0.1" class="visual" material="window_material"/>
            <geom class="collision" type="box" pos="-0.03966673 -0.14717241 0.01346565" size="0.15619301795959473 0.011817453429102898 0.09648047387599945" quat="1.0 0.0 0.0 0.0"/>
          </body>
        </body>
        <body name="knob_temp">
          <joint axis="0.0 1.0 0.0" pos="0.20854701 -0.17021730 0.05495206" limited="true" name="knob_temp_joint" range="0.0 5.235987755982989" type="hinge" damping="0.05" armature="0.001"/>
          <geom mesh="knob_temp_vis" type="mesh" solimp="0.998 0.998 0.001" solref="0.001 1" friction="0.95 0.3 0.1" class="visual" material="knob_temp_material"/>
          <geom class="collision" type="cylinder" pos="0.20876767 -0.16428209 0.05516789" size="0.020782804116606712 0.004295899532735348" quat="0.7071068286895752 0.7071067690849304 0.0 0.0"/>
          <geom class="collision" type="box" pos="0.20876765 -0.17535544 0.05516796" size="0.0149827366694808 0.006811194587498903 0.004383939318358898" quat="1.0 0.0 0.0 0.0" name="knob_temp_main"/>
        </body>
        <body name="knob_time">
          <joint axis="0.0 1.0 0.0" pos="0.20807022 -0.17021730 -0.05269055" limited="true" name="knob_time_joint" range="0.0 5.497787143782138" type="hinge" damping="0.05" armature="0.001"/>
          <geom mesh="knob_time_vis" type="mesh" solimp="0.998 0.998 0.001" solref="0.001 1" friction="0.95 0.3 0.1" class="visual" material="knob_time_material"/>
          <geom class="collision" type="cylinder" pos="0.20765947 -0.16412177 -0.05310133" size="0.02137417532503605 0.004418139345943928" quat="0.7071068286895752 0.7071067690849304 0.0 0.0"/>
          <geom class="collision" type="box" pos="0.20765947 -0.17555413 -0.05310133" size="0.015386233106255531 0.007005007937550545 0.004426498897373676" quat="0.914474606513977 1.6456271242797814e-16 -0.40464332699775696 1.3850357305500438e-08" name="knob_time_main"/>
        </body>
        <body name="rack0">
          <geom class="region" name="reg_rack0" type="box" pos="-0.037654889999999996 -0.004722564999999998 0.07169399" size="0.15731159 0.106541025 0.0681962"/>
          <joint axis="0.0 -1.0 0.0" pos="-0.03837361 -0.00475379 0.00594592" limited="true" name="rack0_joint" range="0.0 0.2" type="slide" damping="1" frictionloss="1" armature=".01" stiffness="0.05"/>
          <geom mesh="rack0_vis" type="mesh" solimp="0.998 0.998 0.001" solref="0.001 1" friction="0.95 0.3 0.1" class="visual" material="rack0_material"/>
          <geom class="collision" type="box" pos="-0.21577507 -0.00461658 0.01161791" size="0.008577265776693821 0.10600447654724121 0.001667578355409205" quat="1.0 0.0 0.0 0.0"/>
          <geom class="collision" type="box" pos="-0.20187555 -0.00462306 0.00682768" size="0.008577265776693821 0.10601095855236053 0.0016675611259415746" quat="0.9440328478813171 -2.0632491271044273e-08 0.3298514783382416 7.209132402152818e-09"/>
          <geom class="collision" type="box" pos="0.12622657 -0.00462306 0.00682768" size="0.008577265776693821 0.10601095855236053 0.0016675611259415746" quat="7.127249546101666e-08 -0.9440328478813171 -2.4903092921135794e-08 -0.3298514783382416"/>
          <geom class="collision" type="box" pos="0.13933556 -0.00461658 0.01161791" size="0.008577265776693821 0.10600447654724121 0.0016675770748406649" quat="1.0 0.0 0.0 0.0"/>
          <geom class="collision" type="box" pos="-0.03711260 -0.00480515 0.00117563" size="0.15898673236370087 0.10659922659397125 0.0024258748162537813" quat="1.0 0.0 0.0 0.0"/>
        </body>
        <geom class="region" name="reg_main" type="box" pos="-4.999999997368221e-09 0.010531625000000003 0.0" size="0.259999525 0.17302758499999998 0.16609502"/>
      </body>
    </body>
  </worldbody>
  <actuator>
    <motor name="door_joint_actuator" joint="door_joint" gear="50"/>
    <motor name="knob_temp_joint_actuator" joint="knob_temp_joint" gear="50"/>
    <motor name="knob_time_joint_actuator" joint="knob_time_joint" gear="50"/>
    <motor name="rack0_joint_actuator" joint="rack0_joint" gear="50"/>
  </actuator>
</mujoco>
