<?xml version='1.0' encoding='UTF-8'?>
<mujoco model="model">
  <option timestep="0.002" gravity="0.0 0.0 -9.81"/>
  <compiler angle="radian"/>
  <asset>
    <mesh file="visuals/button_cancel.obj" name="button_cancel_vis"/>
    <mesh file="visuals/knob_doneness.obj" name="knob_doneness_vis"/>
    <mesh file="visuals/lever.obj" name="lever_vis"/>
    <mesh file="visuals/Body001.obj" name="Body001_vis"/>
    <texture file="visuals/T_BC001.png" name="Body001_material" type="2d"/>
    <material name="Body001_material" rgba="1 1 1 1.0" texture="Body001_material" shininess="0.4472135901451111" specular="0.6"/>
    <texture file="visuals/T_BC001.png" name="button_cancel_material" type="2d"/>
    <material name="button_cancel_material" rgba="1 1 1 1.0" texture="button_cancel_material" shininess="0.4472135901451111" specular="1"/>
    <texture file="visuals/T_BC001.png" name="knob_doneness_material" type="2d"/>
    <material name="knob_doneness_material" rgba="1 1 1 1.0" texture="knob_doneness_material" shininess="0.4472135901451111" specular="0.8"/>
    <texture file="visuals/T_BC001.png" name="lever_material" type="2d"/>
    <material name="lever_material" rgba="1 1 1 1.0" texture="lever_material" shininess="0.4472135901451111" specular="0.8"/>
  </asset>
  <default>
    <default class="visual">
      <geom conaffinity="0" contype="0" group="1" type="mesh"/>
    </default>
    <default class="collision">
      <geom group="0" rgba="0.5 0 0 0.5" density="1.0" solref="0.004 1" solimp="0.998 0.998 0.001"/>
    </default>
    <default class="spawn">
      <geom group="0" rgba="1 1 1 0.5" contype="0" conaffinity="0"/>
      <site group="0" rgba="1 1 1 0.5"/>
    </default>
    <default class="region">
      <geom group="1" conaffinity="0" contype="0" rgba="0 1 0 0" mass="0"/>
    </default>
  </default>
  <worldbody>
    <body>
      <body name="object">
        <geom mesh="Body001_vis" type="mesh" solimp="0.998 0.998 0.001" solref="0.001 1" friction="0.95 0.3 0.1" class="visual" material="Body001_material"/>
        <geom type="box" pos="-0.07504845 0.01058266 0.00021636" size="0.021174892783164978 0.17523810267448425 0.11730574816465378" quat="1.0 0.0 0.0 0.0" class="collision"/>
        <geom type="box" pos="0.07381747 0.00834707 0.00021636" size="0.020160019397735596 0.1774737387895584 0.11730577051639557" quat="1.0 0.0 0.0 0.0" class="collision"/>
        <geom type="box" pos="0.00148916 0.03754975 0.00545023" size="0.013403093442320824 0.14827120304107666 0.11274226754903793" quat="1.0 0.0 0.0 0.0" class="collision"/>
        <geom type="box" pos="0.00073473 0.14547075 0.00055153" size="0.05448992922902107 0.040457259863615036 0.11764099448919296" quat="1.0 0.0 0.0 0.0" class="collision"/>
        <geom type="box" pos="0.00017980 -0.10956949 0.00530475" size="0.050426919013261795 0.02293148636817932 0.1123087927699089" quat="1.0 0.0 0.0 0.0" class="collision"/>
        <geom type="box" pos="0.00488791 0.01114249 -0.08444864" size="0.05540130287408829 0.17467844486236572 0.023428503423929214" quat="1.0 0.0 0.0 0.0" class="collision"/>
        <body name="button_cancel">
          <joint axis="0.0 1.0 0.0" pos="-0.04723416 -0.16826971 -0.07679564" limited="true" name="button_cancel_joint" range="0.0 0.002" type="slide" damping="1" frictionloss="1" armature=".01" stiffness="0.05"/>
          <geom mesh="button_cancel_vis" type="mesh" solimp="0.998 0.998 0.001" solref="0.001 1" friction="0.95 0.3 0.1" class="visual" material="button_cancel_material"/>
          <geom class="collision" type="cylinder" pos="-0.04726291 -0.16874505 -0.07679604" size="0.007795682642608881 0.0016939903143793344" quat="0.7071067094802856 0.70710688829422 0.0 0.0" name="button_cancel_main"/>
        </body>
        <body name="knob_doneness">
          <joint axis="0.0 1.0 0.0" pos="-0.00005406 -0.17574685 -0.07763972" limited="true" name="knob_doneness_joint" range="0.0 4.71238898038469" type="hinge" damping="0.05" frictionloss="0.1" armature="0.001"/>
          <geom mesh="knob_doneness_vis" type="mesh" solimp="0.998 0.998 0.001" solref="0.001 1" friction="0.95 0.3 0.1" class="visual" material="knob_doneness_material"/>
          <geom type="cylinder" pos="-0.00011330 -0.17101034 -0.07769664" size="0.01758095808327198 0.004087055567651987" quat="0.7071068286895752 0.7071067690849304 0.0 0.0" class="collision" density="0.001"/>
          <geom class="collision" type="box" pos="-0.00014808 -0.18031519 -0.07795726" size="0.005595101974904537 0.004999999888241291 0.016220778226852417" quat="0.9238795042037964 0.0 0.3826834559440613 0.0" name="knob_doneness_main" density="0.001"/>
        </body>
        <body name="lever">
          <joint axis="0.0 0.0 -1.0" pos="0.00000138 -0.14242431 0.08540410" limited="true" name="lever_joint" range="0.0 0.06" type="slide" damping="1" frictionloss="1" armature=".01" stiffness="2.2" springref="-0.5"/>
          <geom class="region" name="reg_slotL" type="box" pos="-0.032787995 0.009268605 0.11677094499999999" size="0.019773335000000003 0.093749535 0.076000075"/>
          <geom class="region" name="reg_slotR" type="box" pos="0.0337854 0.009268605 0.11677094499999999" size="0.01761961 0.093749535 0.076000075"/>
          <geom mesh="lever_vis" type="mesh" solimp="0.998 0.998 0.001" solref="0.001 1" friction="0.95 0.3 0.1" class="visual" material="lever_material"/>
          <geom class="collision" type="box" pos="0.00020692 -0.16417966 0.08713321" size="0.0056160325184464455 0.027931539341807365 0.026226477697491646" quat="0.7013015151023865 -0.09042166918516159 0.09042159467935562 0.7013016939163208" name="lever_handle"/>
          <geom class="collision" type="box" pos="-0.03304620 0.00926392 0.03621329" size="0.01916724070906639 0.09201328456401825 0.0007658192771486938" quat="1.0 0.0 0.0 0.0" name="slotL_floor"/>
          <geom class="collision" type="box" pos="0.03423255 0.00926392 0.03621329" size="0.017851172015070915 0.09201328456401825 0.0007658193353563547" quat="1.0 0.0 0.0 0.0" name="slotR_floor"/>
        </body>
        <geom class="region" name="reg_main" type="box" pos="-5.000000004307115e-09 0.009033680000000002 -3.800000000012127e-07" size="0.09439610500000001 0.17750923000000002 0.1176007"/>
      </body>
    </body>
  </worldbody>
  <actuator>
    <motor name="button_cancel_joint_actuator" joint="button_cancel_joint" gear="0.5"/>
    <motor name="knob_doneness_joint_actuator" joint="knob_doneness_joint" gear="10"/>
    <motor name="lever_joint_actuator" joint="lever_joint" gear="2"/>
  </actuator>
</mujoco>
