<?xml version='1.0' encoding='UTF-8'?>
<mujoco model="model">
  <option timestep="0.002" gravity="0.0 0.0 -9.81"/>
  <compiler angle="radian"/>
  <asset>
    <mesh file="visuals/button_lid.obj" name="button_lid_vis"/>
    <mesh file="visuals/Body001.obj" name="Body001_vis"/>
    <mesh file="visuals/kettle_main.obj" name="kettle_main_vis"/>
    <mesh file="visuals/kettle_main_Clear.obj" name="kettle_main_Clear_vis"/>
    <mesh file="visuals/lid.obj" name="lid_vis"/>
    <mesh file="visuals/switch.obj" name="switch_vis"/>
    <texture file="visuals/T_BC001.png" name="Body001_material" type="2d"/>
    <material name="Body001_material" rgba="1 1 1 1.0" texture="Body001_material" shininess="0.1" specular="5"/>
    <texture file="visuals/T_BC001.png" name="kettle_main_material" type="2d"/>
    <material name="kettle_main_material" rgba="1 1 1 1.0" texture="kettle_main_material" shininess="0.1" specular="5"/>
    <texture file="visuals/T_BC001.png" name="button_lid_material" type="2d"/>
    <material name="button_lid_material" rgba="1 1 1 1.0" texture="button_lid_material" shininess="0.1" specular="5"/>
    <texture file="visuals/T_BC001.png" name="kettle_main_Clear_material" type="2d"/>
    <material name="kettle_main_Clear_material" rgba="1 1 1 0.800000011920929" texture="kettle_main_Clear_material" shininess="0.141421377658844" specular="0.3103448502657381"/>
    <texture file="visuals/T_BC001.png" name="lid_material" type="2d"/>
    <material name="lid_material" rgba="1 1 1 1.0" texture="lid_material" shininess="0.1" specular="5"/>
    <texture file="visuals/T_BC001.png" name="switch_material" type="2d"/>
    <material name="switch_material" rgba="1 1 1 1.0" texture="switch_material" shininess="0.1" specular="5"/>
  </asset>
  <default>
    <default class="visual">
      <geom conaffinity="0" contype="0" group="1" type="mesh"/>
    </default>
    <default class="collision">
      <geom group="0" rgba="0.5 0 0 0.5"/>
    </default>
    <default class="spawn">
      <geom group="0" rgba="1 1 1 0.5" contype="0" conaffinity="0"/>
      <site group="0" rgba="1 1 1 0.5"/>
    </default>
    <default class="region">
      <geom group="1" conaffinity="0" contype="0" rgba="0 1 0 0" mass="0"/>
    </default>
  </default>
  <worldbody>
    <body>
      <body name="object">
        <geom mesh="Body001_vis" type="mesh" solimp="0.998 0.998 0.001" solref="0.001 1" friction="0.95 0.3 0.1" class="visual" material="Body001_material"/>
        <geom type="cylinder" pos="-0.027411337941884995 -0.00014148722402751446 -0.11141645163297653" size="0.07713119685649872 0.009560033679008484" quat="1.0 0.0 0.0 0.0" class="collision"/>
        <body name="kettle_main">
          <!-- <joint axis="0.0 0.0 1.0" pos="0.0 0.0 0.007473532110452652" limited="true" name="kettle_main_joint" range="0.0 0.1" type="slide" damping="1" frictionloss="1" armature=".01" stiffness="0.05"></joint> -->
          <geom mesh="kettle_main_vis" type="mesh" solimp="0.998 0.998 0.001" solref="0.001 1" friction="0.95 0.3 0.1" class="visual" material="kettle_main_material"/>
          <geom class="collision" type="box" pos="0.043139271438121796 0.00021091324742883444 0.10062777996063232" size="0.021188074722886086 0.019086692482233047 0.00618768809363246" quat="0.9914178252220154 0.0 0.13073121011257172 0.0" name="handle_1"/>
          <geom class="collision" type="box" pos="0.07470306754112244 0.00021091324742883444 0.07349132001399994" size="0.02591952495276928 0.019086692482233047 0.013031343929469585" quat="0.9236460328102112 0.0 0.3832467198371887 0.0" name="handle_3"/>
          <geom type="box" pos="0.038333527743816376 0.00021091324742883444 0.0646439790725708" size="0.02591952495276928 0.019086692482233047 0.008350091055035591" quat="0.7764915227890015 0.0 0.6301277279853821 0.0" class="collision"/>
          <geom class="collision" type="box" pos="0.0913977101445198 0.00021091324742883444 0.040479276329278946" size="0.02591952495276928 0.019086692482233047 0.013031343929469585" quat="0.7436996698379517 0.0 0.6685138940811157 0.0" name="handle_main"/>
          <geom class="collision" type="box" pos="0.08862174302339554 0.00021091324742883444 -0.0022946903482079506" size="0.02591952495276928 0.019086692482233047 0.013031343929469585" quat="0.5591312050819397 0.0 0.8290791511535645 0.0" name="handle_4"/>
          <geom class="collision" type="box" pos="0.06790471822023392 0.00021091324742883444 -0.03869720548391342" size="0.03122704289853573 0.019086692482233047 0.012154500000178814" quat="0.4453384280204773 0.0 0.8953623175621033 0.0" name="handle_5"/>
          <geom type="box" pos="0.04824516922235489 0.00021091324742883444 0.014211696572601795" size="0.02591952495276928 0.019086692482233047 0.008350091055035591" quat="0.7611410617828369 0.0 0.6485863924026489 0.0" class="collision"/>
          <geom type="box" pos="0.05432259663939476 0.00021091324742883444 -0.032876066863536835" size="0.02591952495276928 0.019086692482233047 0.008350091055035591" quat="0.7370997667312622 0.0 0.6757839322090149 0.0" class="collision"/>
          <geom type="box" pos="0.05268525704741478 0.00021091324742883444 -0.07152266800403595" size="0.0060615320689976215 0.019086692482233047 0.025983070954680443" quat="1.0 0.0 0.0 0.0" class="collision"/>
          <geom class="collision" type="box" pos="0.045523203909397125 0.00021091324742883444 0.0769275352358818" size="0.016873879358172417 0.019086692482233047 0.013031343929469585" quat="0.8781300187110901 0.0 0.478422075510025 0.0" name="handle_2"/>
          <geom type="box" pos="0.03180955722928047 0.00021091324742883444 0.08913789689540863" size="0.009536889381706715 0.019086692482233047 0.013031343929469585" quat="0.6158644556999207 0.0 0.7878521084785461 0.0" class="collision"/>
          <geom type="cylinder" pos="-0.027411337941884995 -0.00014148722402751446 -0.0824677124619484" size="0.0785139873623848 0.018464617431163788" quat="1.0 0.0 0.0 0.0" class="collision"/>
          <body name="button_lid">
            <joint axis="-0.2840818762779236 0.0 -0.9588000774383545" pos="0.038537777960300446 -0.00021366938017308712 0.11094487458467484" limited="true" name="button_lid_joint" range="0.0 0.0015" type="slide" damping="1" frictionloss="1" armature=".01" stiffness="0.05" springref="-2"/>
            <geom mesh="button_lid_vis" type="mesh" solimp="0.998 0.998 0.001" solref="0.001 1" friction="0.95 0.3 0.1" class="visual" material="button_lid_material"/>
            <geom class="collision" type="box" pos="0.03889802098274231 -0.00021366938017308712 0.1121906265616417" size="0.014842482283711433 0.003208839800208807 0.001418435713276267" quat="0.9931944608688354 0.0 0.11646802723407745 0.0" name="button_lid_main"/>
          </body>
          <body name="kettle_main_Clear">
            <geom mesh="kettle_main_Clear_vis" type="mesh" solimp="0.998 0.998 0.001" solref="0.001 1" friction="0.95 0.3 0.1" class="visual" material="kettle_main_Clear_material"/>
            <geom type="box" pos="-0.02687045931816101 -0.07368562370538712 -0.03169490769505501" size="0.023114826530218124 0.004641236737370491 0.03293635696172714" quat="1.0 0.0 0.0 0.0" class="collision"/>
            <geom type="box" pos="-0.026870455592870712 -0.06244158372282982 0.049160268157720566" size="0.023114824667572975 0.00464123860001564 0.04993676394224167" quat="0.9941283464431763 -0.1082073450088501 -0.0 0.0" class="collision"/>
            <geom type="box" pos="-0.060415118932724 -0.05307438224554062 0.049160268157720566" size="0.023114824667572975 0.00464123860001564 0.04993676394224167" quat="0.954690158367157 -0.10391447693109512 0.03017573617398739 -0.2772325873374939" class="collision"/>
            <geom type="box" pos="-0.06643757969141006 -0.06256955862045288 -0.03169490769505501" size="0.023114826530218124 0.00464123860001564 0.03293635696172714" quat="0.9603288769721985 0.0 -0.0 -0.27886995673179626" class="collision"/>
            <geom type="box" pos="-0.09424497932195663 -0.03125660866498947 -0.03169490769505501" size="0.023114826530218124 0.00464123860001564 0.03293635696172714" quat="0.8415003418922424 0.0 -0.0 -0.5402565598487854" class="collision"/>
            <geom type="box" pos="-0.08402130752801895 -0.026576334610581398 0.049160268157720566" size="0.023114824667572975 0.00464123860001564 0.04993676394224167" quat="0.8365593552589417 -0.09105635434389114 0.05845963582396507 -0.5370844006538391" class="collision"/>
            <geom type="box" pos="-0.08917441219091415 0.009867627173662186 0.049160268157720566" size="0.023114826530218124 0.00464123860001564 0.04993676394224167" quat="0.6411194801330566 -0.06978342682123184 0.08269856125116348 -0.7597743272781372" class="collision"/>
            <geom type="box" pos="-0.10025826096534729 0.011758790351450443 -0.03169490769505501" size="0.023114828392863274 0.00464123860001564 0.03293635696172714" quat="0.6449061036109924 0.0 -0.0 -0.764261782169342" class="collision"/>
            <geom type="box" pos="-0.08117441087961197 0.0505029559135437 -0.03169490769505501" size="0.023114826530218124 0.00464123860001564 0.03293635696172714" quat="0.3926233649253845 0.0 -0.0 -0.9196993708610535" class="collision"/>
            <geom type="box" pos="-0.07305407524108887 0.04272552579641342 0.049160268157720566" size="0.023114824667572975 0.00464123860001564 0.04993676394224167" quat="0.3903179168701172 -0.04248465970158577 0.09951813519001007 -0.9142992496490479" class="collision"/>
            <geom type="box" pos="-0.04157891869544983 0.060840267688035965 0.049160268157720566" size="0.023114824667572975 0.004641239065676928 0.04993676394224167" quat="0.10759035497903824 -0.01171080395579338 0.1075715497136116 -0.9882891774177551" class="collision"/>
            <geom type="box" pos="-0.04399840533733368 0.07182089239358902 -0.03169490769505501" size="0.023114826530218124 0.00464123860001564 0.03293635696172714" quat="0.10822581499814987 0.0 -0.0 -0.9941263198852539" class="collision"/>
            <geom type="box" pos="-0.0009369682520627975 0.06872864812612534 -0.03169490769505501" size="0.023114826530218124 0.00464123860001564 0.03293635696172714" quat="0.18773965537548065 0.0 0.0 0.9822188019752502" class="collision"/>
            <geom type="box" pos="-0.005083801690489054 0.05827724188566208 0.049160268157720566" size="0.023114824667572975 0.004641239065676928 0.04993676394224167" quat="0.18663731217384338 -0.020314807072281837 -0.1062832847237587 0.976451575756073" class="collision"/>
            <geom type="box" pos="0.023972077295184135 0.035334523767232895 0.049160268157720566" size="0.023114824667572975 0.00464123860001564 0.04993676394224167" quat="0.4677036702632904 -0.050907790660858154 -0.0954839363694191 0.8772368431091309" class="collision"/>
            <geom type="box" pos="0.03330794721841812 0.04160107672214508 -0.03169490769505501" size="0.023114826530218124 0.00464123860001564 0.03293635696172714" quat="0.4704661965370178 0.0 0.0 0.8824180364608765" class="collision"/>
            <geom type="box" pos="0.04617307335138321 -0.00041814439464360476 -0.03169490769505501" size="0.023114826530218124 0.00464123860001564 0.03293635696172714" quat="0.7121827602386475 0.0 0.0 0.7019941210746765" class="collision"/>
            <geom type="box" pos="0.03493022173643112 -0.0002561284927651286 0.049160268157720566" size="0.023114824667572975 0.00464123860001564 0.04993676394224167" quat="0.7080011367797852 -0.07706322520971298 -0.07596074044704437 0.6978722214698792" class="collision"/>
            <geom type="box" pos="0.023652678355574608 -0.035795554518699646 0.049160268157720566" size="0.023114824667572975 0.00464123860001564 0.04993676394224167" quat="0.8840618133544922 -0.09622674435377121 -0.04948921129107475 0.4546712338924408" class="collision"/>
            <geom type="box" pos="0.03279901295900345 -0.04233564808964729 -0.03169490769505501" size="0.023114826530218124 0.00464123860001564 0.03293635696172714" quat="0.889283299446106 0.0 0.0 0.4573568105697632" class="collision"/>
            <geom type="box" pos="0.007360944524407387 -0.06491312384605408 -0.03169490769505501" size="0.023114826530218124 0.00464123860001564 0.03293635696172714" quat="0.9708279371261597 0.0 0.0 0.23977723717689514" class="collision"/>
            <geom type="box" pos="0.002126123523339629 -0.05496200919151306 0.049160268157720566" size="0.023114824667572975 0.00464123860001564 0.04993676394224167" quat="0.9651275873184204 -0.10505039244890213 -0.025945579633116722 0.23836936056613922" class="collision"/>
          </body>
          <body name="lid">
            <joint axis="0.0 1.0 0.0" pos="0.018651749938726425 -1.6279518604278564e-06 0.11513517051935196" limited="true" name="lid_joint" range="0.0 1.5707963267948966" type="hinge" damping="1" frictionloss="1" armature=".01" stiffness="0.05"/>
            <geom mesh="lid_vis" type="mesh" solimp="0.998 0.998 0.001" solref="0.001 1" friction="0.95 0.3 0.1" class="visual" material="lid_material"/>
            <geom class="collision" type="cylinder" pos="-0.026940740644931793 -1.6279518604278564e-06 0.10010033845901489" size="0.04084323412179947 0.018784377723932266" quat="1.0 0.0 0.0 0.0" name="lid_main"/>
          </body>
          <body name="switch">
            <joint axis="0.0 1.0 0.0" pos="0.05468204990029335 -0.00029036635532975197 -0.09035534411668777" limited="true" name="switch_joint" range="0.0 0.2617993877991494" type="hinge" damping="1" frictionloss="1" armature=".01" stiffness="0.05" springref="-1"/>
            <geom mesh="switch_vis" type="mesh" solimp="0.998 0.998 0.001" solref="0.001 1" friction="0.95 0.3 0.1" class="visual" material="switch_material"/>
            <geom class="collision" type="box" pos="0.07512793689966202 -0.0002831017191056162 -0.09035534411668777" size="0.014685453847050667 0.010064838454127312 0.001832139678299427" quat="1.0 0.0 0.0 0.0" name="switch_main"/>
          </body>
        </body>
        <geom class="region" name="reg_main" type="box" pos="1.862645149230957e-09 0.0 0.0" size="0.1065677980184555 0.07904344594478607 0.12214959955215454"/>
      </body>
    </body>
  </worldbody>
  <actuator>
    <!-- <motor name="kettle_main_joint_actuator" joint="kettle_main_joint" gear="10"/> -->
    <motor name="button_lid_joint_actuator" joint="button_lid_joint" gear="0.5"/>
    <motor name="lid_joint_actuator" joint="lid_joint" gear="0.5"/>
    <motor name="switch_joint_actuator" joint="switch_joint" gear="0.5"/>
  </actuator>
</mujoco>