<?xml version='1.0' encoding='UTF-8'?>
<mujoco model="model">
  <option timestep="0.002" gravity="0.0 0.0 -9.81"/>
  <compiler angle="radian"/>
  <asset>
    <mesh file="visuals/knob_center.obj" name="knob_center_vis"/>
    <mesh file="visuals/knob_front_left.obj" name="knob_front_left_vis"/>
    <mesh file="visuals/knob_front_right.obj" name="knob_front_right_vis"/>
    <mesh file="visuals/knob_rear_left.obj" name="knob_rear_left_vis"/>
    <mesh file="visuals/knob_rear_right.obj" name="knob_rear_right_vis"/>
    <mesh file="visuals/Body001.obj" name="Body001_vis"/>
    <texture file="visuals/T_BC001.png" name="Body001_material" type="2d"/>
    <material name="Body001_material" rgba="1 1 1 1.0" texture="Body001_material" shininess="0.1" specular="0.99"/>
    <texture file="visuals/T_BC001.png" name="knob_center_material" type="2d"/>
    <material name="knob_center_material" rgba="1 1 1 1.0" texture="knob_center_material" shininess="0.1" specular="0.99"/>
    <texture file="visuals/T_BC001.png" name="knob_front_left_material" type="2d"/>
    <material name="knob_front_left_material" rgba="1 1 1 1.0" texture="knob_front_left_material" shininess="0.1" specular="0.99"/>
    <texture file="visuals/T_BC001.png" name="knob_front_right_material" type="2d"/>
    <material name="knob_front_right_material" rgba="1 1 1 1.0" texture="knob_front_right_material" shininess="0.1" specular="0.99"/>
    <texture file="visuals/T_BC001.png" name="knob_rear_left_material" type="2d"/>
    <material name="knob_rear_left_material" rgba="1 1 1 1.0" texture="knob_rear_left_material" shininess="0.1" specular="0.99"/>
    <texture file="visuals/T_BC001.png" name="knob_rear_right_material" type="2d"/>
    <material name="knob_rear_right_material" rgba="1 1 1 1.0" texture="knob_rear_right_material" shininess="0.1" specular="0.99"/>
  </asset>
  <default>
    <default class="visual">
      <geom conaffinity="0" contype="0" group="1" type="mesh"/>
    </default>
    <default class="collision">
      <geom group="0" rgba="0.5 0 0 0.5"/>
    </default>
    <default class="spawn">
      <geom group="0" rgba="1 1 1 0.5" contype="0" conaffinity="0"/>
      <site group="0" rgba="1 1 1 0.5"/>
    </default>
    <default class="region">
      <geom group="1" conaffinity="0" contype="0" rgba="0 1 0 0"/>
    </default>
  </default>
  <worldbody>
    <body>
      <body name="object">
        <geom mesh="Body001_vis" type="mesh" solimp="0.998 0.998 0.001" solref="0.001 1" friction="0.95 0.3 0.1" class="visual" material="Body001_material"/>
        <geom class="collision" type="box" pos="-0.00029522180557250977 1.8924474716186523e-05 -0.009677570313215256" size="0.5993380546569824 0.39361193776130676 0.01063532568514347" quat="1.0 0.0 0.0 0.0"/>
        <geom class="collision" type="box" pos="-7.250926864799112e-05 0.029300684109330177 -6.970670074224472e-05" size="0.5444291234016418 0.3083740472793579 0.005356773268431425" quat="1.0 0.0 0.0 0.0"/>
        <body name="knob_center">
          <joint axis="0.0 0.0 1.0" pos="0.0015727486461400986 -0.34418222308158875 0.009913011454045773" limited="true" name="knob_center_joint" range="0.0 3.141592653589793" type="hinge" damping="0.05" armature="0.001"/>
          <geom mesh="knob_center_vis" type="mesh" solimp="0.998 0.998 0.001" solref="0.001 1" friction="0.95 0.3 0.1" class="visual" material="knob_center_material"/>
          <geom class="collision" type="cylinder" pos="0.0007215924561023712 -0.3444579541683197 0.005814229138195515" size="0.025363123044371605 0.0042502121068537235" quat="1.0 0.0 0.0 0.0"/>
          <geom class="collision" type="box" pos="0.00024800002574920654 -0.3441460430622101 0.011451083235442638" size="0.009305347688496113 0.023183301091194153 0.007698982022702694" quat="0.9997909665107727 -0.020444730296730995 0.0 0.0" name="knob_center_main"/>
        </body>
        <body name="knob_front_left">
          <joint axis="0.0 0.0 1.0" pos="-0.2281254231929779 -0.34418222308158875 0.009913011454045773" limited="true" name="knob_front_left_joint" range="0.0 3.141592653589793" type="hinge" damping="0.05" armature="0.001"/>
          <geom mesh="knob_front_left_vis" type="mesh" solimp="0.998 0.998 0.001" solref="0.001 1" friction="0.95 0.3 0.1" class="visual" material="knob_front_left_material"/>
          <geom class="collision" type="cylinder" pos="-0.22827336192131042 -0.34419381618499756 0.0058477697893977165" size="0.02581617794930935 0.004138886462897062" quat="1.0 0.0 0.0 0.0"/>
          <geom class="collision" type="box" pos="-0.22847935557365417 -0.3441460430622101 0.011451083235442638" size="0.009305347688496113 0.023183301091194153 0.007698982022702694" quat="0.9997909665107727 -0.020444730296730995 0.0 0.0" name="knob_front_left_main"/>
        </body>
        <body name="knob_front_right">
          <joint axis="0.0 0.0 1.0" pos="0.2340814471244812 -0.34418222308158875 0.009913011454045773" limited="true" name="knob_front_right_joint" range="0.0 3.141592653589793" type="hinge" damping="0.05" armature="0.001"/>
          <geom mesh="knob_front_right_vis" type="mesh" solimp="0.998 0.998 0.001" solref="0.001 1" friction="0.95 0.3 0.1" class="visual" material="knob_front_right_material"/>
          <geom class="collision" type="cylinder" pos="0.2347954511642456 -0.34429094195365906 0.005814229138195515" size="0.025363123044371605 0.0042502121068537235" quat="1.0 0.0 0.0 0.0"/>
          <geom class="collision" type="box" pos="0.23388102650642395 -0.3441460430622101 0.011451083235442638" size="0.009305347688496113 0.023183301091194153 0.007698982022702694" quat="0.9997909665107727 -0.020444730296730995 0.0 0.0" name="knob_front_right_main"/>
        </body>
        <body name="knob_rear_left">
          <joint axis="0.0 0.0 1.0" pos="-0.11417058855295181 -0.34418222308158875 0.009913011454045773" limited="true" name="knob_rear_left_joint" range="0.0 3.141592653589793" type="hinge" damping="0.05" armature="0.001"/>
          <geom mesh="knob_rear_left_vis" type="mesh" solimp="0.998 0.998 0.001" solref="0.001 1" friction="0.95 0.3 0.1" class="visual" material="knob_rear_left_material"/>
          <geom class="collision" type="cylinder" pos="-0.11459353566169739 -0.34462302923202515 0.005814229138195515" size="0.025363123044371605 0.0042502121068537235" quat="1.0 0.0 0.0 0.0"/>
          <geom class="collision" type="box" pos="-0.1144222840666771 -0.3441460430622101 0.011451083235442638" size="0.009305347688496113 0.023183301091194153 0.007698982022702694" quat="0.9997909665107727 -0.020444730296730995 0.0 0.0" name="knob_rear_left_main"/>
        </body>
        <body name="knob_rear_right">
          <joint axis="0.0 0.0 1.0" pos="0.11450554430484772 -0.34418222308158875 0.009913011454045773" limited="true" name="knob_rear_right_joint" range="0.0 3.141592653589793" type="hinge" damping="0.05" armature="0.001"/>
          <geom mesh="knob_rear_right_vis" type="mesh" solimp="0.998 0.998 0.001" solref="0.001 1" friction="0.95 0.3 0.1" class="visual" material="knob_rear_right_material"/>
          <geom class="collision" type="cylinder" pos="0.11459513008594513 -0.34395888447761536 0.005814229138195515" size="0.025363123044371605 0.0042502121068537235" quat="1.0 0.0 0.0 0.0"/>
          <geom class="collision" type="box" pos="0.1149182841181755 -0.3441460430622101 0.011451083235442638" size="0.009305347688496113 0.023183301091194153 0.007698982022702694" quat="0.9997909665107727 -0.020444730296730995 0.0 0.0" name="knob_rear_right_main"/>
        </body>
        <site type="cylinder" rgba="0.3 0.4 1 0.5" size="0.10174809396266937 0.006138943135738373" pos="4.069006536155939e-05 0.030525188893079758 -0.0055334921926259995" name="burner_on_center"/>
        <site type="cylinder" rgba="0.3 0.4 1 0.5" size="0.042219217866659164 0.0061389426700770855" pos="-0.35221078991889954 -0.11905696243047714 -0.0055334921926259995" name="burner_on_front_left"/>
        <site type="cylinder" rgba="0.3 0.4 1 0.5" size="0.05456821620464325 0.006138941738754511" pos="0.35252463817596436 -0.12075084447860718 -0.005533489864319563" name="burner_on_front_right"/>
        <site type="cylinder" rgba="0.3 0.4 1 0.5" size="0.05681011453270912 0.006138941273093224" pos="-0.35137036442756653 0.18157240748405457 -0.005533493123948574" name="burner_on_rear_left"/>
        <site type="cylinder" rgba="0.3 0.4 1 0.5" size="0.056028492748737335 0.006138943135738373" pos="0.3526456952095032 0.18153207004070282 -0.005533491261303425" name="burner_on_rear_right"/>
        <site type="cylinder" rgba="0.5 0 0 0" size="0.10174809396266937 4.999999873689376e-05" pos="4.069006536155939e-05 0.030525188893079758 0.005251838825643063" name="burner_center_place_site"/>
        <site type="cylinder" rgba="0.5 0 0 0" size="0.042219217866659164 4.999999873689376e-05" pos="-0.35221078991889954 -0.11905696243047714 0.005251838825643063" name="burner_front_left_place_site"/>
        <site type="cylinder" rgba="0.5 0 0 0" size="0.05456821620464325 4.999999873689376e-05" pos="0.35252463817596436 -0.12075084447860718 0.005251838825643063" name="burner_front_right_place_site"/>
        <site type="cylinder" rgba="0.5 0 0 0" size="0.05681011453270912 4.999999873689376e-05" pos="-0.35137036442756653 0.18157240748405457 0.005251838825643063" name="burner_rear_left_place_site"/>
        <site type="cylinder" rgba="0.5 0 0 0" size="0.056028492748737335 4.999999873689376e-05" pos="0.3526456952095032 0.18153207004070282 0.005251838825643063" name="burner_rear_right_place_site"/>
        <geom class="region" name="reg_main" type="box" pos="0.0 0.0 -0.009289504960179329" size="0.5996396074295044 0.39434142208099365 0.011304404422640801"/>
      </body>
    </body>
  </worldbody>
  <actuator>
    <motor name="knob_center_joint_actuator" joint="knob_center_joint" gear="10"/>
    <motor name="knob_front_left_joint_actuator" joint="knob_front_left_joint" gear="10"/>
    <motor name="knob_front_right_joint_actuator" joint="knob_front_right_joint" gear="10"/>
    <motor name="knob_rear_left_joint_actuator" joint="knob_rear_left_joint" gear="10"/>
    <motor name="knob_rear_right_joint_actuator" joint="knob_rear_right_joint" gear="10"/>
  </actuator>
</mujoco>
