<?xml version='1.0' encoding='UTF-8'?>
<mujoco model="model">
  <option timestep="0.002" gravity="0.0 0.0 -9.81"/>
  <compiler angle="radian"/>
  <asset>
    <mesh file="visuals/button_power.obj" name="button_power_vis"/>
    <mesh file="visuals/Body001.obj" name="Body001_vis"/>
    <mesh file="visuals/door.obj" name="door_vis"/>
    <mesh file="visuals/rack0.obj" name="rack0_vis"/>
    <mesh file="visuals/rack1.obj" name="rack1_vis"/>
    <texture file="visuals/T_BC001.png" name="Body001_material" type="2d"/>
    <material name="Body001_material" rgba="1 1 1 1.0" texture="Body001_material" shininess="2" specular="2"/>
    <texture file="visuals/T_BC001.png" name="button_power_material" type="2d"/>
    <material name="button_power_material" rgba="1 1 1 1.0" texture="button_power_material" shininess="2" specular="2"/>
    <texture file="visuals/T_BC001.png" name="door_material" type="2d"/>
    <material name="door_material" rgba="1 1 1 1.0" texture="door_material" shininess="2" specular="2"/>
    <texture file="visuals/T_BC001.png" name="rack0_material" type="2d"/>
    <material name="rack0_material" rgba="1 1 1 1.0" texture="rack0_material" shininess="10" specular="10"/>
    <texture file="visuals/T_BC001.png" name="rack1_material" type="2d"/>
    <material name="rack1_material" rgba="1 1 1 1.0" texture="rack1_material" shininess="10" specular="10"/>
  </asset>
  <default>
    <default class="visual">
      <geom conaffinity="0" contype="0" group="1" type="mesh"/>
    </default>
    <default class="collision">
      <geom group="0" rgba="0.5 0 0 0.5"/>
    </default>
    <default class="spawn">
      <geom group="0" rgba="1 1 1 0.5" contype="0" conaffinity="0"/>
      <site group="0" rgba="1 1 1 0.5"/>
    </default>
    <default class="region">
      <geom group="1" conaffinity="0" contype="0" rgba="0 1 0 0"/>
    </default>
  </default>
  <worldbody>
    <body>
      <body name="object">
        <geom mesh="Body001_vis" type="mesh" solimp="0.998 0.998 0.001" solref="0.001 1" friction="0.95 0.3 0.1" class="visual" material="Body001_material"/>
        <geom class="collision" type="box" pos="-0.31074389815330505 0.04210297390818596 -0.0015653906157240272" size="0.015660235658288002 0.3092889189720154 0.4851975739002228" quat="1.0 0.0 0.0 0.0"/>
        <geom class="collision" type="box" pos="-0.0004225249867886305 -0.285555362701416 -0.4219219982624054" size="0.32598164677619934 0.013015281409025192 0.06484092026948929" quat="1.0 0.0 0.0 0.0"/>
        <geom class="collision" type="box" pos="-0.0014278511516749859 0.031286075711250305 0.3953034281730652" size="0.3249762952327728 0.3201058506965637 0.08955497294664383" quat="1.0 0.0 0.0 0.0"/>
        <geom class="collision" type="box" pos="-0.0008205829653888941 0.026971997693181038 -0.4234071671962738" size="0.3255835771560669 0.3244198262691498 0.06335577368736267" quat="1.0 0.0 0.0 0.0"/>
        <geom class="collision" type="box" pos="0.0009469911456108093 0.2978161871433258 -0.0015653906157240272" size="0.2965596318244934 0.053575702011585236 0.4851975739002228" quat="1.0 0.0 0.0 0.0"/>
        <geom class="collision" type="box" pos="-0.0003573329886421561 -0.28971847891807556 0.442055881023407" size="0.32604682445526123 0.008409310132265091 0.043088555335998535" quat="1.0 0.0 0.0 0.0"/>
        <geom class="collision" type="box" pos="0.28995102643966675 -0.009116381406784058 0.16600890457630157" size="0.016765600070357323 0.24925102293491364 0.012454171665012836" quat="0.9512218236923218 0.0 -0.3085077702999115 0.0"/>
        <geom class="collision" type="box" pos="-0.2861086130142212 -0.010392174124717712 0.16318382322788239" size="0.016765600070357323 0.24744851887226105 0.012454171665012836" quat="1.0 0.0 0.0 0.0"/>
        <geom class="collision" type="box" pos="-0.2861086130142212 -0.010392174124717712 -0.1537511646747589" size="0.016765600070357323 0.24744851887226105 0.012454171665012836" quat="1.0 0.0 0.0 0.0"/>
        <geom class="collision" type="box" pos="0.28995102643966675 -0.009116381406784058 -0.15092608332633972" size="0.016765600070357323 0.24925102293491364 0.012454171665012836" quat="0.9512218236923218 0.0 -0.3085077702999115 0.0"/>
        <geom class="collision" type="box" pos="0.3109588921070099 0.04210297390818596 -0.0015653906157240272" size="0.015445224940776825 0.3092889189720154 0.4851975739002228" quat="1.0 0.0 0.0 0.0"/>
        <body name="button_power">
          <joint axis="0.0 1.0 0.0" pos="0.29694992303848267 -0.3024997115135193 0.3710770905017853" limited="true" name="button_power_joint" range="0.0 0.005" type="slide" damping="1" frictionloss="1" armature=".01" stiffness="4" springref="-1"/>
          <geom mesh="button_power_vis" type="mesh" solimp="0.998 0.998 0.001" solref="0.001 1" friction="0.95 0.3 0.1" class="visual" material="button_power_material"/>
          <geom class="collision" type="box" pos="0.29694992303848267 -0.30306148529052734 0.3710770905017853" size="0.0164952352643013 0.0035244703758507967 0.02042667753994465" quat="1.0 0.0 0.0 0.0"/>
        </body>
        <body name="door">
          <joint axis="1.0 0.0 0.0" pos="-0.00018922117305919528 -0.2985706701874733 -0.349735789000988" limited="true" name="door_joint" range="0.0 0.6035987755982988" type="hinge" damping="1" frictionloss="10" armature="1" stiffness="2"/>
          <geom mesh="door_vis" type="mesh" solimp="0.998 0.998 0.001" solref="0.001 1" friction="0.95 0.3 0.1" class="visual" material="door_material"/>
          <geom class="collision" type="box" pos="-0.00018922117305919528 -0.2843288481235504 -0.025368444621562958" size="0.3262149393558502 0.011756437830626965 0.32436734437942505" quat="1.0 0.0 0.0 0.0"/>
          <geom class="collision" type="cylinder" pos="0.2391108274459839 -0.31386852264404297 0.26950329542160034" size="0.011444659903645515 0.014086979441344738" quat="0.5 0.5 0.4999999701976776 -0.5"/>
          <geom class="collision" type="cylinder" pos="0.015101909637451172 -0.34027668833732605 0.26950329542160034" size="0.01144466269761324 0.23524464666843414" quat="0.7071068286895752 -0.0 0.7071067690849304 0.0" name="door_handle_main"/>
          <geom class="collision" type="cylinder" pos="-0.2097417712211609 -0.31286537647247314 0.2697909474372864" size="0.01144466269761324 0.014086979441344738" quat="0.5 0.5 0.4999999701976776 -0.5"/>
          <geom class="collision" type="box" pos="-0.00018922117305919528 -0.2939428985118866 -0.025368444621562958" size="0.3262149393558502 0.0046277716755867004 0.32436734437942505" quat="1.0 0.0 0.0 0.0" name="door_main"/>
        </body>
        <body name="rack0">
          <geom class="region" name="reg_rack0" type="box" pos="-0.0005035474896430969 0.00885559618473053 -0.1099739819765091" size="0.24927804416418076 0.1946556249856949 0.12362563407421112"/>
          <joint axis="0.0 -1.0 0.0" pos="0.0011369017884135246 0.009013836272060871 -0.19645054638385773" limited="true" name="rack0_joint" range="0.0 0.09" type="slide" damping="1" frictionloss="1" armature=".01" stiffness="0.05"/>
          <geom mesh="rack0_vis" type="mesh" solimp="0.998 0.998 0.001" solref="0.001 1" friction="0.95 0.3 0.1" class="visual" material="rack0_material"/>
          <geom class="collision" type="box" pos="0.2601785659790039 0.009433153085410595 -0.21831165254116058" size="0.0028752374928444624 0.20597416162490845 0.07085639983415604" quat="0.9996649622917175 0.0 0.02588295005261898 0.0"/>
          <geom class="collision" type="box" pos="0.14208747446537018 -0.19310100376605988 -0.17227700352668762" size="0.0028752374928444624 0.0034400008153170347 0.07150132954120636" quat="1.0 0.0 0.0 0.0"/>
          <geom class="collision" type="box" pos="-0.006363436579704285 -0.193630188703537 -0.17979823052883148" size="0.0028752374928444624 0.00291081378236413 0.07902255654335022" quat="1.0 0.0 0.0 0.0"/>
          <geom class="collision" type="box" pos="-0.13641364872455597 -0.19315925240516663 -0.17979823052883148" size="0.0028752374928444624 0.003381751012057066 0.07902255654335022" quat="1.0 0.0 0.0 0.0"/>
          <geom class="collision" type="box" pos="-0.2753942608833313 0.009433153085410595 -0.13552449643611908" size="0.012880324386060238 0.20597416162490845 0.003205620450899005" quat="1.0 0.0 0.0 0.0"/>
          <geom class="collision" type="box" pos="-0.25940003991127014 0.009433153085410595 -0.21402280032634735" size="0.0028752374928444624 0.20597416162490845 0.07541237026453018" quat="0.9998655319213867 0.0 -0.01640046387910843 0.0"/>
          <geom class="collision" type="box" pos="0.24281170964241028 0.009433153085410595 -0.29280000925064087" size="0.016986049711704254 0.20597416162490845 0.0034507845994085073" quat="1.0 0.0 0.0 0.0"/>
          <geom class="collision" type="box" pos="0.13599054515361786 0.00883317831903696 -0.26949208974838257" size="0.0028752374928444624 0.2060575932264328 0.02738598734140396" quat="1.0 0.0 0.0 0.0"/>
          <geom class="collision" type="box" pos="-0.11531074345111847 0.007706544827669859 -0.27247416973114014" size="0.021465769037604332 0.20655052363872528 0.0034507852979004383" quat="0.8538821935653687 0.0 0.5204663276672363 0.0"/>
          <geom class="collision" type="box" pos="-0.17202086746692657 0.00963241420686245 -0.2762652635574341" size="0.04208718240261078 0.2057749181985855 0.0034507852979004383" quat="0.976375937461853 0.0 -0.2160787284374237 0.0"/>
          <geom class="collision" type="box" pos="0.18302851915359497 0.008778777904808521 -0.26716160774230957" size="0.05139434337615967 0.20498640835285187 0.0034507852979004383" quat="0.9649385213851929 0.0 0.26247602701187134 0.0"/>
          <geom class="collision" type="box" pos="0.05050894618034363 0.007706544827669859 -0.2728479504585266" size="0.0846700668334961 0.20655052363872528 0.0034507852979004383" quat="0.9919333457946777 0.0 0.1267605870962143 0.0"/>
          <geom class="collision" type="box" pos="-0.037192992866039276 0.009365230798721313 -0.2719617486000061" size="0.021055378019809723 0.2048918455839157 0.003450785530731082" quat="0.8327611684799194 0.0 -0.5536324381828308 0.0"/>
          <geom class="collision" type="box" pos="-0.028020158410072327 0.032729458063840866 -0.23228012025356293" size="0.06565605849027634 0.18267786502838135 0.003450785530731082" quat="0.8327611684799194 0.0 -0.5536324381828308 0.0"/>
          <geom class="collision" type="box" pos="-0.00038360804319381714 -0.19653765857219696 -0.16516639292240143" size="0.26663410663604736 0.0031389184296131134 0.0034507845994085073" quat="1.0 0.0 0.0 0.0"/>
          <geom class="collision" type="box" pos="0.00156847620382905 -0.19638462364673615 -0.1000041514635086" size="0.29132577776908875 0.0031389184296131134 0.0034507845994085073" quat="1.0 0.0 0.0 0.0"/>
          <geom class="collision" type="box" pos="-0.2851855456829071 0.008442491292953491 -0.11516757309436798" size="0.0028752374928444624 0.20498350262641907 0.017951978370547295" quat="1.0 0.0 0.0 0.0"/>
          <geom class="collision" type="box" pos="-0.07622170448303223 0.009433153085410595 -0.29280000925064087" size="0.03436841815710068 0.20597416162490845 0.0034507845994085073" quat="1.0 0.0 0.0 0.0"/>
          <geom class="collision" type="box" pos="0.00156847620382905 0.2151338905096054 -0.1000041514635086" size="0.29132577776908875 0.0031389184296131134 0.0034507845994085073" quat="1.0 0.0 0.0 0.0"/>
          <geom class="collision" type="box" pos="-0.00038360804319381714 0.2151338905096054 -0.16516639292240143" size="0.26663410663604736 0.0031389184296131134 0.0034507845994085073" quat="1.0 0.0 0.0 0.0"/>
          <geom class="collision" type="box" pos="-0.00038360804319381714 0.2151338905096054 -0.2438908964395523" size="0.26663410663604736 0.0031389184296131134 0.0034507845994085073" quat="1.0 0.0 0.0 0.0"/>
          <geom class="collision" type="box" pos="0.28881484270095825 0.008442491292953491 -0.11348722875118256" size="0.0028752374928444624 0.20498350262641907 0.015420433133840561" quat="1.0 0.0 0.0 0.0"/>
          <geom class="collision" type="box" pos="0.2766624391078949 0.009433153085410595 -0.13924627006053925" size="0.016239330172538757 0.20597416162490845 0.003205620450899005" quat="0.950692892074585 0.0 -0.3101339042186737 0.0"/>
          <geom class="collision" type="box" pos="0.14208747446537018 0.21093378961086273 -0.17227700352668762" size="0.0028752374928444624 0.0034400008153170347 0.07150132954120636" quat="1.0 0.0 0.0 0.0"/>
          <geom class="collision" type="box" pos="0.13117694854736328 0.0095750093460083 -0.2305232137441635" size="0.0028752374928444624 0.1594955176115036 0.06274466961622238" quat="1.0 0.0 0.0 0.0"/>
          <geom class="collision" type="box" pos="-0.13641364872455597 0.21017642319202423 -0.17979823052883148" size="0.0028752374928444624 0.003381751012057066 0.07902255654335022" quat="1.0 0.0 0.0 0.0"/>
          <geom class="collision" type="box" pos="-0.006363436579704285 0.21039453148841858 -0.17979823052883148" size="0.0028752374928444624 0.00291081378236413 0.07902255654335022" quat="1.0 0.0 0.0 0.0"/>
          <geom class="collision" type="box" pos="-0.00038360804319381714 -0.19794560968875885 -0.2438908964395523" size="0.26663410663604736 0.0031389184296131134 0.0034507845994085073" quat="1.0 0.0 0.0 0.0"/>
          <geom class="collision" type="box" pos="-0.23661816120147705 0.009433153085410595 -0.29320621490478516" size="0.02875845693051815 0.20597416162490845 0.0038504458498209715" quat="1.0 0.0 0.0 0.0"/>
        </body>
        <body name="rack1">
          <geom class="region" name="reg_rack1" type="box" pos="-0.0005035474896430969 0.00885559618473053 0.19251640513539314" size="0.24927804416418076 0.1946556249856949 0.10889726302027702"/>
          <joint axis="0.0 -1.0 0.0" pos="0.0011369017884135246 0.009013836272060871 0.11977115273475647" limited="true" name="rack1_joint" range="0.0 0.26" type="slide" damping="1" frictionloss="1" armature=".01" stiffness="0.05"/>
          <geom mesh="rack1_vis" type="mesh" solimp="0.998 0.998 0.001" solref="0.001 1" friction="0.95 0.3 0.1" class="visual" material="rack1_material"/>
          <geom class="collision" type="box" pos="-0.23661816120147705 0.009433153085410595 0.023139236494898796" size="0.02875845693051815 0.20597416162490845 0.0038504458498209715" quat="1.0 0.0 0.0 0.0"/>
          <geom class="collision" type="box" pos="-0.07622170448303223 0.009433153085410595 0.02354547008872032" size="0.03436841815710068 0.20597416162490845 0.0034507845994085073" quat="1.0 0.0 0.0 0.0"/>
          <geom class="collision" type="box" pos="0.24281170964241028 0.009433153085410595 0.02354547008872032" size="0.016986049711704254 0.20597416162490845 0.0034507845994085073" quat="1.0 0.0 0.0 0.0"/>
          <geom class="collision" type="box" pos="-0.25940003991127014 0.009433153085410595 0.10232266783714294" size="0.0028752374928444624 0.20597416162490845 0.07541237026453018" quat="0.9998655319213867 0.0 -0.01640046387910843 0.0"/>
          <geom class="collision" type="box" pos="-0.2753942608833313 0.009433153085410595 0.18082097172737122" size="0.012880324386060238 0.20597416162490845 0.003205620450899005" quat="1.0 0.0 0.0 0.0"/>
          <geom class="collision" type="box" pos="-0.13641364872455597 -0.19315925240516663 0.1365472376346588" size="0.0028752374928444624 0.003381751012057066 0.07902255654335022" quat="1.0 0.0 0.0 0.0"/>
          <geom class="collision" type="box" pos="-0.006363436579704285 -0.193630188703537 0.1365472376346588" size="0.0028752374928444624 0.00291081378236413 0.07902255654335022" quat="1.0 0.0 0.0 0.0"/>
          <geom class="collision" type="box" pos="0.14208747446537018 -0.19310100376605988 0.14406846463680267" size="0.0028752374928444624 0.0034400008153170347 0.07150132954120636" quat="1.0 0.0 0.0 0.0"/>
          <geom class="collision" type="box" pos="0.2601785659790039 0.009433153085410595 0.09803382307291031" size="0.0028752374928444624 0.20597416162490845 0.07085639983415604" quat="0.9996649622917175 0.0 0.02588295005261898 0.0"/>
          <geom class="collision" type="box" pos="-0.00038360804319381714 -0.19794560968875885 0.07245457172393799" size="0.26663410663604736 0.0031389184296131134 0.0034507845994085073" quat="1.0 0.0 0.0 0.0"/>
          <geom class="collision" type="box" pos="-0.006363436579704285 0.21039453148841858 0.1365472376346588" size="0.0028752374928444624 0.00291081378236413 0.07902255654335022" quat="1.0 0.0 0.0 0.0"/>
          <geom class="collision" type="box" pos="-0.13641364872455597 0.21017642319202423 0.1365472376346588" size="0.0028752374928444624 0.003381751012057066 0.07902255654335022" quat="1.0 0.0 0.0 0.0"/>
          <geom class="collision" type="box" pos="0.13117694854736328 0.0095750093460083 0.08582226186990738" size="0.0028752374928444624 0.1594955176115036 0.06274466961622238" quat="1.0 0.0 0.0 0.0"/>
          <geom class="collision" type="box" pos="0.14208747446537018 0.21093378961086273 0.14406846463680267" size="0.0028752374928444624 0.0034400008153170347 0.07150132954120636" quat="1.0 0.0 0.0 0.0"/>
          <geom class="collision" type="box" pos="0.2766624391078949 0.009433153085410595 0.17709919810295105" size="0.016239330172538757 0.20597416162490845 0.003205620450899005" quat="0.950692892074585 0.0 -0.3101339042186737 0.0"/>
          <geom class="collision" type="box" pos="0.28881484270095825 0.008442491292953491 0.20285823941230774" size="0.0028752374928444624 0.20498350262641907 0.015420433133840561" quat="1.0 0.0 0.0 0.0"/>
          <geom class="collision" type="box" pos="-0.00038360804319381714 0.2151338905096054 0.07245457172393799" size="0.26663410663604736 0.0031389184296131134 0.0034507845994085073" quat="1.0 0.0 0.0 0.0"/>
          <geom class="collision" type="box" pos="-0.00038360804319381714 0.2151338905096054 0.15117907524108887" size="0.26663410663604736 0.0031389184296131134 0.0034507845994085073" quat="1.0 0.0 0.0 0.0"/>
          <geom class="collision" type="box" pos="0.00156847620382905 0.2151338905096054 0.2163413166999817" size="0.29132577776908875 0.0031389184296131134 0.0034507845994085073" quat="1.0 0.0 0.0 0.0"/>
          <geom class="collision" type="box" pos="-0.2851855456829071 0.008442491292953491 0.20117789506912231" size="0.0028752374928444624 0.20498350262641907 0.017951978370547295" quat="1.0 0.0 0.0 0.0"/>
          <geom class="collision" type="box" pos="0.00156847620382905 -0.19638462364673615 0.2163413166999817" size="0.29132577776908875 0.0031389184296131134 0.0034507845994085073" quat="1.0 0.0 0.0 0.0"/>
          <geom class="collision" type="box" pos="-0.00038360804319381714 -0.19653765857219696 0.15117907524108887" size="0.26663410663604736 0.0031389184296131134 0.0034507845994085073" quat="1.0 0.0 0.0 0.0"/>
          <geom class="collision" type="box" pos="-0.028020158410072327 0.032729458063840866 0.08406535536050797" size="0.06565605849027634 0.18267786502838135 0.003450785530731082" quat="0.8327611684799194 0.0 -0.5536324381828308 0.0"/>
          <geom class="collision" type="box" pos="-0.037192992866039276 0.009365230798721313 0.04438371956348419" size="0.021055378019809723 0.2048918455839157 0.003450785530731082" quat="0.8327611684799194 0.0 -0.5536324381828308 0.0"/>
          <geom class="collision" type="box" pos="0.05050894618034363 0.007706544827669859 0.043497517704963684" size="0.0846700668334961 0.20655052363872528 0.0034507852979004383" quat="0.9919333457946777 0.0 0.1267605870962143 0.0"/>
          <geom class="collision" type="box" pos="0.18302851915359497 0.008778777904808521 0.04918387532234192" size="0.05139434337615967 0.20498640835285187 0.0034507852979004383" quat="0.9649385213851929 0.0 0.26247602701187134 0.0"/>
          <geom class="collision" type="box" pos="-0.17202086746692657 0.00963241420686245 0.04008018597960472" size="0.04208718240261078 0.2057749181985855 0.0034507852979004383" quat="0.976375937461853 0.0 -0.2160787284374237 0.0"/>
          <geom class="collision" type="box" pos="-0.11531074345111847 0.007706544827669859 0.04387129843235016" size="0.021465769037604332 0.20655052363872528 0.0034507852979004383" quat="0.8538821935653687 0.0 0.5204663276672363 0.0"/>
          <geom class="collision" type="box" pos="0.13599054515361786 0.00883317831903696 0.04685338959097862" size="0.0028752374928444624 0.2060575932264328 0.02738598734140396" quat="1.0 0.0 0.0 0.0"/>
        </body>
        <geom class="region" name="reg_int" type="box" pos="6.364285945892334e-05 -0.014126770198345184 -0.027165621519088745" size="0.29041164910793305 0.2536001110672951 0.3283073434829712"/>
        <geom class="region" name="reg_main" type="box" pos="0.0 0.026410609483718872 3.725290298461914e-08" size="0.3274040946960449 0.3259812424182892 0.4877629408836365"/>
      </body>
    </body>
  </worldbody>
  <actuator>
    <motor name="button_power_joint_actuator" joint="button_power_joint" gear="0.5"/>
    <motor name="door_joint_actuator" joint="door_joint" gear="50"/>
    <motor name="rack0_joint_actuator" joint="rack0_joint" gear="50"/>
    <motor name="rack1_joint_actuator" joint="rack1_joint" gear="50"/>
  </actuator>
</mujoco>
