<?xml version='1.0' encoding='UTF-8'?>
<mujoco model="model">
  <option timestep="0.002" gravity="0.0 0.0 -9.81"/>
  <compiler angle="radian"/>
  <asset>
    <mesh file="visuals/door.obj" name="door_vis"/>
    <mesh file="visuals/knob_temp.obj" name="knob_temp_vis"/>
    <mesh file="visuals/knob_time.obj" name="knob_time_vis"/>
    <mesh file="visuals/rack0.obj" name="rack0_vis"/>
    <mesh file="visuals/Body001.obj" name="Body001_vis"/>
    <mesh file="visuals/window.obj" name="window_vis"/>
    <texture file="visuals/T_BC001.png" name="Body001_material" type="2d"/>
    <material name="Body001_material" rgba="1 1 1 1.0" texture="Body001_material" shininess="0.1" specular="4"/>
    <texture file="visuals/T_BC001.png" name="door_material" type="2d"/>
    <material name="door_material" rgba="1 1 1 1.0" texture="door_material" shininess="0.1" specular="4"/>
    <material name="window_material" rgba="0.048379525542259216 0.048379525542259216 0.048379525542259216 0.800000011920929" shininess="0.141421377658844" specular="0.3103448502657381"/>
    <texture file="visuals/T_BC001.png" name="knob_temp_material" type="2d"/>
    <material name="knob_temp_material" rgba="1 1 1 1.0" texture="knob_temp_material" shininess="0.1" specular="4"/>
    <texture file="visuals/T_BC001.png" name="knob_time_material" type="2d"/>
    <material name="knob_time_material" rgba="1 1 1 1.0" texture="knob_time_material" shininess="0.1" specular="4"/>
    <texture file="visuals/T_BC001.png" name="rack0_material" type="2d"/>
    <material name="rack0_material" rgba="1 1 1 1.0" texture="rack0_material" shininess="0.1" specular="4"/>
  </asset>
  <default>
    <default class="visual">
      <geom conaffinity="0" contype="0" group="1" type="mesh"/>
    </default>
    <default class="collision">
      <geom group="0" rgba="0.5 0 0 0.5"/>
    </default>
    <default class="spawn">
      <geom group="0" rgba="1 1 1 0.5" contype="0" conaffinity="0"/>
      <site group="0" rgba="1 1 1 0.5"/>
    </default>
    <default class="region">
      <geom group="1" conaffinity="0" contype="0" rgba="0 1 0 0"/>
    </default>
  </default>
  <worldbody>
    <body>
      <body name="object">
        <geom mesh="Body001_vis" type="mesh" solimp="0.998 0.998 0.001" solref="0.001 1" friction="0.95 0.3 0.1" class="visual" material="Body001_material"/>
        <geom class="collision" type="box" pos="-0.20415274798870087 0.030364345759153366 0.018009334802627563" size="0.01228012889623642 0.166828453540802 0.14232683181762695" quat="1.0 0.0 0.0 0.0"/>
        <geom class="collision" type="box" pos="-0.03830508887767792 0.030487140640616417 -0.14075882732868195" size="0.17812778055667877 0.1667056530714035 0.019267026335000992" quat="1.0 0.0 0.0 0.0"/>
        <geom class="collision" type="box" pos="-0.03784903511404991 0.18357542157173157 0.013823936693370342" size="0.17491492629051208 0.013617407530546188 0.1465122401714325" quat="1.0 0.0 0.0 0.0"/>
        <geom class="collision" type="box" pos="0.17535442113876343 0.017078449949622154 0.00015325029380619526" size="0.04107845202088356 0.18011435866355896 0.16018293797969818" quat="1.0 0.0 0.0 0.0"/>
        <geom class="collision" type="box" pos="-0.037926942110061646 0.030364345759153366 0.14960181713104248" size="0.17850592732429504 0.166828453540802 0.006701894570142031" quat="1.0 0.0 0.0 0.0"/>
        <geom class="collision" type="box" pos="-0.18752072751522064 0.01099355798214674 -0.004263693932443857" size="0.0038743503391742706 0.1269080638885498 0.01615913026034832" quat="1.0 0.0 0.0 0.0"/>
        <geom class="collision" type="box" pos="0.129982128739357 0.01099355798214674 -0.00426369346678257" size="0.0038743503391742706 0.1269080638885498 0.01615913212299347" quat="1.0 0.0 0.0 0.0"/>
        <geom class="collision" type="box" pos="0.129982128739357 0.01099355798214674 -0.0417608767747879" size="0.0038743503391742706 0.1269080638885498 0.01615913212299347" quat="1.0 0.0 0.0 0.0"/>
        <geom class="collision" type="box" pos="-0.18752072751522064 0.01099355798214674 -0.041760873049497604" size="0.0038743503391742706 0.1269080638885498 0.01615913026034832" quat="1.0 0.0 0.0 0.0"/>
        <body name="door">
          <joint axis="1.0 0.0 0.0" pos="-0.04003845155239105 -0.1473190039396286 -0.13602320849895477" limited="true" name="door_joint" range="0.0 1.5707963267948966" type="hinge" damping="1" frictionloss="1" armature=".01" stiffness="0.5" springref="-1"/>
          <geom mesh="door_vis" type="mesh" solimp="0.998 0.998 0.001" solref="0.001 1" friction="0.95 0.3 0.1" class="visual" material="door_material"/>
          <geom class="collision" type="box" pos="0.12332412600517273 -0.15798062086105347 0.010491401888430119" size="0.009190008975565434 0.00839040707796812 0.14581428468227386" quat="1.0 0.0 0.0 0.0"/>
          <geom class="collision" type="box" pos="-0.04032648354768753 -0.19220219552516937 0.13966584205627441" size="0.14049723744392395 0.005172229837626219 0.013130838051438332" quat="1.0 0.0 0.0 0.0" name="door_handle_main"/>
          <geom class="collision" type="box" pos="-0.19089266657829285 -0.1786157488822937 0.13966584205627441" size="0.020299002528190613 0.005172316916286945 0.013131000101566315" quat="0.9027569890022278 0.0 -0.0 -0.4301508665084839"/>
          <geom class="collision" type="box" pos="-0.20517940819263458 -0.15798062086105347 0.010491397231817245" size="0.007584668230265379 0.00839040707796812 0.14581377804279327" quat="1.0 0.0 0.0 0.0"/>
          <geom class="collision" type="box" pos="-0.03475116938352585 -0.15798062086105347 0.12886808812618256" size="0.16726775467395782 0.00839040707796812 0.027435943484306335" quat="1.0 0.0 0.0 0.0" name="door_main"/>
          <geom class="collision" type="box" pos="-0.03475116938352585 -0.15798062086105347 -0.1301911473274231" size="0.16726741194725037 0.00839040707796812 0.004178016446530819" quat="1.0 0.0 0.0 0.0"/>
          <geom class="collision" type="box" pos="0.11066592484712601 -0.1786157488822937 0.13966584205627441" size="0.020299002528190613 0.005172316916286945 0.013131000101566315" quat="0.9027569890022278 0.0 0.0 0.4301508665084839"/>
          <body name="window">
            <geom mesh="window_vis" type="mesh" solimp="0.998 0.998 0.001" solref="0.001 1" friction="0.95 0.3 0.1" class="visual" material="window_material"/>
            <geom class="collision" type="box" pos="-0.04032052308320999 -0.16133713722229004 -0.013235360383987427" size="0.1489069014787674 0.0013776615960523486 0.10721638798713684" quat="1.0 0.0 0.0 0.0"/>
          </body>
        </body>
        <body name="knob_temp">
          <joint axis="0.0 1.0 0.0" pos="0.17750678956508636 -0.17745542526245117 -0.06337741017341614" limited="true" name="knob_temp_joint" range="0.0 4.014257279586958" type="hinge" damping="0.05" armature="0.001"/>
          <geom mesh="knob_temp_vis" type="mesh" solimp="0.998 0.998 0.001" solref="0.001 1" friction="0.95 0.3 0.1" class="visual" material="knob_temp_material"/>
          <geom class="collision" type="cylinder" pos="0.17726966738700867 -0.16968730092048645 -0.06367860734462738" size="0.02181580662727356 0.0030348224099725485" quat="0.7071068286895752 0.7071067690849304 0.0 0.0"/>
          <geom class="collision" type="cylinder" pos="0.17726966738700867 -0.17273741960525513 -0.06367860734462738" size="0.01766309328377247 0.0030348224099725485" quat="0.7071068286895752 0.7071067690849304 0.0 0.0"/>
          <geom class="collision" type="box" pos="0.17711836099624634 -0.1826753318309784 -0.06318798661231995" size="0.016971873119473457 0.008014261722564697 0.0056409635581076145" quat="1.0 0.0 0.0 0.0" name="knob_temp_main"/>
        </body>
        <body name="knob_time">
          <joint axis="0.0 1.0 0.0" pos="0.17845702171325684 -0.17745542526245117 0.041536737233400345" limited="true" name="knob_time_joint" range="0.0 4.049163864626845" type="hinge" damping="0.05" frictionloss="0.1" armature="0.001"/>
          <geom mesh="knob_time_vis" type="mesh" solimp="0.998 0.998 0.001" solref="0.001 1" friction="0.95 0.3 0.1" class="visual" material="knob_time_material"/>
          <geom class="collision" type="cylinder" pos="0.1791357696056366 -0.16968730092048645 0.041744932532310486" size="0.02181580662727356 0.0030348224099725485" quat="0.7071068286895752 0.7071067690849304 0.0 0.0" density="0.001"/>
          <geom class="collision" type="cylinder" pos="0.1791357696056366 -0.17273741960525513 0.041744932532310486" size="0.01766309328377247 0.0030348224099725485" quat="0.7071068286895752 0.7071067690849304 0.0 0.0" density="0.001"/>
          <geom class="collision" type="box" pos="0.1784660965204239 -0.1826753318309784 0.041192345321178436" size="0.005347182508558035 0.008014271035790443 0.016881121322512627" quat="1.0 0.0 0.0 0.0" name="knob_time_main" density="0.001"/>
        </body>
        <body name="rack0">
          <geom class="region" name="reg_rack0" type="box" pos="-0.02793034538626671 0.009045477956533432 0.05444629583507776" size="0.13092550805211067 0.11804923585057259 0.08276541235297918"/>
          <joint axis="0.0 -1.0 0.0" pos="-0.0286320298910141 0.008345574140548706 -0.02907991036772728" limited="true" name="rack0_joint" range="0.0 0.22" type="slide" damping="1" frictionloss="1" armature=".01" stiffness="0.05"/>
          <geom mesh="rack0_vis" type="mesh" solimp="0.998 0.998 0.001" solref="0.001 1" friction="0.95 0.3 0.1" class="visual" material="rack0_material"/>
          <geom class="collision" type="box" pos="-0.028050526976585388 0.00856306403875351 -0.03445521369576454" size="0.13570380210876465 0.12284986674785614 0.0017037037760019302" quat="1.0 0.0 0.0 0.0"/>
          <geom class="collision" type="box" pos="-0.18249718844890594 0.00848282128572464 -0.023407921195030212" size="0.008577265776693821 0.12300089746713638 0.0016675754450261593" quat="1.0 0.0 0.0 0.0"/>
          <geom class="collision" type="box" pos="-0.16859768331050873 0.008476242423057556 -0.028198152780532837" size="0.008577265776693821 0.12300733476877213 0.0016675754450261593" quat="0.9440328478813171 -2.0632491271044273e-08 0.3298514783382416 7.209132402152818e-09"/>
          <geom class="collision" type="box" pos="0.11243187636137009 0.00847623497247696 -0.028198152780532837" size="0.008577265776693821 0.12300732731819153 0.001667564152739942" quat="7.127249546101666e-08 -0.9440328478813171 -2.4903092921135794e-08 -0.3298514783382416"/>
          <geom class="collision" type="box" pos="0.1255408525466919 0.00848282128572464 -0.023407921195030212" size="0.008577265776693821 0.12300089746713638 0.0016675754450261593" quat="1.0 0.0 0.0 0.0"/>
        </body>
        <geom class="region" name="reg_int" type="box" pos="-0.028664641082286835 0.014313898980617523 0.010159991681575775" size="0.15817176347970963 0.14997451549768448 0.12705171650648117"/>
        <geom class="region" name="reg_main" type="box" pos="0.0 0.015410885214805603 -5.960464477539063e-08" size="0.2174328694343567 0.18278191781044006 0.1613362262248993"/>
      </body>
    </body>
  </worldbody>
  <actuator>
    <motor name="door_joint_actuator" joint="door_joint" gear="50"/>
    <motor name="knob_temp_joint_actuator" joint="knob_temp_joint" gear="50"/>
    <motor name="knob_time_joint_actuator" joint="knob_time_joint" gear="50"/>
    <motor name="rack0_joint_actuator" joint="rack0_joint" gear="50"/>
  </actuator>
</mujoco>
