<?xml version='1.0' encoding='UTF-8'?>
<mujoco model="model">
  <option timestep="0.002" gravity="0.0 0.0 -9.81"/>
  <compiler angle="radian"/>
  <asset>
    <mesh file="visuals/door.obj" name="door_vis"/>
    <mesh file="visuals/door_Clear.obj" name="door_Clear_vis"/>
    <mesh file="visuals/Body001.obj" name="Body001_vis"/>
    <mesh file="visuals/Disc001.obj" name="Disc001_vis"/>
    <texture file="visuals/T_BC001.png" name="Body001_material" type="2d"/>
    <material name="Body001_material" rgba="1 1 1 1.0" texture="Body001_material" shininess="0.4472135901451111" specular="0.5"/>
    <texture file="visuals/T_BC001.png" name="door_material" type="2d"/>
    <material name="door_material" rgba="1 1 1 1.0" texture="door_material" shininess="0.4472135901451111" specular="0.5"/>
    <material name="door_Clear_material" rgba="0.11601322144269943 0.11601322144269943 0.11601322144269943 0.699999988079071" shininess="0.4472135901451111" specular="0.3103448502657381"/>
    <texture file="visuals/T_BC001.png" name="Disc001_material" type="2d"/>
    <material name="Disc001_material" rgba="1 1 1 1.0" texture="Disc001_material" shininess="0.4472135901451111" specular="0.5"/>
  </asset>
  <default>
    <default class="visual">
      <geom conaffinity="0" contype="0" group="1" type="mesh"/>
    </default>
    <default class="collision">
      <geom group="0" rgba="0.5 0 0 0.5"/>
    </default>
    <default class="spawn">
      <geom group="0" rgba="1 1 1 0.5" contype="0" conaffinity="0"/>
      <site group="0" rgba="1 1 1 0.5"/>
    </default>
    <default class="region">
      <geom group="1" conaffinity="0" contype="0" rgba="0 1 0 0"/>
    </default>
  </default>
  <worldbody>
    <body>
      <body name="object">
        <geom class="collision" type="cylinder" pos="-0.053759023547172546 0.01935245841741562 -0.12291630357503891" size="0.14134545624256134 0.0019897485617548227" quat="1.0 0.0 0.0 0.0" name="tray" rgba="0 1 0 0.5"/>
        <geom class="collision" type="box" pos="0.24784424901008606 -0.17830020189285278 -0.10434824228286743" size="0.01096301432698965 0.0005531709175556898 0.006239055655896664" quat="1.0 0.0 0.0 0.0" name="stop_button" rgba="0.0 0.5 0 0.5"/>
        <geom class="collision" type="box" pos="0.20505373179912567 -0.17830020189285278 -0.10434824228286743" size="0.010903910733759403 0.0005531710339710116 0.006239056587219238" quat="1.0 0.0 0.0 0.0" name="start_button" rgba="0.0 0.5 0 0.5"/>
        <geom mesh="Body001_vis" type="mesh" solimp="0.998 0.998 0.001" solref="0.001 1" friction="0.95 0.3 0.1" class="visual" material="Body001_material"/>
        <geom class="collision" type="box" pos="1.5071140779809866e-08 0.03501347452402115 0.14736834168434143" size="0.2771352529525757 0.17626895010471344 0.009800040163099766" quat="1.0 0.0 0.0 0.0"/>
        <geom class="collision" type="box" pos="1.5071140779809866e-08 0.03501347452402115 -0.1419992595911026" size="0.2771352529525757 0.17626895010471344 0.008780794218182564" quat="1.0 0.0 0.0 0.0"/>
        <geom class="collision" type="box" pos="-0.2614961564540863 0.035013481974601746 0.0060613928362727165" size="0.015639089047908783 0.17626896500587463 0.14205798506736755" quat="1.0 0.0 0.0 0.0"/>
        <geom class="collision" type="box" pos="0.20731253921985626 0.035562701523303986 0.0060613928362727165" size="0.06982272118330002 0.1757197082042694 0.14205798506736755" quat="1.0 0.0 0.0 0.0"/>
        <geom class="collision" type="box" pos="-0.041193969547748566 0.19684278964996338 0.0019925192464143038" size="0.20513026416301727 0.014439636841416359 0.1452065259218216" quat="1.0 0.0 0.0 0.0"/>
        <geom class="collision" type="box" pos="0.22564545273780823 0.0016016747104004025 0.005581490695476532" size="0.051489803940057755 0.17765840888023376 0.1515868604183197" quat="1.0 0.0 0.0 0.0"/>
        <geom class="collision" type="box" pos="-0.1910099983215332 0.033206794410943985 -0.15430724620819092" size="0.0305914506316185 0.17000168561935425 0.00286117079667747" quat="1.0 0.0 0.0 0.0"/>
        <geom class="collision" type="box" pos="0.19278842210769653 0.033206794410943985 -0.15430724620819092" size="0.0305914506316185 0.17000168561935425 0.00286117079667747" quat="1.0 0.0 0.0 0.0"/>
        <body name="door">
          <joint axis="0.0 0.0 1.0" pos="-0.25734397768974304 -0.16165359318256378 0.003742557018995285" limited="true" name="microjoint" range="-1.5707963267948966 0.0" type="hinge" damping="1" frictionloss="1" armature=".01" stiffness="0.05"/>
          <geom mesh="door_vis" type="mesh" solimp="0.998 0.998 0.001" solref="0.001 1" friction="0.95 0.3 0.1" class="visual" material="door_material"/>
          <geom class="collision" type="box" pos="-0.039882414042949677 -0.1612330824136734 0.0055624027736485004" size="0.21326802670955658 0.019354145973920822 0.15110208094120026" quat="1.0 0.0 0.0 0.0"/>
          <geom class="collision" type="box" pos="0.1542731523513794 -0.20566736161708832 0.0045122005976736546" size="0.012436413206160069 0.006091923452913761 0.07990747690200806" quat="1.0 0.0 0.0 0.0" name="door_handle_main"/>
          <geom class="collision" type="box" pos="0.154417023062706 -0.20513561367988586 -0.0935002788901329" size="0.012513306923210621 0.006880520842969418 0.013624418526887894" quat="1.0 0.0 0.0 0.0"/>
          <geom class="collision" type="box" pos="0.15464726090431213 -0.20087064802646637 -0.11470231413841248" size="0.011913502588868141 0.011351507157087326 0.006156741641461849" quat="0.864357054233551 -0.5028786063194275 7.70788858517335e-07 -5.2654712590083363e-08"/>
          <geom class="collision" type="box" pos="0.1547970175743103 -0.18898290395736694 -0.12767444550991058" size="0.012174788862466812 0.010396204888820648 0.006479963660240173" quat="0.9755166172981262 -0.21992573142051697 4.951577921019634e-07 7.552212650807633e-07"/>
          <geom class="collision" type="box" pos="0.15461300313472748 -0.20513561367988586 0.10205253213644028" size="0.011992817744612694 0.006880525965243578 0.013624419458210468" quat="1.0 0.0 0.0 0.0"/>
          <geom class="collision" type="box" pos="0.15468689799308777 -0.20087064802646637 0.12325455248355865" size="0.01183171197772026 0.011351506225764751 0.006156741641461849" quat="9.661798827664825e-08 -6.952240596547199e-07 -0.5028786063194275 0.864357054233551"/>
          <geom class="collision" type="box" pos="0.15490113198757172 -0.18898290395736694 0.13622668385505676" size="0.012070685625076294 0.010396204888820648 0.006479963660240173" quat="7.97862526269455e-07 4.855448878515745e-07 0.21992573142051697 -0.9755166172981262"/>
          <geom class="collision" type="box" pos="-0.050893645733594894 -0.16073425114154816 0.0058904653415083885" size="0.1643805205821991 0.015393154695630074 0.10524028539657593" quat="1.0 0.0 0.0 0.0"/>
          <geom class="collision" type="box" pos="-0.039882414042949677 -0.1762211173772812 0.0055624027736485004" size="0.21326757967472076 0.004366063047200441 0.15110161900520325" quat="1.0 0.0 0.0 0.0" name="door_main"/>
          <body name="door_Clear">
            <geom mesh="door_Clear_vis" type="mesh" solimp="0.998 0.998 0.001" solref="0.001 1" friction="0.95 0.3 0.1" class="visual" material="door_Clear_material"/>
            <geom class="collision" type="box" pos="-0.050893645733594894 -0.16073425114154816 0.0058904653415083885" size="0.1643805205821991 0.015393154695630074 0.10524028539657593" quat="1.0 0.0 0.0 0.0"/>
          </body>
        </body>
        <body name="Disc001">
          <joint axis="0.0 0.0 1.0" pos="-0.05375900864601135 0.019352491945028305 -0.12597490847110748" limited="false" name="Disc001_joint" range="0 360" type="hinge" damping="1" frictionloss="1" armature=".01" stiffness="0.05"/>
          <geom mesh="Disc001_vis" type="mesh" solimp="0.998 0.998 0.001" solref="0.001 1" friction="0.95 0.3 0.1" class="visual" material="Disc001_material"/>
          <geom class="collision" type="cylinder" pos="-0.05375901237130165 0.01935245841741562 -0.12884104251861572" size="0.14195889234542847 0.002919303486123681" quat="1.0 0.0 0.0 0.0"/>
        </body>
        <geom class="region" name="reg_int" type="box" pos="-0.05417686700820923 0.01931052654981613 0.0042724572122097015" size="0.18473282253742218 0.15285192972421646 0.12628440728783608"/>
        <geom class="region" name="reg_main" type="box" pos="1.0849102949350709e-08 0.015347645618021488 -5.424551474675354e-09" size="0.2781352529525757 0.19693480229377747 0.15816838836669922"/>
      </body>
    </body>
  </worldbody>
  <actuator>
    <motor name="microjoint_actuator" joint="microjoint" gear="10"/>
    <motor name="Disc001_joint_actuator" joint="Disc001_joint" gear="10"/>
  </actuator>
</mujoco>
