<?xml version='1.0' encoding='UTF-8'?>
<mujoco model="model">
  <option timestep="0.002" gravity="0.0 0.0 -9.81"/>
  <compiler angle="radian"/>
  <asset>
    <mesh file="visuals/button_power.obj" name="button_power_vis"/>
    <mesh file="visuals/Body001.obj" name="Body001_vis"/>
    <mesh file="visuals/door.obj" name="door_vis"/>
    <mesh file="visuals/rack0.obj" name="rack0_vis"/>
    <mesh file="visuals/rack1.obj" name="rack1_vis"/>
    <texture file="visuals/T_BC001.png" name="Body001_material" type="2d"/>
    <material name="Body001_material" rgba="1 1 1 1.0" texture="Body001_material" shininess="0.2512328028678894" specular="2"/>
    <texture file="visuals/T_BC001.png" name="button_power_material" type="2d"/>
    <material name="button_power_material" rgba="1 1 1 1.0" texture="button_power_material" shininess="0.2512328028678894" specular="0.3103448502657381"/>
    <texture file="visuals/T_BC001.png" name="door_material" type="2d"/>
    <material name="door_material" rgba="1 1 1 1.0" texture="door_material" shininess="0.2512328028678894" specular="2"/>
    <texture file="visuals/T_BC001.png" name="rack0_material" type="2d"/>
    <material name="rack0_material" rgba="1 1 1 1.0" texture="rack0_material" shininess="0.2512328028678894" specular="3"/>
    <texture file="visuals/T_BC001.png" name="rack1_material" type="2d"/>
    <material name="rack1_material" rgba="1 1 1 1.0" texture="rack1_material" shininess="0.2512328028678894" specular="3"/>
  </asset>
  <default>
    <default class="visual">
      <geom conaffinity="0" contype="0" group="1" type="mesh"/>
    </default>
    <default class="collision">
      <geom group="0" rgba="0.5 0 0 0.5"/>
    </default>
    <default class="spawn">
      <geom group="0" rgba="1 1 1 0.5" contype="0" conaffinity="0"/>
      <site group="0" rgba="1 1 1 0.5"/>
    </default>
    <default class="region">
      <geom group="1" conaffinity="0" contype="0" rgba="0 1 0 0"/>
    </default>
  </default>
  <worldbody>
    <body>
      <body name="object">
        <geom mesh="Body001_vis" type="mesh" solimp="0.998 0.998 0.001" solref="0.001 1" friction="0.95 0.3 0.1" class="visual" material="Body001_material"/>
        <geom class="collision" type="box" pos="-0.00177823 0.01467969 0.32512522" size="0.29804348945617676 0.28858518600463867 0.0793590173125267" quat="1.0 0.0 0.0 0.0"/>
        <geom class="collision" type="box" pos="-0.00177823 0.02901688 0.21973945" size="0.29804348945617676 0.27424800395965576 0.027695506811141968" quat="1.0 0.0 0.0 0.0"/>
        <geom class="collision" type="box" pos="-0.27568915 0.02901688 -0.05877522" size="0.024132370948791504 0.27424800395965576 0.26131245493888855" quat="1.0 0.0 0.0 0.0"/>
        <geom class="collision" type="box" pos="0.27381995 0.02901688 -0.05877522" size="0.02218632400035858 0.27424800395965576 0.26131245493888855" quat="1.0 0.0 0.0 0.0"/>
        <geom class="collision" type="box" pos="-0.00177823 0.02901688 -0.35299551" size="0.29804348945617676 0.27424800395965576 0.05177992209792137" quat="1.0 0.0 0.0 0.0"/>
        <geom class="collision" type="box" pos="-0.00088241 0.25872649 -0.05458955" size="0.25167155265808105 0.04453840106725693 0.2503986656665802" quat="1.0 0.0 0.0 0.0"/>
        <geom class="collision" type="box" pos="0.24383005 -0.03295913 -0.03038457" size="0.010900299064815044 0.1843888759613037 0.007303493097424507" quat="1.0 0.0 0.0 0.0"/>
        <geom class="collision" type="box" pos="-0.24466084 -0.03295913 -0.03038457" size="0.010900299996137619 0.1843888759613037 0.0073034935630857944" quat="1.0 0.0 0.0 0.0"/>
        <geom class="collision" type="box" pos="0.24383005 -0.03295913 -0.26445565" size="0.010900300927460194 0.1843888908624649 0.007303494028747082" quat="1.0 0.0 0.0 0.0"/>
        <geom class="collision" type="box" pos="-0.24466084 -0.03295913 -0.26445565" size="0.010900301858782768 0.1843889057636261 0.007303494494408369" quat="1.0 0.0 0.0 0.0"/>
        <body name="button_power">
          <joint axis="0.0 1.0 0.0" pos="-0.26339871 -0.27605458 0.33619192" limited="true" name="button_power_joint" range="0.0 0.002" type="slide" damping="1" frictionloss="1" armature=".01" stiffness="0.05"/>
          <geom mesh="button_power_vis" type="mesh" solimp="0.998 0.998 0.001" solref="0.001 1" friction="0.95 0.3 0.1" class="visual" material="button_power_material"/>
          <geom class="collision" type="cylinder" pos="-0.26333568 -0.27668836 0.33622333" size="0.013412986882030964 0.001069585676304996" quat="0.7071068286895752 0.7071067690849304 0.0 0.0"/>
        </body>
        <body name="door">
          <joint axis="1.0 0.0 0.0" pos="-0.00056733 -0.24537418 -0.33511138" limited="true" name="door_joint" range="0.0 0.7035987755982988" type="hinge" damping="1" frictionloss="1" armature=".01" stiffness="0.2" springref="-25"/>
          <geom mesh="door_vis" type="mesh" solimp="0.998 0.998 0.001" solref="0.001 1" friction="0.95 0.3 0.1" class="visual" material="door_material"/>
          <geom class="collision" type="box" pos="-0.00005808 -0.30321457 0.16038239" size="0.21962477266788483 0.003024103818461299 0.014494245871901512" quat="1.0 0.0 0.0 0.0" name="door_handle_main"/>
          <geom class="collision" type="box" pos="-0.21845451 -0.28778654 0.16053617" size="0.0032157255336642265 0.013620124198496342 0.014182114973664284" quat="1.0 0.0 0.0 0.0"/>
          <geom class="collision" type="box" pos="0.21869750 -0.28736626 0.16053617" size="0.0032104982528835535 0.013199752196669579 0.014575919136404991" quat="1.0 0.0 0.0 0.0"/>
          <geom class="collision" type="box" pos="-0.00140643 -0.25991874 -0.04509626" size="0.2971552312374115 0.01361782941967249 0.2902294099330902" quat="1.0 0.0 0.0 0.0" name="door_main"/>
        </body>
        <body name="rack0">
          <geom class="region" name="reg_rack0" type="box" pos="0.0005391599999999969 -0.0318602 -0.12172383" size="0.21964761 0.15385995 0.07859109"/>
          <joint axis="0.0 -1.0 0.0" pos="0.00768080 -0.03099884 -0.22583704" limited="true" name="rack0_joint" range="0.0 0.3" type="slide" damping="1" frictionloss="1" armature=".01" stiffness="0.05"/>
          <geom mesh="rack0_vis" type="mesh" solimp="0.998 0.998 0.001" solref="0.001 1" friction="0.95 0.3 0.1" class="visual" material="rack0_material"/>
          <geom class="collision" type="box" pos="-0.21289666 -0.03105473 -0.25407311" size="0.02861114591360092 0.17393465340137482 0.002080216072499752" quat="1.0 0.0 0.0 0.0"/>
          <geom class="collision" type="box" pos="0.00054535 0.14380837 -0.18787077" size="0.23066891729831696 0.0020802852232009172 0.08269806951284409" quat="1.0 0.0 0.0 0.0"/>
          <geom class="collision" type="box" pos="0.00054535 -0.20568841 -0.18787077" size="0.23066891729831696 0.0025122754741460085 0.08269806951284409" quat="1.0 0.0 0.0 0.0"/>
          <geom class="collision" type="box" pos="0.23808181 -0.03248625 -0.18041717" size="0.0062791104428470135 0.1759839951992035 0.0752444714307785" quat="1.0 0.0 0.0 0.0"/>
          <geom class="collision" type="box" pos="-0.24302222 -0.03248625 -0.18083633" size="0.0019362475723028183 0.1759839951992035 0.07566363364458084" quat="1.0 0.0 0.0 0.0"/>
          <geom class="collision" type="box" pos="0.21793766 -0.03105473 -0.25407311" size="0.024869751185178757 0.1739347130060196 0.0020802170038223267" quat="1.0 0.0 0.0 0.0"/>
          <geom class="collision" type="box" pos="0.11940948 -0.03105473 -0.26743525" size="0.012249970808625221 0.1739347279071808 0.0020802172366529703" quat="1.0 0.0 0.0 0.0"/>
          <geom class="collision" type="box" pos="0.04976084 -0.03105473 -0.26743525" size="0.012249971739947796 0.17393474280834198 0.002080217469483614" quat="1.0 0.0 0.0 0.0"/>
          <geom class="collision" type="box" pos="-0.04785695 -0.03105473 -0.26743525" size="0.012249973602592945 0.17393475770950317 0.0020802177023142576" quat="1.0 0.0 0.0 0.0"/>
          <geom class="collision" type="box" pos="-0.11152510 -0.03105473 -0.26780644" size="0.01224997453391552 0.17393477261066437 0.0020802179351449013" quat="1.0 0.0 0.0 0.0"/>
          <geom class="collision" type="box" pos="-0.12786569 -0.03105473 -0.23669188" size="0.03250827267765999 0.17393484711647034 0.002080218866467476" quat="0.7633305191993713 0.0 0.6460081338882446 0.0"/>
          <geom class="collision" type="box" pos="-0.16917881 -0.03105473 -0.22969912" size="0.04203127697110176 0.17393484711647034 0.004355957731604576" quat="0.9576954245567322 0.0 -0.28778377175331116 0.0"/>
          <geom class="collision" type="box" pos="0.02454331 -0.03105473 -0.24564180" size="0.02700870670378208 0.17393484711647034 0.002080218866467476" quat="0.8822809457778931 0.0 0.4707231819629669 0.0"/>
          <geom class="collision" type="box" pos="0.17281966 -0.03105473 -0.22915442" size="0.04005209729075432 0.17393484711647034 0.005054346285760403" quat="0.9604085683822632 0.0 0.27859532833099365 0.0"/>
          <geom class="collision" type="box" pos="0.13449025 -0.03105473 -0.23977327" size="0.02700870670378208 0.17393484711647034 0.0020802184008061886" quat="0.6370745897293091 0.0 0.7708021998405457 0.0"/>
          <geom class="collision" type="box" pos="0.06340965 -0.03105473 -0.25696263" size="0.011668791994452477 0.17393484711647034 0.002080219332128763" quat="0.5749940276145935 0.0 0.8181576132774353 0.0"/>
          <geom class="collision" type="box" pos="0.10461231 -0.03105473 -0.25696263" size="0.011668792925775051 0.17393484711647034 0.0020802197977900505" quat="0.8316628932952881 0.0 0.555280864238739 0.0"/>
          <geom class="collision" type="box" pos="0.08283009 -0.03105473 -0.24838564" size="0.017921647056937218 0.17393478751182556 0.0021293272729963064" quat="1.0 0.0 0.0 0.0"/>
          <geom class="collision" type="box" pos="-0.09897950 -0.03105473 -0.25696263" size="0.011668791994452477 0.17393484711647034 0.002080219332128763" quat="0.5749940276145935 0.0 0.8181576132774353 0.0"/>
          <geom class="collision" type="box" pos="-0.06227265 -0.03105473 -0.25696263" size="0.011668792925775051 0.17393484711647034 0.002080219332128763" quat="0.8316628932952881 0.0 0.555280864238739 0.0"/>
          <geom class="collision" type="box" pos="-0.08180696 -0.03105473 -0.24838564" size="0.01567373424768448 0.17393480241298676 0.00212932750582695" quat="1.0 0.0 0.0 0.0"/>
          <geom class="collision" type="box" pos="-0.02169313 -0.03105473 -0.24553087" size="0.027008702978491783 0.17393484711647034 0.002080218866467476" quat="0.45507773756980896 0.0 0.8904517292976379 0.0"/>
          <geom class="collision" type="box" pos="0.00119191 -0.03105473 -0.22540230" size="0.011677444912493229 0.17393481731414795 0.00212932750582695" quat="1.0 0.0 0.0 0.0"/>
          <geom class="collision" type="box" pos="0.05433665 -0.03105473 -0.23392637" size="0.03453165665268898 0.17393484711647034 0.0020802190992981195" quat="0.662051260471344 0.0 0.7494585514068604 0.0"/>
          <geom class="collision" type="box" pos="-0.11183884 -0.03105473 -0.23392637" size="0.0023748327512294054 0.17393483221530914 0.03454814851284027" quat="1.0 0.0 0.0 0.0"/>
          <geom class="collision" type="box" pos="0.21061321 -0.03105473 -0.16303907" size="0.03517039492726326 0.17393484711647034 0.002080218866467476" quat="0.9728459715843201 0.0 0.23145335912704468 0.0"/>
        </body>
        <body name="rack1">
          <geom class="region" name="reg_rack1" type="box" pos="0.0008743850000000053 -0.031080695000000005 0.10925218" size="0.221449735 0.151722215 0.07429195999999999"/>
          <joint axis="0.0 -1.0 0.0" pos="0.00768080 -0.03099884 0.00813467" limited="true" name="rack1_joint" range="0.0 0.3" type="slide" damping="1" frictionloss="1" armature=".01" stiffness="0.05"/>
          <geom mesh="rack1_vis" type="mesh" solimp="0.998 0.998 0.001" solref="0.001 1" friction="0.95 0.3 0.1" class="visual" material="rack1_material"/>
          <geom class="collision" type="box" pos="-0.04785695 -0.03105473 -0.03346353" size="0.012249944731593132 0.1739344596862793 0.002080213278532028" quat="1.0 0.0 0.0 0.0"/>
          <geom class="collision" type="box" pos="0.04976084 -0.03105473 -0.03346353" size="0.012249945662915707 0.1739344596862793 0.002080213511362672" quat="1.0 0.0 0.0 0.0"/>
          <geom class="collision" type="box" pos="0.11940948 -0.03105473 -0.03346353" size="0.012249946594238281 0.1739344745874405 0.0020802137441933155" quat="1.0 0.0 0.0 0.0"/>
          <geom class="collision" type="box" pos="0.21793766 -0.03105473 -0.02010141" size="0.024869708344340324 0.17393448948860168 0.002080213977023959" quat="1.0 0.0 0.0 0.0"/>
          <geom class="collision" type="box" pos="-0.24302222 -0.03248625 0.05313539" size="0.0019362475723028183 0.1759839951992035 0.07566363364458084" quat="1.0 0.0 0.0 0.0"/>
          <geom class="collision" type="box" pos="0.23808181 -0.03248625 0.05355456" size="0.0062791104428470135 0.1759839951992035 0.0752444714307785" quat="1.0 0.0 0.0 0.0"/>
          <geom class="collision" type="box" pos="0.00001500 -0.20568841 0.04610095" size="0.23119927942752838 0.0025122754741460085 0.08269806951284409" quat="1.0 0.0 0.0 0.0"/>
          <geom class="collision" type="box" pos="0.21061321 -0.03105473 0.07093265" size="0.03517039492726326 0.17393484711647034 0.002080218866467476" quat="0.9728459715843201 0.0 0.23145335912704468 0.0"/>
          <geom class="collision" type="box" pos="-0.11183884 -0.03105473 0.00004535" size="0.0023748292587697506 0.17393454909324646 0.0345480851829052" quat="1.0 0.0 0.0 0.0"/>
          <geom class="collision" type="box" pos="0.05433665 -0.03105473 0.00004535" size="0.03453165665268898 0.17393484711647034 0.0020802190992981195" quat="0.662051260471344 0.0 0.7494585514068604 0.0"/>
          <geom class="collision" type="box" pos="0.00119191 -0.03105473 0.00856942" size="0.011677420698106289 0.17393456399440765 0.0021293240133672953" quat="1.0 0.0 0.0 0.0"/>
          <geom class="collision" type="box" pos="-0.02169313 -0.03105473 -0.01155915" size="0.027008702978491783 0.17393484711647034 0.002080218866467476" quat="0.45507773756980896 0.0 0.8904517292976379 0.0"/>
          <geom class="collision" type="box" pos="-0.08180696 -0.03105473 -0.01441392" size="0.015673711895942688 0.17393457889556885 0.002129324246197939" quat="1.0 0.0 0.0 0.0"/>
          <geom class="collision" type="box" pos="-0.06227265 -0.03105473 -0.02299091" size="0.011668792925775051 0.17393484711647034 0.002080219332128763" quat="0.8316628932952881 0.0 0.555280864238739 0.0"/>
          <geom class="collision" type="box" pos="0.00001500 0.14380837 0.04610095" size="0.23119927942752838 0.0020802852232009172 0.08269806951284409" quat="1.0 0.0 0.0 0.0"/>
          <geom class="collision" type="box" pos="-0.09897950 -0.03105473 -0.02299091" size="0.011668791994452477 0.17393484711647034 0.002080219332128763" quat="0.5749940276145935 0.0 0.8181576132774353 0.0"/>
          <geom class="collision" type="box" pos="0.08283009 -0.03105473 -0.01441392" size="0.017921630293130875 0.17393460869789124 0.0021293247118592262" quat="1.0 0.0 0.0 0.0"/>
          <geom class="collision" type="box" pos="0.10461231 -0.03105473 -0.02299091" size="0.011668792925775051 0.17393484711647034 0.0020802197977900505" quat="0.8316628932952881 0.0 0.555280864238739 0.0"/>
          <geom class="collision" type="box" pos="0.06340965 -0.03105473 -0.02299091" size="0.011668791994452477 0.17393484711647034 0.002080219332128763" quat="0.5749940276145935 0.0 0.8181576132774353 0.0"/>
          <geom class="collision" type="box" pos="0.13449025 -0.03105473 -0.00580156" size="0.02700870670378208 0.17393484711647034 0.0020802184008061886" quat="0.6370745897293091 0.0 0.7708021998405457 0.0"/>
          <geom class="collision" type="box" pos="0.17281966 -0.03105473 0.00481730" size="0.04005209729075432 0.17393484711647034 0.005054346285760403" quat="0.9604085683822632 0.0 0.27859532833099365 0.0"/>
          <geom class="collision" type="box" pos="0.02454331 -0.03105473 -0.01167008" size="0.02700870670378208 0.17393484711647034 0.002080218866467476" quat="0.8822809457778931 0.0 0.4707231819629669 0.0"/>
          <geom class="collision" type="box" pos="-0.16917881 -0.03105473 0.00427260" size="0.04203127697110176 0.17393484711647034 0.004355957731604576" quat="0.9576954245567322 0.0 -0.28778377175331116 0.0"/>
          <geom class="collision" type="box" pos="-0.12786569 -0.03105473 -0.00272016" size="0.03250827267765999 0.17393484711647034 0.002080218866467476" quat="0.7633305191993713 0.0 0.6460081338882446 0.0"/>
          <geom class="collision" type="box" pos="-0.11152510 -0.03105473 -0.03383471" size="0.0122499605640769 0.17393462359905243 0.0020802156068384647" quat="1.0 0.0 0.0 0.0"/>
          <geom class="collision" type="box" pos="-0.21289666 -0.03105473 -0.02010141" size="0.028611132875084877 0.17393463850021362 0.0020802158396691084" quat="1.0 0.0 0.0 0.0"/>
        </body>
        <geom class="region" name="reg_int" type="box" pos="-0.0005580399999999958 -0.012449515000000008 -0.07165257499999998" size="0.24582147999999998 0.22209263499999998 0.22401481499999998"/>
        <geom class="region" name="reg_main" type="box" pos="-9.999999994736442e-09 0.015663005000000008 9.999999994736442e-09" size="0.30100654 0.291667595 0.40599991"/>
      </body>
    </body>
  </worldbody>
  <actuator>
    <motor name="button_power_joint_actuator" joint="button_power_joint" gear="0.5"/>
    <motor name="door_joint_actuator" joint="door_joint" gear="50"/>
    <motor name="rack0_joint_actuator" joint="rack0_joint" gear="50"/>
    <motor name="rack1_joint_actuator" joint="rack1_joint" gear="50"/>
  </actuator>
</mujoco>
