<?xml version='1.0' encoding='UTF-8'?>
<mujoco model="model">
  <option timestep="0.002" gravity="0.0 0.0 -9.81"/>
  <compiler angle="radian"/>
  <asset>
    <mesh file="visuals/knob_front_center.obj" name="knob_front_center_vis"/>
    <mesh file="visuals/knob_front_left.obj" name="knob_front_left_vis"/>
    <mesh file="visuals/knob_front_right.obj" name="knob_front_right_vis"/>
    <mesh file="visuals/knob_rear_center.obj" name="knob_rear_center_vis"/>
    <mesh file="visuals/knob_rear_left.obj" name="knob_rear_left_vis"/>
    <mesh file="visuals/knob_rear_right.obj" name="knob_rear_right_vis"/>
    <mesh file="visuals/Body001.obj" name="Body001_vis"/>
    <mesh file="visuals/Door001.obj" name="Door001_vis"/>
    <mesh file="visuals/Door001_Clear.obj" name="Door001_Clear_vis"/>
    <mesh file="visuals/Knob001.obj" name="Knob001_vis"/>
    <mesh file="visuals/Knob002.obj" name="Knob002_vis"/>
    <mesh file="visuals/Shelf001.obj" name="Shelf001_vis"/>
    <mesh file="visuals/Shelf002.obj" name="Shelf002_vis"/>
    <texture file="visuals/T_BC001.png" name="Body001_material" type="2d"/>
    <material name="Body001_material" rgba="1 1 1 1.0" texture="Body001_material" shininess="0.1" specular="5"/>
    <texture file="visuals/T_BC001.png" name="knob_front_center_material" type="2d"/>
    <material name="knob_front_center_material" rgba="1 1 1 1.0" texture="knob_front_center_material" shininess="0.1" specular="5"/>
    <texture file="visuals/T_BC001.png" name="knob_front_left_material" type="2d"/>
    <material name="knob_front_left_material" rgba="1 1 1 1.0" texture="knob_front_left_material" shininess="0.1" specular="5"/>
    <texture file="visuals/T_BC001.png" name="knob_front_right_material" type="2d"/>
    <material name="knob_front_right_material" rgba="1 1 1 1.0" texture="knob_front_right_material" shininess="0.1" specular="5"/>
    <texture file="visuals/T_BC001.png" name="knob_rear_center_material" type="2d"/>
    <material name="knob_rear_center_material" rgba="1 1 1 1.0" texture="knob_rear_center_material" shininess="0.1" specular="5"/>
    <texture file="visuals/T_BC001.png" name="knob_rear_left_material" type="2d"/>
    <material name="knob_rear_left_material" rgba="1 1 1 1.0" texture="knob_rear_left_material" shininess="0.1" specular="5"/>
    <texture file="visuals/T_BC001.png" name="knob_rear_right_material" type="2d"/>
    <material name="knob_rear_right_material" rgba="1 1 1 1.0" texture="knob_rear_right_material" shininess="0.1" specular="5"/>
    <texture file="visuals/T_BC001.png" name="Door001_material" type="2d"/>
    <material name="Door001_material" rgba="1 1 1 1.0" texture="Door001_material" shininess="0.1" specular="5"/>
    <material name="Door001_Clear_material" rgba="0.048628754913806915 0.048628754913806915 0.048628754913806915 0.5" shininess="0.5" specular="0.3103448502657381"/>
    <texture file="visuals/T_BC001.png" name="Knob001_material" type="2d"/>
    <material name="Knob001_material" rgba="1 1 1 1.0" texture="Knob001_material" shininess="0.1" specular="5"/>
    <texture file="visuals/T_BC001.png" name="Knob002_material" type="2d"/>
    <material name="Knob002_material" rgba="1 1 1 1.0" texture="Knob002_material" shininess="0.1" specular="5"/>
    <texture file="visuals/T_BC001.png" name="Shelf001_material" type="2d"/>
    <material name="Shelf001_material" rgba="1 1 1 1.0" texture="Shelf001_material" shininess="0.1" specular="5"/>
    <texture file="visuals/T_BC001.png" name="Shelf002_material" type="2d"/>
    <material name="Shelf002_material" rgba="1 1 1 1.0" texture="Shelf002_material" shininess="0.1" specular="5"/>
  </asset>
  <default>
    <default class="visual">
      <geom conaffinity="0" contype="0" group="1" type="mesh"/>
    </default>
    <default class="collision">
      <geom group="0" rgba="0.5 0 0 0.5"/>
    </default>
    <default class="spawn">
      <geom group="0" rgba="1 1 1 0.5" contype="0" conaffinity="0"/>
      <site group="0" rgba="1 1 1 0.5"/>
    </default>
    <default class="region">
      <geom group="1" conaffinity="0" contype="0" rgba="0 1 0 0"/>
    </default>
  </default>
  <worldbody>
    <body>
      <body name="object">
        <geom mesh="Body001_vis" type="mesh" solimp="0.998 0.998 0.001" solref="0.001 1" friction="0.95 0.3 0.1" class="visual" material="Body001_material"/>
        <geom class="collision" type="box" pos="0.0009991551050916314 0.32055824995040894 0.029305987060070038" size="0.41986000537872314 0.015738647431135178 0.4128321707248688" quat="1.0 0.0 0.0 0.0"/>
        <geom class="collision" type="box" pos="-6.367638340666677e-17 0.32031571865081787 0.45546573400497437" size="0.42060387134552 0.02045418694615364 0.0005000059027224779" quat="0.9397256374359131 0.34192946553230286 -7.59235930863473e-17 3.5777871277648934e-24"/>
        <geom class="collision" type="box" pos="-7.158653293349906e-17 0.3360876142978668 0.45539191365242004" size="0.4205954372882843 0.00020944442076142877 0.014329597353935242" quat="1.0 0.0 0.0 0.0"/>
        <geom class="collision" type="box" pos="0.00106047501321882 0.28442537784576416 -0.09054946899414062" size="0.41953495144844055 0.013762049376964569 0.2713563144207001" quat="1.0 0.0 0.0 0.0"/>
        <geom class="collision" type="box" pos="0.0008671018294990063 0.0038781710900366306 0.2706303298473358" size="0.4197283387184143 0.3026042878627777 0.09329330176115036" quat="1.0 0.0 0.0 0.0"/>
        <geom class="collision" type="box" pos="0.0009372210479341447 0.002938526915386319 -0.36970576643943787" size="0.41965821385383606 0.3018699586391449 0.013855750672519207" quat="1.0 0.0 0.0 0.0"/>
        <geom class="collision" type="box" pos="0.3847431540489197 0.0037059225142002106 -0.011078834533691406" size="0.03611557185649872 0.3027200698852539 0.37200498580932617" quat="1.0 0.0 0.0 0.0"/>
        <geom class="collision" type="box" pos="-0.38106897473335266 0.0037059225142002106 -0.011078834533691406" size="0.037791453301906586 0.30272039771080017 0.37200498580932617" quat="1.0 0.0 0.0 0.0"/>
        <geom class="collision" type="box" pos="0.0009916865965351462 -0.27736935019493103 0.34854137897491455" size="0.4198112487792969 0.04959246888756752 0.015382237732410431" quat="1.0 0.0 0.0 0.0"/>
        <geom class="collision" type="box" pos="-0.006441392935812473 -0.2696748375892639 0.16858352720737457" size="0.34016135334968567 0.005052653606981039 0.012017963454127312" quat="1.0 0.0 0.0 0.0"/>
        <geom class="collision" type="box" pos="-0.006441392935812473 -0.28656005859375 -0.32885345816612244" size="0.37182310223579407 0.006954066921025515 0.028841743245720863" quat="1.0 0.0 0.0 0.0"/>
        <geom class="collision" type="cylinder" pos="-0.2973065674304962 -0.2415791004896164 -0.42189061641693115" size="0.019751792773604393 0.047438085079193115" quat="1.0 0.0 0.0 0.0"/>
        <geom class="collision" type="cylinder" pos="0.3025815784931183 -0.2415791004896164 -0.42189061641693115" size="0.019751792773604393 0.047438085079193115" quat="1.0 0.0 0.0 0.0"/>
        <geom class="collision" type="cylinder" pos="-0.2973065674304962 0.24921715259552002 -0.42189061641693115" size="0.019751792773604393 0.047438085079193115" quat="1.0 0.0 0.0 0.0"/>
        <geom class="collision" type="cylinder" pos="0.3025815784931183 0.24921715259552002 -0.42189061641693115" size="0.019751792773604393 0.047438085079193115" quat="1.0 0.0 0.0 0.0"/>
        <geom class="collision" type="box" pos="0.3307049572467804 -0.08799564838409424 -0.05039212852716446" size="0.005058102775365114 0.18542473018169403 0.14291945099830627" quat="1.0 0.0 0.0 0.0"/>
        <geom class="collision" type="box" pos="-0.32686981558799744 -0.08799564838409424 -0.050392117351293564" size="0.005058105569332838 0.1854248344898224 0.14291954040527344" quat="1.0 0.0 0.0 0.0"/>
        <geom class="collision" type="box" pos="-0.30610141158103943 -0.08799564838409424 0.03368536755442619" size="0.019839996472001076 0.1854335069656372 0.0019175105262547731" quat="1.0 0.0 0.0 0.0"/>
        <geom class="collision" type="box" pos="-0.30610141158103943 -0.08799564838409424 -0.0009286291897296906" size="0.019839977845549583 0.1854332834482193 0.0019175105262547731" quat="1.0 0.0 0.0 0.0"/>
        <geom class="collision" type="box" pos="-0.30610141158103943 -0.08799564838409424 -0.06802652776241302" size="0.01983995921909809 0.1854330599308014 0.0019175105262547731" quat="1.0 0.0 0.0 0.0"/>
        <geom class="collision" type="box" pos="-0.30610141158103943 -0.08799564838409424 -0.13530026376247406" size="0.019839942455291748 0.18543283641338348 0.0019175105262547731" quat="1.0 0.0 0.0 0.0"/>
        <geom class="collision" type="box" pos="0.307759553194046 -0.08799567073583603 0.033685412257909775" size="0.019839923828840256 0.18543261289596558 0.0019175105262547731" quat="1.0 0.0 0.0 0.0"/>
        <geom class="collision" type="box" pos="0.307759553194046 -0.08799567073583603 -0.0009285828564316034" size="0.019839905202388763 0.18543240427970886 0.0019175105262547731" quat="1.0 0.0 0.0 0.0"/>
        <geom class="collision" type="box" pos="0.307759553194046 -0.08799567073583603 -0.06802648305892944" size="0.01983988657593727 0.18543218076229095 0.0019175105262547731" quat="1.0 0.0 0.0 0.0"/>
        <geom class="collision" type="box" pos="0.307759553194046 -0.08799567073583603 -0.13530021905899048" size="0.01983986794948578 0.18543195724487305 0.0019175105262547731" quat="1.0 0.0 0.0 0.0"/>
        <geom class="collision" type="box" pos="0.3362254202365875 -0.08799567073583603 0.08303318172693253" size="0.011012679897248745 0.18315410614013672 0.0037078524474054575" quat="1.0 0.0 0.0 0.0"/>
        <geom class="collision" type="box" pos="0.3362254500389099 -0.08799567073583603 -0.18539047241210938" size="0.011012679897248745 0.18315410614013672 0.0037078524474054575" quat="1.0 0.0 0.0 0.0"/>
        <geom class="collision" type="box" pos="-0.3413293659687042 -0.08799564838409424 0.08303312957286835" size="0.011012679897248745 0.18315410614013672 0.0037078524474054575" quat="1.0 0.0 0.0 0.0"/>
        <geom class="collision" type="box" pos="-0.34132933616638184 -0.08799564838409424 -0.18539051711559296" size="0.011012679897248745 0.18315410614013672 0.0037078524474054575" quat="1.0 0.0 0.0 0.0"/>
        <body name="knob_front_center">
          <joint axis="0.0 -1.0 0.0" pos="0.06034150347113609 -0.3108179569244385 0.24555693566799164" limited="true" name="knob_front_center_joint" range="0.0 3.490658503988659" type="hinge" damping="0.05" frictionloss="0.1" armature="0.001"/>
          <geom mesh="knob_front_center_vis" type="mesh" solimp="0.998 0.998 0.001" solref="0.001 1" friction="0.95 0.3 0.1" class="visual" material="knob_front_center_material"/>
          <geom class="collision" type="cylinder" pos="0.060289982706308365 -0.30690068006515503 0.24564823508262634" size="0.02347167767584324 0.00744240265339613" quat="0.7071067094802856 0.7071068286895752 -1.5700929612083792e-16 2.2148510003422914e-23" density="0.001"/>
          <geom class="collision" type="box" pos="0.059647057205438614 -0.3183431923389435 0.24519884586334229" size="0.005083238240331411 0.00786667037755251 0.018166542053222656" quat="1.0 0.0 0.0 0.0" name="knob_front_center_main" density="0.001"/>
        </body>
        <body name="knob_front_left">
          <joint axis="0.0 -1.0 0.0" pos="-0.33890798687934875 -0.3108178377151489 0.24555687606334686" limited="true" name="knob_front_left_joint" range="0.0 3.490658503988659" type="hinge" damping="0.05" frictionloss="0.1" armature="0.001"/>
          <geom mesh="knob_front_left_vis" type="mesh" solimp="0.998 0.998 0.001" solref="0.001 1" friction="0.95 0.3 0.1" class="visual" material="knob_front_left_material"/>
          <geom class="collision" type="cylinder" pos="-0.33865484595298767 -0.30690068006515503 0.24564823508262634" size="0.02347167767584324 0.00744240265339613" quat="0.7071067094802856 0.7071068286895752 -1.5700929612083792e-16 2.2148510003422914e-23" density="0.001"/>
          <geom class="collision" type="box" pos="-0.3392977714538574 -0.3183431923389435 0.24519884586334229" size="0.005083238240331411 0.00786663219332695 0.018166499212384224" quat="1.0 0.0 0.0 0.0" name="knob_front_left_main" density="0.001"/>
        </body>
        <body name="knob_front_right">
          <joint axis="0.0 -1.0 0.0" pos="0.35979992151260376 -0.3108179271221161 0.24555693566799164" limited="true" name="knob_front_right_joint" range="0.0 3.5779249665883754" type="hinge" damping="0.05" frictionloss="0.1" armature="0.001"/>
          <geom mesh="knob_front_right_vis" type="mesh" solimp="0.998 0.998 0.001" solref="0.001 1" friction="0.95 0.3 0.1" class="visual" material="knob_front_right_material"/>
          <geom class="collision" type="cylinder" pos="0.3594783842563629 -0.30690068006515503 0.24564823508262634" size="0.02347167767584324 0.00744240265339613" quat="0.7071067094802856 0.7071068286895752 -1.5700929612083792e-16 2.2148510003422914e-23" density="0.001"/>
          <geom class="collision" type="box" pos="0.35883548855781555 -0.3183431923389435 0.24519884586334229" size="0.005083238240331411 0.007866698317229748 0.018166575580835342" quat="1.0 0.0 0.0 0.0" name="knob_front_right_main" density="0.001"/>
        </body>
        <body name="knob_rear_center">
          <joint axis="0.0 -1.0 0.0" pos="0.1608692705631256 -0.3108178973197937 0.24555696547031403" limited="true" name="knob_rear_center_joint" range="0.0 3.5255650890285457" type="hinge" damping="0.05" frictionloss="0.1" armature="0.001"/>
          <geom mesh="knob_rear_center_vis" type="mesh" solimp="0.998 0.998 0.001" solref="0.001 1" friction="0.95 0.3 0.1" class="visual" material="knob_rear_center_material"/>
          <geom class="collision" type="cylinder" pos="0.1607709378004074 -0.30690068006515503 0.24564823508262634" size="0.02347167767584324 0.00744240265339613" quat="0.7071067094802856 0.7071068286895752 -1.5700929612083792e-16 2.2148510003422914e-23" density="0.001"/>
          <geom class="collision" type="box" pos="0.16012801229953766 -0.3183431923389435 0.24519884586334229" size="0.005083238240331411 0.007866679690778255 0.01816655322909355" quat="1.0 0.0 0.0 0.0" name="knob_rear_center_main" density="0.001"/>
        </body>
        <body name="knob_rear_left">
          <joint axis="0.0 -1.0 0.0" pos="-0.2386472523212433 -0.3108178377151489 0.24555687606334686" limited="true" name="knob_rear_left_joint" range="0.0 3.5255650890285457" type="hinge" damping="0.05" frictionloss="0.1" armature="0.001"/>
          <geom mesh="knob_rear_left_vis" type="mesh" solimp="0.998 0.998 0.001" solref="0.001 1" friction="0.95 0.3 0.1" class="visual" material="knob_rear_left_material"/>
          <geom class="collision" type="cylinder" pos="-0.23832663893699646 -0.30690068006515503 0.24564823508262634" size="0.02347167767584324 0.00744240265339613" quat="0.7071067094802856 0.7071068286895752 -1.5700929612083792e-16 2.2148510003422914e-23" density="0.001"/>
          <geom class="collision" type="box" pos="-0.2389695644378662 -0.3183431923389435 0.24519884586334229" size="0.005083238240331411 0.007866641506552696 0.01816651038825512" quat="1.0 0.0 0.0 0.0" name="knob_rear_left_main" density="0.001"/>
        </body>
        <body name="knob_rear_right">
          <joint axis="0.0 -1.0 0.0" pos="0.26078206300735474 -0.31081801652908325 0.24555693566799164" limited="true" name="knob_rear_right_joint" range="0.0 3.5255650890285457" type="hinge" damping="0.05" frictionloss="0.1" armature="0.001"/>
          <geom mesh="knob_rear_right_vis" type="mesh" solimp="0.998 0.998 0.001" solref="0.001 1" friction="0.95 0.3 0.1" class="visual" material="knob_rear_right_material"/>
          <geom class="collision" type="cylinder" pos="0.2606376111507416 -0.30690068006515503 0.24564823508262634" size="0.02347167767584324 0.00744240265339613" quat="0.7071067094802856 0.7071068286895752 -1.5700929612083792e-16 2.2148510003422914e-23" density="0.001"/>
          <geom class="collision" type="box" pos="0.2599946856498718 -0.3183431923389435 0.24519884586334229" size="0.005083238240331411 0.007866689004004002 0.018166564404964447" quat="1.0 0.0 0.0 0.0" name="knob_rear_right_main" density="0.001"/>
        </body>
        <body name="Door001">
          <joint axis="1.0 0.0 0.0" pos="0.0016129817813634872 -0.2922552824020386 -0.29685622453689575" limited="true" name="Door001_joint" range="0.0 1.5707963267948966" type="hinge" damping="1" frictionloss="1" armature=".01" stiffness="0.05"/>
          <geom mesh="Door001_vis" type="mesh" solimp="0.998 0.998 0.001" solref="0.001 1" friction="0.95 0.3 0.1" class="visual" material="Door001_material"/>
          <geom class="collision" type="box" pos="-0.000584539317060262 -0.284593790769577 -0.06605206429958344" size="0.33768004179000854 0.011523301713168621 0.21855700016021729" quat="1.0 0.0 0.0 0.0"/>
          <geom class="collision" type="box" pos="-0.0001881122589111328 -0.3264852464199066 0.13902106881141663" size="0.20595194399356842 0.01082640141248703 0.008509228006005287" quat="1.0 0.0 0.0 0.0"/>
          <geom class="collision" type="box" pos="0.20505066215991974 -0.318261057138443 0.13902106881141663" size="0.014032981358468533 0.014184807427227497 0.008509357459843159" quat="0.921194314956665 0.0 0.0 0.38910287618637085"/>
          <geom class="collision" type="box" pos="0.2124926745891571 -0.30020400881767273 0.13902106881141663" size="0.011084587313234806 0.018823664635419846 0.008509357459843159" quat="1.0 0.0 0.0 0.0"/>
          <geom class="collision" type="box" pos="-0.20834961533546448 -0.3052693009376526 0.13902106881141663" size="0.01097660232335329 0.018761852756142616 0.008509357459843159" quat="1.0 0.0 0.0 0.0"/>
          <geom class="collision" type="box" pos="-0.20250751078128815 -0.32134079933166504 0.13902106881141663" size="0.01035991683602333 0.013933978043496609 0.008509357459843159" quat="0.3940070867538452 0.0 0.0 0.9191073775291443"/>
          <body name="Door001_Clear">
            <geom mesh="Door001_Clear_vis" type="mesh" solimp="0.998 0.998 0.001" solref="0.001 1" friction="0.95 0.3 0.1" class="visual" material="Door001_Clear_material"/>
          </body>
        </body>
        <body name="Knob001">
          <joint axis="0.0 1.0 0.0" pos="-0.13926179707050323 -0.3108179271221161 0.24555693566799164" limited="true" name="Knob001_joint" range="0.0 4.014257279586958" type="hinge" damping="0.05" frictionloss="0.1" armature="0.001"/>
          <geom mesh="Knob001_vis" type="mesh" solimp="0.998 0.998 0.001" solref="0.001 1" friction="0.95 0.3 0.1" class="visual" material="Knob001_material"/>
          <geom class="collision" type="cylinder" pos="-0.13933701813220978 -0.30690068006515503 0.24564823508262634" size="0.02347167767584324 0.00744240265339613" quat="0.7071067094802856 0.7071068286895752 -1.5700929612083792e-16 2.2148510003422914e-23" density="0.001"/>
          <geom class="collision" type="box" pos="-0.13997994363307953 -0.3183431923389435 0.24519884586334229" size="0.005083238240331411 0.007866650819778442 0.018166521564126015" quat="1.0 0.0 0.0 0.0" density="0.001"/>
        </body>
        <body name="Knob002">
          <joint axis="0.0 1.0 0.0" pos="-0.03939433395862579 -0.3108179569244385 0.24555693566799164" limited="true" name="Knob002_joint" range="0.0 3.2637657012293966" type="hinge" damping="0.05" frictionloss="0.1" armature="0.001"/>
          <geom mesh="Knob002_vis" type="mesh" solimp="0.998 0.998 0.001" solref="0.001 1" friction="0.95 0.3 0.1" class="visual" material="Knob002_material"/>
          <geom class="collision" type="cylinder" pos="-0.0393357127904892 -0.30690068006515503 0.24564823508262634" size="0.02347167767584324 0.00744240265339613" quat="0.7071067094802856 0.7071068286895752 -1.5700929612083792e-16 2.2148510003422914e-23" density="0.001"/>
          <geom class="collision" type="box" pos="-0.03997863829135895 -0.3183431923389435 0.24519884586334229" size="0.005083238240331411 0.007866661064326763 0.01816653087735176" quat="1.0 0.0 0.0 0.0" density="0.001"/>
        </body>
        <body name="Shelf001">
          <joint axis="0.0 -1.0 0.0" pos="-0.0015620995545759797 -0.08939860016107559 0.04237963259220123" limited="true" name="Shelf001_joint" range="0.0 0.3" type="slide" damping="1" frictionloss="1" armature=".01" stiffness="0.05"/>
          <geom mesh="Shelf001_vis" type="mesh" solimp="0.998 0.998 0.001" solref="0.001 1" friction="0.95 0.3 0.1" class="visual" material="Shelf001_material"/>
          <geom class="collision" type="box" pos="0.0 -0.09224695712327957 0.042326919734478" size="0.31443482637405396 0.1782684624195099 0.004741078242659569" quat="1.0 0.0 0.0 0.0"/>
        </body>
        <body name="Shelf002">
          <joint axis="0.0 -1.0 0.0" pos="-0.0014364566886797547 -0.0893985778093338 -0.05968460440635681" limited="true" name="Shelf002_joint" range="0.0 0.3" type="slide" damping="1" frictionloss="1" armature=".01" stiffness="0.05"/>
          <geom mesh="Shelf002_vis" type="mesh" solimp="0.998 0.998 0.001" solref="0.001 1" friction="0.95 0.3 0.1" class="visual" material="Shelf002_material"/>
          <geom class="collision" type="box" pos="0.0 -0.09224695712327957 -0.06016969680786133" size="0.31443482637405396 0.1782684624195099 0.004741081036627293" quat="1.0 0.0 0.0 0.0"/>
        </body>
        <geom class="region" name="reg_int" type="box" pos="0.0028312653303146362 -0.0002694129943847656 -0.09907705336809158" size="0.33901673352718353 0.266022337436676 0.25103688782453537"/>
        <site type="cylinder" rgba="0.5 0 0 0.5" size="0.08490437269210815 0.0001" pos="-0.2602962851524353 0.1317937821149826 0.36463239789009094" name="burner_on_rear_left"/>
        <site type="cylinder" rgba="0.5 0 0 0.5" size="0.1030343696475029 0.0001" pos="-0.012764574028551579 0.1435437798500061 0.36477190256118774" name="burner_on_rear_center"/>
        <site type="cylinder" rgba="0.5 0 0 0.5" size="0.10889677703380585 0.0001" pos="0.2580289840698242 0.143657848238945 0.36467739939689636" name="burner_on_rear_right"/>
        <site type="cylinder" rgba="0.5 0 0 0.5" size="0.10935959219932556 0.0001" pos="-0.25987282395362854 -0.11982551962137222 0.36482030153274536" name="burner_on_front_left"/>
        <site type="cylinder" rgba="0.5 0 0 0.5" size="0.0966821163892746 0.0001" pos="-0.013433662243187428 -0.11818808317184448 0.3648717999458313" name="burner_on_front_center"/>
        <site type="cylinder" rgba="0.5 0 0 0.5" size="0.08166041970252991 0.0001" pos="0.2578319013118744 -0.11594367027282715 0.36488378047943115" name="burner_on_front_right"/>
        <site name="burner_rear_left_place_site" type="cylinder" rgba="0.5 0 0 0" size="0.08490437269210815 4.999999873689376e-05" pos="-0.2602962851524353 0.1317937821149826 0.36463239789009094"/>
        <site name="burner_rear_center_place_site" type="cylinder" rgba="0.5 0 0 0" size="0.1030343696475029 4.999999873689376e-05" pos="-0.012764574028551579 0.1435437798500061 0.36477190256118774"/>
        <site name="burner_rear_right_place_site" type="cylinder" rgba="0.5 0 0 0" size="0.10889677703380585 4.999999873689376e-05" pos="0.2580289840698242 0.143657848238945 0.36467739939689636"/>
        <site name="burner_front_left_place_site" type="cylinder" rgba="0.5 0 0 0" size="0.10935959219932556 5.4252926929621026e-05" pos="-0.25987282395362854 -0.11982551962137222 0.36482030153274536"/>
        <site name="burner_front_center_place_site" type="cylinder" rgba="0.5 0 0 0" size="0.0966821163892746 4.999999873689376e-05" pos="-0.013433662243187428 -0.11818808317184448 0.3648717999458313"/>
        <site name="burner_front_right_place_site" type="cylinder" rgba="0.5 0 0 0" size="0.08166041970252991 4.999999873689376e-05" pos="0.2578319013118744 -0.11594367027282715 0.36488378047943115"/>
        <geom class="region" name="reg_main" type="box" pos="0.000999148702248931 0.018583834171295166 -0.0528859943151474" size="0.42086003518104553 0.31871320104599 0.417809618473053"/>
      </body>
    </body>
  </worldbody>
  <actuator>
    <motor name="knob_front_center_joint_actuator" joint="knob_front_center_joint" gear="10"/>
    <motor name="knob_front_left_joint_actuator" joint="knob_front_left_joint" gear="10"/>
    <motor name="knob_front_right_joint_actuator" joint="knob_front_right_joint" gear="10"/>
    <motor name="knob_rear_center_joint_actuator" joint="knob_rear_center_joint" gear="10"/>
    <motor name="knob_rear_left_joint_actuator" joint="knob_rear_left_joint" gear="10"/>
    <motor name="knob_rear_right_joint_actuator" joint="knob_rear_right_joint" gear="10"/>
    <motor name="Door001_joint_actuator" joint="Door001_joint" gear="50"/>
    <motor name="Knob001_joint_actuator" joint="Knob001_joint" gear="50"/>
    <motor name="Knob002_joint_actuator" joint="Knob002_joint" gear="50"/>
    <motor name="Shelf001_joint_actuator" joint="Shelf001_joint" gear="50"/>
    <motor name="Shelf002_joint_actuator" joint="Shelf002_joint" gear="50"/>
  </actuator>
</mujoco>
