<?xml version='1.0' encoding='UTF-8'?>
<mujoco model="model">
  <option timestep="0.002" gravity="0.0 0.0 -9.81"/>
  <compiler angle="radian"/>
  <asset>
    <mesh file="visuals/handle.obj" name="handle_vis"/>
    <mesh file="visuals/Body001.obj" name="Body001_vis"/>
    <mesh file="visuals/Funnel001.obj" name="Funnel001_vis"/>
    <mesh file="visuals/spout.obj" name="spout_vis"/>
    <texture file="visuals/T_BC001.png" name="Body001_material" type="2d"/>
    <material name="Body001_material" rgba="1 1 1 1.0" texture="Body001_material" shininess="0.1" specular="5"/>
    <texture file="visuals/T_BC001.png" name="handle_material" type="2d"/>
    <material name="handle_material" rgba="1 1 1 1.0" texture="handle_material" shininess="0.1" specular="5"/>
    <texture file="visuals/T_BC001.png" name="Funnel001_material" type="2d"/>
    <material name="Funnel001_material" rgba="1 1 1 1.0" texture="Funnel001_material" shininess="0.1" specular="5"/>
    <texture file="visuals/T_BC001.png" name="spout_material" type="2d"/>
    <material name="spout_material" rgba="1 1 1 1.0" texture="spout_material" shininess="0.1" specular="5"/>
  </asset>
  <default>
    <default class="visual">
      <geom conaffinity="0" contype="0" group="1" type="mesh"/>
    </default>
    <default class="collision">
      <geom group="0" rgba="0.5 0 0 0.5"/>
    </default>
    <default class="spawn">
      <geom group="0" rgba="1 1 1 0.5" contype="0" conaffinity="0"/>
      <site group="0" rgba="1 1 1 0.5"/>
    </default>
    <default class="region">
      <geom group="1" conaffinity="0" contype="0" rgba="0 1 0 0"/>
    </default>
  </default>
  <worldbody>
    <body>
      <body name="object">
        <geom mesh="Body001_vis" type="mesh" solimp="0.998 0.998 0.001" solref="0.001 1" friction="0.95 0.3 0.1" class="visual" material="Body001_material"/>
        <geom class="collision" type="box" pos="-0.23356184363365173 -2.6807390440808376e-07 -0.11480680108070374" size="0.008296264335513115 0.2596202492713928 0.13297192752361298" quat="1.0 0.0 0.0 0.0"/>
        <geom class="collision" type="box" pos="0.23371736705303192 -2.6807390440808376e-07 -0.11480680108070374" size="0.008736610412597656 0.2596202492713928 0.13297192752361298" quat="1.0 0.0 0.0 0.0"/>
        <geom class="collision" type="box" pos="0.0030584409832954407 -0.2499607801437378 -0.11480680108070374" size="0.23583543300628662 0.010839504189789295 0.1329718828201294" quat="1.0 0.0 0.0 0.0"/>
        <geom class="collision" type="box" pos="0.0030584409832954407 0.2537139356136322 -0.11532757431268692" size="0.2358359396457672 0.006797631271183491 0.1324511170387268" quat="1.0 0.0 0.0 0.0"/>
        <geom class="collision" type="box" pos="0.0030584409832954407 0.1276591718196869 -0.11224254220724106" size="0.005302014295011759 0.20624402165412903 0.11287185549736023" quat="0.036606963723897934 0.7061585783958435 0.7061585783958435 -0.03660690039396286"/>
        <geom class="collision" type="box" pos="0.0030584412161260843 -0.21895095705986023 -0.11246468871831894" size="0.0073319533839821815 0.21064023673534393 0.12072356045246124" quat="0.03493489325046539 -0.7062432169914246 -0.7062433362007141 -0.03493494540452957"/>
        <geom class="collision" type="box" pos="-0.19945518672466278 -0.040441274642944336 -0.11609373986721039" size="0.005518236663192511 0.1761256605386734 0.13290388882160187" quat="7.538027091413824e-08 0.9984419941902161 -4.212775461809315e-09 0.055799901485443115"/>
        <geom class="collision" type="box" pos="0.19890040159225464 -0.040441274642944336 -0.11591848731040955" size="0.004599577747285366 0.1761256605386734 0.13290388882160187" quat="0.9984419941902161 0.0 0.05579989776015282 0.0"/>
        <geom class="collision" type="box" pos="0.0030584409832954407 -0.000232011079788208 -0.24096815288066864" size="0.23583975434303284 0.2589706480503082 0.006810608319938183" quat="1.0 0.0 0.0 0.0"/>
        <geom class="collision" type="box" pos="-0.11705823242664337 -0.04320057854056358 -0.1983031928539276" size="0.06129753217101097 0.15863636136054993 0.006797538138926029" quat="1.0 0.0 0.0 0.0"/>
        <geom class="collision" type="box" pos="0.11731576919555664 -0.04320057854056358 -0.1983031928539276" size="0.06129753217101097 0.1586366593837738 0.006797549780458212" quat="1.0 0.0 0.0 0.0"/>
        <geom class="collision" type="box" pos="-0.0008477899827994406 -0.11839557439088821 -0.1983031928539276" size="0.05848265811800957 0.07372784614562988 0.0067975884303450584" quat="1.0 0.0 0.0 0.0"/>
        <geom class="collision" type="box" pos="-0.0008477899827994406 0.08693782985210419 -0.1983031928539276" size="0.05848265811800957 0.016707109287381172 0.006797580048441887" quat="1.0 0.0 0.0 0.0"/>
        <geom class="collision" type="box" pos="0.0030584409832954407 0.19810841977596283 0.012743569910526276" size="0.23583976924419403 0.05932534858584404 0.00516147306188941" quat="1.0 0.0 0.0 0.0"/>
        <geom class="collision" type="cylinder" pos="0.0008517603273503482 0.20203258097171783 0.031043171882629395" size="0.02263602614402771 0.032472364604473114" quat="1.0 -8.146033536604591e-08 0.0 0.0"/>
        <geom class="collision" type="cylinder" pos="0.004111836664378643 0.20203258097171783 0.04953136667609215" size="0.02263602614402771 0.052698273211717606" quat="0.7071068286895752 -5.760115939779098e-08 0.7071067690849304 5.760115229236362e-08"/>
        <geom class="collision" type="box" pos="0.24023039638996124 -6.903064786456525e-10 0.013483488000929356" size="0.008810929954051971 0.26489129662513733 0.004248413722962141" quat="1.0 0.0 0.0 0.0"/>
        <geom class="collision" type="box" pos="-0.2402338981628418 8.046086804824881e-06 0.013483488000929356" size="0.008931607007980347 0.26441359519958496 0.004240342881530523" quat="1.0 0.0 0.0 0.0"/>
        <geom class="collision" type="box" pos="-0.0023004859685897827 -0.25572049617767334 0.013483488000929356" size="0.24679666757583618 0.009049715474247932 0.004248466808348894" quat="1.0 0.0 0.0 0.0"/>
        <geom class="collision" type="box" pos="-0.0023004859685897827 0.2558632493019104 0.013483488000929356" size="0.24679668247699738 0.008705463260412216 0.004248467274010181" quat="1.0 0.0 0.0 0.0"/>
        <body name="handle">
          <joint axis="1.0 0.0 0.0" pos="0.07896038144826889 0.2020242065191269 0.049925073981285095" limited="true" name="handle_temp_joint" type="hinge" range="-0.7853981633974483 0.7853981633974483" damping="1" frictionloss="1" armature=".01"/>
          <joint axis="0.0 1.0 0.0" pos="0.07896038144826889 0.2020242065191269 0.049925073981285095" limited="true" name="handle_joint" type="hinge" range="0 0.5" damping="1" frictionloss="1" armature=".01"/>
          <geom mesh="handle_vis" type="mesh" solimp="0.998 0.998 0.001" solref="0.001 1" friction="0.95 0.3 0.1" class="visual" material="handle_material"/>
          <geom class="collision" type="cylinder" pos="0.08255445957183838 0.20203258097171783 0.04953136667609215" size="0.02263602614402771 0.01148841343820095" quat="0.7071068286895752 -5.760115939779098e-08 0.7071067690849304 5.760115229236362e-08" density="0.001"/>
          <geom class="collision" type="cylinder" pos="0.08758033066987991 0.20254206657409668 0.0986068919301033" size="0.0038201643619686365 0.027743283659219742" quat="1.0 -8.146033536604591e-08 0.0 0.0" density="0.001"/>
        </body>
        <body name="Funnel001">
          <joint axis="0.0 0.0 1.0" pos="1.4901161193847656e-08 0.01558181643486023 -0.20757544040679932" limited="true" name="Funnel001_joint" range="0.0 0.1" type="slide" damping="0" frictionloss="0" armature="0" stiffness="0"/>
          <geom mesh="Funnel001_vis" type="mesh" solimp="0.998 0.998 0.001" solref="0.001 1" friction="0.95 0.3 0.1" class="visual" material="Funnel001_material"/>
          <geom class="collision" type="cylinder" pos="0.0 0.014945222064852715 -0.2025204598903656" size="0.04206973314285278 0.0024675829336047173" quat="1.0 0.0 0.0 0.0"/>
          <geom class="collision" type="cylinder" pos="0.0 0.014945222064852715 -0.1996491253376007" size="0.00880388543009758 0.0031682653352618217" quat="1.0 0.0 0.0 0.0"/>
        </body>
        <body name="spout">
          <joint axis="0.0 0.0 1.0" pos="0.000901303777936846 0.20278413593769073 0.15556210279464722" limited="true" name="spout_joint" range="-0.7853981633974483 0.7853981633974483" type="hinge" damping="1" frictionloss="1" armature=".01" stiffness="0.05"/>
          <site type="cylinder" rgba="0.5 0.75 1 0.5" size="0.006213285028934479 0.22314435243606567" pos="0.001067635603249073 0.00037171365693211555 -0.0006376374512910843" name="water"/>
          <geom mesh="spout_vis" type="mesh" solimp="0.998 0.998 0.001" solref="0.001 1" friction="0.95 0.3 0.1" class="visual" material="spout_material"/>
          <geom class="collision" type="cylinder" pos="0.0011019762605428696 0.2018282413482666 0.1327592134475708" size="0.012858516536653042 0.05865353345870972" quat="1.0 -8.146033536604591e-08 0.0 0.0"/>
          <geom class="collision" type="cylinder" pos="0.0009104841738007963 -0.00013754557585343719 0.22098270058631897" size="0.009285930544137955 0.0064205266535282135" quat="1.0 -8.146033536604591e-08 0.0 0.0"/>
          <geom class="collision" type="cylinder" pos="0.0011019762605428696 0.19932816922664642 0.20134544372558594" size="0.012858516536653042 0.024497201666235924" quat="0.9920640587806702 0.12573325634002686 0.0 0.0"/>
          <geom class="collision" type="cylinder" pos="0.0011019762605428696 0.18931762874126434 0.21816012263298035" size="0.012858516536653042 0.024497203528881073" quat="0.9472011923789978 0.32063978910446167 0.0 0.0"/>
          <geom class="collision" type="cylinder" pos="0.0011019762605428696 0.1683201789855957 0.23184886574745178" size="0.012858516536653042 0.024497201666235924" quat="0.826365053653717 0.5631347894668579 0.0 0.0"/>
          <geom class="collision" type="cylinder" pos="0.0011019762605428696 0.07001488655805588 0.23639380931854248" size="0.012858516536653042 0.09095170348882675" quat="0.7071067094802856 0.70710688829422 0.0 0.0"/>
        </body>
        <geom class="region" name="reg_basin" type="box" pos="5.361437797546387e-05 -0.04405975341796875 -0.08324193209409714" size="0.1791754046678543 0.15094169771671295 0.10113153403997421"/>
        <geom class="region" name="reg_main" type="box" pos="-3.725290298461914e-09 0.0 -0.1150500625371933" size="0.2502935210466385 0.2658911476135254 0.13372865116596222"/>
      </body>
    </body>
  </worldbody>
  <actuator>
    <motor name="handle_joint_actuator" joint="handle_joint" gear="10"/>
    <motor name="handle_temp_joint_actuator" joint="handle_temp_joint" gear="10"/>
    <motor name="Funnel001_joint_actuator" joint="Funnel001_joint" gear="10"/>
    <motor name="spout_joint_actuator" joint="spout_joint" gear="10"/>
  </actuator>
</mujoco>
