<?xml version='1.0' encoding='UTF-8'?>
<mujoco model="model">
  <compiler angle="radian"/>
  <asset>
    <mesh file="visuals/handle.obj" name="handle_vis"/>
    <mesh file="visuals/Body001.obj" name="Body001_vis"/>
    <mesh file="visuals/Funnel001.obj" name="Funnel001_vis"/>
    <mesh file="visuals/Funnel002.obj" name="Funnel002_vis"/>
    <mesh file="visuals/spout.obj" name="spout_vis"/>
    <texture file="visuals/T_BC001.png" name="Body001_material" type="2d"/>
    <material name="Body001_material" rgba="1 1 1 1.0" texture="Body001_material" shininess="0.5" specular="0.3103448502657381"/>
    <texture file="visuals/T_BC001.png" name="handle_material" type="2d"/>
    <material name="handle_material" rgba="1 1 1 1.0" texture="handle_material" shininess="0.5" specular="0.3103448502657381"/>
    <texture file="visuals/T_BC001.png" name="Funnel001_material" type="2d"/>
    <material name="Funnel001_material" rgba="1 1 1 1.0" texture="Funnel001_material" shininess="0.5" specular="0.3103448502657381"/>
    <texture file="visuals/T_BC001.png" name="Funnel002_material" type="2d"/>
    <material name="Funnel002_material" rgba="1 1 1 1.0" texture="Funnel002_material" shininess="0.5" specular="0.3103448502657381"/>
    <texture file="visuals/T_BC001.png" name="spout_material" type="2d"/>
    <material name="spout_material" rgba="1 1 1 1.0" texture="spout_material" shininess="0.5" specular="0.3103448502657381"/>
  </asset>
  <default>
    <default class="visual">
      <geom conaffinity="0" contype="0" group="1" type="mesh"/>
    </default>
    <default class="collision">
      <geom group="0" rgba="0.5 0 0 0.5"/>
    </default>
    <default class="spawn">
      <geom group="0" rgba="1 1 1 0.5" contype="0" conaffinity="0"/>
      <site group="0" rgba="1 1 1 0.5"/>
    </default>
    <default class="region">
      <geom group="1" conaffinity="0" contype="0" rgba="0 1 0 0"/>
    </default>
  </default>
  <worldbody>
    <body>
      <body name="object">
        <geom mesh="Body001_vis" type="mesh" solimp="0.998 0.998 0.001" solref="0.001 1" density="100" friction="0.95 0.3 0.1" class="visual" material="Body001_material"/>
        <geom class="collision" type="box" pos="0.17336689 -0.14053522 -0.32121863" size="0.24221104383468628 0.07210440933704376 0.015311747789382935" quat="1.0 0.0 0.0 0.0"/>
        <geom class="collision" type="box" pos="0.39686671 -0.02815075 -0.21005003" size="0.016926951706409454 0.18149104714393616 0.08872916549444199" quat="1.0 0.0 0.0 0.0"/>
        <geom class="collision" type="box" pos="0.17134723 -0.21802081 -0.21005003" size="0.23601697385311127 0.015311755239963531 0.08872832357883453" quat="1.0 0.0 0.0 0.0"/>
        <geom class="collision" type="box" pos="-0.07193616 -0.04082068 -0.21005003" size="0.015311645343899727 0.19369356334209442 0.09160289168357849" quat="1.0 0.0 0.0 0.0"/>
        <geom class="collision" type="box" pos="0.17134723 0.16442883 -0.22692783" size="0.2360171675682068 0.015311741270124912 0.08872826397418976" quat="1.0 0.0 0.0 0.0"/>
        <geom class="collision" type="box" pos="-0.00428317 0.19784949 -0.13693392" size="0.41164645552635193 0.04474449157714844 0.01531176082789898" quat="1.0 0.0 0.0 0.0"/>
        <geom class="collision" type="box" pos="-0.39905816 -0.04082068 -0.21005003" size="0.016874592751264572 0.19369344413280487 0.08872760087251663" quat="1.0 0.0 0.0 0.0"/>
        <geom class="collision" type="box" pos="-0.24680398 -0.21802081 -0.21005003" size="0.16859567165374756 0.015311719849705696 0.08872818201780319" quat="1.0 0.0 0.0 0.0"/>
        <geom class="collision" type="box" pos="-0.24680398 0.16276832 -0.21444852" size="0.16859574615955353 0.0153117123991251 0.08432964980602264" quat="1.0 0.0 0.0 0.0"/>
        <geom class="collision" type="box" pos="-0.25025874 -0.14042936 -0.32121863" size="0.1685260534286499 0.06921228021383286 0.015311681665480137" quat="1.0 0.0 0.0 0.0"/>
        <geom class="collision" type="box" pos="0.17336689 0.12745932 -0.32121863" size="0.24221214652061462 0.07210403680801392 0.015311652794480324" quat="1.0 0.0 0.0 0.0"/>
        <geom class="collision" type="box" pos="0.31501511 -0.00713272 -0.32121863" size="0.08214612305164337 0.07210347801446915 0.015311544761061668" quat="1.0 0.0 0.0 0.0"/>
        <geom class="collision" type="box" pos="0.01875615 -0.00713272 -0.32121863" size="0.0782523974776268 0.07210355252027512 0.015311557799577713" quat="1.0 0.0 0.0 0.0"/>
        <geom class="collision" type="box" pos="-0.25025874 0.13136478 -0.32121863" size="0.1685265600681305 0.06921207904815674 0.015311631374061108" quat="1.0 0.0 0.0 0.0"/>
        <geom class="collision" type="box" pos="-0.35502121 -0.00477758 -0.32121863" size="0.055496376007795334 0.06496187299489975 0.015311609022319317" quat="1.0 0.0 0.0 0.0"/>
        <geom class="collision" type="box" pos="-0.11449406 -0.00477758 -0.32121863" size="0.055496323853731155 0.06496187299489975 0.015311609022319317" quat="1.0 0.0 0.0 0.0"/>
        <geom class="collision" type="cylinder" pos="-0.08179542 0.20925662 -0.06360914" size="0.01719251088798046 0.0542680025100708" quat="1.0 0.0 0.0 0.0"/>
        <geom class="collision" type="cylinder" pos="-0.06002961 0.20753311 -0.06714850" size="0.013796098530292511 0.023086797446012497" quat="0.7071068286895752 1.2101618374060763e-08 0.7071067690849304 -1.2101617485882343e-08"/>
        <geom class="collision" type="cylinder" pos="-0.08179542 0.20925662 -0.11978674" size="0.021898172795772552 0.00178152893204242" quat="1.0 0.0 0.0 0.0"/>
        <body name="handle">
          <joint axis="1.0 0.0 0.0" pos="-0.02256895 0.20808094 -0.06725065" limited="true" name="handle_temp_joint" type="hinge" range="-0.7853981633974483 0.7853981633974483" damping="1" frictionloss="1" armature=".01" stiffness="0.05"/>
          <joint axis="0.0 1.0 0.0" pos="-0.02256895 0.20808094 -0.06725065" limited="true" name="handle_joint" type="hinge" range="0 0.5" damping="1" frictionloss="1" armature=".01" stiffness="0.05"/>
          <geom mesh="handle_vis" type="mesh" solimp="0.998 0.998 0.001" solref="0.001 1" density="100" friction="0.95 0.3 0.1" class="visual" material="handle_material"/>
          <geom class="collision" type="cylinder" pos="-0.01788149 0.20865532 -0.02683046" size="0.003564587328583002 0.02724577859044075" quat="1.0 0.0 0.0 0.0"/>
          <geom class="collision" type="cylinder" pos="-0.02215050 0.20865532 -0.06706728" size="0.013808298856019974 0.009049287997186184" quat="0.7071068286895752 1.2101618374060763e-08 0.7071067690849304 -1.2101617485882343e-08"/>
        </body>
        <body name="Funnel001">
          <joint axis="0.0 0.0 1.0" pos="0.16242066 -0.00607784 -0.33120965" limited="true" name="Funnel001_joint" range="0.0 0.1" type="slide" damping="1" frictionloss="1" armature=".01" stiffness="0.05"/>
          <geom mesh="Funnel001_vis" type="mesh" solimp="0.998 0.998 0.001" solref="0.001 1" density="100" friction="0.95 0.3 0.1" class="visual" material="Funnel001_material"/>
          <geom class="collision" type="cylinder" pos="0.16187106 -0.00554697 -0.33756208" size="0.0567057766020298 0.006010390818119049" quat="1.0 0.0 0.0 0.0"/>
          <geom class="collision" type="cylinder" pos="0.16187106 -0.00554697 -0.32490104" size="0.00963414553552866 0.00779954856261611" quat="1.0 0.0 0.0 0.0"/>
        </body>
        <body name="Funnel002">
          <joint axis="0.0 0.0 1.0" pos="-0.23308423 -0.00607784 -0.33120965" limited="true" name="Funnel002_joint" range="0.0 0.1" type="slide" damping="1" frictionloss="1" armature=".01" stiffness="0.05"/>
          <geom mesh="Funnel002_vis" type="mesh" solimp="0.998 0.998 0.001" solref="0.001 1" density="100" friction="0.95 0.3 0.1" class="visual" material="Funnel002_material"/>
          <geom class="collision" type="cylinder" pos="-0.23404416 -0.00554697 -0.33724072" size="0.0567057803273201 0.006307606119662523" quat="1.0 0.0 0.0 0.0"/>
          <geom class="collision" type="cylinder" pos="-0.23373787 -0.00554697 -0.32490104" size="0.00963414553552866 0.00779954856261611" quat="1.0 0.0 0.0 0.0"/>
        </body>
        <body name="spout">
          <joint axis="0.0 0.0 1.0" pos="-0.08283399 0.20881334 0.12898899" limited="true" name="spout_joint" range="-0.7853981633974483 0.7853981633974483" type="hinge" damping="1" frictionloss="1" armature=".01" stiffness="0.05"/>
          <site type="cylinder" rgba="0.5 0.75 1 0.5" size="0.005516553297638893 0.19040846824645996" pos="-0.08293843 0.01115462 -0.13073258" name="water"/>
          <geom mesh="spout_vis" type="mesh" solimp="0.998 0.998 0.001" solref="0.001 1" density="100" friction="0.95 0.3 0.1" class="visual" material="spout_material"/>
          <geom class="collision" type="cylinder" pos="-0.08139011 0.20925662 0.06623679" size="0.01332130841910839 0.07394440472126007" quat="1.0 0.0 0.0 0.0"/>
          <geom class="collision" type="cylinder" pos="-0.08266839 0.20925662 0.19288733" size="0.006440197583287954 0.055047474801540375" quat="1.0 0.0 0.0 0.0"/>
          <geom class="collision" type="cylinder" pos="-0.08276860 0.20721907 0.25845579" size="0.006440198514610529 0.007824218831956387" quat="0.994442343711853 0.09780789911746979 -0.01097042951732874 0.037386294454336166"/>
          <geom class="collision" type="cylinder" pos="-0.08276860 0.20294959 0.27580914" size="0.006440197583287954 0.007824219763278961" quat="0.9805814027786255 0.1922031044960022 -0.014486033469438553 0.036169588565826416"/>
          <geom class="collision" type="cylinder" pos="-0.08276860 0.19574993 0.29058022" size="0.006440199911594391 0.007824218831956387" quat="0.9713069796562195 0.23461611568927765 -0.01604348048567772 0.03550620749592781"/>
          <geom class="collision" type="cylinder" pos="-0.08276860 0.18673963 0.30424339" size="0.006440198048949242 0.007824218831956387" quat="0.9441950917243958 0.327074259519577 -0.019388651475310326 0.03379601240158081"/>
          <geom class="collision" type="cylinder" pos="-0.08276860 0.17555496 0.31617254" size="0.0064401994459331036 0.007824218831956387" quat="0.9140971899032593 0.4036189317703247 -0.022102370858192444 0.03208690136671066"/>
          <geom class="collision" type="cylinder" pos="-0.08276860 0.16263444 0.32576466" size="0.006440198048949242 0.007824218831956387" quat="0.860331118106842 0.5082443356513977 -0.025719990953803062 0.029267169535160065"/>
          <geom class="collision" type="cylinder" pos="-0.08276860 0.14791437 0.33258564" size="0.006440197117626667 0.007824216969311237" quat="0.8240454196929932 0.5651823282241821 -0.027637701481580734 0.02746354043483734"/>
          <geom class="collision" type="cylinder" pos="-0.08276860 0.13262691 0.33751265" size="0.006440197583287954 0.007824218831956387" quat="0.7813286781311035 0.6229024529457092 -0.02953859232366085 0.025407683104276657"/>
          <geom class="collision" type="cylinder" pos="-0.08276860 0.11661797 0.33958304" size="0.006440198514610529 0.007824219763278961" quat="0.7136919498443604 0.6993752717971802 -0.031976960599422455 0.022261176258325577"/>
          <geom class="collision" type="cylinder" pos="-0.08276860 0.10053902 0.33904332" size="0.006440198980271816 0.007824219763278961" quat="0.6678956747055054 0.7432343363761902 -0.033324532210826874 0.020188095048069954"/>
          <geom class="collision" type="cylinder" pos="-0.08276860 0.08464273 0.33616439" size="0.006440198514610529 0.007824220694601536" quat="0.612804114818573 0.789273738861084 -0.034688107669353485 0.01774313487112522"/>
          <geom class="collision" type="cylinder" pos="-0.08276860 0.06882927 0.33025146" size="0.006440197583287954 0.007824218831956387" quat="0.5160938501358032 0.8556454181671143 -0.03652830421924591 0.013556111603975296"/>
          <geom class="collision" type="cylinder" pos="-0.08276860 0.04148858 0.31173817" size="0.006440200377255678 0.007824218831956387" quat="0.4162314236164093 0.9084235429763794 -0.03782482445240021 0.009347004815936089"/>
          <geom class="collision" type="cylinder" pos="-0.08276860 0.05438669 0.32169587" size="0.006440198514610529 0.007824218831956387" quat="0.45055606961250305 0.8918974995613098 -0.03744104504585266 0.010782015509903431"/>
          <geom class="collision" type="cylinder" pos="-0.08276860 0.03018348 0.29995865" size="0.006440197583287954 0.007824216037988663" quat="0.3240131139755249 0.9452499151229858 -0.03856576979160309 0.005546665284782648"/>
          <geom class="collision" type="cylinder" pos="-0.08276860 0.02139480 0.28650615" size="0.006440198048949242 0.007824217900633812" quat="0.23667094111442566 0.9708083271980286 -0.038910411298274994 0.0020149636548012495"/>
          <geom class="collision" type="cylinder" pos="-0.08276860 0.01507124 0.27139843" size="0.006440198048949242 0.007824218831956387" quat="0.1699947863817215 0.9846743941307068 -0.03895731642842293 -0.0006401168648153543"/>
          <geom class="collision" type="cylinder" pos="-0.08276860 0.01100865 0.25572593" size="0.006440198048949242 0.007824218831956387" quat="0.06431341171264648 0.9971688389778137 -0.03866862133145332 -0.0047795120626688"/>
          <geom class="collision" type="cylinder" pos="-0.08266839 0.01010317 0.19288733" size="0.006440197583287954 0.055047474801540375" quat="1.0 0.0 0.0 0.0"/>
          <geom class="collision" type="cylinder" pos="-0.08266839 0.00914020 0.09945943" size="0.013979204930365086 0.05057741701602936" quat="1.0 0.0 0.0 0.0"/>
          <geom class="collision" type="box" pos="-0.08424297 0.10847837 0.12158256" size="0.0031662501860409975 0.08885996788740158 0.0068920147605240345" quat="1.0 0.0 0.0 0.0"/>
        </body>
        <geom class="region" name="reg_main" type="box" pos="9.999999994736442e-09 1.0999999999997123e-05 -0.233699855" size="0.4144849 0.23916179999999998 0.11238948500000001"/>
        <geom class="region" name="reg_basin_left" type="box" pos="-0.2299635 -0.024986809999999998 -0.22588456499999998" size="0.14423534 0.17730326 0.09956517499999999"/>
        <geom class="region" name="reg_basin_right" type="box" pos="0.17044713 -0.02467402499999999 -0.225728105" size="0.22053781 0.176814625 0.099408715"/>
      </body>
    </body>
  </worldbody>
  <actuator>
    <motor name="handle_temp_joint_actuator" joint="handle_temp_joint" gear="10"/>
    <motor name="handle_joint_actuator" joint="handle_joint" gear="10"/>
    <motor name="Funnel001_joint_actuator" joint="Funnel001_joint" gear="10"/>
    <motor name="Funnel002_joint_actuator" joint="Funnel002_joint" gear="10"/>
    <motor name="spout_joint_actuator" joint="spout_joint" gear="10"/>
  </actuator>
</mujoco>
