<?xml version='1.0' encoding='UTF-8'?>
<mujoco model="model">
  <option timestep="0.002" gravity="0.0 0.0 -9.81"/>
  <compiler angle="radian"/>
  <asset>
    <mesh file="visuals/handle.obj" name="handle_vis"/>
    <mesh file="visuals/Body001.obj" name="Body001_vis"/>
    <mesh file="visuals/Funnel001.obj" name="Funnel001_vis"/>
    <mesh file="visuals/Shelf001.obj" name="Shelf001_vis"/>
    <mesh file="visuals/spout.obj" name="spout_vis"/>
    <texture file="visuals/T_BC001.png" name="Body001_material" type="2d"/>
    <material name="Body001_material" rgba="1 1 1 1.0" texture="Body001_material" shininess="0.1" specular="5"/>
    <texture file="visuals/T_BC001.png" name="handle_material" type="2d"/>
    <material name="handle_material" rgba="1 1 1 1.0" texture="handle_material" shininess="0.2" specular="1"/>
    <texture file="visuals/T_BC001.png" name="Funnel001_material" type="2d"/>
    <material name="Funnel001_material" rgba="1 1 1 1.0" texture="Funnel001_material" shininess="0.1" specular="3"/>
    <texture file="visuals/T_BC001.png" name="Shelf001_material" type="2d"/>
    <material name="Shelf001_material" rgba="1 1 1 1.0" texture="Shelf001_material" shininess="0.2" specular="3"/>
    <texture file="visuals/T_BC001.png" name="spout_material" type="2d"/>
    <material name="spout_material" rgba="1 1 1 1.0" texture="spout_material" shininess="0.2" specular="2"/>
  </asset>
  <default>
    <default class="visual">
      <geom conaffinity="0" contype="0" group="1" type="mesh"/>
    </default>
    <default class="collision">
      <geom group="0" rgba="0.5 0 0 0.5"/>
    </default>
    <default class="spawn">
      <geom group="0" rgba="1 1 1 0.5" contype="0" conaffinity="0"/>
      <site group="0" rgba="1 1 1 0.5"/>
    </default>
    <default class="region">
      <geom group="1" conaffinity="0" contype="0" rgba="0 1 0 0"/>
    </default>
  </default>
  <worldbody>
    <body>
      <body name="object">
        <geom mesh="Body001_vis" type="mesh" solimp="0.998 0.998 0.001" solref="0.001 1" friction="0.95 0.3 0.1" class="visual" material="Body001_material"/>
        <geom class="collision" type="cylinder" pos="0.01446781 0.23220078 -0.01140881" size="0.023818261921405792 0.058100372552871704" quat="1.0 0.0 0.0 0.0"/>
        <geom class="collision" type="cylinder" pos="-0.00912876 0.23113279 -0.00875691" size="0.017742056399583817 0.010086488910019398" quat="0.7071068286895752 -0.0 0.7071067690849304 0.0"/>
        <geom class="collision" type="box" pos="0.00031437 -0.26389782 -0.18426010" size="0.4193645417690277 0.015467206947505474 0.11859586834907532" quat="1.0 0.0 0.0 0.0"/>
        <geom class="collision" type="box" pos="-0.00000001 0.23764659 -0.18426025" size="0.4190496802330017 0.04178822040557861 0.11859574168920517" quat="1.0 0.0 0.0 0.0"/>
        <geom class="collision" type="box" pos="-0.40072238 -0.02596472 -0.18426012" size="0.018327658995985985 0.22813750803470612 0.1185956746339798" quat="1.0 0.0 0.0 0.0"/>
        <geom class="collision" type="box" pos="0.40077850 -0.02596472 -0.18426012" size="0.01827150024473667 0.22813750803470612 0.11859569698572159" quat="1.0 0.0 0.0 0.0"/>
        <geom class="collision" type="box" pos="0.00022718 -0.22606264 -0.17819351" size="0.3873293101787567 0.01631571352481842 0.10411050915718079" quat="7.645235911013515e-08 6.835321642029157e-09 -0.09209904074668884 0.995749831199646"/>
        <geom class="collision" type="box" pos="0.00022718 0.17271432 -0.17452004" size="0.3873293101787567 0.017418405041098595 0.10019877552986145" quat="7.620395336971342e-08 -5.913063816365138e-09 0.07906337827444077 0.9968695640563965"/>
        <geom class="collision" type="box" pos="-0.13379312 -0.02596472 -0.28834272" size="0.2625046968460083 0.22813750803470612 0.014513286761939526" quat="1.0 0.0 0.0 0.0"/>
        <geom class="collision" type="box" pos="0.32366988 -0.02596472 -0.28733919" size="0.07233934849500656 0.22813750803470612 0.015516786836087704" quat="1.0 0.0 0.0 0.0"/>
        <geom class="collision" type="box" pos="0.18699886 0.11873327 -0.28834272" size="0.07233936339616776 0.08343951404094696 0.014513293281197548" quat="1.0 0.0 0.0 0.0"/>
        <geom class="collision" type="box" pos="0.37823457 -0.02596472 -0.17543993" size="0.018271517008543015 0.22813750803470612 0.09256541728973389" quat="0.9945106506347656 4.444838213243647e-16 0.10463552922010422 1.4058707087372113e-08"/>
        <geom class="collision" type="box" pos="-0.38114434 -0.02596472 -0.16789106" size="0.018327679485082626 0.22813750803470612 0.09352923184633255" quat="0.9962621331214905 -2.974396163650674e-16 -0.0863814726471901 -1.16061142918511e-08"/>
        <geom class="collision" type="box" pos="0.18699886 -0.16819060 -0.28834269" size="0.07233937084674835 0.08343951404094696 0.014513283036649227" quat="1.0 0.0 0.0 0.0"/>
        <geom class="collision" type="cylinder" pos="0.03512879 0.23286472 -0.00798832" size="0.02268277481198311 0.017486507073044777" quat="0.7071068286895752 -0.0 0.7071067690849304 0.0"/>
        <geom class="collision" type="box" pos="0.19035213 -0.02421205 -0.29660193" size="0.061352916061878204 0.060629572719335556 0.0061859916895627975" quat="1.0 0.0 0.0 0.0"/>
        <geom class="collision" type="box" pos="-0.22731018 -0.02596472 -0.26780913" size="0.16898782551288605 0.17503397166728973 0.003857055678963661" quat="0.9997517466545105 3.966724378116649e-16 0.02228236198425293 2.9938327372747153e-09"/>
        <body name="handle">
          <joint axis="1.0 0.0 0.0" pos="0.08099219 0.23277400 -0.00819496" limited="true" name="handle_temp_joint" type="hinge" range="-0.7853981633974483 0.7853981633974483" damping="1" frictionloss="1" armature=".01" stiffness="0.05"/>
          <joint axis="0.0 1.0 0.0" pos="0.08099219 0.23277400 -0.00819496" limited="true" name="handle_joint" type="hinge" range="0 0.5" damping="1" frictionloss="1" armature=".01" stiffness="0.05"/>
          <geom mesh="handle_vis" type="mesh" solimp="0.998 0.998 0.001" solref="0.001 1" friction="0.95 0.3 0.1" class="visual" material="handle_material"/>
          <geom class="collision" type="cylinder" pos="0.08792080 0.23281470 -0.00806773" size="0.021927855908870697 0.009958228096365929" quat="0.70710688829422 -4.7503021960437763e-08 -0.7071066498756409 -4.750300774958305e-08"/>
          <geom class="collision" type="cylinder" pos="0.08904275 0.23257366 0.05547520" size="0.004649974871426821 0.04207927733659744" quat="7.549790126404332e-08 0.0 0.0 1.0"/>
        </body>
        <body name="Funnel001">
          <joint axis="0.0 0.0 1.0" pos="0.19233739 -0.02491243 -0.26917342" limited="true" name="Funnel001_joint" range="0.0 0.1" type="slide" damping="1" frictionloss="1" armature=".01" stiffness="0.05"/>
          <geom mesh="Funnel001_vis" type="mesh" solimp="0.998 0.998 0.001" solref="0.001 1" friction="0.95 0.3 0.1" class="visual" material="Funnel001_material"/>
          <geom class="collision" type="cylinder" pos="0.19200933 -0.02496019 -0.27496145" size="0.053283076733350754 0.0024267947301268578" quat="1.0 0.0 0.0 0.0"/>
          <geom class="collision" type="cylinder" pos="0.19200933 -0.02496019 -0.26430998" size="0.00820619985461235 0.005855671130120754" quat="1.0 0.0 0.0 0.0"/>
        </body>
        <body name="Shelf001">
          <joint axis="0.0 0.0 1.0" pos="-0.24271366 -0.03025551 -0.06430702" limited="true" name="Shelf001_joint" range="0.0 0.1" type="slide" damping="1" frictionloss="1" armature=".01" stiffness="0.05"/>
          <geom mesh="Shelf001_vis" type="mesh" solimp="0.998 0.998 0.001" solref="0.001 1" friction="0.95 0.3 0.1" class="visual" material="Shelf001_material"/>
          <geom class="collision" type="box" pos="-0.24190325 -0.02886014 -0.06051323" size="0.14196902513504028 0.21602289378643036 0.003069336526095867" quat="1.0 0.0 0.0 0.0"/>
        </body>
        <body name="spout">
          <joint axis="0.0 0.0 1.0" pos="0.01468697 0.23264329 0.17445582" limited="true" name="spout_joint" range="-1.0471975511965976 1.0471975511965976" type="hinge" damping="1" frictionloss="1" armature=".01" stiffness="0.05"/>
          <site type="cylinder" rgba="0.5 0.75 1 0.5" size="0.007177439983934164 0.22816672921180725" pos="0.01486730 0.03502153 -0.04394450" name="water"/>
          <geom mesh="spout_vis" type="mesh" solimp="0.998 0.998 0.001" solref="0.001 1" friction="0.95 0.3 0.1" class="visual" material="spout_material"/>
          <geom class="collision" type="cylinder" pos="0.01453570 0.23241006 0.12438226" size="0.010794290341436863 0.07506126910448074" quat="1.0 0.0 0.0 0.0"/>
          <geom class="collision" type="cylinder" pos="0.01479855 0.22939001 0.21044513" size="0.010841227136552334 0.012862671166658401" quat="0.9968740940093994 0.0790063813328743 1.7542944038336892e-17 -4.5949226852819725e-24"/>
          <geom class="collision" type="cylinder" pos="0.01449803 0.22368352 0.23338133" size="0.010841227136552334 0.01286267302930355" quat="0.9837262034416199 0.17967408895492554 3.989565878853892e-17 -2.8741391747410816e-24"/>
          <geom class="collision" type="cylinder" pos="0.01449803 0.21100734 0.25529336" size="0.010841227136552334 0.01631930097937584" quat="0.9403983950614929 0.34007471799850464 1.0998129235289522e-16 2.0087690746601152e-17"/>
          <geom class="collision" type="cylinder" pos="0.01449803 0.18956093 0.27549886" size="0.010841227136552334 0.01631930284202099" quat="0.881496250629425 0.47219106554985046 1.2380990592765462e-16 3.0933881461743464e-17"/>
          <geom class="collision" type="cylinder" pos="0.01449803 0.16854144 0.28652972" size="0.010841227136552334 0.01080181635916233" quat="0.8340665698051453 0.5516638159751892 4.176387928921444e-17 2.0189935564268627e-16"/>
          <geom class="collision" type="cylinder" pos="0.01449803 0.15047885 0.29191196" size="0.010841227136552334 0.01080181635916233" quat="0.7745123505592346 0.6325587630271912 3.9877794996030227e-17 1.9278140330751835e-16"/>
          <geom class="collision" type="cylinder" pos="0.01449803 0.13083686 0.29383134" size="0.010841227136552334 0.01080181635916233" quat="0.7095870971679688 0.7046177387237549 3.767462590427484e-17 1.8213058603561616e-16"/>
          <geom class="collision" type="cylinder" pos="0.01449803 0.11207430 0.29194420" size="0.010841227136552334 0.01080181635916233" quat="0.6383018493652344 0.7697861790657043 2.4664484384579504e-17 1.8156852673555373e-16"/>
          <geom class="collision" type="cylinder" pos="0.01449803 0.09182177 0.28540623" size="0.010841227136552334 0.017336048185825348" quat="0.557436466217041 0.8302196264266968 3.211736846879248e-17 1.552649641148657e-16"/>
          <geom class="collision" type="cylinder" pos="0.01449803 0.06763999 0.26822519" size="0.010841227136552334 0.017336048185825348" quat="0.36648058891296387 0.9304257035255432 1.898018358753758e-17 1.3208991768486143e-16"/>
          <geom class="collision" type="cylinder" pos="0.01449803 0.04907648 0.24237054" size="0.010841227136552334 0.017336048185825348" quat="0.25571370124816895 0.9667525291442871 2.0071699690999277e-17 9.70322099972961e-17"/>
          <geom class="collision" type="cylinder" pos="0.01449803 0.03924100 0.21380725" size="0.010841227136552334 0.017336048185825348" quat="0.10857351869344711 0.9940884113311768 1.3839796229460509e-17 6.690520682715116e-17"/>
          <geom class="collision" type="cylinder" pos="0.01449803 0.03633268 0.18985478" size="0.010841227136552334 0.010712708346545696" quat="1.0 1.3665806921110431e-33 -6.500693981790527e-17 2.1022070657818602e-17"/>
        </body>
        <geom class="region" name="reg_basin" type="box" pos="0.120486745 -0.024862450000000008 -0.16740106" size="0.216262285 0.16050691 0.09767837"/>
        <geom class="region" name="reg_main" type="box" pos="-4.999999997368221e-09 3.499999999997949e-05 -0.18426012" size="0.42005012500000005 0.28040001999999997 0.11959588000000002"/>
      </body>
    </body>
  </worldbody>
  <actuator>
    <motor name="handle_joint_actuator" joint="handle_joint" gear="10"/>
    <motor name="handle_temp_joint_actuator" joint="handle_temp_joint" gear="10"/>
    <motor name="Funnel001_joint_actuator" joint="Funnel001_joint" gear="10"/>
    <motor name="Shelf001_joint_actuator" joint="Shelf001_joint" gear="30"/>
    <motor name="spout_joint_actuator" joint="spout_joint" gear="10"/>
  </actuator>
</mujoco>
