<?xml version='1.0' encoding='UTF-8'?>
<mujoco model="model">
  <option timestep="0.002" gravity="0.0 0.0 -9.81"/>
  <compiler angle="radian"/>
  <asset>
    <mesh file="visuals/handle.obj" name="handle_vis"/>
    <mesh file="visuals/Body001.obj" name="Body001_vis"/>
    <mesh file="visuals/spout.obj" name="spout_vis"/>
    <texture file="visuals/T_BC001.png" name="Body001_material" type="2d"/>
    <material name="Body001_material" rgba="1 1 1 1.0" texture="Body001_material" shininess="0.587886393070221" specular="1"/>
    <texture file="visuals/T_BC001.png" name="handle_material" type="2d"/>
    <material name="handle_material" rgba="1 1 1 1.0" texture="handle_material" shininess="0.587886393070221" specular="1"/>
    <texture file="visuals/T_BC001.png" name="spout_material" type="2d"/>
    <material name="spout_material" rgba="1 1 1 1.0" texture="spout_material" shininess="0.587886393070221" specular="1"/>
  </asset>
  <default>
    <default class="visual">
      <geom conaffinity="0" contype="0" group="1" type="mesh"/>
    </default>
    <default class="collision">
      <geom group="0" rgba="0.5 0 0 0.5"/>
    </default>
    <default class="spawn">
      <geom group="0" rgba="1 1 1 0.5" contype="0" conaffinity="0"/>
      <site group="0" rgba="1 1 1 0.5"/>
    </default>
    <default class="region">
      <geom group="1" conaffinity="0" contype="0" rgba="0 1 0 0"/>
    </default>
  </default>
  <worldbody>
    <body>
      <body name="object">
        <geom mesh="Body001_vis" type="mesh" solimp="0.998 0.998 0.001" solref="0.001 1" friction="0.95 0.3 0.1" class="visual" material="Body001_material"/>
        <geom class="collision" type="box" pos="-0.21006083 -0.00000001 0.00767329" size="0.22063221037387848 0.26440149545669556 0.014596006833016872" quat="1.0 0.0 0.0 0.0"/>
        <geom class="collision" type="box" pos="0.41206345 -0.00014385 -0.09136853" size="0.018630051985383034 0.26425763964653015 0.11348769068717957" quat="1.0 0.0 0.0 0.0"/>
        <geom class="collision" type="box" pos="0.19161091 0.24674986 -0.09136853" size="0.20151031017303467 0.017363911494612694 0.11348769068717957" quat="1.0 0.0 0.0 0.0"/>
        <geom class="collision" type="box" pos="0.19161089 -0.24697384 -0.09136853" size="0.20151033997535706 0.017427615821361542 0.11348769068717957" quat="1.0 0.0 0.0 0.0"/>
        <geom class="collision" type="box" pos="0.20225530 -0.22995342 -0.08435947" size="0.19086593389511108 0.0014722681371495128 0.09959064424037933" quat="1.0 0.0 0.0 0.0"/>
        <geom class="collision" type="box" pos="0.20225530 0.22991753 -0.08435947" size="0.19086593389511108 0.0014722681371495128 0.09959064424037933" quat="1.0 0.0 0.0 0.0"/>
        <geom class="collision" type="box" pos="0.01156765 0.00032856 -0.08435947" size="0.0011739537585526705 0.22482742369174957 0.09959064424037933" quat="1.0 0.0 0.0 0.0"/>
        <geom class="collision" type="box" pos="0.39447695 0.00032856 -0.08435947" size="0.0011739537585526705 0.22482742369174957 0.09959064424037933" quat="1.0 0.0 0.0 0.0"/>
        <geom class="collision" type="box" pos="0.20190192 0.00030896 -0.19227582" size="0.1868343949317932 0.2241944819688797 0.0038830465637147427" quat="1.0 0.0 0.0 0.0"/>
        <geom class="collision" type="cylinder" pos="-0.00816955 0.22527768 0.05134399" size="0.013920615427196026 0.02904500439763069" quat="1.0 0.0 0.0 0.0"/>
        <geom class="collision" type="cylinder" pos="0.00307343 0.22415069 0.05050052" size="0.013920619152486324 0.0049588605761528015" quat="0.7071069478988647 -4.7503021960437763e-08 0.7071065902709961 4.750299709144201e-08"/>
        <geom class="collision" type="cylinder" pos="0.15536760 -0.00035775 -0.21169163" size="0.05291753634810448 0.0159302931278944" quat="1.0 0.0 0.0 0.0"/>
        <geom class="collision" type="box" pos="0.00033596 -0.00000001 -0.09500086" size="0.01023541484028101 0.26440149545669556 0.10985535383224487" quat="1.0 0.0 0.0 0.0"/>
        <body name="handle">
          <joint axis="1.0 0.0 0.0" pos="0.02087837 0.22473663 0.05047607" limited="true" name="handle_temp_joint" type="hinge" range="-0.7853981633974483 0.7853981633974483" damping="1" frictionloss="1" armature=".01" stiffness="0.05"/>
          <joint axis="0.0 1.0 0.0" pos="0.02087837 0.22473663 0.05047607" limited="true" name="handle_joint" type="hinge" range="0 0.5" damping="1" frictionloss="1" armature=".01" stiffness="0.05"/>
          <geom mesh="handle_vis" type="mesh" solimp="0.998 0.998 0.001" solref="0.001 1" friction="0.95 0.3 0.1" class="visual" material="handle_material"/>
          <geom name="handle_main" class="collision" type="cylinder" pos="0.02650223 0.22471671 0.08590855" size="0.003368337405845523 0.021307164803147316" quat="1.9470718370939721e-07 -6.717942824252532e-08 1.0 1.3435884227419592e-07"/>
          <geom class="collision" type="cylinder" pos="0.02881479 0.22448906 0.05017698" size="0.014957386068999767 0.006886166986078024" quat="0.70710688829422 -4.7503021960437763e-08 0.7071066498756409 4.750300774958305e-08"/>
        </body>
        <body name="spout">
          <joint axis="0.0 0.0 1.0" pos="-0.00826244 0.22408599 0.19120851" limited="true" name="spout_joint" range="0.0 1.3089969389957472" type="hinge" damping="1" frictionloss="1" armature=".01" stiffness="0.05"/>
          <site type="cylinder" rgba="0.5 0.75 1 0.5" size="0.005772154778242111 0.2162049263715744" pos="-0.00821951 0.04347442 -0.01026095" name="water"/>
          <geom mesh="spout_vis" type="mesh" solimp="0.998 0.998 0.001" solref="0.001 1" friction="0.95 0.3 0.1" class="visual" material="spout_material"/>
          <geom class="collision" type="cylinder" pos="-0.00858793 0.22403820 0.12787965" size="0.009026975370943546 0.047061484307050705" quat="1.0 0.0 0.0 0.0"/>
          <geom class="collision" type="cylinder" pos="-0.00858793 0.10862398 0.21914259" size="0.009026975370943546 0.07580804079771042" quat="0.7071068286895752 0.7071067690849304 1.5700924318127872e-16 5.9269340452702814e-24" name="spout_main"/>
          <geom class="collision" type="cylinder" pos="-0.00858793 0.20785320 0.20345309" size="0.009639048017561436 0.029844213277101517" quat="0.9302526712417603 0.36691954731941223 8.147251254125512e-17 3.892325692199141e-24"/>
          <geom class="collision" type="cylinder" pos="-0.00858793 0.04354711 0.20944294" size="0.006854245904833078 0.003997443709522486" quat="1.0 0.0 0.0 0.0"/>
        </body>
        <geom class="region" name="reg_basin" type="box" pos="0.20367614 0.0003995649999999906 -0.08430736" size="0.18576218 0.223894645 0.10335438999999999"/>
        <geom class="region" name="reg_main" type="box" pos="2.1000000000048757e-07 0.0 -0.102676265" size="0.43169327 0.26540147000000003 0.12594566499999998"/>
      </body>
    </body>
  </worldbody>
  <actuator>
    <motor name="handle_joint_actuator" joint="handle_joint" gear="10"/>
    <motor name="handle_temp_joint_actuator" joint="handle_temp_joint" gear="10"/>
    <motor name="spout_joint_actuator" joint="spout_joint" gear="10"/>
  </actuator>
</mujoco>
