<?xml version='1.0' encoding='UTF-8'?>
<mujoco model="model">
  <option timestep="0.002" gravity="0.0 0.0 -9.81"/>
  <compiler angle="radian"/>
  <asset>
    <mesh file="visuals/handle.obj" name="handle_vis"/>
    <mesh file="visuals/Body001.obj" name="Body001_vis"/>
    <mesh file="visuals/Funnel001.obj" name="Funnel001_vis"/>
    <mesh file="visuals/spout.obj" name="spout_vis"/>
    <texture file="visuals/T_BC001.png" name="Body001_material" type="2d"/>
    <material name="Body001_material" rgba="1 1 1 1.0" texture="Body001_material" shininess="0.1" specular="2"/>
    <texture file="visuals/T_BC001.png" name="handle_material" type="2d"/>
    <material name="handle_material" rgba="1 1 1 1.0" texture="handle_material" shininess="0.33964836597442627" specular="0.3103448502657381"/>
    <texture file="visuals/T_BC001.png" name="Funnel001_material" type="2d"/>
    <material name="Funnel001_material" rgba="1 1 1 1.0" texture="Funnel001_material" shininess="0.1" specular="2"/>
    <texture file="visuals/T_BC001.png" name="spout_material" type="2d"/>
    <material name="spout_material" rgba="1 1 1 1.0" texture="spout_material" shininess="0.33964836597442627" specular="0.3103448502657381"/>
  </asset>
  <default>
    <default class="visual">
      <geom conaffinity="0" contype="0" group="1" type="mesh"/>
    </default>
    <default class="collision">
      <geom group="0" rgba="0.5 0 0 0.5"/>
    </default>
    <default class="spawn">
      <geom group="0" rgba="1 1 1 0.5" contype="0" conaffinity="0"/>
      <site group="0" rgba="1 1 1 0.5"/>
    </default>
    <default class="region">
      <geom group="1" conaffinity="0" contype="0" rgba="0 1 0 0"/>
    </default>
  </default>
  <worldbody>
    <body>
      <body name="object">
        <geom mesh="Body001_vis" type="mesh" solimp="0.998 0.998 0.001" solref="0.001 1" friction="0.95 0.3 0.1" class="visual" material="Body001_material"/>
        <geom class="collision" type="box" pos="-0.35746220 0.02221176 -0.13569940" size="0.022984236478805542 0.2331775724887848 0.13575202226638794" quat="1.0 0.0 0.0 0.0"/>
        <geom class="collision" type="box" pos="0.35453987 -0.00022186 -0.13569945" size="0.02422625757753849 0.25632336735725403 0.13575178384780884" quat="1.0 0.0 0.0 0.0"/>
        <geom class="collision" type="box" pos="-0.02048980 0.20655160 -0.13569948" size="0.3499520719051361 0.05221382901072502 0.13575208187103271" quat="1.0 0.0 0.0 0.0"/>
        <geom class="collision" type="box" pos="-0.02310603 -0.23056762 -0.13569952" size="0.3556530177593231 0.026718564331531525 0.13575203716754913" quat="1.0 0.0 0.0 0.0"/>
        <geom class="collision" type="box" pos="-0.36679310 0.00000001 0.00315979" size="0.026208268478512764 0.2661294937133789 0.008420050144195557" quat="1.0 0.0 0.0 0.0"/>
        <geom class="collision" type="box" pos="0.36581090 0.00000001 0.00315979" size="0.027190066874027252 0.2661294639110565 0.008420044556260109" quat="1.0 0.0 0.0 0.0"/>
        <geom class="collision" type="box" pos="-0.00085371 -0.24423161 0.00315980" size="0.3392278254032135 0.021897615864872932 0.008420041762292385" quat="1.0 0.0 0.0 0.0"/>
        <geom class="collision" type="box" pos="-0.00085371 0.21553633 0.00315980" size="0.3392276167869568 0.05059293657541275 0.008420038968324661" quat="1.0 0.0 0.0 0.0"/>
        <geom class="collision" type="box" pos="0.19487718 -0.02442248 -0.24339394" size="0.1402111053466797 0.18389683961868286 0.028057489544153214" quat="1.0 0.0 0.0 0.0"/>
        <geom class="collision" type="box" pos="-0.19603050 -0.02442248 -0.24339394" size="0.14021100103855133 0.1838967651128769 0.028057483956217766" quat="1.0 0.0 0.0 0.0"/>
        <geom class="collision" type="box" pos="-0.00089251 -0.11934040 -0.24339394" size="0.05441329628229141 0.08897864818572998 0.028057478368282318" quat="1.0 0.0 0.0 0.0"/>
        <geom class="collision" type="box" pos="-0.00089251 0.11920124 -0.24339394" size="0.05441324785351753 0.04058996960520744 0.028057469055056572" quat="1.0 0.0 0.0 0.0"/>
        <geom class="collision" type="cylinder" pos="0.00068549 0.21144406 0.03583772" size="0.02336934022605419 0.022742383182048798" quat="1.0 0.0 0.0 0.0"/>
        <geom class="collision" type="cylinder" pos="-0.00135984 0.21144406 0.06344340" size="0.023010553792119026 0.05056120455265045" quat="0.7071068286895752 0.0 -0.7071067690849304 0.0"/>
        <body name="handle">
          <joint axis="1.0 0.0 0.0" pos="0.07490511 0.21156736 0.06390479" limited="true" name="handle_temp_joint" type="hinge" range="-0.7853981633974483 0.7853981633974483" damping="1" frictionloss="1" armature=".01" stiffness="0.05"/>
          <joint axis="0.0 1.0 0.0" pos="0.07490511 0.21156736 0.06390479" limited="true" name="handle_joint" type="hinge" range="0 0.5" damping="1" frictionloss="1" armature=".01" stiffness="0.05"/>
          <geom mesh="handle_vis" type="mesh" solimp="0.998 0.998 0.001" solref="0.001 1" friction="0.95 0.3 0.1" class="visual" material="handle_material"/>
          <geom class="collision" type="cylinder" pos="0.08008852 0.21144406 0.06344340" size="0.0212209764868021 0.010090702213346958" quat="0.7071068286895752 0.0 -0.7071067690849304 0.0"/>
          <geom class="collision" type="cylinder" pos="0.08331956 0.21221165 0.11158325" size="0.0037490269169211388 0.0287446491420269" quat="7.549790126404332e-08 -0.0 -1.0 -0.0"/>
        </body>
        <body name="Funnel001">
          <joint axis="0.0 0.0 1.0" pos="0.00036652 0.02356690 -0.23604333" limited="true" name="Funnel001_joint" range="0.0 0.05" type="slide" damping="1" frictionloss="1" armature=".01" stiffness="0.05"/>
          <geom mesh="Funnel001_vis" type="mesh" solimp="0.998 0.998 0.001" solref="0.001 1" friction="0.95 0.3 0.1" class="visual" material="Funnel001_material"/>
          <geom class="collision" type="cylinder" pos="-0.00047175 0.02313605 -0.23840877" size="0.04696207121014595 0.004018215928226709" quat="1.0 0.0 0.0 0.0"/>
          <geom class="collision" type="cylinder" pos="-0.00047175 0.02313605 -0.23385105" size="0.006461434997618198 0.0018289702711626887" quat="1.0 0.0 0.0 0.0"/>
        </body>
        <body name="spout">
          <joint axis="0.0 0.0 1.0" pos="0.00043718 0.21142881 0.17631159" limited="true" name="spout_joint" range="-0.7853981633974483 0.7853981633974483" type="hinge" damping="1" frictionloss="1" armature=".01" stiffness="0.05"/>
          <site type="cylinder" rgba="0.5 0.75 1 0.5" size="0.00637557078152895 0.2281561940908432" pos="0.00051080 -0.00038310 0.00975460" name="water"/>
          <geom mesh="spout_vis" type="mesh" solimp="0.998 0.998 0.001" solref="0.001 1" friction="0.95 0.3 0.1" class="visual" material="spout_material"/>
          <geom class="collision" type="cylinder" pos="0.00048344 0.07038264 0.25966764" size="0.012713657692074776 0.09240955114364624" quat="2.247645092268158e-08 8.429369557916289e-08 -0.7071068286895752 -0.7071067094802856" name="spout_main"/>
          <geom class="collision" type="cylinder" pos="0.00045443 0.21158510 0.15086413" size="0.012904489412903786 0.06219162791967392" quat="7.549790126404332e-08 -0.0 -1.0 -0.0"/>
          <geom class="collision" type="cylinder" pos="0.00048342 0.19532503 0.24092621" size="0.014660518616437912 0.03633870184421539" quat="3.2521985104949636e-08 -1.0958445528785887e-07 0.9077298641204834 0.419555127620697"/>
          <geom class="collision" type="cylinder" pos="0.00045443 -0.00035874 0.24390701" size="0.00948744360357523 0.007031399291008711" quat="7.549790126404332e-08 -0.0 -1.0 -0.0"/>
        </body>
        <geom class="region" name="reg_basin" type="box" pos="-0.0038416949999999783 -0.024933109999999994 -0.107796365" size="0.326003235 0.17416052999999998 0.103542085"/>
        <geom class="region" name="reg_main" type="box" pos="-1.8999999998325912e-07 0.0 -0.129935795" size="0.39400113999999997 0.26712923 0.142515615"/>
      </body>
    </body>
  </worldbody>
  <actuator>
    <motor name="handle_joint_actuator" joint="handle_joint" gear="10"/>
    <motor name="handle_temp_joint_actuator" joint="handle_temp_joint" gear="10"/>
    <motor name="Funnel001_joint_actuator" joint="Funnel001_joint" gear="10"/>
    <motor name="spout_joint_actuator" joint="spout_joint" gear="10"/>
  </actuator>
</mujoco>
