<?xml version='1.0' encoding='UTF-8'?>
<mujoco model="model">
  <option timestep="0.002" gravity="0.0 0.0 -9.81"/>
  <compiler angle="radian"/>
  <asset>
    <mesh file="visuals/handle.obj" name="handle_vis"/>
    <mesh file="visuals/Body001.obj" name="Body001_vis"/>
    <mesh file="visuals/Funnel001.obj" name="Funnel001_vis"/>
    <mesh file="visuals/spout.obj" name="spout_vis"/>
    <texture file="visuals/T_BC001.png" name="Body001_material" type="2d"/>
    <material name="Body001_material" rgba="1 1 1 1.0" texture="Body001_material" shininess="0.4472135901451111" specular="1"/>
    <texture file="visuals/T_BC001.png" name="handle_material" type="2d"/>
    <material name="handle_material" rgba="1 1 1 1.0" texture="handle_material" shininess="0.4472135901451111" specular="1"/>
    <texture file="visuals/T_BC001.png" name="Funnel001_material" type="2d"/>
    <material name="Funnel001_material" rgba="1 1 1 1.0" texture="Funnel001_material" shininess="0.4472135901451111" specular="1"/>
    <texture file="visuals/T_BC001.png" name="spout_material" type="2d"/>
    <material name="spout_material" rgba="1 1 1 1.0" texture="spout_material" shininess="0.4472135901451111" specular="1"/>
  </asset>
  <default>
    <default class="visual">
      <geom conaffinity="0" contype="0" group="1" type="mesh"/>
    </default>
    <default class="collision">
      <geom group="0" rgba="0.5 0 0 0.5"/>
    </default>
    <default class="spawn">
      <geom group="0" rgba="1 1 1 0.5" contype="0" conaffinity="0"/>
      <site group="0" rgba="1 1 1 0.5"/>
    </default>
    <default class="region">
      <geom group="1" conaffinity="0" contype="0" rgba="0 1 0 0"/>
    </default>
  </default>
  <worldbody>
    <body>
      <body name="object">
        <geom mesh="Body001_vis" type="mesh" solimp="0.998 0.998 0.001" solref="0.001 1" friction="0.95 0.3 0.1" class="visual" material="Body001_material"/>
        <geom class="collision" type="box" pos="-0.20834444 -0.01296722 -0.27576032" size="0.0030757812783122063 0.00853711273521185 0.019730962812900543" quat="0.16950276494026184 -3.091321385783046e-16 -1.7973683386898406e-15 -0.9855297207832336"/>
        <geom class="collision" type="box" pos="-0.19919984 -0.02452703 -0.27576026" size="0.0030757810454815626 0.00853711273521185 0.019730962812900543" quat="0.39220166206359863 -7.152801486824461e-16 -1.6776381140130772e-15 -0.9198792576789856"/>
        <geom class="collision" type="box" pos="-0.18730278 -0.03172605 -0.27576029" size="0.00307578151114285 0.00853711273521185 0.019730962812900543" quat="0.5035309791564941 -9.183187106996302e-16 -1.5756856285915237e-15 -0.8639771938323975"/>
        <geom class="collision" type="box" pos="-0.17259724 -0.03446363 -0.27576032" size="0.0030757817439734936 0.00853711273521185 0.019730962812900543" quat="0.7007964849472046 -1.2780832495516855e-15 -1.300998561269348e-15 -0.7133612632751465"/>
        <geom class="collision" type="box" pos="-0.15914121 -0.03211268 -0.27576032" size="0.0030757817439734936 0.008537111803889275 0.019730962812900543" quat="0.7737264633178711 -1.411090186281068e-15 -1.1553868213727558e-15 -0.6335198283195496"/>
        <geom class="collision" type="box" pos="-0.14640332 -0.02469664 -0.27576032" size="0.0030757817439734936 0.008537116460502148 0.019730962812900543" quat="0.8989648222923279 -1.6394953733652688e-15 -7.988432841213127e-16 -0.4380207657814026"/>
        <geom class="collision" type="box" pos="-0.13759253 -0.01393849 -0.27576029" size="0.0030757817439734936 0.00853711273521185 0.019730962812900543" quat="0.946450412273407 -1.7260967630463773e-15 -5.88798859657829e-16 -0.3228491544723511"/>
        <geom class="collision" type="box" pos="-0.13341988 -0.00313501 -0.27576032" size="0.00307578151114285 0.0085371108725667 0.019730962812900543" quat="0.9925193786621094 -1.810115972787781e-15 -2.2265703621567577e-16 -0.12208721786737442"/>
        <geom class="collision" type="box" pos="-0.13268199 0.01050489 -0.27576029" size="0.00307578151114285 0.00853711273521185 0.019730962812900543" quat="0.99989914894104 -1.823574267528468e-15 -2.5902970630557174e-17 -0.01420315820723772"/>
        <geom class="collision" type="box" pos="-0.13704083 0.02458512 -0.27576026" size="0.0030757817439734936 0.008537111803889275 0.019730962812900543" quat="0.9762247800827026 -1.7803982453498375e-15 3.9531911738996894e-16 0.21676069498062134"/>
        <geom class="collision" type="box" pos="-0.14553989 0.03559119 -0.27576026" size="0.0030757812783122063 0.00853711273521185 0.019730962812900543" quat="0.9416987299919128 -1.717430874842137e-15 6.13616660314584e-16 0.3364573121070862"/>
        <geom class="collision" type="box" pos="-0.15263325 0.04076965 -0.27576026" size="0.0030757812783122063 0.008537111803889275 0.019730962812900543" quat="0.8705456852912903 -1.5876659567183701e-15 8.97449301186942e-16 0.49208757281303406"/>
        <geom class="collision" type="box" pos="-0.16545984 0.04546750 -0.27576029" size="0.003075780812650919 0.008537111803889275 0.019730962812900543" quat="0.8123213648796082 -1.48147798892319e-15 1.0636344125811571e-15 0.5832101106643677"/>
        <geom class="collision" type="box" pos="-0.18019923 0.04542069 -0.27576026" size="0.0030757817439734936 0.008537111803889275 0.019730962812900543" quat="0.655936598777771 -1.1962705606378791e-15 1.3766017575259516e-15 0.7548159956932068"/>
        <geom class="collision" type="box" pos="-0.19321093 0.04051521 -0.27576032" size="0.00307578151114285 0.008537113666534424 0.019730962812900543" quat="0.5569969415664673 -1.0158284024337164e-15 1.5146577517747986e-15 0.8305145502090454"/>
        <geom class="collision" type="box" pos="-0.20157375 0.03393926 -0.27576032" size="0.0030757810454815626 0.00853711273521185 0.019730962812900543" quat="0.3859434425830841 -7.038672796907009e-16 1.6824580491203093e-15 0.9225224256515503"/>
        <geom class="collision" type="box" pos="-0.20930609 0.02267865 -0.27576026" size="0.0030757810454815626 0.008537120185792446 0.019730962812900543" quat="0.2840755879878998 -5.180861140013167e-16 1.7486238160368422e-15 0.9588018655776978"/>
        <geom class="collision" type="box" pos="-0.21291644 0.00838814 -0.27576032" size="0.0030757810454815626 0.008537111803889275 0.019730962812900543" quat="0.05531521886587143 -1.0087701165889157e-16 1.8209778997868966e-15 0.9984689354896545"/>
        <geom class="collision" type="box" pos="-0.21139125 -0.00543370 -0.27576029" size="0.0030757812783122063 0.008537122048437595 0.019730981439352036" quat="0.0692598968744278 -1.2631098246265976e-16 -1.8193787015824804e-15 -0.9975986480712891"/>
        <geom class="collision" type="box" pos="-0.17270378 0.10810089 -0.25314906" size="0.15964625775814056 0.05763038992881775 0.008205107413232327" quat="1.0 0.0 0.0 0.0"/>
        <geom class="collision" type="box" pos="-0.17270378 0.10810089 -0.25314903" size="0.15964625775814056 0.057630401104688644 0.00820512231439352" quat="1.0 0.0 0.0 0.0"/>
        <geom class="collision" type="box" pos="-0.17270378 -0.11926490 -0.25403941" size="0.15964625775814056 0.07829376310110092 0.00936921127140522" quat="1.0 0.0 0.0 0.0"/>
        <geom class="collision" type="box" pos="-0.07614181 0.00537536 -0.25403950" size="0.054623886942863464 0.050640009343624115 0.009369130246341228" quat="1.0 0.0 0.0 0.0"/>
        <geom class="collision" type="box" pos="-0.27132023 0.00674504 -0.25403947" size="0.05755132436752319 0.05064016208052635 0.009369130246341228" quat="1.0 0.0 0.0 0.0"/>
        <geom class="collision" type="box" pos="-0.00005962 -0.22175469 -0.07358859" size="0.4024573862552643 0.029771815985441208 0.004993463400751352" quat="1.0 0.0 0.0 0.0"/>
        <geom class="collision" type="box" pos="0.00002018 0.20791146 -0.07356735" size="0.4025282561779022 0.043647401034832 0.0050147222355008125" quat="1.0 0.0 0.0 0.0"/>
        <geom class="collision" type="box" pos="-0.36608941 -0.01465240 -0.07345046" size="0.03667639195919037 0.17720961570739746 0.005131593439728022" quat="1.0 0.0 0.0 0.0"/>
        <geom class="collision" type="box" pos="0.19458005 -0.01465240 -0.07351969" size="0.20796838402748108 0.17720964550971985 0.005062346812337637" quat="1.0 0.0 0.0 0.0"/>
        <geom class="collision" type="box" pos="-0.17270378 -0.19338624 -0.15953189" size="0.15964625775814056 0.008025255985558033 0.08541201055049896" quat="1.0 0.0 0.0 0.0"/>
        <geom class="collision" type="box" pos="-0.01688968 -0.01094567 -0.15953203" size="0.008025319315493107 0.1836344450712204 0.08541210740804672" quat="1.0 0.0 0.0 0.0"/>
        <geom class="collision" type="box" pos="-0.33145739 -0.01094564 -0.15953217" size="0.008025317452847958 0.18363440036773682 0.08541207760572433" quat="1.0 0.0 0.0 0.0"/>
        <geom class="collision" type="box" pos="-0.17270378 0.16505067 -0.15953209" size="0.15964625775814056 0.010186362080276012 0.08541205525398254" quat="1.0 0.0 0.0 0.0"/>
        <geom class="collision" type="cylinder" pos="-0.16517578 0.19767201 -0.01823673" size="0.023443039506673813 0.05424214154481888" quat="1.0 -1.8237584971944956e-15 0.0 0.0"/>
        <geom class="collision" type="cylinder" pos="-0.16517578 0.19767201 0.04279619" size="0.015013178810477257 0.009217644110321999" quat="1.0 -1.8237584971944956e-15 0.0 0.0"/>
        <geom class="collision" type="cylinder" pos="-0.13696488 0.19849768 -0.01632117" size="0.016235442832112312 0.010867130011320114" quat="0.7051935791969299 -6.3438906905410875e-12 0.7090148329734802 9.523659372234761e-08"/>
        <body name="handle">
          <joint axis="1.0 0.0 0.0" pos="-0.10478451 0.19924854 -0.01567544" limited="true" name="handle_temp_joint" type="hinge" range="-0.7853981633974483 0.7853981633974483" damping="1" frictionloss="1" armature=".01" stiffness="0.05"/>
          <joint axis="0.0 1.0 0.0" pos="-0.10478451 0.19924854 -0.01567544" limited="true" name="handle_joint" type="hinge" range="0 0.5" damping="1" frictionloss="1" armature=".01" stiffness="0.05"/>
          <geom mesh="handle_vis" type="mesh" solimp="0.998 0.998 0.001" solref="0.001 1" friction="0.95 0.3 0.1" class="visual" material="handle_material"/>
          <geom class="collision" type="cylinder" pos="-0.10113013 0.19849771 -0.01555669" size="0.018503012135624886 0.010279472917318344" quat="0.7051935791969299 -6.3438906905410875e-12 0.7090148329734802 9.523659372234761e-08"/>
          <geom class="collision" type="cylinder" pos="-0.09756843 0.19971254 0.02264243" size="0.0032653282396495342 0.027250390499830246" quat="0.9999913573265076 1.3009839245400195e-13 -0.004157534800469875 -5.585981122102623e-10"/>
        </body>
        <body name="Funnel001">
          <joint axis="0.0 0.0 1.0" pos="-0.17264567 0.00482790 -0.27430484" limited="true" name="Funnel001_joint" range="0.0 0.05" type="slide" damping="1" frictionloss="1" armature=".01" stiffness="0.05"/>
          <geom mesh="Funnel001_vis" type="mesh" solimp="0.998 0.998 0.001" solref="0.001 1" friction="0.95 0.3 0.1" class="visual" material="Funnel001_material"/>
          <geom class="collision" type="cylinder" pos="-0.17270386 0.00583014 -0.27385303" size="0.033521901816129684 0.020131705328822136" quat="7.907536314633035e-07 1.4421436566754754e-21 1.8237584971944956e-15 1.0"/>
        </body>
        <body name="spout">
          <joint axis="0.0 0.0 1.0" pos="-0.16471953 0.19774088 0.16800553" limited="true" name="spout_joint" range="-0.7853981633974483 0.7853981633974483" type="hinge" damping="1" frictionloss="1" armature=".01" stiffness="0.05"/>
          <site type="cylinder" rgba="0.5 0.75 1 0.5" size="0.004266842734068632 0.1593114584684372" pos="-0.16262632 0.05965479 -0.10095969" name="water"/>
          <geom mesh="spout_vis" type="mesh" solimp="0.998 0.998 0.001" solref="0.001 1" friction="0.95 0.3 0.1" class="visual" material="spout_material"/>
          <geom class="collision" type="cylinder" pos="-0.16490055 0.19794722 0.10633916" size="0.014699677005410194 0.050279878079891205" quat="1.0 -1.8237584971944956e-15 0.0 0.0"/>
          <geom class="collision" type="cylinder" pos="-0.16517578 0.19767199 0.19352908" size="0.01120044570416212 0.03831084072589874" quat="1.0 -1.8237584971944956e-15 0.0 0.0"/>
          <geom class="collision" type="cylinder" pos="-0.16517578 0.18863596 0.25107449" size="0.01120044570416212 0.02547653578221798" quat="0.9593374729156494 0.28226161003112793 -6.267466768486506e-17 -1.38730607210171e-25"/>
          <geom class="collision" type="cylinder" pos="-0.16517578 0.15671034 0.27914697" size="0.01120044570416212 0.025476541370153427" quat="0.8404239416122437 0.5419295430183411 -1.203325312767103e-16 -2.5543239197118103e-24"/>
          <geom class="collision" type="cylinder" pos="-0.16465230 0.11823454 0.28558722" size="0.01120044570416212 0.02174557000398636" quat="0.65557461977005 0.755130410194397 -1.676726203636019e-16 -4.94466140659854e-24"/>
          <geom class="collision" type="cylinder" pos="-0.16324923 0.06671323 0.24336834" size="0.012502557598054409 0.01421136874705553" quat="0.26908019185066223 0.963117778301239 -2.138551065791725e-16 -4.641503738443915e-25"/>
          <geom class="collision" type="cylinder" pos="-0.16517578 0.05959039 0.20208523" size="0.012454117648303509 0.03192519024014473" quat="0.0002859393716789782 -0.9999999403953552 2.2204531960908055e-16 -2.368643094129728e-22"/>
          <geom class="collision" type="cylinder" pos="-0.16517576 0.06038303 0.20208520" size="0.011054271832108498 0.03192519024014473" quat="0.0002859393716789782 -0.9999999403953552 2.2204531960908055e-16 -2.368643094129728e-22"/>
          <geom class="collision" type="cylinder" pos="-0.16490057 0.05963232 0.11545447" size="0.01948469690978527 0.057862669229507446" quat="1.0 -1.8237584971944956e-15 0.0 0.0" name="spout_main"/>
          <geom class="collision" type="cylinder" pos="-0.16490057 0.13211092 0.12800983" size="0.007005923893302679 0.05968574434518814" quat="0.7071068286895752 0.7071067690849304 -1.5776961407011706e-16 -7.678365040593655e-19"/>
          <geom class="collision" type="cylinder" pos="-0.16408202 0.08669423 0.26923907" size="0.01120044570416212 0.02547653578221798" quat="0.3535419702529907 0.9354186654090881 -2.0770468123515083e-16 1.2017664013457033e-23"/>
        </body>
        <geom class="region" name="reg_basin" type="box" pos="-0.173802505 -0.0150401 -0.15654764" size="0.14417160499999998 0.16491908 0.0837391"/>
        <geom class="region" name="reg_main" type="box" pos="-3.00000000119649e-08 -1.1999999999234845e-07 -0.18146969500000001" size="0.40376586999999997 0.25270389 0.114261415"/>
      </body>
    </body>
  </worldbody>
  <actuator>
    <motor name="handle_joint_actuator" joint="handle_joint" gear="10"/>
    <motor name="handle_temp_joint_actuator" joint="handle_temp_joint" gear="10"/>
    <motor name="Funnel001_joint_actuator" joint="Funnel001_joint" gear="10"/>
    <motor name="spout_joint_actuator" joint="spout_joint" gear="10"/>
  </actuator>
</mujoco>
