<?xml version='1.0' encoding='UTF-8'?>
<mujoco model="model">
  <option timestep="0.002" gravity="0.0 0.0 -9.81"/>
  <compiler angle="radian"/>
  <asset>
    <mesh file="visuals/knob_center.obj" name="knob_center_vis"/>
    <mesh file="visuals/knob_front_left.obj" name="knob_front_left_vis"/>
    <mesh file="visuals/knob_front_right.obj" name="knob_front_right_vis"/>
    <mesh file="visuals/knob_rear_left.obj" name="knob_rear_left_vis"/>
    <mesh file="visuals/knob_rear_right.obj" name="knob_rear_right_vis"/>
    <mesh file="visuals/Body001.obj" name="Body001_vis"/>
    <texture file="visuals/T_BC001.png" name="Body001_material" type="2d"/>
    <material name="Body001_material" rgba="1 1 1 1.0" texture="Body001_material" shininess="0.1" specular="4"/>
    <texture file="visuals/T_BC001.png" name="knob_center_material" type="2d"/>
    <material name="knob_center_material" rgba="1 1 1 1.0" texture="knob_center_material" shininess="0.141421377658844" specular="0.3103448502657381"/>
    <texture file="visuals/T_BC001.png" name="knob_front_left_material" type="2d"/>
    <material name="knob_front_left_material" rgba="1 1 1 1.0" texture="knob_front_left_material" shininess="0.141421377658844" specular="0.3103448502657381"/>
    <texture file="visuals/T_BC001.png" name="knob_front_right_material" type="2d"/>
    <material name="knob_front_right_material" rgba="1 1 1 1.0" texture="knob_front_right_material" shininess="0.141421377658844" specular="0.3103448502657381"/>
    <texture file="visuals/T_BC001.png" name="knob_rear_left_material" type="2d"/>
    <material name="knob_rear_left_material" rgba="1 1 1 1.0" texture="knob_rear_left_material" shininess="0.141421377658844" specular="0.3103448502657381"/>
    <texture file="visuals/T_BC001.png" name="knob_rear_right_material" type="2d"/>
    <material name="knob_rear_right_material" rgba="1 1 1 1.0" texture="knob_rear_right_material" shininess="0.141421377658844" specular="0.3103448502657381"/>
  </asset>
  <default>
    <default class="visual">
      <geom conaffinity="0" contype="0" group="1" type="mesh"/>
    </default>
    <default class="collision">
      <geom group="0" rgba="0.5 0 0 0.5"/>
    </default>
    <default class="spawn">
      <geom group="0" rgba="1 1 1 0.5" contype="0" conaffinity="0"/>
      <site group="0" rgba="1 1 1 0.5"/>
    </default>
    <default class="region">
      <geom group="1" conaffinity="0" contype="0" rgba="0 1 0 0"/>
    </default>
  </default>
  <worldbody>
    <body>
      <body name="object">
        <geom mesh="Body001_vis" type="mesh" solimp="0.998 0.998 0.001" solref="0.001 1" friction="0.95 0.3 0.1" class="visual" material="Body001_material"/>
        <geom class="collision" type="box" pos="0.00000507 0.00002325 -0.01622455" size="0.5037747621536255 0.34315985441207886 0.0023943993728607893" quat="1.0 0.0 0.0 0.0"/>
        <geom class="collision" type="box" pos="-0.00066295 0.03935498 0.00272973" size="0.4771367013454437 0.27203309535980225 0.015992630273103714" quat="1.0 0.0 0.0 0.0"/>
        <geom class="collision" type="box" pos="-0.34202588 -0.24491544 0.00272973" size="0.007446399424225092 0.016593515872955322 0.015992630273103714" quat="1.0 0.0 0.0 0.0"/>
        <geom class="collision" type="box" pos="0.34063055 -0.24491544 0.00272973" size="0.007446399424225092 0.016593515872955322 0.015992630273103714" quat="1.0 0.0 0.0 0.0"/>
        <body name="knob_center">
          <joint axis="0.0 0.0 1.0" pos="0.00075761 -0.27646983 -0.00278144" limited="true" name="knob_center_joint" range="0.0 3.141592653589793" type="hinge" damping="0.05" armature="0.001"/>
          <geom mesh="knob_center_vis" type="mesh" solimp="0.998 0.998 0.001" solref="0.001 1" friction="0.95 0.3 0.1" class="visual" material="knob_center_material"/>
          <geom class="collision" type="box" pos="0.00067418 -0.27661869 0.00524147" size="0.014874361455440521 0.026102233678102493 0.013480888679623604" quat="1.0 0.0 0.0 0.0" name="knob_center_main"/>
          <geom class="collision" type="cylinder" pos="0.00096464 -0.27648753 -0.01021900" size="0.02549481950700283 0.002379579236730933" quat="1.0 0.0 0.0 0.0"/>
        </body>
        <body name="knob_front_left">
          <joint axis="0.0 0.0 1.0" pos="-0.21243743 -0.27646983 0.00218252" limited="true" name="knob_front_left_joint" range="0.0 3.141592653589793" type="hinge" damping="0.05" armature="0.001"/>
          <geom mesh="knob_front_left_vis" type="mesh" solimp="0.998 0.998 0.001" solref="0.001 1" friction="0.95 0.3 0.1" class="visual" material="knob_front_left_material"/>
          <geom class="collision" type="box" pos="-0.21199395 -0.27661869 0.00524147" size="0.014874360524117947 0.026102233678102493 0.013480888679623604" quat="1.0 0.0 0.0 0.0" name="knob_front_left_main"/>
          <geom class="collision" type="cylinder" pos="-0.21255463 -0.27648753 -0.01021900" size="0.02549481950700283 0.002379579236730933" quat="1.0 0.0 0.0 0.0"/>
        </body>
        <body name="knob_front_right">
          <joint axis="0.0 0.0 1.0" pos="0.21546326 -0.27646983 0.00218252" limited="true" name="knob_front_right_joint" range="0.0 3.141592653589793" type="hinge" damping="0.05" armature="0.001"/>
          <geom mesh="knob_front_right_vis" type="mesh" solimp="0.998 0.998 0.001" solref="0.001 1" friction="0.95 0.3 0.1" class="visual" material="knob_front_right_material"/>
          <geom class="collision" type="box" pos="0.21526844 -0.27661869 0.00544147" size="0.014874360524117947 0.026102233678102493 0.01328088715672493" quat="1.0 0.0 0.0 0.0" name="knob_front_right_main"/>
          <geom class="collision" type="cylinder" pos="0.21547901 -0.27648753 -0.01021900" size="0.02549481764435768 0.002379579236730933" quat="1.0 0.0 0.0 0.0"/>
        </body>
        <body name="knob_rear_left">
          <joint axis="0.0 0.0 1.0" pos="-0.10701134 -0.27646983 0.00218252" limited="true" name="knob_rear_left_joint" range="0.0 3.141592653589793" type="hinge" damping="0.05" armature="0.001"/>
          <geom mesh="knob_rear_left_vis" type="mesh" solimp="0.998 0.998 0.001" solref="0.001 1" friction="0.95 0.3 0.1" class="visual" material="knob_rear_left_material"/>
          <geom class="collision" type="box" pos="-0.10674547 -0.27661869 0.00524147" size="0.01487436331808567 0.026102233678102493 0.013480888679623604" quat="1.0 0.0 0.0 0.0" name="knob_rear_left_main"/>
          <geom class="collision" type="cylinder" pos="-0.10709531 -0.27648753 -0.01021900" size="0.02549481950700283 0.002379579236730933" quat="1.0 0.0 0.0 0.0"/>
        </body>
        <body name="knob_rear_right">
          <joint axis="0.0 0.0 1.0" pos="0.10765153 -0.27646983 0.00218252" limited="true" name="knob_rear_right_joint" range="0.0 3.141592653589793" type="hinge" damping="0.05" armature="0.001"/>
          <geom mesh="knob_rear_right_vis" type="mesh" solimp="0.998 0.998 0.001" solref="0.001 1" friction="0.95 0.3 0.1" class="visual" material="knob_rear_right_material"/>
          <geom class="collision" type="box" pos="0.10764588 -0.27661869 0.00524147" size="0.01487436331808567 0.026102233678102493 0.013480888679623604" quat="1.0 0.0 0.0 0.0" name="knob_rear_right_main"/>
          <geom class="collision" type="cylinder" pos="0.10777196 -0.27648753 -0.01021900" size="0.02549481764435768 0.002379579236730933" quat="1.0 0.0 0.0 0.0"/>
        </body>
        <site type="cylinder" rgba="0.3 0.4 1 0.5" size="0.04798935726284981 0.005398983135819435" pos="-0.32848684 0.16873083 0.00916122" name="burner_on_rear_left"/>
        <site type="cylinder" rgba="0.3 0.4 1 0.5" size="0.06387793272733688 0.006224197335541248" pos="-0.34205759 -0.12123667 0.00878625" name="burner_on_front_left"/>
        <site type="cylinder" rgba="0.3 0.4 1 0.5" size="0.08508281409740448 0.006080179009586573" pos="0.00075783 0.00697827 0.00894887" name="burner_on_center"/>
        <site type="cylinder" rgba="0.3 0.4 1 0.5" size="0.0483204647898674 0.006255870219320059" pos="0.32884099 0.16873272 0.00894880" name="burner_on_rear_right"/>
        <site type="cylinder" rgba="0.3 0.4 1 0.5" size="0.033213403075933456 0.0054710628464818" pos="0.34055238 -0.12134513 0.00908137" name="burner_on_front_right"/>
        <site type="cylinder" rgba="0.5 0 0 0" size="0.047458648681640625 4.999999873689376e-05" pos="-0.32848684 0.16873083 0.01867236" name="burner_rear_left_place_site"/>
        <site type="cylinder" rgba="0.5 0 0 0" size="0.06139972433447838 4.999999873689376e-05" pos="-0.34205759 -0.12123667 0.01867236" name="burner_front_left_place_site"/>
        <site type="cylinder" rgba="0.5 0 0 0" size="0.08221416175365448 4.999999873689376e-05" pos="0.00075783 0.00697827 0.01867236" name="burner_center_place_site"/>
        <site type="cylinder" rgba="0.5 0 0 0" size="0.04726271331310272 4.999999873689376e-05" pos="0.32884099 0.16873272 0.01867236" name="burner_rear_right_place_site"/>
        <site type="cylinder" rgba="0.5 0 0 0" size="0.032118458300828934 4.999999873689376e-05" pos="0.34055238 -0.12160791 0.01867236" name="burner_front_right_place_site"/>
        <geom class="region" name="reg_main" type="box" pos="4.999999999977245e-06 -1.4999999992104662e-08 -0.016224495" size="0.5047740500000001 0.34418226500000004 0.003394335"/>
      </body>
    </body>
  </worldbody>
  <actuator>
    <motor name="knob_center_joint_actuator" joint="knob_center_joint" gear="10"/>
    <motor name="knob_front_left_joint_actuator" joint="knob_front_left_joint" gear="10"/>
    <motor name="knob_front_right_joint_actuator" joint="knob_front_right_joint" gear="10"/>
    <motor name="knob_rear_left_joint_actuator" joint="knob_rear_left_joint" gear="10"/>
    <motor name="knob_rear_right_joint_actuator" joint="knob_rear_right_joint" gear="10"/>
  </actuator>
</mujoco>
