<?xml version='1.0' encoding='UTF-8'?>
<mujoco model="model">
  <option timestep="0.002" gravity="0.0 0.0 -9.81"/>
  <compiler angle="radian"/>
  <asset>
    <mesh file="visuals/door.obj" name="door_vis"/>
    <mesh file="visuals/door_Clear.obj" name="door_Clear_vis"/>
    <mesh file="visuals/knob_temp.obj" name="knob_temp_vis"/>
    <mesh file="visuals/knob_time.obj" name="knob_time_vis"/>
    <mesh file="visuals/Body001.obj" name="Body001_vis"/>
    <mesh file="visuals/rack0.obj" name="rack0_vis"/>
    <texture file="visuals/T_BC001.png" name="Body001_material" type="2d"/>
    <material name="Body001_material" rgba="1 1 1 1.0" texture="Body001_material" shininess="0.1" specular="5"/>
    <texture file="visuals/T_BC001.png" name="door_material" type="2d"/>
    <material name="door_material" rgba="1 1 1 1.0" texture="door_material" shininess="0.1" specular="5"/>
    <texture file="visuals/T_BC001.png" name="door_Clear_material" type="2d"/>
    <material name="door_Clear_material" rgba="1 1 1 0.800000011920929" texture="door_Clear_material" shininess="0.1" specular="5"/>
    <texture file="visuals/T_BC001.png" name="knob_temp_material" type="2d"/>
    <material name="knob_temp_material" rgba="1 1 1 1.0" texture="knob_temp_material" shininess="0.1" specular="5"/>
    <texture file="visuals/T_BC001.png" name="knob_time_material" type="2d"/>
    <material name="knob_time_material" rgba="1 1 1 1.0" texture="knob_time_material" shininess="0.1" specular="5"/>
    <texture file="visuals/T_BC001.png" name="rack0_material" type="2d"/>
    <material name="rack0_material" rgba="1 1 1 1.0" texture="rack0_material" shininess="0.1" specular="5"/>
  </asset>
  <default>
    <default class="visual">
      <geom conaffinity="0" contype="0" group="1" type="mesh"/>
    </default>
    <default class="collision">
      <geom group="0" rgba="0.5 0 0 0.5"/>
    </default>
    <default class="spawn">
      <geom group="0" rgba="1 1 1 0.5" contype="0" conaffinity="0"/>
      <site group="0" rgba="1 1 1 0.5"/>
    </default>
    <default class="region">
      <geom group="1" conaffinity="0" contype="0" rgba="0 1 0 0"/>
    </default>
  </default>
  <worldbody>
    <body>
      <body name="object">
        <geom mesh="Body001_vis" type="mesh" solimp="0.998 0.998 0.001" solref="0.001 1" friction="0.95 0.3 0.1" class="visual" material="Body001_material"/>
        <geom class="collision" type="box" pos="-0.2544620633125305 0.023176802322268486 -0.006310977041721344" size="0.0020570470951497555 0.18197987973690033 0.24050770699977875" quat="1.0 0.0 0.0 0.0"/>
        <geom class="collision" type="box" pos="0.25352543592453003 0.02317679673433304 -0.0063109504990279675" size="0.002057039877399802 0.18198014795780182 0.24050800502300262" quat="1.0 0.0 0.0 0.0"/>
        <geom class="collision" type="box" pos="0.0005653143161907792 0.20080973207950592 -0.020130107179284096" size="0.25446319580078125 0.007349087856709957 0.22881145775318146" quat="1.0 0.0 0.0 0.0"/>
        <geom class="collision" type="box" pos="0.000565314432606101 0.160851389169693 0.18146006762981415" size="0.2544921934604645 0.0444716140627861 0.027219019830226898" quat="1.0 0.0 0.0 0.0"/>
        <geom class="collision" type="box" pos="0.000565314432606101 0.09966830164194107 0.22004328668117523" size="0.003014849964529276 0.2544921934604645 0.028582042083144188" quat="0.629673421382904 0.32173192501068115 0.32173189520835876 -0.6296733617782593"/>
        <geom class="collision" type="box" pos="0.0005653135012835264 -0.04897317662835121 0.19615307450294495" size="0.2544921934604645 0.12711374461650848 0.03950924798846245" quat="1.0 0.0 0.0 0.0"/>
        <geom class="collision" type="box" pos="-0.00042295793537050486 -0.1732904613018036 0.21226297318935394" size="0.26582059264183044 0.006865283008664846 0.05265137180685997" quat="1.0 0.0 0.0 0.0"/>
        <geom class="collision" type="box" pos="0.0005653519765473902 0.019687483087182045 -0.24789226055145264" size="0.25451263785362244 0.17850933969020844 0.0010494127636775374" quat="1.0 0.0 0.0 0.0"/>
        <geom class="collision" type="box" pos="-0.24748526513576508 0.1498759388923645 -0.043011587113142014" size="0.003164632013067603 0.0026933911722153425 0.1804380863904953" quat="1.0 0.0 0.0 0.0"/>
        <geom class="collision" type="box" pos="-0.24748526513576508 -0.11828050762414932 -0.043011587113142014" size="0.003164628054946661 0.0026933911722153425 0.1804378479719162" quat="1.0 0.0 0.0 0.0"/>
        <geom class="collision" type="box" pos="-0.21665705740451813 0.01477318350225687 -0.20392325520515442" size="0.002550966339185834 0.13574707508087158 0.0023388429544866085" quat="1.0 0.0 0.0 0.0"/>
        <geom class="collision" type="box" pos="-0.23302842676639557 0.1502387821674347 -0.20392325520515442" size="0.012358578853309155 0.0020729394163936377 0.00233883922919631" quat="1.0 0.0 0.0 0.0"/>
        <geom class="collision" type="box" pos="-0.23302842676639557 -0.1191842183470726 -0.20392325520515442" size="0.012358563020825386 0.0020729394163936377 0.0023388355039060116" quat="1.0 0.0 0.0 0.0"/>
        <geom class="collision" type="box" pos="-0.23302842676639557 -0.1191842183470726 -0.17641738057136536" size="0.012358547188341618 0.0020729394163936377 0.002338831778615713" quat="1.0 0.0 0.0 0.0"/>
        <geom class="collision" type="box" pos="-0.23302842676639557 0.1502387821674347 -0.17641738057136536" size="0.012358531355857849 0.0020729394163936377 0.0023388280533254147" quat="1.0 0.0 0.0 0.0"/>
        <geom class="collision" type="box" pos="-0.21665705740451813 0.015500597655773163 -0.1831607222557068" size="0.0025509465485811234 0.10936176776885986 0.002338824328035116" quat="1.0 0.0 0.0 0.0"/>
        <geom class="collision" type="box" pos="-0.21665705740451813 0.015500597655773163 -0.11657079309225082" size="0.0025509425904601812 0.10936175286769867 0.0023388206027448177" quat="1.0 0.0 0.0 0.0"/>
        <geom class="collision" type="box" pos="-0.23302842676639557 0.1502387821674347 -0.1098274514079094" size="0.012358483858406544 0.0020729394163936377 0.0023388168774545193" quat="1.0 0.0 0.0 0.0"/>
        <geom class="collision" type="box" pos="-0.23302842676639557 -0.1191842183470726 -0.1098274514079094" size="0.012358468025922775 0.0020729394163936377 0.002338813152164221" quat="1.0 0.0 0.0 0.0"/>
        <geom class="collision" type="box" pos="-0.23302842676639557 -0.1191842183470726 -0.14427690207958221" size="0.012358452193439007 0.0020729394163936377 0.0023388094268739223" quat="1.0 0.0 0.0 0.0"/>
        <geom class="collision" type="box" pos="-0.23302842676639557 0.1502387821674347 -0.14427690207958221" size="0.012358436360955238 0.0020729394163936377 0.002338805701583624" quat="1.0 0.0 0.0 0.0"/>
        <geom class="collision" type="box" pos="-0.21665705740451813 0.01477318350225687 -0.14427690207958221" size="0.0025509227998554707 0.13574707508087158 0.0023388019762933254" quat="1.0 0.0 0.0 0.0"/>
        <geom class="collision" type="box" pos="-0.21665705740451813 0.01477318350225687 0.00997750274837017" size="0.0025509188417345285 0.13574707508087158 0.002338798251003027" quat="1.0 0.0 0.0 0.0"/>
        <geom class="collision" type="box" pos="-0.23302842676639557 0.1502387821674347 0.00997750274837017" size="0.012358388863503933 0.0020729394163936377 0.0023387945257127285" quat="1.0 0.0 0.0 0.0"/>
        <geom class="collision" type="box" pos="-0.23302842676639557 -0.1191842183470726 0.00997750274837017" size="0.012358373031020164 0.0020729394163936377 0.00233879080042243" quat="1.0 0.0 0.0 0.0"/>
        <geom class="collision" type="box" pos="-0.23302842676639557 -0.1191842183470726 0.04442695528268814" size="0.012358357198536396 0.0020729394163936377 0.0023387870751321316" quat="1.0 0.0 0.0 0.0"/>
        <geom class="collision" type="box" pos="-0.23302842676639557 0.1502387821674347 0.04442695528268814" size="0.012358341366052628 0.0020729394163936377 0.002338783349841833" quat="1.0 0.0 0.0 0.0"/>
        <geom class="collision" type="box" pos="-0.21665705740451813 0.015500597655773163 0.0385490320622921" size="0.002550899051129818 0.10936175286769867 0.0023387796245515347" quat="1.0 0.0 0.0 0.0"/>
        <geom class="collision" type="box" pos="-0.21665705740451813 0.015500597655773163 -0.03830826282501221" size="0.002550895093008876 0.10936176776885986 0.002338775899261236" quat="1.0 0.0 0.0 0.0"/>
        <geom class="collision" type="box" pos="-0.23302842676639557 0.1502387821674347 -0.031564921140670776" size="0.012358293868601322 0.0020729394163936377 0.0023387721739709377" quat="1.0 0.0 0.0 0.0"/>
        <geom class="collision" type="box" pos="-0.23302842676639557 -0.1191842183470726 -0.031564921140670776" size="0.012358278036117554 0.0020729394163936377 0.0023387684486806393" quat="1.0 0.0 0.0 0.0"/>
        <geom class="collision" type="box" pos="-0.23302842676639557 -0.1191842183470726 -0.06716689467430115" size="0.012358262203633785 0.0020729394163936377 0.002338764723390341" quat="1.0 0.0 0.0 0.0"/>
        <geom class="collision" type="box" pos="-0.23302842676639557 0.1502387821674347 -0.06716689467430115" size="0.012358246371150017 0.0020729394163936377 0.0023387609981000423" quat="1.0 0.0 0.0 0.0"/>
        <geom class="collision" type="box" pos="-0.21665705740451813 0.01477318350225687 -0.06716689467430115" size="0.002550875535234809 0.13574707508087158 0.002338757272809744" quat="1.0 0.0 0.0 0.0"/>
        <geom class="collision" type="box" pos="-0.21665705740451813 0.01477318350225687 0.07496404647827148" size="0.002550871577113867 0.13574707508087158 0.0023387533146888018" quat="1.0 0.0 0.0 0.0"/>
        <geom class="collision" type="box" pos="-0.23302842676639557 0.1502387821674347 0.07496404647827148" size="0.012358198873698711 0.0020729394163936377 0.0023387495893985033" quat="1.0 0.0 0.0 0.0"/>
        <geom class="collision" type="box" pos="-0.23302842676639557 -0.1191842183470726 0.07496404647827148" size="0.012358183041214943 0.0020729394163936377 0.002338745864108205" quat="1.0 0.0 0.0 0.0"/>
        <geom class="collision" type="box" pos="-0.21665705740451813 0.015500597655773163 0.09847967326641083" size="0.0025508597027510405 0.10936175286769867 0.0023387421388179064" quat="1.0 0.0 0.0 0.0"/>
        <geom class="collision" type="box" pos="-0.23302842676639557 0.1502387821674347 0.10435759276151657" size="0.012358151376247406 0.0020729394163936377 0.002338738413527608" quat="1.0 0.0 0.0 0.0"/>
        <geom class="collision" type="box" pos="-0.23302842676639557 -0.1191842183470726 0.10435759276151657" size="0.012358135543763638 0.0020729394163936377 0.0023387346882373095" quat="1.0 0.0 0.0 0.0"/>
        <geom class="collision" type="box" pos="0.23276957869529724 -0.1191842257976532 0.10435760021209717" size="0.012358119711279869 0.0020729394163936377 0.002338730962947011" quat="1.0 0.0 0.0 0.0"/>
        <geom class="collision" type="box" pos="0.23276957869529724 0.1502387821674347 0.10435760021209717" size="0.0123581038787961 0.0020729394163936377 0.0023387272376567125" quat="1.0 0.0 0.0 0.0"/>
        <geom class="collision" type="box" pos="0.2163982093334198 0.015500589273869991 0.09847967326641083" size="0.00255083991214633 0.10936175286769867 0.002338723512366414" quat="1.0 0.0 0.0 0.0"/>
        <geom class="collision" type="box" pos="0.23276957869529724 -0.1191842257976532 0.07496404647827148" size="0.012358072213828564 0.0020729394163936377 0.0023387197870761156" quat="1.0 0.0 0.0 0.0"/>
        <geom class="collision" type="box" pos="0.23276957869529724 0.1502387821674347 0.07496404647827148" size="0.012358056381344795 0.0020729394163936377 0.002338716061785817" quat="1.0 0.0 0.0 0.0"/>
        <geom class="collision" type="box" pos="0.2163982093334198 0.014773176051676273 0.07496404647827148" size="0.0025508280377835035 0.13574707508087158 0.0023387123364955187" quat="1.0 0.0 0.0 0.0"/>
        <geom class="collision" type="box" pos="0.2163982093334198 0.01477318350225687 -0.06716689467430115" size="0.0025508240796625614 0.13574707508087158 0.0023387086112052202" quat="1.0 0.0 0.0 0.0"/>
        <geom class="collision" type="box" pos="0.23276957869529724 0.1502387821674347 -0.06716689467430115" size="0.012358009815216064 0.0020729394163936377 0.0023387048859149218" quat="1.0 0.0 0.0 0.0"/>
        <geom class="collision" type="box" pos="0.23276957869529724 -0.1191842257976532 -0.06716689467430115" size="0.012357993982732296 0.0020729394163936377 0.0023387011606246233" quat="1.0 0.0 0.0 0.0"/>
        <geom class="collision" type="box" pos="0.23276957869529724 -0.1191842257976532 -0.031564921140670776" size="0.012357978150248528 0.0020729394163936377 0.002338697435334325" quat="1.0 0.0 0.0 0.0"/>
        <geom class="collision" type="box" pos="0.23276957869529724 0.1502387821674347 -0.031564921140670776" size="0.012357962317764759 0.0020729394163936377 0.0023386937100440264" quat="1.0 0.0 0.0 0.0"/>
        <geom class="collision" type="box" pos="0.2163982093334198 0.015500590205192566 -0.03830826282501221" size="0.002550804289057851 0.10936176776885986 0.002338689984753728" quat="1.0 0.0 0.0 0.0"/>
        <geom class="collision" type="box" pos="0.2163982093334198 0.015500589273869991 0.0385490357875824" size="0.0025508003309369087 0.10936175286769867 0.0023386862594634295" quat="1.0 0.0 0.0 0.0"/>
        <geom class="collision" type="box" pos="0.23276957869529724 0.1502387821674347 0.04442696273326874" size="0.012357914820313454 0.0020729394163936377 0.002338682534173131" quat="1.0 0.0 0.0 0.0"/>
        <geom class="collision" type="box" pos="0.23276957869529724 -0.1191842257976532 0.04442696273326874" size="0.012357898987829685 0.0020729394163936377 0.0023386788088828325" quat="1.0 0.0 0.0 0.0"/>
        <geom class="collision" type="box" pos="0.23276957869529724 -0.1191842257976532 0.009977500885725021" size="0.012357883155345917 0.0020729394163936377 0.002338675083592534" quat="1.0 0.0 0.0 0.0"/>
        <geom class="collision" type="box" pos="0.23276957869529724 0.1502387821674347 0.009977500885725021" size="0.012357867322862148 0.0020729394163936377 0.0023386713583022356" quat="1.0 0.0 0.0 0.0"/>
        <geom class="collision" type="box" pos="0.2163982093334198 0.014773176051676273 0.009977500885725021" size="0.002550780540332198 0.13574707508087158 0.002338667633011937" quat="1.0 0.0 0.0 0.0"/>
        <geom class="collision" type="box" pos="0.2163982093334198 0.014773176051676273 -0.14427690207958221" size="0.002550776582211256 0.13574707508087158 0.0023386639077216387" quat="1.0 0.0 0.0 0.0"/>
        <geom class="collision" type="box" pos="0.23276957869529724 0.1502387821674347 -0.14427690207958221" size="0.012357819825410843 0.0020729394163936377 0.0023386601824313402" quat="1.0 0.0 0.0 0.0"/>
        <geom class="collision" type="box" pos="0.23276957869529724 -0.1191842257976532 -0.14427690207958221" size="0.012357803992927074 0.0020729394163936377 0.0023386564571410418" quat="1.0 0.0 0.0 0.0"/>
        <geom class="collision" type="box" pos="0.23276957869529724 -0.1191842257976532 -0.1098274514079094" size="0.012357788160443306 0.0020729394163936377 0.0023386527318507433" quat="1.0 0.0 0.0 0.0"/>
        <geom class="collision" type="box" pos="0.23276957869529724 0.1502387821674347 -0.1098274514079094" size="0.012357772327959538 0.0020729394163936377 0.002338649006560445" quat="1.0 0.0 0.0 0.0"/>
        <geom class="collision" type="box" pos="0.2163982093334198 0.015500589273869991 -0.11657078564167023" size="0.0025507567916065454 0.10936175286769867 0.0023386452812701464" quat="1.0 0.0 0.0 0.0"/>
        <geom class="collision" type="box" pos="0.2163982093334198 0.015500590205192566 -0.1831607222557068" size="0.0025507528334856033 0.10936176776885986 0.002338641555979848" quat="1.0 0.0 0.0 0.0"/>
        <geom class="collision" type="box" pos="0.23276957869529724 0.1502387821674347 -0.17641738057136536" size="0.012357724830508232 0.0020729394163936377 0.0023386378306895494" quat="1.0 0.0 0.0 0.0"/>
        <geom class="collision" type="box" pos="0.23276957869529724 -0.1191842257976532 -0.17641738057136536" size="0.012357708998024464 0.0020729394163936377 0.002338634105399251" quat="1.0 0.0 0.0 0.0"/>
        <geom class="collision" type="box" pos="0.23276957869529724 -0.1191842257976532 -0.20392325520515442" size="0.012357693165540695 0.0020729394163936377 0.002338630147278309" quat="1.0 0.0 0.0 0.0"/>
        <geom class="collision" type="box" pos="0.23276957869529724 0.1502387821674347 -0.20392325520515442" size="0.012357677333056927 0.0020729394163936377 0.0023386264219880104" quat="1.0 0.0 0.0 0.0"/>
        <geom class="collision" type="box" pos="0.2163982093334198 0.01477318350225687 -0.20392325520515442" size="0.0025507330428808928 0.13574707508087158 0.002338622696697712" quat="1.0 0.0 0.0 0.0"/>
        <geom class="collision" type="box" pos="0.24722640216350555 -0.11828050762414932 -0.043011587113142014" size="0.0031643868423998356 0.0026933911722153425 0.18042327463626862" quat="1.0 0.0 0.0 0.0"/>
        <geom class="collision" type="box" pos="0.24722640216350555 0.1498759388923645 -0.043011587113142014" size="0.0031643828842788935 0.0026933911722153425 0.18042303621768951" quat="1.0 0.0 0.0 0.0"/>
        <body name="door">
          <joint axis="1.0 0.0 0.0" pos="0.0003685092960949987 -0.17758384346961975 -0.245472714304924" limited="true" name="door_joint" range="0.0 1.15" type="hinge" damping="5" frictionloss="1" armature=".01" stiffness="0.05"/>
          <geom mesh="door_vis" type="mesh" solimp="0.998 0.998 0.001" solref="0.001 1" friction="0.95 0.3 0.1" class="visual" material="door_material"/>
          <geom class="collision" type="box" pos="0.0009000943973660469 -0.168915256857872 -0.052469637244939804" size="0.2612549066543579 0.004692927002906799 0.20488972961902618" quat="1.0 0.0 0.0 0.0" name="door_main"/>
          <geom class="collision" type="box" pos="0.0018851065542548895 -0.17674724757671356 -0.04527357220649719" size="0.19902880489826202 0.0031392890959978104 0.132785364985466" quat="1.0 0.0 0.0 0.0"/>
          <geom class="collision" type="box" pos="0.22110596299171448 -0.19176335632801056 0.1247517466545105" size="0.01560712605714798 0.011398117989301682 0.011398117989301682" quat="1.0 0.0 0.0 0.0"/>
          <geom class="collision" type="box" pos="-0.22049954533576965 -0.19176335632801056 0.1247517466545105" size="0.015607141889631748 0.011398130096495152 0.011398130096495152" quat="1.0 0.0 0.0 0.0"/>
          <geom class="collision" type="box" pos="0.001501724123954773 -0.20500588417053223 0.1247517466545105" size="0.0735284686088562 0.0032432442530989647 0.011398712173104286" quat="1.0 0.0 0.0 0.0" name="door_handle_main"/>
          <geom class="collision" type="box" pos="0.1457395702600479 -0.20274510979652405 0.1247517466545105" size="0.07359613478183746 0.005732421297580004 0.011398712173104286" quat="1.0 0.0 0.0 0.0"/>
          <geom class="collision" type="box" pos="-0.14361155033111572 -0.20300555229187012 0.1247517466545105" size="0.0735284686088562 0.0032432442530989647 0.011398712173104286" quat="0.999872088432312 0.0 -0.0 -0.01599567010998726"/>
          <body name="door_Clear">
            <geom mesh="door_Clear_vis" type="mesh" solimp="0.998 0.998 0.001" solref="0.001 1" friction="0.95 0.3 0.1" class="visual" material="door_Clear_material"/>
            <geom class="collision" type="box" pos="0.0018851065542548895 -0.17674724757671356 -0.04527357220649719" size="0.19902880489826202 0.0031392890959978104 0.132785364985466" quat="1.0 0.0 0.0 0.0"/>
          </body>
        </body>
        <body name="knob_temp">
          <joint axis="0.0 1.0 0.0" pos="-0.16855961084365845 -0.1892067939043045 0.21480366587638855" limited="true" name="knob_temp_joint" range="0.0 5.602506898901798" type="hinge" damping="0.05" armature="0.001" springref="-0.01"/>
          <geom mesh="knob_temp_vis" type="mesh" solimp="0.998 0.998 0.001" solref="0.001 1" friction="0.95 0.3 0.1" class="visual" material="knob_temp_material"/>
          <geom class="collision" type="cylinder" pos="-0.16874589025974274 -0.1833120882511139 0.214882954955101" size="0.014560258947312832 0.0017202203162014484" quat="0.7071067094802856 0.7071068286895752 0.0 0.0"/>
          <geom class="collision" type="box" pos="-0.1685321033000946 -0.19157104194164276 0.2150518298149109" size="0.005066616926342249 0.006823244970291853 0.012592457234859467" quat="1.0 0.0 0.0 0.0" name="knob_temp_main"/>
        </body>
        <body name="knob_time">
          <joint axis="0.0 1.0 0.0" pos="0.17643292248249054 -0.1892067939043045 0.2154439240694046" limited="true" name="knob_time_joint" range="-3.141592653589793 0.9948376736367678" type="hinge" damping="0.05" armature="0.001" springref="-0.01"/>
          <geom mesh="knob_time_vis" type="mesh" solimp="0.998 0.998 0.001" solref="0.001 1" friction="0.95 0.3 0.1" class="visual" material="knob_time_material"/>
          <geom class="collision" type="cylinder" pos="0.17623311281204224 -0.1833120882511139 0.21548950672149658" size="0.014560258947312832 0.0017202203162014484" quat="0.7071067094802856 0.7071068286895752 0.0 0.0"/>
          <geom class="collision" type="box" pos="0.17633473873138428 -0.19157104194164276 0.2150518298149109" size="0.005066616926342249 0.006823244970291853 0.012592457234859467" quat="1.0 0.0 0.0 0.0" name="knob_time_main"/>
        </body>
        <body name="rack0">
          <geom class="region" name="reg_rack0" type="box" pos="-0.0001293569803237915 0.020383965224027634 0.022574447095394135" size="0.2085575441122055 0.12269179692864418 0.11763363128900528"/>
          <joint axis="0.0 -1.0 0.0" pos="-0.0008307830430567265 0.020319785922765732 -0.1150580495595932" limited="true" name="rack0_joint" range="0.0 0.2" type="slide" damping="1" frictionloss="1" armature=".01" stiffness="0.05"/>
          <geom mesh="rack0_vis" type="mesh" solimp="0.998 0.998 0.001" solref="0.001 1" friction="0.95 0.3 0.1" class="visual" material="rack0_material"/>
          <geom class="collision" type="box" pos="-0.0006766723236069083 0.020319797098636627 -0.10297143459320068" size="0.23616035282611847 0.12719988822937012 0.0033169181551784277" quat="1.0 0.0 0.0 0.0"/>
          <geom class="collision" type="box" pos="0.18381276726722717 -0.09597183763980865 -0.11820642650127411" size="0.015721142292022705 0.000929249741602689 0.011941387318074703" quat="1.0 0.0 0.0 0.0"/>
          <geom class="collision" type="box" pos="-0.184906005859375 -0.09597183763980865 -0.11820642650127411" size="0.015721160918474197 0.000929249741602689 0.011941398493945599" quat="1.0 0.0 0.0 0.0"/>
        </body>
        <geom class="region" name="reg_int" type="box" pos="0.00027339160442352295 0.025984928011894226 -0.050483524799346924" size="0.20893291926383972 0.16298641061782837 0.19089115953445435"/>
        <geom class="region" name="reg_main" type="box" pos="-0.0004229483020026237 0.013647045008838177 1.3520306652026193e-08" size="0.26682059264183045 0.195512277841568 0.26591445302963257"/>
      </body>
    </body>
  </worldbody>
  <actuator>
    <motor name="door_joint_actuator" joint="door_joint" gear="50"/>
    <motor name="knob_temp_joint_actuator" joint="knob_temp_joint" gear="50"/>
    <motor name="knob_time_joint_actuator" joint="knob_time_joint" gear="50"/>
    <motor name="rack0_joint_actuator" joint="rack0_joint" gear="50"/>
  </actuator>
</mujoco>
