<?xml version='1.0' encoding='UTF-8'?>
<mujoco model="model">
  <option timestep="0.002" gravity="0.0 0.0 -9.81"/>
  <compiler angle="radian"/>
  <asset>
    <mesh file="visuals/handle.obj" name="handle_vis"/>
    <mesh file="visuals/Body001.obj" name="Body001_vis"/>
    <mesh file="visuals/Funnel001.obj" name="Funnel001_vis"/>
    <mesh file="visuals/Funnel002.obj" name="Funnel002_vis"/>
    <mesh file="visuals/spout.obj" name="spout_vis"/>
    <texture file="visuals/T_BC001.png" name="Body001_material" type="2d"/>
    <material name="Body001_material" rgba="1 1 1 1.0" texture="Body001_material" shininess="0.1" specular="2"/>
    <texture file="visuals/T_BC001.png" name="handle_material" type="2d"/>
    <material name="handle_material" rgba="1 1 1 1.0" texture="handle_material" shininess="-1023.0" specular="0.3103448502657381"/>
    <texture file="visuals/T_BC001.png" name="Funnel001_material" type="2d"/>
    <material name="Funnel001_material" rgba="1 1 1 1.0" texture="Funnel001_material" shininess="0.1" specular="4"/>
    <texture file="visuals/T_BC001.png" name="Funnel002_material" type="2d"/>
    <material name="Funnel002_material" rgba="1 1 1 1.0" texture="Funnel002_material" shininess="0.1" specular="4"/>
    <texture file="visuals/T_BC001.png" name="spout_material" type="2d"/>
    <material name="spout_material" rgba="1 1 1 1.0" texture="spout_material" shininess="-1023.0" specular="0.3103448502657381"/>
  </asset>
  <default>
    <default class="visual">
      <geom conaffinity="0" contype="0" group="1" type="mesh"/>
    </default>
    <default class="collision">
      <geom group="0" rgba="0.5 0 0 0.5"/>
    </default>
    <default class="spawn">
      <geom group="0" rgba="1 1 1 0.5" contype="0" conaffinity="0"/>
      <site group="0" rgba="1 1 1 0.5"/>
    </default>
    <default class="region">
      <geom group="1" conaffinity="0" contype="0" rgba="0 1 0 0"/>
    </default>
  </default>
  <worldbody>
    <body>
      <body name="object">
        <geom mesh="Body001_vis" type="mesh" solimp="0.998 0.998 0.001" solref="0.001 1" friction="0.95 0.3 0.1" class="visual" material="Body001_material"/>
        <geom class="collision" type="box" pos="0.23670988 -0.00060980 -0.04791216" size="0.16209204494953156 0.22278743982315063 0.005591025110334158" quat="1.0 0.0 0.0 0.0"/>
        <geom class="collision" type="cylinder" pos="-0.02469046 0.18437863 -0.00541452" size="0.018282365053892136 0.016813375055789948" quat="0.5 0.4999999701976776 0.5 0.5"/>
        <geom class="collision" type="cylinder" pos="-0.05109613 0.18426987 -0.00747108" size="0.020259195938706398 0.047851018607616425" quat="0.9990497827529907 0.0 0.0 0.04358314350247383"/>
        <geom class="collision" type="box" pos="-0.07542227 0.00003916 -0.12663867" size="0.012089341878890991 0.223550483584404 0.08126405626535416" quat="1.0 0.0 0.0 0.0"/>
        <geom class="collision" type="box" pos="0.00527080 -0.18073804 -0.11856291" size="0.06973908096551895 0.042737413197755814 0.07391282171010971" quat="1.0 0.0 0.0 0.0"/>
        <geom class="collision" type="box" pos="0.00527080 -0.13143561 -0.09637622" size="0.06973908096551895 0.0026383125223219395 0.05264557898044586" quat="0.9983898401260376 0.05672502517700195 0.0 0.0"/>
        <geom class="collision" type="box" pos="0.00527080 0.12864044 -0.10693872" size="0.06973908096551895 0.0026383125223219395 0.06332626193761826" quat="0.9974493384361267 -0.07137805223464966 0.0 0.0"/>
        <geom class="collision" type="box" pos="0.00527080 0.18163302 -0.11856291" size="0.06973908096551895 0.04194354638457298 0.07391265034675598" quat="1.0 0.0 0.0 0.0"/>
        <geom class="collision" type="box" pos="-0.23857894 0.18907208 -0.12344535" size="0.14949655532836914 0.002638312289491296 0.07926877588033676" quat="0.9990689158439636 -0.043143387883901596 0.0 0.0"/>
        <geom class="collision" type="box" pos="-0.24331340 0.20952461 -0.15105695" size="0.1542310118675232 0.014065057970583439 0.1064031645655632" quat="1.0 0.0 0.0 0.0"/>
        <geom class="collision" type="box" pos="-0.23857894 -0.18763717 -0.12316214" size="0.14949655532836914 0.002638312289491296 0.07926878333091736" quat="0.9984583854675293 0.05550497770309448 3.7769980803748115e-18 -2.7465182901449057e-19"/>
        <geom class="collision" type="box" pos="-0.24268528 -0.20968848 -0.15105692" size="0.15485912561416626 0.013900484889745712 0.10640312731266022" quat="1.0 0.0 0.0 0.0"/>
        <geom class="collision" type="box" pos="-0.30180554 -0.00144850 -0.23118746" size="0.0775531753897667 0.19654637575149536 0.0262719988822937" quat="1.0 0.0 0.0 0.0"/>
        <geom class="collision" type="box" pos="-0.38616783 0.00020106 -0.15141785" size="0.011722794733941555 0.22169646620750427 0.10604222863912582" quat="1.0 0.0 0.0 0.0"/>
        <geom class="collision" type="box" pos="-0.36718757 0.00079176 -0.14775291" size="0.002350295428186655 0.19769826531410217 0.10238055139780045" quat="0.9991256594657898 0.0 -0.041807886213064194 0.0"/>
        <geom class="collision" type="box" pos="-0.11670500 -0.00144850 -0.23133656" size="0.029372988268733025 0.19654637575149536 0.026122961193323135" quat="1.0 0.0 0.0 0.0"/>
        <geom class="collision" type="box" pos="-0.18465571 0.11878018 -0.23197168" size="0.040500521659851074 0.07903575897216797 0.02548784390091896" quat="1.0 0.0 0.0 0.0"/>
        <geom class="collision" type="box" pos="-0.18582716 -0.12189366 -0.23143718" size="0.04122575372457504 0.08241641521453857 0.02602284401655197" quat="1.0 0.0 0.0 0.0"/>
        <geom class="collision" type="box" pos="-0.04548515 -0.00126435 -0.16022502" size="0.014139543287456036 0.12646296620368958 0.013112707063555717" quat="1.0 0.0 0.0 0.0"/>
        <geom class="collision" type="box" pos="0.05140214 -0.00515893 -0.15966541" size="0.01209177728742361 0.044978559017181396 0.012109190225601196" quat="1.0 0.0 0.0 0.0"/>
        <geom class="collision" type="box" pos="0.01327724 0.08140714 -0.15391225" size="0.04683591052889824 0.042417895048856735 0.006276856176555157" quat="1.0 0.0 0.0 0.0"/>
        <geom class="collision" type="box" pos="0.01436195 -0.07922777 -0.15349045" size="0.046548981219530106 0.04533576965332031 0.006698658689856529" quat="1.0 0.0 0.0 0.0"/>
        <geom class="collision" type="box" pos="-0.09149786 0.00078330 -0.12651628" size="0.007510052993893623 0.19804197549819946 0.08050790429115295" quat="0.9981808066368103 0.0 0.06029169261455536 0.0"/>
        <geom class="collision" type="box" pos="0.07223516 0.00106131 -0.10861724" size="0.007510052062571049 0.2208782583475113 0.06595868617296219" quat="0.9981808066368103 0.0 0.06029169261455536 0.0"/>
        <geom class="collision" type="box" pos="-0.05886271 0.00078330 -0.09674533" size="0.0012203236110508442 0.14010055363178253 0.054632414132356644" quat="0.9985798597335815 0.0 -0.05327498912811279 0.0"/>
        <geom class="collision" type="box" pos="0.00008770 0.21480292 -0.04151143" size="0.40047717094421387 0.007950956001877785 0.003980221226811409" quat="1.0 0.0 0.0 0.0"/>
        <geom class="collision" type="box" pos="-0.00002723 -0.21457759 -0.04151143" size="0.4004419147968292 0.008779192343354225 0.003980221226811409" quat="1.0 0.0 0.0 0.0"/>
        <geom class="collision" type="box" pos="-0.39194978 -0.00062166 -0.04151143" size="0.008455842733383179 0.20691721141338348 0.003980293404310942" quat="1.0 0.0 0.0 0.0"/>
        <geom class="collision" type="box" pos="0.39128979 -0.00062162 -0.04151143" size="0.008395257405936718 0.20691721141338348 0.003980282694101334" quat="1.0 0.0 0.0 0.0"/>
        <geom class="collision" type="box" pos="0.00527080 0.00086008 -0.18351416" size="0.06973908096551895 0.14008310437202454 0.008961565792560577" quat="1.0 0.0 0.0 0.0"/>
        <geom class="collision" type="box" pos="-0.18501400 -0.00442859 -0.24538176" size="0.039277613162994385 0.04429144784808159 0.004517825786024332" quat="1.0 0.0 0.0 0.0"/>
        <geom class="collision" type="box" pos="-0.21945454 0.03320457 -0.21335998" size="0.0077866483479738235 0.01505254115909338 0.004746152553707361" quat="0.9355807900428772 0.0 -0.0 -0.35311275720596313"/>
        <geom class="collision" type="box" pos="-0.21863602 -0.03221463 -0.21335998" size="0.007786647416651249 0.01505254115909338 0.004746152553707361" quat="0.9381937980651855 0.0 0.0 0.34611037373542786"/>
        <geom class="collision" type="box" pos="-0.15310965 0.03237374 -0.21335998" size="0.007786647416651249 0.01505254115909338 0.004746152553707361" quat="0.9381937980651855 0.0 0.0 0.34611037373542786"/>
        <geom class="collision" type="box" pos="-0.15419618 -0.03285781 -0.21335998" size="0.0077866483479738235 0.01505254115909338 0.004746152553707361" quat="0.9355807900428772 0.0 -0.0 -0.35311275720596313"/>
        <geom class="collision" type="box" pos="-0.02687940 0.03069607 -0.15218110" size="0.0077866483479738235 0.01505254115909338 0.004746152553707361" quat="0.9355807900428772 0.0 -0.0 -0.35311275720596313"/>
        <geom class="collision" type="box" pos="0.03643595 -0.03217261 -0.15218110" size="0.0077866483479738235 0.01505254115909338 0.004746152553707361" quat="0.9355807900428772 0.0 -0.0 -0.35311275720596313"/>
        <geom class="collision" type="box" pos="0.03424314 0.03468773 -0.15218110" size="0.0077866483479738235 0.01505254115909338 0.004746152553707361" quat="0.9161313772201538 0.0 0.0 0.4008781909942627"/>
        <geom class="collision" type="box" pos="-0.02919467 -0.03071806 -0.15218110" size="0.0077866483479738235 0.01505254115909338 0.004746152553707361" quat="0.9573758840560913 0.0 0.0 0.2888449430465698"/>
        <body name="handle">
          <joint axis="1.0 0.0 0.0" pos="0.01191097 0.18467748 -0.00550503" limited="true" name="handle_temp_joint" type="hinge" range="-0.7853981633974483 0.7853981633974483" damping="1" frictionloss="1" armature=".01"/>
          <joint axis="0.0 1.0 0.0" pos="0.01191097 0.18467748 -0.00550503" limited="true" name="handle_joint" type="hinge" range="0 0.5" damping="1" frictionloss="1" armature=".01"/>
          <geom mesh="handle_vis" type="mesh" solimp="0.998 0.998 0.001" solref="0.001 1" friction="0.95 0.3 0.1" class="visual" material="handle_material"/>
          <geom class="collision" type="cylinder" pos="0.02044635 0.18483601 -0.00541452" size="0.01856803148984909 0.014965763315558434" quat="0.5 0.4999999701976776 0.5 0.5" density="0.001"/>
          <geom class="collision" type="cylinder" pos="0.00636543 0.18437863 -0.00541452" size="0.01044311560690403 0.002668767236173153" quat="0.5 0.4999999701976776 0.5 0.5" density="0.001"/>
          <geom class="collision" type="cylinder" pos="0.01906048 0.18462793 0.04046518" size="0.0043233647011220455 0.02681279182434082" quat="1.0 0.0 0.0 0.0" density="0.001"/>
        </body>
        <body name="Funnel001">
          <joint axis="0.0 0.0 1.0" pos="-0.18503589 -0.00003510 -0.21897011" limited="true" name="Funnel001_joint" range="0.0 0.3" type="slide" damping="0" frictionloss="0" armature="0" stiffness="0"/>
          <geom mesh="Funnel001_vis" type="mesh" solimp="0.998 0.998 0.001" solref="0.001 1" friction="0.95 0.3 0.1" class="visual" material="Funnel001_material"/>
          <geom class="collision" type="cylinder" pos="-0.18458488 0.00005870 -0.21786107" size="0.03602096065878868 0.0008388549904339015" quat="1.0 0.0 0.0 0.0"/>
          <geom class="collision" type="cylinder" pos="-0.18518324 0.00005870 -0.21777080" size="0.014919627457857132 0.00391645822674036" quat="1.0 0.0 0.0 0.0"/>
        </body>
        <body name="Funnel002">
          <joint axis="0.0 0.0 1.0" pos="0.00452456 0.00058985 -0.15720591" limited="true" name="Funnel002_joint" range="0.0 0.3" type="slide" damping="0" frictionloss="0" armature="0" stiffness="0"/>
          <geom mesh="Funnel002_vis" type="mesh" solimp="0.998 0.998 0.001" solref="0.001 1" friction="0.95 0.3 0.1" class="visual" material="Funnel002_material"/>
          <geom class="collision" type="cylinder" pos="0.00418160 0.00089222 -0.15743731" size="0.03342888504266739 0.0018126824870705605" quat="1.0 0.0 0.0 0.0"/>
          <geom class="collision" type="cylinder" pos="0.00459823 0.00044574 -0.15603814" size="0.014739518985152245 0.004046990070492029" quat="1.0 0.0 0.0 0.0"/>
        </body>
        <body name="spout">
          <joint axis="0.0 0.0 1.0" pos="-0.05146552 0.18482775 0.13828491" limited="true" name="spout_joint" range="-0.7853981633974483 0.7853981633974483" type="hinge" damping="1" frictionloss="1" armature=".01" stiffness="0.05"/>
          <site type="cylinder" rgba="0.5 0.75 1 0.5" size="0.0060607255436480045 0.17275060713291168" pos="-0.13199584 0.03861545 -0.02676252" name="water"/>
          <geom mesh="spout_vis" type="mesh" solimp="0.998 0.998 0.001" solref="0.001 1" friction="0.95 0.3 0.1" class="visual" material="spout_material"/>
          <geom class="collision" type="cylinder" pos="-0.05109613 0.18426987 0.10782514" size="0.010071869939565659 0.06765434145927429" quat="0.9990497827529907 0.0 0.0 0.04358314350247383"/>
          <geom class="collision" type="cylinder" pos="-0.05616848 0.17468436 0.20623840" size="0.00965795572847128 0.013342335820198059" quat="0.9196361303329468 0.16925090551376343 -0.19007854163646698 0.29915493726730347"/>
          <geom class="collision" type="cylinder" pos="-0.06676484 0.15893758 0.22841702" size="0.010738730430603027 0.014835407957434654" quat="0.8670938014984131 0.2554492652416229 -0.30630964040756226 0.2984432876110077"/>
          <geom class="collision" type="cylinder" pos="-0.07931789 0.13524030 0.24280737" size="0.010424953885376453 0.0144019341096282" quat="0.755740761756897 0.35412755608558655 -0.47815293073654175 0.2735312283039093"/>
          <geom class="collision" type="cylinder" pos="-0.09468217 0.10820958 0.24692099" size="0.010484162718057632 0.016757162287831306" quat="0.6666451692581177 0.44615498185157776 -0.546674907207489 0.24015936255455017"/>
          <geom class="collision" type="cylinder" pos="-0.11042153 0.08023166 0.23883243" size="0.011186142452061176 0.017792953178286552" quat="0.48275741934776306 0.5455015301704407 -0.6670209765434265 0.15638543665409088"/>
          <geom class="collision" type="cylinder" pos="-0.12116082 0.05757057 0.21907827" size="0.010224497877061367 0.016100460663437843" quat="0.31250452995300293 0.6214025020599365 -0.7136070728302002 0.08345532417297363" name="spout_main"/>
          <geom class="collision" type="cylinder" pos="-0.12882037 0.04181876 0.18920147" size="0.01005901675671339 0.01656615175306797" quat="0.10936148464679718 0.6737759113311768 -0.7270243167877197 0.07417364418506622"/>
          <geom class="collision" type="cylinder" pos="-0.13081978 0.03844295 0.15513280" size="0.0089662941172719 0.01852126605808735" quat="-0.006637726444751024 0.6839892268180847 -0.7293778657913208 0.011073256842792034"/>
          <geom class="collision" type="cylinder" pos="-0.05287620 0.18099231 0.18917209" size="0.009657956659793854 0.013342335820198059" quat="0.9186800122261047 0.09213677048683167 -0.16663409769535065 0.34607934951782227"/>
        </body>
        <geom class="region" name="reg_basin_left" type="box" pos="-0.232503175 -0.00027899000000000673 -0.118821335" size="0.12060432500000001 0.17198626 0.083069845"/>
        <geom class="region" name="reg_basin_right" type="box" pos="0.0029324150000000007 -0.0007398500000000002 -0.08934986" size="0.051864845 0.11667115 0.05388074000000001"/>
        <geom class="region" name="reg_main" type="box" pos="-4.999999997368221e-09 -3.999999999976245e-07 -0.14749558499999998" size="0.40167416499999997 0.2245893 0.110964465"/>
      </body>
    </body>
  </worldbody>
  <actuator>
    <motor name="handle_joint_actuator" joint="handle_joint" gear="10"/>
    <motor name="handle_temp_joint_actuator" joint="handle_temp_joint" gear="10"/>
    <motor name="Funnel001_joint_actuator" joint="Funnel001_joint" gear="10"/>
    <motor name="Funnel002_joint_actuator" joint="Funnel002_joint" gear="10"/>
    <motor name="spout_joint_actuator" joint="spout_joint" gear="10"/>
  </actuator>
</mujoco>
