<?xml version='1.0' encoding='UTF-8'?>
<mujoco model="model">
  <option timestep="0.002" gravity="0.0 0.0 -9.81"/>
  <compiler angle="radian"/>
  <asset>
    <mesh file="visuals/handle.obj" name="handle_vis"/>
    <mesh file="visuals/Body001.obj" name="Body001_vis"/>
    <mesh file="visuals/spout.obj" name="spout_vis"/>
    <texture file="visuals/T_BC001.png" name="Body001_material" type="2d"/>
    <material name="Body001_material" rgba="1 1 1 1.0" texture="Body001_material" shininess="0.1" specular="2"/>
    <texture file="visuals/T_BC001.png" name="handle_material" type="2d"/>
    <material name="handle_material" rgba="1 1 1 1.0" texture="handle_material" shininess="-1023.0" specular="0.3103448502657381"/>
    <texture file="visuals/T_BC001.png" name="spout_material" type="2d"/>
    <material name="spout_material" rgba="1 1 1 1.0" texture="spout_material" shininess="-1023.0" specular="0.3103448502657381"/>
  </asset>
  <default>
    <default class="visual">
      <geom conaffinity="0" contype="0" group="1" type="mesh"/>
    </default>
    <default class="collision">
      <geom group="0" rgba="0.5 0 0 0.5"/>
    </default>
    <default class="spawn">
      <geom group="0" rgba="1 1 1 0.5" contype="0" conaffinity="0"/>
      <site group="0" rgba="1 1 1 0.5"/>
    </default>
    <default class="region">
      <geom group="1" conaffinity="0" contype="0" rgba="0 1 0 0"/>
    </default>
  </default>
  <worldbody>
    <body>
      <body name="object">
        <geom mesh="Body001_vis" type="mesh" solimp="0.998 0.998 0.001" solref="0.001 1" friction="0.95 0.3 0.1" class="visual" material="Body001_material"/>
        <geom class="collision" type="box" pos="0.23670988 -0.00060930 -0.04762416" size="0.16209204494953156 0.22278743982315063 0.005591041874140501" quat="1.0 0.0 0.0 0.0"/>
        <geom class="collision" type="cylinder" pos="-0.02469046 0.18437913 -0.00512652" size="0.018282365053892136 0.016813375055789948" quat="0.5 0.4999999701976776 0.5 0.5"/>
        <geom class="collision" type="cylinder" pos="-0.05109613 0.18427037 -0.00718308" size="0.020259195938706398 0.047851018607616425" quat="0.9990497827529907 0.0 0.0 0.043583158403635025"/>
        <geom class="collision" type="box" pos="-0.07542227 0.00003966 -0.12635067" size="0.012089341878890991 0.223550483584404 0.08126430958509445" quat="1.0 0.0 0.0 0.0"/>
        <geom class="collision" type="box" pos="0.00527080 -0.18073754 -0.11827491" size="0.06973908096551895 0.042737413197755814 0.07391305267810822" quat="1.0 0.0 0.0 0.0"/>
        <geom class="collision" type="box" pos="0.00527080 -0.13143511 -0.09608822" size="0.06973908096551895 0.0026383125223219395 0.05264557898044586" quat="0.9983898401260376 0.05672502517700195 0.0 0.0"/>
        <geom class="collision" type="box" pos="0.00527080 0.12864094 -0.10665072" size="0.06973908096551895 0.0026383125223219395 0.06332626193761826" quat="0.9974493384361267 -0.07137805223464966 0.0 0.0"/>
        <geom class="collision" type="box" pos="0.00527080 0.18163352 -0.11827491" size="0.06973908096551895 0.04194354638457298 0.07391286641359329" quat="1.0 0.0 0.0 0.0"/>
        <geom class="collision" type="box" pos="-0.23857894 0.18907258 -0.12315735" size="0.14949655532836914 0.002638312289491296 0.07926877588033676" quat="0.9990689158439636 -0.043143387883901596 0.0 0.0"/>
        <geom class="collision" type="box" pos="-0.24331340 0.20952511 -0.15076895" size="0.1542310118675232 0.014065057970583439 0.1064031645655632" quat="1.0 0.0 0.0 0.0"/>
        <geom class="collision" type="box" pos="-0.23857894 -0.18763667 -0.12287414" size="0.14949655532836914 0.002638312289491296 0.07926878333091736" quat="0.9984583854675293 0.05550500005483627 3.7769997347360366e-18 -2.7465200996024956e-19"/>
        <geom class="collision" type="box" pos="-0.24268528 -0.20968798 -0.15076892" size="0.15485912561416626 0.013900484889745712 0.10640312731266022" quat="1.0 0.0 0.0 0.0"/>
        <geom class="collision" type="box" pos="-0.38616783 0.00020156 -0.15112985" size="0.011722794733941555 0.22169646620750427 0.10604238510131836" quat="1.0 0.0 0.0 0.0"/>
        <geom class="collision" type="box" pos="-0.36718757 0.00079226 -0.14746491" size="0.002350295428186655 0.19769826531410217 0.10238055139780045" quat="0.9991256594657898 0.0 -0.041807886213064194 0.0"/>
        <geom class="collision" type="box" pos="-0.23512405 -0.00144800 -0.23104856" size="0.1477920264005661 0.19654637575149536 0.026122910901904106" quat="1.0 0.0 0.0 0.0"/>
        <geom class="collision" type="box" pos="0.00225436 -0.00126385 -0.15993702" size="0.061879049986600876 0.12646277248859406 0.013112707063555717" quat="1.0 0.0 0.0 0.0"/>
        <geom class="collision" type="box" pos="-0.09149786 0.00078380 -0.12622828" size="0.007510052993893623 0.19804197549819946 0.08050790429115295" quat="0.9981808066368103 0.0 0.06029169261455536 0.0"/>
        <geom class="collision" type="box" pos="0.07223516 0.00106181 -0.10832924" size="0.007510052062571049 0.2208782583475113 0.06595868617296219" quat="0.9981808066368103 0.0 0.06029169261455536 0.0"/>
        <geom class="collision" type="box" pos="-0.05886271 0.00078380 -0.09645733" size="0.0012203236110508442 0.14010055363178253 0.054632414132356644" quat="0.9985798597335815 0.0 -0.05327498912811279 0.0"/>
        <geom class="collision" type="box" pos="0.00008770 0.21480342 -0.04122343" size="0.40047717094421387 0.007950956001877785 0.003980221226811409" quat="1.0 0.0 0.0 0.0"/>
        <geom class="collision" type="box" pos="-0.00002723 -0.21457709 -0.04122343" size="0.4004419147968292 0.008779192343354225 0.003980221226811409" quat="1.0 0.0 0.0 0.0"/>
        <geom class="collision" type="box" pos="-0.39194978 -0.00062116 -0.04122343" size="0.008455842733383179 0.20691721141338348 0.0039802975952625275" quat="1.0 0.0 0.0 0.0"/>
        <geom class="collision" type="box" pos="0.39128979 -0.00062112 -0.04122343" size="0.008395257405936718 0.20691721141338348 0.003980285953730345" quat="1.0 0.0 0.0 0.0"/>
        <geom class="collision" type="box" pos="0.00527080 0.00086058 -0.18322616" size="0.06973908096551895 0.14008310437202454 0.00896157044917345" quat="1.0 0.0 0.0 0.0"/>
        <geom class="collision" type="box" pos="-0.18501400 -0.00442809 -0.24509376" size="0.03927760198712349 0.04429144039750099 0.004517825320363045" quat="1.0 0.0 0.0 0.0"/>
        <body name="handle">
          <joint axis="1.0 0.0 0.0" pos="0.01191097 0.18467798 -0.00521703" limited="true" name="handle_temp_joint" type="hinge" range="-0.7853981633974483 0.7853981633974483" damping="1" frictionloss="1" armature=".01" stiffness="0.05"/>
          <joint axis="0.0 1.0 0.0" pos="0.01191097 0.18467798 -0.00521703" limited="true" name="handle_joint" type="hinge" range="0 0.5" damping="1" frictionloss="1" armature=".01" stiffness="0.05"/>
          <geom mesh="handle_vis" type="mesh" solimp="0.998 0.998 0.001" solref="0.001 1" friction="0.95 0.3 0.1" class="visual" material="handle_material"/>
          <geom class="collision" type="cylinder" pos="0.02044635 0.18483651 -0.00512652" size="0.01856803148984909 0.014965763315558434" quat="0.5 0.4999999701976776 0.5 0.5"/>
          <geom class="collision" type="cylinder" pos="0.00636543 0.18437913 -0.00512652" size="0.01044311560690403 0.002668767236173153" quat="0.5 0.4999999701976776 0.5 0.5"/>
          <geom name="handle_main" class="collision" type="cylinder" pos="0.01906048 0.18462843 0.04075318" size="0.0043233647011220455 0.02681279182434082" quat="1.0 0.0 0.0 0.0"/>
        </body>
        <body name="spout">
          <joint axis="0.0 0.0 1.0" pos="-0.05146552 0.18482825 0.13857291" limited="true" name="spout_joint" range="-0.7853981633974483 0.7853981633974483" type="hinge" damping="1" frictionloss="1" armature=".01" stiffness="0.05"/>
          <site type="cylinder" rgba="0.5 0.75 1 0.5" size="0.0060607255436480045 0.17275060713291168" pos="-0.13199584 0.03861595 -0.02647452" name="water"/>
          <geom mesh="spout_vis" type="mesh" solimp="0.998 0.998 0.001" solref="0.001 1" friction="0.95 0.3 0.1" class="visual" material="spout_material"/>
          <geom class="collision" type="cylinder" pos="-0.05109613 0.18427037 0.10811314" size="0.010071869939565659 0.06765434145927429" quat="0.9990497827529907 0.0 0.0 0.043583158403635025" name="spout_main"/>
          <geom class="collision" type="cylinder" pos="-0.05616848 0.17468486 0.20652640" size="0.00965795572847128 0.013342335820198059" quat="0.9196361303329468 0.16925090551376343 -0.19007854163646698 0.29915493726730347"/>
          <geom class="collision" type="cylinder" pos="-0.06676484 0.15893808 0.22870502" size="0.010738730430603027 0.014835407957434654" quat="0.8670938014984131 0.2554492652416229 -0.30630964040756226 0.2984432876110077"/>
          <geom class="collision" type="cylinder" pos="-0.07931789 0.13524080 0.24309537" size="0.010424953885376453 0.0144019341096282" quat="0.755740761756897 0.35412755608558655 -0.47815293073654175 0.2735312283039093"/>
          <geom class="collision" type="cylinder" pos="-0.09468217 0.10821008 0.24720899" size="0.010484162718057632 0.016757162287831306" quat="0.6666451692581177 0.44615498185157776 -0.546674907207489 0.24015936255455017"/>
          <geom class="collision" type="cylinder" pos="-0.11042153 0.08023216 0.23912043" size="0.011186142452061176 0.017792953178286552" quat="0.48275741934776306 0.5455014705657959 -0.6670209765434265 0.15638543665409088"/>
          <geom class="collision" type="cylinder" pos="-0.12116082 0.05757107 0.21936627" size="0.010224497877061367 0.016100460663437843" quat="0.31250452995300293 0.6214025020599365 -0.7136070728302002 0.08345532417297363"/>
          <geom class="collision" type="cylinder" pos="-0.12882037 0.04181926 0.18948947" size="0.01005901675671339 0.01656615175306797" quat="0.10936148464679718 0.6737759113311768 -0.7270243167877197 0.07417364418506622"/>
          <geom class="collision" type="cylinder" pos="-0.13081978 0.03844345 0.15542080" size="0.0089662941172719 0.01852126605808735" quat="-0.006637726444751024 0.6839892268180847 -0.7293778657913208 0.011073256842792034"/>
          <geom class="collision" type="cylinder" pos="-0.05287620 0.18099281 0.18946009" size="0.009657956659793854 0.013342335820198059" quat="0.9186800122261047 0.09213677048683167 -0.16663409769535065 0.34607934951782227"/>
        </body>
        <geom class="region" name="reg_basin_left" type="box" pos="-0.232503175 -0.00027848999999999235 -0.11853333499999999" size="0.12060432500000001 0.17198626 0.083069845"/>
        <geom class="region" name="reg_basin_right" type="box" pos="0.0029324150000000007 -0.0007393499999999997 -0.08906185999999999" size="0.051864845 0.11667115 0.05388074"/>
        <geom class="region" name="reg_main" type="box" pos="-4.999999997368221e-09 1.0000000000287557e-07 -0.147207585" size="0.40167416499999997 0.2245893 0.110964465"/>
      </body>
    </body>
  </worldbody>
  <actuator>
    <motor name="handle_joint_actuator" joint="handle_joint" gear="10"/>
    <motor name="handle_temp_joint_actuator" joint="handle_temp_joint" gear="10"/>
    <motor name="spout_joint_actuator" joint="spout_joint" gear="10"/>
  </actuator>
</mujoco>
