<?xml version='1.0' encoding='UTF-8'?>
<mujoco model="model">
  <option timestep="0.002" gravity="0.0 0.0 -9.81"/>
  <compiler angle="radian"/>
  <asset>
    <mesh file="visuals/freezer0.obj" name="freezer0_vis"/>
    <mesh file="visuals/freezer1.obj" name="freezer1_vis"/>
    <mesh file="visuals/freezer2.obj" name="freezer2_vis"/>
    <mesh file="visuals/fridge_drawer0.obj" name="fridge_drawer0_vis"/>
    <mesh file="visuals/fridge_left_door.obj" name="fridge_left_door_vis"/>
    <mesh file="visuals/fridge_left_door_Clear.obj" name="fridge_left_door_Clear_vis"/>
    <mesh file="visuals/fridge_right_door.obj" name="fridge_right_door_vis"/>
    <mesh file="visuals/fridge_right_door_Clear.obj" name="fridge_right_door_Clear_vis"/>
    <mesh file="visuals/Body001.obj" name="Body001_vis"/>
    <mesh file="visuals/Body001_Clear.obj" name="Body001_Clear_vis"/>
    <texture file="visuals/T_BC001.png" name="Body001_material" type="2d"/>
    <material name="Body001_material" rgba="1 1 1 1.0" texture="Body001_material" shininess="0.5" specular="1"/>
    <texture file="visuals/T_BC001.png" name="freezer0_material" type="2d"/>
    <material name="freezer0_material" rgba="1 1 1 1.0" texture="freezer0_material" shininess="0.5" specular="1"/>
    <texture file="visuals/T_BC001.png" name="freezer1_material" type="2d"/>
    <material name="freezer1_material" rgba="1 1 1 1.0" texture="freezer1_material" shininess="0.5" specular="1"/>
    <texture file="visuals/T_BC001.png" name="freezer2_material" type="2d"/>
    <material name="freezer2_material" rgba="1 1 1 1.0" texture="freezer2_material" shininess="0.5" specular="1"/>
    <texture file="visuals/T_BC001.png" name="fridge_drawer0_material" type="2d"/>
    <material name="fridge_drawer0_material" rgba="1 1 1 1.0" texture="fridge_drawer0_material" shininess="0.5" specular="0.3103448502657381"/>
    <texture file="visuals/T_BC001.png" name="fridge_left_door_material" type="2d"/>
    <material name="fridge_left_door_material" rgba="1 1 1 1.0" texture="fridge_left_door_material" shininess="0.5" specular="1"/>
    <texture file="visuals/T_BC001.png" name="fridge_left_door_Clear_material" type="2d"/>
    <material name="fridge_left_door_Clear_material" rgba="1 1 1 0.699999988079071" texture="fridge_left_door_Clear_material" shininess="0.5" specular="0.3103448502657381"/>
    <texture file="visuals/T_BC001.png" name="fridge_right_door_material" type="2d"/>
    <material name="fridge_right_door_material" rgba="1 1 1 1.0" texture="fridge_right_door_material" shininess="0.5" specular="1"/>
    <texture file="visuals/T_BC001.png" name="fridge_right_door_Clear_material" type="2d"/>
    <material name="fridge_right_door_Clear_material" rgba="1 1 1 0.699999988079071" texture="fridge_right_door_Clear_material" shininess="0.5" specular="0.3103448502657381"/>
    <texture file="visuals/T_BC001.png" name="Body001_Clear_material" type="2d"/>
    <material name="Body001_Clear_material" rgba="1 1 1 0.699999988079071" texture="Body001_Clear_material" shininess="0.5" specular="0.3103448502657381"/>
  </asset>
  <default>
    <default class="visual">
      <geom conaffinity="0" contype="0" group="1" type="mesh"/>
    </default>
    <default class="collision">
      <geom group="0" rgba="0.5 0 0 0.5"/>
    </default>
    <default class="spawn">
      <geom group="0" rgba="1 1 1 0.5" contype="0" conaffinity="0"/>
      <site group="0" rgba="1 1 1 0.5"/>
    </default>
    <default class="region">
      <geom group="1" conaffinity="0" contype="0" rgba="0 1 0 0"/>
    </default>
  </default>
  <worldbody>
    <body>
      <body name="object">
        <geom mesh="Body001_vis" type="mesh" solimp="0.998 0.998 0.001" solref="0.001 1" friction="0.95 0.3 0.1" class="visual" material="Body001_material"/>
        <geom class="collision" type="box" pos="-0.00013399665476754308 0.06447411328554153 -0.0886266827583313" size="0.3999479413032532 0.3867715299129486 0.0470595583319664" quat="1.0 0.0 0.0 0.0"/>
        <geom class="collision" type="box" pos="-0.00013399665476754308 0.08992300927639008 -0.4449865221977234" size="0.3999479413032532 0.36132264137268066 0.04415065795183182" quat="1.0 0.0 0.0 0.0"/>
        <geom class="collision" type="box" pos="-0.00013399665476754308 0.08992300927639008 -0.6705933809280396" size="0.3999479413032532 0.36140090227127075 0.036733899265527725" quat="1.0 0.0 0.0 0.0"/>
        <geom class="collision" type="box" pos="-0.00013435666915029287 0.07528030872344971 -0.9536763429641724" size="0.43175753951072693 0.37888437509536743 0.016284508630633354" quat="1.0 0.0 0.0 0.0"/>
        <geom class="collision" type="box" pos="-0.00013366535131353885 0.07527303695678711 0.944145917892456" size="0.4317586421966553 0.3789542317390442 0.028293505311012268" quat="1.0 0.0 0.0 0.0"/>
        <geom class="collision" type="box" pos="-0.41002967953681946 0.07527482509613037 -0.002807188080623746" size="0.021927762776613235 0.37895575165748596 0.9624706506729126" quat="1.0 0.0 0.0 0.0"/>
        <geom class="collision" type="box" pos="0.40976184606552124 0.07527221739292145 -0.0028071862179785967" size="0.0219277236610651 0.37895312905311584 0.9624706506729126" quat="1.0 0.0 0.0 0.0"/>
        <geom class="collision" type="box" pos="-0.00013399665476754308 0.4272623658180237 -0.006178800016641617" size="0.3999081254005432 0.026964757591485977 0.9433217644691467" quat="1.0 0.0 0.0 0.0"/>
        <geom class="collision" type="box" pos="-5.065973527962342e-05 0.08187665790319443 0.6061820387840271" size="0.33722153306007385 0.27503347396850586 0.0030499768909066916" quat="1.0 0.0 0.0 0.0"/>
        <geom class="collision" type="box" pos="-5.0662893045227975e-05 0.08229579776525497 0.28636524081230164" size="0.33722150325775146 0.27461498975753784 0.0030499135609716177" quat="1.0 0.0 0.0 0.0"/>
        <geom class="collision" type="box" pos="-0.0009399434784427285 -0.021683931350708008 0.27292436361312866" size="0.0038265313487499952 0.1539125293493271 0.008033503778278828" quat="1.0 0.0 0.0 0.0"/>
        <geom class="collision" type="box" pos="-0.0009399201953783631 0.2594670057296753 0.25017231702804565" size="0.0038265520706772804 0.1272384077310562 0.03078554943203926" quat="1.0 0.0 0.0 0.0"/>
        <geom class="collision" type="box" pos="0.32965287566185 -0.021683931350708008 0.27292436361312866" size="0.003826610278338194 0.1539125293493271 0.008033503778278828" quat="1.0 0.0 0.0 0.0"/>
        <geom class="collision" type="box" pos="0.32965287566185 0.2594670057296753 0.25017231702804565" size="0.0038265895564109087 0.1272384077310562 0.03078554943203926" quat="1.0 0.0 0.0 0.0"/>
        <geom class="collision" type="box" pos="-0.33032265305519104 -0.021683931350708008 0.27292436361312866" size="0.0038265646435320377 0.1539125293493271 0.008033503778278828" quat="1.0 0.0 0.0 0.0"/>
        <geom class="collision" type="box" pos="-0.33032262325286865 0.2594670057296753 0.25017231702804565" size="0.0038265991024672985 0.1272384077310562 0.03078554943203926" quat="1.0 0.0 0.0 0.0"/>
        <geom class="collision" type="box" pos="-0.00093989132437855 -0.021683931350708008 0.5920451879501343" size="0.0038266184274107218 0.1539125293493271 0.008033503778278828" quat="1.0 0.0 0.0 0.0"/>
        <geom class="collision" type="box" pos="-0.0009399170521646738 0.2594670057296753 0.569293200969696" size="0.003826627740636468 0.1272384077310562 0.03078554943203926" quat="1.0 0.0 0.0 0.0"/>
        <geom class="collision" type="box" pos="0.32965287566185 -0.021683931350708008 0.5920451879501343" size="0.003826649161055684 0.1539125293493271 0.008033503778278828" quat="1.0 0.0 0.0 0.0"/>
        <geom class="collision" type="box" pos="0.32965287566185 0.2594670057296753 0.569293200969696" size="0.0038266496267169714 0.1272384077310562 0.03078554943203926" quat="1.0 0.0 0.0 0.0"/>
        <geom class="collision" type="box" pos="-0.33032262325286865 -0.021683931350708008 0.5920451879501343" size="0.003826639847829938 0.1539125293493271 0.008033503778278828" quat="1.0 0.0 0.0 0.0"/>
        <geom class="collision" type="box" pos="-0.33032265305519104 0.2594670057296753 0.569293200969696" size="0.0038266184274107218 0.1272384077310562 0.03078554943203926" quat="1.0 0.0 0.0 0.0"/>
        <body name="freezer0">
          <geom class="region" name="reg_freezer0" type="box" pos="0.00010037422180175781 0.0012854933738708496 -0.8189382553100586" size="0.34329305386543274 0.2959751913547516 0.07477606630325317"/>
          <joint axis="0.0 -1.0 0.0" pos="-6.583333015441895e-05 -0.07093723118305206 -0.815532386302948" limited="true" name="freezer0_door_joint" range="0.0 0.5" type="slide" damping="1" frictionloss="1" armature=".01" stiffness="0.05"/>
          <geom mesh="freezer0_vis" type="mesh" solimp="0.998 0.998 0.001" solref="0.001 1" friction="0.95 0.3 0.1" class="visual" material="freezer0_material"/>
          <geom class="collision" type="box" pos="-0.00013399665476754308 -0.35537487268447876 -0.8095715045928955" size="0.42000454664230347 0.02528861165046692 0.14819277822971344" quat="1.0 0.0 0.0 0.0"/>
          <geom class="collision" type="box" pos="0.00020126614253968 0.0025204368866980076 -0.8990223407745361" size="0.35140591859817505 0.3098565340042114 0.0009697779314592481" quat="1.0 0.0 0.0 0.0"/>
          <geom class="collision" type="box" pos="-6.612413562834263e-05 0.3104879856109619 -0.819580614566803" size="0.35164567828178406 0.0018648114055395126 0.08040610700845718" quat="1.0 0.0 0.0 0.0"/>
          <geom class="collision" type="box" pos="0.35014593601226807 0.002522309310734272 -0.8194289207458496" size="0.0014610412763431668 0.30980774760246277 0.08056319504976273" quat="1.0 0.0 0.0 0.0"/>
          <geom class="collision" type="box" pos="-0.3502781391143799 0.002522238064557314 -0.8194288611412048" size="0.0014610099606215954 0.30980852246284485 0.0805632472038269" quat="1.0 0.0 0.0 0.0"/>
          <geom class="collision" type="cylinder" pos="0.23993445932865143 -0.4070470333099365 -0.6995123624801636" size="0.008121767081320286 0.03666220232844353" quat="0.5 0.5 0.4999999701976776 -0.5" name="freezer0_door_handle_2"/>
          <geom class="collision" type="cylinder" pos="-0.2377200722694397 -0.4070470333099365 -0.6995123624801636" size="0.007529731839895248 0.033989716321229935" quat="0.5 0.5 0.4999999701976776 -0.5" name="freezer0_door_handle_1"/>
          <geom class="collision" type="cylinder" pos="0.0008210699306800961 -0.440376341342926 -0.6994198560714722" size="0.014790027402341366 0.25877222418785095" quat="0.7071068286895752 -0.0 0.7071067690849304 0.0" name="freezer0_door_handle_main"/>
          <geom class="collision" type="box" pos="-0.00013399665476754308 -0.3731548488140106 -0.8095715045928955" size="0.42000454664230347 0.007508635986596346 0.14819277822971344" quat="1.0 0.0 0.0 0.0" name="freezer0_door_main"/>
          <geom class="collision" type="box" pos="-0.0007377916481345892 -0.30778127908706665 -0.8198358416557312" size="0.35056930780410767 0.007508635986596346 0.0823802500963211" quat="1.0 0.0 0.0 0.0"/>
        </body>
        <body name="freezer1">
          <geom class="region" name="reg_freezer1" type="box" pos="0.00010037422180175781 0.0007288306951522827 -0.5593092739582062" size="0.34329305386543274 0.295418528676033 0.04807631468772888"/>
          <joint axis="0.0 -1.0 0.0" pos="-6.522797048091888e-05 -0.07093720138072968 -0.5496818423271179" limited="true" name="freezer1_door_joint" range="0.0 0.5" type="slide" damping="1" frictionloss="1" armature=".01" stiffness="0.05"/>
          <geom mesh="freezer1_vis" type="mesh" solimp="0.998 0.998 0.001" solref="0.001 1" friction="0.95 0.3 0.1" class="visual" material="freezer1_material"/>
          <geom class="collision" type="box" pos="-0.00013399665476754308 -0.3564911484718323 -0.5496636033058167" size="0.42000454664230347 0.028597764670848846 0.09995020925998688" quat="1.0 0.0 0.0 0.0"/>
          <geom class="collision" type="box" pos="0.00020226230844855309 0.0020770179107785225 -0.6152252554893494" size="0.3513733446598053 0.31024885177612305 0.0005310800042934716" quat="1.0 0.0 0.0 0.0"/>
          <geom class="collision" type="box" pos="0.00020118302199989557 0.3104879856109619 -0.5601717829704285" size="0.3514058589935303 0.0018649663543328643 0.05559072270989418" quat="1.0 0.0 0.0 0.0"/>
          <geom class="collision" type="box" pos="0.35014572739601135 0.002076992765069008 -0.5601726770401001" size="0.0014612486120313406 0.3102502226829529 0.05558044835925102" quat="1.0 0.0 0.0 0.0"/>
          <geom class="collision" type="box" pos="-0.3502781391143799 0.002076918724924326 -0.560171902179718" size="0.001461076084524393 0.31025102734565735 0.05558130890130997" quat="1.0 0.0 0.0 0.0"/>
          <geom class="collision" type="cylinder" pos="0.000821079418528825 -0.440376341342926 -0.48796892166137695" size="0.0140595817938447 0.25877225399017334" quat="0.7071068286895752 -0.0 0.7071067690849304 0.0" name="freezer1_door_handle_main"/>
          <geom class="collision" type="cylinder" pos="-0.2377200722694397 -0.4070470333099365 -0.4880024790763855" size="0.007502472028136253 0.03386666253209114" quat="0.5 0.5 0.4999999701976776 -0.5" name="freezer1_door_handle_1"/>
          <geom class="collision" type="cylinder" pos="0.23993445932865143 -0.4070470333099365 -0.4880024790763855" size="0.0083658741787076 0.03776412084698677" quat="0.5 0.5 0.4999999701976776 -0.5" name="freezer1_door_handle_2"/>
          <geom class="collision" type="box" pos="-0.00013399665476754308 -0.3731115460395813 -0.5496636033058167" size="0.42000454664230347 0.011977366171777248 0.09994330257177353" quat="1.0 0.0 0.0 0.0" name="freezer1_door_main"/>
          <geom class="collision" type="box" pos="-0.00028097856556996703 -0.3117515444755554 -0.5599279403686523" size="0.35102614760398865 0.011977366171777248 0.05586544796824455" quat="1.0 0.0 0.0 0.0"/>
        </body>
        <body name="freezer2">
          <geom class="region" name="reg_freezer2" type="box" pos="0.00010037422180175781 0.0007288306951522827 -0.26996050775051117" size="0.34329305386543274 0.295418528676033 0.09268212115764618"/>
          <joint axis="0.0 -1.0 0.0" pos="-6.613595178350806e-05 -0.07093724608421326 -0.254861056804657" limited="true" name="freezer2_door_joint" range="0.0 0.5" type="slide" damping="1" frictionloss="1" armature=".01" stiffness="0.05"/>
          <geom mesh="freezer2_vis" type="mesh" solimp="0.998 0.998 0.001" solref="0.001 1" friction="0.95 0.3 0.1" class="visual" material="freezer2_material"/>
          <geom class="collision" type="box" pos="-0.00013399665476754308 -0.3565518260002136 -0.25507447123527527" size="0.419242799282074 0.028595970943570137 0.18303528428077698" quat="1.0 0.0 0.0 0.0"/>
          <geom class="collision" type="box" pos="-0.0015341822290793061 0.002073821146041155 -0.37368839979171753" size="0.34967049956321716 0.3103087246417999 0.000969756452832371" quat="1.0 0.0 0.0 0.0"/>
          <geom class="collision" type="box" pos="0.00020239735022187233 0.31048789620399475 -0.2740156352519989" size="0.35137051343917847 0.0018647989491000772 0.10063576698303223" quat="1.0 0.0 0.0 0.0"/>
          <geom class="collision" type="box" pos="0.3501459062099457 0.002077206037938595 -0.2731657922267914" size="0.0014610732905566692 0.3102470934391022 0.10149236768484116" quat="1.0 0.0 0.0 0.0"/>
          <geom class="collision" type="box" pos="-0.3502781391143799 0.00207709614187479 -0.2734798192977905" size="0.001461076783016324 0.31024783849716187 0.10117834061384201" quat="1.0 0.0 0.0 0.0"/>
          <geom class="collision" type="cylinder" pos="0.23993445932865143 -0.4070470333099365 -0.13443587720394135" size="0.007350651081651449 0.033181332051754" quat="0.5 0.5 0.4999999701976776 -0.5" name="freezer2_door_handle_2"/>
          <geom class="collision" type="cylinder" pos="-0.2377200722694397 -0.4070470333099365 -0.13443587720394135" size="0.007350651081651449 0.033181332051754" quat="0.5 0.5 0.4999999701976776 -0.5" name="freezer2_door_handle_1"/>
          <geom class="collision" type="cylinder" pos="0.0008211028762161732 -0.440376341342926 -0.13434341549873352" size="0.013850869610905647 0.25877225399017334" quat="0.7071068286895752 -0.0 0.7071067690849304 0.0" name="freezer2_door_handle_main"/>
          <geom class="collision" type="box" pos="-0.00013399665476754308 -0.3741771876811981 -0.25507447123527527" size="0.4192579984664917 0.010971879586577415 0.18304795026779175" quat="1.0 0.0 0.0 0.0" name="freezer2_door_main"/>
          <geom class="collision" type="box" pos="-7.019043550826609e-06 -0.31047993898391724 -0.2721339464187622" size="0.3501594662666321 0.010414138436317444 0.10111083090305328" quat="1.0 0.0 0.0 0.0"/>
        </body>
        <body name="fridge_drawer0">
          <geom class="region" name="reg_fridge_drawer0" type="box" pos="0.002929896116256714 0.10004615783691406 0.07945136446505785" size="0.22513897514343262 0.2645689675807953 0.09988372104614973"/>
          <joint axis="0.0 -1.0 0.0" pos="0.002504657953977585 0.09708143770694733 0.0759696364402771" limited="true" name="fridge_drawer0_joint" range="0.0 0.5" type="slide" damping="1" frictionloss="1" armature=".01" stiffness="0.05"/>
          <geom mesh="fridge_drawer0_vis" type="mesh" solimp="0.998 0.998 0.001" solref="0.001 1" friction="0.95 0.3 0.1" class="visual" material="fridge_drawer0_material"/>
          <geom class="collision" type="box" pos="0.21386530995368958 -0.18348529934883118 0.14336903393268585" size="0.030655859038233757 0.00422917865216732 0.041308920830488205" quat="1.0 0.0 0.0 0.0"/>
          <geom class="collision" type="box" pos="-0.20805875957012177 -0.1834852695465088 0.14336903393268585" size="0.033260006457567215 0.004229210317134857 0.04130912199616432" quat="1.0 0.0 0.0 0.0"/>
          <geom class="collision" type="box" pos="0.0016013744752854109 -0.18348529934883118 0.03527094051241875" size="0.2424848973751068 0.004229214508086443 0.07027726620435715" quat="1.0 0.0 0.0 0.0"/>
          <geom class="collision" type="box" pos="0.002677417127415538 -0.18425938487052917 0.1789802461862564" size="0.24173784255981445 0.00500309094786644 0.008780845440924168" quat="1.0 0.0 0.0 0.0"/>
          <geom class="collision" type="box" pos="-0.2355773150920868 0.10171693563461304 0.0775151401758194" size="0.005487506277859211 0.28084343671798706 0.11023811250925064" quat="1.0 0.0 0.0 0.0"/>
          <geom class="collision" type="box" pos="0.24040058255195618 0.10102833062410355 0.0775151401758194" size="0.004412728827446699 0.2807350158691406 0.110238216817379" quat="1.0 0.0 0.0 0.0"/>
          <geom class="collision" type="box" pos="0.001488185254856944 0.10091280937194824 -0.031191881746053696" size="0.24263273179531097 0.28054341673851013 0.00440264493227005" quat="1.0 0.0 0.0 0.0"/>
          <geom class="collision" type="box" pos="0.0032178673427551985 0.3781997263431549 0.0764784961938858" size="0.24227656424045563 0.004624526482075453 0.10920175909996033" quat="1.0 0.0 0.0 0.0"/>
        </body>
        <body name="fridge_left_door">
          <joint axis="0.0 0.0 -1.0" pos="-0.39066505432128906 -0.3538122773170471 0.44921910762786865" limited="true" name="fridge_left_door_joint" range="0.0 1.5707963267948966" type="hinge" damping="1" frictionloss="1" armature=".01" stiffness="0.05"/>
          <geom mesh="fridge_left_door_vis" type="mesh" solimp="0.998 0.998 0.001" solref="0.001 1" friction="0.95 0.3 0.1" class="visual" material="fridge_left_door_material"/>
          <geom class="collision" type="box" pos="-0.21446019411087036 -0.2671769857406616 0.31673663854599" size="0.14336563646793365 0.0571720264852047 0.0037615143228322268" quat="1.0 0.0 0.0 0.0"/>
          <geom class="collision" type="box" pos="-0.21446019411087036 -0.3326944410800934 0.3526189923286438" size="0.14335346221923828 0.0046825832687318325 0.039373692125082016" quat="1.0 0.0 0.0 0.0"/>
          <geom class="collision" type="box" pos="-0.21446019411087036 -0.21211181581020355 0.3493254780769348" size="0.14336563646793365 0.004683000035583973 0.03478723764419556" quat="1.0 0.0 0.0 0.0"/>
          <geom class="collision" type="box" pos="-0.07370350509881973 -0.26717692613601685 0.35360556840896606" size="0.003901515621691942 0.05717901512980461 0.03991582244634628" quat="1.0 0.0 0.0 0.0"/>
          <geom class="collision" type="box" pos="-0.35507452487945557 -0.26717692613601685 0.3529898524284363" size="0.0039015235379338264 0.05717901512980461 0.03991582617163658" quat="1.0 0.0 0.0 0.0"/>
          <geom class="collision" type="box" pos="-0.2144598811864853 -0.2648744583129883 0.6741377115249634" size="0.14336563646793365 0.05717332661151886 0.0037615748587995768" quat="1.0 0.0 0.0 0.0"/>
          <geom class="collision" type="box" pos="-0.2144598811864853 -0.3326944410800934 0.7100199460983276" size="0.14335577189922333 0.004682662431150675 0.03937489911913872" quat="1.0 0.0 0.0 0.0"/>
          <geom class="collision" type="box" pos="-0.2144598811864853 -0.2098092883825302 0.7067265510559082" size="0.14336563646793365 0.004683000035583973 0.03478723764419556" quat="1.0 0.0 0.0 0.0"/>
          <geom class="collision" type="box" pos="-0.07370318472385406 -0.2648743987083435 0.7110066413879395" size="0.003901595715433359 0.05717901512980461 0.039915814995765686" quat="1.0 0.0 0.0 0.0"/>
          <geom class="collision" type="box" pos="-0.3550742268562317 -0.2648743987083435 0.7103908658027649" size="0.003901603864505887 0.05717901512980461 0.03991582244634628" quat="1.0 0.0 0.0 0.0"/>
          <geom class="collision" type="box" pos="-0.2022995948791504 -0.35299602150917053 0.4509809613227844" size="0.18996977806091309 0.028667094185948372 0.5130335688591003" quat="1.0 0.0 0.0 0.0"/>
          <geom class="collision" type="box" pos="-0.2022995948791504 -0.3696701228618622 0.4509809613227844" size="0.18996977806091309 0.011994974687695503 0.5130335688591003" quat="1.0 0.0 0.0 0.0" name="fridge_left_door_main"/>
          <geom class="collision" type="cylinder" pos="-0.04111017659306526 -0.4068422019481659 0.6293106079101562" size="0.007803468964993954 0.02586364932358265" quat="1.0677025841232535e-07 9.30011547373849e-14 0.7071068286895752 -0.7071067094802856" name="fridge_left_door_handle_1"/>
          <geom class="collision" type="cylinder" pos="-0.04111017659306526 -0.4068422019481659 0.032748203724622726" size="0.007803468964993954 0.02586364932358265" quat="1.0677025841232535e-07 9.30011547373849e-14 0.7071068286895752 -0.7071067094802856" name="fridge_left_door_handle_2"/>
          <geom class="collision" type="cylinder" pos="-0.04101753234863281 -0.43140700459480286 0.33132824301719666" size="0.013910680077970028 0.3180851638317108" quat="7.549789415861596e-08 -6.71794140316706e-08 1.0 6.717942113709796e-08" name="fridge_left_door_handle_main"/>
          <body name="fridge_left_door_Clear">
            <geom mesh="fridge_left_door_Clear_vis" type="mesh" solimp="0.998 0.998 0.001" solref="0.001 1" friction="0.95 0.3 0.1" class="visual" material="fridge_left_door_Clear_material"/>
            <geom class="collision" type="box" pos="-0.21446019411087036 -0.2671769857406616 0.31673663854599" size="0.14336563646793365 0.0571720264852047 0.0037615143228322268" quat="1.0 0.0 0.0 0.0"/>
            <geom class="collision" type="box" pos="-0.21446019411087036 -0.3326944410800934 0.3526189923286438" size="0.14335346221923828 0.0046825832687318325 0.039373692125082016" quat="1.0 0.0 0.0 0.0"/>
            <geom class="collision" type="box" pos="-0.21446019411087036 -0.21211181581020355 0.3493254780769348" size="0.14336563646793365 0.004683000035583973 0.03478723764419556" quat="1.0 0.0 0.0 0.0"/>
            <geom class="collision" type="box" pos="-0.07370350509881973 -0.26717692613601685 0.35360556840896606" size="0.003901515621691942 0.05717901512980461 0.03991582244634628" quat="1.0 0.0 0.0 0.0"/>
            <geom class="collision" type="box" pos="-0.35507452487945557 -0.26717692613601685 0.3529898524284363" size="0.0039015235379338264 0.05717901512980461 0.03991582617163658" quat="1.0 0.0 0.0 0.0"/>
            <geom class="collision" type="box" pos="-0.2144598811864853 -0.2648744583129883 0.6741377115249634" size="0.14336563646793365 0.05717332661151886 0.0037615748587995768" quat="1.0 0.0 0.0 0.0"/>
            <geom class="collision" type="box" pos="-0.2144598811864853 -0.3326944410800934 0.7100199460983276" size="0.14335577189922333 0.004682662431150675 0.03937489911913872" quat="1.0 0.0 0.0 0.0"/>
            <geom class="collision" type="box" pos="-0.2144598811864853 -0.2098092883825302 0.7067265510559082" size="0.14336563646793365 0.004683000035583973 0.03478723764419556" quat="1.0 0.0 0.0 0.0"/>
            <geom class="collision" type="box" pos="-0.07370318472385406 -0.2648743987083435 0.7110066413879395" size="0.003901595715433359 0.05717901512980461 0.039915814995765686" quat="1.0 0.0 0.0 0.0"/>
            <geom class="collision" type="box" pos="-0.3550742268562317 -0.2648743987083435 0.7103908658027649" size="0.003901603864505887 0.05717901512980461 0.03991582244634628" quat="1.0 0.0 0.0 0.0"/>
          </body>
        </body>
        <body name="fridge_right_door">
          <joint axis="0.0 0.0 1.0" pos="0.3962591290473938 -0.3573495149612427 0.44921910762786865" limited="true" name="fridge_right_door_joint" range="0.0 1.5707963267948966" type="hinge" damping="1" frictionloss="1" armature=".01" stiffness="0.05"/>
          <geom mesh="fridge_right_door_vis" type="mesh" solimp="0.998 0.998 0.001" solref="0.001 1" friction="0.95 0.3 0.1" class="visual" material="fridge_right_door_material"/>
          <geom class="collision" type="box" pos="0.21565814316272736 -0.2608833312988281 0.6741378307342529" size="0.14336563646793365 0.05717137083411217 0.0037614840548485518" quat="1.0 0.0 0.0 0.0"/>
          <geom class="collision" type="box" pos="0.21565814316272736 -0.33385661244392395 0.7100200653076172" size="0.14335229992866516 0.004682543687522411 0.03937308117747307" quat="1.0 0.0 0.0 0.0"/>
          <geom class="collision" type="box" pos="0.21565814316272736 -0.20581822097301483 0.7067265510559082" size="0.14336563646793365 0.004683000035583973 0.03478723764419556" quat="1.0 0.0 0.0 0.0"/>
          <geom class="collision" type="box" pos="0.3564148545265198 -0.2608833312988281 0.711006760597229" size="0.00390147534199059 0.05717901512980461 0.03991582244634628" quat="1.0 0.0 0.0 0.0"/>
          <geom class="collision" type="box" pos="0.07504381239414215 -0.2608833312988281 0.7103910446166992" size="0.003901483491063118 0.05717901512980461 0.03991582244634628" quat="1.0 0.0 0.0 0.0"/>
          <geom class="collision" type="box" pos="0.21565814316272736 -0.2669946551322937 0.31673672795295715" size="0.14336563646793365 0.057172682136297226 0.0037615445908159018" quat="1.0 0.0 0.0 0.0"/>
          <geom class="collision" type="box" pos="0.21565814316272736 -0.3338566720485687 0.35261908173561096" size="0.1433546096086502 0.004682622849941254 0.03937429562211037" quat="1.0 0.0 0.0 0.0"/>
          <geom class="collision" type="box" pos="0.21565814316272736 -0.2119295448064804 0.34932559728622437" size="0.14336563646793365 0.004683000035583973 0.03478723764419556" quat="1.0 0.0 0.0 0.0"/>
          <geom class="collision" type="box" pos="0.356414794921875 -0.2669945955276489 0.3536056876182556" size="0.0039015556685626507 0.05717901512980461 0.03991582244634628" quat="1.0 0.0 0.0 0.0"/>
          <geom class="collision" type="box" pos="0.07504381239414215 -0.2669945955276489 0.35298991203308105" size="0.003901563584804535 0.05717901512980461 0.03991582617163658" quat="1.0 0.0 0.0 0.0"/>
          <geom class="collision" type="box" pos="0.2065921276807785 -0.3537568151950836 0.4509809613227844" size="0.18996977806091309 0.028667185455560684 0.5130335688591003" quat="1.0 0.0 0.0 0.0"/>
          <geom class="collision" type="cylinder" pos="0.04520506039261818 -0.4068422019481659 0.6293106079101562" size="0.007803468964993954 0.02586364932358265" quat="1.0677025841232535e-07 9.30011547373849e-14 0.7071068286895752 -0.7071067094802856" name="fridge_right_door_handle_1"/>
          <geom class="collision" type="cylinder" pos="0.04520506039261818 -0.4068422019481659 0.032748203724622726" size="0.007803468964993954 0.02586364932358265" quat="1.0677025841232535e-07 9.30011547373849e-14 0.7071068286895752 -0.7071067094802856" name="fridge_right_door_handle_2"/>
          <geom class="collision" type="cylinder" pos="0.04529770463705063 -0.43140700459480286 0.33132824301719666" size="0.013910680077970028 0.3180851638317108" quat="7.549789415861596e-08 -6.71794140316706e-08 1.0 6.717942113709796e-08" name="fridge_right_door_handle_main"/>
          <geom class="collision" type="box" pos="0.2065921276807785 -0.37296539545059204 0.4509809613227844" size="0.18996977806091309 0.009460550732910633 0.5130335688591003" quat="1.0 0.0 0.0 0.0" name="fridge_right_door_main"/>
          <body name="fridge_right_door_Clear">
            <geom mesh="fridge_right_door_Clear_vis" type="mesh" solimp="0.998 0.998 0.001" solref="0.001 1" friction="0.95 0.3 0.1" class="visual" material="fridge_right_door_Clear_material"/>
            <geom class="collision" type="box" pos="0.21565814316272736 -0.2608833312988281 0.6741378307342529" size="0.14336563646793365 0.05717137083411217 0.0037614840548485518" quat="1.0 0.0 0.0 0.0"/>
            <geom class="collision" type="box" pos="0.21565814316272736 -0.33385661244392395 0.7100200653076172" size="0.14335229992866516 0.004682543687522411 0.03937308117747307" quat="1.0 0.0 0.0 0.0"/>
            <geom class="collision" type="box" pos="0.21565814316272736 -0.20581822097301483 0.7067265510559082" size="0.14336563646793365 0.004683000035583973 0.03478723764419556" quat="1.0 0.0 0.0 0.0"/>
            <geom class="collision" type="box" pos="0.3564148545265198 -0.2608833312988281 0.711006760597229" size="0.00390147534199059 0.05717901512980461 0.03991582244634628" quat="1.0 0.0 0.0 0.0"/>
            <geom class="collision" type="box" pos="0.07504381239414215 -0.2608833312988281 0.7103910446166992" size="0.003901483491063118 0.05717901512980461 0.03991582244634628" quat="1.0 0.0 0.0 0.0"/>
            <geom class="collision" type="box" pos="0.21565814316272736 -0.2669946551322937 0.31673672795295715" size="0.14336563646793365 0.057172682136297226 0.0037615445908159018" quat="1.0 0.0 0.0 0.0"/>
            <geom class="collision" type="box" pos="0.21565814316272736 -0.3338566720485687 0.35261908173561096" size="0.1433546096086502 0.004682622849941254 0.03937429562211037" quat="1.0 0.0 0.0 0.0"/>
            <geom class="collision" type="box" pos="0.21565814316272736 -0.2119295448064804 0.34932559728622437" size="0.14336563646793365 0.004683000035583973 0.03478723764419556" quat="1.0 0.0 0.0 0.0"/>
            <geom class="collision" type="box" pos="0.356414794921875 -0.2669945955276489 0.3536056876182556" size="0.0039015556685626507 0.05717901512980461 0.03991582244634628" quat="1.0 0.0 0.0 0.0"/>
            <geom class="collision" type="box" pos="0.07504381239414215 -0.2669945955276489 0.35298991203308105" size="0.003901563584804535 0.05717901512980461 0.03991582617163658" quat="1.0 0.0 0.0 0.0"/>
          </body>
        </body>
        <body name="Body001_Clear">
          <geom mesh="Body001_Clear_vis" type="mesh" solimp="0.998 0.998 0.001" solref="0.001 1" friction="0.95 0.3 0.1" class="visual" material="Body001_Clear_material"/>
          <geom class="collision" type="box" pos="-5.065973527962342e-05 0.08187665790319443 0.6061820387840271" size="0.33722153306007385 0.27503347396850586 0.0030499768909066916" quat="1.0 0.0 0.0 0.0"/>
          <geom class="collision" type="box" pos="-5.0662893045227975e-05 0.08229579776525497 0.28636524081230164" size="0.33722150325775146 0.27461498975753784 0.0030499135609716177" quat="1.0 0.0 0.0 0.0"/>
        </body>
        <geom class="region" name="reg_fridge_shelf1" type="box" pos="0.0008389204740524292 0.08273360133171082 0.762322723865509" size="0.33195161616802216 0.26890401339530945 0.1480535397529602"/>
        <geom class="region" name="reg_fridge_shelf0" type="box" pos="-0.0004532039165496826 0.08294907212257385 0.4126630574464798" size="0.33065949177742004 0.26844207739830017 0.1187280992269516"/>
        <geom class="region" name="reg_main" type="box" pos="-7.450580596923828e-09 0.02913828194141388 0.0" size="0.4329606423377991 0.42608891224861145 0.9734394083023071"/>
      </body>
    </body>
  </worldbody>
  <actuator>
    <motor name="freezer0_door_joint_actuator" joint="freezer0_door_joint" gear="50"/>
    <motor name="freezer1_door_joint_actuator" joint="freezer1_door_joint" gear="50"/>
    <motor name="freezer2_door_joint_actuator" joint="freezer2_door_joint" gear="50"/>
    <motor name="fridge_drawer0_joint_actuator" joint="fridge_drawer0_joint" gear="50"/>
    <motor name="fridge_left_door_joint_actuator" joint="fridge_left_door_joint" gear="50"/>
    <motor name="fridge_right_door_joint_actuator" joint="fridge_right_door_joint" gear="50"/>
  </actuator>
</mujoco>
