<?xml version='1.0' encoding='UTF-8'?>
<mujoco model="model">
  <option timestep="0.002" gravity="0.0 0.0 -9.81"/>
  <compiler angle="radian"/>
  <asset>
    <mesh file="visuals/door.obj" name="door_vis"/>
    <mesh file="visuals/door_Clear.obj" name="door_Clear_vis"/>
    <mesh file="visuals/Body001.obj" name="Body001_vis"/>
    <mesh file="visuals/Disc001.obj" name="Disc001_vis"/>
    <texture file="visuals/T_BC001.png" name="Body001_material" type="2d"/>
    <material name="Body001_material" rgba="1 1 1 1.0" texture="Body001_material" shininess="0.4472135901451111" specular="0.5"/>
    <texture file="visuals/T_BC001.png" name="door_material" type="2d"/>
    <material name="door_material" rgba="1 1 1 1.0" texture="door_material" shininess="0.4472135901451111" specular="0.5"/>
    <material name="door_Clear_material" rgba="0.15626506507396698 0.15626506507396698 0.15626506507396698 0.699999988079071" shininess="0.4472135901451111" specular="0.3103448502657381"/>
    <texture file="visuals/T_BC001.png" name="Disc001_material" type="2d"/>
    <material name="Disc001_material" rgba="1 1 1 1.0" texture="Disc001_material" shininess="0.4472135901451111" specular="0.3103448502657381"/>
  </asset>
  <default>
    <default class="visual">
      <geom conaffinity="0" contype="0" group="1" type="mesh"/>
    </default>
    <default class="collision">
      <geom group="0" rgba="0.5 0 0 0.5"/>
    </default>
    <default class="spawn">
      <geom group="0" rgba="1 1 1 0.5" contype="0" conaffinity="0"/>
      <site group="0" rgba="1 1 1 0.5"/>
    </default>
    <default class="region">
      <geom group="1" conaffinity="0" contype="0" rgba="0 1 0 0"/>
    </default>
  </default>
  <worldbody>
    <body>
      <body name="object">
        <geom class="collision" type="cylinder" pos="-0.00488904 -0.01272559 -0.12117022" size="0.15272502601146698 0.0017746438970789313" quat="1.0 0.0 0.0 0.0" name="tray" rgba="0 1 0 0.5"/>
        <geom class="collision" type="box" pos="0.26505053 -0.21284153 -0.12445283" size="0.014366177842020988 0.000769797305110842 0.01334370207041502" quat="1.0 0.0 0.0 0.0" name="stop_button" rgba="0.0 0.5 0 0.5"/>
        <geom class="collision" type="box" pos="0.20863220 -0.21284153 -0.12470591" size="0.014642727561295033 0.0007697980618104339 0.013612133450806141" quat="1.0 0.0 0.0 0.0" name="start_button" rgba="0.0 0.5 0 0.5"/>
        <geom mesh="Body001_vis" type="mesh" solimp="0.998 0.998 0.001" solref="0.001 1" friction="0.95 0.3 0.1" class="visual" material="Body001_material"/>
        <geom class="collision" type="box" pos="0.00022452 0.21556661 0.00195000" size="0.2843378782272339 0.023882132023572922 0.15333765745162964" quat="1.0 0.0 0.0 0.0"/>
        <geom class="collision" type="box" pos="-0.24260980 0.00965590 0.00372144" size="0.041503578424453735 0.20020213723182678 0.15156620740890503" quat="1.0 0.0 0.0 0.0"/>
        <geom class="collision" type="box" pos="0.22390804 0.00897172 0.00337590" size="0.06065431982278824 0.1993701159954071 0.15191176533699036" quat="1.0 0.0 0.0 0.0"/>
        <geom class="collision" type="box" pos="-0.05128234 0.00906298 0.14960418" size="0.22826983034610748 0.19998085498809814 0.005683446768671274" quat="1.0 0.0 0.0 0.0"/>
        <geom class="collision" type="box" pos="-0.05162154 0.00064078 -0.14206440" size="0.22826983034610748 0.19134223461151123 0.006302667781710625" quat="1.0 0.0 0.0 0.0"/>
        <geom class="collision" type="box" pos="0.23655933 -0.19828415 0.00371492" size="0.04786551743745804 0.012290961109101772 0.152129665017128" quat="1.0 0.0 0.0 0.0"/>
        <geom class="collision" type="box" pos="-0.04321811 0.24391250 0.00400957" size="0.20306691527366638 0.002654001582413912 0.1391487866640091" quat="1.0 0.0 0.0 0.0"/>
        <geom class="collision" type="box" pos="0.23369126 0.01649758 -0.15050511" size="0.021882038563489914 0.20807993412017822 0.005352536216378212" quat="1.0 0.0 0.0 0.0"/>
        <geom class="collision" type="box" pos="-0.22992377 0.01649758 -0.15050511" size="0.021882038563489914 0.20807993412017822 0.005352542735636234" quat="1.0 0.0 0.0 0.0"/>
        <geom class="collision" type="box" pos="-0.25150034 -0.20093538 0.00392083" size="0.03274006396532059 0.009257613681256771 0.15176571905612946" quat="1.0 0.0 0.0 0.0"/>
        <body name="door">
          <joint axis="0.0 0.0 1.0" pos="-0.20478417 -0.20020254 0.00938616" limited="true" name="microjoint" range="-1.5707963267948966 0.0" type="hinge" damping="1" frictionloss="1" armature=".01" stiffness="0.05"/>
          <geom mesh="door_vis" type="mesh" solimp="0.998 0.998 0.001" solref="0.001 1" friction="0.95 0.3 0.1" class="visual" material="door_material"/>
          <geom class="collision" type="box" pos="-0.00457589 -0.20070133 0.00471165" size="0.19244207441806793 0.009490731172263622 0.14833500981330872" quat="1.0 0.0 0.0 0.0"/>
          <geom class="collision" type="box" pos="-0.00446908 -0.19849996 0.00441974" size="0.1926005482673645 0.005018194671720266 0.1278620958328247" quat="1.0 0.0 0.0 0.0"/>
          <geom class="collision" type="box" pos="0.16236411 -0.24132748 0.00146638" size="0.014240493066608906 0.005890222266316414 0.10606895387172699" quat="1.0 0.0 0.0 0.0" name="door_handle_main"/>
          <geom class="collision" type="box" pos="0.16241534 -0.23755424 0.12476714" size="0.013812358491122723 0.006593006197363138 0.012758745811879635" quat="0.972201943397522 -0.2341439425945282 0.0 0.0"/>
          <geom class="collision" type="box" pos="0.16241534 -0.22180322 0.13282467" size="0.013812358491122723 0.012901995331048965 0.006874673068523407" quat="1.0 0.0 0.0 0.0"/>
          <geom class="collision" type="box" pos="0.16241534 -0.23527494 -0.12196973" size="0.013812358491122723 0.0065930066630244255 0.012758745811879635" quat="0.2628830671310425 -0.9648277163505554 0.0 0.0"/>
          <geom class="collision" type="box" pos="0.16241534 -0.22180322 -0.12715862" size="0.013812358491122723 0.012901995331048965 0.006874673999845982" quat="1.0 0.0 0.0 0.0"/>
          <geom class="collision" type="box" pos="-0.00457589 -0.20800541 0.00471165" size="0.19244268536567688 0.00218672095797956 0.14833538234233856" quat="1.0 0.0 0.0 0.0" name="door_main"/>
          <body name="door_Clear">
            <geom mesh="door_Clear_vis" type="mesh" solimp="0.998 0.998 0.001" solref="0.001 1" friction="0.95 0.3 0.1" class="visual" material="door_Clear_material"/>
            <geom class="collision" type="box" pos="-0.00446908 -0.19849996 0.00441974" size="0.1926005482673645 0.005018194671720266 0.1278620958328247" quat="1.0 0.0 0.0 0.0"/>
          </body>
        </body>
        <body name="Disc001">
          <joint axis="0.0 0.0 1.0" pos="-0.00632300 -0.01359365 -0.11086820" limited="false" name="Disc001_joint" range="0 360" type="hinge" damping="1" frictionloss="1" armature=".01" stiffness="0.05"/>
          <geom mesh="Disc001_vis" type="mesh" solimp="0.998 0.998 0.001" solref="0.001 1" friction="0.95 0.3 0.1" class="visual" material="Disc001_material"/>
          <geom class="collision" type="cylinder" pos="-0.00589897 -0.01519557 -0.12682248" size="0.14966647326946259 0.00367545522749424" quat="1.0 0.0 0.0 0.0"/>
        </body>
        <geom class="region" name="reg_int" type="box" pos="-0.02034387 0.001866409999999999 0.008076979999999997" size="0.17272071 0.18256681000000002 0.12847255000000002"/>
        <geom class="region" name="reg_main" type="box" pos="0.0 0.017995709999999998 1.5000000000431335e-07" size="0.28556241 0.22957082 0.15685783"/>
      </body>
    </body>
  </worldbody>
  <actuator>
    <motor name="microjoint_actuator" joint="microjoint" gear="10"/>
    <motor name="Disc001_joint_actuator" joint="Disc001_joint" gear="10"/>
  </actuator>
</mujoco>
