<?xml version='1.0' encoding='UTF-8'?>
<mujoco model="model">
  <option timestep="0.002" gravity="0.0 0.0 -9.81"/>
  <compiler angle="radian"/>
  <asset>
    <mesh file="visuals/handle.obj" name="handle_vis"/>
    <mesh file="visuals/Body001.obj" name="Body001_vis"/>
    <mesh file="visuals/Funnel001.obj" name="Funnel001_vis"/>
    <mesh file="visuals/Funnel002.obj" name="Funnel002_vis"/>
    <mesh file="visuals/spout.obj" name="spout_vis"/>
    <texture file="visuals/T_BC001.png" name="Body001_material" type="2d"/>
    <material name="Body001_material" rgba="1 1 1 1.0" texture="Body001_material" shininess="0.5" specular="0.5"/>
    <texture file="visuals/T_BC001.png" name="handle_material" type="2d"/>
    <material name="handle_material" rgba="1 1 1 1.0" texture="handle_material" shininess="1" specular="1"/>
    <texture file="visuals/T_BC001.png" name="Funnel001_material" type="2d"/>
    <material name="Funnel001_material" rgba="1 1 1 1.0" texture="Funnel001_material" shininess="3" specular="3"/>
    <texture file="visuals/T_BC001.png" name="Funnel002_material" type="2d"/>
    <material name="Funnel002_material" rgba="1 1 1 1.0" texture="Funnel002_material" shininess="3" specular="3"/>
    <texture file="visuals/T_BC001.png" name="spout_material" type="2d"/>
    <material name="spout_material" rgba="1 1 1 1.0" texture="spout_material" shininess="1" specular="1"/>
  </asset>
  <default>
    <default class="visual">
      <geom conaffinity="0" contype="0" group="1" type="mesh"/>
    </default>
    <default class="collision">
      <geom group="0" rgba="0.5 0 0 0.5"/>
    </default>
    <default class="spawn">
      <geom group="0" rgba="1 1 1 0.5" contype="0" conaffinity="0"/>
      <site group="0" rgba="1 1 1 0.5"/>
    </default>
    <default class="region">
      <geom group="1" conaffinity="0" contype="0" rgba="0 1 0 0"/>
    </default>
  </default>
  <worldbody>
    <body>
      <body name="object">
        <geom mesh="Body001_vis" type="mesh" solimp="0.998 0.998 0.001" solref="0.001 1" friction="0.95 0.3 0.1" class="visual" material="Body001_material"/>
        <geom class="collision" type="box" pos="-0.46896427869796753 -0.023084159940481186 -0.17865459620952606" size="0.017832264304161072 0.191153883934021 0.13331298530101776" quat="1.0 0.0 0.0 0.0"/>
        <geom class="collision" type="box" pos="-0.0005250170361250639 -0.02308417111635208 -0.1443372368812561" size="0.015185253694653511 0.19115479290485382 0.09899568557739258" quat="1.0 0.0 0.0 0.0"/>
        <geom class="collision" type="box" pos="0.4699346721172333 -0.023084159940481186 -0.14980769157409668" size="0.01686198078095913 0.19115403294563293 0.10446613281965256" quat="1.0 0.0 0.0 0.0"/>
        <geom class="collision" type="box" pos="6.440677680075169e-08 0.20663128793239594 -0.17865455150604248" size="0.48679661750793457 0.0403938926756382 0.13331300020217896" quat="1.0 0.0 0.0 0.0"/>
        <geom class="collision" type="box" pos="4.0105078369379044e-08 -0.2305738776922226 -0.17865455150604248" size="0.48679661750793457 0.016451485455036163 0.13331295549869537" quat="1.0 0.0 0.0 0.0"/>
        <geom class="collision" type="box" pos="0.00044145656283944845 -0.025442227721214294 -0.28128746151924133" size="0.18996965885162354 0.18879622220993042 0.030680136755108833" quat="1.0 0.0 0.0 0.0"/>
        <geom class="collision" type="box" pos="0.3819931149482727 -0.025442227721214294 -0.28128740191459656" size="0.10480355471372604 0.1887962967157364 0.03068007528781891" quat="1.0 0.0 0.0 0.0"/>
        <geom class="collision" type="box" pos="-0.3629124164581299 -0.025442227721214294 -0.28128743171691895" size="0.08718343079090118 0.18879637122154236 0.030680106952786446" quat="1.0 0.0 0.0 0.0"/>
        <geom class="collision" type="box" pos="-0.23297733068466187 -0.10285942256450653 -0.28128743171691895" size="0.041802000254392624 0.11137925088405609 0.030680106952786446" quat="1.0 0.0 0.0 0.0"/>
        <geom class="collision" type="box" pos="-0.23297733068466187 0.13056351244449615 -0.28128743171691895" size="0.041802018880844116 0.03260359913110733 0.030680106952786446" quat="1.0 0.0 0.0 0.0"/>
        <geom class="collision" type="box" pos="0.23444999754428864 0.13022543489933014 -0.28128746151924133" size="0.04180203750729561 0.032941680401563644 0.030680136755108833" quat="1.0 0.0 0.0 0.0"/>
        <geom class="collision" type="box" pos="0.23445001244544983 -0.10195980966091156 -0.28128740191459656" size="0.0418020561337471 0.11227908730506897 0.03068007528781891" quat="1.0 0.0 0.0 0.0"/>
        <geom class="collision" type="cylinder" pos="-0.2331215888261795 0.053658485412597656 -0.30111947655677795" size="0.0638626217842102 0.010848076082766056" quat="1.0 0.0 0.0 0.0"/>
        <geom class="collision" type="cylinder" pos="0.2341102659702301 0.053658485412597656 -0.3013029098510742" size="0.0638626217842102 0.010664579458534718" quat="1.0 0.0 0.0 0.0"/>
        <geom class="collision" type="cylinder" pos="-0.00014972896315157413 0.20837345719337463 0.03174792602658272" size="0.025186479091644287 0.07796847820281982" quat="1.0 0.0 0.0 0.0"/>
        <geom class="collision" type="cylinder" pos="0.03975735604763031 0.20696187019348145 0.030607126653194427" size="0.020408621057868004 0.02134617045521736" quat="1.3767878215276141e-07 0.7071068286895752 -1.3767875373105198e-07 0.7071067094802856"/>
        <body name="handle">
          <joint axis="1.0 0.0 0.0" pos="0.07462769001722336 0.20718786120414734 0.030960608273744583" limited="true" name="handle_temp_joint" type="hinge" range="-0.7853981633974483 0.7853981633974483" damping="1" frictionloss="1" armature=".01"/>
          <joint axis="0.0 1.0 0.0" pos="0.07462769001722336 0.20718786120414734 0.030960608273744583" limited="true" name="handle_joint" type="hinge" range="0 0.5" damping="1" frictionloss="1" armature=".01"/>
          <geom mesh="handle_vis" type="mesh" solimp="0.998 0.998 0.001" solref="0.001 1" friction="0.95 0.3 0.1" class="visual" material="handle_material"/>
          <geom class="collision" type="cylinder" pos="0.08902686089277267 0.20696187019348145 0.030607124790549278" size="0.020408619195222855 0.010828463360667229" quat="1.3767878215276141e-07 0.7071068286895752 -1.3767875373105198e-07 0.7071067094802856" density="0.001"/>
          <geom class="collision" type="cylinder" pos="0.09323366731405258 0.20837345719337463 0.08650544285774231" size="0.004830267746001482 0.036618586629629135" quat="7.549790836947068e-08 1.0 -1.6292068494294654e-07 7.549789415861596e-08" density="0.001"/>
        </body>
        <body name="Funnel001">
          <joint axis="0.0 0.0 1.0" pos="-0.23377270996570587 0.05327993631362915 -0.2681823968887329" limited="true" name="Funnel001_joint" range="0.0 0.1" type="slide" damping="1" frictionloss="1" armature=".01" stiffness="0.05"/>
          <geom mesh="Funnel001_vis" type="mesh" solimp="0.998 0.998 0.001" solref="0.001 1" friction="0.95 0.3 0.1" class="visual" material="Funnel001_material"/>
          <geom class="collision" type="cylinder" pos="-0.2331215888261795 0.053658485412597656 -0.2684289216995239" size="0.04160851240158081 0.005387522745877504" quat="1.0 0.0 0.0 0.0"/>
          <geom class="collision" type="cylinder" pos="-0.2331215888261795 0.053658485412597656 -0.2624143958091736" size="0.009606130421161652 0.001243814011104405" quat="1.0 0.0 0.0 0.0"/>
        </body>
        <body name="Funnel002">
          <joint axis="0.0 0.0 1.0" pos="0.23377270996570587 0.05328001827001572 -0.2681823968887329" limited="true" name="Funnel002_joint" range="0.0 0.1" type="slide" damping="1" frictionloss="1" armature=".01" stiffness="0.05"/>
          <geom mesh="Funnel002_vis" type="mesh" solimp="0.998 0.998 0.001" solref="0.001 1" friction="0.95 0.3 0.1" class="visual" material="Funnel002_material"/>
          <geom class="collision" type="cylinder" pos="0.23389877378940582 0.053658485412597656 -0.2684289216995239" size="0.04160851240158081 0.005387522745877504" quat="1.0 0.0 0.0 0.0"/>
          <geom class="collision" type="cylinder" pos="0.23389877378940582 0.053658485412597656 -0.2632989287376404" size="0.008709521032869816 0.0027029607445001602" quat="1.0 0.0 0.0 0.0"/>
        </body>
        <body name="spout">
          <joint axis="0.0 0.0 1.0" pos="-0.00010259231203235686 0.2080770581960678 0.18622417747974396" limited="true" name="spout_joint" range="-1.0471975511965976 1.0471975511965976" type="hinge" damping="1" frictionloss="1" armature=".01" stiffness="0.05"/>
          <site type="cylinder" rgba="0.5 0.75 1 0.5" size="0.008077822625637054 0.25433674454689026" pos="-0.00022850713867228478 -0.006902423687279224 0.014040738344192505" name="water"/>
          <geom mesh="spout_vis" type="mesh" solimp="0.998 0.998 0.001" solref="0.001 1" friction="0.95 0.3 0.1" class="visual" material="spout_material"/>
          <geom class="collision" type="cylinder" pos="-0.00022850713867228478 0.2069898098707199 0.17759908735752106" size="0.014976673759520054 0.06626234948635101" quat="1.0 0.0 0.0 0.0"/>
          <geom class="collision" type="cylinder" pos="4.6260698582045734e-05 0.06275240331888199 0.2975461781024933" size="0.014976673759520054 0.08919991552829742" quat="0.7071068286895752 0.7071067690849304 -1.5700924318127872e-16 -5.9269340452702814e-24" name="spout_main"/>
          <geom class="collision" type="cylinder" pos="-0.00022851070389151573 0.2002333104610443 0.25821176171302795" size="0.014976675622165203 0.020353922620415688" quat="0.982413113117218 0.1867203712463379 -4.146025768229317e-17 1.6905972352430204e-23"/>
          <geom class="collision" type="cylinder" pos="-0.00022850713867228478 -0.006902423687279224 0.27870461344718933" size="0.010961321182549 0.009372392669320107" quat="7.549790126404332e-08 1.0 -2.220446049250313e-16 -1.7645063234279917e-24"/>
          <geom class="collision" type="cylinder" pos="-0.00022851070389151573 0.18160898983478546 0.28285831212997437" size="0.014976675622165203 0.020353922620415688" quat="0.8874186277389526 0.4609643816947937 -1.023546738702665e-16 6.925955778681676e-24"/>
          <geom class="collision" type="cylinder" pos="-0.00022851070389151573 0.15852375328540802 0.2951258420944214" size="0.014976675622165203 0.012227360159158707" quat="0.7861025929450989 0.6180960536003113 -1.372449072622919e-16 2.2254117968248472e-23"/>
        </body>
        <geom class="region" name="reg_basin_left" type="box" pos="-0.23375546652823687 -0.0237249955534935 -0.14782967790961266" size="0.2123054720684886 0.18507411128282547 0.09834811261296272"/>
        <geom class="region" name="reg_basin_right" type="box" pos="0.2337692016735673 -0.023518703877925873 -0.1476185917854309" size="0.21374445112794638 0.18496488577127457 0.09799775278568268"/>
        <geom class="region" name="reg_main" type="box" pos="0.0 0.0 -0.17865456640720367" size="0.48779661750793457 0.24802522158622742 0.13431298530101776"/>
      </body>
    </body>
  </worldbody>
  <actuator>
    <motor name="handle_joint_actuator" joint="handle_joint" gear="10"/>
    <motor name="handle_temp_joint_actuator" joint="handle_temp_joint" gear="10"/>
    <motor name="Funnel001_joint_actuator" joint="Funnel001_joint" gear="10"/>
    <motor name="Funnel002_joint_actuator" joint="Funnel002_joint" gear="10"/>
    <motor name="spout_joint_actuator" joint="spout_joint" gear="10"/>
  </actuator>
</mujoco>
