<?xml version='1.0' encoding='UTF-8'?>
<mujoco model="model">
  <option timestep="0.002" gravity="0.0 0.0 -9.81"/>
  <compiler angle="radian"/>
  <asset>
    <mesh file="visuals/handle.obj" name="handle_vis"/>
    <mesh file="visuals/Body001.obj" name="Body001_vis"/>
    <mesh file="visuals/Shelf001.obj" name="Shelf001_vis"/>
    <mesh file="visuals/Shelf002.obj" name="Shelf002_vis"/>
    <mesh file="visuals/spout.obj" name="spout_vis"/>
    <texture file="visuals/T_BC001.png" name="Body001_material" type="2d"/>
    <material name="Body001_material" rgba="1 1 1 1.0" texture="Body001_material" shininess="0.141421377658844" specular="1"/>
    <texture file="visuals/T_BC001.png" name="handle_material" type="2d"/>
    <material name="handle_material" rgba="1 1 1 1.0" texture="handle_material" shininess="0.141421377658844" specular="1"/>
    <texture file="visuals/T_BC001.png" name="Shelf001_material" type="2d"/>
    <material name="Shelf001_material" rgba="1 1 1 1.0" texture="Shelf001_material" shininess="0.141421377658844" specular="1"/>
    <texture file="visuals/T_BC001.png" name="Shelf002_material" type="2d"/>
    <material name="Shelf002_material" rgba="1 1 1 1.0" texture="Shelf002_material" shininess="0.141421377658844" specular="1"/>
    <texture file="visuals/T_BC001.png" name="spout_material" type="2d"/>
    <material name="spout_material" rgba="1 1 1 1.0" texture="spout_material" shininess="0.141421377658844" specular="1"/>
  </asset>
  <default>
    <default class="visual">
      <geom conaffinity="0" contype="0" group="1" type="mesh"/>
    </default>
    <default class="collision">
      <geom group="0" rgba="0.5 0 0 0.5"/>
    </default>
    <default class="spawn">
      <geom group="0" rgba="1 1 1 0.5" contype="0" conaffinity="0"/>
      <site group="0" rgba="1 1 1 0.5"/>
    </default>
    <default class="region">
      <geom group="1" conaffinity="0" contype="0" rgba="0 1 0 0"/>
    </default>
  </default>
  <worldbody>
    <body>
      <body name="object">
        <geom mesh="Body001_vis" type="mesh" solimp="0.998 0.998 0.001" solref="0.001 1" friction="0.95 0.3 0.1" class="visual" material="Body001_material"/>
        <geom class="collision" type="box" pos="-0.41402581 -0.00023080 -0.05207147" size="0.022894691675901413 0.2682405114173889 0.012045697309076786" quat="1.0 0.0 0.0 0.0"/>
        <geom class="collision" type="box" pos="0.40795222 -0.00023081 -0.05207147" size="0.028964372351765633 0.26824042201042175 0.012045692652463913" quat="1.0 0.0 0.0 0.0"/>
        <geom class="collision" type="box" pos="-0.01061450 -0.24163963 -0.05207147" size="0.3914196491241455 0.02683018147945404 0.01204568613320589" quat="1.0 0.0 0.0 0.0"/>
        <geom class="collision" type="box" pos="-0.01061450 0.23987053 -0.05207147" size="0.3914194405078888 0.027941973879933357 0.012045681476593018" quat="1.0 0.0 0.0 0.0"/>
        <geom class="collision" type="box" pos="-0.01061450 -0.22191751 -0.15760472" size="0.3914192318916321 0.011272481642663479 0.11095090955495834" quat="1.0 0.0 0.0 0.0"/>
        <geom class="collision" type="box" pos="0.38790286 -0.00379841 -0.16528009" size="0.010467687621712685 0.21606667339801788 0.10984964668750763" quat="1.0 0.0 0.0 0.0"/>
        <geom class="collision" type="box" pos="-0.36811498 0.00235081 -0.16112319" size="0.03185322880744934 0.203094482421875 0.10391531884670258" quat="1.0 0.0 0.0 0.0"/>
        <geom class="collision" type="box" pos="-0.01061420 0.00046252 -0.27352744" size="0.39141860604286194 0.2120686024427414 0.002776971086859703" quat="1.0 0.0 0.0 0.0"/>
        <geom class="collision" type="box" pos="-0.01061450 0.20614104 -0.15760472" size="0.3914184272289276 0.011272456496953964 0.11095070838928223" quat="1.0 0.0 0.0 0.0"/>
        <geom class="collision" type="cylinder" pos="0.18741572 0.21382920 0.00228175" size="0.02383415773510933 0.04755035787820816" quat="1.0 0.0 0.0 0.0"/>
        <geom class="collision" type="cylinder" pos="0.21505156 0.21382920 0.00228175" size="0.02383415773510933 0.024705450981855392" quat="0.7071068286895752 -0.0 0.7071067690849304 0.0"/>
        <geom class="collision" type="box" pos="-0.27097130 0.17762549 -0.16112319" size="0.12899693846702576 0.027818942442536354 0.1039150133728981" quat="1.0 0.0 0.0 0.0"/>
        <geom class="collision" type="box" pos="0.27775401 0.17762549 -0.16678700" size="0.12899692356586456 0.027818936854600906 0.09825118631124496" quat="1.0 0.0 0.0 0.0"/>
        <geom class="collision" type="box" pos="0.27775401 0.19877374 -0.14603704" size="0.12899689376354218 0.02781892940402031 0.09825116395950317" quat="1.0 0.0 0.0 0.0"/>
        <body name="handle">
          <joint axis="1.0 0.0 0.0" pos="0.26993331 0.21191886 0.00368081" limited="true" name="handle_temp_joint" type="hinge" range="-0.7853981633974483 0.7853981633974483" damping="1" frictionloss="1" armature=".01" stiffness="0.05"/>
          <joint axis="0.0 1.0 0.0" pos="0.26993331 0.21191886 0.00368081" limited="true" name="handle_joint" type="hinge" range="0 0.5" damping="1" frictionloss="1" armature=".01" stiffness="0.05"/>
          <geom mesh="handle_vis" type="mesh" solimp="0.998 0.998 0.001" solref="0.001 1" friction="0.95 0.3 0.1" class="visual" material="handle_material"/>
          <geom class="collision" type="cylinder" pos="0.26889989 0.21159852 0.00439400" size="0.02383415773510933 0.014818627387285233" quat="0.7071068286895752 -0.0 0.7071067690849304 0.0"/>
          <geom class="collision" type="cylinder" pos="0.27432001 0.21330808 0.06082442" size="0.006863738875836134 0.03465331345796585" quat="1.0 0.0 0.0 0.0"/>
        </body>
        <body name="Shelf001">
          <joint axis="0.0 0.0 1.0" pos="0.26770413 -0.03321151 -0.10938835" limited="true" name="Shelf001_joint" range="0.0 0.06" type="slide" damping="1" frictionloss="1" armature=".01" stiffness="0.05"/>
          <geom mesh="Shelf001_vis" type="mesh" solimp="0.998 0.998 0.001" solref="0.001 1" friction="0.95 0.3 0.1" class="visual" material="Shelf001_material"/>
          <geom class="collision" type="box" pos="0.16404225 -0.02255300 -0.06089588" size="0.025579331442713737 0.18334241211414337 0.005609891843050718" quat="1.0 0.0 0.0 0.0"/>
          <geom class="collision" type="box" pos="0.27087563 -0.03479288 -0.14149196" size="0.08489122241735458 0.14692017436027527 0.010312174446880817" quat="1.0 0.0 0.0 0.0"/>
          <geom class="collision" type="box" pos="0.18675058 -0.03535408 -0.10815577" size="0.0028710034675896168 0.14635898172855377 0.045173279941082" quat="1.0 0.0 0.0 0.0"/>
          <geom class="collision" type="box" pos="0.35946745 -0.03535408 -0.10815577" size="0.004827061202377081 0.14635898172855377 0.045173279941082" quat="1.0 0.0 0.0 0.0"/>
          <geom class="collision" type="box" pos="0.27484369 0.11546270 -0.10815577" size="0.0887058898806572 0.002871009986847639 0.045173279941082" quat="1.0 0.0 0.0 0.0"/>
          <geom class="collision" type="box" pos="0.27484366 -0.19101422 -0.10815577" size="0.0887058898806572 0.002871009986847639 0.045173279941082" quat="1.0 0.0 0.0 0.0"/>
          <geom class="collision" type="box" pos="0.36737180 -0.03535408 -0.06021336" size="0.009337583556771278 0.14635898172855377 0.004192819818854332" quat="1.0 0.0 0.0 0.0"/>
        </body>
        <body name="Shelf002">
          <joint axis="0.0 0.0 1.0" pos="-0.00150317 0.17703077 -0.09450805" limited="true" name="Shelf002_joint" range="0.0 0.06" type="slide" damping="1" frictionloss="1" armature=".01" stiffness="0.05"/>
          <geom mesh="Shelf002_vis" type="mesh" solimp="0.998 0.998 0.001" solref="0.001 1" friction="0.95 0.3 0.1" class="visual" material="Shelf002_material"/>
          <geom class="collision" type="box" pos="-0.00233199 0.15722592 -0.12684396" size="0.11054285615682602 0.03088262863457203 0.0038003886584192514" quat="1.0 0.0 0.0 0.0"/>
          <geom class="collision" type="box" pos="-0.00233199 0.13634940 -0.09363169" size="0.11054285615682602 0.00439953850582242 0.034315261989831924" quat="1.0 0.0 0.0 0.0"/>
          <geom class="collision" type="box" pos="-0.11227445 0.16119415 -0.09363169" size="0.002740363823249936 0.02775304764509201 0.034315261989831924" quat="1.0 0.0 0.0 0.0"/>
          <geom class="collision" type="box" pos="0.10907755 0.16119415 -0.09363169" size="0.002740363823249936 0.02775304764509201 0.034315261989831924" quat="1.0 0.0 0.0 0.0"/>
          <geom class="collision" type="box" pos="-0.00233199 0.18889587 -0.11126097" size="0.11054285615682602 0.00439953850582242 0.01668599247932434" quat="1.0 0.0 0.0 0.0"/>
        </body>
        <body name="spout">
          <joint axis="0.0 0.0 1.0" pos="0.18720418 0.21321146 0.16918962" limited="true" name="spout_joint" range="-0.7853981633974483 0.7853981633974483" type="hinge" damping="1" frictionloss="1" armature=".01" stiffness="0.05"/>
          <site type="cylinder" rgba="0.5 0.75 1 0.5" size="0.0057831453159451485 0.23046548664569855" pos="0.18744722 0.05002866 -0.02274617" name="water"/>
          <geom mesh="spout_vis" type="mesh" solimp="0.998 0.998 0.001" solref="0.001 1" friction="0.95 0.3 0.1" class="visual" material="spout_material"/>
          <geom class="collision" type="cylinder" pos="0.18700486 0.21382920 0.13669544" size="0.011294265277683735 0.08440812677145004" quat="1.0 0.0 0.0 0.0" name="spout_main"/>
          <geom class="collision" type="cylinder" pos="0.18700486 0.20095083 0.24846722" size="0.011294265277683735 0.032382093369960785" quat="0.958923876285553 0.2836635708808899 0.0 0.0"/>
          <geom class="collision" type="cylinder" pos="0.18700486 0.15753220 0.27737826" size="0.011294265277683735 0.03238209709525108" quat="0.7945126295089722 0.6072476506233215 0.0 0.0"/>
          <geom class="collision" type="cylinder" pos="0.18700486 0.10506007 0.27439380" size="0.011294265277683735 0.032382093369960785" quat="0.564933717250824 0.8251363039016724 0.0 0.0"/>
          <geom class="collision" type="cylinder" pos="0.18700486 0.06076001 0.23716174" size="0.011294265277683735 0.032382093369960785" quat="0.21412184834480286 0.9768069386482239 0.0 0.0"/>
          <geom class="collision" type="cylinder" pos="0.18700486 0.04923241 0.20282787" size="0.011294265277683735 0.011119321919977665" quat="1.0 0.0 0.0 0.0"/>
        </body>
        <geom class="region" name="reg_basin" type="box" pos="-0.09019965499999999 -0.026884485 -0.155341335" size="0.223737305 0.128664245 0.11407146500000001"/>
        <geom class="region" name="reg_main" type="box" pos="9.999999994736442e-09 1.9999999989472883e-08 -0.16640881000000002" size="0.43817593 0.26980756 0.12803651"/>
      </body>
    </body>
  </worldbody>
  <actuator>
    <motor name="handle_joint_actuator" joint="handle_joint" gear="10"/>
    <motor name="handle_temp_joint_actuator" joint="handle_temp_joint" gear="10"/>
    <motor name="Shelf001_joint_actuator" joint="Shelf001_joint" gear="10"/>
    <motor name="Shelf002_joint_actuator" joint="Shelf002_joint" gear="10"/>
    <motor name="spout_joint_actuator" joint="spout_joint" gear="10"/>
  </actuator>
</mujoco>
