<?xml version='1.0' encoding='UTF-8'?>
<mujoco model="model">
  <option timestep="0.002" gravity="0.0 0.0 -9.81"/>
  <compiler angle="radian"/>
  <asset>
    <mesh file="visuals/freezer_door.obj" name="freezer_door_vis"/>
    <mesh file="visuals/freezer_drawer0.obj" name="freezer_drawer0_vis"/>
    <mesh file="visuals/freezer_drawer1.obj" name="freezer_drawer1_vis"/>
    <mesh file="visuals/freezer_drawer2.obj" name="freezer_drawer2_vis"/>
    <mesh file="visuals/fridge_door.obj" name="fridge_door_vis"/>
    <mesh file="visuals/fridge_drawer0.obj" name="fridge_drawer0_vis"/>
    <mesh file="visuals/fridge_drawer1.obj" name="fridge_drawer1_vis"/>
    <mesh file="visuals/fridge_drawer2.obj" name="fridge_drawer2_vis"/>
    <mesh file="visuals/fridge_drawer3.obj" name="fridge_drawer3_vis"/>
    <mesh file="visuals/fridge_drawer4.obj" name="fridge_drawer4_vis"/>
    <mesh file="visuals/Body001.obj" name="Body001_vis"/>
    <mesh file="visuals/Body001_Clear.obj" name="Body001_Clear_vis"/>
    <texture file="visuals/T_BC001.png" name="Body001_material" type="2d"/>
    <material name="Body001_material" rgba="1 1 1 1.0" texture="Body001_material" shininess="0.4472135901451111" specular="1"/>
    <texture file="visuals/T_BC001.png" name="freezer_door_material" type="2d"/>
    <material name="freezer_door_material" rgba="1 1 1 1.0" texture="freezer_door_material" shininess="0.4472135901451111" specular="1"/>
    <texture file="visuals/T_BC001.png" name="freezer_drawer0_material" type="2d"/>
    <material name="freezer_drawer0_material" rgba="1 1 1 1.0" texture="freezer_drawer0_material" shininess="0.4472135901451111" specular="0.3103448502657381"/>
    <texture file="visuals/T_BC001.png" name="freezer_drawer1_material" type="2d"/>
    <material name="freezer_drawer1_material" rgba="1 1 1 1.0" texture="freezer_drawer1_material" shininess="0.4472135901451111" specular="0.3103448502657381"/>
    <texture file="visuals/T_BC001.png" name="freezer_drawer2_material" type="2d"/>
    <material name="freezer_drawer2_material" rgba="1 1 1 1.0" texture="freezer_drawer2_material" shininess="0.4472135901451111" specular="0.3103448502657381"/>
    <texture file="visuals/T_BC001.png" name="fridge_door_material" type="2d"/>
    <material name="fridge_door_material" rgba="1 1 1 1.0" texture="fridge_door_material" shininess="0.4472135901451111" specular="1"/>
    <material name="fridge_drawer0_material" rgba="1.0 1.0 1.0 0.2653976380825043" shininess="0.4472135901451111" specular="0.3103448502657381"/>
    <material name="fridge_drawer1_material" rgba="1.0 1.0 1.0 0.2653976380825043" shininess="0.4472135901451111" specular="0.3103448502657381"/>
    <material name="fridge_drawer2_material" rgba="1.0 1.0 1.0 0.2653976380825043" shininess="0.4472135901451111" specular="0.3103448502657381"/>
    <material name="fridge_drawer3_material" rgba="1.0 1.0 1.0 0.2653976380825043" shininess="0.4472135901451111" specular="0.3103448502657381"/>
    <material name="fridge_drawer4_material" rgba="1.0 1.0 1.0 0.2653976380825043" shininess="0.4472135901451111" specular="0.3103448502657381"/>
    <material name="Body001_Clear_material" rgba="1.0 1.0 1.0 0.2653976380825043" shininess="0.4472135901451111" specular="0.3103448502657381"/>
  </asset>
  <default>
    <default class="visual">
      <geom conaffinity="0" contype="0" group="1" type="mesh"/>
    </default>
    <default class="collision">
      <geom group="0" rgba="0.5 0 0 0.5"/>
    </default>
    <default class="spawn">
      <geom group="0" rgba="1 1 1 0.5" contype="0" conaffinity="0"/>
      <site group="0" rgba="1 1 1 0.5"/>
    </default>
    <default class="region">
      <geom group="1" conaffinity="0" contype="0" rgba="0 1 0 0"/>
    </default>
  </default>
  <worldbody>
    <body>
      <body name="object">
        <geom mesh="Body001_vis" type="mesh" solimp="0.998 0.998 0.001" solref="0.001 1" friction="0.95 0.3 0.1" class="visual" material="Body001_material"/>
        <geom class="collision" type="box" pos="-0.00000003 0.07244694 -0.87347156" size="0.4304637610912323 0.3956150412559509 0.0588507205247879" quat="1.0 0.0 0.0 0.0"/>
        <geom class="collision" type="box" pos="-0.40861815 0.07244785 0.03347566" size="0.021845141425728798 0.395599901676178 0.8861163258552551" quat="1.0 0.0 0.0 0.0"/>
        <geom class="collision" type="box" pos="0.41922861 0.07246298 0.03347566" size="0.011235269717872143 0.39558467268943787 0.8861758708953857" quat="1.0 0.0 0.0 0.0"/>
        <geom class="collision" type="box" pos="0.00422757 0.44963735 0.03726095" size="0.39516299962997437 0.018424177542328835 0.8771956562995911" quat="1.0 0.0 0.0 0.0"/>
        <geom class="collision" type="box" pos="-0.00005763 0.06491915 0.92715174" size="0.42882394790649414 0.40309831500053406 0.005167157854884863" quat="1.0 0.0 0.0 0.0"/>
        <geom class="collision" type="box" pos="0.06976730 0.07117526 0.03347566" size="0.007711742073297501 0.394353449344635 0.8863667249679565" quat="1.0 0.0 0.0 0.0"/>
        <geom class="collision" type="box" pos="-0.16336530 0.08476427 0.17532346" size="0.23660500347614288 0.3807418942451477 0.003616984933614731" quat="1.0 0.0 0.0 0.0"/>
        <geom class="collision" type="box" pos="-0.16336530 0.08476427 -0.09813295" size="0.23661182820796967 0.38075974583625793 0.040179990231990814" quat="1.0 0.0 0.0 0.0"/>
        <geom class="collision" type="box" pos="0.25140142 0.05892735 -0.13335752" size="0.15414109826087952 0.3807351887226105 0.011884043924510479" quat="1.0 0.0 0.0 0.0"/>
        <geom class="collision" type="box" pos="-0.16960494 0.05646115 0.41550559" size="0.21129442751407623 0.3519227206707001 0.01067923754453659" quat="1.0 0.0 0.0 0.0"/>
        <geom class="collision" type="box" pos="0.24783821 0.10986395 0.54615122" size="0.15461844205856323 0.2929384708404541 0.004145659971982241" quat="1.0 0.0 0.0 0.0"/>
        <geom class="collision" type="box" pos="0.25126901 0.10986399 0.20493993" size="0.15199317038059235 0.2910866439342499 0.004145502578467131" quat="1.0 0.0 0.0 0.0"/>
        <geom class="collision" type="box" pos="-0.00354902 0.07651708 0.89048517" size="0.42538413405418396 0.38581550121307373 0.032244957983493805" quat="1.0 0.0 0.0 0.0"/>
        <geom class="collision" type="box" pos="-0.17521077 -0.00168094 -0.35653734" size="0.20460020005702972 0.3087306618690491 0.0006429601344279945" quat="1.0 0.0 0.0 0.0"/>
        <geom class="collision" type="box" pos="-0.17521077 -0.00168094 -0.57321596" size="0.20460020005702972 0.30873045325279236 0.0001045343087753281" quat="1.0 0.0 0.0 0.0"/>
        <geom class="collision" type="box" pos="0.25022644 -0.00168094 -0.59977818" size="0.15879812836647034 0.30873170495033264 0.0016550397267565131" quat="1.0 0.0 0.0 0.0"/>
        <geom class="collision" type="box" pos="0.25022644 -0.00168094 -0.38382816" size="0.1587982475757599 0.30873173475265503 0.001671178499236703" quat="1.0 0.0 0.0 0.0"/>
        <geom class="collision" type="box" pos="-0.17554763 -0.04852468 -0.81352317" size="0.2269284576177597 0.29276221990585327 0.024953356012701988" quat="1.0 0.0 0.0 0.0"/>
        <body name="freezer_door">
          <joint axis="0.0 0.0 1.0" pos="0.41125858 -0.37849856 0.02739461" limited="true" name="freezer_door_joint" range="0.0 1.5707963267948966" type="hinge" damping="1" frictionloss="1" armature=".01" stiffness="0.05"/>
          <geom mesh="freezer_door_vis" type="mesh" solimp="0.998 0.998 0.001" solref="0.001 1" friction="0.95 0.3 0.1" class="visual" material="freezer_door_material"/>
          <geom class="collision" type="box" pos="0.10799358 -0.42213989 0.45491844" size="0.020545627921819687 0.015073212794959545 0.17384988069534302" quat="0.9959166646003723 -0.09027764201164246 5.812459611657523e-18 3.734767511574259e-19" name="freezer_door_handle_1"/>
          <geom class="collision" type="box" pos="0.10799358 -0.42104629 -0.15091255" size="0.020545627921819687 0.015073212794959545 0.16665861010551453" quat="0.9952443242073059 0.09741028398275375 5.640280312793385e-18 1.4530146072651087e-18" name="freezer_door_handle_2"/>
          <geom class="collision" type="box" pos="0.10799358 -0.45493445 0.14793020" size="0.020545581355690956 0.015073142945766449 0.13386665284633636" quat="1.0 0.0 0.0 0.0" name="freezer_door_handle_main"/>
          <geom class="collision" type="box" pos="0.24725594 -0.37833334 0.03077910" size="0.15779338777065277 0.008189450018107891 0.8890061378479004" quat="1.0 0.0 0.0 0.0" name="freezer_door_main"/>
        </body>
        <body name="freezer_drawer0">
          <geom class="region" name="reg_freezer_drawer0" type="box" pos="0.250738735 -0.007979545000000005 -0.6950289350000001" size="0.117325265 0.27091784500000005 0.06638477500000001"/>
          <joint axis="0.0 -1.0 0.0" pos="0.25054911 -0.00831169 -0.70767558" limited="true" name="freezer_drawer0_joint" range="0.0 0.45" type="slide" damping="1" frictionloss="1" armature=".01" stiffness="0.05"/>
          <geom mesh="freezer_drawer0_vis" type="mesh" solimp="0.998 0.998 0.001" solref="0.001 1" friction="0.95 0.3 0.1" class="visual" material="freezer_drawer0_material"/>
          <geom class="collision" type="box" pos="0.25229502 -0.01856448 -0.78834569" size="0.13306231796741486 0.29579514265060425 0.022255269810557365" quat="1.0 0.0 0.0 0.0"/>
          <geom class="collision" type="box" pos="0.37864539 -0.00891570 -0.70721042" size="0.0055981045588850975 0.3054431974887848 0.10118091851472855" quat="1.0 0.0 0.0 0.0"/>
          <geom class="collision" type="box" pos="0.12072334 -0.00891568 -0.70721042" size="0.00732760364189744 0.3054424524307251 0.10118067264556885" quat="1.0 0.0 0.0 0.0"/>
          <geom class="collision" type="box" pos="0.24773729 -0.29905850 -0.72060519" size="0.13345694541931152 0.014037924818694592 0.08960815519094467" quat="1.0 0.0 0.0 0.0"/>
          <geom class="collision" type="box" pos="0.24773729 0.28295066 -0.70721042" size="0.1334570050239563 0.013863825239241123 0.10118020325899124" quat="1.0 0.0 0.0 0.0"/>
          <geom class="collision" type="box" pos="0.16804263 -0.29833872 -0.63085544" size="0.05193275585770607 0.012029588222503662 0.009430548176169395" quat="0.9891068339347839 -3.418605705118806e-15 0.14719928801059723 1.9777544935095648e-08"/>
          <geom class="collision" type="box" pos="0.33302104 -0.29833872 -0.63245958" size="0.05193275585770607 0.012029588222503662 0.009430548176169395" quat="0.985614538192749 -5.7940937238257304e-15 -0.16900873184204102 -2.2707819624656622e-08"/>
        </body>
        <body name="freezer_drawer1">
          <geom class="region" name="reg_freezer_drawer1" type="box" pos="0.250738735 -0.007979545000000005 -0.47893213" size="0.117325265 0.27091784500000005 0.06638476000000001"/>
          <joint axis="0.0 -1.0 0.0" pos="0.25054911 -0.00796666 -0.49253732" limited="true" name="freezer_drawer1_joint" range="0.0 0.45" type="slide" damping="1" frictionloss="1" armature=".01" stiffness="0.05"/>
          <geom mesh="freezer_drawer1_vis" type="mesh" solimp="0.998 0.998 0.001" solref="0.001 1" friction="0.95 0.3 0.1" class="visual" material="freezer_drawer1_material"/>
          <geom class="collision" type="box" pos="0.25035903 -0.01856448 -0.57326460" size="0.13429798185825348 0.29579707980155945 0.022312471643090248" quat="1.0 0.0 0.0 0.0"/>
          <geom class="collision" type="box" pos="0.37939233 -0.00891570 -0.49036545" size="0.006345077883452177 0.30544513463974 0.10118143260478973" quat="1.0 0.0 0.0 0.0"/>
          <geom class="collision" type="box" pos="0.12147030 -0.00891568 -0.49036545" size="0.006580587010830641 0.3054443895816803 0.10118119418621063" quat="1.0 0.0 0.0 0.0"/>
          <geom class="collision" type="box" pos="0.24961606 -0.29905850 -0.50651467" size="0.1333988755941391 0.014037911780178547 0.08765426278114319" quat="1.0 0.0 0.0 0.0"/>
          <geom class="collision" type="box" pos="0.24961606 0.28295078 -0.49036545" size="0.13340258598327637 0.013863880187273026 0.10118072479963303" quat="1.0 0.0 0.0 0.0"/>
          <geom class="collision" type="box" pos="0.33302104 -0.29833872 -0.41739845" size="0.05193275585770607 0.012029588222503662 0.009430548176169395" quat="0.985614538192749 -5.7940937238257304e-15 -0.16900873184204102 -2.2707819624656622e-08"/>
          <geom class="collision" type="box" pos="0.16804263 -0.29833872 -0.41579434" size="0.05193275585770607 0.012029588222503662 0.009430548176169395" quat="0.9891068339347839 -3.418605705118806e-15 0.14719928801059723 1.9777544935095648e-08"/>
        </body>
        <body name="freezer_drawer2">
          <geom class="region" name="reg_freezer_drawer2" type="box" pos="0.250738735 -0.007979545000000005 -0.26260218" size="0.117325265 0.27091784500000005 0.06638478"/>
          <joint axis="0.0 -1.0 0.0" pos="0.25054911 -0.00796666 -0.27639794" limited="true" name="freezer_drawer2_joint" range="0.0 0.45" type="slide" damping="1" frictionloss="1" armature=".01" stiffness="0.05"/>
          <geom mesh="freezer_drawer2_vis" type="mesh" solimp="0.998 0.998 0.001" solref="0.001 1" friction="0.95 0.3 0.1" class="visual" material="freezer_drawer2_material"/>
          <geom class="collision" type="box" pos="0.24770607 0.28295069 -0.29124722" size="0.13339771330356598 0.013863182626664639 0.0890372022986412" quat="1.0 0.0 0.0 0.0"/>
          <geom class="collision" type="box" pos="0.24770607 -0.29905847 -0.28972170" size="0.1334020048379898 0.014037898741662502 0.08554614335298538" quat="1.0 0.0 0.0 0.0"/>
          <geom class="collision" type="box" pos="0.12202056 -0.00891563 -0.27476159" size="0.006030341610312462 0.30544716119766235 0.10350504517555237" quat="1.0 0.0 0.0 0.0"/>
          <geom class="collision" type="box" pos="0.37843734 -0.00891564 -0.27476159" size="0.00539003312587738 0.30544644594192505 0.10350482165813446" quat="1.0 0.0 0.0 0.0"/>
          <geom class="collision" type="box" pos="0.25187901 -0.01856442 -0.35260093" size="0.13306187093257904 0.2957969605922699 0.017787983641028404" quat="1.0 0.0 0.0 0.0"/>
          <geom class="collision" type="box" pos="0.33457136 -0.29833872 -0.20044599" size="0.05210725590586662 0.012029591016471386 0.026185838505625725" quat="1.0 0.0 0.0 0.0"/>
          <geom class="collision" type="box" pos="0.16929151 -0.29833872 -0.19892801" size="0.0524059534072876 0.012029590085148811 0.024144254624843597" quat="1.0 0.0 0.0 0.0"/>
        </body>
        <body name="fridge_door">
          <joint axis="0.0 0.0 -1.0" pos="-0.41614547 -0.37171198 0.02781687" limited="true" name="fridge_door_joint" range="0.0 1.5707963267948966" type="hinge" damping="1" frictionloss="1" armature=".01" stiffness="0.05"/>
          <geom mesh="fridge_door_vis" type="mesh" solimp="0.998 0.998 0.001" solref="0.001 1" friction="0.95 0.3 0.1" class="visual" material="fridge_door_material"/>
          <geom class="collision" type="box" pos="0.04544019 -0.42298672 0.45028567" size="0.020545627921819687 0.015073212794959545 0.17567604780197144" quat="0.9959166646003723 -0.09027764201164246 5.812459611657523e-18 3.734767511574259e-19" name="fridge_door_handle_1"/>
          <geom class="collision" type="box" pos="0.04544019 -0.42097614 -0.15126748" size="0.020545627921819687 0.015073210932314396 0.16911983489990234" quat="0.9952443242073059 0.09741028398275375 5.640280312793385e-18 1.4530146072651087e-18" name="fridge_door_handle_2"/>
          <geom class="collision" type="box" pos="0.04544019 -0.45493445 0.14793020" size="0.020545577630400658 0.015073137357831001 0.13386663794517517" quat="1.0 0.0 0.0 0.0" name="fridge_door_handle_main"/>
          <geom class="collision" type="box" pos="-0.16265643 -0.37758050 0.03347565" size="0.22955015301704407 0.006571865174919367 0.8863381743431091" quat="1.0 0.0 0.0 0.0" name="fridge_door_main"/>
        </body>
        <body name="fridge_drawer0">
          <geom class="region" name="reg_fridge_drawer0" type="box" pos="-0.17480606999999998 -0.008594285000000007 -0.66825548" size="0.1733844 0.27091784500000005 0.06616978000000001"/>
          <joint axis="0.0 -1.0 0.0" pos="-0.17504564 -0.00831169 -0.67909628" limited="true" name="fridge_drawer0_joint" range="0.0 0.45" type="slide" damping="1" frictionloss="1" armature=".01" stiffness="0.05"/>
          <geom mesh="fridge_drawer0_vis" type="mesh" solimp="0.998 0.998 0.001" solref="0.001 1" friction="0.95 0.3 0.1" class="visual" material="fridge_drawer0_material"/>
          <geom class="collision" type="box" pos="-0.17526354 -0.00891567 -0.76087093" size="0.1947074681520462 0.30544930696487427 0.02335994876921177" quat="1.0 0.0 0.0 0.0"/>
          <geom class="collision" type="box" pos="0.01267767 -0.00891567 -0.68661112" size="0.009852822870016098 0.3054485619068146 0.09661044925451279" quat="1.0 0.0 0.0 0.0"/>
          <geom class="collision" type="box" pos="-0.36245143 -0.00891567 -0.68661112" size="0.009158141911029816 0.3054478168487549 0.09661021083593369" quat="1.0 0.0 0.0 0.0"/>
          <geom class="collision" type="box" pos="-0.17514957 -0.29768840 -0.69255406" size="0.19513551890850067 0.012679442763328552 0.09059213101863861" quat="1.0 0.0 0.0 0.0"/>
          <geom class="collision" type="box" pos="-0.17514957 0.28266033 -0.68661112" size="0.19513559341430664 0.01357348170131445 0.09660974144935608" quat="1.0 0.0 0.0 0.0"/>
          <geom class="collision" type="box" pos="-0.03524977 -0.29833872 -0.59694600" size="0.05193275213241577 0.012029588222503662 0.00943054724484682" quat="0.9922551512718201 -6.5854943941373156e-15 -0.12421657890081406 -1.6689606141540025e-08"/>
          <geom class="collision" type="box" pos="-0.30773485 -0.29833872 -0.59762812" size="0.05193274840712547 0.012029588222503662 0.00943054910749197" quat="0.9920896887779236 -2.2518929944500762e-15 0.1255311369895935 1.6866216867583717e-08"/>
        </body>
        <body name="fridge_drawer1">
          <geom class="region" name="reg_fridge_drawer1" type="box" pos="-0.17480606999999998 -0.008594285000000007 -0.45511489" size="0.1733844 0.27091784500000005 0.06206706000000001"/>
          <joint axis="0.0 -1.0 0.0" pos="-0.17504564 -0.00831168 -0.46395811" limited="true" name="fridge_drawer1_joint" range="0.0 0.45" type="slide" damping="1" frictionloss="1" armature=".01" stiffness="0.05"/>
          <geom mesh="fridge_drawer1_vis" type="mesh" solimp="0.998 0.998 0.001" solref="0.001 1" friction="0.95 0.3 0.1" class="visual" material="fridge_drawer1_material"/>
          <geom class="collision" type="box" pos="-0.17514959 0.28280016 -0.46779487" size="0.19513492286205292 0.014015227556228638 0.09975799918174744" quat="1.0 0.0 0.0 0.0"/>
          <geom class="collision" type="box" pos="-0.17514959 -0.29744733 -0.47926727" size="0.19513501226902008 0.012920749373733997 0.08636489510536194" quat="1.0 0.0 0.0 0.0"/>
          <geom class="collision" type="box" pos="-0.36221918 -0.00891567 -0.46464807" size="0.009390406310558319 0.3054497539997101 0.09661072492599487" quat="1.0 0.0 0.0 0.0"/>
          <geom class="collision" type="box" pos="0.01278688 -0.00891567 -0.46464807" size="0.009743595495820045 0.3054490089416504 0.09661048650741577" quat="1.0 0.0 0.0 0.0"/>
          <geom class="collision" type="box" pos="-0.17106414 -0.00891567 -0.55850321" size="0.19470739364624023 0.3054482638835907 0.008594129234552383" quat="1.0 0.0 0.0 0.0"/>
          <geom class="collision" type="box" pos="-0.30773485 -0.29833872 -0.38405535" size="0.05193274840712547 0.012029588222503662 0.00943054910749197" quat="0.9920896887779236 -2.2518929944500762e-15 0.1255311369895935 1.6866216867583717e-08"/>
          <geom class="collision" type="box" pos="-0.03524977 -0.29833872 -0.38337320" size="0.05193275213241577 0.012029588222503662 0.00943054724484682" quat="0.9922551512718201 -6.5854943941373156e-15 -0.12421657890081406 -1.6689606141540025e-08"/>
        </body>
        <body name="fridge_drawer2">
          <geom class="region" name="reg_fridge_drawer2" type="box" pos="-0.17480606999999998 -0.008594285000000007 -0.237246235" size="0.1733844 0.27091784500000005 0.063254705"/>
          <joint axis="0.0 -1.0 0.0" pos="-0.17504564 -0.00796667 -0.24781865" limited="true" name="fridge_drawer2_joint" range="0.0 0.45" type="slide" damping="1" frictionloss="1" armature=".01" stiffness="0.05"/>
          <geom mesh="fridge_drawer2_vis" type="mesh" solimp="0.998 0.998 0.001" solref="0.001 1" friction="0.95 0.3 0.1" class="visual" material="fridge_drawer2_material"/>
          <geom class="collision" type="box" pos="-0.17535956 0.28441837 -0.24910988" size="0.19492459297180176 0.01239717099815607 0.10317104309797287" quat="1.0 0.0 0.0 0.0"/>
          <geom class="collision" type="box" pos="-0.17535956 -0.29833872 -0.26275274" size="0.19492465257644653 0.012029588222503662 0.08953393250703812" quat="1.0 0.0 0.0 0.0"/>
          <geom class="collision" type="box" pos="-0.36245149 -0.00891564 -0.24547902" size="0.009158159606158733 0.3054516613483429 0.09953965991735458" quat="1.0 0.0 0.0 0.0"/>
          <geom class="collision" type="box" pos="0.02102525 -0.00891564 -0.24547899" size="0.0015052473172545433 0.3054509162902832 0.09953941404819489" quat="1.0 0.0 0.0 0.0"/>
          <geom class="collision" type="box" pos="-0.17106414 -0.00891564 -0.34266606" size="0.1947070211172104 0.3054502010345459 0.008997596800327301" quat="1.0 0.0 0.0 0.0"/>
          <geom class="collision" type="box" pos="-0.29626244 -0.29833872 -0.16954002" size="0.05193275213241577 0.012029588222503662 0.009430548176169395" quat="0.9918231964111328 -5.2083047957459695e-15 0.12761953473091125 1.7146815523005898e-08"/>
          <geom class="collision" type="box" pos="-0.05106309 -0.29833872 -0.16916795" size="0.05193275213241577 0.012029588222503662 0.009430548176169395" quat="0.9903227090835571 -3.951238445318913e-15 -0.138783797621727 -1.8646842292469046e-08"/>
        </body>
        <body name="fridge_drawer3">
          <geom class="region" name="reg_fridge_drawer3" type="box" pos="-0.17365725999999998 0.004097469999999992 0.071667285" size="0.18880045 0.2836096 0.09489863500000001"/>
          <joint axis="0.0 -1.0 0.0" pos="-0.17504576 -0.00842516 0.06357863" limited="true" name="fridge_drawer3_joint" range="0.0 0.45" type="slide" damping="1" frictionloss="1" armature=".01" stiffness="0.05"/>
          <geom mesh="fridge_drawer3_vis" type="mesh" solimp="0.998 0.998 0.001" solref="0.001 1" friction="0.95 0.3 0.1" class="visual" material="fridge_drawer3_material"/>
          <geom class="collision" type="box" pos="-0.17106414 -0.00891561 -0.03655959" size="0.19470636546611786 0.3054550588130951 0.005770247895270586" quat="1.0 0.0 0.0 0.0"/>
          <geom class="collision" type="box" pos="0.02102525 -0.00891561 0.06164588" size="0.0015052432427182794 0.3054543435573578 0.10378623753786087" quat="1.0 0.0 0.0 0.0"/>
          <geom class="collision" type="box" pos="-0.37010440 -0.00891561 0.06164585" size="0.0015052438247948885 0.3054535984992981 0.10378599166870117" quat="1.0 0.0 0.0 0.0"/>
          <geom class="collision" type="box" pos="-0.17606108 -0.30803574 0.06164588" size="0.19554020464420319 0.002331118332222104 0.10378577560186386" quat="1.0 0.0 0.0 0.0"/>
          <geom class="collision" type="box" pos="-0.17606108 0.29448255 0.06164588" size="0.19554027915000916 0.0023311125114560127 0.10378553718328476" quat="1.0 0.0 0.0 0.0"/>
        </body>
        <body name="fridge_drawer4">
          <geom class="region" name="reg_fridge_drawer4" type="box" pos="-0.173577685 0.004030814999999993 0.282838795" size="0.18877744500000002 0.283542945 0.07966555499999999"/>
          <joint axis="0.0 -1.0 0.0" pos="-0.17504576 -0.00814063 0.27327278" limited="true" name="fridge_drawer4_joint" range="0.0 0.45" type="slide" damping="1" frictionloss="1" armature=".01" stiffness="0.05"/>
          <geom mesh="fridge_drawer4_vis" type="mesh" solimp="0.998 0.998 0.001" solref="0.001 1" friction="0.95 0.3 0.1" class="visual" material="fridge_drawer4_material"/>
          <geom class="collision" type="box" pos="-0.17472963 0.29448255 0.27721068" size="0.1955537497997284 0.002331150695681572 0.08908568322658539" quat="1.0 0.0 0.0 0.0"/>
          <geom class="collision" type="box" pos="-0.17472963 -0.31053091 0.27721068" size="0.19555382430553436 0.0023311448749154806 0.08908543735742569" quat="1.0 0.0 0.0 0.0"/>
          <geom class="collision" type="box" pos="-0.37010440 -0.00891561 0.27721065" size="0.0015052409144118428 0.3054555058479309 0.0890851691365242" quat="1.0 0.0 0.0 0.0"/>
          <geom class="collision" type="box" pos="0.02102524 -0.00891561 0.27721068" size="0.001505241496488452 0.3054547607898712 0.0890849232673645" quat="1.0 0.0 0.0 0.0"/>
          <geom class="collision" type="box" pos="-0.17106415 -0.00891561 0.19193172" size="0.1947062909603119 0.3054540455341339 0.007545307278633118" quat="1.0 0.0 0.0 0.0"/>
        </body>
        <body name="Body001_Clear">
          <geom mesh="Body001_Clear_vis" type="mesh" solimp="0.998 0.998 0.001" solref="0.001 1" friction="0.95 0.3 0.1" class="visual" material="Body001_Clear_material"/>
        </body>
        <geom class="region" name="reg_freezer_shelf0" type="box" pos="0.24812231 0.067997625 0.039696394999999995" size="0.14638845 0.354399815 0.157135265"/>
        <geom class="region" name="reg_freezer_shelf1" type="box" pos="0.24847813000000002 0.113857815 0.37535915" size="0.14674428 0.287013435 0.16236351000000002"/>
        <geom class="region" name="reg_freezer_shelf2" type="box" pos="0.24796447 0.11502860000000001 0.7038880000000001" size="0.14768298000000002 0.28448966 0.14993901000000004"/>
        <geom class="region" name="reg_fridge_shelf0" type="box" pos="-0.180734365 0.06302706000000002 0.64300582" size="0.200879085 0.36386594 0.21145014"/>
        <geom class="region" name="reg_main" type="box" pos="-9.999999994736442e-09 0.040539615 0.0" size="0.43146382 0.42853824500000004 0.93332012"/>
      </body>
    </body>
  </worldbody>
  <actuator>
    <motor name="freezer_door_joint_actuator" joint="freezer_door_joint" gear="50"/>
    <motor name="freezer_drawer0_joint_actuator" joint="freezer_drawer0_joint" gear="50"/>
    <motor name="freezer_drawer1_joint_actuator" joint="freezer_drawer1_joint" gear="50"/>
    <motor name="freezer_drawer2_joint_actuator" joint="freezer_drawer2_joint" gear="50"/>
    <motor name="fridge_door_joint_actuator" joint="fridge_door_joint" gear="50"/>
    <motor name="fridge_drawer0_joint_actuator" joint="fridge_drawer0_joint" gear="50"/>
    <motor name="fridge_drawer1_joint_actuator" joint="fridge_drawer1_joint" gear="50"/>
    <motor name="fridge_drawer2_joint_actuator" joint="fridge_drawer2_joint" gear="50"/>
    <motor name="fridge_drawer3_joint_actuator" joint="fridge_drawer3_joint" gear="50"/>
    <motor name="fridge_drawer4_joint_actuator" joint="fridge_drawer4_joint" gear="50"/>
  </actuator>
</mujoco>
