<?xml version='1.0' encoding='UTF-8'?>
<mujoco model="model">
  <option timestep="0.002" gravity="0.0 0.0 -9.81"/>
  <compiler angle="radian"/>
  <asset>
    <mesh file="visuals/handle.obj" name="handle_vis"/>
    <mesh file="visuals/Body001.obj" name="Body001_vis"/>
    <mesh file="visuals/Funnel001.obj" name="Funnel001_vis"/>
    <mesh file="visuals/spout.obj" name="spout_vis"/>
    <texture file="visuals/T_BC001.png" name="Body001_material" type="2d"/>
    <material name="Body001_material" rgba="1 1 1 1.0" texture="Body001_material" shininess="0.5" specular="0.5"/>
    <texture file="visuals/T_BC001.png" name="handle_material" type="2d"/>
    <material name="handle_material" rgba="1 1 1 1.0" texture="handle_material" shininess="1" specular="1"/>
    <texture file="visuals/T_BC001.png" name="Funnel001_material" type="2d"/>
    <material name="Funnel001_material" rgba="1 1 1 1.0" texture="Funnel001_material" shininess="5" specular="5"/>
    <texture file="visuals/T_BC001.png" name="spout_material" type="2d"/>
    <material name="spout_material" rgba="1 1 1 1.0" texture="spout_material" shininess="1" specular="1"/>
  </asset>
  <default>
    <default class="visual">
      <geom conaffinity="0" contype="0" group="1" type="mesh"/>
    </default>
    <default class="collision">
      <geom group="0" rgba="0.5 0 0 0.5"/>
    </default>
    <default class="spawn">
      <geom group="0" rgba="1 1 1 0.5" contype="0" conaffinity="0"/>
      <site group="0" rgba="1 1 1 0.5"/>
    </default>
    <default class="region">
      <geom group="1" conaffinity="0" contype="0" rgba="0 1 0 0"/>
    </default>
  </default>
  <worldbody>
    <body>
      <body name="object">
        <geom mesh="Body001_vis" type="mesh" solimp="0.998 0.998 0.001" solref="0.001 1" friction="0.95 0.3 0.1" class="visual" material="Body001_material"/>
        <geom class="collision" type="box" pos="-0.3524441123008728 2.0489096641540527e-08 -0.25851669907569885" size="0.011873608455061913 0.3014654517173767 0.13877208530902863" quat="1.0 0.0 0.0 0.0"/>
        <geom class="collision" type="box" pos="0.35296860337257385 -9.313225746154785e-09 -0.25851672887802124" size="0.011349148117005825 0.3014655113220215 0.1387721300125122" quat="1.0 0.0 0.0 0.0"/>
        <geom class="collision" type="box" pos="-0.0007268190383911133 -0.23696185648441315 -0.36737051606178284" size="0.33796435594558716 0.038684990257024765 0.029918313026428223" quat="1.0 0.0 0.0 0.0"/>
        <geom class="collision" type="box" pos="0.0005569830536842346 0.23077604174613953 -0.25851672887802124" size="0.3362390995025635 0.07068934291601181 0.1387721747159958" quat="1.0 0.0 0.0 0.0"/>
        <geom class="collision" type="box" pos="0.0005569830536842346 -0.28945785760879517 -0.25851672887802124" size="0.3362390995025635 0.012007510289549828 0.13877207040786743" quat="1.0 0.0 0.0 0.0"/>
        <geom class="collision" type="cylinder" pos="-0.001985963899642229 0.2551099956035614 -0.035752419382333755" size="0.030178183689713478 0.08440031111240387" quat="1.0 0.0 0.0 0.0"/>
        <geom class="collision" type="cylinder" pos="0.0381937175989151 0.2546387314796448 -0.016625920310616493" size="0.021399369463324547 0.019612431526184082" quat="0.5000000596046448 0.5 0.4999999701976776 0.5"/>
        <geom class="collision" type="box" pos="-0.0007268190383911133 0.12832729518413544 -0.367371141910553" size="0.33796435594558716 0.038684990257024765 0.0299177598208189" quat="1.0 0.0 0.0 0.0"/>
        <geom class="collision" type="box" pos="-0.22707338631153107 -0.05449286103248596 -0.3673707842826843" size="0.1116178035736084 0.14057162404060364 0.02991802990436554" quat="1.0 0.0 0.0 0.0"/>
        <geom class="collision" type="box" pos="0.23310363292694092 -0.05449286103248596 -0.3673707842826843" size="0.11229205131530762 0.14057162404060364 0.02991802990436554" quat="1.0 0.0 0.0 0.0"/>
        <geom class="collision" type="box" pos="0.002433479530736804 -0.05449286103248596 -0.37644320726394653" size="0.1174427941441536 0.14057162404060364 0.02084561437368393" quat="1.0 0.0 0.0 0.0"/>
        <body name="handle">
          <joint axis="0.0 1.0 0.0" pos="0.07194176316261292 0.254017174243927 -0.017591847106814384" limited="true" name="handle_joint" type="hinge" range="0 0.5" damping="1" frictionloss="1" armature=".01"/>
          <joint axis="1.0 0.0 0.0" pos="0.07194176316261292 0.254017174243927 -0.017591847106814384" limited="true" name="handle_temp_joint" type="hinge" range="-0.7853981633974483 0.7853981633974483" damping="1" frictionloss="1" armature=".01"/>
          <geom mesh="handle_vis" type="mesh" solimp="0.998 0.998 0.001" solref="0.001 1" friction="0.95 0.3 0.1" class="visual" material="handle_material"/>
          <geom class="collision" type="cylinder" pos="0.08161629736423492 0.2537739872932434 -0.017231235280632973" size="0.02353030815720558 0.009531225077807903" quat="0.5000000596046448 0.5 0.4999999701976776 0.5" density="0.001"/>
          <geom class="collision" type="cylinder" pos="0.08213990181684494 0.2537529766559601 0.04715613275766373" size="0.004157292190939188 0.04314939305186272" quat="5.338507946817117e-08 0.7071068286895752 0.7071067094802856 5.338507591545749e-08" density="0.001"/>
        </body>
        <body name="Funnel001">
          <joint axis="0.0 0.0 1.0" pos="0.0002033539058174938 -0.05557889863848686 -0.33190903067588806" limited="true" name="Funnel001_joint" range="0.0 0.1" type="slide" damping="1" frictionloss="1" armature=".01" stiffness="0.05"/>
          <geom mesh="Funnel001_vis" type="mesh" solimp="0.998 0.998 0.001" solref="0.001 1" friction="0.95 0.3 0.1" class="visual" material="Funnel001_material"/>
          <geom class="collision" type="box" pos="-0.0006947148940525949 -0.05559322610497475 -0.3426222503185272" size="0.11300185322761536 0.13947126269340515 0.006462354678660631" quat="1.0 0.0 0.0 0.0"/>
          <geom class="collision" type="cylinder" pos="-6.787099118810147e-05 -0.057669881731271744 -0.32537341117858887" size="0.010172259993851185 0.012283321470022202" quat="1.0 0.0 0.0 0.0"/>
        </body>
        <body name="spout">
          <joint axis="0.0 0.0 1.0" pos="-0.0030321134254336357 0.25473126769065857 0.22855141758918762" limited="true" name="spout_joint" range="-1.0471975511965976 1.0471975511965976" type="hinge" damping="1" frictionloss="1" armature=".01" stiffness="0.05"/>
          <site type="cylinder" rgba="0.5 0.75 1 0.5" size="0.011609296314418316 0.2936442196369171" pos="-0.00281657837331295 -0.012468467466533184 -0.05398388206958771" name="water"/>
          <geom mesh="spout_vis" type="mesh" solimp="0.998 0.998 0.001" solref="0.001 1" friction="0.95 0.3 0.1" class="visual" material="spout_material"/>
          <geom class="collision" type="cylinder" pos="-0.001985963899642229 0.2551099956035614 0.1680082082748413" size="0.01867983676493168 0.1152455285191536" quat="1.0 0.0 0.0 0.0"/>
          <geom class="collision" type="cylinder" pos="-0.001985963899642229 0.22945097088813782 0.33195406198501587" size="0.01867983676493168 0.019234102219343185" quat="0.9550366401672363 0.29648786783218384 -7.311360098850056e-17 7.311360760594546e-17"/>
          <geom class="collision" type="cylinder" pos="-0.003100561909377575 0.1576118916273117 0.3783402144908905" size="0.01867983676493168 0.023211244493722916" quat="0.6504695415496826 -0.7595323324203491 -1.6865005668006397e-16 -5.628278406301753e-24"/>
          <geom class="collision" type="cylinder" pos="-0.001985963899642229 0.2478446066379547 0.2981155216693878" size="0.01867983676493168 0.018054183572530746" quat="0.9834555983543396 0.18114937841892242 -2.589090371978125e-17 8.142348223762665e-18"/>
          <geom class="collision" type="cylinder" pos="-0.003100561909377575 0.1980898380279541 0.3608796298503876" size="0.01867983676493168 0.024418875575065613" quat="6.614553171857551e-08 -3.6396450298070704e-08 0.48208558559417725 -0.8761241436004639"/>
          <geom class="collision" type="cylinder" pos="-0.003100561909377575 0.11066237092018127 0.3805367052555084" size="0.01867983676493168 0.023211244493722916" quat="0.7335634827613831 -0.6796209216117859 -1.5090617227296447e-16 4.9560979175719814e-24"/>
          <geom class="collision" type="cylinder" pos="-0.003100561909377575 0.06645843386650085 0.3712017238140106" size="0.01867983676493168 0.023211244493722916" quat="0.8416051268577576 -0.5400933623313904 -1.1992481726150536e-16 -3.352237595465912e-23"/>
          <geom class="collision" type="cylinder" pos="-0.003100561909377575 0.026921994984149933 0.34456953406333923" size="0.01867983676493168 0.023211244493722916" quat="0.9195057153701782 -0.39307668805122375 -8.728055128612885e-17 -2.358671229644574e-23"/>
          <geom class="collision" type="cylinder" pos="-0.001114597893320024 0.00029224343597888947 0.30757367610931396" size="0.01867983676493168 0.023211244493722916" quat="0.9744263291358948 -0.22470727562904358 -4.9895044858276e-17 -1.3303184644857047e-23"/>
          <geom class="collision" type="cylinder" pos="-0.001114597893320024 -0.010003702715039253 0.26505520939826965" size="0.01867983676493168 0.023211244493722916" quat="0.9989654421806335 -0.04547514393925667 -1.0097506233998116e-17 -1.2421837687107923e-23"/>
          <geom class="collision" type="cylinder" pos="-0.000953328562900424 -0.011199960485100746 0.2366466522216797" size="0.01867983676493168 0.012093055993318558" quat="1.0 0.0 0.0 0.0"/>
        </body>
        <geom class="region" name="reg_basin" type="box" pos="0.0007221996784210205 -0.05901142209768295 -0.22596844285726547" size="0.3306256363391876 0.20870130306482315 0.10155673867464066"/>
        <geom class="region" name="reg_main" type="box" pos="-7.450580596923828e-09 0.0 -0.25851672887802124" size="0.36531771516799927 0.3024655411243439 0.13977210021018982"/>
      </body>
    </body>
  </worldbody>
  <actuator>
    <motor name="handle_joint_actuator" joint="handle_joint" gear="10"/>
    <motor name="handle_temp_joint_actuator" joint="handle_temp_joint" gear="10"/>
    <motor name="Funnel001_joint_actuator" joint="Funnel001_joint" gear="10"/>
    <motor name="spout_joint_actuator" joint="spout_joint" gear="10"/>
  </actuator>
</mujoco>
