<?xml version='1.0' encoding='UTF-8'?>
<mujoco model="model">
  <option timestep="0.002" gravity="0.0 0.0 -9.81"/>
  <compiler angle="radian"/>
  <asset>
    <mesh file="visuals/handle.obj" name="handle_vis"/>
    <mesh file="visuals/Body001.obj" name="Body001_vis"/>
    <mesh file="visuals/spout.obj" name="spout_vis"/>
    <texture file="visuals/T_BC001.png" name="Body001_material" type="2d"/>
    <material name="Body001_material" rgba="1 1 1 1.0" texture="Body001_material" shininess="0.1" specular="3"/>
    <texture file="visuals/T_BC001.png" name="handle_material" type="2d"/>
    <material name="handle_material" rgba="1 1 1 1.0" texture="handle_material" shininess="0.1" specular="3"/>
    <texture file="visuals/T_BC001.png" name="spout_material" type="2d"/>
    <material name="spout_material" rgba="1 1 1 1.0" texture="spout_material" shininess="0.1" specular="3"/>
  </asset>
  <default>
    <default class="visual">
      <geom conaffinity="0" contype="0" group="1" type="mesh"/>
    </default>
    <default class="collision">
      <geom group="0" rgba="0.5 0 0 0.5"/>
    </default>
    <default class="spawn">
      <geom group="0" rgba="1 1 1 0.5" contype="0" conaffinity="0"/>
      <site group="0" rgba="1 1 1 0.5"/>
    </default>
    <default class="region">
      <geom group="1" conaffinity="0" contype="0" rgba="0 1 0 0"/>
    </default>
  </default>
  <worldbody>
    <body>
      <body name="object">
        <geom mesh="Body001_vis" type="mesh" solimp="0.998 0.998 0.001" solref="0.001 1" friction="0.95 0.3 0.1" class="visual" material="Body001_material"/>
        <geom class="collision" type="box" pos="-0.22370186 -0.01297073 -0.13942419" size="0.0030769745353609324 0.14365696907043457 0.07520347088575363" quat="1.0 0.0 0.0 0.0"/>
        <geom class="collision" type="box" pos="0.22353817 -0.01297073 -0.13942419" size="0.004052217584103346 0.14365696907043457 0.07520347088575363" quat="1.0 0.0 0.0 0.0"/>
        <geom class="collision" type="box" pos="0.00052068 -0.16089737 -0.13942419" size="0.22694265842437744 0.008095183409750462 0.07520347088575363" quat="1.0 0.0 0.0 0.0"/>
        <geom class="collision" type="box" pos="0.00052068 0.13065380 -0.13942419" size="0.22694265842437744 0.007858645170927048 0.07520347088575363" quat="1.0 0.0 0.0 0.0"/>
        <geom class="collision" type="box" pos="0.00104106 -0.01458936 -0.21025735" size="0.2276076376438141 0.1383713185787201 0.006834566127508879" quat="1.0 0.0 0.0 0.0"/>
        <geom class="collision" type="box" pos="0.00021407 0.15526815 -0.05972812" size="0.22942407429218292 0.033051520586013794 0.0076792286708951" quat="1.0 0.0 0.0 0.0"/>
        <geom class="collision" type="box" pos="-0.23806421 0.00000152 -0.05972812" size="0.017874063923954964 0.18831804394721985 0.007679254747927189" quat="1.0 0.0 0.0 0.0"/>
        <geom class="collision" type="box" pos="0.23828895 0.00000155 -0.05972812" size="0.017648139968514442 0.18831808865070343 0.007679241709411144" quat="1.0 0.0 0.0 0.0"/>
        <geom class="collision" type="box" pos="0.00066572 -0.17055937 -0.05972812" size="0.22415614128112793 0.017757192254066467 0.0076792421750724316" quat="1.0 0.0 0.0 0.0"/>
        <geom class="collision" type="cylinder" pos="0.01099786 0.15715011 -0.01293133" size="0.020531006157398224 0.043195951730012894" quat="1.0 -8.146032826061855e-08 0.0 0.0"/>
        <geom class="collision" type="cylinder" pos="0.03755776 0.15715011 -0.01293133" size="0.019330136477947235 0.02658579871058464" quat="0.7071068286895752 -1.5454311608209537e-08 0.7071067690849304 1.5454309831852697e-08"/>
        <geom class="collision" type="cylinder" pos="0.00005492 0.04247664 -0.22765857" size="0.041211847215890884 0.01047203317284584" quat="1.0 0.0 0.0 0.0"/>
        <body name="handle">
          <joint axis="1.0 0.0 0.0" pos="0.08124840 0.15679020 -0.01260636" limited="true" name="handle_temp_joint" type="hinge" range="-0.7853981633974483 0.7853981633974483" damping="1" frictionloss="1" armature=".01" stiffness="0.01" springref="-0.01"/>
          <joint axis="0.0 1.0 0.0" pos="0.08124840 0.15679020 -0.01260636" limited="true" name="handle_joint" type="hinge" range="0 0.5" damping="1" frictionloss="1" armature=".01" stiffness="0.01" springref="-0.01"/>
          <geom mesh="handle_vis" type="mesh" solimp="0.998 0.998 0.001" solref="0.001 1" friction="0.95 0.3 0.1" class="visual" material="handle_material"/>
          <geom class="collision" type="cylinder" pos="0.08606666 0.15715011 -0.01222685" size="0.020337821915745735 0.009487312287092209" quat="0.7071068286895752 -1.5454311608209537e-08 0.7071067690849304 1.5454309831852697e-08"/>
          <geom class="collision" type="cylinder" pos="0.08584638 0.15715009 0.03725621" size="0.00495106540620327 0.031458549201488495" quat="9.099629210140847e-07 4.371146999915254e-08 -8.14603211551912e-08 -1.0"/>
        </body>
        <body name="spout">
          <joint axis="0.0 0.0 1.0" pos="0.01050470 0.15753365 0.13018970" limited="true" name="spout_joint" range="-0.7853981633974483 0.7853981633974483" type="hinge" damping="1" frictionloss="1" armature=".01" stiffness="0.01" springref="-0.01"/>
          <site type="cylinder" rgba="0.5 0.75 1 0.5" size="0.008058087900280952 0.20167091488838196" pos="0.00688797 0.00886206 -0.01290043" name="water"/>
          <geom mesh="spout_vis" type="mesh" solimp="0.998 0.998 0.001" solref="0.001 1" friction="0.95 0.3 0.1" class="visual" material="spout_material"/>
          <geom class="collision" type="cylinder" pos="0.01048973 0.15755093 0.10893022" size="0.01348385401070118 0.0760563388466835" quat="1.0 0.0 0.0 0.0" name="spout_main"/>
          <geom class="collision" type="cylinder" pos="0.01058588 0.14599571 0.20155093" size="0.012817899696528912 0.0224286075681448" quat="0.9396012425422668 0.34198689460754395 -0.004769474267959595 -0.013104013167321682"/>
          <geom class="collision" type="cylinder" pos="0.00858321 0.09358337 0.21933845" size="0.01414923183619976 0.04494063928723335" quat="0.7500154972076416 0.6612758040428162 -0.01036915834993124 -0.009142313152551651"/>
          <geom class="collision" type="cylinder" pos="0.00678419 0.02141563 0.20039377" size="0.013681190088391304 0.022014377638697624" quat="0.9656696915626526 -0.25977304577827454 0.0 0.0"/>
          <geom class="collision" type="cylinder" pos="0.00743583 0.04168981 0.22042586" size="0.01379110012203455 0.022191235795617104" quat="0.8438840508460999 -0.5365256071090698 0.0 0.0"/>
        </body>
        <geom class="region" name="reg_basin" type="box" pos="-0.0003302550000000015 -0.015177239999999995 -0.13795961" size="0.215540635 0.13314206 0.06636233999999999"/>
        <geom class="region" name="reg_main" type="box" pos="-1.849999999858909e-07 1.544999999991692e-06 -0.145089745" size="0.256938055 0.189318075 0.094040855"/>
      </body>
    </body>
  </worldbody>
  <actuator>
    <motor name="handle_joint_actuator" joint="handle_joint" gear="10"/>
    <motor name="handle_temp_joint_actuator" joint="handle_temp_joint" gear="10"/>
    <motor name="spout_joint_actuator" joint="spout_joint" gear="10"/>
  </actuator>
</mujoco>
