<?xml version='1.0' encoding='UTF-8'?>
<mujoco model="model">
  <option timestep="0.002" gravity="0.0 0.0 -9.81"/>
  <compiler angle="radian"/>
  <asset>
    <mesh file="visuals/handle.obj" name="handle_vis"/>
    <mesh file="visuals/Body001.obj" name="Body001_vis"/>
    <mesh file="visuals/Container001.obj" name="Container001_vis"/>
    <mesh file="visuals/Funnel001.obj" name="Funnel001_vis"/>
    <mesh file="visuals/spout.obj" name="spout_vis"/>
    <texture file="visuals/T_BC001.png" name="Body001_material" type="2d"/>
    <material name="Body001_material" rgba="1 1 1 1.0" texture="Body001_material" shininess="0.1" specular="3"/>
    <texture file="visuals/T_BC001.png" name="handle_material" type="2d"/>
    <material name="handle_material" rgba="1 1 1 1.0" texture="handle_material" shininess="0.5" specular="1"/>
    <texture file="visuals/T_BC001.png" name="Container001_material" type="2d"/>
    <material name="Container001_material" rgba="1 1 1 1.0" texture="Container001_material" shininess="0.5" specular="3"/>
    <texture file="visuals/T_BC001.png" name="Funnel001_material" type="2d"/>
    <material name="Funnel001_material" rgba="1 1 1 1.0" texture="Funnel001_material" shininess="0.1" specular="2"/>
    <texture file="visuals/T_BC001.png" name="spout_material" type="2d"/>
    <material name="spout_material" rgba="1 1 1 1.0" texture="spout_material" shininess="0.2" specular="1"/>
  </asset>
  <default>
    <default class="visual">
      <geom conaffinity="0" contype="0" group="1" type="mesh"/>
    </default>
    <default class="collision">
      <geom group="0" rgba="0.5 0 0 0.5"/>
    </default>
    <default class="spawn">
      <geom group="0" rgba="1 1 1 0.5" contype="0" conaffinity="0"/>
      <site group="0" rgba="1 1 1 0.5"/>
    </default>
    <default class="region">
      <geom group="1" conaffinity="0" contype="0" rgba="0 1 0 0"/>
    </default>
  </default>
  <worldbody>
    <body>
      <body name="object">
        <geom mesh="Body001_vis" type="mesh" solimp="0.998 0.998 0.001" solref="0.001 1" friction="0.95 0.3 0.1" class="visual" material="Body001_material"/>
        <geom class="collision" type="box" pos="-0.33033314 -0.03073106 -0.18203157" size="0.04538177698850632 0.21870219707489014 0.11276067048311234" quat="1.0 0.0 0.0 0.0"/>
        <geom class="collision" type="box" pos="-0.00000001 -0.22260673 -0.18203154" size="0.37571418285369873 0.026827223598957062 0.11276067048311234" quat="1.0 0.0 0.0 0.0"/>
        <geom class="collision" type="box" pos="0.33197743 -0.01938420 -0.18203155" size="0.04373747855424881 0.23004919290542603 0.11276067048311234" quat="1.0 0.0 0.0 0.0"/>
        <geom class="collision" type="box" pos="-0.14741498 0.19010052 -0.18203143" size="0.2282993048429489 0.008557597175240517 0.11276069283485413" quat="1.0 0.0 0.0 0.0"/>
        <geom class="collision" type="box" pos="-0.14692110 -0.19321556 -0.18203152" size="0.22879329323768616 0.008557607419788837 0.1127607449889183" quat="1.0 0.0 0.0 0.0"/>
        <geom class="collision" type="box" pos="0.18044676 0.19147414 -0.18232904" size="0.1059616282582283 0.009983002208173275 0.11246313154697418" quat="1.0 0.0 0.0 0.0"/>
        <geom class="collision" type="box" pos="0.18649410 -0.19420634 -0.18203154" size="0.11200913041830063 0.008966133929789066 0.11276078224182129" quat="1.0 0.0 0.0 0.0"/>
        <geom class="collision" type="box" pos="-0.00000001 -0.09258664 -0.27024726" size="0.37571457028388977 0.09105529636144638 0.02454528398811817" quat="1.0 0.0 0.0 0.0"/>
        <geom class="collision" type="box" pos="0.20183869 0.04549660 -0.27024726" size="0.1631738245487213 0.04596805199980736 0.024545306339859962" quat="1.0 0.0 0.0 0.0"/>
        <geom class="collision" type="box" pos="-0.00000004 0.13803725 -0.27024726" size="0.37571460008621216 0.045394498854875565 0.02454531192779541" quat="1.0 0.0 0.0 0.0"/>
        <geom class="collision" type="box" pos="-0.21556140 0.04549660 -0.27024726" size="0.16015343368053436 0.045968133956193924 0.02454533241689205" quat="1.0 0.0 0.0 0.0"/>
        <geom class="collision" type="cylinder" pos="0.01843523 0.21879329 -0.02663432" size="0.020228685811161995 0.020443851128220558" quat="0.7071068286895752 1.2101618374060763e-08 0.7071067690849304 -1.2101617485882343e-08"/>
        <geom class="collision" type="cylinder" pos="-0.01212471 0.21897301 -0.02592911" size="0.022797370329499245 0.045382849872112274" quat="1.0 0.0 0.0 0.0"/>
        <geom class="collision" type="box" pos="-0.00000001 0.22344549 -0.18203149" size="0.3757146894931793 0.025988398119807243 0.11276087164878845" quat="1.0 0.0 0.0 0.0"/>
        <geom class="collision" type="box" pos="0.00210933 -0.18545331 -0.22251361" size="0.36479583382606506 0.008557697758078575 0.04323146864771843" quat="0.9932255744934082 0.11620211601257324 -3.3462691708326277e-17 -1.1685481251863116e-18"/>
        <geom class="collision" type="box" pos="0.27490819 0.00378976 -0.21471907" size="0.20199944078922272 0.008557695895433426 0.04323146492242813" quat="0.69902104139328 0.10662775486707687 0.10662778466939926 0.6990212202072144"/>
        <body name="handle">
          <joint axis="1.0 0.0 0.0" pos="0.06479135 0.21923083 -0.02750173" limited="true" name="handle_temp_joint" type="hinge" range="-0.7853981633974483 0.7853981633974483" damping="1" frictionloss="1" armature=".01"/>
          <joint axis="0.0 1.0 0.0" pos="0.06479135 0.21923083 -0.02750173" limited="true" name="handle_joint" type="hinge" range="0 0.5" damping="1" frictionloss="1" armature=".01"/>
          <geom mesh="handle_vis" type="mesh" solimp="0.998 0.998 0.001" solref="0.001 1" friction="0.95 0.3 0.1" class="visual" material="handle_material"/>
          <geom class="collision" type="cylinder" pos="0.06841291 0.21881914 -0.02743400" size="0.02281017042696476 0.010983329266309738" quat="0.7071068286895752 -0.0 0.7071067690849304 0.0" density="0.001"/>
          <geom class="collision" type="cylinder" pos="0.06494518 0.21913177 0.02755849" size="0.004913790617138147 0.03293713927268982" quat="1.0 0.0 0.0 0.0" density="0.001"/>
        </body>
        <body name="Container001">
          <joint axis="0.0 0.0 1.0" pos="0.18269193 0.00158033 -0.10476265" limited="true" name="Container001_joint" range="0.0 0.1" type="slide" damping="1" frictionloss="1" armature=".01" stiffness="0.05"/>
          <geom mesh="Container001_vis" type="mesh" solimp="0.998 0.998 0.001" solref="0.001 1" friction="0.95 0.3 0.1" class="visual" material="Container001_material"/>
          <geom class="collision" type="box" pos="0.17930797 0.15847993 -0.10158688" size="0.08510932326316833 0.005809545051306486 0.03817487508058548" quat="0.04934852570295334 0.9987816214561462 -2.2177407054261217e-16 -7.894152648962042e-26"/>
          <geom class="collision" type="box" pos="0.09633640 -0.00895250 -0.10384757" size="0.15226206183433533 0.002230982296168804 0.038181714713573456" quat="0.014585187658667564 0.7069562673568726 0.7069564461708069 0.014585212804377079"/>
          <geom class="collision" type="box" pos="0.27124405 -0.00817993 -0.10481862" size="0.15285062789916992 0.0019349642097949982 0.038318976759910583" quat="0.027257831767201424 0.7065810561180115 -0.7065814137458801 -0.027257852256298065"/>
          <geom class="collision" type="box" pos="0.18310186 0.18146019 -0.06548583" size="0.10112003237009048 0.01446457114070654 0.0009946709033101797" quat="0.9999801516532898 -0.006300822366029024 -1.3990645435459048e-18 -8.2058420696737615e-25"/>
          <geom class="collision" type="box" pos="0.18387479 -0.17512453 -0.10324496" size="0.08209159970283508 0.0028013784904032946 0.03832589462399483" quat="0.08811910450458527 -0.9961099624633789 -2.2203249500086353e-16 -1.723404501910754e-17"/>
          <geom class="collision" type="box" pos="0.18230173 -0.00654619 -0.14102266" size="0.08560527116060257 0.16589590907096863 0.0034047740045934916" quat="1.0 0.0 0.0 0.0"/>
          <geom class="collision" type="box" pos="0.18265931 -0.18769257 -0.06630756" size="0.10111471265554428 0.0077414135448634624 0.0017976694507524371" quat="1.0 0.0 0.0 0.0"/>
          <geom class="collision" type="box" pos="0.09148815 -0.00599018 -0.06544333" size="0.009462566114962101 0.17565231025218964 0.0017827058909460902" quat="1.0 0.0 0.0 0.0"/>
          <geom class="collision" type="box" pos="0.27447024 -0.00617371 -0.06582341" size="0.009462566114962101 0.1756560504436493 0.002278570318594575" quat="1.0 0.0 0.0 0.0"/>
        </body>
        <body name="Funnel001">
          <joint axis="0.0 0.0 1.0" pos="-0.00834750 0.04629402 -0.25556348" limited="true" name="Funnel001_joint" range="0.0 0.1" type="slide" damping="1" frictionloss="1" armature=".01" stiffness="0.05"/>
          <geom mesh="Funnel001_vis" type="mesh" solimp="0.998 0.998 0.001" solref="0.001 1" friction="0.95 0.3 0.1" class="visual" material="Funnel001_material"/>
          <geom class="collision" type="cylinder" pos="-0.00895030 0.04639759 -0.25988166" size="0.035002294927835464 0.000941219215746969" quat="1.0 0.0 0.0 0.0"/>
          <geom class="collision" type="cylinder" pos="-0.00855932 0.04639759 -0.25822766" size="0.00952162966132164 0.004481073003262281" quat="1.0 0.0 0.0 0.0"/>
          <geom class="collision" type="box" pos="0.02620432 0.04639759 -0.25437165" size="0.001374227344058454 0.00741409370675683 0.00636748131364584" quat="0.9920489192008972 6.231488514656287e-16 0.1258530467748642 -4.307769252420712e-09"/>
          <geom class="collision" type="box" pos="0.03125759 0.04642378 -0.25057469" size="0.004876116290688515 0.00741409370675683 0.0028620604425668716" quat="1.0 0.0 0.0 0.0"/>
          <geom class="collision" type="box" pos="0.02434607 0.03518393 -0.25437165" size="0.001374227344058454 0.00741409370675683 0.00636748131364584" quat="0.9787018895149231 0.020574934780597687 0.12415982037782669 -0.16218392550945282"/>
          <geom class="collision" type="box" pos="0.02913767 0.03357869 -0.25057469" size="0.002857643412426114 0.00741409370675683 0.004873522557318211" quat="0.6972854137420654 0.11559805274009705 0.6979194283485413 -0.11549302935600281"/>
          <geom class="collision" type="box" pos="0.01907729 0.02530901 -0.25437165" size="0.001374227344058454 0.00741409370675683 0.00636748131364584" quat="0.9398285746574402 0.04029399901628494 0.11922828108072281 -0.3176213204860687"/>
          <geom class="collision" type="box" pos="0.02311046 0.02226437 -0.25057469" size="0.002857643412426114 0.007414093241095543 0.004873522557318211" quat="0.6696330904960632 0.22634083032608032 0.6702418923377991 -0.2261352688074112"/>
          <geom class="collision" type="box" pos="0.01079749 0.01752157 -0.25437165" size="0.001374227344058454 0.00741409370675683 0.006367481779307127" quat="0.8752581477165222 0.05924379825592041 0.11103677749633789 -0.46699488162994385"/>
          <geom class="collision" type="box" pos="0.01363297 0.01333871 -0.25057469" size="0.002857643412426114 0.00741409370675683 0.004873522557318211" quat="0.6236976981163025 0.33278799057006836 0.6242648959159851 -0.3324856162071228"/>
          <geom class="collision" type="box" pos="0.00041107 0.01281124 -0.25437165" size="0.001374227344058454 0.00741409370675683 0.006367481779307127" quat="0.7868015766143799 0.07665476948022842 0.09981502592563629 -0.6042386293411255"/>
          <geom class="collision" type="box" pos="0.00174032 0.00793586 -0.25057469" size="0.002857643412426114 0.00741409370675683 0.004873522557318211" quat="0.5608556866645813 0.4304916262626648 0.56136554479599 -0.430100679397583"/>
          <geom class="collision" type="box" pos="-0.01090233 0.01171299 -0.25437165" size="0.001374227344058454 0.007414093241095543 0.00636748131364584" quat="0.6774327754974365 0.09194158762693405 0.08594029396772385 -0.7247384786605835"/>
          <geom class="collision" type="box" pos="-0.01121679 0.00666944 -0.25057469" size="0.002857643412426114 0.0074140941724181175 0.004873522557318211" quat="0.48273414373397827 0.5167186856269836 0.48317280411720276 -0.5162495374679565"/>
          <geom class="collision" type="box" pos="-0.02180239 0.01425521 -0.25437165" size="0.001374227344058454 0.00741409370675683 0.00636748131364584" quat="0.5519278645515442 0.10457713156938553 0.070018470287323 -0.8243401646614075"/>
          <geom class="collision" type="box" pos="-0.02370320 0.00957300 -0.25057469" size="0.002857643412426114 0.00741409370675683 0.004873522557318211" quat="0.3932725787162781 0.5878006815910339 0.39363011717796326 -0.5872668623924255"/>
          <geom class="collision" type="box" pos="-0.03146262 0.02024515 -0.25437165" size="0.001374227344058454 0.00741409370675683 0.00636748131364584" quat="0.4097360372543335 0.11461713165044785 0.051979824900627136 -0.9034807085990906"/>
          <geom class="collision" type="box" pos="-0.03477216 0.01642635 -0.25057469" size="0.002857643412426114 0.00741409370675683 0.004873522557318211" quat="0.2921501398086548 0.6441637873649597 0.2924155592918396 -0.6435794234275818"/>
          <geom class="collision" type="box" pos="-0.03873438 0.02913558 -0.25437165" size="0.001374227344058454 0.00741409370675683 0.00636748131364584" quat="0.25485607981681824 0.12162920832633972 0.03233148530125618 -0.9587540626525879"/>
          <geom class="collision" type="box" pos="-0.04310764 0.02660363 -0.25057469" size="0.002857643412426114 0.00741409370675683 0.004873522557318211" quat="0.18165908753871918 0.6836621761322021 0.18182417750358582 -0.6830417513847351"/>
          <geom class="collision" type="box" pos="-0.04268959 0.03979183 -0.25437165" size="0.001374227344058454 0.00741409370675683 0.00636748131364584" quat="0.09468649327754974 0.12527848780155182 0.012012094259262085 -0.9875198602676392"/>
          <geom class="collision" type="box" pos="-0.04764581 0.03880590 -0.25057469" size="0.002857643412426114 0.00741409370675683 0.004873522557318211" quat="0.06749895215034485 0.7041943669319153 0.06756032258272171 -0.7035551071166992"/>
          <geom class="collision" type="box" pos="-0.04301969 0.05097955 -0.25437165" size="0.0013742272276431322 0.00741409370675683 0.00636748131364584" quat="0.06552086770534515 -0.12557794153690338 0.00831207912415266 0.9898828864097595"/>
          <geom class="collision" type="box" pos="-0.04803233 0.05161962 -0.25057469" size="0.002857643412426114 0.0074140941724181175 0.004873523022979498" quat="0.046698931604623795 -0.7058820128440857 0.04674135893583298 0.7052411437034607"/>
          <geom class="collision" type="box" pos="-0.03969965 0.06185046 -0.25437165" size="0.001374227344058454 0.00741409370675683 0.00636748131364584" quat="0.22646915912628174 -0.12252973765134811 0.0287302415817976 0.9658533930778503"/>
          <geom class="collision" type="box" pos="-0.04423787 0.06407324 -0.25057469" size="0.002857643412426114 0.0074140941724181175 0.004873522557318211" quat="0.161423921585083 -0.6887299418449402 0.16157051920890808 0.6881048679351807"/>
          <geom class="collision" type="box" pos="-0.03302310 0.07109646 -0.25437165" size="0.001374227344058454 0.00741409370675683 0.006367481779307127" quat="0.3818311095237732 -0.11615757644176483 0.048439763486385345 0.9156233072280884"/>
          <geom class="collision" type="box" pos="-0.03659778 0.07466829 -0.25057469" size="0.002857643412426114 0.00741409370675683 0.004873522557318211" quat="0.27206623554229736 -0.6529161930084229 0.2723134160041809 0.6523234248161316"/>
          <geom class="collision" type="box" pos="-0.02374834 0.07766746 -0.25437165" size="0.001374227344058454 0.00741409370675683 0.00636748131364584" quat="0.5263835191726685 -0.10667566955089569 0.06677792221307755 0.84088134765625"/>
          <geom class="collision" type="box" pos="-0.02597978 0.08220144 -0.25057469" size="0.002857643412426114 0.00741409370675683 0.004873522557318211" quat="0.3751906454563141 -0.5995249152183533 0.3755315840244293 0.598980724811554"/>
          <geom class="collision" type="box" pos="-0.01302467 0.08087327 -0.25437165" size="0.0013742272276431322 0.00741409370675683 0.00636748131364584" quat="0.6548842787742615 -0.09453434497117996 0.0830797404050827 0.7451762557029724"/>
          <geom class="collision" type="box" pos="-0.01369973 0.08588130 -0.25057469" size="0.002857643412426114 0.00741409370675683 0.004873522557318211" quat="0.46660754084587097 -0.5313527584075928 0.4670315086841583 0.530870258808136"/>
          <geom class="collision" type="box" pos="-0.00166521 0.08047079 -0.25437165" size="0.001374227344058454 0.00741409370675683 0.006367481779307127" quat="0.7678977251052856 -0.07968029379844666 0.09741685539484024 0.6280876398086548"/>
          <geom class="collision" type="box" pos="-0.00068875 0.08542888 -0.25057469" size="0.002857643412426114 0.00741409370675683 0.004873522557318211" quat="0.5472222566604614 -0.44772467017173767 0.5477197170257568 0.4473181366920471"/>
          <geom class="collision" type="box" pos="0.00325179 0.07909328 -0.25437165" size="0.001374227344058454 0.00741409370675683 0.006367481779307127" quat="0.8119527697563171 -0.07231049984693527 0.10300575196743011 0.5699945092201233"/>
          <geom class="collision" type="box" pos="0.00494404 0.08385485 -0.25057469" size="0.002857643412426114 0.00741409370675683 0.004873522557318211" quat="0.5785268545150757 -0.40638935565948486 0.5790526866912842 0.4060201644897461"/>
          <geom class="collision" type="box" pos="0.01316704 0.07353568 -0.25437165" size="0.001374227344058454 0.00741409370675683 0.00636748131364584" quat="0.8942137360572815 -0.054497841745615005 0.11344150453805923 0.4295845031738281"/>
          <geom class="collision" type="box" pos="0.01630476 0.07749686 -0.25057469" size="0.002857643412426114 0.0074140941724181175 0.004873522091656923" quat="0.6371185183525085 -0.3062611520290375 0.6376977562904358 0.3059830665588379"/>
          <geom class="collision" type="box" pos="0.02066446 0.06522527 -0.25437165" size="0.001374227344058454 0.00741409370675683 0.00636748131364584" quat="0.9517059326171875 -0.03552510216832161 0.1207350492477417 0.28003010153770447"/>
          <geom class="collision" type="box" pos="0.02489826 0.06798409 -0.25057469" size="0.002857643412426114 0.00741409370675683 0.004873522557318211" quat="0.6780804395675659 -0.19956126809120178 0.6786971688270569 0.19937993586063385"/>
          <geom class="collision" type="box" pos="0.02517556 0.05479218 -0.25437165" size="0.001374227344058454 0.00741409370675683 0.006367481779307127" quat="0.9846820831298828 -0.015308922156691551 0.12491849064826965 0.12067393213510513"/>
          <geom class="collision" type="box" pos="0.03007296 0.05603784 -0.25057469" size="0.002857643412426114 0.00741409370675683 0.004873522557318211" quat="0.7015421390533447 -0.08600940555334091 0.702180027961731 0.08593123406171799"/>
        </body>
        <body name="spout">
          <joint axis="0.0 0.0 1.0" pos="-0.01111200 0.21855922 0.15633931" limited="true" name="spout_joint" range="-0.7853981633974483 0.7853981633974483" type="hinge" damping="1" frictionloss="1" armature=".01" stiffness="0.05"/>
          <site type="cylinder" rgba="0.5 0.75 1 0.5" size="0.006065879482775927 0.216606006026268" pos="-0.01077057 0.03488784 -0.03946172" name="water"/>
          <geom mesh="spout_vis" type="mesh" solimp="0.998 0.998 0.001" solref="0.001 1" friction="0.95 0.3 0.1" class="visual" material="spout_material"/>
          <geom class="collision" type="cylinder" pos="-0.01093094 0.21909758 0.11077619" size="0.011920161545276642 0.09080865979194641" quat="1.0 0.0 0.0 0.0"/>
          <geom class="collision" type="cylinder" pos="-0.01093094 0.21294346 0.22501730" size="0.011920161545276642 0.02771236188709736" quat="0.9908534288406372 0.13494248688220978 5.597813108299096e-17 -5.141014360981385e-18"/>
          <geom class="collision" type="cylinder" pos="-0.01093094 0.18697892 0.26433777" size="0.011920161545276642 0.02771236188709736" quat="0.9126067757606506 0.4088384807109833 8.829445634143715e-17 1.095444797781019e-18"/>
          <geom class="collision" type="cylinder" pos="-0.01093094 0.14426059 0.28428750" size="0.011920161545276642 0.02771236188709736" quat="0.749485194683075 0.6620211005210876 1.4844748708999145e-16 -1.2915069722786706e-18"/>
          <geom class="collision" type="cylinder" pos="-0.01093094 0.09543393 0.27955948" size="0.011920161545276642 0.027712363749742508" quat="0.5441926121711731 0.8389602899551392 1.7793484803606138e-16 1.1991887148726233e-17"/>
          <geom class="collision" type="cylinder" pos="-0.01093094 0.06120956 0.25418990" size="0.011920161545276642 0.02771236188709736" quat="0.9412050843238831 -0.33783581852912903 6.469056639466089e-17 -4.214016970556522e-16" name="spout_main"/>
          <geom class="collision" type="cylinder" pos="-0.01093094 0.03929905 0.20224209" size="0.011920161545276642 0.03456389904022217" quat="0.9946037530899048 -0.10374680906534195 -2.303643577475876e-17 -1.6915156271088787e-23"/>
        </body>
        <geom class="region" name="reg_basin" type="box" pos="-0.10145215499999999 0.004719755000000006 -0.15551136999999998" size="0.179042665 0.17177500499999998 0.08551029"/>
        <geom class="region" name="reg_main" type="box" pos="-1.4999999992104662e-08 -2.500000000071889e-08 -0.18203149000000002" size="0.37671501500000004 0.250434025 0.11376102"/>
      </body>
    </body>
  </worldbody>
  <actuator>
    <motor name="handle_joint_actuator" joint="handle_joint" gear="10"/>
    <motor name="handle_temp_joint_actuator" joint="handle_temp_joint" gear="10"/>
    <motor name="Container001_joint_actuator" joint="Container001_joint" gear="30"/>
    <motor name="Funnel001_joint_actuator" joint="Funnel001_joint" gear="10"/>
    <motor name="spout_joint_actuator" joint="spout_joint" gear="10"/>
  </actuator>
</mujoco>
