<?xml version='1.0' encoding='UTF-8'?>
<mujoco model="model">
  <option timestep="0.002" gravity="0.0 0.0 -9.81"/>
  <compiler angle="radian"/>
  <asset>
    <mesh file="visuals/handle.obj" name="handle_vis"/>
    <mesh file="visuals/Body001.obj" name="Body001_vis"/>
    <mesh file="visuals/Funnel001.obj" name="Funnel001_vis"/>
    <mesh file="visuals/Funnel002.obj" name="Funnel002_vis"/>
    <mesh file="visuals/spout.obj" name="spout_vis"/>
    <texture file="visuals/T_BC001.png" name="Body001_material" type="2d"/>
    <material name="Body001_material" rgba="1 1 1 1.0" texture="Body001_material" shininess="0.4472135901451111" specular="5"/>
    <texture file="visuals/T_BC001.png" name="handle_material" type="2d"/>
    <material name="handle_material" rgba="1 1 1 1.0" texture="handle_material" shininess="0.4472135901451111" specular="1"/>
    <texture file="visuals/T_BC001.png" name="Funnel001_material" type="2d"/>
    <material name="Funnel001_material" rgba="1 1 1 1.0" texture="Funnel001_material" shininess="0.4472135901451111" specular="2"/>
    <texture file="visuals/T_BC001.png" name="Funnel002_material" type="2d"/>
    <material name="Funnel002_material" rgba="1 1 1 1.0" texture="Funnel002_material" shininess="0.4472135901451111" specular="2"/>
    <texture file="visuals/T_BC001.png" name="spout_material" type="2d"/>
    <material name="spout_material" rgba="1 1 1 1.0" texture="spout_material" shininess="0.4472135901451111" specular="2"/>
  </asset>
  <default>
    <default class="visual">
      <geom conaffinity="0" contype="0" group="1" type="mesh"/>
    </default>
    <default class="collision">
      <geom group="0" rgba="0.5 0 0 0.5"/>
    </default>
    <default class="spawn">
      <geom group="0" rgba="1 1 1 0.5" contype="0" conaffinity="0"/>
      <site group="0" rgba="1 1 1 0.5"/>
    </default>
    <default class="region">
      <geom group="1" conaffinity="0" contype="0" rgba="0 1 0 0"/>
    </default>
  </default>
  <worldbody>
    <body>
      <body name="object">
        <geom mesh="Body001_vis" type="mesh" solimp="0.998 0.998 0.001" solref="0.001 1" friction="0.95 0.3 0.1" class="visual" material="Body001_material"/>
        <geom class="collision" type="box" pos="-0.30388611 0.00000046 -0.10586761" size="0.021419450640678406 0.24999506771564484 0.08091449737548828" quat="1.0 0.0 0.0 0.0"/>
        <geom class="collision" type="box" pos="-0.11187685 0.00000727 -0.10586766" size="0.016419874504208565 0.24998833239078522 0.08091457188129425" quat="1.0 0.0 0.0 0.0"/>
        <geom class="collision" type="box" pos="0.30258090 0.00011994 -0.10586761" size="0.022722894325852394 0.2498757690191269 0.08091454207897186" quat="1.0 0.0 0.0 0.0"/>
        <geom class="collision" type="box" pos="-0.20496794 0.20526514 -0.10586764" size="0.07693108171224594 0.04473176971077919 0.08091460168361664" quat="1.0 0.0 0.0 0.0"/>
        <geom class="collision" type="box" pos="-0.20496793 -0.20580221 -0.10586760" size="0.0776364803314209 0.04418020322918892 0.08091482520103455" quat="1.0 0.0 0.0 0.0"/>
        <geom class="collision" type="box" pos="0.09009420 -0.22442133 -0.10586758" size="0.18988753855228424 0.025487767532467842 0.08091457933187485" quat="1.0 0.0 0.0 0.0"/>
        <geom class="collision" type="box" pos="0.09448574 0.22408366 -0.10635973" size="0.19207032024860382 0.02584603615105152 0.08042269200086594" quat="1.0 0.0 0.0 0.0"/>
        <geom class="collision" type="box" pos="0.00039778 -0.00075466 -0.16717361" size="0.287281334400177 0.20857033133506775 0.019608931615948677" quat="1.0 0.0 0.0 0.0"/>
        <geom class="collision" type="cylinder" pos="-0.12338913 0.18286921 0.00269686" size="0.015378177165985107 0.023764031007885933" quat="1.0 0.0 0.0 0.0"/>
        <geom class="collision" type="cylinder" pos="-0.10889814 0.18293495 0.00179391" size="0.011896234005689621 0.004643584135919809" quat="0.7071014046669006 -0.002766991499811411 0.7071013450622559 0.002766991499811411"/>
        <geom class="collision" type="box" pos="-0.09055963 0.17251273 -0.10611788" size="0.005225161090493202 0.025845898315310478 0.08066464960575104" quat="1.0 0.0 0.0 0.0"/>
        <geom class="collision" type="box" pos="-0.06939384 0.19341173 -0.10611786" size="0.025845898315310478 0.00522515969350934 0.08066462725400925" quat="1.0 0.0 0.0 0.0"/>
        <geom class="collision" type="box" pos="-0.05923939 0.16147462 -0.10509981" size="0.025845900177955627 0.005225156433880329 0.07925937324762344" quat="0.9315856695175171 -0.10113897919654846 -0.03768659383058548 0.34712931513786316"/>
        <geom class="collision" type="box" pos="-0.07738153 0.13300913 -0.10312422" size="0.02584589645266533 0.005225156433880329 0.07925937324762344" quat="0.7804167866706848 -0.12432725727558136 -0.024337584152817726 0.6122908592224121"/>
        <geom class="collision" type="box" pos="-0.08554688 0.00506707 -0.10355678" size="0.11396775394678116 0.005225156433880329 0.07925938069820404" quat="0.7045438289642334 -0.0719207376241684 -0.07518203556537628 0.7019922137260437"/>
        <geom class="collision" type="box" pos="0.09477891 -0.18662270 -0.10468359" size="0.11396775394678116 0.005225156433880329 0.07925937324762344" quat="0.005484840366989374 0.010454756207764149 0.08968508243560791 -0.9959002137184143"/>
        <geom class="collision" type="box" pos="-0.07222503 -0.13550728 -0.10720751" size="0.02584589645266533 0.005225156433880329 0.07925937324762344" quat="0.5429361462593079 -0.05733748525381088 -0.08152171969413757 0.833838701248169"/>
        <geom class="collision" type="box" pos="-0.04223741 -0.17192182 -0.10615744" size="0.025845898315310478 0.005225156433880329 0.07925937324762344" quat="0.2774260938167572 -0.04453260824084282 -0.09324575215578079 0.9551737308502197"/>
        <geom class="collision" type="box" pos="0.22865280 -0.17325068 -0.10720751" size="0.02584589645266533 0.005225156433880329 0.07925937324762344" quat="0.20856431126594543 -0.017389820888638496 0.0981375053524971 -0.9729170203208923"/>
        <geom class="collision" type="box" pos="0.25863571 -0.14064262 -0.10615744" size="0.02584589645266533 0.005225156433880329 0.07925937324762344" quat="0.48180389404296875 -0.03473207354545593 0.09732218086719513 -0.8701649904251099"/>
        <geom class="collision" type="box" pos="0.26828486 0.00506707 -0.10313093" size="0.11396775394678116 0.005225156433880329 0.07925938069820404" quat="0.06677046418190002 -0.7022401690483093 -0.7053907513618469 0.06945767253637314"/>
        <geom class="collision" type="box" pos="0.25981987 0.14185652 -0.10734455" size="0.025845900177955627 0.005225156433880329 0.07925937324762344" quat="0.8157275319099426 -0.07961252331733704 0.05996018275618553 -0.5697852373123169"/>
        <geom class="collision" type="box" pos="0.22942055 0.17407675 -0.10629448" size="0.025845900177955627 0.005225156433880329 0.07925937324762344" quat="0.9456391334533691 -0.09174712002277374 0.047543659806251526 -0.30836454033851624"/>
        <geom class="collision" type="box" pos="0.08103766 0.18726265 -0.10513535" size="0.11396776139736176 0.0052251568995416164 0.07925937324762344" quat="0.002029395429417491 -0.0021109217777848244 0.9961948394775391 -0.08710483461618423"/>
        <geom class="collision" type="box" pos="0.27042619 0.18605117 -0.10635983" size="0.025845898315310478 0.04232998192310333 0.0804227888584137" quat="0.9190593957901001 0.0 0.0 0.3941190540790558"/>
        <geom class="collision" type="box" pos="0.26216654 -0.19022184 -0.10635976" size="0.025845900177955627 0.04232998192310333 0.08042271435260773" quat="0.4444805085659027 0.0 0.0 0.8957885503768921"/>
        <geom class="collision" type="box" pos="-0.08565658 -0.18425654 -0.10635971" size="0.025845898315310478 0.04232998192310333 0.08042267709970474" quat="0.9276973605155945 0.0 0.0 0.3733331561088562"/>
        <geom class="collision" type="box" pos="-0.09148322 0.18932817 -0.10635973" size="0.025845900177955627 0.04232998192310333 0.08042269200086594" quat="0.9256194233894348 0.0 -0.0 -0.37845566868782043"/>
        <geom class="collision" type="box" pos="0.21324394 0.18173854 -0.10211369" size="0.02584589645266533 0.0052251568995416164 0.07715897262096405" quat="0.9745601415634155 -0.09655645489692688 0.03680741414427757 -0.1988832950592041"/>
        <geom class="collision" type="box" pos="-0.02899321 0.18115410 -0.10402058" size="0.025845900177955627 0.005225156433880329 0.07925937324762344" quat="0.9735565781593323 -0.09422709792852402 -0.052636709064245224 0.20134100317955017"/>
        <geom class="collision" type="box" pos="-0.20724527 0.14944457 -0.10500268" size="0.04446038976311684 0.005225156433880329 0.07925935834646225" quat="0.002029395429417491 -0.0021109217777848244 0.9961948394775391 -0.08710483461618423"/>
        <geom class="collision" type="box" pos="-0.25862285 0.12916609 -0.10509981" size="0.025845898315310478 0.005225156433880329 0.07925937324762344" quat="0.9061340093612671 -0.10344431549310684 -0.030800145119428635 0.40898874402046204"/>
        <geom class="collision" type="box" pos="-0.15103566 0.13856410 -0.10643145" size="0.025845900177955627 0.005225156433880329 0.07925937324762344" quat="0.9296858310699463 -0.060102034360170364 0.029010022059082985 -0.3622574210166931"/>
        <geom class="collision" type="box" pos="-0.20053644 -0.15208452 -0.10500268" size="0.04446038976311684 0.005225156433880329 0.07925935834646225" quat="0.08711718767881393 -0.9961850047111511 0.004906183574348688 0.0014157721307128668"/>
        <geom class="collision" type="box" pos="-0.14887827 -0.13253184 -0.10509981" size="0.02584589645266533 0.005225156433880329 0.07925937324762344" quat="0.4025959074497223 -0.030070720240473747 0.10365870594978333 -0.9089924097061157"/>
        <geom class="collision" type="box" pos="-0.25658717 -0.14041326 -0.10643145" size="0.025845900177955627 0.005225156433880329 0.07925937324762344" quat="0.3687969446182251 -0.029432643204927444 -0.059896212071180344 0.9271110892295837"/>
        <geom class="collision" type="box" pos="-0.13376733 0.00506707 -0.10355678" size="0.14837190508842468 0.005225186236202717 0.07925985753536224" quat="0.042465563863515854 -0.7042139172554016 -0.7072701454162598 0.04525955766439438"/>
        <geom class="collision" type="box" pos="-0.27700206 0.00506707 -0.10355678" size="0.11396775394678116 0.0052251568995416164 0.07925938069820404" quat="0.7069447636604309 -0.04441684111952782 -0.047575876116752625 0.7042675614356995"/>
        <geom class="collision" type="box" pos="-0.27466094 -0.15430315 -0.10635973" size="0.011584443040192127 0.023624230176210403 0.08042269200086594" quat="0.9276973605155945 0.0 0.0 0.3733331561088562"/>
        <geom class="collision" type="box" pos="-0.13414098 -0.15695864 -0.10635977" size="0.011584443040192127 0.023624230176210403 0.08042272925376892" quat="0.42179039120674133 0.0 0.0 0.9066933989524841"/>
        <geom class="collision" type="box" pos="-0.27567890 0.15320330 -0.10635974" size="0.011584442108869553 0.023624230176210403 0.08042269945144653" quat="0.3680267930030823 0.0 0.0 0.9298151731491089"/>
        <geom class="collision" type="box" pos="-0.14135506 0.15585879 -0.10635971" size="0.011584443040192127 0.023624230176210403 0.08042267709970474" quat="0.8962980508804321 0.0 0.0 0.4434520900249481"/>
        <geom class="collision" type="box" pos="0.00115264 0.23716059 -0.02564474" size="0.32415100932121277 0.01222260482609272 0.00451293308287859" quat="1.0 0.0 0.0 0.0"/>
        <geom class="collision" type="box" pos="0.00115265 -0.23419056 -0.02564474" size="0.32415106892585754 0.01222260482609272 0.004512934945523739" quat="1.0 0.0 0.0 0.0"/>
        <geom class="collision" type="box" pos="0.31145445 -0.00016693 -0.02564474" size="0.012222640216350555 0.24724873900413513 0.0045129405334591866" quat="1.0 0.0 0.0 0.0"/>
        <geom class="collision" type="box" pos="-0.31279993 -0.00016690 -0.02564475" size="0.01222264301031828 0.24724873900413513 0.004512928891927004" quat="1.0 0.0 0.0 0.0"/>
        <body name="handle">
          <joint axis="1.0 0.0 0.0" pos="-0.09311167 0.18299634 0.00189447" limited="true" name="handle_temp_joint" type="hinge" range="-0.7853981633974483 0.7853981633974483" damping="1" frictionloss="1" armature=".01" stiffness="0.05"/>
          <joint axis="0.0 1.0 0.0" pos="-0.09311167 0.18299634 0.00189447" limited="true" name="handle_joint" type="hinge" range="0 0.5" damping="1" frictionloss="1" armature=".01" stiffness="0.05"/>
          <geom mesh="handle_vis" type="mesh" solimp="0.998 0.998 0.001" solref="0.001 1" friction="0.95 0.3 0.1" class="visual" material="handle_material"/>
          <geom class="collision" type="cylinder" pos="-0.09218669 0.18305192 0.00160005" size="0.012242971919476986 0.005963981617242098" quat="0.7071014046669006 -0.002766991499811411 0.7071013450622559 0.002766991499811411"/>
          <geom name="handle_main" class="collision" type="box" pos="-0.08835223 0.18299953 0.03800136" size="0.0020829199347645044 0.005032389424741268 0.023850250989198685" quat="0.9999874830245972 0.0 -0.0 -0.005006327759474516"/>
        </body>
        <body name="Funnel001">
          <geom mesh="Funnel001_vis" type="mesh" solimp="0.998 0.998 0.001" solref="0.001 1" friction="0.95 0.3 0.1" class="visual" material="Funnel001_material"/>
        </body>
        <body name="Funnel002">
          <geom mesh="Funnel002_vis" type="mesh" solimp="0.998 0.998 0.001" solref="0.001 1" friction="0.95 0.3 0.1" class="visual" material="Funnel002_material"/>
        </body>
        <body name="spout">
          <joint axis="0.0 0.0 1.0" pos="-0.12329047 0.18267258 0.10712221" limited="true" name="spout_joint" range="-0.7853981633974483 0.7853981633974483" type="hinge" damping="1" frictionloss="1" armature=".01" stiffness="0.05"/>
          <site type="cylinder" rgba="0.5 0.75 1 0.5" size="0.003978706896305084 0.16658493876457214" pos="-0.12462452 0.05335313 -0.00141883" name="water"/>
          <geom mesh="spout_vis" type="mesh" solimp="0.998 0.998 0.001" solref="0.001 1" friction="0.95 0.3 0.1" class="visual" material="spout_material"/>
          <geom class="collision" type="cylinder" pos="-0.12328100 0.18270586 0.10798463" size="0.015337559394538403 0.08002017438411713" quat="0.9449544548988342 0.0 0.0 0.32720187306404114" name="spout_main"/>
          <geom class="collision" type="box" pos="-0.12428731 0.10692272 0.17342079" size="0.014858418144285679 0.06735827773809433 0.007122769020497799" quat="0.9999867677688599 0.0 -0.0 -0.005144515074789524"/>
          <geom class="collision" type="cylinder" pos="-0.12451452 0.05347980 0.15697777" size="0.008447862230241299 0.009460891596972942" quat="0.9449544548988342 0.0 0.0 0.32720187306404114"/>
        </body>
        <geom class="region" name="reg_basin_right" type="box" pos="0.09399911 0.001375169999999995 -0.08619668500000001" size="0.13950502 0.14709323000000002 0.057271205000000006"/>
        <geom class="region" name="reg_basin_left" type="box" pos="-0.20922971499999998 -0.007646465000000005 -0.08606540500000001" size="0.042423635 0.118041615 0.05710645500000001"/>
        <geom class="region" name="reg_main" type="box" pos="-8.950000000007563e-07 4.7000000000241293e-07 -0.103957145" size="0.326304775 0.25099641 0.083825335"/>
      </body>
    </body>
  </worldbody>
  <actuator>
    <motor name="handle_joint_actuator" joint="handle_joint" gear="10"/>
    <motor name="handle_temp_joint_actuator" joint="handle_temp_joint" gear="10"/>
    <motor name="spout_joint_actuator" joint="spout_joint" gear="10"/>
  </actuator>
</mujoco>
