<?xml version='1.0' encoding='UTF-8'?>
<mujoco model="model">
  <option timestep="0.002" gravity="0.0 0.0 -9.81"/>
  <compiler angle="radian"/>
  <asset>
    <mesh file="visuals/sideL_button_cancel.obj" name="sideL_button_cancel_vis"/>
    <mesh file="visuals/sideL_knob_doneness.obj" name="sideL_knob_doneness_vis"/>
    <mesh file="visuals/sideL_lever.obj" name="sideL_lever_vis"/>
    <mesh file="visuals/sideR_button_cancel.obj" name="sideR_button_cancel_vis"/>
    <mesh file="visuals/sideR_knob_doneness.obj" name="sideR_knob_doneness_vis"/>
    <mesh file="visuals/sideR_lever.obj" name="sideR_lever_vis"/>
    <mesh file="visuals/Body001.obj" name="Body001_vis"/>
    <texture file="visuals/T_BC001.png" name="Body001_material" type="2d"/>
    <material name="Body001_material" rgba="1 1 1 1.0" texture="Body001_material" shininess="0.5" specular="0.8"/>
    <texture file="visuals/T_BC001.png" name="sideL_button_cancel_material" type="2d"/>
    <material name="sideL_button_cancel_material" rgba="1 1 1 1.0" texture="sideL_button_cancel_material" shininess="0.5" specular="1"/>
    <texture file="visuals/T_BC001.png" name="sideL_knob_doneness_material" type="2d"/>
    <material name="sideL_knob_doneness_material" rgba="1 1 1 1.0" texture="sideL_knob_doneness_material" shininess="0.5" specular="1"/>
    <texture file="visuals/T_BC001.png" name="sideL_lever_material" type="2d"/>
    <material name="sideL_lever_material" rgba="1 1 1 1.0" texture="sideL_lever_material" shininess="0.5" specular="1"/>
    <texture file="visuals/T_BC001.png" name="sideR_button_cancel_material" type="2d"/>
    <material name="sideR_button_cancel_material" rgba="1 1 1 1.0" texture="sideR_button_cancel_material" shininess="0.5" specular="1"/>
    <texture file="visuals/T_BC001.png" name="sideR_knob_doneness_material" type="2d"/>
    <material name="sideR_knob_doneness_material" rgba="1 1 1 1.0" texture="sideR_knob_doneness_material" shininess="0.5" specular="1"/>
    <texture file="visuals/T_BC001.png" name="sideR_lever_material" type="2d"/>
    <material name="sideR_lever_material" rgba="1 1 1 1.0" texture="sideR_lever_material" shininess="0.5" specular="1"/>
  </asset>
  <default>
    <default class="visual">
      <geom conaffinity="0" contype="0" group="1" type="mesh"/>
    </default>
    <default class="collision_1">
      <geom group="0" rgba="0.5 0 0 0.5" solref="0.004 1" solimp="0.998 0.998 0.001"/>
    </default>
    <default class="collision_2">
      <geom group="0" rgba="0.5 0 0 0.5" solref="0.004 1" solimp="0.998 0.998 0.001"/>
    </default>
    <default class="collision_3">
      <geom group="0" rgba="0.5 0 0 0.5" solref="0.004 1" solimp="0.998 0.998 0.001"/>
    </default>
    <default class="collision_4">
      <geom group="0" rgba="0.5 0 0 0.5" solref="0.004 1" solimp="0.998 0.998 0.001"/>
    </default>
    <default class="collision_5">
      <geom group="0" rgba="0.5 0 0 0.5" solref="0.004 1" solimp="0.998 0.998 0.001"/>
    </default>
    <default class="collision_6">
      <geom group="0" rgba="0.5 0 0 0.5" solref="0.004 1" solimp="0.998 0.998 0.001"/>
    </default>
    <default class="collision_7">
      <geom group="0" rgba="0.5 0 0 0.5" solref="0.004 1" solimp="0.998 0.998 0.001"/>
    </default>
    <default class="spawn">
      <geom group="0" rgba="1 1 1 0.5" contype="0" conaffinity="0"/>
      <site group="0" rgba="1 1 1 0.5"/>
    </default>
    <default class="region">
      <geom group="1" conaffinity="0" contype="0" rgba="0 1 0 0" mass="0"/>
    </default>
  </default>
  <worldbody>
    <body>
      <body name="object">
        <geom mesh="Body001_vis" type="mesh" solimp="0.998 0.998 0.001" solref="0.001 1" friction="0.95 0.3 0.1" class="visual" material="Body001_material"/>
        <geom type="box" pos="0.00000000 0.00940626 -0.07077789" size="0.15093529224395752 0.1104334369301796 0.022948309779167175" quat="1.0 0.0 0.0 0.0" class="collision_1"/>
        <geom type="box" pos="0.00000000 0.09704461 0.02173615" size="0.13765887916088104 0.014824471436440945 0.022948309779167175" quat="1.0 0.0 0.0 0.0" class="collision_1"/>
        <geom type="box" pos="-0.00013554 0.09431498 0.07045700" size="0.12757332623004913 0.012452364899218082 0.02426888793706894" quat="1.0 0.0 0.0 0.0" class="collision_1"/>
        <geom type="box" pos="0.00000000 -0.07095163 0.07045700" size="0.1274377852678299 0.014194607734680176 0.02426888793706894" quat="1.0 0.0 0.0 0.0" class="collision_1"/>
        <geom type="box" pos="-0.12577364 0.00444608 0.02173615" size="0.014984704554080963 0.07420015335083008 0.02294839173555374" quat="1.0 0.0 0.0 0.0" class="collision_1"/>
        <geom type="box" pos="-0.11411787 0.00520545 0.07034178" size="0.015380154363811016 0.07584980875253677 0.02426861599087715" quat="1.0 0.0 0.0 0.0" class="collision_1"/>
        <geom type="box" pos="0.12300202 0.00027097 0.02173615" size="0.016548022627830505 0.07668700814247131 0.02294783666729927" quat="1.0 0.0 0.0 0.0" class="collision_1"/>
        <geom type="box" pos="0.11462644 0.00356586 0.07058856" size="0.0166690181940794 0.07728996872901917 0.02426888793706894" quat="1.0 0.0 0.0 0.0" class="collision_1"/>
        <geom type="box" pos="-0.05518054 0.01270593 0.05973982" size="0.014374571852385998 0.06940566748380661 0.03724751994013786" quat="1.0 0.0 0.0 0.0" class="collision_1"/>
        <geom type="box" pos="0.00034491 0.01270593 0.05973982" size="0.011652554385364056 0.06940566003322601 0.037247635424137115" quat="1.0 0.0 0.0 0.0" class="collision_1"/>
        <geom type="box" pos="0.05497347 0.01270593 0.05973982" size="0.014171146787703037 0.069404736161232 0.037247978150844574" quat="1.0 0.0 0.0 0.0" class="collision_1"/>
        <geom type="box" pos="-0.00000000 -0.07869960 0.02286830" size="0.13765887916088104 0.011381338350474834 0.022948311641812325" quat="0.9988005757331848 -0.048963017761707306 1.0871969798932527e-17 -1.478460231598969e-24" class="collision_1"/>
        <geom type="box" pos="0.00000000 0.10472535 -0.01845559" size="0.14615358412265778 0.011247177608311176 0.02679312415421009" quat="1.0 0.0 0.0 0.0" class="collision_1"/>
        <geom type="box" pos="0.00000000 -0.07952600 -0.01845559" size="0.14615358412265778 0.011247174814343452 0.02679312415421009" quat="1.0 0.0 0.0 0.0" class="collision_1"/>
        <geom type="box" pos="-0.13292025 0.01194264 -0.01981102" size="0.015164616517722607 0.07797303795814514 0.02679312415421009" quat="0.9989761710166931 -4.4053948005657706e-16 0.0452394038438797 -1.5484783455477213e-09" class="collision_1"/>
        <geom type="box" pos="0.13039266 0.01194264 -0.02066867" size="0.015164618380367756 0.07797303795814514 0.02679312601685524" quat="0.9976035952568054 -2.6082881421170723e-16 -0.06918864697217941 2.3682258376567233e-09" class="collision_1"/>
        <body name="sideL_button_cancel">
          <joint axis="0.0 0.992957592010498 -0.11847041547298431" pos="-0.09366097 -0.09360679 0.03181589" limited="true" name="sideL_button_cancel_joint" range="0.0 0.003" type="slide" damping="1" frictionloss="1" armature=".01" stiffness="0.2" springref="-0.1"/>
          <geom mesh="sideL_button_cancel_vis" type="mesh" solimp="0.998 0.998 0.001" solref="0.001 1" friction="0.95 0.3 0.1" class="visual" material="sideL_button_cancel_material"/>
          <geom class="collision_2" type="box" pos="-0.09374179 -0.09599165 0.03246795" size="0.003607057500630617 0.0006552753038704395 0.01218100730329752" quat="0.9980376362800598 -0.0626167431473732 1.3903713302573094e-17 -2.9686382030840907e-24" name="sideL_button_cancel_main"/>
        </body>
        <body name="sideL_knob_doneness">
          <joint axis="0.0 0.9977890849113464 -0.06645891070365906" pos="-0.07737011 -0.10765579 -0.02615916" limited="true" name="sideL_knob_doneness_joint" range="0.0 4.276056667386108" type="hinge" damping="0.05" armature="0.001"/>
          <geom mesh="sideL_knob_doneness_vis" type="mesh" solimp="0.998 0.998 0.001" solref="0.001 1" friction="0.95 0.3 0.1" class="visual" material="sideL_knob_doneness_material"/>
          <geom type="cylinder" pos="-0.07737018 -0.10314882 -0.02635292" size="0.01965203881263733 0.005387690383940935" quat="0.7274610996246338 0.6861489415168762 -1.523556706388432e-16 5.119599595370804e-24" class="collision_3"/>
          <geom class="collision_3" type="box" pos="-0.07762850 -0.11319786 -0.02588205" size="0.016234053298830986 0.0054860045202076435 0.004217417910695076" quat="0.9710913300514221 2.9724225768835717e-16 -0.23870821297168732 8.170633947202077e-09" name="sideL_knob_doneness_main"/>
        </body>
        <body name="sideL_lever">
          <joint axis="-2.6346724905051047e-17 -0.11865510046482086 -0.9929355978965759" pos="-0.03429602 -0.09949766 0.04578988" limited="true" name="sideL_lever_joint" range="0.0 0.06" type="slide" damping="1" frictionloss="1" armature=".01" stiffness="1" springref="-1"/>
          <geom class="region" name="reg_sideL_slotL" type="box" pos="-0.084131095 0.01456584 0.09565963999999999" size="0.011496275 0.06019422000000001 0.07600008"/>
          <geom class="region" name="reg_sideL_slotR" type="box" pos="-0.02629522 0.01456584 0.09565963999999999" size="0.01254893 0.06019422000000001 0.07600008"/>
          <geom mesh="sideL_lever_vis" type="mesh" solimp="0.998 0.998 0.001" solref="0.001 1" friction="0.95 0.3 0.1" class="visual" material="sideL_lever_material"/>
          <geom class="collision_4" type="box" pos="-0.08424067 0.01456114 0.01566017" size="0.013065160252153873 0.06504657119512558 0.00047058789641596377" quat="1.0 0.0 0.0 0.0" name="sideL_slotL_floor"/>
          <geom class="collision_4" type="box" pos="-0.02612666 0.01456115 0.01566017" size="0.013133001513779163 0.06504657864570618 0.00047059060307219625" quat="1.0 0.0 0.0 0.0" name="sideL_slotR_floor"/>
          <geom class="collision_4" type="cylinder" pos="-0.03461213 -0.10596226 0.04598620" size="0.012125927023589611 0.0031209716107696295" quat="1.0 0.0 0.0 0.0" name="sideL_lever_handle"/>
          <geom type="box" pos="-0.03403327 -0.09081052 0.04580460" size="0.00280679389834404 0.0012262039817869663 0.001948524615727365" quat="1.0 0.0 0.0 0.0" class="collision_4"/>
        </body>
        <body name="sideR_button_cancel">
          <joint axis="0.0 0.992957592010498 -0.11847041547298431" pos="0.09366097 -0.09360679 0.03181589" limited="true" name="sideR_button_cancel_joint" range="0.0 0.003" type="slide" damping="1" frictionloss="1" armature=".01" stiffness="0.2" springref="-0.1"/>
          <geom mesh="sideR_button_cancel_vis" type="mesh" solimp="0.998 0.998 0.001" solref="0.001 1" friction="0.95 0.3 0.1" class="visual" material="sideR_button_cancel_material"/>
          <geom class="collision_5" type="box" pos="0.09374186 -0.09599165 0.03246795" size="0.003607057500630617 0.0006552753038704395 0.01218100730329752" quat="0.9980376362800598 -0.0626167431473732 1.3903713302573094e-17 -2.9686382030840907e-24" name="sideR_button_cancel_main"/>
        </body>
        <body name="sideR_knob_doneness">
          <joint axis="0.0 0.997789204120636 -0.06645891070365906" pos="0.07737032 -0.10770656 -0.02615224" limited="true" name="sideR_knob_doneness_joint" range="0.0 4.276056667386108" type="hinge" damping="0.05" armature="0.001"/>
          <geom mesh="sideR_knob_doneness_vis" type="mesh" solimp="0.998 0.998 0.001" solref="0.001 1" friction="0.95 0.3 0.1" class="visual" material="sideR_knob_doneness_material"/>
          <geom type="cylinder" pos="0.07715547 -0.10314882 -0.02635292" size="0.01965203881263733 0.005387690383940935" quat="0.7274610996246338 0.6861489415168762 -1.523556706388432e-16 5.119599595370804e-24" class="collision_6"/>
          <geom class="collision_6" type="box" pos="0.07775127 -0.11319786 -0.02588205" size="0.016234053298830986 0.0054860045202076435 0.004217417910695076" quat="0.9710913300514221 2.9724225768835717e-16 -0.23870821297168732 8.170633947202077e-09" name="sideR_knob_doneness_main"/>
        </body>
        <body name="sideR_lever">
          <joint axis="-2.6346724905051047e-17 -0.11865510046482086 -0.9929355978965759" pos="0.03461206 -0.09949766 0.04578988" limited="true" name="sideR_lever_joint" range="0.0 0.06" type="slide" damping="1" frictionloss="1" armature=".01" stiffness="1" springref="-1"/>
          <geom class="region" name="reg_sideR_slotL" type="box" pos="0.025938845000000002 0.01456584 0.09565963999999999" size="0.011874015000000002 0.06019422000000001 0.07600008"/>
          <geom class="region" name="reg_sideR_slotR" type="box" pos="0.08364371500000001 0.01456584 0.09565963999999999" size="0.011699124999999998 0.06019422000000001 0.07600008"/>
          <geom mesh="sideR_lever_vis" type="mesh" solimp="0.998 0.998 0.001" solref="0.001 1" friction="0.95 0.3 0.1" class="visual" material="sideR_lever_material"/>
          <geom class="collision_7" type="box" pos="0.02634382 0.01456114 0.01566028" size="0.013275045901536942 0.06504658609628677 0.00047059025382623076" quat="1.0 0.0 0.0 0.0" name="sideR_slotL_floor"/>
          <geom class="collision_7" type="box" pos="0.08314843 0.01456114 0.01566028" size="0.012585317716002464 0.06504657864570618 0.0004705892060883343" quat="1.0 0.0 0.0 0.0" name="sideR_slotR_floor"/>
          <geom class="collision_7" type="cylinder" pos="0.03457708 -0.10582397 0.04598620" size="0.012125923298299313 0.0031209716107696295" quat="1.0 0.0 1.5407439555097887e-33 0.0" name="sideR_lever_handle"/>
          <geom type="box" pos="0.03463467 -0.09081052 0.04580460" size="0.002806799951940775 0.0012262053787708282 0.0019485288066789508" quat="1.0 0.0 0.0 0.0" class="collision_7"/>
        </body>
        <geom class="region" name="reg_main" type="box" pos="-4.999999997368221e-09 0.009404999999999997 0.0" size="0.152049805 0.11077471 0.09609316"/>
      </body>
    </body>
  </worldbody>
  <actuator>
    <motor name="sideL_button_cancel_joint_actuator" joint="sideL_button_cancel_joint" gear="0.1"/>
    <motor name="sideL_knob_doneness_joint_actuator" joint="sideL_knob_doneness_joint" gear="10"/>
    <motor name="sideL_lever_joint_actuator" joint="sideL_lever_joint" gear="2"/>
    <motor name="sideR_button_cancel_joint_actuator" joint="sideR_button_cancel_joint" gear="0.1"/>
    <motor name="sideR_knob_doneness_joint_actuator" joint="sideR_knob_doneness_joint" gear="10"/>
    <motor name="sideR_lever_joint_actuator" joint="sideR_lever_joint" gear="2"/>
  </actuator>
</mujoco>
