<?xml version='1.0' encoding='UTF-8'?>
<mujoco model="model">
  <option timestep="0.002" gravity="0.0 0.0 -9.81"/>
  <compiler angle="radian"/>
  <asset>
    <mesh file="visuals/door.obj" name="door_vis"/>
    <mesh file="visuals/door_Clear.obj" name="door_Clear_vis"/>
    <mesh file="visuals/knob_temp.obj" name="knob_temp_vis"/>
    <mesh file="visuals/knob_time.obj" name="knob_time_vis"/>
    <mesh file="visuals/Body001.obj" name="Body001_vis"/>
    <mesh file="visuals/rack0.obj" name="rack0_vis"/>
    <texture file="visuals/T_BC001.png" name="Body001_material" type="2d"/>
    <material name="Body001_material" rgba="1 1 1 1.0" texture="Body001_material" shininess="0.1" specular="2"/>
    <texture file="visuals/T_BC001.png" name="door_material" type="2d"/>
    <material name="door_material" rgba="1 1 1 1.0" texture="door_material" shininess="0.1" specular="2"/>
    <texture file="visuals/T_BC001.png" name="door_Clear_material" type="2d"/>
    <material name="door_Clear_material" rgba="1 1 1 0.699999988079071" texture="door_Clear_material" shininess="0.1" specular="2"/>
    <texture file="visuals/T_BC001.png" name="knob_temp_material" type="2d"/>
    <material name="knob_temp_material" rgba="1 1 1 1.0" texture="knob_temp_material" shininess="0.1" specular="2"/>
    <texture file="visuals/T_BC001.png" name="knob_time_material" type="2d"/>
    <material name="knob_time_material" rgba="1 1 1 1.0" texture="knob_time_material" shininess="0.1" specular="2"/>
    <texture file="visuals/T_BC001.png" name="rack0_material" type="2d"/>
    <material name="rack0_material" rgba="1 1 1 1.0" texture="rack0_material" shininess="0.1" specular="2"/>
  </asset>
  <default>
    <default class="visual">
      <geom conaffinity="0" contype="0" group="1" type="mesh"/>
    </default>
    <default class="collision">
      <geom group="0" rgba="0.5 0 0 0.5"/>
    </default>
    <default class="spawn">
      <geom group="0" rgba="1 1 1 0.5" contype="0" conaffinity="0"/>
      <site group="0" rgba="1 1 1 0.5"/>
    </default>
    <default class="region">
      <geom group="1" conaffinity="0" contype="0" rgba="0 1 0 0"/>
    </default>
  </default>
  <worldbody>
    <body>
      <body name="object">
        <geom mesh="Body001_vis" type="mesh" solimp="0.998 0.998 0.001" solref="0.001 1" friction="0.95 0.3 0.1" class="visual" material="Body001_material"/>
        <geom class="collision" type="box" pos="-0.33505768 0.03734199 -0.01160994" size="0.019283024594187737 0.21519224345684052 0.3147348165512085" quat="1.0 0.0 0.0 0.0"/>
        <geom class="collision" type="box" pos="0.33195981 0.03734194 -0.01160994" size="0.02430092729628086 0.21519237756729126 0.31473508477211" quat="1.0 0.0 0.0 0.0"/>
        <geom class="collision" type="box" pos="0.00534328 0.03734175 -0.29232646" size="0.34893864393234253 0.2151922881603241 0.03400268033146858" quat="1.0 0.0 0.0 0.0"/>
        <geom class="collision" type="box" pos="0.00534331 0.03734171 0.23121967" size="0.34893864393234253 0.21519242227077484 0.07190866023302078" quat="1.0 0.0 0.0 0.0"/>
        <geom class="collision" type="box" pos="-0.00011246 -0.18920712 0.25214111" size="0.3764316141605377 0.011466951109468937 0.07451142370700836" quat="1.0 0.0 0.0 0.0"/>
        <geom class="collision" type="box" pos="-0.31837842 0.03755784 -0.03748379" size="0.010815974324941635 0.19568881392478943 0.005391944199800491" quat="1.0 0.0 0.0 0.0"/>
        <geom class="collision" type="box" pos="0.30868345 0.03755784 -0.03748379" size="0.010815974324941635 0.19568897783756256 0.005391949322074652" quat="1.0 0.0 0.0 0.0"/>
        <geom class="collision" type="box" pos="0.00534331 0.23777639 0.01949205" size="0.34893864393234253 0.014759241603314877 0.2836351990699768" quat="1.0 0.0 0.0 0.0"/>
        <body name="door">
          <joint axis="1.0 0.0 0.0" pos="2.078e-05 -0.20137755361799659 -0.31849180957141876" limited="true" name="door_joint" range="0.0 1.15" type="hinge" damping="1" frictionloss="1" armature="1" stiffness="2"/>
          <geom mesh="door_vis" type="mesh" solimp="0.998 0.998 0.001" solref="0.001 1" friction="0.95 0.3 0.1" class="visual" material="door_material"/>
          <geom class="collision" type="box" pos="0.00157031 -0.18669690 -0.07338551" size="0.35471275448799133 0.007204413879662752 0.242497980594635" quat="1.0 0.0 0.0 0.0"/>
          <geom class="collision" type="box" pos="0.00002078 -0.19795781 -0.07539741" size="0.37640616297721863 0.0034197436179965734 0.24309439957141876" quat="1.0 0.0 0.0 0.0" name="door_main"/>
          <geom class="collision" type="box" pos="-0.30970249 -0.21283459 0.15632437" size="0.005096600390970707 0.011907828040421009 0.014070375822484493" quat="1.0 0.0 0.0 0.0"/>
          <geom class="collision" type="box" pos="0.31947091 -0.21283459 0.15632437" size="0.005096600390970707 0.011907828040421009 0.014070375822484493" quat="1.0 0.0 0.0 0.0"/>
          <geom class="collision" type="box" pos="0.00075840 -0.23801475 0.15626089" size="0.330466628074646 0.017917407676577568 0.017917409539222717" quat="1.0 0.0 0.0 0.0" name="door_handle_main"/>
          <body name="door_Clear">
            <geom mesh="door_Clear_vis" type="mesh" solimp="0.998 0.998 0.001" solref="0.001 1" friction="0.95 0.3 0.1" class="visual" material="door_Clear_material"/>
          </body>
        </body>
        <body name="knob_temp">
          <joint axis="0.0 1.0 0.0" pos="0.20950517 -0.21150000 0.26849842" limited="true" name="knob_temp_joint" range="0.0 5.585053606381854" type="hinge" damping="0.05" armature="1" frictionloss="0.75"/>
          <geom mesh="knob_temp_vis" type="mesh" solimp="0.998 0.998 0.001" solref="0.001 1" friction="0.95 0.3 0.1" class="visual" material="knob_temp_material"/>
          <geom class="collision" type="box" pos="0.20932555 -0.21096106 0.26867267" size="0.010200371034443378 0.008497285656630993 0.02675803191959858" quat="1.0 0.0 0.0 0.0" name="knob_temp_main" friction="100 0.5 0.01"/>
        </body>
        <body name="knob_time">
          <joint axis="0.0 1.0 0.0" pos="-0.21009600 -0.21150000 0.26849213" limited="true" name="knob_time_joint" range="0.0 5.235987755982989" type="hinge" damping="0.05" armature="1" frictionloss="0.75"/>
          <geom mesh="knob_time_vis" type="mesh" solimp="0.998 0.998 0.001" solref="0.001 1" friction="0.95 0.3 0.1" class="visual" material="knob_time_material"/>
          <geom class="collision" type="box" pos="-0.21009015 -0.21096106 0.26867270" size="0.02675819955766201 0.008497263304889202 0.01020028255879879" quat="1.0 0.0 0.0 0.0" name="knob_time_main" friction="100 0.5 0.01"/>
        </body>
        <body name="rack0">
          <geom class="region" name="reg_rack0" type="box" pos="-0.0038322650000000014 0.015266425 0.06627683999999999" size="0.300044925 0.162804915 0.08700524"/>
          <joint axis="0.0 -1.0 0.0" pos="-0.00429360 0.01529943 -0.02903694" limited="true" name="rack0_joint" range="0.0 0.29" type="slide" damping="1" frictionloss="1" armature=".01" stiffness="0.05"/>
          <geom mesh="rack0_vis" type="mesh" solimp="0.998 0.998 0.001" solref="0.001 1" friction="0.95 0.3 0.1" class="visual" material="rack0_material"/>
          <geom class="collision" type="box" pos="-0.00444339 0.01536123 -0.02885869" size="0.3110940158367157 0.1721295863389969 0.002637086668983102" quat="1.0 0.0 0.0 0.0"/>
        </body>
        <geom class="region" name="reg_int" type="box" pos="-0.004039569999999992 0.022458085000000003 -0.049980264999999996" size="0.30675131 0.195501945 0.203397515"/>
        <geom class="region" name="reg_main" type="box" pos="9.999999994736442e-09 0.02507999999999999 -0.0021069999999999978" size="0.37758724 0.22845524 0.32975994"/>
      </body>
    </body>
  </worldbody>
  <actuator>
    <motor name="door_joint_actuator" joint="door_joint" gear="50"/>
    <motor name="knob_temp_joint_actuator" joint="knob_temp_joint" gear="50"/>
    <motor name="knob_time_joint_actuator" joint="knob_time_joint" gear="50"/>
    <motor name="rack0_joint_actuator" joint="rack0_joint" gear="50"/>
  </actuator>
</mujoco>