<?xml version='1.0' encoding='UTF-8'?>
<mujoco model="model">
  <option timestep="0.002" gravity="0.0 0.0 -9.81"/>
  <compiler angle="radian"/>
  <asset>
    <mesh file="visuals/door.obj" name="door_vis"/>
    <mesh file="visuals/door_Clear.obj" name="door_Clear_vis"/>
    <mesh file="visuals/Body001.obj" name="Body001_vis"/>
    <mesh file="visuals/Disc001.obj" name="Disc001_vis"/>
    <texture file="visuals/T_BC001.png" name="Body001_material" type="2d"/>
    <material name="Body001_material" rgba="1 1 1 1.0" texture="Body001_material" shininess="0.5" specular="2"/>
    <texture file="visuals/T_BC001.png" name="door_material" type="2d"/>
    <material name="door_material" rgba="1 1 1 1.0" texture="door_material" shininess="0.5" specular="2"/>
    <texture file="visuals/T_BC001.png" name="door_Clear_material" type="2d"/>
    <material name="door_Clear_material" rgba="1 1 1 0.699999988079071" texture="door_Clear_material" shininess="0.5" specular="1"/>
    <texture file="visuals/T_BC001.png" name="Disc001_material" type="2d"/>
    <material name="Disc001_material" rgba="1 1 1 1.0" texture="Disc001_material" shininess="0.5" specular="2"/>
  </asset>
  <default>
    <default class="visual">
      <geom conaffinity="0" contype="0" group="1" type="mesh"/>
    </default>
    <default class="collision">
      <geom group="0" rgba="0.5 0 0 0.5"/>
    </default>
    <default class="spawn">
      <geom group="0" rgba="1 1 1 0.5" contype="0" conaffinity="0"/>
      <site group="0" rgba="1 1 1 0.5"/>
    </default>
    <default class="region">
      <geom group="1" conaffinity="0" contype="0" rgba="0 1 0 0"/>
    </default>
  </default>
  <worldbody>
    <body>
      <body name="object">
        <geom class="collision" type="cylinder" pos="-0.05468723 -0.01058693 -0.14799659" size="0.16692419350147247 0.0016871257685124874" quat="1.0 0.0 0.0 0.0" name="tray" rgba="0 1 0 0.5"/>
        <geom class="collision" type="box" pos="0.27547468 -0.23399280 -0.08502374" size="0.013391491957008839 0.0010977822821587324 0.008388223126530647" quat="1.0 0.0 0.0 0.0" name="start_button" rgba="0.0 0.5 0 0.5"/>
        <geom class="collision" type="box" pos="0.22040416 -0.23399280 -0.08502374" size="0.01339150220155716 0.0010977822821587324 0.008388223126530647" quat="1.0 0.0 0.0 0.0" name="stop_button" rgba="0.0 0.5 0 0.5"/>
        <geom mesh="Body001_vis" type="mesh" solimp="0.998 0.998 0.001" solref="0.001 1" friction="0.95 0.3 0.1" class="visual" material="Body001_material"/>
        <geom class="collision" type="box" pos="-0.01199733 0.03515721 0.16092911" size="0.2781570553779602 0.2375412881374359 0.014522206969559193" quat="1.0 0.0 0.0 0.0"/>
        <geom class="collision" type="box" pos="-0.04028525 0.03515726 -0.16748843" size="0.25267335772514343 0.23754151165485382 0.00814619567245245" quat="1.0 0.0 0.0 0.0"/>
        <geom class="collision" type="box" pos="-0.29934488 0.03930693 -0.00003569" size="0.008127178996801376 0.2345574051141739 0.17521588504314423" quat="1.0 0.0 0.0 0.0"/>
        <geom class="collision" type="box" pos="-0.30557646 0.04019809 0.00776376" size="0.00692749535664916 0.20491495728492737 0.1239769384264946" quat="1.0 0.0 0.0 0.0"/>
        <geom class="collision" type="box" pos="0.25932936 0.02196794 -0.00003567" size="0.04693977162241936 0.25341349840164185 0.17521433532238007" quat="1.0 0.0 0.0 0.0"/>
        <geom class="collision" type="box" pos="0.30582093 0.04019809 0.00776376" size="0.006695611868053675 0.20491527020931244 0.12397713214159012" quat="1.0 0.0 0.0 0.0"/>
        <geom class="collision" type="box" pos="-0.01947560 0.22568462 -0.00067893" size="0.28539082407951355 0.05013616383075714 0.17457124590873718" quat="1.0 0.0 0.0 0.0"/>
        <geom class="collision" type="box" pos="0.18414085 -0.01299822 -0.00273758" size="0.02824878878891468 0.1878320723772049 0.11487241089344025" quat="1.0 0.0 0.0 0.0"/>
        <body name="door">
          <joint axis="0.0 0.0 1.0" pos="-0.28508385 -0.22319469 -0.00506721" limited="true" name="microjoint" range="-1.5707963267948966 0.0" type="hinge" damping="1" frictionloss="1" armature=".01" stiffness="0.05"/>
          <geom mesh="door_vis" type="mesh" solimp="0.998 0.998 0.001" solref="0.001 1" friction="0.95 0.3 0.1" class="visual" material="door_material"/>
          <geom class="collision" type="box" pos="-0.04323483 -0.22098480 -0.00128351" size="0.22930869460105896 0.011220528744161129 0.17378352582454681" quat="1.0 0.0 0.0 0.0" name="door_main"/>
          <geom class="collision" type="box" pos="-0.05357160 -0.23522090 -0.00366319" size="0.19063909351825714 0.0018959838198497891 0.09010432660579681" quat="1.0 0.0 0.0 0.0"/>
          <geom class="collision" type="box" pos="0.16861270 -0.25005739 0.09338046" size="0.008060113526880741 0.012087414041161537 0.007869666442275047" quat="1.0 0.0 0.0 0.0"/>
          <geom class="collision" type="box" pos="0.16861270 -0.25005739 -0.10834935" size="0.008060119114816189 0.012087421491742134 0.007869672030210495" quat="1.0 0.0 0.0 0.0"/>
          <geom class="collision" type="box" pos="0.16861270 -0.26585298 0.07919264" size="0.011003851890563965 0.02170410566031933 0.0042842356488108635" quat="0.6625279188156128 -0.7490372061729431 -1.6631969698859998e-16 8.487738654533709e-24"/>
          <geom class="collision" type="box" pos="0.16861270 -0.26932983 -0.00796175" size="0.011003851890563965 0.004525520373135805 0.06377788633108139" quat="1.0 0.0 0.0 0.0" name="door_handle_main"/>
          <geom class="collision" type="box" pos="0.16861270 -0.26626222 -0.09602845" size="0.011003851890563965 0.02266821824014187 0.0042842356488108635" quat="0.7379992604255676 -0.6748015284538269 -1.4983606525811687e-16 2.1780897666146301e-23"/>
          <body name="door_Clear">
            <geom mesh="door_Clear_vis" type="mesh" solimp="0.998 0.998 0.001" solref="0.001 1" friction="0.95 0.3 0.1" class="visual" material="door_Clear_material"/>
            <geom class="collision" type="box" pos="-0.05357160 -0.23522090 -0.00366319" size="0.19063909351825714 0.0018959838198497891 0.09010432660579681" quat="1.0 0.0 0.0 0.0"/>
          </body>
        </body>
        <body name="Disc001">
          <joint axis="0.0 0.0 1.0" pos="-0.05456707 -0.01058821 -0.15472470" limited="false" name="Disc001_joint" range="0 360" type="hinge" damping="1" frictionloss="1" armature=".01" stiffness="0.05"/>
          <geom mesh="Disc001_vis" type="mesh" solimp="0.998 0.998 0.001" solref="0.001 1" friction="0.95 0.3 0.1" class="visual" material="Disc001_material"/>
          <geom class="collision" type="cylinder" pos="-0.05468723 -0.01058693 -0.15364919" size="0.16692419350147247 0.0016871365951374173" quat="1.0 0.0 0.0 0.0"/>
        </body>
        <geom class="region" name="reg_int" type="box" pos="-0.06875119 -0.015883660000000008 -0.0005967299999999898" size="0.22136246999999998 0.18750304 0.14671275"/>
        <geom class="region" name="reg_main" type="box" pos="-5.000000000143778e-08 0.019406564999999987 4.800000000110272e-07" size="0.31600024000000004 0.259092465 0.17850001"/>
      </body>
    </body>
  </worldbody>
  <actuator>
    <motor name="microjoint_actuator" joint="microjoint" gear="10"/>
    <motor name="Disc001_joint_actuator" joint="Disc001_joint" gear="20"/>
  </actuator>
</mujoco>
