<?xml version='1.0' encoding='UTF-8'?>
<mujoco model="model">
  <option timestep="0.005" gravity="0.0 0.0 -9.81"/>
  <compiler angle="radian"/>
  <asset>
    <mesh file="visuals/freezer0.obj" name="freezer0_vis"/>
    <mesh file="visuals/fridge_door.obj" name="fridge_door_vis"/>
    <mesh file="visuals/fridge_door_Clear.obj" name="fridge_door_Clear_vis"/>
    <mesh file="visuals/fridge_drawer0.obj" name="fridge_drawer0_vis"/>
    <mesh file="visuals/Body001.obj" name="Body001_vis"/>
    <mesh file="visuals/Body001_Clear.obj" name="Body001_Clear_vis"/>
    <texture file="visuals/T_BC001.png" name="Body001_material" type="2d"/>
    <material name="Body001_material" rgba="1 1 1 1.0" texture="Body001_material" shininess="0.1" specular="5"/>
    <texture file="visuals/T_BC001.png" name="freezer0_material" type="2d"/>
    <material name="freezer0_material" rgba="1 1 1 1.0" texture="freezer0_material" shininess="0.1" specular="5"/>
    <texture file="visuals/T_BC001.png" name="fridge_door_material" type="2d"/>
    <material name="fridge_door_material" rgba="1 1 1 1.0" texture="fridge_door_material" shininess="0.1" specular="5"/>
    <texture file="visuals/T_BC001.png" name="fridge_door_Clear_material" type="2d"/>
    <material name="fridge_door_Clear_material" rgba="1 1 1 0.699999988079071" texture="fridge_door_Clear_material" shininess="0.2512328028678894" specular="0.3103448502657381"/>
    <texture file="visuals/T_BC001.png" name="fridge_drawer0_material" type="2d"/>
    <material name="fridge_drawer0_material" rgba="1 1 1 1.0" texture="fridge_drawer0_material" shininess="0.1" specular="5"/>
    <texture file="visuals/T_BC001.png" name="Body001_Clear_material" type="2d"/>
    <material name="Body001_Clear_material" rgba="1 1 1 0.699999988079071" texture="Body001_Clear_material" shininess="0.2512328028678894" specular="0.3103448502657381"/>
  </asset>
  <default>
    <default class="visual">
      <geom conaffinity="0" contype="0" group="1" type="mesh"/>
    </default>
    <default class="collision">
      <geom group="0" rgba="0.5 0 0 0.5"/>
    </default>
    <default class="spawn">
      <geom group="0" rgba="1 1 1 0.5" contype="0" conaffinity="0"/>
      <site group="0" rgba="1 1 1 0.5"/>
    </default>
    <default class="region">
      <geom group="1" conaffinity="0" contype="0" rgba="0 1 0 0"/>
    </default>
  </default>
  <worldbody>
    <body>
      <body name="object">
        <geom mesh="Body001_vis" type="mesh" solimp="0.998 0.998 0.001" solref="0.001 1" friction="0.95 0.3 0.1" class="visual" material="Body001_material"/>
        <geom class="collision" type="box" pos="-0.37498215 0.10683183 0.36146265" size="0.031195690855383873 0.33520451188087463 0.5680927038192749" quat="1.0 0.0 0.0 0.0"/>
        <geom class="collision" type="box" pos="0.38533691 0.10683183 0.36146265" size="0.0325014553964138 0.33520451188087463 0.5680903792381287" quat="1.0 0.0 0.0 0.0"/>
        <geom class="collision" type="box" pos="0.00624308 0.09642668 0.88848519" size="0.3562801778316498 0.3370806574821472 0.041102055460214615" quat="1.0 0.0 0.0 0.0"/>
        <geom class="collision" type="box" pos="0.00624308 0.09642668 -0.18899992" size="0.35628077387809753 0.3370806574821472 0.043630000203847885" quat="1.0 0.0 0.0 0.0"/>
        <geom class="collision" type="box" pos="0.01057978 0.08701955 -0.86895347" size="0.3951025903224945 0.31481149792671204 0.06105321645736694" quat="1.0 0.0 0.0 0.0"/>
        <geom class="collision" type="box" pos="0.01219927 0.39924748 0.02470104" size="0.369966596364975 0.06026953458786011 0.9048711657524109" quat="1.0 0.0 0.0 0.0"/>
        <geom class="collision" type="box" pos="0.00371478 0.00521502 0.83800280" size="0.2067861258983612 0.07712382078170776 0.021174250170588493" quat="1.0 0.0 0.0 0.0"/>
        <geom class="collision" type="box" pos="0.00697397 0.10739441 0.50214899" size="0.34100404381752014 0.22730039060115814 0.00182140723336488" quat="1.0 0.0 0.0 0.0"/>
        <geom class="collision" type="box" pos="0.00853892 0.10739441 0.18026702" size="0.33464011549949646 0.22730039060115814 0.0018213489092886448" quat="1.0 0.0 0.0 0.0"/>
        <geom class="collision" type="box" pos="0.37079200 0.10683183 -0.54742235" size="0.04704749956727028 0.33520451188087463 0.33481961488723755" quat="1.0 0.0 0.0 0.0"/>
        <geom class="collision" type="box" pos="-0.35940635 0.10683183 -0.54742235" size="0.04677271097898483 0.33520451188087463 0.3348206579685211" quat="1.0 0.0 0.0 0.0"/>
        <body name="freezer0">
          <geom class="region" name="reg_freezer0" type="box" pos="0.008230729999999992 0.012634525000000008 -0.60733554" size="0.29248737999999996 0.241976305 0.17986314000000003"/>
          <joint axis="0.0 -1.0 0.0" pos="0.00597213 -0.08789717 -0.51584709" limited="true" name="freezer0_door_joint" range="0.0 0.5" type="slide" damping="1" frictionloss="1" armature=".01" stiffness="0.05"/>
          <geom mesh="freezer0_vis" type="mesh" solimp="0.998 0.998 0.001" solref="0.001 1" friction="0.95 0.3 0.1" class="visual" material="freezer0_material"/>
          <geom class="collision" type="box" pos="-0.01937570 -0.30954974 -0.51580966" size="0.3811870217323303 0.034648895263671875 0.37754932045936584" quat="1.0 0.0 0.0 0.0" name="freezer0_door_main"/>
          <geom class="collision" type="box" pos="0.00278338 -0.26311429 -0.49932554" size="0.341817170381546 0.011310314759612083 0.30125892162323" quat="1.0 0.0 0.0 0.0"/>
          <geom class="collision" type="box" pos="-0.30114576 0.00350488 -0.61156356" size="0.0049627781845629215 0.2570788860321045 0.18902094662189484" quat="1.0 0.0 0.0 0.0"/>
          <geom class="collision" type="box" pos="0.31010330 0.00350492 -0.61156356" size="0.004962789360433817 0.25707924365997314 0.18902094662189484" quat="1.0 0.0 0.0 0.0"/>
          <geom class="collision" type="box" pos="0.00044368 0.26494520 -0.61156356" size="0.30573150515556335 0.005501455627381802 0.18902094662189484" quat="1.0 0.0 0.0 0.0"/>
          <geom class="collision" type="box" pos="0.00535845 0.00334557 -0.79693633" size="0.3057325482368469 0.25625815987586975 0.004017821047455072" quat="1.0 0.0 0.0 0.0"/>
          <geom class="collision" type="box" pos="-0.22919912 -0.38848229 -0.19690244" size="0.014942779205739498 0.04655171185731888 0.013089067302644253" quat="1.0 0.0 0.0 0.0" name="freezer0_door_handle_2"/>
          <geom class="collision" type="box" pos="0.26194156 -0.39701479 -0.19849212" size="0.01589740812778473 0.029414836317300797 0.015767445787787437" quat="1.0 0.0 0.0 0.0" name="freezer0_door_handle_1"/>
          <geom class="collision" type="box" pos="0.01794117 -0.44173293 -0.21624349" size="0.2620830833911896 0.0216655433177948 0.016649946570396423" quat="0.8749849796295166 0.48415008187294006 0.0 0.0" name="freezer0_door_handle_main"/>
        </body>
        <body name="fridge_door">
          <joint axis="0.0 0.0 1.0" pos="0.36447525 -0.29339688 0.39571536" limited="true" name="fridge_door_joint" range="0.0 1.5707963267948966" type="hinge" damping="1" frictionloss="1" armature=".01" stiffness="0.05"/>
          <geom mesh="fridge_door_vis" type="mesh" solimp="0.998 0.998 0.001" solref="0.001 1" friction="0.95 0.3 0.1" class="visual" material="fridge_door_material"/>
          <geom class="collision" type="box" pos="0.00859993 -0.14479240 0.61289334" size="0.2844829857349396 0.0019456865265965462 0.03054332546889782" quat="1.0 0.0 0.0 0.0"/>
          <geom class="collision" type="box" pos="0.00859993 -0.21667939 0.58366883" size="0.2844829857349396 0.07154836505651474 0.0014210047665983438" quat="1.0 0.0 0.0 0.0"/>
          <geom class="collision" type="box" pos="-0.27801117 -0.21667939 0.61266774" size="0.0017949444008991122 0.07155442237854004 0.030536290258169174" quat="1.0 0.0 0.0 0.0"/>
          <geom class="collision" type="box" pos="0.29283229 -0.21667939 0.61266774" size="0.001794932410120964 0.07155442237854004 0.030536342412233353" quat="1.0 0.0 0.0 0.0"/>
          <geom class="collision" type="box" pos="0.00859993 -0.14479240 0.26346412" size="0.2844829857349396 0.0019457011949270964 0.05010267347097397" quat="1.0 0.0 0.0 0.0"/>
          <geom class="collision" type="box" pos="0.00859993 -0.21667939 0.21468025" size="0.2844829857349396 0.071549192070961 0.001421006629243493" quat="1.0 0.0 0.0 0.0"/>
          <geom class="collision" type="box" pos="-0.27801117 -0.21667939 0.26323855" size="0.0017949462635442615 0.07155442237854004 0.050094570964574814" quat="1.0 0.0 0.0 0.0"/>
          <geom class="collision" type="box" pos="0.29283229 -0.21667939 0.26323855" size="0.0017949307803064585 0.07155442237854004 0.05009468272328377" quat="1.0 0.0 0.0 0.0"/>
          <geom class="collision" type="box" pos="-0.38644641 -0.38941418 0.14176241" size="0.019419187679886818 0.016224142163991928 0.2570379972457886" quat="1.0 0.0 0.0 0.0" name="fridge_door_handle_main"/>
          <geom class="collision" type="box" pos="-0.01937570 -0.30978586 0.40456060" size="0.3811870217323303 0.03488543629646301 0.5239416360855103" quat="1.0 0.0 0.0 0.0" name="fridge_door_main"/>
          <geom class="collision" type="box" pos="-0.41224080 -0.33347549 -0.10008273" size="0.005623071454465389 0.06038874387741089 0.015767445787787437" quat="1.0 0.0 0.0 0.0" name="fridge_door_handle_2"/>
          <geom class="collision" type="box" pos="-0.41224080 -0.33347549 0.38093626" size="0.005623071454465389 0.06038874387741089 0.015767453238368034" quat="1.0 0.0 0.0 0.0" name="fridge_door_handle_1"/>
          <body name="fridge_door_Clear">
            <geom mesh="fridge_door_Clear_vis" type="mesh" solimp="0.998 0.998 0.001" solref="0.001 1" friction="0.95 0.3 0.1" class="visual" material="fridge_door_Clear_material"/>
            <geom class="collision" type="box" pos="0.00859993 -0.14479240 0.61289334" size="0.2844829857349396 0.0019456865265965462 0.03054332546889782" quat="1.0 0.0 0.0 0.0"/>
            <geom class="collision" type="box" pos="0.00859993 -0.21667939 0.58366883" size="0.2844829857349396 0.07154836505651474 0.0014210047665983438" quat="1.0 0.0 0.0 0.0"/>
            <geom class="collision" type="box" pos="-0.27801117 -0.21667939 0.61266774" size="0.0017949444008991122 0.07155442237854004 0.030536290258169174" quat="1.0 0.0 0.0 0.0"/>
            <geom class="collision" type="box" pos="0.29283229 -0.21667939 0.61266774" size="0.001794932410120964 0.07155442237854004 0.030536342412233353" quat="1.0 0.0 0.0 0.0"/>
            <geom class="collision" type="box" pos="0.00859993 -0.14479240 0.26346412" size="0.2844829857349396 0.0019457011949270964 0.05010267347097397" quat="1.0 0.0 0.0 0.0"/>
            <geom class="collision" type="box" pos="0.00859993 -0.21667939 0.21468025" size="0.2844829857349396 0.071549192070961 0.001421006629243493" quat="1.0 0.0 0.0 0.0"/>
            <geom class="collision" type="box" pos="-0.27801117 -0.21667939 0.26323855" size="0.0017949462635442615 0.07155442237854004 0.050094570964574814" quat="1.0 0.0 0.0 0.0"/>
            <geom class="collision" type="box" pos="0.29283229 -0.21667939 0.26323855" size="0.0017949307803064585 0.07155442237854004 0.05009468272328377" quat="1.0 0.0 0.0 0.0"/>
          </body>
        </body>
        <body name="fridge_drawer0">
          <geom class="region" name="reg_fridge_drawer0" type="box" pos="0.008725960000000005 0.09259087000000002 0.011095829999999994" size="0.27230537 0.20467778 0.11553443999999999"/>
          <joint axis="0.0 -1.0 0.0" pos="0.00765877 0.08214359 0.01506785" limited="true" name="fridge_drawer0_joint" range="0.0 0.5" type="slide" damping="1" frictionloss="1" armature=".01" stiffness="0.05"/>
          <geom mesh="fridge_drawer0_vis" type="mesh" solimp="0.998 0.998 0.001" solref="0.001 1" friction="0.95 0.3 0.1" class="visual" material="fridge_drawer0_material"/>
          <geom class="collision" type="box" pos="0.00861231 -0.13220423 0.11384147" size="0.2942259609699249 0.015158834867179394 0.04744071513414383" quat="1.0 0.0 0.0 0.0"/>
          <geom class="collision" type="box" pos="0.00802649 0.09290544 -0.11368094" size="0.27767154574394226 0.21130329370498657 0.0037512939888983965" quat="1.0 0.0 0.0 0.0"/>
          <geom class="collision" type="box" pos="0.01087599 0.30790026 0.00861796" size="0.2778552174568176 0.005564889870584011 0.12145978957414627" quat="1.0 0.0 0.0 0.0"/>
          <geom class="collision" type="box" pos="-0.27555060 0.09532172 0.00794716" size="0.0060361758805811405 0.2138131707906723 0.12078895419836044" quat="1.0 0.0 0.0 0.0"/>
          <geom class="collision" type="box" pos="0.29196811 0.10102713 0.00908123" size="0.006036188919097185 0.21951988339424133 0.12192296981811523" quat="1.0 0.0 0.0 0.0"/>
          <geom class="collision" type="box" pos="0.00861231 -0.13220420 -0.06710216" size="0.2942620515823364 0.015161102637648582 0.06715428084135056" quat="1.0 0.0 0.0 0.0"/>
          <geom class="collision" type="box" pos="-0.16129227 -0.13220423 0.03182351" size="0.12436330318450928 0.015161124058067799 0.0341324657201767" quat="1.0 0.0 0.0 0.0"/>
          <geom class="collision" type="box" pos="0.20334919 -0.13220423 0.03182351" size="0.09833893179893494 0.01516119483858347 0.0341324508190155" quat="1.0 0.0 0.0 0.0"/>
          <geom class="collision" type="box" pos="0.03545672 -0.14485174 0.05484637" size="0.07131637632846832 0.002514158608391881 0.011327690444886684" quat="1.0 0.0 0.0 0.0"/>
          <geom class="collision" type="box" pos="0.03545672 -0.11873006 0.03211670" size="0.07131661474704742 0.001339258742518723 0.03299644589424133" quat="1.0 0.0 0.0 0.0"/>
        </body>
        <body name="Body001_Clear">
          <geom mesh="Body001_Clear_vis" type="mesh" solimp="0.998 0.998 0.001" solref="0.001 1" friction="0.95 0.3 0.1" class="visual" material="Body001_Clear_material"/>
          <geom class="collision" type="box" pos="0.00697397 0.10739441 0.50214899" size="0.34100404381752014 0.22730039060115814 0.00182140723336488" quat="1.0 0.0 0.0 0.0"/>
          <geom class="collision" type="box" pos="0.00853892 0.10739441 0.18026702" size="0.33464011549949646 0.22730039060115814 0.0018213489092886448" quat="1.0 0.0 0.0 0.0"/>
        </body>
        <geom class="region" name="reg_main" type="box" pos="-1.5000000019860238e-08 0.057422575000000003 0.0" size="0.420914485 0.40309442500000003 0.93100013"/>
      </body>
    </body>
  </worldbody>
  <actuator>
    <motor name="freezer0_door_joint_actuator" joint="freezer0_door_joint" gear="50"/>
    <motor name="fridge_door_joint_actuator" joint="fridge_door_joint" gear="50"/>
    <motor name="fridge_drawer0_joint_actuator" joint="fridge_drawer0_joint" gear="50"/>
  </actuator>
</mujoco>
